weight=6
embed_into_distance=1
dimensions=5,4,8
max_cut_in=3

rule1=0,100,85
rule2=5,100,35-14,35-9,35-5
rule3=5,100,35-4,35-0
rule4=0,100,4
rule5=0,100,54-4
rule6=0,70,103,86-0

layer
4,4,4,4,4,4,4,4
4,4,4,4,4,4,4,4
4,4,4,4,4,4,4,4
4,4,4,4,4,4,4,4
endlayer

layer
0,0,0,0,0,6,6,0
0,1,0,0,0,6,6,1
0,2,2,2,2,2,2,2
0,1,2,2,2,2,2,1
endlayer
            
layer
0,0,0,0,0,0,0,0
0,1,0,0,0,0,0,1
0,0,5,0,0,6,6,0
0,1,0,0,0,6,6,1
endlayer
            
layer
0,0,0,0,0,0,0,0
0,1,0,0,0,0,0,1
0,0,0,0,0,0,0,0
0,1,0,0,0,0,0,1
endlayer
            
layer
0,0,0,0,0,0,0,0
0,2,3,2,3,2,3,2
0,2,3,2,3,2,3,2
0,2,3,2,3,2,3,2
endlayer
            
layer:base
4,4,4,4,4,4,4,4
4,4,4,4,4,4,4,4
4,4,4,4,4,4,4,4
4,4,4,4,4,4,4,4
endlayer


