weight=3
embed_into_distance=36
dimensions=42,10,10

rule1=0,100,PRESERVE
rule2=0,95,112 #exterior
rule3=1,95,114-0 #stairs
rule4=1,95,114-1
rule5=1,95,114-2
rule6=1,95,114-3
rule7=0,100,8 #water
rule8=0,80,65-3 #ladder
rule9=0,100,101 #iron bars
rule10=0,60,56,21,21,21,21,15,15,15,15,15,14,14,14,14,14,73,73,73,48,48,48,48,48,0-2,0-2,0-2 #ores
rule11=0,60,52-0-MEDIUM


layer
1,1,1,1,1,1,1,1,1,1
1,1,1,1,10,10,1,1,1,1
1,1,1,10,10,10,10,1,1,1
1,1,10,10,10,10,10,10,1,1
1,1,10,10,10,10,10,10,1,1
1,1,1,10,10,10,10,1,1,1
1,1,1,1,10,10,1,1,1,1
1,1,1,1,1,1,1,1,1,1
1,1,1,1,1,1,1,1,1,1
1,1,1,1,1,1,1,1,1,1
endlayer
layer
1,1,1,1,1,1,1,1,1,1
1,1,1,1,10,10,1,1,1,1
1,1,1,10,10,10,10,1,1,1
1,1,10,10,10,10,10,10,1,1
1,1,10,10,10,10,10,10,1,1
1,1,1,10,10,10,10,1,1,1
1,1,1,1,10,10,1,1,1,1
1,1,1,1,1,1,1,1,1,1
1,1,1,1,1,1,1,1,1,1
1,1,1,1,1,1,1,1,1,1
endlayer
layer
1,1,1,1,1,1,1,1,1,1
1,1,1,1,10,10,1,1,1,1
1,1,1,10,10,10,10,1,1,1
1,1,10,10,10,10,10,10,1,1
1,1,10,10,10,10,10,10,1,1
1,1,1,10,10,10,10,1,1,1
1,1,1,1,10,10,1,1,1,1
1,1,1,1,1,1,1,1,1,1
1,1,1,1,1,1,1,1,1,1
1,1,1,1,1,1,1,1,1,1
endlayer

layer
1,1,1,1,1,1,1,1,1,1
1,1,10,10,10,10,10,10,1,1
1,10,10,0,0,11,0,10,10,1
1,10,0,0,0,0,0,0,10,1
1,10,0,0,0,0,0,0,10,1
1,10,0,0,0,0,11,0,10,1
1,10,0,11,0,0,0,0,10,1
1,10,10,0,0,11,0,10,10,1
1,1,10,10,10,10,10,10,1,1
1,1,1,1,1,1,1,1,1,1
endlayer
layer
1,1,1,1,1,1,1,1,1,1
1,1,10,10,10,10,10,10,1,1
1,10,10,0,0,0,0,10,10,1
1,10,0,0,0,0,0,0,10,1
1,10,0,0,0,0,0,0,10,1
1,10,0,0,0,0,0,0,10,1
1,10,0,0,0,0,0,0,10,1
1,10,10,0,0,0,0,10,10,1
1,1,10,10,10,10,10,10,1,1
1,1,1,1,1,1,1,1,1,1
endlayer
layer
1,1,1,1,1,1,1,1,1,1
1,1,10,10,10,10,10,10,1,1
1,10,10,0,0,0,0,10,10,1
1,10,0,0,0,0,0,0,10,1
1,10,0,0,0,0,0,0,10,1
1,10,0,0,0,0,0,0,10,1
1,10,0,0,0,0,0,0,10,1
1,10,10,0,0,0,0,10,10,1
1,1,10,10,10,10,10,10,1,1
1,1,1,1,1,1,1,1,1,1
endlayer

layer
1,1,1,1,1,1,1,1,1,1
1,1,1,1,1,1,1,1,1,1
1,1,1,1,1,1,1,1,1,1
1,1,1,1,1,1,1,1,1,1
1,1,1,1,1,8,1,1,1,1
1,1,1,1,1,1,1,1,1,1
1,1,1,1,1,1,1,1,1,1
1,1,1,1,1,1,1,1,1,1
1,1,1,1,1,1,1,1,1,1
1,1,1,1,1,1,1,1,1,1
endlayer
layer
1,1,1,1,1,1,1,1,1,1
1,1,1,1,1,1,1,1,1,1
1,1,1,1,1,1,1,1,1,1
1,1,1,1,1,1,1,1,1,1
1,1,1,1,1,8,1,1,1,1
1,1,1,1,1,1,1,1,1,1
1,1,1,1,1,1,1,1,1,1
1,1,1,1,1,1,1,1,1,1
1,1,1,1,1,1,1,1,1,1
1,1,1,1,1,1,1,1,1,1
endlayer
layer
1,1,1,1,1,1,1,1,1,1
1,1,1,1,1,1,1,1,1,1
1,1,1,1,1,1,1,1,1,1
1,1,1,1,1,1,1,1,1,1
1,1,1,1,1,8,1,1,1,1
1,1,1,1,1,1,1,1,1,1
1,1,1,1,1,1,1,1,1,1
1,1,1,1,1,1,1,1,1,1
1,1,1,1,1,1,1,1,1,1
1,1,1,1,1,1,1,1,1,1
endlayer
layer
1,1,1,1,1,1,1,1,1,1
1,1,1,1,1,1,1,1,1,1
1,1,1,1,1,1,1,1,1,1
1,1,1,1,1,1,1,1,1,1
1,1,1,1,1,8,1,1,1,1
1,1,1,1,1,1,1,1,1,1
1,1,1,1,1,1,1,1,1,1
1,1,1,1,1,1,1,1,1,1
1,1,1,1,1,1,1,1,1,1
1,1,1,1,1,1,1,1,1,1
endlayer
layer
1,1,1,1,1,1,1,1,1,1
1,1,1,1,1,1,1,1,1,1
1,1,1,1,1,1,1,1,1,1
1,1,1,1,1,1,1,1,1,1
1,1,1,1,1,8,1,1,1,1
1,1,1,1,1,1,1,1,1,1
1,1,1,1,1,1,1,1,1,1
1,1,1,1,1,1,1,1,1,1
1,1,1,1,1,1,1,1,1,1
1,1,1,1,1,1,1,1,1,1
endlayer
layer
1,1,1,1,1,1,1,1,1,1
1,1,1,1,1,1,1,1,1,1
1,1,1,1,1,1,1,1,1,1
1,1,1,1,1,1,1,1,1,1
1,1,1,1,1,8,1,1,1,1
1,1,1,1,1,1,1,1,1,1
1,1,1,1,1,1,1,1,1,1
1,1,1,1,1,1,1,1,1,1
1,1,1,1,1,1,1,1,1,1
1,1,1,1,1,1,1,1,1,1
endlayer
layer
1,1,1,1,1,1,1,1,1,1
1,1,1,1,1,1,1,1,1,1
1,1,1,1,1,1,1,1,1,1
1,1,1,1,1,1,1,1,1,1
1,1,1,1,1,8,1,1,1,1
1,1,1,1,1,1,1,1,1,1
1,1,1,1,1,1,1,1,1,1
1,1,1,1,1,1,1,1,1,1
1,1,1,1,1,1,1,1,1,1
1,1,1,1,1,1,1,1,1,1
endlayer
layer
1,1,1,1,1,1,1,1,1,1
1,1,1,1,1,1,1,1,1,1
1,1,1,1,1,1,1,1,1,1
1,1,1,1,1,1,1,1,1,1
1,1,1,1,1,8,1,1,1,1
1,1,1,1,1,1,1,1,1,1
1,1,1,1,1,1,1,1,1,1
1,1,1,1,1,1,1,1,1,1
1,1,1,1,1,1,1,1,1,1
1,1,1,1,1,1,1,1,1,1
endlayer
layer
1,1,1,1,1,1,1,1,1,1
1,1,1,1,1,1,1,1,1,1
1,1,1,1,1,1,1,1,1,1
1,1,1,1,1,1,1,1,1,1
1,1,1,1,1,8,1,1,1,1
1,1,1,1,1,1,1,1,1,1
1,1,1,1,1,1,1,1,1,1
1,1,1,1,1,1,1,1,1,1
1,1,1,1,1,1,1,1,1,1
1,1,1,1,1,1,1,1,1,1
endlayer
layer
1,1,1,1,1,1,1,1,1,1
1,1,1,1,1,1,1,1,1,1
1,1,1,1,1,1,1,1,1,1
1,1,1,1,1,1,1,1,1,1
1,1,1,1,1,8,1,1,1,1
1,1,1,1,1,1,1,1,1,1
1,1,1,1,1,1,1,1,1,1
1,1,1,1,1,1,1,1,1,1
1,1,1,1,1,1,1,1,1,1
1,1,1,1,1,1,1,1,1,1
endlayer
layer
1,1,1,1,1,1,1,1,1,1
1,1,1,1,1,1,1,1,1,1
1,1,1,1,1,1,1,1,1,1
1,1,1,1,1,1,1,1,1,1
1,1,1,1,1,8,1,1,1,1
1,1,1,1,1,1,1,1,1,1
1,1,1,1,1,1,1,1,1,1
1,1,1,1,1,1,1,1,1,1
1,1,1,1,1,1,1,1,1,1
1,1,1,1,1,1,1,1,1,1
endlayer
layer
1,1,1,1,1,1,1,1,1,1
1,1,1,1,1,1,1,1,1,1
1,1,1,1,1,1,1,1,1,1
1,1,1,1,1,1,1,1,1,1
1,1,1,1,1,8,1,1,1,1
1,1,1,1,1,1,1,1,1,1
1,1,1,1,1,1,1,1,1,1
1,1,1,1,1,1,1,1,1,1
1,1,1,1,1,1,1,1,1,1
1,1,1,1,1,1,1,1,1,1
endlayer
layer
1,1,1,1,1,1,1,1,1,1
1,1,1,1,1,1,1,1,1,1
1,1,1,1,1,1,1,1,1,1
1,1,1,1,1,1,1,1,1,1
1,1,1,1,1,8,1,1,1,1
1,1,1,1,1,1,1,1,1,1
1,1,1,1,1,1,1,1,1,1
1,1,1,1,1,1,1,1,1,1
1,1,1,1,1,1,1,1,1,1
1,1,1,1,1,1,1,1,1,1
endlayer
layer
1,1,1,1,1,1,1,1,1,1
1,1,1,1,1,1,1,1,1,1
1,1,1,1,1,1,1,1,1,1
1,1,1,1,1,1,1,1,1,1
1,1,1,1,1,8,1,1,1,1
1,1,1,1,1,1,1,1,1,1
1,1,1,1,1,1,1,1,1,1
1,1,1,1,1,1,1,1,1,1
1,1,1,1,1,1,1,1,1,1
1,1,1,1,1,1,1,1,1,1
endlayer
layer
1,1,1,1,1,1,1,1,1,1
1,1,1,1,1,1,1,1,1,1
1,1,1,1,1,1,1,1,1,1
1,1,1,1,1,1,1,1,1,1
1,1,1,1,1,8,1,1,1,1
1,1,1,1,1,1,1,1,1,1
1,1,1,1,1,1,1,1,1,1
1,1,1,1,1,1,1,1,1,1
1,1,1,1,1,1,1,1,1,1
1,1,1,1,1,1,1,1,1,1
endlayer
layer
1,1,1,1,1,1,1,1,1,1
1,1,1,1,1,1,1,1,1,1
1,1,1,1,1,1,1,1,1,1
1,1,1,1,1,1,1,1,1,1
1,1,1,1,1,8,1,1,1,1
1,1,1,1,1,1,1,1,1,1
1,1,1,1,1,1,1,1,1,1
1,1,1,1,1,1,1,1,1,1
1,1,1,1,1,1,1,1,1,1
1,1,1,1,1,1,1,1,1,1
endlayer
layer
1,1,1,1,1,1,1,1,1,1
1,1,1,1,1,1,1,1,1,1
1,1,1,1,1,1,1,1,1,1
1,1,1,1,1,1,1,1,1,1
1,1,1,1,1,8,1,1,1,1
1,1,1,1,1,1,1,1,1,1
1,1,1,1,1,1,1,1,1,1
1,1,1,1,1,1,1,1,1,1
1,1,1,1,1,1,1,1,1,1
1,1,1,1,1,1,1,1,1,1
endlayer
layer
1,1,1,1,1,1,1,1,1,1
1,1,1,1,1,1,1,1,1,1
1,1,1,1,1,1,1,1,1,1
1,1,1,1,1,1,1,1,1,1
1,1,1,1,1,8,1,1,1,1
1,1,1,1,1,1,1,1,1,1
1,1,1,1,1,1,1,1,1,1
1,1,1,1,1,1,1,1,1,1
1,1,1,1,1,1,1,1,1,1
1,1,1,1,1,1,1,1,1,1
endlayer

layer
1,1,1,1,1,1,1,1,1,1
1,1,1,1,1,1,1,1,1,1
1,1,1,1,1,1,1,1,1,1
1,1,1,1,2,2,2,1,1,1
1,1,1,1,2,8,2,1,1,1
1,1,1,1,2,2,2,1,1,1
1,1,1,1,1,1,1,1,1,1
1,1,1,1,1,1,1,1,1,1
1,1,1,1,1,1,1,1,1,1
1,1,1,1,1,1,1,1,1,1
endlayer

layer
1,1,1,1,1,1,1,1,1,1
1,1,1,1,1,1,1,1,1,1
1,1,1,1,1,1,1,1,1,1
1,1,1,1,2,2,2,1,1,1
1,1,1,1,2,8,2,1,1,1
1,1,1,1,2,2,2,1,1,1
1,1,1,1,1,1,1,1,1,1
1,1,1,1,1,1,1,1,1,1
1,1,1,1,1,1,1,1,1,1
1,1,1,1,1,1,1,1,1,1
endlayer

layer
2,2,2,2,2,2,2,2,2,2
2,2,2,2,2,2,2,2,2,2
2,2,2,2,2,2,2,2,2,2
2,2,2,2,2,2,2,2,2,2
2,2,2,2,2,8,2,2,2,2
2,2,2,2,2,2,2,2,2,2
2,2,2,2,2,2,2,2,2,2
2,2,2,2,2,2,2,2,2,2
2,2,2,2,2,2,2,2,2,2
2,2,2,2,2,2,2,2,2,2
endlayer

layer
2,2,2,2,2,2,2,2,2,2
2,1,1,1,1,1,1,1,1,2
2,1,1,1,1,1,1,1,1,2
2,1,1,1,2,2,2,1,1,2
2,1,1,1,2,8,2,1,1,2
2,1,1,1,2,2,2,1,1,2
2,1,1,1,1,1,1,1,1,2
2,1,1,1,1,1,1,1,1,2
2,1,1,1,1,1,1,1,1,2
2,2,2,2,2,2,2,2,2,2
endlayer

layer
2,2,2,2,2,2,2,2,2,2
2,1,1,1,1,1,1,1,1,2
2,1,1,1,1,1,1,1,1,2
2,1,1,1,2,2,2,1,1,2
2,1,1,1,2,8,2,1,1,2
2,1,1,1,2,2,2,1,1,2
2,1,1,1,1,1,1,1,1,2
2,1,1,1,1,1,1,1,1,2
2,1,1,1,1,1,1,1,1,2
2,2,2,2,2,2,2,2,2,2
endlayer

layer
2,2,2,2,2,2,2,2,2,2
2,1,1,1,1,1,1,1,1,2
2,1,1,1,1,1,1,1,1,2
2,1,1,1,2,2,2,1,1,2
2,1,1,1,2,8,2,1,1,2
2,1,1,1,2,2,2,1,1,2
2,1,1,1,1,1,1,1,1,2
2,1,1,1,1,1,1,1,1,2
2,1,1,1,1,1,1,1,1,2
2,2,2,2,2,2,2,2,2,2
endlayer

layer
2,2,2,2,2,2,2,2,2,2
2,1,1,1,1,1,1,1,1,2
2,1,1,1,1,1,1,1,1,2
2,1,1,1,2,2,2,1,1,2
2,1,1,1,2,8,2,1,1,2
2,1,1,1,2,2,2,1,1,2
2,1,1,1,1,1,1,1,1,2
2,1,1,1,1,1,1,1,1,2
2,1,1,1,1,1,1,1,1,2
2,2,2,2,2,2,2,2,2,2
endlayer

layer
2,2,2,2,2,2,2,2,2,2
2,1,1,1,1,1,1,1,1,2
2,1,1,1,1,1,1,1,1,2
2,1,1,1,2,2,2,1,1,2
2,1,1,1,2,8,2,1,1,2
2,1,1,1,2,2,2,1,1,2
2,1,1,1,1,1,1,1,1,2
2,1,1,1,1,1,1,1,1,2
2,1,1,1,1,1,1,1,1,2
2,2,2,2,2,2,2,2,2,2
endlayer

layer
2,2,2,2,2,2,2,2,2,2
2,1,1,1,1,1,1,1,1,2
2,1,1,1,1,1,1,1,1,2
2,1,1,1,2,2,2,1,1,2
2,1,1,1,2,8,2,1,1,2
2,1,1,1,2,2,2,1,1,2
2,1,1,1,1,1,1,1,1,2
2,1,1,1,1,1,1,1,1,2
2,1,1,1,1,1,1,1,1,2
2,2,2,2,2,2,2,2,2,2
endlayer


layer
2,2,2,2,2,2,2,2,2,2
2,1,1,1,1,1,1,1,1,2
2,1,1,1,1,1,1,1,1,2
2,1,1,1,2,2,2,1,1,2
2,1,1,1,2,8,2,1,1,2
2,1,1,1,2,2,2,1,1,2
2,1,1,1,1,1,1,1,1,2
2,1,1,1,1,1,1,1,1,2
2,1,1,1,1,1,1,1,1,2
2,2,2,2,2,2,2,2,2,2
endlayer


layer
2,2,2,2,2,2,2,2,2,2
2,2,2,2,2,2,2,2,2,2
2,2,2,2,2,2,2,2,2,2
2,2,2,2,2,2,2,2,2,2
2,2,2,2,2,8,2,2,2,2
2,2,2,2,2,2,2,2,2,2
2,2,2,2,2,2,2,2,2,2
2,2,2,2,2,2,2,2,2,2
2,2,2,2,2,2,2,2,2,2
2,2,2,2,2,2,2,2,2,2
endlayer

layer
2,2,2,2,2,2,2,2,2,2
2,2,2,2,2,2,2,2,2,2
2,2,2,2,2,2,2,2,2,2
2,2,2,2,2,2,2,2,2,2
2,2,2,2,2,8,2,2,2,2
2,2,2,2,2,2,2,2,2,2
2,2,2,2,2,2,2,2,2,2
2,2,2,2,2,2,2,2,2,2
2,2,2,2,2,2,2,2,2,2
2,2,2,2,2,2,2,2,2,2
endlayer

layer
2,2,2,2,2,2,2,2,2,2
2,2,2,2,2,2,2,2,2,2
2,2,2,2,2,2,2,2,2,2
2,2,2,2,2,2,2,2,2,2
2,2,2,2,2,8,2,2,2,2
2,2,2,2,2,2,2,2,2,2
2,2,2,2,2,2,2,2,2,2
2,2,2,2,2,2,2,2,2,2
2,2,2,2,2,2,2,2,2,2
2,2,2,2,2,2,2,2,2,2
endlayer

layer
1,1,1,1,0,0,1,1,1,1
1,2,2,2,0,0,2,2,2,1
1,2,0,0,0,0,0,0,2,1
1,2,0,0,0,0,0,0,2,1
3,2,0,0,0,0,0,0,2,4
3,2,0,0,0,0,0,0,2,4
1,2,0,0,0,0,0,0,2,1
1,2,0,9,9,9,9,0,2,1
1,2,2,2,0,0,2,2,2,1
1,1,1,9,9,9,9,1,1,1
endlayer

layer
1,1,1,1,0,0,1,1,1,1
1,1,1,1,0,0,1,1,1,1
1,1,2,2,0,0,2,2,1,1
1,1,2,0,0,0,0,2,1,1
1,3,2,0,0,0,0,2,4,1
1,3,2,0,0,0,0,2,4,1
1,1,2,0,0,0,0,2,1,1
1,1,2,2,9,9,2,2,1,1
1,1,0,0,0,0,0,0,1,1
1,1,0,0,0,0,0,0,1,1
endlayer

layer
1,1,1,0,0,0,0,1,1,1
1,1,1,0,0,0,0,1,1,1
1,1,1,0,5,5,0,1,1,1
1,1,1,2,2,2,2,1,1,1
1,1,3,2,0,0,2,4,1,1
1,1,3,2,0,0,2,4,1,1
1,1,1,2,2,2,2,1,1,1
1,1,1,2,7,7,2,1,1,1
1,1,1,0,0,0,0,1,1,1
1,1,1,0,0,0,0,1,1,1
endlayer

layer
1,1,1,1,0,0,1,1,1,1
1,1,1,1,0,0,1,1,1,1
1,1,1,1,0,0,1,1,1,1
1,1,1,1,5,5,1,1,1,1
1,1,1,3,2,2,4,1,1,1
1,1,1,3,2,2,4,1,1,1
1,1,1,1,6,6,1,1,1,1
1,1,1,1,0,0,1,1,1,1
1,1,1,1,0,0,1,1,1,1
1,1,1,1,0,0,1,1,1,1
endlayer

layer
0,0,0,0,0,0,0,0,0,0
0,0,0,0,0,0,0,0,0,0
0,0,0,0,0,0,0,0,0,0
0,0,0,0,0,0,0,0,0,0
0,0,0,0,0,0,0,0,0,0
0,0,0,0,0,0,0,0,0,0
0,0,0,0,0,0,0,0,0,0
0,0,0,0,0,0,0,0,0,0
0,0,0,0,0,0,0,0,0,0
0,0,0,0,0,0,0,0,0,0
endlayer




