# Converted from schematic
# author:MohawkyMagoo

weight=15
embed_into_distance=5
#acceptable_target_blocks=1,2,3,12,13
dimensions=14,16,12
#allowable_overhang=0
max_cut_in=2
#cut_in_buffer=1
max_leveling=2
#leveling_buffer=1
#preserve_water=0
#preserve_lava=0
#preserve_plants=0


rule1=0,100,1
rule2=0,100,24
rule3=0,100,13
rule4=0,100,3
rule5=0,100,4
rule6=0,100,5
rule7=0,100,54
rule8=0,100,67-1
rule9=0,100,50-3
rule10=0,100,50-4
rule11=0,100,50-1
rule12=0,100,12
rule13=0,100,67-0
rule14=0,100,2
rule15=0,100,17
rule16=0,100,67-3
rule17=0,100,85
rule18=0,100,107
rule19=0,100,98
rule20=0,100,109-2
rule21=0,100,109-1
rule22=0,100,9
rule23=0,100,109-3
rule24=0,100,61-2
rule25=0,100,64-1
rule26=0,100,11
rule27=0,100,61-3
rule28=0,100,43
rule29=0,100,58
rule30=0,100,109-0
rule31=0,100,107-3
rule32=0,100,20
rule33=0,100,64-9
rule34=0,100,64-8
rule35=0,100,50-2
rule36=0,100,53-2
rule37=0,100,44-5
rule38=0,100,54-4
rule39=0,100,26-0
rule40=0,100,26-8
rule41=0,100,26-1
rule42=0,100,26-9
rule43=0,100,53-1
rule44=0,100,53-3
rule45=0,100,50-5
rule46=0,100,126-0


layer
1,1,1,1,1,1,1,1,1,1,1,1
1,1,1,1,2,2,1,1,1,2,1,1
1,1,1,1,1,2,1,1,1,2,1,1
1,1,1,1,1,1,5,5,5,3,1,1
1,1,1,1,1,1,5,5,5,2,1,1
1,1,1,1,1,1,5,5,5,3,1,1
1,1,1,1,1,1,1,5,3,3,1,1
1,1,1,1,1,1,5,5,5,3,1,1
1,1,5,1,1,1,5,5,5,3,1,1
1,1,5,1,1,1,5,5,5,3,1,1
1,1,5,1,1,1,5,5,5,3,1,1
1,1,5,1,1,1,1,1,1,3,1,1
1,1,1,1,1,1,1,1,1,1,1,1
1,1,4,4,4,4,4,4,4,4,1,1
1,1,4,4,4,4,4,4,4,4,1,1
1,1,4,4,4,4,4,4,4,4,1,1
endlayer

layer
1,1,1,1,1,1,1,1,1,1,1,1
1,1,1,1,2,2,2,2,1,2,1,1
1,1,1,5,5,5,5,5,5,2,1,1
1,1,1,0,0,0,8,5,0,5,1,1
1,1,5,0,0,0,5,0,0,5,1,1
1,1,1,0,0,0,0,0,0,5,1,1
1,1,5,5,0,1,5,5,5,2,1,1
1,1,1,0,0,6,7,7,6,5,1,1
1,1,5,0,0,0,0,0,7,5,1,1
1,1,5,0,0,0,0,0,7,5,1,1
1,1,5,7,7,6,7,7,6,5,1,1
1,1,4,1,1,1,1,1,1,3,1,1
1,1,1,1,1,1,1,1,2,2,1,1
1,1,4,4,4,4,4,4,4,4,1,1
1,1,4,4,4,4,4,4,4,4,1,1
1,1,4,4,4,4,4,4,4,4,1,1
endlayer

layer
1,1,1,1,1,1,1,1,1,1,1,1
1,1,2,2,2,2,2,2,2,2,1,1
1,1,2,5,5,5,5,5,5,2,1,1
1,1,1,0,0,0,0,8,5,5,1,1
1,1,5,11,0,0,5,0,9,5,1,1
1,1,5,0,0,0,0,0,0,5,1,1
1,1,5,5,0,1,5,5,5,2,1,1
1,1,1,0,0,0,0,0,0,5,1,1
1,1,1,0,0,0,0,0,0,5,1,1
1,1,1,0,0,0,0,0,0,5,1,1
1,1,1,0,10,0,0,10,0,5,1,1
1,1,1,1,1,5,1,1,5,1,1,1
1,1,1,1,1,1,2,1,2,2,1,1
1,1,4,4,4,4,4,4,4,4,1,1
1,1,4,4,4,4,4,4,4,4,1,1
1,1,4,4,4,4,4,4,4,4,1,1
endlayer

layer
1,1,1,1,1,1,1,1,1,1,1,1
1,1,2,12,12,12,12,12,5,12,1,1
1,1,2,5,5,5,5,5,5,12,1,1
1,1,5,0,0,0,0,0,0,5,1,1
1,1,5,0,0,0,5,5,13,5,1,1
1,1,5,0,0,0,5,5,5,5,1,1
1,1,5,5,5,1,5,5,5,12,1,1
1,1,1,0,0,0,0,0,0,5,1,1
1,1,1,0,0,0,0,0,0,5,1,1
1,1,1,0,0,0,0,0,0,5,1,1
1,1,5,0,0,0,0,0,0,5,1,1
1,1,2,5,5,5,5,5,5,1,1,1
1,1,1,1,4,2,2,1,2,2,1,1
1,1,4,4,4,4,4,4,4,4,1,1
1,1,4,4,4,4,4,4,4,4,1,1
1,1,4,4,4,4,4,4,4,4,1,1
endlayer

layer
14,14,14,14,14,14,14,14,14,14,14,14
14,14,14,14,14,14,14,14,14,14,14,14
14,14,4,4,4,15,5,5,5,15,14,14
14,14,4,5,5,5,0,0,0,5,14,14
14,14,5,5,5,5,5,5,0,5,14,14
14,14,4,5,5,5,5,16,0,5,14,14
14,14,4,4,4,5,5,5,5,15,14,14
14,5,5,5,5,5,5,5,5,5,14,14
5,5,5,5,5,5,5,5,5,5,5,5
14,14,5,5,5,5,5,5,5,5,14,14
14,14,5,5,5,5,5,5,5,5,14,14
14,14,4,5,5,5,5,5,5,4,14,14
14,14,14,5,5,5,5,5,5,14,14,14
14,14,14,5,5,5,5,5,5,14,14,14
14,14,14,5,5,5,5,5,5,14,14,14
14,14,4,14,14,14,14,14,14,4,14,14
endlayer

layer
17,17,17,17,17,17,17,17,17,17,17,17
17,0,0,0,0,0,0,0,0,0,0,17
17,0,15,19,19,19,19,19,19,15,0,17
17,0,19,28,0,0,8,0,0,19,0,17
17,0,19,29,0,0,0,5,0,19,0,17
17,0,19,28,0,0,0,0,0,19,0,17
17,0,15,19,19,25,25,19,19,15,0,17
17,0,0,0,0,0,0,0,0,0,0,17
31,0,0,0,0,0,0,0,0,0,0,18
17,0,30,20,24,20,20,24,20,20,0,17
17,0,30,22,5,26,26,5,22,21,0,17
17,0,19,23,19,27,27,19,23,19,0,17
17,0,0,0,0,0,0,0,0,0,0,17
17,0,0,0,0,0,0,0,0,0,0,17
17,0,0,0,0,0,0,0,0,0,0,17
17,17,19,17,17,17,17,17,17,19,17,17
endlayer

layer
0,0,0,0,0,0,0,0,0,0,0,0
0,0,0,10,0,0,0,0,10,0,0,0
0,35,15,19,19,32,32,19,19,15,11,0
0,0,19,0,0,0,0,8,5,19,0,0
0,0,32,0,0,0,0,5,0,32,0,0
0,0,19,0,0,0,0,0,0,19,0,0
0,35,15,19,19,34,33,19,19,15,11,0
0,0,0,0,0,0,0,0,0,0,0,0
0,0,0,0,0,0,0,0,0,0,0,0
0,0,0,0,0,0,0,0,0,0,0,0
0,0,0,0,19,0,0,19,0,0,0,0
0,0,19,0,19,0,0,19,0,19,0,0
0,0,0,0,9,0,0,9,0,0,0,0
0,0,0,0,0,0,0,0,0,0,0,0
0,0,0,0,0,0,0,0,0,0,0,0
0,0,19,0,0,0,0,0,0,19,0,0
endlayer

layer
0,0,0,0,0,0,0,0,0,0,0,0
0,0,0,0,0,0,0,0,0,0,0,0
0,0,15,19,19,19,19,19,19,15,0,0
0,0,19,9,0,0,0,0,0,19,0,0
0,0,19,0,0,0,0,5,13,19,0,0
0,0,19,0,10,0,0,0,10,19,0,0
0,0,15,19,19,19,19,19,19,15,0,0
0,0,0,0,0,9,9,0,0,0,0,0
0,0,0,0,0,0,0,0,0,0,0,0
0,0,0,0,30,20,20,21,0,0,0,0
0,0,0,0,30,0,0,21,0,0,0,0
0,0,19,0,23,23,23,23,0,19,0,0
0,0,0,0,0,0,0,0,0,0,0,0
0,0,0,0,0,0,0,0,0,0,0,0
0,0,0,0,0,0,0,0,0,0,0,0
0,0,19,0,0,0,0,0,0,19,0,0
endlayer

layer
0,0,0,0,0,0,0,0,0,0,0,0
0,36,36,36,36,36,36,36,36,36,36,0
0,0,15,15,15,15,15,15,15,15,0,0
0,0,15,5,5,5,0,0,0,15,0,0
0,0,15,5,5,5,5,5,0,15,0,0
0,0,15,5,5,5,5,5,13,15,0,0
0,0,15,5,5,5,5,5,5,15,0,0
0,0,19,5,5,5,5,5,5,19,0,0
0,0,19,5,5,5,5,5,5,19,0,0
0,0,19,5,5,5,5,5,5,19,0,0
0,0,19,19,19,19,19,19,19,19,0,0
0,35,19,0,0,0,0,0,0,19,11,0
0,0,9,0,0,0,0,0,0,9,0,0
0,0,0,0,0,0,0,0,0,0,0,0
0,0,10,0,0,0,0,0,0,0,0,0
0,35,19,11,0,0,0,0,35,19,11,0
endlayer

layer
0,0,0,0,0,0,0,0,0,0,0,0
0,0,0,0,0,0,0,0,0,0,0,0
0,36,36,36,36,36,36,36,36,36,36,0
0,0,19,0,0,17,0,0,0,19,0,0
0,0,19,42,41,17,17,17,0,19,0,0
0,0,19,0,0,0,0,17,0,19,0,0
0,0,19,0,0,0,0,0,0,19,0,0
0,0,19,43,0,0,0,0,0,19,0,0
0,0,19,0,0,39,39,0,0,19,0,0
0,0,19,38,0,40,40,0,38,19,0,0
0,0,19,19,19,19,19,19,19,19,0,0
0,23,23,23,23,23,23,23,23,23,23,0
0,37,37,37,37,37,37,37,37,37,37,0
0,37,37,37,37,37,37,37,37,37,37,0
0,37,37,37,37,37,37,37,37,37,37,0
0,37,19,37,37,37,37,37,37,19,37,0
endlayer

layer
0,0,0,0,0,0,0,0,0,0,0,0
0,0,0,0,0,0,0,0,0,0,0,0
0,0,0,0,0,0,0,0,0,0,0,0
0,36,36,36,36,36,36,36,36,36,36,0
0,0,19,0,0,0,0,0,35,19,0,0
0,0,19,0,0,0,0,0,0,19,0,0
0,0,32,0,0,0,0,0,0,32,0,0
0,0,32,0,0,0,0,0,0,32,0,0
0,0,19,0,0,0,0,0,0,19,0,0
0,0,19,11,0,0,0,0,35,19,0,0
0,44,44,44,44,19,19,44,44,44,44,0
0,0,0,0,0,0,0,0,0,0,0,0
0,0,0,0,0,0,0,0,0,0,0,0
0,0,0,0,0,0,0,0,0,0,0,0
0,0,0,0,0,0,0,0,0,0,0,0
0,0,45,0,0,0,0,0,0,45,0,0
endlayer

layer
0,0,0,0,0,0,0,0,0,0,0,0
0,0,0,0,0,0,0,0,0,0,0,0
0,0,0,0,0,0,0,0,0,0,0,0
0,0,0,0,0,0,0,0,0,0,0,0
0,36,36,36,36,36,36,36,36,36,36,0
0,0,19,11,0,0,0,0,0,19,0,0
0,35,19,0,0,0,0,0,0,19,11,0
0,35,19,0,0,0,0,0,0,19,11,0
0,0,19,0,0,0,0,0,0,19,0,0
0,44,44,44,44,6,6,44,44,44,44,0
0,0,0,0,0,19,19,0,0,0,0,0
0,0,0,0,0,0,0,0,0,0,0,0
0,0,0,0,0,0,0,0,0,0,0,0
0,0,0,0,0,0,0,0,0,0,0,0
0,0,0,0,0,0,0,0,0,0,0,0
0,0,0,0,0,0,0,0,0,0,0,0
endlayer

layer
0,0,0,0,0,0,0,0,0,0,0,0
0,0,0,0,0,0,0,0,0,0,0,0
0,0,0,0,0,0,0,0,0,0,0,0
0,0,0,0,0,0,0,0,0,0,0,0
0,0,0,0,0,0,0,0,0,0,0,0
0,46,46,46,46,46,46,46,46,46,46,0
0,36,36,36,36,36,36,36,36,36,36,0
0,44,44,44,44,44,44,44,44,44,44,0
0,46,46,46,46,46,46,46,46,46,46,0
0,0,0,0,0,45,45,0,0,0,0,0
0,0,0,0,0,19,19,0,0,0,0,0
0,0,0,0,0,9,9,0,0,0,0,0
0,0,0,0,0,0,0,0,0,0,0,0
0,0,0,0,0,0,0,0,0,0,0,0
0,0,0,0,0,0,0,0,0,0,0,0
0,0,0,0,0,0,0,0,0,0,0,0
endlayer

layer
0,0,0,0,0,0,0,0,0,0,0,0
0,0,0,0,0,0,0,0,0,0,0,0
0,0,0,0,0,0,0,0,0,0,0,0
0,0,0,0,0,0,0,0,0,0,0,0
0,0,0,0,0,0,0,0,0,0,0,0
0,0,0,0,0,0,0,0,0,0,0,0
0,0,0,0,0,0,0,0,0,0,0,0
0,0,0,0,0,0,0,0,0,0,0,0
0,0,0,0,0,0,0,0,0,0,0,0
0,0,0,0,0,0,0,0,0,0,0,0
0,0,0,0,0,19,19,0,0,0,0,0
0,0,0,0,0,0,0,0,0,0,0,0
0,0,0,0,0,0,0,0,0,0,0,0
0,0,0,0,0,0,0,0,0,0,0,0
0,0,0,0,0,0,0,0,0,0,0,0
0,0,0,0,0,0,0,0,0,0,0,0
endlayer







