# Converted from schematic
# author:MohawkyMagoo

weight=15
embed_into_distance=1
#acceptable_target_blocks=1,2,3,12,13
dimensions=34,26,19
#allowable_overhang=0
max_cut_in=2
#cut_in_buffer=1
max_leveling=2
#leveling_buffer=1
#preserve_water=0
#preserve_lava=0
#preserve_plants=0


rule1=0,100,2
rule2=0,100,12
rule3=0,100,24
rule4=0,100,24-5
rule5=0,100,35-14
rule6=0,100,5
rule7=0,100,37
rule8=0,100,38
rule9=0,100,31-1
rule10=0,100,98
rule11=0,100,98-1
rule12=0,100,54-3
rule13=0,100,85
rule14=0,100,53-2
rule15=0,100,54-4
rule16=0,100,38-5
rule17=0,100,53-2
rule18=0,100,3-5
rule19=0,100,53-2
rule20=0,100,44-2
rule21=0,100,68-3
rule22=0,100,64-6
rule23=0,100,53-2
rule24=0,100,54-2
rule25=0,100,72
rule26=0,100,68-2
rule27=0,100,41
rule28=0,100,64-15
rule29=0,100,102
rule30=0,100,50-5
rule31=0,100,109-2
rule32=0,100,109-3
rule33=0,100,109-1
rule34=0,100,109
rule35=0,100,30
rule36=0,100,44-5


layer
1,1,1,1,1,1,1,1,1,1,1,1,1,1,1,1,1,1,1
1,1,1,1,1,1,1,1,3,1,1,3,1,1,1,1,1,1,1
1,1,1,1,1,1,1,3,3,3,3,3,1,1,1,1,1,1,1
1,1,1,1,1,1,1,3,3,3,3,3,1,1,1,1,1,1,1
1,1,1,1,1,1,1,3,4,4,3,3,2,1,1,1,1,1,1
1,1,1,1,1,1,1,3,4,3,3,3,3,1,1,1,1,1,1
1,1,1,1,1,1,1,3,3,3,3,3,3,1,1,1,1,1,1
3,3,1,1,1,1,3,3,3,5,3,3,2,2,2,2,2,2,2
3,3,3,3,3,3,3,3,3,5,3,3,3,3,3,3,3,3,2
1,3,3,3,3,3,3,3,3,5,3,3,3,3,3,3,3,3,2
1,3,3,3,3,3,3,3,3,5,3,3,3,3,3,3,3,3,2
1,3,3,3,3,3,3,3,3,5,3,3,3,3,3,3,3,3,2
1,3,3,3,3,3,3,3,3,5,3,3,3,3,3,3,3,3,2
1,3,2,2,2,2,2,3,3,5,3,3,2,2,2,2,2,2,2
1,1,1,1,1,1,2,3,3,5,3,3,2,1,1,1,1,1,1
1,1,1,1,1,1,2,3,3,5,3,3,2,1,1,1,1,1,1
1,1,1,1,1,1,2,3,3,5,3,3,2,1,1,1,1,1,1
1,1,1,1,1,1,2,3,3,5,3,3,2,1,1,1,1,1,1
1,1,1,1,1,1,2,3,3,5,3,3,2,1,1,1,1,1,1
1,1,1,1,1,1,2,3,3,5,3,3,2,1,1,1,1,1,1
1,1,1,1,1,1,2,3,3,5,3,3,2,1,1,1,1,1,1
1,1,1,1,1,1,2,3,3,5,3,3,2,1,1,1,1,1,1
1,1,1,1,1,1,2,3,3,5,3,3,2,1,1,1,1,1,1
1,1,1,1,1,1,2,3,3,5,3,3,2,1,1,1,1,1,1
1,1,1,1,1,1,2,3,3,5,3,3,2,1,1,1,1,1,1
1,1,1,1,1,1,2,2,2,6,2,2,2,1,1,1,1,1,1
endlayer

layer
0,0,0,0,0,0,0,0,0,0,0,0,0,0,0,0,0,0,0
0,0,8,0,0,0,10,10,10,11,10,10,10,0,9,0,7,0,7
0,0,0,0,9,0,10,6,6,6,6,6,10,0,9,8,0,0,8
8,0,0,7,9,0,10,5,5,5,5,5,10,0,9,7,0,0,9
9,7,0,9,9,0,11,5,5,5,5,5,11,0,7,9,9,7,9
7,9,9,9,9,0,10,5,5,5,5,5,10,0,9,0,9,9,0
0,0,0,0,0,0,11,6,6,5,6,6,10,0,0,0,0,0,0
10,10,10,11,10,10,10,18,23,0,19,18,10,11,10,11,10,10,10
11,0,0,13,0,0,17,17,20,0,20,17,17,0,0,13,0,0,11
10,0,13,0,13,0,0,0,0,0,0,0,0,0,13,0,13,0,10
11,0,0,0,0,0,0,0,0,0,0,0,0,0,0,0,0,0,11
10,24,0,14,14,14,0,14,14,0,14,14,0,14,14,14,0,12,10
11,24,0,0,15,15,0,0,0,0,0,0,0,15,15,0,0,12,11
10,10,10,11,11,11,10,14,14,0,14,14,10,11,11,11,10,10,10
0,0,0,0,0,0,11,0,0,0,0,0,11,0,0,0,0,0,0
0,9,9,9,9,0,10,14,14,0,14,14,10,0,0,9,9,9,0
9,0,9,0,9,0,11,0,0,0,0,0,11,0,16,0,9,0,0
0,0,9,0,0,0,10,14,14,0,14,14,10,0,0,0,0,0,0
0,0,0,0,0,0,10,0,0,0,0,0,10,0,9,0,9,0,0
0,16,0,9,9,0,11,14,14,0,14,14,11,0,9,9,0,0,0
0,0,0,0,9,0,10,0,0,0,21,0,10,0,9,0,0,0,0
0,0,0,0,9,0,10,14,14,0,0,14,10,0,0,0,0,0,0
0,0,0,0,0,0,11,0,0,0,0,6,11,0,16,0,0,0,0
0,0,0,0,0,0,10,14,14,0,0,0,10,0,0,0,0,0,0
0,0,0,0,16,0,10,0,0,0,0,0,10,0,16,0,0,0,0
0,0,0,0,0,0,10,10,10,22,10,10,10,0,0,0,0,0,0
endlayer

layer
0,0,0,0,0,0,0,0,0,0,0,0,0,0,0,0,0,0,0
0,0,0,0,0,0,10,10,10,10,10,10,10,0,0,0,0,0,0
0,0,0,0,0,0,10,0,0,0,0,0,10,0,0,0,0,0,0
0,0,0,0,0,0,10,0,0,26,0,0,10,0,0,0,0,0,0
0,0,0,0,0,0,10,0,1,27,1,0,10,0,0,0,0,0,0
0,0,0,0,0,0,10,0,0,0,0,0,10,0,0,0,0,0,0
0,0,0,0,0,0,10,0,13,0,13,0,10,0,0,0,0,0,0
10,10,10,10,10,10,10,16,0,0,0,16,10,10,10,10,10,10,10
10,0,0,25,0,0,0,0,0,0,0,0,0,0,0,25,0,0,10
10,0,13,0,13,0,0,0,0,0,0,0,0,0,13,0,13,0,10
10,0,0,0,0,0,0,0,0,0,0,0,0,0,0,0,0,0,10
10,0,0,0,0,0,0,0,0,0,0,0,0,0,0,0,0,0,10
10,0,0,0,0,0,0,0,0,0,0,0,0,0,0,0,0,0,10
10,10,10,10,10,10,10,0,0,0,0,0,10,10,10,10,10,10,10
0,0,0,0,0,0,10,0,0,0,0,0,10,0,0,0,0,0,0
0,0,0,0,0,0,10,0,0,0,0,0,10,0,0,0,0,0,0
0,0,0,0,0,0,10,0,0,0,0,0,10,0,0,0,0,0,0
0,0,0,0,0,0,10,0,0,0,0,0,10,0,0,0,0,0,0
0,0,0,0,0,0,10,0,0,0,0,0,10,0,0,0,0,0,0
0,0,0,0,0,0,10,0,0,0,0,0,10,0,0,0,0,0,0
0,0,0,0,0,0,10,0,0,0,0,0,10,0,0,0,0,0,0
0,0,0,0,0,0,10,0,0,0,0,0,10,0,0,0,0,0,0
0,0,0,0,0,0,10,0,0,0,0,14,10,0,0,0,0,0,0
0,0,0,0,0,0,10,0,0,0,0,6,10,0,0,0,0,0,0
0,0,0,0,0,0,10,0,0,0,0,0,10,0,0,0,0,0,0
0,0,0,0,0,0,10,10,10,28,10,10,10,0,0,0,0,0,0
endlayer

layer
0,0,0,0,0,0,0,0,0,0,0,0,0,0,0,0,0,0,0
0,0,0,0,0,0,10,10,10,10,10,10,10,0,0,0,0,0,0
0,0,0,0,0,0,10,0,0,0,0,0,10,0,0,0,0,0,0
0,0,0,0,0,0,10,0,0,0,0,0,10,0,0,0,0,0,0
0,0,0,0,0,0,29,0,25,25,25,0,29,0,0,0,0,0,0
0,0,0,0,0,0,10,0,0,0,0,0,10,0,0,0,0,0,0
0,0,0,0,0,0,10,0,30,0,30,0,10,0,0,0,0,0,0
10,10,10,29,10,10,10,0,0,0,0,0,10,10,10,29,10,10,10
29,0,0,0,0,0,0,0,0,0,0,0,0,21,0,0,0,0,29
10,0,13,0,30,0,0,0,0,0,0,0,0,0,30,0,13,0,10
29,0,0,0,0,0,0,0,0,0,0,0,0,0,0,0,0,0,29
10,0,0,0,0,0,0,0,0,0,0,0,0,0,0,0,0,0,10
29,0,0,0,0,0,0,0,0,0,0,0,0,0,0,0,0,0,29
10,10,10,29,10,10,10,0,0,0,0,0,10,10,10,29,10,10,10
0,0,0,0,0,0,10,0,0,0,0,0,10,0,0,0,0,0,0
0,0,0,0,0,0,10,0,0,0,0,0,10,0,0,0,0,0,0
0,0,0,0,0,0,29,0,0,0,0,0,29,0,0,0,0,0,0
0,0,0,0,0,0,10,0,0,0,0,0,10,0,0,0,0,0,0
0,0,0,0,0,0,10,0,0,0,0,0,10,0,0,0,0,0,0
0,0,0,0,0,0,29,0,0,0,0,0,29,0,0,0,0,0,0
0,0,0,0,0,0,10,0,0,0,0,0,10,0,0,0,0,0,0
0,0,0,0,0,0,10,0,0,0,0,0,10,0,0,0,0,0,0
0,0,0,0,0,0,29,0,0,0,0,0,29,0,0,0,0,0,0
0,0,0,0,0,0,10,0,0,0,0,14,10,0,0,0,0,0,0
0,0,0,0,0,0,10,0,0,0,0,6,10,0,0,0,0,0,0
0,0,0,0,0,0,10,10,10,10,10,10,10,0,0,0,0,0,0
endlayer

layer
0,0,0,0,0,0,0,0,0,0,0,0,0,0,0,0,0,0,0
0,0,0,0,0,0,10,10,10,29,10,10,10,0,0,0,0,0,0
0,0,0,0,0,0,10,0,0,0,0,0,10,0,0,0,0,0,0
0,0,0,0,0,0,10,0,0,0,0,0,10,0,0,0,0,0,0
0,0,0,0,0,0,29,0,0,0,0,0,29,0,0,0,0,0,0
0,0,0,0,0,0,10,0,0,0,0,0,10,0,0,0,0,0,0
0,0,0,0,0,0,10,0,0,0,0,0,10,0,0,0,0,0,0
10,10,10,29,10,10,10,0,0,0,0,0,10,10,10,29,10,10,10
29,0,0,0,0,0,13,0,0,0,0,0,13,0,0,0,0,0,29
10,0,30,0,0,0,0,0,0,0,0,0,0,0,0,0,30,0,10
29,0,0,0,0,0,0,0,0,0,0,0,0,0,0,0,0,0,29
10,0,0,0,0,0,0,0,0,0,0,0,0,0,0,0,0,0,10
29,0,0,0,0,0,0,0,0,0,0,0,0,0,0,0,0,0,29
10,10,10,29,10,10,10,0,0,0,0,0,10,10,10,29,10,10,10
0,0,0,0,0,0,10,0,0,0,0,0,10,0,0,0,0,0,0
0,0,0,0,0,0,10,0,0,0,0,0,10,0,0,0,0,0,0
0,0,0,0,0,0,29,0,0,0,0,0,29,0,0,0,0,0,0
0,0,0,0,0,0,10,0,0,0,0,0,10,0,0,0,0,0,0
0,0,0,0,0,0,10,13,0,0,0,13,10,0,0,0,0,0,0
0,0,0,0,0,0,29,0,0,0,0,0,29,0,0,0,0,0,0
0,0,0,0,0,0,10,0,0,0,0,0,10,0,0,0,0,0,0
0,0,0,0,0,0,10,0,0,0,0,0,10,0,0,0,0,0,0
0,0,0,0,0,0,29,0,0,0,0,0,29,0,0,0,0,0,0
0,0,0,0,0,0,10,6,6,6,6,0,10,0,0,0,0,0,0
0,0,0,0,0,0,10,20,20,20,20,20,10,0,0,0,0,0,0
0,0,0,0,0,0,10,10,10,10,10,10,10,0,0,0,0,0,0
endlayer

layer
0,0,0,0,0,0,0,0,0,0,0,0,0,0,0,0,0,0,0
0,0,0,0,0,0,10,10,10,29,10,10,10,0,0,0,0,0,0
0,0,0,0,0,0,10,0,0,0,0,0,10,0,0,0,0,0,0
0,0,0,0,0,0,10,0,0,0,0,0,10,0,0,0,0,0,0
0,0,0,0,0,0,10,0,0,0,0,0,10,0,0,0,0,0,0
0,0,0,0,0,0,10,0,0,0,0,0,10,0,0,0,0,0,0
0,0,0,0,0,0,10,0,0,0,0,0,10,0,0,0,0,0,0
10,10,10,10,10,10,10,0,0,0,0,0,10,10,10,10,10,10,10
29,0,0,0,0,0,30,0,0,0,0,0,30,0,0,0,0,0,29
10,0,0,0,0,0,0,0,0,0,0,0,0,0,0,0,0,0,10
29,0,0,0,0,0,0,0,0,0,0,0,0,0,0,0,0,0,29
10,0,0,0,0,0,0,0,0,0,0,0,0,0,0,0,0,0,10
29,0,0,0,0,0,0,0,0,0,0,0,0,0,0,0,0,0,29
10,10,10,10,10,10,10,0,0,0,0,0,10,10,10,10,10,10,10
0,0,0,0,0,0,10,0,0,0,0,0,10,0,0,0,0,0,0
0,0,0,0,0,0,10,0,0,0,0,0,10,0,0,0,0,0,0
0,0,0,0,0,0,10,0,0,0,0,0,10,0,0,0,0,0,0
0,0,0,0,0,0,10,0,0,0,0,0,10,0,0,0,0,0,0
0,0,0,0,0,0,10,30,0,0,0,30,10,0,0,0,0,0,0
0,0,0,0,0,0,10,0,0,0,0,0,10,0,0,0,0,0,0
0,0,0,0,0,0,10,0,0,0,0,0,10,0,0,0,0,0,0
0,0,0,0,0,0,10,0,0,0,0,0,10,0,0,0,0,0,0
0,0,0,0,0,0,10,0,0,0,0,0,10,0,0,0,0,0,0
0,0,0,0,0,0,10,13,13,13,13,0,10,0,0,0,0,0,0
0,0,0,0,0,0,10,0,0,0,0,0,10,0,0,0,0,0,0
0,0,0,0,0,0,10,10,10,10,10,10,10,0,0,0,0,0,0
endlayer

layer
0,0,0,0,0,0,0,0,0,0,0,0,0,0,0,0,0,0,0
0,0,0,0,0,0,10,10,29,29,29,10,10,0,0,0,0,0,0
0,0,0,0,0,0,34,0,0,0,0,0,33,0,0,0,0,0,0
0,0,0,0,0,0,34,0,0,0,0,0,33,0,0,0,0,0,0
0,0,0,0,0,0,34,0,0,0,0,0,33,0,0,0,0,0,0
0,0,0,0,0,0,34,0,0,0,0,0,33,0,0,0,0,0,0
0,0,0,0,0,0,10,0,0,0,0,0,10,0,0,0,0,0,0
10,31,31,31,31,10,10,0,0,0,0,0,10,10,31,31,31,31,10
10,0,0,0,0,0,0,0,0,13,0,0,0,0,0,0,0,0,10
10,0,0,0,0,0,0,0,0,13,0,0,0,0,0,0,0,0,10
29,0,0,0,0,0,0,13,13,13,13,13,0,0,0,0,0,0,29
10,0,0,0,0,0,0,0,0,13,0,0,0,0,0,0,0,0,10
10,0,0,0,0,0,0,0,0,13,0,0,0,0,0,0,0,0,10
10,32,32,32,32,10,10,0,0,0,0,0,10,10,32,32,32,32,10
0,0,0,0,0,0,10,0,0,0,0,0,10,0,0,0,0,0,0
0,0,0,0,0,0,34,0,0,0,0,0,33,0,0,0,0,0,0
0,0,0,0,0,0,34,0,0,0,0,0,33,0,0,0,0,0,0
0,0,0,0,0,0,34,0,0,0,0,0,33,0,0,0,0,0,0
0,0,0,0,0,0,34,0,0,0,0,0,33,0,0,0,0,0,0
0,0,0,0,0,0,34,0,0,0,0,0,33,0,0,0,0,0,0
0,0,0,0,0,0,34,0,0,0,0,0,33,0,0,0,0,0,0
0,0,0,0,0,0,34,0,0,0,0,0,33,0,0,0,0,0,0
0,0,0,0,0,0,34,0,0,0,0,0,33,0,0,0,0,0,0
0,0,0,0,0,0,34,0,0,0,0,0,33,0,0,0,0,0,0
0,0,0,0,0,0,34,0,0,0,0,0,33,0,0,0,0,0,0
0,0,0,0,0,0,10,10,10,29,10,10,10,0,0,0,0,0,0
endlayer

layer
0,0,0,0,0,0,0,0,0,0,0,0,0,0,0,0,0,0,0
0,0,0,0,0,0,0,10,10,29,10,10,0,0,0,0,0,0,0
0,0,0,0,0,0,0,10,0,0,0,10,0,0,0,0,0,0,0
0,0,0,0,0,0,0,10,0,0,0,10,0,0,0,0,0,0,0
0,0,0,0,0,0,0,10,0,0,0,10,0,0,0,0,0,0,0
0,0,0,0,0,0,0,10,0,0,0,10,0,0,0,0,0,0,0
0,0,0,0,0,0,0,10,0,0,0,10,0,0,0,0,0,0,0
0,0,0,0,0,0,10,10,0,0,0,10,10,0,0,0,0,0,0
10,10,10,10,10,10,10,0,0,30,0,0,10,10,10,10,10,10,10
10,0,0,0,0,0,0,0,0,30,0,0,0,0,0,0,0,0,10
29,0,0,0,0,0,0,30,30,13,30,30,0,0,0,0,0,0,29
10,0,0,0,0,0,0,0,0,30,0,0,0,0,0,0,0,0,10
10,10,10,10,10,10,10,0,0,30,0,0,10,10,10,10,10,10,10
0,0,0,0,0,0,10,10,0,0,0,10,10,0,0,0,0,0,0
0,0,0,0,0,0,0,10,0,0,0,10,0,0,0,0,0,0,0
0,0,0,0,0,0,0,10,0,0,0,10,0,0,0,0,0,0,0
0,0,0,0,0,0,0,10,0,0,0,10,0,0,0,0,0,0,0
0,0,0,0,0,0,0,10,0,0,0,10,0,0,0,0,0,0,0
0,0,0,0,0,0,0,10,0,0,0,10,0,0,0,0,0,0,0
0,0,0,0,0,0,0,10,0,0,0,10,0,0,0,0,0,0,0
0,0,0,0,0,0,0,10,0,0,0,10,0,0,0,0,0,0,0
0,0,0,0,0,0,0,10,0,0,0,10,0,0,0,0,0,0,0
0,0,0,0,0,0,0,10,0,0,0,10,0,0,0,0,0,0,0
0,0,0,0,0,0,0,10,0,0,0,10,0,0,0,0,0,0,0
0,0,0,0,0,0,0,10,0,0,0,10,0,0,0,0,0,0,0
0,0,0,0,0,0,0,10,29,29,29,10,0,0,0,0,0,0,0
endlayer

layer
0,0,0,0,0,0,0,0,0,0,0,0,0,0,0,0,0,0,0
0,0,0,0,0,0,0,10,10,10,10,10,0,0,0,0,0,0,0
0,0,0,0,0,0,0,34,0,0,0,33,0,0,0,0,0,0,0
0,0,0,0,0,0,0,34,0,0,0,33,0,0,0,0,0,0,0
0,0,0,0,0,0,0,34,0,0,0,33,0,0,0,0,0,0,0
0,0,0,0,0,0,0,34,0,0,0,33,0,0,0,0,0,0,0
0,0,0,0,0,0,0,34,0,0,0,33,0,0,0,0,0,0,0
0,0,0,0,0,0,10,10,0,0,0,10,10,0,0,0,0,0,0
10,31,31,31,31,31,10,0,0,0,0,0,10,31,31,31,31,31,10
10,0,0,0,0,0,0,0,0,13,0,0,0,0,0,0,0,0,10
10,0,0,0,0,0,0,0,13,13,13,0,0,0,0,0,0,0,10
10,0,0,0,0,0,0,0,0,13,0,0,0,0,0,0,0,0,10
10,32,32,32,32,32,10,0,0,0,0,0,10,32,32,32,32,32,10
0,0,0,0,0,0,10,10,0,0,0,10,10,0,0,0,0,0,0
0,0,0,0,0,0,0,34,0,0,0,33,0,0,0,0,0,0,0
0,0,0,0,0,0,0,34,0,0,0,33,0,0,0,0,0,0,0
0,0,0,0,0,0,0,34,0,0,0,33,0,0,0,0,0,0,0
0,0,0,0,0,0,0,34,0,0,0,33,0,0,0,0,0,0,0
0,0,0,0,0,0,0,34,0,0,0,33,0,0,0,0,0,0,0
0,0,0,0,0,0,0,34,0,0,0,33,0,0,0,0,0,0,0
0,0,0,0,0,0,0,34,0,0,0,33,0,0,0,0,0,0,0
0,0,0,0,0,0,0,34,0,0,0,33,0,0,0,0,0,0,0
0,0,0,0,0,0,0,34,0,0,0,33,0,0,0,0,0,0,0
0,0,0,0,0,0,0,34,0,0,0,33,0,0,0,0,0,0,0
0,0,0,0,0,0,0,34,0,0,0,33,0,0,0,0,0,0,0
0,0,0,0,0,0,0,10,10,29,10,10,0,0,0,0,0,0,0
endlayer

layer
0,0,0,0,0,0,0,0,0,0,0,0,0,0,0,0,0,0,0
0,0,0,0,0,0,0,0,10,10,10,0,0,0,0,0,0,0,0
0,0,0,0,0,0,0,0,34,0,33,0,0,0,0,0,0,0,0
0,0,0,0,0,0,0,0,34,0,33,0,0,0,0,0,0,0,0
0,0,0,0,0,0,0,0,34,0,33,0,0,0,0,0,0,0,0
0,0,0,0,0,0,0,0,34,0,33,0,0,0,0,0,0,0,0
0,0,0,0,0,0,0,0,34,0,33,0,0,0,0,0,0,0,0
0,0,0,0,0,0,10,10,10,0,10,10,10,0,0,0,0,0,0
0,0,0,0,0,0,10,0,0,0,0,0,10,0,0,0,0,0,0
10,31,31,31,31,31,10,0,0,30,0,0,10,31,31,31,31,31,10
10,35,0,0,0,0,0,0,30,13,30,0,0,0,0,0,0,0,10
10,32,32,32,32,32,10,0,0,30,0,0,10,32,32,32,32,32,10
0,0,0,0,0,0,10,0,0,0,0,0,10,0,0,0,0,0,0
0,0,0,0,0,0,10,10,10,0,10,10,10,0,0,0,0,0,0
0,0,0,0,0,0,0,0,34,0,33,0,0,0,0,0,0,0,0
0,0,0,0,0,0,0,0,34,0,33,0,0,0,0,0,0,0,0
0,0,0,0,0,0,0,0,34,0,33,0,0,0,0,0,0,0,0
0,0,0,0,0,0,0,0,34,0,33,0,0,0,0,0,0,0,0
0,0,0,0,0,0,0,0,34,0,33,0,0,0,0,0,0,0,0
0,0,0,0,0,0,0,0,34,0,33,0,0,0,0,0,0,0,0
0,0,0,0,0,0,0,0,34,0,33,0,0,0,0,0,0,0,0
0,0,0,0,0,0,0,0,34,0,33,0,0,0,0,0,0,0,0
0,0,0,0,0,0,0,0,34,0,33,0,0,0,0,0,0,0,0
0,0,0,0,0,0,0,0,34,0,33,0,0,0,0,0,0,0,0
0,0,0,0,0,0,0,0,34,0,33,0,0,0,0,0,0,0,0
0,0,0,0,0,0,0,0,10,10,10,0,0,0,0,0,0,0,0
endlayer

layer
0,0,0,0,0,0,0,0,0,0,0,0,0,0,0,0,0,0,0
0,0,0,0,0,0,0,0,0,10,0,0,0,0,0,0,0,0,0
0,0,0,0,0,0,0,0,0,10,0,0,0,0,0,0,0,0,0
0,0,0,0,0,0,0,0,0,10,0,0,0,0,0,0,0,0,0
0,0,0,0,0,0,0,0,0,10,0,0,0,0,0,0,0,0,0
0,0,0,0,0,0,0,0,0,10,0,0,0,0,0,0,0,0,0
0,0,0,0,0,0,0,0,0,10,0,0,0,0,0,0,0,0,0
0,0,0,0,0,0,10,10,10,10,10,10,10,0,0,0,0,0,0
0,0,0,0,0,0,10,0,0,0,0,0,10,0,0,0,0,0,0
0,0,0,0,0,0,10,0,0,0,0,0,10,0,0,0,0,0,0
10,10,10,10,10,10,10,0,0,13,0,0,10,10,10,10,10,10,10
0,0,0,0,0,0,10,0,0,0,0,0,10,0,0,0,0,0,0
0,0,0,0,0,0,10,0,0,0,0,0,10,0,0,0,0,0,0
0,0,0,0,0,0,10,10,10,10,10,10,10,0,0,0,0,0,0
0,0,0,0,0,0,0,0,0,10,0,0,0,0,0,0,0,0,0
0,0,0,0,0,0,0,0,0,10,0,0,0,0,0,0,0,0,0
0,0,0,0,0,0,0,0,0,10,0,0,0,0,0,0,0,0,0
0,0,0,0,0,0,0,0,0,10,0,0,0,0,0,0,0,0,0
0,0,0,0,0,0,0,0,0,10,0,0,0,0,0,0,0,0,0
0,0,0,0,0,0,0,0,0,10,0,0,0,0,0,0,0,0,0
0,0,0,0,0,0,0,0,0,10,0,0,0,0,0,0,0,0,0
0,0,0,0,0,0,0,0,0,10,0,0,0,0,0,0,0,0,0
0,0,0,0,0,0,0,0,0,10,0,0,0,0,0,0,0,0,0
0,0,0,0,0,0,0,0,0,10,0,0,0,0,0,0,0,0,0
0,0,0,0,0,0,0,0,0,10,0,0,0,0,0,0,0,0,0
0,0,0,0,0,0,0,0,0,10,0,0,0,0,0,0,0,0,0
endlayer

layer
0,0,0,0,0,0,0,0,0,0,0,0,0,0,0,0,0,0,0
0,0,0,0,0,0,0,0,0,32,0,0,0,0,0,0,0,0,0
0,0,0,0,0,0,0,0,0,0,0,0,0,0,0,0,0,0,0
0,0,0,0,0,0,0,0,0,0,0,0,0,0,0,0,0,0,0
0,0,0,0,0,0,0,0,0,0,0,0,0,0,0,0,0,0,0
0,0,0,0,0,0,0,0,0,0,0,0,0,0,0,0,0,0,0
0,0,0,0,0,0,0,0,0,31,0,0,0,0,0,0,0,0,0
0,0,0,0,0,0,10,10,10,10,10,10,10,0,0,0,0,0,0
0,0,0,0,0,0,10,0,0,0,0,0,10,0,0,0,0,0,0
0,0,0,0,0,0,10,0,0,0,0,0,10,0,0,0,0,0,0
33,0,0,0,0,34,10,0,0,13,0,0,10,33,0,0,0,0,34
0,0,0,0,0,0,10,0,0,0,0,0,10,0,0,0,0,0,0
0,0,0,0,0,0,10,0,0,0,0,0,10,0,0,0,0,0,0
0,0,0,0,0,0,10,10,10,10,10,10,10,0,0,0,0,0,0
0,0,0,0,0,0,0,0,0,32,0,0,0,0,0,0,0,0,0
0,0,0,0,0,0,0,0,0,0,0,0,0,0,0,0,0,0,0
0,0,0,0,0,0,0,0,0,0,0,0,0,0,0,0,0,0,0
0,0,0,0,0,0,0,0,0,0,0,0,0,0,0,0,0,0,0
0,0,0,0,0,0,0,0,0,0,0,0,0,0,0,0,0,0,0
0,0,0,0,0,0,0,0,0,0,0,0,0,0,0,0,0,0,0
0,0,0,0,0,0,0,0,0,0,0,0,0,0,0,0,0,0,0
0,0,0,0,0,0,0,0,0,0,0,0,0,0,0,0,0,0,0
0,0,0,0,0,0,0,0,0,0,0,0,0,0,0,0,0,0,0
0,0,0,0,0,0,0,0,0,0,0,0,0,0,0,0,0,0,0
0,0,0,0,0,0,0,0,0,0,0,0,0,0,0,0,0,0,0
0,0,0,0,0,0,0,0,0,31,0,0,0,0,0,0,0,0,0
endlayer

layer
0,0,0,0,0,0,0,0,0,0,0,0,0,0,0,0,0,0,0
0,0,0,0,0,0,0,0,0,0,0,0,0,0,0,0,0,0,0
0,0,0,0,0,0,0,0,0,0,0,0,0,0,0,0,0,0,0
0,0,0,0,0,0,0,0,0,0,0,0,0,0,0,0,0,0,0
0,0,0,0,0,0,0,0,0,0,0,0,0,0,0,0,0,0,0
0,0,0,0,0,0,0,0,0,0,0,0,0,0,0,0,0,0,0
0,0,0,0,0,0,0,0,0,0,0,0,0,0,0,0,0,0,0
0,0,0,0,0,0,10,10,10,10,10,10,10,0,0,0,0,0,0
0,0,0,0,0,0,10,0,0,0,0,0,10,0,0,0,0,0,0
0,0,0,0,0,0,10,0,0,0,0,0,10,0,0,0,0,0,0
0,0,0,0,0,0,10,0,0,13,0,0,10,0,0,0,0,0,0
0,0,0,0,0,0,10,0,0,0,0,0,10,0,0,0,0,0,0
0,0,0,0,0,0,10,0,0,0,0,0,10,0,0,0,0,0,0
0,0,0,0,0,0,10,10,10,10,10,10,10,0,0,0,0,0,0
0,0,0,0,0,0,0,0,0,0,0,0,0,0,0,0,0,0,0
0,0,0,0,0,0,0,0,0,0,0,0,0,0,0,0,0,0,0
0,0,0,0,0,0,0,0,0,0,0,0,0,0,0,0,0,0,0
0,0,0,0,0,0,0,0,0,0,0,0,0,0,0,0,0,0,0
0,0,0,0,0,0,0,0,0,0,0,0,0,0,0,0,0,0,0
0,0,0,0,0,0,0,0,0,0,0,0,0,0,0,0,0,0,0
0,0,0,0,0,0,0,0,0,0,0,0,0,0,0,0,0,0,0
0,0,0,0,0,0,0,0,0,0,0,0,0,0,0,0,0,0,0
0,0,0,0,0,0,0,0,0,0,0,0,0,0,0,0,0,0,0
0,0,0,0,0,0,0,0,0,0,0,0,0,0,0,0,0,0,0
0,0,0,0,0,0,0,0,0,0,0,0,0,0,0,0,0,0,0
0,0,0,0,0,0,0,0,0,0,0,0,0,0,0,0,0,0,0
endlayer

layer
0,0,0,0,0,0,0,0,0,0,0,0,0,0,0,0,0,0,0
0,0,0,0,0,0,0,0,0,0,0,0,0,0,0,0,0,0,0
0,0,0,0,0,0,0,0,0,0,0,0,0,0,0,0,0,0,0
0,0,0,0,0,0,0,0,0,0,0,0,0,0,0,0,0,0,0
0,0,0,0,0,0,0,0,0,0,0,0,0,0,0,0,0,0,0
0,0,0,0,0,0,0,0,0,0,0,0,0,0,0,0,0,0,0
0,0,0,0,0,0,0,0,0,0,0,0,0,0,0,0,0,0,0
0,0,0,0,0,0,10,10,10,10,10,10,10,0,0,0,0,0,0
0,0,0,0,0,0,10,0,0,0,0,0,10,0,0,0,0,0,0
0,0,0,0,0,0,10,0,0,0,0,0,10,0,0,0,0,0,0
0,0,0,0,0,0,10,0,0,13,0,0,10,0,0,0,0,0,0
0,0,0,0,0,0,10,0,0,0,0,0,10,0,0,0,0,0,0
0,0,0,0,0,0,10,0,0,0,0,0,10,0,0,0,0,0,0
0,0,0,0,0,0,10,10,10,10,10,10,10,0,0,0,0,0,0
0,0,0,0,0,0,0,0,0,0,0,0,0,0,0,0,0,0,0
0,0,0,0,0,0,0,0,0,0,0,0,0,0,0,0,0,0,0
0,0,0,0,0,0,0,0,0,0,0,0,0,0,0,0,0,0,0
0,0,0,0,0,0,0,0,0,0,0,0,0,0,0,0,0,0,0
0,0,0,0,0,0,0,0,0,0,0,0,0,0,0,0,0,0,0
0,0,0,0,0,0,0,0,0,0,0,0,0,0,0,0,0,0,0
0,0,0,0,0,0,0,0,0,0,0,0,0,0,0,0,0,0,0
0,0,0,0,0,0,0,0,0,0,0,0,0,0,0,0,0,0,0
0,0,0,0,0,0,0,0,0,0,0,0,0,0,0,0,0,0,0
0,0,0,0,0,0,0,0,0,0,0,0,0,0,0,0,0,0,0
0,0,0,0,0,0,0,0,0,0,0,0,0,0,0,0,0,0,0
0,0,0,0,0,0,0,0,0,0,0,0,0,0,0,0,0,0,0
endlayer

layer
0,0,0,0,0,0,0,0,0,0,0,0,0,0,0,0,0,0,0
0,0,0,0,0,0,0,0,0,0,0,0,0,0,0,0,0,0,0
0,0,0,0,0,0,0,0,0,0,0,0,0,0,0,0,0,0,0
0,0,0,0,0,0,0,0,0,0,0,0,0,0,0,0,0,0,0
0,0,0,0,0,0,0,0,0,0,0,0,0,0,0,0,0,0,0
0,0,0,0,0,0,0,0,0,0,0,0,0,0,0,0,0,0,0
0,0,0,0,0,0,0,0,0,0,0,0,0,0,0,0,0,0,0
0,0,0,0,0,0,10,10,10,10,10,10,10,0,0,0,0,0,0
0,0,0,0,0,0,10,0,0,0,0,35,10,0,0,0,0,0,0
0,0,0,0,0,0,10,0,0,0,0,0,10,0,0,0,0,0,0
0,0,0,0,0,0,10,0,0,13,0,0,10,0,0,0,0,0,0
0,0,0,0,0,0,10,0,0,0,0,0,10,0,0,0,0,0,0
0,0,0,0,0,0,10,0,0,0,0,0,10,0,0,0,0,0,0
0,0,0,0,0,0,10,10,10,10,10,10,10,0,0,0,0,0,0
0,0,0,0,0,0,0,0,0,0,0,0,0,0,0,0,0,0,0
0,0,0,0,0,0,0,0,0,0,0,0,0,0,0,0,0,0,0
0,0,0,0,0,0,0,0,0,0,0,0,0,0,0,0,0,0,0
0,0,0,0,0,0,0,0,0,0,0,0,0,0,0,0,0,0,0
0,0,0,0,0,0,0,0,0,0,0,0,0,0,0,0,0,0,0
0,0,0,0,0,0,0,0,0,0,0,0,0,0,0,0,0,0,0
0,0,0,0,0,0,0,0,0,0,0,0,0,0,0,0,0,0,0
0,0,0,0,0,0,0,0,0,0,0,0,0,0,0,0,0,0,0
0,0,0,0,0,0,0,0,0,0,0,0,0,0,0,0,0,0,0
0,0,0,0,0,0,0,0,0,0,0,0,0,0,0,0,0,0,0
0,0,0,0,0,0,0,0,0,0,0,0,0,0,0,0,0,0,0
0,0,0,0,0,0,0,0,0,0,0,0,0,0,0,0,0,0,0
endlayer

layer
0,0,0,0,0,0,0,0,0,0,0,0,0,0,0,0,0,0,0
0,0,0,0,0,0,0,0,0,0,0,0,0,0,0,0,0,0,0
0,0,0,0,0,0,0,0,0,0,0,0,0,0,0,0,0,0,0
0,0,0,0,0,0,0,0,0,0,0,0,0,0,0,0,0,0,0
0,0,0,0,0,0,0,0,0,0,0,0,0,0,0,0,0,0,0
0,0,0,0,0,0,0,0,0,0,0,0,0,0,0,0,0,0,0
0,0,0,0,0,0,0,0,0,0,0,0,0,0,0,0,0,0,0
0,0,0,0,0,0,10,10,10,10,10,10,10,0,0,0,0,0,0
0,0,0,0,0,0,10,20,20,20,20,20,10,0,0,0,0,0,0
0,0,0,0,0,0,10,20,0,0,0,20,10,0,0,0,0,0,0
0,0,0,0,0,0,10,20,0,13,0,20,10,0,0,0,0,0,0
0,0,0,0,0,0,10,20,0,0,0,20,10,0,0,0,0,0,0
0,0,0,0,0,0,10,20,20,20,20,20,10,0,0,0,0,0,0
0,0,0,0,0,0,10,10,10,10,10,10,10,0,0,0,0,0,0
0,0,0,0,0,0,0,0,0,0,0,0,0,0,0,0,0,0,0
0,0,0,0,0,0,0,0,0,0,0,0,0,0,0,0,0,0,0
0,0,0,0,0,0,0,0,0,0,0,0,0,0,0,0,0,0,0
0,0,0,0,0,0,0,0,0,0,0,0,0,0,0,0,0,0,0
0,0,0,0,0,0,0,0,0,0,0,0,0,0,0,0,0,0,0
0,0,0,0,0,0,0,0,0,0,0,0,0,0,0,0,0,0,0
0,0,0,0,0,0,0,0,0,0,0,0,0,0,0,0,0,0,0
0,0,0,0,0,0,0,0,0,0,0,0,0,0,0,0,0,0,0
0,0,0,0,0,0,0,0,0,0,0,0,0,0,0,0,0,0,0
0,0,0,0,0,0,0,0,0,0,0,0,0,0,0,0,0,0,0
0,0,0,0,0,0,0,0,0,0,0,0,0,0,0,0,0,0,0
0,0,0,0,0,0,0,0,0,0,0,0,0,0,0,0,0,0,0
endlayer

layer
0,0,0,0,0,0,0,0,0,0,0,0,0,0,0,0,0,0,0
0,0,0,0,0,0,0,0,0,0,0,0,0,0,0,0,0,0,0
0,0,0,0,0,0,0,0,0,0,0,0,0,0,0,0,0,0,0
0,0,0,0,0,0,0,0,0,0,0,0,0,0,0,0,0,0,0
0,0,0,0,0,0,0,0,0,0,0,0,0,0,0,0,0,0,0
0,0,0,0,0,0,0,0,0,0,0,0,0,0,0,0,0,0,0
0,0,0,0,0,0,0,0,0,0,0,0,0,0,0,0,0,0,0
0,0,0,0,0,0,10,10,10,10,10,10,10,0,0,0,0,0,0
0,0,0,0,0,0,10,0,0,0,0,0,10,0,0,0,0,0,0
0,0,0,0,0,0,10,0,0,0,0,0,10,0,0,0,0,0,0
0,0,0,0,0,0,10,0,0,13,0,0,10,0,0,0,0,0,0
0,0,0,0,0,0,10,0,0,0,0,0,10,0,0,0,0,0,0
0,0,0,0,0,0,10,0,0,0,0,0,10,0,0,0,0,0,0
0,0,0,0,0,0,10,10,10,10,10,10,10,0,0,0,0,0,0
0,0,0,0,0,0,0,0,0,0,0,0,0,0,0,0,0,0,0
0,0,0,0,0,0,0,0,0,0,0,0,0,0,0,0,0,0,0
0,0,0,0,0,0,0,0,0,0,0,0,0,0,0,0,0,0,0
0,0,0,0,0,0,0,0,0,0,0,0,0,0,0,0,0,0,0
0,0,0,0,0,0,0,0,0,0,0,0,0,0,0,0,0,0,0
0,0,0,0,0,0,0,0,0,0,0,0,0,0,0,0,0,0,0
0,0,0,0,0,0,0,0,0,0,0,0,0,0,0,0,0,0,0
0,0,0,0,0,0,0,0,0,0,0,0,0,0,0,0,0,0,0
0,0,0,0,0,0,0,0,0,0,0,0,0,0,0,0,0,0,0
0,0,0,0,0,0,0,0,0,0,0,0,0,0,0,0,0,0,0
0,0,0,0,0,0,0,0,0,0,0,0,0,0,0,0,0,0,0
0,0,0,0,0,0,0,0,0,0,0,0,0,0,0,0,0,0,0
endlayer

layer
0,0,0,0,0,0,0,0,0,0,0,0,0,0,0,0,0,0,0
0,0,0,0,0,0,0,0,0,0,0,0,0,0,0,0,0,0,0
0,0,0,0,0,0,0,0,0,0,0,0,0,0,0,0,0,0,0
0,0,0,0,0,0,0,0,0,0,0,0,0,0,0,0,0,0,0
0,0,0,0,0,0,0,0,0,0,0,0,0,0,0,0,0,0,0
0,0,0,0,0,0,0,0,0,0,0,0,0,0,0,0,0,0,0
0,0,0,0,0,0,0,0,0,0,0,0,0,0,0,0,0,0,0
0,0,0,0,0,0,10,10,10,29,10,10,10,0,0,0,0,0,0
0,0,0,0,0,0,10,0,0,0,0,0,10,0,0,0,0,0,0
0,0,0,0,0,0,10,0,0,0,0,0,10,0,0,0,0,0,0
0,0,0,0,0,0,29,0,0,13,0,0,29,0,0,0,0,0,0
0,0,0,0,0,0,10,0,0,0,0,0,10,0,0,0,0,0,0
0,0,0,0,0,0,10,0,0,0,0,0,10,0,0,0,0,0,0
0,0,0,0,0,0,10,10,10,29,10,10,10,0,0,0,0,0,0
0,0,0,0,0,0,0,0,0,0,0,0,0,0,0,0,0,0,0
0,0,0,0,0,0,0,0,0,0,0,0,0,0,0,0,0,0,0
0,0,0,0,0,0,0,0,0,0,0,0,0,0,0,0,0,0,0
0,0,0,0,0,0,0,0,0,0,0,0,0,0,0,0,0,0,0
0,0,0,0,0,0,0,0,0,0,0,0,0,0,0,0,0,0,0
0,0,0,0,0,0,0,0,0,0,0,0,0,0,0,0,0,0,0
0,0,0,0,0,0,0,0,0,0,0,0,0,0,0,0,0,0,0
0,0,0,0,0,0,0,0,0,0,0,0,0,0,0,0,0,0,0
0,0,0,0,0,0,0,0,0,0,0,0,0,0,0,0,0,0,0
0,0,0,0,0,0,0,0,0,0,0,0,0,0,0,0,0,0,0
0,0,0,0,0,0,0,0,0,0,0,0,0,0,0,0,0,0,0
0,0,0,0,0,0,0,0,0,0,0,0,0,0,0,0,0,0,0
endlayer

layer
0,0,0,0,0,0,0,0,0,0,0,0,0,0,0,0,0,0,0
0,0,0,0,0,0,0,0,0,0,0,0,0,0,0,0,0,0,0
0,0,0,0,0,0,0,0,0,0,0,0,0,0,0,0,0,0,0
0,0,0,0,0,0,0,0,0,0,0,0,0,0,0,0,0,0,0
0,0,0,0,0,0,0,0,0,0,0,0,0,0,0,0,0,0,0
0,0,0,0,0,0,0,0,0,0,0,0,0,0,0,0,0,0,0
0,0,0,0,0,0,0,0,0,0,0,0,0,0,0,0,0,0,0
0,0,0,0,0,0,10,10,10,29,10,10,10,0,0,0,0,0,0
0,0,0,0,0,0,10,0,0,0,0,0,10,0,0,0,0,0,0
0,0,0,0,0,0,10,0,0,0,0,0,10,0,0,0,0,0,0
0,0,0,0,0,0,29,0,0,13,0,0,29,0,0,0,0,0,0
0,0,0,0,0,0,10,0,0,0,0,0,10,0,0,0,0,0,0
0,0,0,0,0,0,10,0,0,0,0,0,10,0,0,0,0,0,0
0,0,0,0,0,0,10,10,10,29,10,10,10,0,0,0,0,0,0
0,0,0,0,0,0,0,0,0,0,0,0,0,0,0,0,0,0,0
0,0,0,0,0,0,0,0,0,0,0,0,0,0,0,0,0,0,0
0,0,0,0,0,0,0,0,0,0,0,0,0,0,0,0,0,0,0
0,0,0,0,0,0,0,0,0,0,0,0,0,0,0,0,0,0,0
0,0,0,0,0,0,0,0,0,0,0,0,0,0,0,0,0,0,0
0,0,0,0,0,0,0,0,0,0,0,0,0,0,0,0,0,0,0
0,0,0,0,0,0,0,0,0,0,0,0,0,0,0,0,0,0,0
0,0,0,0,0,0,0,0,0,0,0,0,0,0,0,0,0,0,0
0,0,0,0,0,0,0,0,0,0,0,0,0,0,0,0,0,0,0
0,0,0,0,0,0,0,0,0,0,0,0,0,0,0,0,0,0,0
0,0,0,0,0,0,0,0,0,0,0,0,0,0,0,0,0,0,0
0,0,0,0,0,0,0,0,0,0,0,0,0,0,0,0,0,0,0
endlayer

layer
0,0,0,0,0,0,0,0,0,0,0,0,0,0,0,0,0,0,0
0,0,0,0,0,0,0,0,0,0,0,0,0,0,0,0,0,0,0
0,0,0,0,0,0,0,0,0,0,0,0,0,0,0,0,0,0,0
0,0,0,0,0,0,0,0,0,0,0,0,0,0,0,0,0,0,0
0,0,0,0,0,0,0,0,0,0,0,0,0,0,0,0,0,0,0
0,0,0,0,0,0,0,0,0,0,0,0,0,0,0,0,0,0,0
0,0,0,0,0,0,0,0,0,0,0,0,0,0,0,0,0,0,0
0,0,0,0,0,0,10,10,10,10,10,10,10,0,0,0,0,0,0
0,0,0,0,0,0,10,0,0,0,0,0,10,0,0,0,0,0,0
0,0,0,0,0,0,10,0,0,0,0,0,10,0,0,0,0,0,0
0,0,0,0,0,0,10,0,0,13,0,0,10,0,0,0,0,0,0
0,0,0,0,0,0,10,0,0,0,0,0,10,0,0,0,0,0,0
0,0,0,0,0,0,10,0,0,0,0,35,10,0,0,0,0,0,0
0,0,0,0,0,0,10,10,10,10,10,10,10,0,0,0,0,0,0
0,0,0,0,0,0,0,0,0,0,0,0,0,0,0,0,0,0,0
0,0,0,0,0,0,0,0,0,0,0,0,0,0,0,0,0,0,0
0,0,0,0,0,0,0,0,0,0,0,0,0,0,0,0,0,0,0
0,0,0,0,0,0,0,0,0,0,0,0,0,0,0,0,0,0,0
0,0,0,0,0,0,0,0,0,0,0,0,0,0,0,0,0,0,0
0,0,0,0,0,0,0,0,0,0,0,0,0,0,0,0,0,0,0
0,0,0,0,0,0,0,0,0,0,0,0,0,0,0,0,0,0,0
0,0,0,0,0,0,0,0,0,0,0,0,0,0,0,0,0,0,0
0,0,0,0,0,0,0,0,0,0,0,0,0,0,0,0,0,0,0
0,0,0,0,0,0,0,0,0,0,0,0,0,0,0,0,0,0,0
0,0,0,0,0,0,0,0,0,0,0,0,0,0,0,0,0,0,0
0,0,0,0,0,0,0,0,0,0,0,0,0,0,0,0,0,0,0
endlayer

layer
0,0,0,0,0,0,0,0,0,0,0,0,0,0,0,0,0,0,0
0,0,0,0,0,0,0,0,0,0,0,0,0,0,0,0,0,0,0
0,0,0,0,0,0,0,0,0,0,0,0,0,0,0,0,0,0,0
0,0,0,0,0,0,0,0,0,0,0,0,0,0,0,0,0,0,0
0,0,0,0,0,0,0,0,0,0,0,0,0,0,0,0,0,0,0
0,0,0,0,0,0,0,0,0,0,0,0,0,0,0,0,0,0,0
0,0,0,0,0,0,0,0,0,0,0,0,0,0,0,0,0,0,0
0,0,0,0,0,0,36,31,31,31,31,31,36,0,0,0,0,0,0
0,0,0,0,0,0,34,10,10,10,10,10,33,0,0,0,0,0,0
0,0,0,0,0,0,34,10,0,0,0,10,33,0,0,0,0,0,0
0,0,0,0,0,0,34,10,0,13,0,10,33,0,0,0,0,0,0
0,0,0,0,0,0,34,10,0,0,0,10,33,0,0,0,0,0,0
0,0,0,0,0,0,34,10,10,10,10,10,33,0,0,0,0,0,0
0,0,0,0,0,0,0,32,32,32,32,32,36,0,0,0,0,0,0
0,0,0,0,0,0,0,0,0,0,0,0,0,0,0,0,0,0,0
0,0,0,0,0,0,0,0,0,0,0,0,0,0,0,0,0,0,0
0,0,0,0,0,0,0,0,0,0,0,0,0,0,0,0,0,0,0
0,0,0,0,0,0,0,0,0,0,0,0,0,0,0,0,0,0,0
0,0,0,0,0,0,0,0,0,0,0,0,0,0,0,0,0,0,0
0,0,0,0,0,0,0,0,0,0,0,0,0,0,0,0,0,0,0
0,0,0,0,0,0,0,0,0,0,0,0,0,0,0,0,0,0,0
0,0,0,0,0,0,0,0,0,0,0,0,0,0,0,0,0,0,0
0,0,0,0,0,0,0,0,0,0,0,0,0,0,0,0,0,0,0
0,0,0,0,0,0,0,0,0,0,0,0,0,0,0,0,0,0,0
0,0,0,0,0,0,0,0,0,0,0,0,0,0,0,0,0,0,0
0,0,0,0,0,0,0,0,0,0,0,0,0,0,0,0,0,0,0
endlayer

layer
0,0,0,0,0,0,0,0,0,0,0,0,0,0,0,0,0,0,0
0,0,0,0,0,0,0,0,0,0,0,0,0,0,0,0,0,0,0
0,0,0,0,0,0,0,0,0,0,0,0,0,0,0,0,0,0,0
0,0,0,0,0,0,0,0,0,0,0,0,0,0,0,0,0,0,0
0,0,0,0,0,0,0,0,0,0,0,0,0,0,0,0,0,0,0
0,0,0,0,0,0,0,0,0,0,0,0,0,0,0,0,0,0,0
0,0,0,0,0,0,0,0,0,0,0,0,0,0,0,0,0,0,0
0,0,0,0,0,0,0,0,0,0,0,0,0,0,0,0,0,0,0
0,0,0,0,0,0,0,10,10,10,10,10,0,0,0,0,0,0,0
0,0,0,0,0,0,0,10,0,0,0,10,0,0,0,0,0,0,0
0,0,0,0,0,0,0,10,0,13,0,10,0,0,0,0,0,0,0
0,0,0,0,0,0,0,10,0,0,0,10,0,0,0,0,0,0,0
0,0,0,0,0,0,0,10,10,10,10,10,0,0,0,0,0,0,0
0,0,0,0,0,0,0,0,0,0,0,0,0,0,0,0,0,0,0
0,0,0,0,0,0,0,0,0,0,0,0,0,0,0,0,0,0,0
0,0,0,0,0,0,0,0,0,0,0,0,0,0,0,0,0,0,0
0,0,0,0,0,0,0,0,0,0,0,0,0,0,0,0,0,0,0
0,0,0,0,0,0,0,0,0,0,0,0,0,0,0,0,0,0,0
0,0,0,0,0,0,0,0,0,0,0,0,0,0,0,0,0,0,0
0,0,0,0,0,0,0,0,0,0,0,0,0,0,0,0,0,0,0
0,0,0,0,0,0,0,0,0,0,0,0,0,0,0,0,0,0,0
0,0,0,0,0,0,0,0,0,0,0,0,0,0,0,0,0,0,0
0,0,0,0,0,0,0,0,0,0,0,0,0,0,0,0,0,0,0
0,0,0,0,0,0,0,0,0,0,0,0,0,0,0,0,0,0,0
0,0,0,0,0,0,0,0,0,0,0,0,0,0,0,0,0,0,0
0,0,0,0,0,0,0,0,0,0,0,0,0,0,0,0,0,0,0
endlayer

layer
0,0,0,0,0,0,0,0,0,0,0,0,0,0,0,0,0,0,0
0,0,0,0,0,0,0,0,0,0,0,0,0,0,0,0,0,0,0
0,0,0,0,0,0,0,0,0,0,0,0,0,0,0,0,0,0,0
0,0,0,0,0,0,0,0,0,0,0,0,0,0,0,0,0,0,0
0,0,0,0,0,0,0,0,0,0,0,0,0,0,0,0,0,0,0
0,0,0,0,0,0,0,0,0,0,0,0,0,0,0,0,0,0,0
0,0,0,0,0,0,0,0,0,0,0,0,0,0,0,0,0,0,0
0,0,0,0,0,0,0,0,0,0,0,0,0,0,0,0,0,0,0
0,0,0,0,0,0,0,10,10,10,10,10,0,0,0,0,0,0,0
0,0,0,0,0,0,0,10,35,0,0,10,0,0,0,0,0,0,0
0,0,0,0,0,0,0,10,0,13,0,10,0,0,0,0,0,0,0
0,0,0,0,0,0,0,10,0,0,0,10,0,0,0,0,0,0,0
0,0,0,0,0,0,0,10,10,10,10,10,0,0,0,0,0,0,0
0,0,0,0,0,0,0,0,0,0,0,0,0,0,0,0,0,0,0
0,0,0,0,0,0,0,0,0,0,0,0,0,0,0,0,0,0,0
0,0,0,0,0,0,0,0,0,0,0,0,0,0,0,0,0,0,0
0,0,0,0,0,0,0,0,0,0,0,0,0,0,0,0,0,0,0
0,0,0,0,0,0,0,0,0,0,0,0,0,0,0,0,0,0,0
0,0,0,0,0,0,0,0,0,0,0,0,0,0,0,0,0,0,0
0,0,0,0,0,0,0,0,0,0,0,0,0,0,0,0,0,0,0
0,0,0,0,0,0,0,0,0,0,0,0,0,0,0,0,0,0,0
0,0,0,0,0,0,0,0,0,0,0,0,0,0,0,0,0,0,0
0,0,0,0,0,0,0,0,0,0,0,0,0,0,0,0,0,0,0
0,0,0,0,0,0,0,0,0,0,0,0,0,0,0,0,0,0,0
0,0,0,0,0,0,0,0,0,0,0,0,0,0,0,0,0,0,0
0,0,0,0,0,0,0,0,0,0,0,0,0,0,0,0,0,0,0
endlayer

layer
0,0,0,0,0,0,0,0,0,0,0,0,0,0,0,0,0,0,0
0,0,0,0,0,0,0,0,0,0,0,0,0,0,0,0,0,0,0
0,0,0,0,0,0,0,0,0,0,0,0,0,0,0,0,0,0,0
0,0,0,0,0,0,0,0,0,0,0,0,0,0,0,0,0,0,0
0,0,0,0,0,0,0,0,0,0,0,0,0,0,0,0,0,0,0
0,0,0,0,0,0,0,0,0,0,0,0,0,0,0,0,0,0,0
0,0,0,0,0,0,0,0,0,0,0,0,0,0,0,0,0,0,0
0,0,0,0,0,0,0,0,0,0,0,0,0,0,0,0,0,0,0
0,0,0,0,0,0,0,36,31,31,31,36,0,0,0,0,0,0,0
0,0,0,0,0,0,0,34,10,10,10,33,0,0,0,0,0,0,0
0,0,0,0,0,0,0,34,10,13,10,33,0,0,0,0,0,0,0
0,0,0,0,0,0,0,34,10,10,10,33,0,0,0,0,0,0,0
0,0,0,0,0,0,0,36,32,32,32,36,0,0,0,0,0,0,0
0,0,0,0,0,0,0,0,0,0,0,0,0,0,0,0,0,0,0
0,0,0,0,0,0,0,0,0,0,0,0,0,0,0,0,0,0,0
0,0,0,0,0,0,0,0,0,0,0,0,0,0,0,0,0,0,0
0,0,0,0,0,0,0,0,0,0,0,0,0,0,0,0,0,0,0
0,0,0,0,0,0,0,0,0,0,0,0,0,0,0,0,0,0,0
0,0,0,0,0,0,0,0,0,0,0,0,0,0,0,0,0,0,0
0,0,0,0,0,0,0,0,0,0,0,0,0,0,0,0,0,0,0
0,0,0,0,0,0,0,0,0,0,0,0,0,0,0,0,0,0,0
0,0,0,0,0,0,0,0,0,0,0,0,0,0,0,0,0,0,0
0,0,0,0,0,0,0,0,0,0,0,0,0,0,0,0,0,0,0
0,0,0,0,0,0,0,0,0,0,0,0,0,0,0,0,0,0,0
0,0,0,0,0,0,0,0,0,0,0,0,0,0,0,0,0,0,0
0,0,0,0,0,0,0,0,0,0,0,0,0,0,0,0,0,0,0
endlayer

layer
0,0,0,0,0,0,0,0,0,0,0,0,0,0,0,0,0,0,0
0,0,0,0,0,0,0,0,0,0,0,0,0,0,0,0,0,0,0
0,0,0,0,0,0,0,0,0,0,0,0,0,0,0,0,0,0,0
0,0,0,0,0,0,0,0,0,0,0,0,0,0,0,0,0,0,0
0,0,0,0,0,0,0,0,0,0,0,0,0,0,0,0,0,0,0
0,0,0,0,0,0,0,0,0,0,0,0,0,0,0,0,0,0,0
0,0,0,0,0,0,0,0,0,0,0,0,0,0,0,0,0,0,0
0,0,0,0,0,0,0,0,0,0,0,0,0,0,0,0,0,0,0
0,0,0,0,0,0,0,0,0,0,0,0,0,0,0,0,0,0,0
0,0,0,0,0,0,0,0,10,10,10,0,0,0,0,0,0,0,0
0,0,0,0,0,0,0,0,10,0,10,0,0,0,0,0,0,0,0
0,0,0,0,0,0,0,0,10,10,10,0,0,0,0,0,0,0,0
0,0,0,0,0,0,0,0,0,0,0,0,0,0,0,0,0,0,0
0,0,0,0,0,0,0,0,0,0,0,0,0,0,0,0,0,0,0
0,0,0,0,0,0,0,0,0,0,0,0,0,0,0,0,0,0,0
0,0,0,0,0,0,0,0,0,0,0,0,0,0,0,0,0,0,0
0,0,0,0,0,0,0,0,0,0,0,0,0,0,0,0,0,0,0
0,0,0,0,0,0,0,0,0,0,0,0,0,0,0,0,0,0,0
0,0,0,0,0,0,0,0,0,0,0,0,0,0,0,0,0,0,0
0,0,0,0,0,0,0,0,0,0,0,0,0,0,0,0,0,0,0
0,0,0,0,0,0,0,0,0,0,0,0,0,0,0,0,0,0,0
0,0,0,0,0,0,0,0,0,0,0,0,0,0,0,0,0,0,0
0,0,0,0,0,0,0,0,0,0,0,0,0,0,0,0,0,0,0
0,0,0,0,0,0,0,0,0,0,0,0,0,0,0,0,0,0,0
0,0,0,0,0,0,0,0,0,0,0,0,0,0,0,0,0,0,0
0,0,0,0,0,0,0,0,0,0,0,0,0,0,0,0,0,0,0
endlayer

layer
0,0,0,0,0,0,0,0,0,0,0,0,0,0,0,0,0,0,0
0,0,0,0,0,0,0,0,0,0,0,0,0,0,0,0,0,0,0
0,0,0,0,0,0,0,0,0,0,0,0,0,0,0,0,0,0,0
0,0,0,0,0,0,0,0,0,0,0,0,0,0,0,0,0,0,0
0,0,0,0,0,0,0,0,0,0,0,0,0,0,0,0,0,0,0
0,0,0,0,0,0,0,0,0,0,0,0,0,0,0,0,0,0,0
0,0,0,0,0,0,0,0,0,0,0,0,0,0,0,0,0,0,0
0,0,0,0,0,0,0,0,0,0,0,0,0,0,0,0,0,0,0
0,0,0,0,0,0,0,0,0,0,0,0,0,0,0,0,0,0,0
0,0,0,0,0,0,0,0,10,10,10,0,0,0,0,0,0,0,0
0,0,0,0,0,0,0,0,10,0,10,0,0,0,0,0,0,0,0
0,0,0,0,0,0,0,0,10,10,10,0,0,0,0,0,0,0,0
0,0,0,0,0,0,0,0,0,0,0,0,0,0,0,0,0,0,0
0,0,0,0,0,0,0,0,0,0,0,0,0,0,0,0,0,0,0
0,0,0,0,0,0,0,0,0,0,0,0,0,0,0,0,0,0,0
0,0,0,0,0,0,0,0,0,0,0,0,0,0,0,0,0,0,0
0,0,0,0,0,0,0,0,0,0,0,0,0,0,0,0,0,0,0
0,0,0,0,0,0,0,0,0,0,0,0,0,0,0,0,0,0,0
0,0,0,0,0,0,0,0,0,0,0,0,0,0,0,0,0,0,0
0,0,0,0,0,0,0,0,0,0,0,0,0,0,0,0,0,0,0
0,0,0,0,0,0,0,0,0,0,0,0,0,0,0,0,0,0,0
0,0,0,0,0,0,0,0,0,0,0,0,0,0,0,0,0,0,0
0,0,0,0,0,0,0,0,0,0,0,0,0,0,0,0,0,0,0
0,0,0,0,0,0,0,0,0,0,0,0,0,0,0,0,0,0,0
0,0,0,0,0,0,0,0,0,0,0,0,0,0,0,0,0,0,0
0,0,0,0,0,0,0,0,0,0,0,0,0,0,0,0,0,0,0
endlayer

layer
0,0,0,0,0,0,0,0,0,0,0,0,0,0,0,0,0,0,0
0,0,0,0,0,0,0,0,0,0,0,0,0,0,0,0,0,0,0
0,0,0,0,0,0,0,0,0,0,0,0,0,0,0,0,0,0,0
0,0,0,0,0,0,0,0,0,0,0,0,0,0,0,0,0,0,0
0,0,0,0,0,0,0,0,0,0,0,0,0,0,0,0,0,0,0
0,0,0,0,0,0,0,0,0,0,0,0,0,0,0,0,0,0,0
0,0,0,0,0,0,0,0,0,0,0,0,0,0,0,0,0,0,0
0,0,0,0,0,0,0,0,0,0,0,0,0,0,0,0,0,0,0
0,0,0,0,0,0,0,0,0,0,0,0,0,0,0,0,0,0,0
0,0,0,0,0,0,0,0,36,31,36,0,0,0,0,0,0,0,0
0,0,0,0,0,0,0,0,34,0,33,0,0,0,0,0,0,0,0
0,0,0,0,0,0,0,0,36,32,36,0,0,0,0,0,0,0,0
0,0,0,0,0,0,0,0,0,0,0,0,0,0,0,0,0,0,0
0,0,0,0,0,0,0,0,0,0,0,0,0,0,0,0,0,0,0
0,0,0,0,0,0,0,0,0,0,0,0,0,0,0,0,0,0,0
0,0,0,0,0,0,0,0,0,0,0,0,0,0,0,0,0,0,0
0,0,0,0,0,0,0,0,0,0,0,0,0,0,0,0,0,0,0
0,0,0,0,0,0,0,0,0,0,0,0,0,0,0,0,0,0,0
0,0,0,0,0,0,0,0,0,0,0,0,0,0,0,0,0,0,0
0,0,0,0,0,0,0,0,0,0,0,0,0,0,0,0,0,0,0
0,0,0,0,0,0,0,0,0,0,0,0,0,0,0,0,0,0,0
0,0,0,0,0,0,0,0,0,0,0,0,0,0,0,0,0,0,0
0,0,0,0,0,0,0,0,0,0,0,0,0,0,0,0,0,0,0
0,0,0,0,0,0,0,0,0,0,0,0,0,0,0,0,0,0,0
0,0,0,0,0,0,0,0,0,0,0,0,0,0,0,0,0,0,0
0,0,0,0,0,0,0,0,0,0,0,0,0,0,0,0,0,0,0
endlayer

layer
0,0,0,0,0,0,0,0,0,0,0,0,0,0,0,0,0,0,0
0,0,0,0,0,0,0,0,0,0,0,0,0,0,0,0,0,0,0
0,0,0,0,0,0,0,0,0,0,0,0,0,0,0,0,0,0,0
0,0,0,0,0,0,0,0,0,0,0,0,0,0,0,0,0,0,0
0,0,0,0,0,0,0,0,0,0,0,0,0,0,0,0,0,0,0
0,0,0,0,0,0,0,0,0,0,0,0,0,0,0,0,0,0,0
0,0,0,0,0,0,0,0,0,0,0,0,0,0,0,0,0,0,0
0,0,0,0,0,0,0,0,0,0,0,0,0,0,0,0,0,0,0
0,0,0,0,0,0,0,0,0,0,0,0,0,0,0,0,0,0,0
0,0,0,0,0,0,0,0,0,0,0,0,0,0,0,0,0,0,0
0,0,0,0,0,0,0,0,0,10,0,0,0,0,0,0,0,0,0
0,0,0,0,0,0,0,0,0,0,0,0,0,0,0,0,0,0,0
0,0,0,0,0,0,0,0,0,0,0,0,0,0,0,0,0,0,0
0,0,0,0,0,0,0,0,0,0,0,0,0,0,0,0,0,0,0
0,0,0,0,0,0,0,0,0,0,0,0,0,0,0,0,0,0,0
0,0,0,0,0,0,0,0,0,0,0,0,0,0,0,0,0,0,0
0,0,0,0,0,0,0,0,0,0,0,0,0,0,0,0,0,0,0
0,0,0,0,0,0,0,0,0,0,0,0,0,0,0,0,0,0,0
0,0,0,0,0,0,0,0,0,0,0,0,0,0,0,0,0,0,0
0,0,0,0,0,0,0,0,0,0,0,0,0,0,0,0,0,0,0
0,0,0,0,0,0,0,0,0,0,0,0,0,0,0,0,0,0,0
0,0,0,0,0,0,0,0,0,0,0,0,0,0,0,0,0,0,0
0,0,0,0,0,0,0,0,0,0,0,0,0,0,0,0,0,0,0
0,0,0,0,0,0,0,0,0,0,0,0,0,0,0,0,0,0,0
0,0,0,0,0,0,0,0,0,0,0,0,0,0,0,0,0,0,0
0,0,0,0,0,0,0,0,0,0,0,0,0,0,0,0,0,0,0
endlayer

layer
0,0,0,0,0,0,0,0,0,0,0,0,0,0,0,0,0,0,0
0,0,0,0,0,0,0,0,0,0,0,0,0,0,0,0,0,0,0
0,0,0,0,0,0,0,0,0,0,0,0,0,0,0,0,0,0,0
0,0,0,0,0,0,0,0,0,0,0,0,0,0,0,0,0,0,0
0,0,0,0,0,0,0,0,0,0,0,0,0,0,0,0,0,0,0
0,0,0,0,0,0,0,0,0,0,0,0,0,0,0,0,0,0,0
0,0,0,0,0,0,0,0,0,0,0,0,0,0,0,0,0,0,0
0,0,0,0,0,0,0,0,0,0,0,0,0,0,0,0,0,0,0
0,0,0,0,0,0,0,0,0,0,0,0,0,0,0,0,0,0,0
0,0,0,0,0,0,0,0,0,0,0,0,0,0,0,0,0,0,0
0,0,0,0,0,0,0,0,0,10,0,0,0,0,0,0,0,0,0
0,0,0,0,0,0,0,0,0,0,0,0,0,0,0,0,0,0,0
0,0,0,0,0,0,0,0,0,0,0,0,0,0,0,0,0,0,0
0,0,0,0,0,0,0,0,0,0,0,0,0,0,0,0,0,0,0
0,0,0,0,0,0,0,0,0,0,0,0,0,0,0,0,0,0,0
0,0,0,0,0,0,0,0,0,0,0,0,0,0,0,0,0,0,0
0,0,0,0,0,0,0,0,0,0,0,0,0,0,0,0,0,0,0
0,0,0,0,0,0,0,0,0,0,0,0,0,0,0,0,0,0,0
0,0,0,0,0,0,0,0,0,0,0,0,0,0,0,0,0,0,0
0,0,0,0,0,0,0,0,0,0,0,0,0,0,0,0,0,0,0
0,0,0,0,0,0,0,0,0,0,0,0,0,0,0,0,0,0,0
0,0,0,0,0,0,0,0,0,0,0,0,0,0,0,0,0,0,0
0,0,0,0,0,0,0,0,0,0,0,0,0,0,0,0,0,0,0
0,0,0,0,0,0,0,0,0,0,0,0,0,0,0,0,0,0,0
0,0,0,0,0,0,0,0,0,0,0,0,0,0,0,0,0,0,0
0,0,0,0,0,0,0,0,0,0,0,0,0,0,0,0,0,0,0
endlayer

layer
0,0,0,0,0,0,0,0,0,0,0,0,0,0,0,0,0,0,0
0,0,0,0,0,0,0,0,0,0,0,0,0,0,0,0,0,0,0
0,0,0,0,0,0,0,0,0,0,0,0,0,0,0,0,0,0,0
0,0,0,0,0,0,0,0,0,0,0,0,0,0,0,0,0,0,0
0,0,0,0,0,0,0,0,0,0,0,0,0,0,0,0,0,0,0
0,0,0,0,0,0,0,0,0,0,0,0,0,0,0,0,0,0,0
0,0,0,0,0,0,0,0,0,0,0,0,0,0,0,0,0,0,0
0,0,0,0,0,0,0,0,0,0,0,0,0,0,0,0,0,0,0
0,0,0,0,0,0,0,0,0,0,0,0,0,0,0,0,0,0,0
0,0,0,0,0,0,0,0,0,0,0,0,0,0,0,0,0,0,0
0,0,0,0,0,0,0,0,0,10,0,0,0,0,0,0,0,0,0
0,0,0,0,0,0,0,0,0,0,0,0,0,0,0,0,0,0,0
0,0,0,0,0,0,0,0,0,0,0,0,0,0,0,0,0,0,0
0,0,0,0,0,0,0,0,0,0,0,0,0,0,0,0,0,0,0
0,0,0,0,0,0,0,0,0,0,0,0,0,0,0,0,0,0,0
0,0,0,0,0,0,0,0,0,0,0,0,0,0,0,0,0,0,0
0,0,0,0,0,0,0,0,0,0,0,0,0,0,0,0,0,0,0
0,0,0,0,0,0,0,0,0,0,0,0,0,0,0,0,0,0,0
0,0,0,0,0,0,0,0,0,0,0,0,0,0,0,0,0,0,0
0,0,0,0,0,0,0,0,0,0,0,0,0,0,0,0,0,0,0
0,0,0,0,0,0,0,0,0,0,0,0,0,0,0,0,0,0,0
0,0,0,0,0,0,0,0,0,0,0,0,0,0,0,0,0,0,0
0,0,0,0,0,0,0,0,0,0,0,0,0,0,0,0,0,0,0
0,0,0,0,0,0,0,0,0,0,0,0,0,0,0,0,0,0,0
0,0,0,0,0,0,0,0,0,0,0,0,0,0,0,0,0,0,0
0,0,0,0,0,0,0,0,0,0,0,0,0,0,0,0,0,0,0
endlayer

layer
0,0,0,0,0,0,0,0,0,0,0,0,0,0,0,0,0,0,0
0,0,0,0,0,0,0,0,0,0,0,0,0,0,0,0,0,0,0
0,0,0,0,0,0,0,0,0,0,0,0,0,0,0,0,0,0,0
0,0,0,0,0,0,0,0,0,0,0,0,0,0,0,0,0,0,0
0,0,0,0,0,0,0,0,0,0,0,0,0,0,0,0,0,0,0
0,0,0,0,0,0,0,0,0,0,0,0,0,0,0,0,0,0,0
0,0,0,0,0,0,0,0,0,0,0,0,0,0,0,0,0,0,0
0,0,0,0,0,0,0,0,0,0,0,0,0,0,0,0,0,0,0
0,0,0,0,0,0,0,0,0,0,0,0,0,0,0,0,0,0,0
0,0,0,0,0,0,0,0,0,0,0,0,0,0,0,0,0,0,0
0,0,0,0,0,0,0,0,0,13,0,0,0,0,0,0,0,0,0
0,0,0,0,0,0,0,0,0,0,0,0,0,0,0,0,0,0,0
0,0,0,0,0,0,0,0,0,0,0,0,0,0,0,0,0,0,0
0,0,0,0,0,0,0,0,0,0,0,0,0,0,0,0,0,0,0
0,0,0,0,0,0,0,0,0,0,0,0,0,0,0,0,0,0,0
0,0,0,0,0,0,0,0,0,0,0,0,0,0,0,0,0,0,0
0,0,0,0,0,0,0,0,0,0,0,0,0,0,0,0,0,0,0
0,0,0,0,0,0,0,0,0,0,0,0,0,0,0,0,0,0,0
0,0,0,0,0,0,0,0,0,0,0,0,0,0,0,0,0,0,0
0,0,0,0,0,0,0,0,0,0,0,0,0,0,0,0,0,0,0
0,0,0,0,0,0,0,0,0,0,0,0,0,0,0,0,0,0,0
0,0,0,0,0,0,0,0,0,0,0,0,0,0,0,0,0,0,0
0,0,0,0,0,0,0,0,0,0,0,0,0,0,0,0,0,0,0
0,0,0,0,0,0,0,0,0,0,0,0,0,0,0,0,0,0,0
0,0,0,0,0,0,0,0,0,0,0,0,0,0,0,0,0,0,0
0,0,0,0,0,0,0,0,0,0,0,0,0,0,0,0,0,0,0
endlayer

layer
0,0,0,0,0,0,0,0,0,0,0,0,0,0,0,0,0,0,0
0,0,0,0,0,0,0,0,0,0,0,0,0,0,0,0,0,0,0
0,0,0,0,0,0,0,0,0,0,0,0,0,0,0,0,0,0,0
0,0,0,0,0,0,0,0,0,0,0,0,0,0,0,0,0,0,0
0,0,0,0,0,0,0,0,0,0,0,0,0,0,0,0,0,0,0
0,0,0,0,0,0,0,0,0,0,0,0,0,0,0,0,0,0,0
0,0,0,0,0,0,0,0,0,0,0,0,0,0,0,0,0,0,0
0,0,0,0,0,0,0,0,0,0,0,0,0,0,0,0,0,0,0
0,0,0,0,0,0,0,0,0,0,0,0,0,0,0,0,0,0,0
0,0,0,0,0,0,0,0,0,0,0,0,0,0,0,0,0,0,0
0,0,0,0,0,0,0,0,0,13,0,0,0,0,0,0,0,0,0
0,0,0,0,0,0,0,0,0,0,0,0,0,0,0,0,0,0,0
0,0,0,0,0,0,0,0,0,0,0,0,0,0,0,0,0,0,0
0,0,0,0,0,0,0,0,0,0,0,0,0,0,0,0,0,0,0
0,0,0,0,0,0,0,0,0,0,0,0,0,0,0,0,0,0,0
0,0,0,0,0,0,0,0,0,0,0,0,0,0,0,0,0,0,0
0,0,0,0,0,0,0,0,0,0,0,0,0,0,0,0,0,0,0
0,0,0,0,0,0,0,0,0,0,0,0,0,0,0,0,0,0,0
0,0,0,0,0,0,0,0,0,0,0,0,0,0,0,0,0,0,0
0,0,0,0,0,0,0,0,0,0,0,0,0,0,0,0,0,0,0
0,0,0,0,0,0,0,0,0,0,0,0,0,0,0,0,0,0,0
0,0,0,0,0,0,0,0,0,0,0,0,0,0,0,0,0,0,0
0,0,0,0,0,0,0,0,0,0,0,0,0,0,0,0,0,0,0
0,0,0,0,0,0,0,0,0,0,0,0,0,0,0,0,0,0,0
0,0,0,0,0,0,0,0,0,0,0,0,0,0,0,0,0,0,0
0,0,0,0,0,0,0,0,0,0,0,0,0,0,0,0,0,0,0
endlayer

layer
0,0,0,0,0,0,0,0,0,0,0,0,0,0,0,0,0,0,0
0,0,0,0,0,0,0,0,0,0,0,0,0,0,0,0,0,0,0
0,0,0,0,0,0,0,0,0,0,0,0,0,0,0,0,0,0,0
0,0,0,0,0,0,0,0,0,0,0,0,0,0,0,0,0,0,0
0,0,0,0,0,0,0,0,0,0,0,0,0,0,0,0,0,0,0
0,0,0,0,0,0,0,0,0,0,0,0,0,0,0,0,0,0,0
0,0,0,0,0,0,0,0,0,0,0,0,0,0,0,0,0,0,0
0,0,0,0,0,0,0,0,0,0,0,0,0,0,0,0,0,0,0
0,0,0,0,0,0,0,0,0,0,0,0,0,0,0,0,0,0,0
0,0,0,0,0,0,0,0,0,0,0,0,0,0,0,0,0,0,0
0,0,0,0,0,0,0,0,13,13,13,0,0,0,0,0,0,0,0
0,0,0,0,0,0,0,0,0,0,0,0,0,0,0,0,0,0,0
0,0,0,0,0,0,0,0,0,0,0,0,0,0,0,0,0,0,0
0,0,0,0,0,0,0,0,0,0,0,0,0,0,0,0,0,0,0
0,0,0,0,0,0,0,0,0,0,0,0,0,0,0,0,0,0,0
0,0,0,0,0,0,0,0,0,0,0,0,0,0,0,0,0,0,0
0,0,0,0,0,0,0,0,0,0,0,0,0,0,0,0,0,0,0
0,0,0,0,0,0,0,0,0,0,0,0,0,0,0,0,0,0,0
0,0,0,0,0,0,0,0,0,0,0,0,0,0,0,0,0,0,0
0,0,0,0,0,0,0,0,0,0,0,0,0,0,0,0,0,0,0
0,0,0,0,0,0,0,0,0,0,0,0,0,0,0,0,0,0,0
0,0,0,0,0,0,0,0,0,0,0,0,0,0,0,0,0,0,0
0,0,0,0,0,0,0,0,0,0,0,0,0,0,0,0,0,0,0
0,0,0,0,0,0,0,0,0,0,0,0,0,0,0,0,0,0,0
0,0,0,0,0,0,0,0,0,0,0,0,0,0,0,0,0,0,0
0,0,0,0,0,0,0,0,0,0,0,0,0,0,0,0,0,0,0
endlayer

layer
0,0,0,0,0,0,0,0,0,0,0,0,0,0,0,0,0,0,0
0,0,0,0,0,0,0,0,0,0,0,0,0,0,0,0,0,0,0
0,0,0,0,0,0,0,0,0,0,0,0,0,0,0,0,0,0,0
0,0,0,0,0,0,0,0,0,0,0,0,0,0,0,0,0,0,0
0,0,0,0,0,0,0,0,0,0,0,0,0,0,0,0,0,0,0
0,0,0,0,0,0,0,0,0,0,0,0,0,0,0,0,0,0,0
0,0,0,0,0,0,0,0,0,0,0,0,0,0,0,0,0,0,0
0,0,0,0,0,0,0,0,0,0,0,0,0,0,0,0,0,0,0
0,0,0,0,0,0,0,0,0,0,0,0,0,0,0,0,0,0,0
0,0,0,0,0,0,0,0,0,0,0,0,0,0,0,0,0,0,0
0,0,0,0,0,0,0,0,0,13,0,0,0,0,0,0,0,0,0
0,0,0,0,0,0,0,0,0,0,0,0,0,0,0,0,0,0,0
0,0,0,0,0,0,0,0,0,0,0,0,0,0,0,0,0,0,0
0,0,0,0,0,0,0,0,0,0,0,0,0,0,0,0,0,0,0
0,0,0,0,0,0,0,0,0,0,0,0,0,0,0,0,0,0,0
0,0,0,0,0,0,0,0,0,0,0,0,0,0,0,0,0,0,0
0,0,0,0,0,0,0,0,0,0,0,0,0,0,0,0,0,0,0
0,0,0,0,0,0,0,0,0,0,0,0,0,0,0,0,0,0,0
0,0,0,0,0,0,0,0,0,0,0,0,0,0,0,0,0,0,0
0,0,0,0,0,0,0,0,0,0,0,0,0,0,0,0,0,0,0
0,0,0,0,0,0,0,0,0,0,0,0,0,0,0,0,0,0,0
0,0,0,0,0,0,0,0,0,0,0,0,0,0,0,0,0,0,0
0,0,0,0,0,0,0,0,0,0,0,0,0,0,0,0,0,0,0
0,0,0,0,0,0,0,0,0,0,0,0,0,0,0,0,0,0,0
0,0,0,0,0,0,0,0,0,0,0,0,0,0,0,0,0,0,0
0,0,0,0,0,0,0,0,0,0,0,0,0,0,0,0,0,0,0
endlayer

