# Converted from schematic
# author:MohawkyMagoo

weight=10
embed_into_distance=2
#acceptable_target_blocks=1,2,3,12,13,9
dimensions=16,14,14
#allowable_overhang=0
max_cut_in=2
#cut_in_buffer=1
max_leveling=2
#leveling_buffer=1
#preserve_water=0
#preserve_lava=0
#preserve_plants=0


rule1=0,100,3
rule2=0,100,2
rule3=0,100,17
rule4=0,100,5
rule5=0,100,98
rule6=0,100,109-3
rule7=0,100,53-0
rule8=0,100,61-4
rule9=0,100,54-3
rule10=0,100,58
rule11=0,100,53-3
rule12=0,100,54-4
rule13=0,100,64-3
rule14=0,100,65-5
rule15=0,100,54-2
rule16=0,100,118-3
rule17=0,100,64-2
rule18=0,100,84
rule19=0,100,85
rule20=0,100,64-1
rule21=0,100,53-1
rule22=0,100,64-2
rule23=0,100,96-3
rule24=0,100,70
rule25=0,100,64-8
rule26=0,100,64-9
rule27=0,100,50-1
rule28=0,100,50-4
rule29=0,100,50-3
rule30=0,100,50-2
rule31=0,100,109-0
rule32=0,100,53-2
rule33=0,100,102
rule34=0,100,44-10
rule35=0,100,54-5
rule36=0,100,47
rule37=0,100,96-0
rule38=0,100,26-1
rule39=0,100,26-9
rule40=0,100,43-2
rule41=0,100,126-0
rule42=0,100,17-4
rule43=0,100,126-8
rule44=0,100,126
rule45=0,100,50-5
rule46=0,100,44-3


layer
1,1,1,1,1,1,1,1,1,1,1,1,1,1
1,1,1,1,1,1,1,1,1,1,1,1,1,1
1,1,1,1,1,1,1,1,1,1,1,1,1,1
1,1,1,1,1,1,1,1,1,1,1,1,1,1
1,1,1,1,1,1,1,1,1,1,1,1,1,1
1,1,1,1,1,1,1,1,1,1,1,1,1,1
1,1,1,1,1,1,1,1,1,1,1,1,1,1
1,1,1,1,1,1,1,1,1,1,1,1,1,1
1,1,1,1,1,1,1,1,1,1,1,1,1,1
1,1,1,1,1,1,1,1,1,1,1,1,1,1
1,1,1,1,1,1,1,1,1,1,1,1,1,1
1,1,1,1,1,1,1,1,1,1,1,1,1,1
1,1,1,1,1,1,1,1,1,1,1,1,1,1
1,1,1,1,1,1,1,1,1,1,1,1,1,1
endlayer

layer
2,2,2,2,2,2,2,2,2,2,2,2,2,2
2,1,1,1,1,1,1,1,1,1,1,1,2,2
1,1,1,1,1,1,1,1,1,1,1,1,2,2
2,1,1,1,1,1,1,1,1,1,1,1,2,2
2,1,1,1,1,1,1,1,1,1,1,1,2,2
1,1,1,1,1,1,1,1,1,1,1,1,2,2
2,1,1,1,1,1,1,1,1,1,1,1,2,2
2,1,1,1,1,1,1,1,1,1,1,1,2,2
2,1,1,1,1,1,1,1,1,1,1,1,2,2
2,1,1,1,1,1,1,1,1,1,1,1,2,2
2,1,1,1,1,1,1,1,1,1,1,1,2,2
2,1,1,1,1,1,1,1,1,1,1,1,2,2
2,1,1,1,1,1,1,2,2,2,2,2,2,2
2,2,2,1,2,2,2,2,2,2,2,2,2,2
endlayer

layer
0,0,0,0,0,0,0,0,0,0,0,0,0,0
0,3,3,3,3,3,3,3,3,3,3,3,0,0
3,3,4,4,4,4,4,4,4,4,4,3,0,0
7,4,4,4,4,4,4,4,4,4,4,3,0,0
7,4,4,4,4,4,4,4,4,4,4,3,0,0
3,3,4,4,4,4,4,4,4,4,4,3,0,0
0,3,3,3,3,3,3,4,4,4,4,3,0,0
0,5,5,5,5,5,3,4,4,4,4,3,0,0
0,5,5,4,4,4,4,4,4,4,4,3,0,0
0,5,5,4,4,4,3,4,4,4,4,3,0,0
0,5,4,4,4,4,3,4,4,4,4,3,0,0
0,5,4,4,4,4,3,3,3,3,3,3,0,0
0,3,5,5,5,5,5,0,0,0,0,0,0,0
0,0,0,6,0,0,0,0,0,0,0,0,0,0
endlayer

layer
0,0,0,0,0,0,0,0,0,0,0,0,0,0
0,3,5,5,5,5,3,5,5,5,5,3,0,0
0,5,21,19,7,18,0,0,0,0,0,5,0,0
0,22,0,0,0,0,0,11,0,11,0,5,0,0
0,22,0,0,0,0,3,3,3,3,0,5,0,0
0,5,21,19,7,0,3,0,0,0,0,5,0,0
0,3,5,5,5,5,3,5,13,5,5,3,0,0
0,5,5,5,5,5,5,14,0,0,8,5,0,0
0,5,5,0,0,0,17,0,0,0,9,5,0,0
0,5,6,0,0,0,5,15,0,0,9,5,0,0
0,5,0,0,0,0,5,16,12,12,10,5,0,0
0,5,0,0,0,0,3,5,5,5,5,3,0,0
0,3,5,20,5,5,5,0,0,0,0,0,0,0
0,0,0,0,0,0,0,0,0,0,0,0,0,0
endlayer

layer
0,0,0,0,0,0,0,0,0,0,0,0,0,0
0,3,5,5,5,5,3,5,5,5,5,3,0,0
0,5,0,24,0,0,0,0,0,0,0,5,0,0
0,25,0,0,0,0,0,0,0,0,0,5,0,0
0,26,0,0,0,0,24,24,24,24,23,5,0,0
0,5,0,24,0,0,24,0,0,0,0,5,0,0
0,3,5,5,5,5,3,5,25,5,5,3,0,0
0,5,5,5,5,5,5,14,0,0,0,5,0,0
0,5,6,0,0,0,25,0,0,0,0,5,0,0
0,5,0,0,0,0,5,0,0,0,0,5,0,0
0,5,0,0,0,0,5,0,0,0,0,5,0,0
0,5,0,0,0,0,3,5,5,5,5,3,0,0
0,3,5,25,5,5,5,0,0,0,0,0,0,0
0,0,0,0,0,0,0,0,0,0,0,0,0,0
endlayer

layer
0,28,0,0,0,0,28,0,0,0,0,28,0,0
30,3,5,5,5,5,3,5,5,5,5,3,27,0
0,5,29,0,0,0,0,0,0,0,29,5,0,0
30,5,0,0,0,0,0,0,0,0,0,5,0,0
30,5,0,0,0,0,0,0,0,0,0,5,0,0
0,5,28,0,0,0,0,0,0,28,0,5,0,0
30,3,5,5,5,5,3,5,5,5,5,3,27,0
0,5,0,31,5,5,5,14,29,0,0,5,0,0
0,5,0,0,0,0,5,0,0,0,0,5,0,0
0,5,0,0,0,0,5,0,0,0,0,5,0,0
0,5,0,0,0,0,5,28,0,0,28,5,0,0
0,5,0,0,0,30,3,5,5,5,5,3,27,0
30,3,5,5,5,5,5,0,0,0,0,29,0,0
0,29,0,0,0,0,29,0,0,0,0,0,0,0
endlayer

layer
32,32,32,32,32,32,32,32,32,32,32,32,32,0
0,3,3,3,3,3,3,3,3,3,3,3,0,0
0,3,0,0,0,0,3,0,0,0,0,3,0,0
0,3,0,0,0,0,3,0,0,0,0,3,0,0
0,3,0,0,0,0,3,0,0,0,0,3,0,0
0,3,0,0,0,0,3,0,0,0,0,3,19,0
0,3,3,3,3,3,3,3,3,3,3,3,3,0
0,5,0,0,31,5,3,14,0,0,0,3,19,0
0,5,0,0,0,19,3,0,0,0,0,3,19,0
0,5,0,0,0,19,3,0,0,0,0,3,19,0
0,5,0,0,0,19,3,0,0,0,0,3,19,0
0,5,0,0,0,0,3,3,3,3,3,3,3,0
0,3,5,5,5,3,3,19,19,19,19,3,19,0
0,0,0,0,0,0,0,0,0,0,0,0,0,0
endlayer

layer
0,0,0,0,0,0,0,0,0,0,0,0,0,0
32,32,32,32,32,32,32,32,32,32,32,32,32,0
0,3,0,0,0,0,3,0,0,0,0,3,0,0
0,33,0,0,0,0,0,0,0,0,0,33,0,0
0,33,0,0,0,0,0,0,0,0,0,33,0,0
0,3,0,0,0,0,3,3,3,3,3,3,19,0
11,3,4,4,4,3,4,4,4,4,4,4,3,0
0,5,0,0,0,31,4,14,4,4,4,4,3,0
0,5,0,4,4,3,4,4,4,4,4,4,3,0
0,5,4,4,4,4,4,4,4,4,4,4,3,0
0,5,4,4,4,4,4,4,4,4,4,4,3,0
0,5,4,4,4,0,4,4,4,4,4,4,3,0
0,3,5,5,5,3,3,3,3,3,3,3,19,0
0,0,0,0,0,0,0,0,0,0,0,0,0,0
endlayer

layer
0,0,0,0,0,0,0,0,0,0,0,0,0,0
0,0,0,0,0,0,0,0,0,0,0,0,0,0
32,32,32,32,32,32,32,32,32,32,32,32,32,0
34,3,0,0,0,0,3,0,0,0,0,3,34,0
34,3,0,0,0,0,3,0,0,0,0,3,34,0
11,4,4,4,4,40,3,4,4,4,4,3,11,0
0,3,4,4,4,3,36,36,3,0,35,35,3,0
0,4,0,0,0,0,0,37,0,0,0,0,4,0
0,4,0,0,0,3,0,0,0,0,0,0,33,0
0,4,0,0,0,0,0,0,0,0,0,0,33,0
0,4,0,0,0,0,0,0,0,0,0,0,4,0
0,4,0,0,0,0,39,38,0,0,0,16,3,0
0,3,4,4,4,3,3,4,33,33,4,3,19,0
0,0,0,0,0,0,0,0,0,0,0,0,0,0
endlayer

layer
0,0,0,0,0,0,0,0,0,0,0,0,0,0
0,0,0,0,0,0,0,0,0,0,0,0,0,0
0,0,0,0,0,0,0,0,0,0,0,0,0,0
0,41,32,32,32,32,32,32,32,32,32,41,0,0
0,41,11,11,11,11,11,11,11,11,11,41,0,0
0,0,0,0,0,19,3,4,4,4,4,3,19,0
0,3,4,0,4,3,36,36,3,0,0,0,3,0
0,4,0,0,0,0,0,0,0,0,0,0,4,0
0,33,0,0,0,3,0,0,0,0,0,0,33,0
0,4,0,0,0,0,0,0,0,0,0,0,33,0
0,33,0,0,0,0,0,0,0,0,0,0,4,0
0,4,0,0,0,0,0,0,0,0,0,0,3,0
0,3,4,33,4,3,3,4,33,33,4,3,19,0
0,0,0,0,0,0,0,0,0,0,0,0,0,0
endlayer

layer
0,0,0,0,0,0,0,0,0,0,0,0,0,0
0,0,0,0,0,0,0,0,0,0,0,0,0,0
0,0,0,0,0,0,0,0,0,0,0,0,0,0
0,0,0,0,0,0,0,0,0,0,0,0,0,0
0,0,0,0,0,0,0,0,0,0,0,0,0,0
0,0,0,0,0,19,3,4,4,4,4,3,19,0
43,4,4,4,4,3,36,36,3,0,0,0,3,0
43,4,0,0,0,42,0,0,0,0,0,0,4,0
43,4,0,0,0,3,0,0,0,0,0,0,33,0
43,4,0,0,0,0,0,0,0,0,0,0,33,0
43,4,0,0,0,0,0,0,0,0,0,0,4,0
43,4,0,0,0,0,0,0,0,0,0,0,3,0
43,4,4,4,4,3,3,4,33,33,4,3,19,0
43,43,43,43,0,0,0,0,0,0,0,0,0,0
endlayer

layer
0,0,0,0,0,0,0,0,0,0,0,0,0,0
0,0,0,0,0,0,0,0,0,0,0,0,0,0
0,0,0,0,0,0,0,0,0,0,0,0,0,0
0,0,0,0,0,0,0,0,0,0,0,0,0,0
0,0,0,0,7,0,28,0,0,0,0,28,0,21
0,0,0,0,7,3,3,3,3,3,3,3,3,21
0,44,44,44,7,3,41,41,41,0,0,0,3,21
0,44,44,44,7,3,0,0,0,0,0,0,3,21
0,44,44,44,7,3,0,0,0,0,0,0,3,21
30,4,44,44,7,3,0,0,0,0,0,0,3,21
0,44,44,44,7,3,0,0,0,0,0,0,3,21
0,44,44,44,7,3,0,0,0,0,0,0,3,21
0,44,44,44,7,3,3,3,3,3,3,3,3,21
0,0,0,0,7,0,0,29,0,0,0,29,0,21
endlayer

layer
0,0,0,0,0,0,0,0,0,0,0,0,0,0
0,0,0,0,0,0,0,0,0,0,0,0,0,0
0,0,0,0,0,0,0,0,0,0,0,0,0,0
0,0,0,0,0,0,0,0,0,0,0,0,0,0
0,0,0,0,0,7,0,0,0,0,0,0,21,0
0,0,0,0,0,7,3,4,33,33,4,3,21,0
0,0,0,0,0,7,0,0,0,0,0,0,21,0
0,0,0,0,0,7,0,0,0,0,0,0,21,0
0,0,0,0,0,7,0,0,0,0,0,0,21,0
0,45,0,0,0,7,0,0,0,0,0,0,21,0
0,0,0,0,0,7,0,0,0,0,0,0,21,0
0,0,0,0,0,7,0,0,0,0,0,0,21,0
0,0,0,0,0,7,3,4,33,33,4,3,21,0
0,0,0,0,0,7,0,0,0,0,0,0,21,0
endlayer

layer
0,0,0,0,0,0,0,0,0,0,0,0,0,0
0,0,0,0,0,0,0,0,0,0,0,0,0,0
0,0,0,0,0,0,0,0,0,0,0,0,0,0
0,0,0,0,0,0,0,0,0,0,0,0,0,0
0,0,0,0,0,0,7,0,0,0,0,21,0,0
0,0,0,0,0,0,7,3,33,33,3,21,0,0
0,0,0,0,0,0,7,0,0,0,0,21,0,0
0,0,0,0,0,0,7,0,0,0,0,21,0,0
0,0,0,0,0,0,7,0,0,0,0,21,0,0
0,0,0,0,0,0,7,0,0,0,0,21,0,0
0,0,0,0,0,0,7,0,0,0,0,21,0,0
0,0,0,0,0,0,7,0,0,0,0,21,0,0
0,0,0,0,0,0,7,3,33,33,3,21,0,0
0,0,0,0,0,0,7,0,0,0,0,21,0,0
endlayer

layer
0,0,0,0,0,0,0,0,0,0,0,0,0,0
0,0,0,0,0,0,0,0,0,0,0,0,0,0
0,0,0,0,0,0,0,0,0,0,0,0,0,0
0,0,0,0,0,0,0,0,0,0,0,0,0,0
0,0,0,0,0,0,0,7,0,0,21,0,0,0
0,0,0,0,0,0,0,7,3,3,21,0,0,0
0,0,0,0,0,0,0,7,0,0,21,0,0,0
0,0,0,0,0,0,0,7,0,0,21,0,0,0
0,0,0,0,0,0,0,7,0,0,21,0,0,0
0,0,0,0,0,0,0,7,0,0,21,0,0,0
0,0,0,0,0,0,0,7,0,0,21,0,0,0
0,0,0,0,0,0,0,7,0,0,21,0,0,0
0,0,0,0,0,0,0,7,3,3,21,0,0,0
0,0,0,0,0,0,0,7,0,0,21,0,0,0
endlayer

layer
0,0,0,0,0,0,0,0,0,0,0,0,0,0
0,0,0,0,0,0,0,0,0,0,0,0,0,0
0,0,0,0,0,0,0,0,0,0,0,0,0,0
0,0,0,0,0,0,0,0,0,0,0,0,0,0
0,0,0,0,0,0,0,0,46,46,0,0,0,0
0,0,0,0,0,0,0,0,7,21,0,0,0,0
0,0,0,0,0,0,0,0,7,21,0,0,0,0
0,0,0,0,0,0,0,0,7,21,0,0,0,0
0,0,0,0,0,0,0,0,7,21,0,0,0,0
0,0,0,0,0,0,0,0,7,21,0,0,0,0
0,0,0,0,0,0,0,0,7,21,0,0,0,0
0,0,0,0,0,0,0,0,7,21,0,0,0,0
0,0,0,0,0,0,0,0,7,21,0,0,0,0
0,0,0,0,0,0,0,0,46,46,0,0,0,0
endlayer

