# Converted from schematic
# author:MohawkyMagoo

weight=10
embed_into_distance=6
#acceptable_target_blocks=1,2,3,12,13
dimensions=23,21,22
#allowable_overhang=0
max_cut_in=2
#cut_in_buffer=1
max_leveling=2
#leveling_buffer=1
#preserve_water=0
#preserve_lava=0
#preserve_plants=0


rule1=0,100,4
rule2=0,100,3
rule3=0,100,1
rule4=0,100,13
rule5=0,100,2
rule6=0,100,5
rule7=0,100,98
rule8=0,100,44-3
rule9=0,100,64-1
rule10=0,100,109-3
rule11=0,100,109-2
rule12=0,100,109-0
rule13=0,100,85
rule14=0,100,102
rule15=0,100,64-8
rule16=0,100,53-0
rule17=0,100,53-3
rule18=0,100,17
rule19=0,100,64-2
rule20=0,100,26-0
rule21=0,100,26-8
rule22=0,100,26-1
rule23=0,100,64
rule24=0,100,26-9
rule25=0,100,54-2
rule26=0,100,11
rule27=0,100,109-1
rule28=0,100,50-2
rule29=0,100,50-4
rule30=0,100,50-3
rule31=0,100,72
rule32=0,100,61-3
rule33=0,100,64-8
rule34=0,100,50-1
rule35=0,100,109-5
rule36=0,100,109-4
rule37=0,100,54-4
rule38=0,100,50-5
rule39=0,100,64-0
rule40=0,100,53-1
rule41=0,100,126
rule42=0,100,53-2
rule43=0,100,53-5


layer
1,1,1,1,1,1,1,1,1,1,1,1,1,1,1,1,1,1,1,1,1,1
3,3,3,3,3,3,3,3,2,2,2,1,2,2,3,3,3,3,3,3,1,1
3,3,3,3,3,3,3,3,2,2,2,2,2,2,3,3,3,3,3,3,1,1
3,3,3,3,3,3,3,3,2,2,2,2,2,2,3,3,3,3,3,3,1,1
3,3,3,3,3,3,3,2,2,2,2,2,2,2,3,3,3,3,3,3,3,1
3,3,3,3,3,3,3,2,2,2,2,2,2,2,3,3,3,3,3,3,3,1
3,3,3,3,3,3,3,2,2,2,2,2,2,2,2,3,3,3,3,2,2,1
3,3,3,3,3,3,3,2,2,2,2,2,2,2,2,2,2,2,2,2,2,2
3,3,3,3,3,3,3,2,2,2,2,2,2,2,2,2,2,2,2,2,2,1
3,3,3,3,2,2,2,2,2,2,2,2,2,2,2,2,2,2,2,2,2,2
3,3,3,3,3,2,2,2,2,2,2,2,2,2,2,2,2,2,2,2,2,2
3,3,3,3,3,3,2,2,2,2,2,2,2,2,2,2,2,2,2,2,2,2
3,3,3,3,3,3,2,2,2,2,2,2,2,2,2,2,2,2,2,2,2,2
3,3,3,3,3,3,2,2,2,2,2,2,2,2,2,2,2,2,2,2,2,2
2,3,3,3,3,3,2,2,2,2,2,2,2,2,2,2,2,2,2,2,2,2
2,3,3,3,2,2,2,2,2,2,2,2,2,2,2,2,2,2,2,2,2,2
2,2,2,2,2,2,2,2,2,2,2,2,2,2,2,2,2,2,2,2,3,3
2,2,2,2,2,2,2,2,2,2,2,2,2,2,2,2,2,2,2,3,3,3
2,2,2,2,2,2,2,2,2,2,2,2,2,2,2,2,2,2,2,2,3,3
2,2,2,2,2,2,2,2,2,2,2,2,2,2,2,2,2,2,2,2,3,3
2,2,2,2,2,2,2,2,2,2,2,2,2,2,2,2,2,2,2,2,3,3
endlayer

layer
1,1,1,1,1,1,1,1,1,1,1,1,1,1,1,1,1,1,1,1,1,1
3,3,3,3,3,3,4,4,2,2,2,2,2,2,3,3,3,3,3,3,3,3
3,3,3,3,3,3,4,2,2,2,2,2,2,2,3,3,3,3,3,3,3,3
3,3,3,3,3,3,3,2,2,2,2,2,2,2,3,3,3,3,3,3,3,3
3,3,3,3,3,3,3,2,2,2,2,2,2,2,3,3,3,3,3,3,3,3
3,3,3,3,3,3,3,2,2,2,2,2,2,2,3,3,3,3,3,3,3,3
3,3,3,3,3,3,3,2,2,2,2,2,2,2,2,3,3,3,3,2,2,2
3,3,3,3,3,3,2,2,2,2,2,2,2,2,2,2,2,2,2,2,2,2
3,3,3,3,3,3,2,2,2,2,2,2,2,2,2,2,2,2,2,2,2,2
3,3,3,3,3,3,2,2,2,2,2,2,2,2,2,2,2,2,2,2,2,2
3,3,3,3,3,3,2,2,2,2,2,2,2,2,2,2,2,2,2,2,2,2
3,3,3,3,3,3,2,2,2,2,2,2,2,2,2,2,2,2,2,2,2,2
3,3,3,3,3,3,2,2,2,2,2,2,2,2,2,2,2,2,2,2,2,2
2,2,3,3,3,3,2,2,2,2,2,2,2,2,2,2,2,2,2,2,2,2
2,2,2,3,2,2,2,2,2,2,2,2,2,2,2,2,2,2,2,2,2,2
2,2,2,2,2,2,2,2,2,2,2,2,2,2,2,2,2,2,2,2,2,2
2,2,2,2,2,2,2,2,2,2,2,2,2,2,2,2,2,2,2,2,2,3
2,2,2,2,2,2,2,2,2,2,2,2,2,2,2,2,2,2,2,2,3,3
2,2,2,2,2,2,2,2,2,2,2,2,2,2,2,2,2,2,2,2,3,3
2,2,2,2,2,2,2,2,2,2,2,2,2,2,2,2,2,2,2,2,2,3
2,2,2,2,2,2,2,2,2,2,2,2,2,2,2,2,2,2,2,2,2,3
endlayer

layer
1,1,1,1,1,1,1,1,1,1,1,1,1,1,1,1,1,1,1,1,1,1
3,3,3,3,3,4,4,2,2,2,2,2,2,2,3,3,3,3,3,3,3,3
3,3,3,3,3,3,4,2,2,2,2,2,2,2,3,3,3,3,3,3,3,3
3,3,3,3,3,3,3,2,2,2,2,2,2,2,3,3,3,3,3,3,3,3
3,3,3,3,3,3,2,2,2,2,2,2,2,2,3,3,3,3,3,3,3,3
3,3,3,3,3,3,2,2,2,2,2,2,2,2,3,3,3,3,3,3,3,3
3,3,3,3,3,3,2,2,2,2,2,2,2,2,2,3,3,3,3,3,2,3
3,3,3,3,3,2,2,2,2,2,2,2,2,2,2,2,2,2,2,2,2,2
3,3,3,3,3,2,2,2,2,2,2,2,2,2,2,2,2,2,2,2,2,2
3,3,3,3,2,2,2,2,2,2,2,2,2,2,2,2,2,2,2,2,2,2
2,3,3,3,2,2,2,2,2,2,2,2,2,2,2,2,2,2,2,2,2,2
2,3,3,3,3,2,2,2,2,2,2,2,2,2,2,2,2,2,2,2,2,2
2,3,3,3,2,2,2,2,2,2,2,2,2,2,2,2,2,2,2,2,2,2
2,2,2,3,2,2,2,2,2,2,2,2,2,2,2,2,2,2,2,2,2,2
2,2,2,3,2,2,2,2,2,2,2,2,2,2,2,2,2,2,2,2,2,2
2,2,2,2,2,2,2,2,2,2,2,2,2,2,2,2,2,2,2,2,2,2
2,2,2,2,2,2,2,2,2,2,2,2,2,2,2,2,2,2,2,2,2,2
2,2,2,2,2,2,2,2,2,2,2,2,2,2,2,2,2,2,2,2,2,3
2,2,2,2,2,2,2,2,2,2,2,2,2,2,2,2,2,2,2,2,2,3
2,2,2,2,2,2,2,2,2,2,2,2,2,2,2,2,2,2,2,2,2,3
2,2,2,2,2,2,2,2,2,2,2,2,2,2,2,2,2,2,2,2,2,3
endlayer

layer
1,1,1,1,1,1,1,1,1,1,1,1,1,1,1,1,1,1,1,1,1,1
1,3,3,3,3,4,4,2,2,2,2,2,2,2,2,3,3,3,3,3,1,1
1,3,3,3,3,3,2,2,2,2,2,2,2,2,2,3,3,3,3,3,1,1
1,3,3,3,3,3,2,2,2,2,2,2,2,2,2,3,3,3,3,3,1,1
1,3,3,3,3,3,2,2,2,2,2,2,2,2,2,3,3,3,3,3,1,1
1,3,3,3,3,2,2,2,2,2,2,2,2,2,2,3,3,3,3,3,1,1
1,3,3,3,3,2,2,2,2,2,2,2,2,2,2,3,2,2,2,2,1,1
1,3,3,3,2,2,2,2,2,2,2,2,2,2,2,2,2,2,2,2,1,1
1,2,2,2,2,2,2,2,2,2,2,2,2,2,2,2,2,2,2,2,1,1
1,2,2,2,2,2,2,2,2,2,2,2,2,2,2,2,2,2,2,2,1,1
1,2,2,2,2,2,2,2,2,2,2,2,2,2,2,2,2,2,2,2,1,1
1,2,2,2,2,2,2,2,2,2,2,2,2,2,2,2,2,2,2,2,1,1
1,2,2,2,2,2,2,2,2,2,2,2,2,2,2,1,1,1,1,1,1,1
1,2,2,3,2,2,2,2,2,2,2,2,2,2,2,1,1,1,1,1,1,1
1,2,2,2,2,2,2,2,2,2,2,2,2,2,2,1,1,1,1,1,1,1
1,2,2,2,2,2,2,2,2,2,2,2,2,2,2,1,1,1,1,1,1,1
1,2,2,2,2,2,2,2,2,2,2,2,2,2,2,1,1,1,1,1,1,1
1,2,2,2,2,2,2,2,2,2,2,2,2,2,2,1,1,1,1,1,1,1
1,2,2,2,2,2,2,2,2,2,2,2,2,2,2,1,1,1,1,1,1,1
1,2,2,2,2,2,2,2,2,2,2,2,2,2,2,1,1,1,1,1,1,1
1,1,1,1,1,1,1,1,1,1,1,1,1,1,1,1,1,1,1,1,1,1
endlayer

layer
1,1,1,1,1,1,1,1,0,0,1,0,0,1,0,0,1,0,0,1,0,1
1,3,3,3,3,3,1,1,1,1,1,1,1,1,1,1,1,1,1,1,1,0
1,3,3,3,3,3,2,2,2,2,2,2,2,2,2,3,3,2,2,2,1,1
1,3,3,3,3,2,2,2,2,2,2,2,2,2,2,3,3,3,3,2,1,0
1,3,3,3,3,2,2,2,2,2,2,2,2,2,2,3,3,3,3,3,1,0
1,3,3,3,2,2,2,2,2,2,2,2,2,2,2,3,3,3,3,3,1,1
1,2,2,2,2,2,2,2,2,2,2,2,2,2,2,2,2,2,2,2,1,0
1,2,2,2,2,2,2,2,2,2,2,2,2,2,2,2,2,2,2,2,1,0
1,2,2,2,2,2,2,2,2,2,2,2,2,2,2,1,1,1,1,1,1,1
1,1,1,1,1,1,1,1,1,1,1,1,1,1,1,1,1,1,1,1,1,0
1,1,1,1,1,1,1,1,1,1,1,1,1,1,1,1,1,1,1,1,1,0
1,1,1,1,1,1,1,1,1,1,1,1,1,1,1,1,1,1,1,1,1,1
1,1,1,1,1,1,1,1,1,1,1,1,1,1,1,1,1,1,1,1,1,0
1,1,1,3,1,1,1,1,1,1,1,1,1,1,1,1,1,1,1,1,1,0
1,2,2,2,2,2,2,2,2,2,2,2,2,2,2,1,1,1,1,1,1,1
1,2,2,2,2,2,2,2,2,2,2,2,2,2,2,1,1,1,1,1,1,0
1,2,2,2,2,2,2,2,2,2,2,2,2,2,2,1,1,1,1,1,1,0
1,2,2,2,2,2,2,2,2,2,2,2,2,2,2,1,1,1,1,1,1,1
1,2,2,2,2,2,2,2,2,2,2,2,2,2,2,1,1,1,1,1,1,0
1,2,2,2,2,2,2,2,2,2,2,2,2,2,2,1,1,1,1,1,1,0
1,1,1,1,1,1,1,1,1,1,1,1,1,1,1,1,1,1,1,1,1,1
endlayer

layer
1,1,1,1,1,1,1,1,0,0,1,0,0,1,0,0,1,0,0,1,0,1
1,3,3,3,3,2,1,1,1,1,1,1,1,1,1,1,1,1,1,1,1,0
1,6,6,6,6,2,2,1,1,1,1,1,1,1,1,1,1,1,1,1,1,1
1,6,6,6,6,2,2,2,2,2,2,2,2,2,1,1,1,1,1,1,1,0
1,6,6,6,6,2,2,2,2,2,2,2,2,2,2,1,1,1,1,1,1,0
1,6,6,6,6,2,2,2,2,2,2,2,2,2,2,1,1,1,1,1,1,1
1,6,6,6,6,2,2,2,2,2,2,2,2,2,2,1,1,1,1,1,1,0
1,2,1,2,2,2,2,2,2,2,2,2,2,2,2,1,1,1,1,1,1,0
1,1,1,1,1,1,2,2,2,2,2,2,2,2,2,1,1,1,1,1,1,1
1,1,1,1,1,1,1,1,1,1,1,1,1,1,1,1,1,1,1,1,1,0
1,1,1,1,1,1,1,1,1,1,1,1,1,1,1,1,1,1,1,1,1,0
1,1,1,1,1,1,1,1,1,1,1,1,1,1,1,1,1,1,1,1,1,1
1,1,1,1,1,1,1,1,1,1,1,1,1,1,1,1,1,1,1,1,1,0
1,1,1,1,1,1,1,1,1,1,1,1,1,1,1,1,1,1,1,1,1,0
1,5,5,5,5,5,5,5,5,5,5,5,5,5,5,1,1,1,1,1,1,1
1,2,2,2,2,2,2,2,2,2,2,2,2,2,5,1,1,1,1,1,1,0
1,2,2,2,2,2,2,2,2,2,2,2,2,2,5,1,1,1,1,1,1,0
1,2,2,2,2,2,2,2,2,2,2,2,2,2,5,1,1,1,1,1,1,1
1,2,2,2,2,2,2,2,2,2,2,2,2,2,5,1,1,1,1,1,1,0
1,2,2,2,2,2,2,2,2,2,2,2,2,2,5,1,1,1,1,1,1,0
1,1,1,1,1,1,1,1,1,1,1,1,1,1,1,1,1,1,1,1,1,1
endlayer

layer
7,7,7,7,7,7,7,7,7,7,7,7,7,7,7,7,7,7,7,7,7,7
7,7,7,7,7,7,7,7,7,7,7,7,7,7,7,7,7,7,7,7,7,7
7,0,0,0,0,7,7,7,7,7,7,7,7,7,7,7,7,7,7,7,7,7
7,0,0,0,0,7,7,7,7,7,7,7,7,7,7,7,7,7,7,7,7,7
7,0,0,0,0,7,7,7,7,7,7,7,7,7,7,7,7,7,7,7,7,7
7,0,0,0,0,7,7,7,7,7,7,7,7,7,7,7,7,7,7,7,7,7
7,0,0,0,0,7,7,7,7,7,7,7,7,7,7,7,7,7,7,7,7,7
7,7,9,7,7,7,7,7,7,7,7,7,7,7,7,7,7,7,7,7,7,7
0,0,0,0,0,12,7,7,7,7,7,7,7,7,7,7,8,8,8,8,7,7
0,0,0,0,0,12,7,7,7,7,7,7,7,7,7,7,0,0,0,0,7,7
13,0,0,0,0,13,10,10,10,10,10,10,0,0,0,0,0,0,0,0,7,7
0,0,0,0,0,0,0,0,0,0,0,0,0,0,0,0,0,0,0,0,7,7
0,0,0,0,0,0,0,0,0,0,0,0,0,0,0,7,7,9,7,7,7,7
0,0,0,0,0,0,0,0,0,0,0,0,0,0,0,7,0,0,0,0,7,7
0,0,11,0,0,0,0,11,0,0,0,11,0,0,0,7,0,0,0,0,7,7
0,7,7,7,7,7,7,7,7,7,7,7,7,7,0,7,0,0,0,0,7,7
0,7,2,2,7,7,7,7,7,7,7,2,2,7,0,7,0,0,0,0,7,7
0,7,2,2,7,7,7,7,7,7,7,2,2,7,0,7,0,0,0,0,7,7
0,7,2,2,7,7,7,7,7,7,7,2,2,7,0,7,0,0,0,0,7,7
0,7,7,7,7,7,7,7,7,7,7,7,7,7,0,7,0,0,0,0,7,7
0,0,0,0,0,0,0,0,0,0,0,0,0,0,0,7,7,7,7,7,7,7
endlayer

layer
7,7,7,7,7,27,0,0,0,0,0,0,0,0,0,0,0,0,0,0,0,0
7,7,7,7,7,7,0,0,13,0,0,0,0,0,0,0,13,0,0,0,13,0
7,0,0,0,0,7,0,0,0,0,0,0,0,0,0,0,0,0,0,0,0,0
7,0,0,0,0,7,7,7,7,7,6,6,6,6,6,7,0,0,0,0,7,0
7,0,0,0,0,7,7,26,26,7,24,22,0,17,6,6,0,0,0,0,0,0
7,0,0,0,0,7,7,7,7,7,25,0,0,13,16,6,0,0,0,0,0,0
7,0,0,0,0,7,0,0,0,7,6,6,0,0,0,6,0,0,0,0,0,0
7,7,15,7,14,7,0,0,0,0,0,0,6,0,0,6,0,0,0,0,7,0
0,0,0,0,0,0,0,0,0,0,0,0,19,0,0,6,0,0,0,0,0,0
0,0,0,0,0,0,7,0,0,0,0,0,7,6,6,7,0,0,0,0,0,0
13,0,0,0,0,13,0,0,0,0,0,0,0,0,0,0,0,0,0,0,0,0
0,0,0,0,0,0,0,0,0,0,0,0,0,0,0,0,0,0,0,0,7,0
0,0,0,0,0,0,0,0,0,0,0,0,0,0,0,7,7,15,7,7,7,0
0,0,0,0,0,0,0,0,0,0,0,0,0,0,0,7,0,0,0,0,7,0
0,0,0,0,0,0,0,0,0,0,0,0,0,0,0,7,0,0,0,0,7,0
0,18,23,6,18,7,6,9,6,7,18,23,6,18,0,7,0,0,0,0,7,0
0,6,0,0,6,6,0,0,0,6,6,0,0,6,0,14,0,0,0,0,14,0
0,6,0,20,6,6,0,0,20,6,6,0,20,6,0,7,0,0,0,0,7,0
0,6,13,21,6,6,0,0,21,6,6,13,21,6,0,7,0,0,0,0,7,0
0,18,6,6,18,7,6,6,6,7,18,6,6,18,0,7,0,0,0,0,7,0
0,0,0,0,0,0,0,0,0,0,0,0,0,0,0,7,7,14,7,7,7,0
endlayer

layer
7,7,7,7,27,0,0,0,0,0,0,0,0,0,0,0,0,0,0,0,0,0
7,7,7,7,7,7,0,0,13,0,0,0,0,0,0,0,13,0,0,0,13,0
7,0,0,0,0,7,0,0,0,29,0,0,0,0,0,0,0,0,0,0,0,0
7,0,0,0,0,7,7,7,7,7,6,14,6,14,6,7,0,0,0,0,7,0
7,0,0,0,0,7,0,0,0,7,0,0,0,0,0,6,0,0,0,0,0,0
7,0,0,0,29,7,0,0,0,7,0,0,0,31,0,14,0,0,0,0,0,0
7,7,7,7,7,7,0,0,0,32,6,6,0,0,0,6,0,0,0,0,0,0
7,7,7,7,7,7,0,0,0,0,0,0,6,0,0,14,0,0,0,28,7,0
0,0,30,0,0,0,0,0,0,0,0,0,15,0,0,6,0,0,0,0,0,0
0,0,0,0,0,0,7,0,0,0,0,0,7,6,6,7,0,0,0,0,0,0
13,0,0,0,0,13,0,0,0,0,0,0,0,0,0,0,0,0,0,0,0,0
0,0,0,0,0,0,0,0,0,0,0,0,0,0,0,0,0,29,0,28,7,0
0,0,0,0,0,0,0,0,0,0,0,0,0,0,0,7,7,7,7,7,7,0
0,0,0,0,0,0,0,0,0,0,0,0,0,0,0,7,30,0,0,0,7,0
0,0,0,0,0,0,0,0,0,0,0,0,0,0,0,7,0,0,0,0,7,0
0,18,33,6,18,7,6,15,6,7,18,15,6,18,0,7,0,0,0,0,7,0
0,6,0,0,6,6,0,0,0,6,6,0,0,6,0,14,0,0,0,0,14,0
0,14,0,0,14,14,0,0,0,14,14,0,0,14,0,7,0,0,0,0,7,0
0,6,31,0,6,6,0,0,0,6,6,31,0,6,0,7,0,0,0,0,7,0
0,18,6,6,18,7,6,14,6,7,18,6,6,18,0,7,29,0,0,0,7,0
0,0,0,0,0,0,0,0,0,0,0,0,0,0,0,7,7,14,7,7,7,0
endlayer

layer
7,7,7,27,0,0,0,0,0,0,0,0,0,0,0,0,0,0,0,0,0,0
7,7,7,7,7,7,0,0,13,0,0,0,0,0,0,0,13,0,0,0,13,0
7,0,0,0,7,7,0,0,0,0,0,0,0,0,0,29,0,0,0,0,29,0
7,0,0,0,0,7,7,7,7,7,6,6,6,6,6,7,34,0,0,28,7,34
7,0,0,0,0,7,7,7,7,7,34,0,0,0,0,6,0,0,0,0,0,0
7,0,0,0,0,7,7,7,7,7,0,0,0,0,0,6,0,0,0,0,0,0
7,7,7,7,7,7,0,0,30,32,6,6,29,0,0,6,34,0,0,0,29,0
7,7,7,7,7,7,34,0,0,0,0,0,6,0,0,6,0,0,0,0,7,34
0,0,0,0,0,0,0,0,0,0,0,28,6,29,0,6,0,0,0,0,30,0
0,0,0,0,0,0,7,0,0,0,0,0,7,6,6,7,0,0,0,0,0,0
13,0,0,0,0,13,35,0,0,0,0,0,35,0,30,35,0,0,0,0,29,0
0,0,0,0,0,0,0,0,0,0,0,0,0,0,0,36,0,0,0,0,7,34
0,0,0,0,0,0,0,0,0,0,0,0,0,0,28,7,7,7,7,7,7,0
0,0,0,0,0,0,0,0,0,0,0,0,0,0,0,7,0,0,0,0,7,0
0,29,0,0,29,0,0,0,0,0,29,0,0,29,0,7,0,0,0,0,7,0
0,18,6,6,18,7,6,6,6,7,18,6,6,18,0,7,0,0,0,0,7,0
0,6,30,0,6,6,0,30,0,6,6,30,0,6,0,14,0,0,0,0,14,0
0,6,0,0,6,6,0,0,0,6,6,0,0,6,0,7,0,0,0,0,7,0
0,6,0,0,6,6,0,29,0,6,6,0,29,6,0,7,0,0,0,0,7,0
0,18,6,6,18,7,6,6,6,7,18,6,6,18,0,7,0,0,0,0,7,0
0,30,0,0,30,0,0,0,0,0,30,0,0,30,28,7,7,14,7,7,7,34
endlayer

layer
7,7,27,0,0,0,0,0,0,0,0,0,0,0,0,0,0,0,0,0,0,0
7,7,7,7,6,6,6,6,6,6,6,6,6,6,6,6,6,6,6,6,6,0
7,7,7,7,6,6,6,6,6,6,6,6,6,6,6,6,6,6,6,6,6,0
7,7,7,7,7,7,7,7,7,7,7,7,7,7,7,7,7,7,7,7,7,0
7,7,7,7,7,7,7,7,7,7,7,7,7,7,7,7,7,7,7,7,7,0
7,7,7,7,7,7,7,7,7,7,7,7,7,7,7,7,7,7,7,7,7,0
7,7,7,7,7,7,7,7,7,7,7,7,7,7,7,7,7,7,7,7,7,0
7,7,7,7,7,7,7,7,7,7,7,7,7,7,7,7,7,7,7,7,7,0
6,6,6,6,6,6,7,7,7,7,7,7,7,7,7,7,7,7,7,7,7,0
6,6,6,6,6,6,7,7,7,7,7,7,7,7,7,7,7,7,7,7,7,0
6,6,6,6,6,6,7,7,7,7,7,7,7,7,7,7,7,7,7,7,7,0
0,0,0,0,0,0,0,0,0,0,0,0,0,0,0,7,7,7,7,7,7,0
0,0,0,0,0,0,0,0,0,0,0,0,0,0,0,7,7,7,7,7,7,0
0,0,0,0,0,0,0,0,0,0,0,0,0,0,0,7,7,7,7,7,7,0
0,0,0,0,0,0,0,0,0,0,0,0,0,0,0,7,7,7,7,7,7,0
0,0,18,18,0,18,18,18,18,18,0,18,18,0,0,7,7,7,7,7,7,0
0,18,0,0,18,18,6,6,6,18,18,0,0,18,0,7,7,7,7,7,7,0
0,18,0,0,18,18,6,6,6,18,18,0,0,18,0,7,7,7,7,7,7,0
0,18,29,0,18,18,6,6,6,18,18,0,0,18,0,7,7,7,7,7,7,0
0,0,18,18,0,18,18,18,18,18,0,18,18,0,0,7,7,7,7,7,7,0
0,0,0,0,0,0,0,0,0,0,0,0,0,0,0,7,7,7,7,7,7,0
endlayer

layer
0,0,0,0,0,0,0,0,0,0,0,0,0,0,0,0,0,0,0,0,0,0
13,0,0,0,13,13,13,13,13,13,13,13,13,13,13,13,13,13,13,13,13,0
13,0,0,0,0,0,0,0,0,0,0,0,0,0,0,0,0,0,0,0,13,0
7,7,23,7,7,7,7,7,7,7,7,7,7,7,7,7,7,7,23,7,7,0
7,0,0,0,0,7,0,0,0,0,0,0,0,0,0,7,0,0,0,0,7,0
7,0,0,0,0,39,0,0,0,0,0,0,0,0,0,7,0,0,0,0,7,0
7,0,0,0,0,7,0,0,0,0,0,0,0,0,0,7,0,0,0,20,7,0
7,7,7,7,7,7,7,0,0,0,0,0,0,0,0,7,0,37,0,21,7,0
13,0,0,0,0,0,19,0,0,0,0,0,0,0,0,7,23,7,7,7,7,0
13,0,0,0,0,0,7,0,0,0,0,0,0,0,0,19,0,0,0,0,7,0
13,13,13,13,13,13,7,7,7,7,7,7,7,7,7,7,0,0,0,0,7,0
0,0,0,0,0,0,0,0,0,0,0,0,0,0,0,7,0,0,0,0,7,0
0,0,0,0,0,0,0,0,0,0,0,0,0,0,0,7,7,9,7,7,7,0
0,0,0,0,0,0,0,0,0,0,0,0,0,0,0,7,0,0,0,0,7,0
0,0,0,0,0,0,0,0,0,0,0,0,0,0,0,7,0,0,0,0,7,0
0,0,0,0,0,0,0,0,0,0,0,0,0,0,0,7,0,0,0,0,7,0
0,0,18,18,0,0,0,0,0,0,0,18,18,0,0,7,0,0,0,0,7,0
0,0,18,18,0,0,0,38,0,0,0,18,18,0,0,7,0,0,0,0,7,0
0,0,18,18,0,0,0,0,0,0,0,18,18,0,0,7,0,20,20,0,7,0
0,0,0,0,0,0,0,0,0,0,0,0,0,0,0,7,37,21,21,37,7,0
0,0,0,0,0,0,0,0,0,0,0,0,0,0,0,7,7,7,7,7,7,0
endlayer

layer
0,0,0,0,0,0,0,0,0,0,0,0,0,0,0,0,0,0,0,0,0,0
13,0,0,0,13,0,0,38,0,0,13,0,38,0,0,13,0,38,0,0,13,0
13,0,0,0,0,0,0,0,0,0,0,0,0,0,0,0,0,0,0,0,38,0
7,7,15,7,7,7,7,14,7,14,7,14,7,14,7,7,7,7,15,7,7,0
7,0,0,0,0,7,0,0,0,0,0,0,0,0,0,7,0,0,0,0,7,0
14,0,0,0,0,15,0,0,0,0,0,0,0,0,0,7,0,0,0,0,14,0
7,0,0,0,0,7,0,0,0,0,0,0,0,0,0,7,0,0,0,0,7,0
7,7,14,14,7,7,7,0,0,0,0,0,0,0,0,7,0,0,0,0,7,0
0,0,0,0,0,0,15,0,0,0,0,0,0,0,0,7,15,7,7,7,7,0
0,0,0,0,0,0,7,0,0,0,0,0,0,0,0,15,0,0,0,0,7,0
38,0,0,0,0,0,7,7,14,7,14,7,14,7,7,7,0,0,0,0,14,0
0,0,0,0,0,0,0,0,0,0,0,0,0,0,0,7,0,0,0,0,7,0
0,0,0,0,0,0,0,0,0,0,0,0,0,0,0,7,7,15,7,7,7,0
0,0,0,0,0,0,0,0,0,0,0,0,0,0,0,7,0,0,0,0,7,0
0,0,0,0,0,0,0,0,0,0,0,0,0,0,0,7,0,0,0,0,7,0
0,0,0,0,0,0,0,0,0,0,0,0,0,0,0,7,0,0,0,0,7,0
0,0,0,0,0,0,0,0,0,0,0,0,0,0,0,14,0,0,0,0,14,0
0,0,38,0,0,0,0,0,0,0,0,38,0,0,0,7,0,0,0,0,7,0
0,0,0,0,0,0,0,0,0,0,0,0,0,0,0,7,0,0,0,0,7,0
0,0,0,0,0,0,0,0,0,0,0,0,0,0,0,7,0,0,0,0,7,0
0,0,0,0,0,0,0,0,0,0,0,0,0,0,0,7,7,14,7,7,7,0
endlayer

layer
0,0,0,0,0,0,0,0,0,0,0,0,0,0,0,0,0,0,0,0,0,0
13,0,0,0,13,0,0,0,0,0,13,0,0,0,0,13,0,0,0,0,13,0
29,0,29,0,0,29,0,0,0,0,0,0,0,0,0,0,0,0,0,0,0,0
7,7,7,7,7,7,7,14,7,14,7,14,7,14,7,7,7,7,7,7,7,0
7,0,0,0,0,7,0,0,30,0,30,0,30,0,28,7,0,30,0,0,7,0
14,0,0,0,0,7,34,0,0,0,0,0,0,0,0,7,0,0,0,0,14,0
7,0,0,0,0,7,0,0,0,0,0,0,0,0,0,7,0,0,0,0,7,0
7,7,14,14,7,7,7,0,0,0,0,0,0,0,28,7,0,29,0,0,7,0
30,0,0,0,0,30,7,0,0,0,0,0,0,0,0,7,7,7,7,7,7,0
0,0,0,0,0,0,7,0,0,29,0,29,0,29,0,7,34,0,0,0,7,0
0,0,0,0,0,0,7,7,14,7,14,7,14,7,7,7,0,0,0,0,14,0
0,0,0,0,0,0,0,0,0,0,0,0,0,0,0,7,0,29,0,0,7,0
0,0,0,0,0,0,0,0,0,0,0,0,0,0,28,7,7,7,7,7,7,34
0,0,0,0,0,0,0,0,0,0,0,0,0,0,0,7,30,0,0,30,7,0
0,0,0,0,0,0,0,0,0,0,0,0,0,0,0,7,0,0,0,0,7,0
0,0,0,0,0,0,0,0,0,0,0,0,0,0,0,7,0,0,0,0,7,0
0,0,0,0,0,0,0,0,0,0,0,0,0,0,0,14,0,0,0,0,14,0
0,0,0,0,0,0,0,0,0,0,0,0,0,0,0,7,0,0,0,0,7,0
0,0,0,0,0,0,0,0,0,0,0,0,0,0,0,7,0,0,0,0,7,0
0,0,0,0,0,0,0,0,0,0,0,0,0,0,0,7,29,0,0,29,7,0
0,0,0,0,0,0,0,0,0,0,0,0,0,0,28,7,7,14,7,7,7,34
endlayer

layer
0,0,0,0,0,0,0,0,0,0,0,0,0,0,0,0,0,0,0,0,0,0
41,41,41,41,41,41,41,41,41,41,41,41,41,41,41,41,41,41,41,41,41,0
42,42,42,42,42,42,42,42,42,42,42,42,42,42,42,42,42,42,42,42,42,0
7,7,7,7,7,7,7,7,7,7,7,7,7,7,7,7,7,7,7,7,7,0
7,0,0,0,0,7,7,34,0,0,0,0,0,0,0,7,0,0,0,0,7,0
7,34,0,0,28,7,7,0,0,0,0,0,0,0,0,7,0,0,0,28,7,0
7,0,0,0,0,7,7,0,0,0,0,0,0,0,0,7,0,0,0,0,7,0
7,7,7,7,7,7,7,0,0,0,0,0,0,0,0,7,0,0,0,0,7,0
0,0,0,0,0,0,7,34,0,0,0,0,0,0,0,7,7,7,7,7,7,0
0,0,0,0,0,0,7,0,0,0,0,0,0,0,0,7,0,0,0,0,7,0
0,0,0,0,0,0,7,7,7,7,7,7,7,7,7,7,0,0,0,28,7,0
0,0,0,0,0,0,43,43,43,43,43,43,43,43,43,7,0,0,0,0,7,0
0,0,0,0,0,0,0,0,0,0,0,0,0,0,16,7,7,7,7,7,7,40
0,0,0,0,0,0,0,0,0,0,0,0,0,0,16,6,0,0,0,0,6,40
0,0,0,0,0,0,0,0,0,0,0,0,0,0,16,6,0,0,0,0,6,40
0,0,0,0,0,0,0,0,0,0,0,0,0,0,16,6,0,0,0,0,6,40
0,0,0,0,0,0,0,0,0,0,0,0,0,0,16,6,0,0,0,0,6,40
0,0,0,0,0,0,0,0,0,0,0,0,0,0,16,6,0,0,0,0,6,40
0,0,0,0,0,0,0,0,0,0,0,0,0,0,16,6,0,0,0,0,6,40
0,0,0,0,0,0,0,0,0,0,0,0,0,0,16,6,0,0,0,0,6,40
0,0,0,0,0,0,0,0,0,0,0,0,0,0,16,7,7,7,7,7,7,40
endlayer

layer
0,0,0,0,0,0,0,0,0,0,0,0,0,0,0,0,0,0,0,0,0,0
0,0,0,0,0,0,0,0,0,0,0,0,0,0,0,0,0,0,0,0,0,0
0,0,0,0,0,0,0,0,0,0,0,0,0,0,0,0,0,0,0,0,0,0
42,42,42,42,42,42,42,42,42,42,42,42,42,42,42,42,42,42,42,42,42,0
7,0,0,0,0,7,7,0,0,0,0,0,0,0,0,7,0,0,0,0,7,0
7,0,0,0,0,7,7,0,0,0,0,0,0,0,0,7,0,0,0,0,7,0
7,0,0,0,0,7,7,0,0,0,0,0,0,0,0,7,34,0,0,0,7,0
17,17,17,17,17,17,7,0,0,0,0,0,0,0,0,7,0,0,0,0,7,0
0,0,0,0,0,0,7,0,0,0,0,0,0,0,0,7,17,17,17,17,17,0
0,0,0,0,0,0,7,0,0,0,0,0,0,0,0,7,41,41,41,41,41,0
0,0,0,0,0,0,17,17,17,17,17,17,17,17,17,7,41,41,41,41,41,0
0,0,0,0,0,0,0,0,0,0,0,0,0,0,0,7,41,41,41,41,41,0
0,0,0,0,0,0,0,0,0,0,0,0,0,0,0,16,7,7,7,7,40,0
0,0,0,0,0,0,0,0,0,0,0,0,0,0,0,16,6,0,0,6,40,0
0,0,0,0,0,0,0,0,0,0,0,0,0,0,0,16,6,0,0,6,40,0
0,0,0,0,0,0,0,0,0,0,0,0,0,0,0,16,6,0,0,6,40,0
0,0,0,0,0,0,0,0,0,0,0,0,0,0,0,16,6,0,0,6,40,0
0,0,0,0,0,0,0,0,0,0,0,0,0,0,0,16,6,0,0,6,40,0
0,0,0,0,0,0,0,0,0,0,0,0,0,0,0,16,6,0,0,6,40,0
0,0,0,0,0,0,0,0,0,0,0,0,0,0,0,16,6,0,0,6,40,0
0,0,0,0,0,0,0,0,0,0,0,0,0,0,0,16,7,7,7,7,40,0
endlayer

layer
0,0,0,0,0,0,0,0,0,0,0,0,0,0,0,0,0,0,0,0,0,0
0,0,0,0,0,0,0,0,0,0,0,0,0,0,0,0,0,0,0,0,0,0
0,0,0,0,0,0,0,0,0,0,0,0,0,0,0,0,0,0,0,0,0,0
0,0,0,0,0,0,0,0,0,0,0,0,0,0,0,0,0,0,0,0,0,0
42,42,42,42,42,42,42,42,42,42,42,42,42,42,42,42,42,42,42,42,42,0
7,6,6,6,6,7,7,0,0,0,0,0,0,0,0,7,0,0,0,0,7,0
17,17,17,17,17,17,7,0,0,0,0,0,0,0,0,7,0,0,0,0,7,0
0,0,0,0,0,0,7,0,0,0,0,0,0,0,0,7,17,17,17,17,17,0
0,0,0,0,0,0,7,0,0,0,0,0,0,0,0,7,0,0,0,0,0,0
0,0,0,0,0,0,17,17,17,17,17,17,17,17,17,17,0,0,0,0,0,0
0,0,0,0,0,0,0,0,0,0,0,0,0,0,0,7,0,0,0,0,0,0
0,0,0,0,0,0,0,0,0,0,0,0,0,0,0,0,0,29,29,0,0,0
0,0,0,0,0,0,0,0,0,0,0,0,0,0,0,0,16,7,7,40,0,0
0,0,0,0,0,0,0,0,0,0,0,0,0,0,0,0,16,6,6,40,0,0
0,0,0,0,0,0,0,0,0,0,0,0,0,0,0,0,16,6,6,40,0,0
0,0,0,0,0,0,0,0,0,0,0,0,0,0,0,0,16,6,6,40,0,0
0,0,0,0,0,0,0,0,0,0,0,0,0,0,0,0,16,6,6,40,0,0
0,0,0,0,0,0,0,0,0,0,0,0,0,0,0,0,16,6,6,40,0,0
0,0,0,0,0,0,0,0,0,0,0,0,0,0,0,0,16,6,6,40,0,0
0,0,0,0,0,0,0,0,0,0,0,0,0,0,0,0,16,6,6,40,0,0
0,0,0,0,0,0,0,0,0,0,0,0,0,0,0,0,16,7,7,40,0,0
endlayer

layer
0,0,0,0,0,0,0,0,0,0,0,0,0,0,0,0,0,0,0,0,0,0
0,0,0,0,0,0,0,0,0,0,0,0,0,0,0,0,0,0,0,0,0,0
0,0,0,0,0,0,0,0,0,0,0,0,0,0,0,0,0,0,0,0,0,0
0,0,0,0,0,0,0,0,0,0,0,0,0,0,0,0,0,0,0,0,0,0
0,0,0,0,0,0,0,0,0,0,0,0,0,0,0,0,0,0,0,0,0,0
38,0,0,0,0,38,42,42,42,42,42,42,42,42,42,42,42,42,42,42,42,0
0,0,0,0,0,0,7,0,0,0,0,0,0,0,0,7,17,17,17,17,17,0
0,0,0,0,0,0,7,0,0,0,0,0,0,0,0,7,34,0,0,0,0,0
0,0,0,0,0,0,17,17,17,17,17,17,17,17,17,17,0,0,0,0,0,0
0,0,0,0,0,0,0,0,0,0,0,0,0,0,0,0,0,0,0,0,0,0
0,0,0,0,0,0,0,0,0,0,0,0,0,0,0,7,0,0,0,0,0,0
0,0,0,0,0,0,0,0,0,0,0,0,0,0,0,0,0,0,0,0,0,0
0,0,0,0,0,0,0,0,0,0,0,0,0,0,0,0,0,16,40,0,0,0
0,0,0,0,0,0,0,0,0,0,0,0,0,0,0,0,0,16,40,0,0,0
0,0,0,0,0,0,0,0,0,0,0,0,0,0,0,0,0,16,40,0,0,0
0,0,0,0,0,0,0,0,0,0,0,0,0,0,0,0,0,16,40,0,0,0
0,0,0,0,0,0,0,0,0,0,0,0,0,0,0,0,0,16,40,0,0,0
0,0,0,0,0,0,0,0,0,0,0,0,0,0,0,0,0,16,40,0,0,0
0,0,0,0,0,0,0,0,0,0,0,0,0,0,0,0,0,16,40,0,0,0
0,0,0,0,0,0,0,0,0,0,0,0,0,0,0,0,0,16,40,0,0,0
0,0,0,0,0,0,0,0,0,0,0,0,0,0,0,0,0,16,40,0,0,0
endlayer

layer
0,0,0,0,0,0,0,0,0,0,0,0,0,0,0,0,0,0,0,0,0,0
0,0,0,0,0,0,0,0,0,0,0,0,0,0,0,0,0,0,0,0,0,0
0,0,0,0,0,0,0,0,0,0,0,0,0,0,0,0,0,0,0,0,0,0
0,0,0,0,0,0,0,0,0,0,0,0,0,0,0,0,0,0,0,0,0,0
0,0,0,0,0,0,0,0,0,0,0,0,0,0,0,0,0,0,0,0,0,0
0,0,0,0,0,0,0,0,0,0,0,0,0,0,0,0,0,0,0,0,0,0
0,0,0,0,0,0,42,42,42,42,42,42,42,42,42,42,0,0,0,0,0,0
0,0,0,0,0,0,17,17,17,17,17,17,17,17,17,17,0,0,0,0,0,0
0,0,0,0,0,0,0,0,0,0,0,0,0,0,0,0,0,0,0,0,0,0
0,0,0,0,0,0,0,0,0,0,0,0,0,0,0,0,0,0,0,0,0,0
0,0,0,0,0,0,0,0,0,0,0,0,0,0,0,7,0,0,0,0,0,0
0,0,0,0,0,0,0,0,0,0,0,0,0,0,0,0,0,0,0,0,0,0
0,0,0,0,0,0,0,0,0,0,0,0,0,0,0,0,0,0,0,0,0,0
0,0,0,0,0,0,0,0,0,0,0,0,0,0,0,0,0,0,0,0,0,0
0,0,0,0,0,0,0,0,0,0,0,0,0,0,0,0,0,0,0,0,0,0
0,0,0,0,0,0,0,0,0,0,0,0,0,0,0,0,0,0,0,0,0,0
0,0,0,0,0,0,0,0,0,0,0,0,0,0,0,0,0,0,0,0,0,0
0,0,0,0,0,0,0,0,0,0,0,0,0,0,0,0,0,0,0,0,0,0
0,0,0,0,0,0,0,0,0,0,0,0,0,0,0,0,0,0,0,0,0,0
0,0,0,0,0,0,0,0,0,0,0,0,0,0,0,0,0,0,0,0,0,0
0,0,0,0,0,0,0,0,0,0,0,0,0,0,0,0,0,0,0,0,0,0
endlayer

layer
0,0,0,0,0,0,0,0,0,0,0,0,0,0,0,0,0,0,0,0,0,0
0,0,0,0,0,0,0,0,0,0,0,0,0,0,0,0,0,0,0,0,0,0
0,0,0,0,0,0,0,0,0,0,0,0,0,0,0,0,0,0,0,0,0,0
0,0,0,0,0,0,0,0,0,0,0,0,0,0,0,0,0,0,0,0,0,0
0,0,0,0,0,0,0,0,0,0,0,0,0,0,0,0,0,0,0,0,0,0
0,0,0,0,0,0,0,0,0,0,0,0,0,0,0,0,0,0,0,0,0,0
0,0,0,0,0,0,0,0,0,0,0,0,0,0,0,0,0,0,0,0,0,0
0,0,0,0,0,0,0,0,0,0,0,0,0,0,0,0,0,0,0,0,0,0
0,0,0,0,0,0,0,0,0,0,0,0,0,0,0,0,0,0,0,0,0,0
0,0,0,0,0,0,0,0,0,0,0,0,0,0,0,0,0,0,0,0,0,0
0,0,0,0,0,0,0,0,0,0,0,0,0,0,0,7,0,0,0,0,0,0
0,0,0,0,0,0,0,0,0,0,0,0,0,0,0,0,0,0,0,0,0,0
0,0,0,0,0,0,0,0,0,0,0,0,0,0,0,0,0,0,0,0,0,0
0,0,0,0,0,0,0,0,0,0,0,0,0,0,0,0,0,0,0,0,0,0
0,0,0,0,0,0,0,0,0,0,0,0,0,0,0,0,0,0,0,0,0,0
0,0,0,0,0,0,0,0,0,0,0,0,0,0,0,0,0,0,0,0,0,0
0,0,0,0,0,0,0,0,0,0,0,0,0,0,0,0,0,0,0,0,0,0
0,0,0,0,0,0,0,0,0,0,0,0,0,0,0,0,0,0,0,0,0,0
0,0,0,0,0,0,0,0,0,0,0,0,0,0,0,0,0,0,0,0,0,0
0,0,0,0,0,0,0,0,0,0,0,0,0,0,0,0,0,0,0,0,0,0
0,0,0,0,0,0,0,0,0,0,0,0,0,0,0,0,0,0,0,0,0,0
endlayer

layer
0,0,0,0,0,0,0,0,0,0,0,0,0,0,0,0,0,0,0,0,0,0
0,0,0,0,0,0,0,0,0,0,0,0,0,0,0,0,0,0,0,0,0,0
0,0,0,0,0,0,0,0,0,0,0,0,0,0,0,0,0,0,0,0,0,0
0,0,0,0,0,0,0,0,0,0,0,0,0,0,0,0,0,0,0,0,0,0
0,0,0,0,0,0,0,0,0,0,0,0,0,0,0,0,0,0,0,0,0,0
0,0,0,0,0,0,0,0,0,0,0,0,0,0,0,0,0,0,0,0,0,0
0,0,0,0,0,0,0,0,0,0,0,0,0,0,0,0,0,0,0,0,0,0
0,0,0,0,0,0,0,0,0,0,0,0,0,0,0,0,0,0,0,0,0,0
0,0,0,0,0,0,0,0,0,0,0,0,0,0,0,0,0,0,0,0,0,0
0,0,0,0,0,0,0,0,0,0,0,0,0,0,0,0,0,0,0,0,0,0
0,0,0,0,0,0,0,0,0,0,0,0,0,0,0,7,0,0,0,0,0,0
0,0,0,0,0,0,0,0,0,0,0,0,0,0,0,0,0,0,0,0,0,0
0,0,0,0,0,0,0,0,0,0,0,0,0,0,0,0,0,0,0,0,0,0
0,0,0,0,0,0,0,0,0,0,0,0,0,0,0,0,0,0,0,0,0,0
0,0,0,0,0,0,0,0,0,0,0,0,0,0,0,0,0,0,0,0,0,0
0,0,0,0,0,0,0,0,0,0,0,0,0,0,0,0,0,0,0,0,0,0
0,0,0,0,0,0,0,0,0,0,0,0,0,0,0,0,0,0,0,0,0,0
0,0,0,0,0,0,0,0,0,0,0,0,0,0,0,0,0,0,0,0,0,0
0,0,0,0,0,0,0,0,0,0,0,0,0,0,0,0,0,0,0,0,0,0
0,0,0,0,0,0,0,0,0,0,0,0,0,0,0,0,0,0,0,0,0,0
0,0,0,0,0,0,0,0,0,0,0,0,0,0,0,0,0,0,0,0,0,0
endlayer

layer
0,0,0,0,0,0,0,0,0,0,0,0,0,0,0,0,0,0,0,0,0,0
0,0,0,0,0,0,0,0,0,0,0,0,0,0,0,0,0,0,0,0,0,0
0,0,0,0,0,0,0,0,0,0,0,0,0,0,0,0,0,0,0,0,0,0
0,0,0,0,0,0,0,0,0,0,0,0,0,0,0,0,0,0,0,0,0,0
0,0,0,0,0,0,0,0,0,0,0,0,0,0,0,0,0,0,0,0,0,0
0,0,0,0,0,0,0,0,0,0,0,0,0,0,0,0,0,0,0,0,0,0
0,0,0,0,0,0,0,0,0,0,0,0,0,0,0,0,0,0,0,0,0,0
0,0,0,0,0,0,0,0,0,0,0,0,0,0,0,0,0,0,0,0,0,0
0,0,0,0,0,0,0,0,0,0,0,0,0,0,0,0,0,0,0,0,0,0
0,0,0,0,0,0,0,0,0,0,0,0,0,0,0,0,0,0,0,0,0,0
0,0,0,0,0,0,0,0,0,0,0,0,0,0,0,7,0,0,0,0,0,0
0,0,0,0,0,0,0,0,0,0,0,0,0,0,0,0,0,0,0,0,0,0
0,0,0,0,0,0,0,0,0,0,0,0,0,0,0,0,0,0,0,0,0,0
0,0,0,0,0,0,0,0,0,0,0,0,0,0,0,0,0,0,0,0,0,0
0,0,0,0,0,0,0,0,0,0,0,0,0,0,0,0,0,0,0,0,0,0
0,0,0,0,0,0,0,0,0,0,0,0,0,0,0,0,0,0,0,0,0,0
0,0,0,0,0,0,0,0,0,0,0,0,0,0,0,0,0,0,0,0,0,0
0,0,0,0,0,0,0,0,0,0,0,0,0,0,0,0,0,0,0,0,0,0
0,0,0,0,0,0,0,0,0,0,0,0,0,0,0,0,0,0,0,0,0,0
0,0,0,0,0,0,0,0,0,0,0,0,0,0,0,0,0,0,0,0,0,0
0,0,0,0,0,0,0,0,0,0,0,0,0,0,0,0,0,0,0,0,0,0
endlayer

layer
0,0,0,0,0,0,0,0,0,0,0,0,0,0,0,0,0,0,0,0,0,0
0,0,0,0,0,0,0,0,0,0,0,0,0,0,0,0,0,0,0,0,0,0
0,0,0,0,0,0,0,0,0,0,0,0,0,0,0,0,0,0,0,0,0,0
0,0,0,0,0,0,0,0,0,0,0,0,0,0,0,0,0,0,0,0,0,0
0,0,0,0,0,0,0,0,0,0,0,0,0,0,0,0,0,0,0,0,0,0
0,0,0,0,0,0,0,0,0,0,0,0,0,0,0,0,0,0,0,0,0,0
0,0,0,0,0,0,0,0,0,0,0,0,0,0,0,0,0,0,0,0,0,0
0,0,0,0,0,0,0,0,0,0,0,0,0,0,0,0,0,0,0,0,0,0
0,0,0,0,0,0,0,0,0,0,0,0,0,0,0,0,0,0,0,0,0,0
0,0,0,0,0,0,0,0,0,0,0,0,0,0,0,0,0,0,0,0,0,0
0,0,0,0,0,0,0,0,0,0,0,0,0,0,0,38,0,0,0,0,0,0
0,0,0,0,0,0,0,0,0,0,0,0,0,0,0,0,0,0,0,0,0,0
0,0,0,0,0,0,0,0,0,0,0,0,0,0,0,0,0,0,0,0,0,0
0,0,0,0,0,0,0,0,0,0,0,0,0,0,0,0,0,0,0,0,0,0
0,0,0,0,0,0,0,0,0,0,0,0,0,0,0,0,0,0,0,0,0,0
0,0,0,0,0,0,0,0,0,0,0,0,0,0,0,0,0,0,0,0,0,0
0,0,0,0,0,0,0,0,0,0,0,0,0,0,0,0,0,0,0,0,0,0
0,0,0,0,0,0,0,0,0,0,0,0,0,0,0,0,0,0,0,0,0,0
0,0,0,0,0,0,0,0,0,0,0,0,0,0,0,0,0,0,0,0,0,0
0,0,0,0,0,0,0,0,0,0,0,0,0,0,0,0,0,0,0,0,0,0
0,0,0,0,0,0,0,0,0,0,0,0,0,0,0,0,0,0,0,0,0,0
endlayer

