# Converted from schematic
# author:MohawkyMagoo

weight=10
embed_into_distance=1
#acceptable_target_blocks=1,2,3,12,13
dimensions=16,28,32
#allowable_overhang=0
max_cut_in=2
#cut_in_buffer=1
max_leveling=2
#leveling_buffer=1
#preserve_water=0
#preserve_lava=0
#preserve_plants=0


rule1=0,100,4
rule2=0,100,1
rule3=0,100,3
rule4=0,100,2
rule5=0,100,98
rule6=0,100,13
rule7=0,100,109-0
rule8=0,100,17
rule9=0,100,64-2
rule10=0,100,102
rule11=0,100,50-3
rule12=0,100,64-8
rule13=0,100,50-4
rule14=0,100,5
rule15=0,100,37
rule16=0,100,31-1
rule17=0,100,17-2
rule18=0,100,109-3
rule19=0,100,64-0
rule20=0,100,65-4
rule21=0,100,109-2
rule22=0,100,64
rule23=0,100,85
rule24=0,100,64-1
rule25=0,100,54-3
rule26=0,100,64-9
rule27=0,100,18
rule28=0,100,54-5
rule29=0,100,53-1
rule30=0,100,64-3
rule31=0,100,54-4
rule32=0,100,54-2
rule33=0,100,72
rule34=0,100,20
rule35=0,100,18-2
rule36=0,100,64-9
rule37=0,100,50-1
rule38=0,100,58
rule39=0,100,53-3
rule40=0,100,50-2
rule41=0,100,109-5
rule42=0,100,109-4
rule43=0,100,17-4
rule44=0,100,44-3
rule45=0,100,50-5
rule46=0,100,47
rule47=0,100,53-0
rule48=0,100,126
rule49=0,100,53-2


layer
1,1,1,1,1,1,1,1,1,1,1,1,1,1,1,1,1,1,1,1,1,1,1,1,1,1,1,1,1,1,1,1
1,1,1,3,3,3,3,3,3,3,3,3,2,2,3,3,3,3,3,3,3,3,3,2,2,2,2,2,2,1,1,1
1,1,1,1,1,3,3,3,3,3,3,3,3,2,3,3,2,2,3,3,3,3,2,2,2,2,2,2,2,2,1,1
1,1,1,1,1,1,1,1,1,1,3,2,3,3,2,3,3,3,3,3,3,3,2,2,2,2,2,2,2,2,2,1
1,1,1,1,1,1,1,1,1,1,3,3,2,3,3,3,3,2,3,3,3,2,2,2,2,2,2,2,2,2,2,1
1,1,1,1,1,1,1,1,1,1,2,2,2,3,2,3,2,2,3,3,3,2,2,2,2,2,2,2,2,2,2,1
1,1,1,1,1,1,1,1,1,1,2,2,2,3,3,2,3,3,3,3,3,2,2,2,2,2,2,2,2,2,2,1
1,1,1,3,3,3,2,2,2,2,2,2,2,3,3,3,2,3,3,3,3,2,2,2,2,2,2,2,2,2,2,1
1,1,1,3,1,3,3,2,3,3,3,3,2,2,3,3,3,3,3,3,2,2,2,2,2,2,2,2,2,2,2,1
1,1,1,3,1,3,3,3,3,2,2,3,2,3,2,3,3,3,3,3,2,2,2,2,2,2,2,2,2,2,2,1
1,1,1,3,1,1,3,3,3,2,3,3,3,3,2,3,3,3,2,3,2,2,2,2,2,2,2,2,2,2,2,1
1,1,1,3,1,1,3,3,3,2,3,2,3,3,3,2,2,3,3,2,2,2,2,2,3,3,2,2,2,2,2,1
1,1,1,3,1,1,3,3,3,3,3,3,3,3,2,2,2,2,2,2,3,2,2,2,3,3,3,3,2,2,2,1
1,1,1,3,3,3,3,3,3,3,3,3,2,2,2,3,3,2,3,2,2,2,2,2,3,3,3,3,3,2,2,1
1,1,1,3,3,3,3,3,3,3,3,3,3,3,3,2,2,2,2,2,2,2,2,2,3,3,3,3,3,2,2,1
1,1,1,3,3,3,3,3,3,3,3,3,3,3,3,2,2,2,2,2,2,2,2,2,2,3,3,3,3,3,2,1
1,1,1,3,3,3,3,3,3,3,3,3,3,3,3,3,2,2,2,2,2,2,2,2,2,3,3,3,3,3,2,1
1,1,1,3,4,4,4,4,4,4,3,3,3,3,3,3,3,2,2,2,2,2,2,2,2,2,3,3,3,3,3,1
1,1,1,3,4,4,4,4,4,4,3,3,3,3,3,3,3,3,2,2,2,2,2,2,2,2,2,3,3,3,3,1
1,1,1,3,4,4,4,4,4,4,3,3,3,3,3,3,3,3,3,3,3,3,3,2,2,2,2,2,2,3,2,1
1,1,1,3,4,4,4,4,4,3,3,3,3,3,3,3,3,3,3,3,3,3,2,2,2,2,2,2,2,2,2,1
1,1,1,3,4,4,4,4,4,4,3,1,3,3,3,3,3,3,3,3,3,3,2,2,2,2,2,2,2,2,2,1
1,1,1,3,4,4,4,4,4,4,3,1,1,1,1,1,1,3,3,3,3,3,2,2,2,2,2,2,2,2,2,1
1,1,1,3,4,4,4,4,4,4,1,1,1,1,1,1,1,1,1,1,3,3,2,2,3,3,3,3,3,3,2,1
1,1,1,3,4,4,4,4,4,4,1,1,1,1,1,1,1,1,1,1,1,1,1,1,1,1,1,1,1,1,1,1
1,1,1,3,4,4,4,4,4,4,1,1,1,1,1,1,1,1,1,1,1,1,1,1,1,1,1,1,1,1,1,1
1,1,1,3,4,4,4,4,4,4,1,1,1,1,1,1,1,1,1,1,1,1,1,1,1,1,1,1,1,1,1,1
1,1,1,1,1,1,1,1,1,1,1,1,1,1,1,1,1,1,1,1,1,1,1,1,1,1,1,1,1,1,1,1
endlayer

layer
0,0,7,5,5,5,5,5,5,5,5,5,5,5,5,5,5,5,5,5,5,5,5,5,5,5,5,5,5,5,5,5
0,0,7,5,5,5,3,3,3,3,3,3,3,3,3,3,3,3,3,3,3,3,3,3,3,3,3,3,2,5,5,5
0,0,5,5,5,5,5,5,5,5,3,3,3,3,3,3,3,3,3,3,3,3,3,3,3,3,3,2,2,6,5,5
0,0,9,0,0,0,0,0,0,0,5,3,3,3,3,3,3,3,3,3,3,3,3,3,3,3,3,2,2,6,6,5
0,0,5,0,0,0,0,0,0,0,5,3,3,3,3,3,3,3,3,3,3,3,3,3,3,3,2,2,2,6,6,5
0,0,10,0,0,0,0,0,0,0,5,3,3,3,3,3,3,3,3,3,3,3,3,3,3,3,2,2,2,2,6,5
0,0,5,0,0,0,0,0,0,0,5,3,3,3,3,3,3,3,3,3,3,3,3,3,3,3,2,2,2,2,2,5
0,0,5,5,5,5,5,5,5,5,3,3,3,3,3,3,3,3,3,3,3,3,3,3,3,3,2,2,2,2,2,5
0,0,5,5,5,5,5,5,5,5,3,3,3,3,3,3,3,3,3,3,3,3,3,3,2,3,2,2,2,2,2,5
0,0,5,5,5,5,5,5,5,5,3,3,3,3,3,3,3,3,3,3,3,3,3,2,2,3,2,2,3,2,2,5
0,0,5,5,5,5,5,5,5,5,3,3,3,3,3,3,3,3,3,3,3,2,3,3,3,3,3,3,3,3,2,5
0,0,5,5,5,5,5,5,5,5,3,3,3,3,3,3,3,3,3,3,3,3,2,3,3,3,3,2,2,2,3,5
0,0,5,5,5,5,5,5,5,5,3,3,3,3,3,3,3,3,3,3,3,2,2,3,3,3,3,3,2,2,2,5
0,0,5,5,5,5,5,5,5,5,5,3,3,3,3,3,3,3,3,3,3,3,3,2,3,3,3,3,3,2,2,5
0,0,5,5,5,5,5,5,5,5,5,5,3,3,3,3,3,3,3,3,3,3,3,3,3,3,3,3,3,2,2,5
0,0,7,5,5,5,5,5,5,5,5,5,3,3,3,3,3,3,3,3,3,3,3,3,3,3,3,3,3,3,2,5
0,0,7,5,5,5,5,5,5,5,5,5,3,3,3,3,3,3,3,3,3,3,3,3,3,3,3,3,3,3,3,5
0,0,0,5,0,0,0,0,0,0,5,5,5,5,5,5,3,3,3,3,3,3,3,3,3,3,3,3,3,3,3,5
0,0,0,5,0,0,0,0,0,0,5,5,5,5,5,5,3,3,3,3,3,3,3,3,3,3,3,3,3,3,3,5
0,0,0,5,0,0,0,0,0,0,5,5,5,5,5,5,3,3,3,3,3,3,3,3,3,3,3,3,3,3,3,5
0,0,0,5,0,0,0,0,0,8,5,5,5,5,5,5,3,3,3,3,3,3,3,3,3,3,3,3,3,3,3,5
0,0,0,5,0,0,0,0,0,0,5,5,5,5,5,5,3,3,3,3,3,3,3,3,3,3,3,3,3,3,3,5
0,0,0,5,0,0,0,0,0,0,5,0,7,5,5,5,5,3,3,3,3,3,3,3,3,3,3,3,3,3,3,5
0,0,0,5,0,0,0,0,0,0,5,0,0,0,0,0,5,5,5,5,3,3,3,3,3,3,3,3,3,3,3,5
0,0,0,5,0,0,0,0,0,0,5,0,0,0,0,0,5,5,5,5,5,5,5,5,5,5,5,5,5,5,5,5
0,0,0,5,0,0,0,0,0,0,5,0,0,0,0,0,5,0,0,0,0,0,0,0,0,0,0,0,0,5,5,5
0,0,0,5,0,0,0,0,0,0,5,0,0,0,0,0,0,0,0,0,0,0,0,0,0,0,0,0,0,5,5,5
0,0,0,5,5,5,5,5,5,5,5,5,5,5,5,5,5,5,5,5,5,5,5,5,5,5,5,5,5,5,5,5
endlayer

layer
0,0,0,7,5,5,5,5,5,5,5,5,5,5,5,5,5,5,5,5,5,5,5,5,5,5,5,5,5,5,5,5
0,0,0,7,5,5,5,5,5,5,5,3,3,3,3,3,3,3,3,3,3,3,3,3,3,3,3,3,3,5,3,5
0,0,5,5,5,5,5,5,5,5,5,3,3,3,3,3,3,3,3,3,3,3,3,3,3,3,3,3,3,6,3,5
0,0,12,0,0,0,0,0,0,0,5,3,3,3,3,3,3,3,3,3,3,3,3,3,3,3,3,3,2,6,6,5
0,0,5,0,0,0,0,0,0,0,5,3,3,3,3,3,3,3,3,3,3,3,3,3,3,3,3,3,2,3,6,5
0,0,10,0,0,0,0,0,0,0,5,3,3,3,3,3,3,3,3,3,3,3,3,3,3,3,3,3,3,3,6,5
0,0,5,0,0,0,0,0,0,0,5,3,3,3,3,3,5,5,5,5,5,3,3,3,3,3,3,3,2,3,2,5
0,0,5,5,5,5,5,5,5,5,3,3,3,3,3,3,5,5,5,5,5,3,3,3,3,3,2,3,3,2,2,5
0,0,5,5,5,5,5,5,5,5,3,3,3,3,3,3,5,5,5,5,5,3,3,3,3,3,3,3,2,2,2,5
0,0,5,5,5,5,5,5,5,5,3,3,3,3,3,3,5,5,5,5,5,3,3,3,3,3,3,3,3,3,3,5
0,0,5,5,5,5,5,5,5,5,3,3,3,3,3,3,5,5,5,5,5,3,3,3,3,3,3,3,3,3,3,5
0,0,5,5,5,5,5,5,5,5,3,3,3,3,3,3,5,5,5,5,5,3,3,3,3,3,3,3,3,3,3,5
0,0,5,5,5,5,5,5,5,5,3,3,3,3,3,3,5,5,5,5,5,3,3,3,3,3,3,3,3,3,3,5
0,0,5,5,5,5,5,5,5,5,5,3,3,3,3,3,3,3,3,3,3,3,3,3,3,3,3,3,3,3,3,5
0,0,5,5,5,5,5,5,5,5,5,5,5,5,5,5,3,3,3,3,3,3,3,3,3,3,3,3,3,3,3,5
0,0,0,7,5,5,5,5,5,5,5,5,5,5,5,5,3,3,3,3,3,3,3,3,3,3,3,3,3,3,3,5
0,0,0,7,5,5,5,5,5,5,5,5,5,5,5,5,3,3,3,3,3,3,3,3,3,3,3,3,3,3,3,5
0,0,0,0,11,0,0,11,0,0,5,5,5,5,5,5,3,3,3,3,3,3,3,3,3,3,3,3,3,3,3,5
0,0,0,0,0,0,0,0,0,0,5,5,5,5,5,5,5,3,3,3,3,3,3,3,3,3,3,3,3,3,3,5
0,0,0,0,0,0,0,0,0,0,5,5,5,5,5,5,5,3,3,3,3,3,3,3,3,3,3,3,3,3,3,5
0,0,0,0,0,0,0,0,0,8,5,5,5,5,5,5,5,3,3,3,3,3,3,3,3,3,3,3,3,3,3,5
0,0,0,0,0,0,0,0,0,0,5,5,5,5,5,5,3,3,3,3,3,3,3,3,3,3,3,3,3,3,3,5
0,0,0,0,0,0,0,0,0,0,5,0,0,7,5,5,5,3,3,3,3,3,3,3,3,3,3,3,3,3,3,5
0,0,0,0,0,0,0,0,0,0,5,0,0,0,0,0,5,5,5,5,3,3,3,3,3,3,3,3,3,3,3,5
0,0,0,0,0,0,0,0,0,0,5,0,0,0,0,0,5,5,5,5,5,5,5,5,5,5,5,5,5,5,5,5
0,0,0,0,0,0,0,0,0,0,5,0,0,0,0,0,5,0,0,0,0,0,0,0,0,0,0,0,0,5,5,5
0,0,0,0,0,0,0,0,0,0,5,0,0,0,0,0,0,0,0,0,0,0,0,0,0,0,0,0,0,5,5,5
0,0,0,0,0,0,0,0,0,0,5,5,5,5,5,5,5,5,5,5,5,5,5,5,5,5,5,5,5,5,5,5
endlayer

layer
0,0,0,0,7,5,5,5,5,5,5,5,5,5,5,5,5,5,5,5,5,5,5,5,5,5,5,5,5,5,5,5
0,0,0,0,7,5,5,5,5,5,5,5,5,5,5,5,5,5,5,5,5,5,3,3,3,3,3,3,3,3,3,5
0,0,5,5,5,5,5,5,5,5,5,5,5,5,5,5,5,5,5,5,5,5,3,3,3,3,3,3,3,3,3,5
0,0,5,0,11,0,0,0,0,11,5,5,5,5,5,5,5,5,5,5,5,5,3,3,3,3,3,3,3,3,3,5
0,0,5,0,0,0,0,0,0,0,5,5,5,5,5,5,5,5,5,5,5,5,3,3,3,3,3,3,3,3,3,5
0,0,10,0,0,0,0,0,0,0,5,5,5,5,5,5,5,5,5,5,5,5,3,3,3,3,3,3,3,3,3,5
0,0,5,0,13,0,0,0,0,13,5,5,5,5,5,5,5,5,5,5,5,3,3,3,3,3,3,3,3,3,3,5
0,0,5,5,5,5,5,5,5,5,3,5,5,5,5,5,5,5,5,5,5,3,3,3,3,3,3,3,3,3,3,5
0,0,5,5,5,5,5,5,5,5,3,5,5,5,5,5,5,5,5,5,5,3,3,3,3,3,3,3,3,3,3,5
0,0,5,5,5,5,5,5,5,5,3,5,5,5,5,5,5,5,5,5,5,3,3,3,3,3,3,3,3,3,3,5
0,0,5,5,5,5,5,5,5,5,3,5,5,5,5,5,5,5,5,5,5,3,3,3,3,3,3,3,3,3,3,5
0,0,5,5,5,5,5,5,5,5,3,5,5,5,5,5,5,5,5,5,5,3,3,3,3,3,3,3,3,3,3,5
0,0,5,5,5,5,5,5,5,5,3,3,5,5,5,5,5,5,5,5,5,3,3,3,3,3,3,3,3,3,3,5
0,0,5,5,5,5,5,5,5,5,5,5,5,5,5,5,5,5,5,5,3,3,3,3,3,3,3,3,3,3,3,5
0,0,5,5,5,5,5,5,5,5,5,5,5,5,5,5,5,5,5,5,3,3,3,3,3,3,3,3,3,3,3,5
0,0,0,0,0,0,0,0,7,5,5,5,5,5,5,5,5,5,5,5,3,3,3,3,3,3,3,3,3,3,3,5
0,0,0,0,0,0,0,0,7,5,5,5,5,5,5,5,5,5,5,5,3,3,3,3,3,3,3,5,5,5,5,5
0,0,0,0,0,0,0,0,0,0,5,5,5,5,5,5,5,5,5,5,5,5,5,5,3,3,3,5,5,5,5,5
0,0,0,0,0,0,0,0,0,0,5,5,5,5,5,5,5,5,5,5,5,5,5,5,3,3,3,5,5,5,5,5
0,0,0,0,0,0,0,0,0,0,5,5,5,5,5,5,5,5,4,4,4,4,3,3,3,3,3,3,3,3,5,5
0,0,0,0,0,0,0,0,0,8,5,5,5,5,5,5,5,5,4,4,4,4,3,3,3,3,3,3,3,3,5,5
0,0,0,0,0,0,0,0,0,0,5,5,5,5,5,5,5,5,4,4,3,4,3,3,3,3,3,3,3,3,5,5
0,0,0,0,0,0,0,0,0,0,5,0,0,0,7,5,5,5,5,5,5,5,3,3,3,3,3,3,3,3,5,5
0,0,0,0,0,0,0,0,0,0,5,5,5,5,5,5,5,5,5,5,5,5,3,3,3,3,3,3,3,3,5,5
0,0,0,0,0,0,0,0,0,0,5,5,5,5,5,5,5,5,5,5,5,5,5,5,5,5,5,5,5,5,5,5
0,0,0,0,0,0,0,0,0,0,5,5,5,5,5,5,5,5,5,5,5,5,5,5,5,5,5,5,5,5,5,5
0,0,0,0,0,0,0,0,0,0,5,5,5,5,5,5,5,5,5,5,5,5,5,5,5,5,5,5,5,5,5,5
0,0,0,0,0,0,0,0,0,0,5,5,5,5,5,5,5,5,5,5,5,5,5,5,5,5,5,5,5,5,5,5
endlayer

layer
0,0,0,0,0,7,5,5,5,5,5,5,5,5,5,5,5,5,5,5,5,5,5,5,5,5,5,5,5,5,5,5
0,0,0,0,0,7,5,5,5,5,5,5,5,5,5,5,5,5,5,5,5,5,5,5,5,5,5,5,5,5,5,5
0,0,5,5,5,5,5,5,5,5,5,5,5,5,5,5,5,5,5,5,5,5,5,5,5,5,5,5,5,5,5,5
0,0,5,5,5,5,5,5,5,5,5,5,5,5,5,5,5,5,5,5,5,5,5,5,5,5,5,5,5,5,5,5
0,0,5,5,5,5,5,5,5,5,5,5,5,5,5,5,5,5,5,5,5,5,5,5,5,5,5,5,5,5,5,5
0,0,5,5,5,5,5,5,5,5,5,5,5,5,5,5,5,5,5,5,5,5,5,5,5,5,5,5,5,5,5,5
0,0,5,5,5,5,5,5,5,5,5,5,5,5,5,5,5,5,5,5,5,5,5,5,5,5,5,5,5,5,5,5
0,0,5,5,5,5,5,5,5,5,5,5,5,5,5,5,5,5,5,5,5,5,5,5,5,5,5,5,5,5,5,5
0,0,5,0,0,0,0,0,0,5,5,5,5,5,5,5,5,5,5,5,5,5,5,5,3,3,3,5,5,5,5,5
0,0,5,0,0,0,0,0,0,5,5,5,5,5,5,5,5,5,5,5,5,5,5,5,3,3,3,5,5,5,5,5
0,0,5,0,0,0,0,0,0,7,5,5,5,5,5,5,5,5,5,5,5,5,5,5,3,3,3,5,5,5,5,5
0,0,5,0,0,0,0,0,0,5,5,5,5,5,5,5,5,5,5,5,5,5,5,5,3,3,3,5,5,5,5,5
0,0,5,0,0,0,0,5,5,5,5,5,5,5,5,5,5,5,5,5,5,5,5,5,3,3,3,5,5,5,5,5
0,0,5,0,0,0,5,5,5,5,5,5,5,5,5,5,5,5,5,5,5,5,5,5,3,3,3,5,5,5,5,5
0,0,5,5,5,5,5,5,5,18,18,18,18,18,18,18,18,18,18,18,5,5,5,5,3,3,3,5,5,5,5,5
0,0,0,0,0,0,0,0,0,0,0,0,0,0,0,0,0,0,0,0,5,5,5,5,3,3,3,5,5,5,5,5
0,0,0,0,0,0,0,0,0,0,0,0,0,0,0,0,0,0,0,0,5,5,5,5,3,3,3,5,5,5,5,5
0,0,0,0,0,0,0,0,0,0,5,5,5,5,5,5,0,0,0,0,0,0,7,5,5,5,5,5,5,5,5,5
0,0,0,0,0,0,0,0,0,0,5,5,0,0,20,5,0,0,0,0,0,0,7,5,5,5,5,5,5,5,5,5
0,0,0,0,0,0,0,0,0,0,5,5,0,0,0,19,0,0,0,16,15,0,5,5,5,5,5,5,5,5,5,5
0,0,0,0,0,0,0,0,0,8,5,5,0,0,0,5,0,0,15,16,16,0,5,5,5,5,5,5,5,5,5,5
0,0,0,0,0,0,0,0,0,0,5,5,5,5,5,5,0,0,0,0,17,0,5,14,14,5,14,14,14,5,5,5
0,0,0,0,0,0,0,0,0,0,5,0,0,0,0,0,0,0,0,0,0,0,5,14,14,5,14,14,14,5,5,5
0,0,0,0,0,0,0,0,0,0,5,0,0,0,0,0,0,0,0,0,0,0,5,14,14,5,14,14,14,5,5,5
0,0,0,0,0,0,0,0,0,0,5,0,0,0,0,0,0,0,0,0,0,0,5,14,14,14,14,14,14,14,5,5
0,0,0,0,0,0,0,0,0,0,5,0,0,0,0,0,0,0,0,0,0,0,5,14,14,14,14,14,14,14,5,5
0,0,0,0,0,0,0,0,0,0,5,0,0,0,0,0,0,0,0,0,0,0,5,14,14,14,14,14,14,14,5,5
0,0,0,0,0,0,0,0,0,0,5,5,5,5,5,5,5,5,5,5,5,5,5,5,5,5,5,5,5,5,5,5
endlayer

layer
0,0,0,0,0,0,0,0,0,0,0,0,0,0,0,0,0,0,0,0,0,0,0,0,0,0,0,0,0,0,0,0
0,0,0,0,0,0,0,0,0,0,0,0,0,0,0,0,0,0,0,0,0,0,0,0,0,0,0,0,0,0,0,0
0,0,5,5,5,5,30,5,5,5,5,5,5,5,22,5,5,5,5,22,5,0,0,0,0,0,0,0,0,0,0,0
0,0,5,0,0,0,0,0,0,28,5,0,0,0,0,5,0,0,0,0,5,0,0,0,0,0,0,0,0,0,0,0
0,0,5,32,0,0,0,0,0,0,5,0,0,0,0,5,0,25,0,0,5,0,0,0,0,0,0,0,0,0,0,0
0,0,5,0,0,0,0,0,0,0,5,0,0,0,0,5,0,0,0,0,5,0,0,0,0,0,0,0,0,0,0,0
0,0,5,0,0,31,31,0,0,0,5,5,5,5,22,5,5,5,22,5,5,0,0,0,0,0,0,0,0,0,0,0
0,0,5,5,5,5,5,5,5,5,0,0,0,0,0,0,5,0,0,0,5,0,0,0,0,0,0,0,0,0,0,0
0,0,5,0,0,0,0,0,0,5,0,0,0,0,0,0,5,0,0,0,5,0,0,0,5,5,5,5,5,5,21,21
0,0,10,0,0,0,0,0,0,5,0,0,0,0,0,0,9,0,0,0,5,0,0,0,5,3,3,5,5,5,5,5
0,0,5,0,0,0,0,0,0,0,9,0,0,0,0,0,5,0,0,0,5,0,0,0,5,3,3,5,5,5,5,5
0,0,5,0,0,0,0,0,0,5,0,0,0,0,0,0,5,0,0,0,5,0,0,0,5,3,3,5,5,5,5,5
0,0,10,0,0,0,0,5,5,5,5,5,5,24,5,5,5,5,5,5,5,0,0,0,5,3,3,5,5,5,5,5
0,0,5,0,0,0,5,5,29,0,0,0,0,0,0,0,0,0,0,0,0,0,0,0,5,3,3,5,5,5,5,5
0,0,5,10,10,5,5,5,5,0,0,0,0,0,0,0,0,0,0,0,0,0,0,0,5,3,3,5,5,5,5,5
0,0,0,0,0,0,0,0,0,0,0,0,0,0,0,0,0,0,0,0,0,0,0,0,5,3,3,5,5,5,5,5
0,0,0,0,0,0,0,0,0,0,0,0,0,0,0,0,0,0,0,0,0,0,0,0,5,5,5,5,5,5,18,18
0,0,0,0,0,0,0,0,0,0,0,5,5,5,5,5,0,0,0,0,0,0,0,0,0,0,0,0,0,0,0,0
0,0,0,0,0,0,0,27,27,27,27,5,0,0,20,5,0,0,0,0,0,0,0,0,0,0,0,0,0,0,0,0
0,0,0,0,0,0,0,27,27,27,27,10,0,0,0,26,0,0,0,0,0,0,0,0,0,0,0,0,0,0,0,0
0,0,0,0,0,0,0,27,27,8,27,5,0,0,0,5,0,0,0,0,0,0,8,14,24,8,8,14,22,8,0,0
0,0,0,0,0,0,0,27,27,27,27,5,5,10,5,5,0,0,0,0,17,0,14,0,0,14,0,0,0,14,0,0
0,0,0,0,0,0,0,27,27,0,0,0,0,0,0,0,0,0,0,0,0,0,14,0,0,14,0,0,0,14,0,0
0,0,0,0,0,0,0,0,0,0,0,0,0,0,0,0,0,0,0,0,0,0,14,23,0,14,0,23,0,14,0,0
0,0,0,0,0,0,0,0,0,0,0,0,0,0,0,0,0,0,0,0,0,0,14,0,0,14,0,0,0,14,0,0
0,0,0,0,0,0,0,0,0,0,0,0,0,0,0,0,0,0,0,0,0,0,14,0,0,14,0,0,0,14,0,0
0,0,0,0,0,0,0,0,0,0,0,0,0,0,0,0,0,0,0,0,0,0,14,14,14,14,14,14,14,14,0,0
0,0,0,0,0,0,0,0,0,0,0,0,0,0,0,0,0,0,0,0,0,0,0,0,0,0,0,0,0,0,0,0
endlayer

layer
0,0,0,0,0,0,0,0,0,0,0,0,0,0,0,0,0,0,0,0,0,0,0,0,0,0,0,0,0,0,0,0
0,0,0,0,0,0,0,0,0,0,0,0,0,0,0,0,0,0,0,0,0,0,0,0,0,0,0,0,0,0,0,0
0,0,5,5,10,5,12,5,10,5,5,10,10,5,12,5,10,10,5,12,5,0,0,0,0,0,0,0,0,0,0,0
0,0,5,0,0,0,0,0,0,0,5,0,0,0,0,5,0,0,0,0,5,0,0,0,0,0,0,0,0,0,0,0
0,0,10,0,0,0,0,0,0,0,5,0,32,0,0,5,0,0,0,0,5,0,0,0,0,0,0,0,0,0,0,0
0,0,10,0,0,0,0,0,0,0,5,0,0,0,0,5,0,0,0,0,5,0,0,0,0,0,0,0,0,0,0,0
0,0,5,0,0,0,0,0,0,0,5,5,10,5,12,5,5,5,12,5,5,0,0,0,0,0,0,0,0,0,0,0
0,0,5,5,5,5,5,5,5,5,0,0,0,0,0,0,5,0,0,0,5,0,0,0,0,0,0,0,0,0,0,0
0,0,5,0,0,11,0,0,0,5,0,0,0,0,0,0,5,0,0,0,5,0,0,0,5,5,5,5,5,5,0,0
0,0,10,0,0,0,0,0,0,5,0,0,0,0,0,0,36,0,0,0,10,0,0,0,5,5,5,5,5,5,21,21
0,0,5,0,0,0,0,0,0,0,12,0,0,0,0,0,5,0,0,0,5,0,0,0,5,5,5,5,5,5,5,5
0,0,5,0,0,0,0,0,0,5,0,0,0,0,0,0,5,0,0,0,5,0,0,0,5,5,5,5,5,5,5,5
0,0,10,0,0,0,0,5,5,5,5,10,5,12,5,5,5,5,10,5,5,0,0,0,5,5,5,5,5,5,5,5
0,0,5,0,0,0,5,29,0,0,0,0,0,0,0,0,0,0,0,0,0,0,0,0,5,5,5,5,5,5,5,5
0,0,5,10,10,5,5,5,23,0,0,0,0,0,0,0,0,0,0,0,0,0,0,0,5,5,5,5,5,5,5,5
0,0,0,0,0,0,0,0,0,0,0,0,0,0,0,0,0,0,0,0,0,0,0,0,5,5,5,5,5,5,18,18
0,0,0,0,0,0,0,0,0,0,0,0,0,0,0,0,0,0,0,0,0,0,0,0,5,5,5,5,5,5,0,0
0,0,0,0,0,0,0,0,0,0,0,5,5,5,5,5,0,0,0,0,0,0,0,0,0,0,0,0,0,0,0,0
0,0,0,0,0,0,0,0,27,27,35,5,11,0,20,5,0,0,0,0,0,0,0,0,0,0,0,0,0,0,0,0
0,0,0,0,0,0,0,27,27,27,35,10,0,0,0,5,0,0,35,35,35,35,0,0,0,0,0,0,0,0,0,0
0,0,0,0,0,0,0,27,27,8,35,5,13,0,0,5,0,0,35,35,35,35,8,14,26,8,8,14,12,8,0,0
0,0,0,0,0,0,0,27,27,27,27,5,5,10,5,5,0,0,35,35,17,35,14,0,0,14,0,0,0,14,0,0
0,0,0,0,0,0,0,0,27,27,0,0,0,0,0,0,0,0,35,35,35,35,10,0,0,0,0,0,0,10,0,0
0,0,0,0,0,0,0,0,0,0,0,0,0,0,0,0,0,0,0,0,35,35,14,33,0,14,0,33,0,14,0,0
0,0,0,0,0,0,0,0,0,0,0,0,0,0,0,0,0,0,0,0,0,0,14,0,0,14,0,0,0,14,0,0
0,0,0,0,0,0,0,0,0,0,0,0,0,0,0,0,0,0,0,0,0,0,14,0,0,14,0,0,0,14,0,0
0,0,0,0,0,0,0,0,0,0,0,0,0,0,0,0,0,0,0,0,0,0,14,14,14,14,14,34,14,14,0,0
0,0,0,0,0,0,0,0,0,0,0,0,0,0,0,0,0,0,0,0,0,0,0,0,0,0,0,0,0,0,0,0
endlayer

layer
0,0,0,0,0,0,0,0,0,0,0,0,0,0,0,0,0,0,0,0,0,0,0,0,0,0,0,0,0,0,0,0
0,0,13,0,0,0,13,0,0,0,13,0,0,13,0,13,0,0,13,0,13,0,0,0,0,0,0,0,0,0,0,0
0,0,5,5,5,5,5,5,5,5,5,10,10,5,5,5,10,10,5,5,5,37,0,0,0,0,0,0,0,0,0,0
0,0,5,0,0,0,11,0,0,0,5,0,0,0,0,5,0,0,11,0,5,0,0,0,0,0,0,0,0,0,0,0
0,0,5,0,0,0,0,0,0,0,5,37,0,0,40,5,0,0,0,0,5,0,0,0,0,0,0,0,0,0,0,0
0,0,5,0,0,0,0,0,0,0,5,0,0,0,0,5,13,0,0,0,5,0,0,0,0,0,0,0,0,0,0,0
0,0,5,0,13,0,0,0,0,13,5,5,10,5,5,5,5,5,5,5,5,37,0,0,0,0,0,0,0,0,0,0
0,0,5,5,5,5,5,5,5,5,37,0,0,0,0,0,5,0,0,0,5,0,0,0,0,0,0,0,0,0,0,0
0,0,5,0,0,0,0,0,0,5,0,0,0,0,0,0,5,0,0,0,5,0,0,0,5,5,5,5,5,5,0,0
0,0,5,0,0,0,0,0,0,5,0,0,0,0,0,40,5,0,0,0,10,0,0,0,5,14,39,0,38,5,0,0
0,0,5,0,0,0,0,0,40,5,0,0,0,0,0,0,5,37,0,40,5,0,0,0,5,29,23,0,0,5,0,0
0,0,5,0,0,0,0,0,0,5,0,0,0,13,0,0,5,0,0,0,5,0,0,0,5,29,0,0,0,5,0,0
0,0,5,0,0,0,5,5,5,5,5,10,5,5,5,5,5,5,10,5,5,0,0,0,5,29,23,0,0,5,0,0
0,0,5,0,0,0,29,0,0,11,0,0,41,11,0,41,11,0,0,0,0,0,0,0,5,29,0,0,0,5,0,0
0,0,5,5,5,5,5,23,23,0,0,0,0,0,0,0,0,0,0,0,0,0,0,0,5,0,0,0,0,19,0,0
0,0,0,0,0,0,0,0,0,0,0,0,0,0,0,0,0,0,0,0,0,0,0,0,5,0,0,0,0,5,0,0
0,0,0,0,0,0,0,0,0,0,0,42,0,13,0,42,0,0,0,0,0,0,0,40,5,5,5,5,5,5,0,0
0,0,0,0,0,0,0,0,0,0,40,5,5,5,5,5,37,0,0,0,0,0,0,0,11,0,0,0,0,0,0,0
0,0,0,0,0,0,0,0,0,0,35,5,0,0,20,5,0,0,0,0,0,0,0,0,0,0,0,0,0,0,0,0
0,0,0,0,0,0,0,0,27,27,35,10,0,0,0,5,0,0,35,35,35,35,13,0,13,0,0,0,13,0,0,0
0,0,0,0,0,0,0,0,27,8,35,5,0,0,0,5,0,0,35,35,35,35,8,14,14,8,8,14,14,8,37,0
0,0,0,0,0,0,0,0,27,27,40,5,5,10,5,5,37,0,35,35,17,35,14,0,0,14,0,0,0,14,0,0
0,0,0,0,0,0,0,0,0,0,0,11,0,0,0,11,0,0,35,35,35,35,14,0,0,14,0,0,0,14,0,0
0,0,0,0,0,0,0,0,0,0,0,0,0,0,0,0,0,0,0,0,35,35,14,0,0,14,0,0,0,14,0,0
0,0,0,0,0,0,0,0,0,0,0,0,0,0,0,0,0,0,0,0,0,0,14,0,0,14,0,0,0,14,0,0
0,0,0,0,0,0,0,0,0,0,0,0,0,0,0,0,0,0,0,0,0,0,14,0,0,14,0,0,0,14,0,0
0,0,0,0,0,0,0,0,0,0,0,0,0,0,0,0,0,0,0,0,0,0,14,14,14,14,14,14,14,14,0,0
0,0,0,0,0,0,0,0,0,0,0,0,0,0,0,0,0,0,0,0,0,0,0,0,0,0,0,0,0,0,0,0
endlayer

layer
0,0,0,0,0,0,0,0,0,0,0,0,0,0,0,0,0,0,0,0,0,0,0,0,0,0,0,0,0,0,0,0
0,0,0,0,0,0,0,0,0,0,44,44,44,44,44,44,44,44,44,44,44,0,0,0,0,0,0,0,0,0,0,0
0,0,14,14,14,14,14,14,14,14,44,44,5,44,44,5,44,44,5,44,44,0,0,0,0,0,0,0,0,0,0,0
0,0,14,14,14,14,14,14,14,14,44,44,44,44,44,44,44,44,44,44,44,0,0,0,0,0,0,0,0,0,0,0
0,0,14,14,14,14,14,14,14,14,21,21,21,21,21,21,21,21,21,21,21,0,0,0,0,0,0,0,0,0,0,0
0,0,14,14,14,14,14,14,14,14,5,0,0,0,0,5,0,0,0,0,5,0,0,0,0,0,0,0,0,0,0,0
0,0,14,14,14,14,14,14,14,14,5,5,5,5,5,5,5,5,5,5,5,0,0,0,0,0,0,0,0,0,0,0
0,0,14,14,5,5,5,5,5,5,5,5,5,5,5,5,5,0,0,0,5,0,0,0,0,0,0,0,0,0,0,0
0,0,14,14,5,5,5,5,5,5,5,5,5,5,5,5,5,0,0,0,5,0,0,0,5,14,10,10,14,5,0,0
0,0,14,14,5,5,5,5,5,5,5,5,5,5,5,5,5,0,0,0,10,0,0,0,14,0,0,0,0,14,0,0
0,0,14,14,5,5,5,5,5,5,5,5,5,5,5,5,5,0,0,0,5,0,0,0,10,0,33,0,0,10,0,0
0,0,14,14,5,5,5,5,5,5,5,5,5,5,5,5,5,0,0,0,5,0,0,0,10,0,0,0,0,10,0,0
0,0,14,14,5,5,5,5,5,5,5,5,5,5,5,5,5,5,10,5,5,37,0,0,14,0,33,0,0,10,0,0
0,0,14,14,14,29,0,0,0,0,0,5,5,5,5,5,0,0,0,0,11,0,0,0,10,0,0,0,0,14,0,0
0,0,14,14,14,5,23,23,0,0,0,5,5,5,5,5,0,0,0,0,0,0,0,0,10,0,0,0,0,12,0,0
0,0,0,0,0,0,0,0,0,0,0,5,5,5,5,5,0,0,0,0,0,0,0,0,14,0,0,0,0,14,0,0
0,0,0,0,0,0,0,0,0,0,0,5,5,5,5,5,0,0,0,0,0,0,0,0,5,14,10,10,14,5,0,0
0,0,0,0,0,0,0,0,0,0,0,5,5,5,5,5,0,0,0,0,0,0,0,0,0,0,0,0,0,0,0,0
0,0,0,0,0,0,0,0,0,0,0,5,5,5,5,5,0,0,0,0,0,0,0,0,0,0,0,0,0,0,0,0
0,0,0,0,0,0,0,0,0,27,0,5,5,5,5,5,0,0,0,0,0,0,0,0,0,0,0,0,0,0,0,0
0,0,0,0,0,0,0,0,27,27,27,5,5,5,5,5,0,0,0,35,35,35,0,8,8,0,0,8,8,0,0,0
0,0,0,0,0,0,0,0,0,27,0,5,5,5,5,5,0,0,0,35,17,35,8,8,8,8,8,8,8,8,0,0
0,0,0,0,0,0,0,0,0,0,0,0,0,0,0,0,0,0,0,0,35,35,8,8,8,8,8,8,8,8,0,0
0,0,0,0,0,0,0,0,0,0,0,0,0,0,0,0,0,0,0,0,0,0,8,8,8,8,8,8,8,8,0,0
0,0,0,0,0,0,0,0,0,0,0,0,0,0,0,0,0,0,0,0,0,0,8,43,43,43,43,43,43,8,0,0
0,0,0,0,0,0,0,0,0,0,0,0,0,0,0,0,0,0,0,0,0,0,8,43,43,43,43,43,43,8,0,0
0,0,0,0,0,0,0,0,0,0,0,0,0,0,0,0,0,0,0,0,0,0,8,8,8,8,8,8,8,8,0,0
0,0,0,0,0,0,0,0,0,0,0,0,0,0,0,0,0,0,0,0,0,0,0,0,0,0,0,0,0,0,0,0
endlayer

layer
0,0,0,0,0,0,0,0,0,0,0,0,0,0,0,0,0,0,0,0,0,0,0,0,0,0,0,0,0,0,0,0
0,0,0,0,0,0,0,0,0,0,0,0,0,0,0,0,0,0,0,0,0,0,0,0,0,0,0,0,0,0,0,0
0,0,23,23,23,23,23,23,23,23,0,0,45,0,0,45,0,0,45,0,0,0,0,0,0,0,0,0,0,0,0,0
0,0,23,0,0,0,0,0,0,23,0,0,0,0,0,0,0,0,0,0,0,0,0,0,0,0,0,0,0,0,0,0
0,0,23,0,0,0,0,0,0,23,0,0,0,0,0,0,0,0,0,0,0,0,0,0,0,0,0,0,0,0,0,0
0,0,23,0,0,0,0,0,0,23,21,21,21,21,21,21,21,21,21,21,21,0,0,0,0,0,0,0,0,0,0,0
0,0,23,0,0,0,0,0,0,23,5,5,5,5,5,5,5,5,5,5,5,0,0,0,0,0,0,0,0,0,0,0
0,0,23,0,5,5,22,5,5,5,0,0,0,0,0,0,7,5,5,5,5,0,0,0,13,0,0,0,0,13,0,0
0,0,23,0,5,0,0,0,0,5,0,0,0,0,0,0,7,5,5,5,5,0,0,40,5,14,10,10,14,5,37,0
0,0,23,0,5,0,0,0,0,5,0,0,0,0,0,0,7,5,5,5,5,0,0,0,14,46,0,0,0,14,0,0
0,0,23,0,5,0,0,0,0,19,0,0,0,0,0,0,7,5,5,5,5,0,0,0,14,46,0,0,0,10,0,0
0,0,23,0,5,0,0,0,0,5,0,0,0,0,0,0,7,5,5,5,5,0,0,0,14,46,0,0,0,10,0,0
0,0,23,0,5,5,5,5,5,5,5,5,5,24,5,5,5,5,5,5,5,0,0,0,14,46,0,0,0,10,0,0
0,0,23,0,0,0,0,0,0,0,0,5,0,0,0,5,0,0,0,0,0,0,0,0,14,46,0,0,0,14,0,0
0,0,23,23,23,23,23,0,0,0,0,5,0,0,0,5,0,0,0,0,0,0,0,0,14,46,0,0,0,14,0,0
0,0,0,0,0,0,0,0,0,0,0,5,0,0,0,5,0,0,0,0,0,0,0,0,14,46,0,0,0,14,0,0
0,0,0,0,0,0,0,0,0,0,0,5,0,0,0,5,0,0,0,0,0,0,0,0,5,14,10,10,14,5,37,0
0,0,0,0,0,0,0,0,0,0,0,5,5,24,5,5,0,0,0,0,0,0,0,0,0,0,0,0,0,11,0,0
0,0,0,0,0,0,0,0,0,0,0,5,0,0,0,5,0,0,0,0,0,0,0,0,0,0,0,0,0,0,0,0
0,0,0,0,0,0,0,0,0,0,0,5,0,0,0,5,0,0,0,0,0,0,0,0,0,0,0,0,0,0,0,0
0,0,0,0,0,0,0,0,0,0,0,5,0,0,0,5,0,0,0,0,35,0,0,0,0,0,0,0,0,0,0,0
0,0,0,0,0,0,0,0,0,0,0,5,5,5,5,5,0,0,0,35,35,35,0,0,0,0,0,0,0,0,0,0
0,0,0,0,0,0,0,0,0,0,0,0,0,0,0,0,0,0,0,0,35,0,0,0,45,0,0,0,45,0,0,0
0,0,0,0,0,0,0,0,0,0,0,0,0,0,0,0,0,0,0,0,0,0,0,0,0,0,0,0,0,0,0,0
0,0,0,0,0,0,0,0,0,0,0,0,0,0,0,0,0,0,0,0,0,0,0,0,0,0,0,0,0,0,0,0
0,0,0,0,0,0,0,0,0,0,0,0,0,0,0,0,0,0,0,0,0,0,0,0,0,0,0,0,0,0,0,0
0,0,0,0,0,0,0,0,0,0,0,0,0,0,0,0,0,0,0,0,0,0,0,0,0,0,0,0,0,0,0,0
0,0,0,0,0,0,0,0,0,0,0,0,0,0,0,0,0,0,0,0,0,0,0,0,0,0,0,0,0,0,0,0
endlayer

layer
0,0,0,0,0,0,0,0,0,0,0,0,0,0,0,0,0,0,0,0,0,0,0,0,0,0,0,0,0,0,0,0
0,0,0,0,0,0,0,0,0,0,0,0,0,0,0,0,0,0,0,0,0,0,0,0,0,0,0,0,0,0,0,0
0,0,45,0,0,45,0,0,0,45,0,0,0,0,0,0,0,0,0,0,0,0,0,0,0,0,0,0,0,0,0,0
0,0,0,0,0,0,0,0,0,0,0,0,0,0,0,0,0,0,0,0,0,0,0,0,0,0,0,0,0,0,0,0
0,0,0,0,0,0,0,0,0,0,0,0,0,0,0,0,0,0,0,0,0,0,0,0,0,0,0,0,0,0,0,0
0,0,45,0,0,0,0,0,0,0,0,0,0,0,0,0,0,0,0,0,0,0,0,0,0,0,0,0,0,0,0,0
0,0,0,0,0,0,0,0,0,0,5,5,5,5,5,5,5,5,10,5,5,0,0,0,0,0,0,0,0,0,0,0
0,0,0,0,5,5,12,5,5,5,0,0,0,0,0,0,0,0,0,0,5,0,0,0,0,0,0,0,0,0,0,0
0,0,0,0,5,0,0,0,0,5,0,0,0,0,0,0,0,0,0,0,5,0,0,0,5,14,14,14,14,5,0,0
0,0,0,0,5,0,0,0,0,5,0,0,0,0,0,0,0,0,0,0,5,0,0,0,14,14,0,0,14,14,0,0
0,0,0,0,10,0,0,0,0,12,0,0,0,0,0,0,0,0,0,0,5,0,0,0,14,14,0,0,14,14,0,0
0,0,0,0,5,0,0,0,0,5,0,0,0,0,0,0,0,0,0,0,5,0,0,0,14,14,0,0,14,14,0,0
0,0,0,0,5,5,10,5,5,5,5,5,5,12,5,5,5,5,10,5,5,0,0,0,14,14,0,0,14,14,0,0
0,0,0,0,0,0,0,0,0,0,0,5,0,0,0,5,0,0,0,0,0,0,0,0,14,14,0,0,14,14,0,0
0,0,45,0,0,0,0,0,0,0,0,10,0,0,0,10,0,0,0,0,0,0,0,0,14,14,0,0,14,14,0,0
0,0,0,0,0,0,0,0,0,0,0,10,0,0,0,10,0,0,0,0,0,0,0,0,14,14,0,0,14,14,0,0
0,0,0,0,0,0,0,0,0,0,0,5,0,0,0,5,0,0,0,0,0,0,0,0,5,14,14,14,14,5,0,0
0,0,0,0,0,0,0,0,0,0,0,5,5,12,5,5,0,0,0,0,0,0,0,0,0,0,0,0,0,0,0,0
0,0,0,0,0,0,0,0,0,0,0,5,0,0,0,5,0,0,0,0,0,0,0,0,0,0,0,0,0,0,0,0
0,0,0,0,0,0,0,0,0,0,0,10,0,0,0,10,0,0,0,0,0,0,0,0,0,0,0,0,0,0,0,0
0,0,0,0,0,0,0,0,0,0,0,5,0,0,0,5,0,0,0,0,0,0,0,0,0,0,0,0,0,0,0,0
0,0,0,0,0,0,0,0,0,0,0,5,5,10,5,5,0,0,0,0,0,0,0,0,0,0,0,0,0,0,0,0
0,0,0,0,0,0,0,0,0,0,0,0,0,0,0,0,0,0,0,0,0,0,0,0,0,0,0,0,0,0,0,0
0,0,0,0,0,0,0,0,0,0,0,0,0,0,0,0,0,0,0,0,0,0,0,0,0,0,0,0,0,0,0,0
0,0,0,0,0,0,0,0,0,0,0,0,0,0,0,0,0,0,0,0,0,0,0,0,0,0,0,0,0,0,0,0
0,0,0,0,0,0,0,0,0,0,0,0,0,0,0,0,0,0,0,0,0,0,0,0,0,0,0,0,0,0,0,0
0,0,0,0,0,0,0,0,0,0,0,0,0,0,0,0,0,0,0,0,0,0,0,0,0,0,0,0,0,0,0,0
0,0,0,0,0,0,0,0,0,0,0,0,0,0,0,0,0,0,0,0,0,0,0,0,0,0,0,0,0,0,0,0
endlayer

layer
0,0,0,0,0,0,0,0,0,0,0,0,0,0,0,0,0,0,0,0,0,0,0,0,0,0,0,0,0,0,0,0
0,0,0,0,0,0,0,0,0,0,0,0,0,0,0,0,0,0,0,0,0,0,0,0,0,0,0,0,0,0,0,0
0,0,0,0,0,0,0,0,0,0,0,0,0,0,0,0,0,0,0,0,0,0,0,0,0,0,0,0,0,0,0,0
0,0,0,0,0,0,0,0,0,0,0,0,0,0,0,0,0,0,0,0,0,0,0,0,0,0,0,0,0,0,0,0
0,0,0,0,0,0,0,0,0,0,0,0,0,0,0,0,0,0,0,0,0,0,0,0,0,0,0,0,0,0,0,0
0,0,0,0,0,0,0,0,0,0,0,0,0,0,0,0,0,0,0,0,0,0,0,0,0,0,0,0,0,0,0,0
0,0,0,0,13,0,13,0,0,13,5,10,5,10,5,5,5,5,10,5,5,29,0,0,0,0,0,0,0,0,0,0
0,0,0,40,5,5,5,5,5,5,11,0,0,0,0,0,0,0,0,0,14,29,0,0,0,0,0,0,0,0,0,0
0,0,0,0,5,11,0,0,0,5,0,0,0,0,0,0,0,0,0,0,14,29,0,47,5,5,5,5,5,5,29,0
0,0,0,0,5,0,0,0,0,5,0,0,0,0,0,0,0,0,0,0,14,29,0,47,5,5,5,5,5,5,29,0
0,0,0,0,10,0,0,0,0,5,0,0,0,0,0,0,0,0,0,0,14,29,0,47,5,5,5,5,5,5,29,0
0,0,0,0,5,13,0,0,0,5,13,0,0,0,0,0,0,0,0,0,14,29,0,47,5,5,5,5,5,5,29,0
0,0,0,40,5,5,10,5,5,5,5,5,10,5,10,5,5,5,10,5,5,29,0,47,5,5,5,5,5,5,29,0
0,0,0,0,11,0,0,0,0,0,0,5,0,0,0,5,0,0,0,0,0,0,0,47,5,5,5,5,5,5,29,0
0,0,0,0,0,0,0,0,0,0,0,5,0,0,0,5,0,0,0,0,0,0,0,47,5,5,5,5,5,5,29,0
0,0,0,0,0,0,0,0,0,0,0,5,0,0,0,5,0,0,0,0,0,0,0,47,5,5,5,5,5,5,29,0
0,0,0,0,0,0,0,0,0,0,0,5,0,0,0,5,0,0,0,0,0,0,0,47,5,5,5,5,5,5,29,0
0,0,0,0,0,0,0,0,0,0,0,5,10,5,10,5,0,0,0,0,0,0,0,0,0,0,0,0,0,0,0,0
0,0,0,0,0,0,0,0,0,0,0,5,0,0,0,5,0,0,0,0,0,0,0,0,0,0,0,0,0,0,0,0
0,0,0,0,0,0,0,0,0,0,0,10,0,0,0,10,0,0,0,0,0,0,0,0,0,0,0,0,0,0,0,0
0,0,0,0,0,0,0,0,0,0,0,5,13,0,0,5,0,0,0,0,0,0,0,0,0,0,0,0,0,0,0,0
0,0,0,0,0,0,0,0,0,0,0,5,5,10,5,5,0,0,0,0,0,0,0,0,0,0,0,0,0,0,0,0
0,0,0,0,0,0,0,0,0,0,0,0,0,0,0,0,0,0,0,0,0,0,0,0,0,0,0,0,0,0,0,0
0,0,0,0,0,0,0,0,0,0,0,0,0,0,0,0,0,0,0,0,0,0,0,0,0,0,0,0,0,0,0,0
0,0,0,0,0,0,0,0,0,0,0,0,0,0,0,0,0,0,0,0,0,0,0,0,0,0,0,0,0,0,0,0
0,0,0,0,0,0,0,0,0,0,0,0,0,0,0,0,0,0,0,0,0,0,0,0,0,0,0,0,0,0,0,0
0,0,0,0,0,0,0,0,0,0,0,0,0,0,0,0,0,0,0,0,0,0,0,0,0,0,0,0,0,0,0,0
0,0,0,0,0,0,0,0,0,0,0,0,0,0,0,0,0,0,0,0,0,0,0,0,0,0,0,0,0,0,0,0
endlayer

layer
0,0,0,0,0,0,0,0,0,0,0,0,0,0,0,0,0,0,0,0,0,0,0,0,0,0,0,0,0,0,0,0
0,0,0,0,0,0,0,0,0,0,0,0,0,0,0,0,0,0,0,0,0,0,0,0,0,0,0,0,0,0,0,0
0,0,0,0,0,0,0,0,0,0,0,0,0,0,0,0,0,0,0,0,0,0,0,0,0,0,0,0,0,0,0,0
0,0,0,0,0,0,0,0,0,0,0,0,0,0,0,0,0,0,0,0,0,0,0,0,0,0,0,0,0,0,0,0
0,0,0,0,0,0,0,0,0,0,0,0,0,0,0,0,0,0,0,0,0,0,0,0,0,0,0,0,0,0,0,0
0,0,0,0,0,0,0,0,0,0,49,49,49,49,49,49,49,49,49,49,48,0,0,0,0,0,0,0,0,0,0,0
0,0,0,0,49,49,49,49,49,49,5,5,5,5,5,5,5,5,5,5,29,0,0,0,0,0,0,0,0,0,0,0
0,0,0,0,5,14,14,14,14,5,0,0,0,0,0,0,0,0,11,14,29,0,0,0,0,0,0,0,0,0,0,0
0,0,0,0,5,0,0,0,0,5,0,0,0,0,0,0,0,0,0,14,29,0,0,0,47,5,5,5,5,29,0,0
0,0,0,0,5,0,0,0,0,5,0,0,0,0,0,0,0,0,0,14,29,0,0,0,47,5,5,5,5,29,0,0
0,0,0,0,5,0,0,0,0,5,0,0,0,0,0,0,0,0,0,14,29,0,0,0,47,5,5,5,5,29,0,0
0,0,0,0,5,0,0,0,0,5,0,0,0,0,0,0,0,0,13,14,29,0,0,0,47,5,5,5,5,29,0,0
0,0,0,0,5,14,14,14,14,5,5,5,5,5,5,5,5,5,5,5,29,0,0,0,47,5,5,5,5,29,0,0
0,0,0,0,39,39,39,39,39,39,39,39,39,39,39,39,39,39,39,39,48,0,0,0,47,5,5,5,5,29,0,0
0,0,0,0,0,0,0,0,0,0,0,48,48,14,48,48,0,0,0,0,0,0,0,0,47,5,5,5,5,29,0,0
0,0,0,0,0,0,0,0,0,0,0,48,48,14,48,48,0,0,0,0,0,0,0,0,47,5,5,5,5,29,0,0
0,0,0,0,0,0,0,0,0,0,0,49,49,49,49,49,0,0,0,0,0,0,0,0,47,5,5,5,5,29,0,0
0,0,0,0,0,0,0,0,0,0,0,5,14,14,14,5,0,0,0,0,0,0,0,0,0,0,0,0,0,0,0,0
0,0,0,0,0,0,0,0,0,0,0,5,0,0,0,5,0,0,0,0,0,0,0,0,0,0,0,0,0,0,0,0
0,0,0,0,0,0,0,0,0,0,0,5,0,0,0,5,0,0,0,0,0,0,0,0,0,0,0,0,0,0,0,0
0,0,0,0,0,0,0,0,0,0,0,5,0,0,0,5,0,0,0,0,0,0,0,0,0,0,0,0,0,0,0,0
0,0,0,0,0,0,0,0,0,0,0,5,14,14,14,5,0,0,0,0,0,0,0,0,0,0,0,0,0,0,0,0
0,0,0,0,0,0,0,0,0,0,0,14,14,39,39,14,0,0,0,0,0,0,0,0,0,0,0,0,0,0,0,0
0,0,0,0,0,0,0,0,0,0,0,0,0,0,0,0,0,0,0,0,0,0,0,0,0,0,0,0,0,0,0,0
0,0,0,0,0,0,0,0,0,0,0,0,0,0,0,0,0,0,0,0,0,0,0,0,0,0,0,0,0,0,0,0
0,0,0,0,0,0,0,0,0,0,0,0,0,0,0,0,0,0,0,0,0,0,0,0,0,0,0,0,0,0,0,0
0,0,0,0,0,0,0,0,0,0,0,0,0,0,0,0,0,0,0,0,0,0,0,0,0,0,0,0,0,0,0,0
0,0,0,0,0,0,0,0,0,0,0,0,0,0,0,0,0,0,0,0,0,0,0,0,0,0,0,0,0,0,0,0
endlayer

layer
0,0,0,0,0,0,0,0,0,0,0,0,0,0,0,0,0,0,0,0,0,0,0,0,0,0,0,0,0,0,0,0
0,0,0,0,0,0,0,0,0,0,0,0,0,0,0,0,0,0,0,0,0,0,0,0,0,0,0,0,0,0,0,0
0,0,0,0,0,0,0,0,0,0,0,0,0,0,0,0,0,0,0,0,0,0,0,0,0,0,0,0,0,0,0,0
0,0,0,0,0,0,0,0,0,0,0,0,0,0,0,0,0,0,0,0,0,0,0,0,0,0,0,0,0,0,0,0
0,0,0,0,0,0,0,0,0,0,0,0,0,0,0,0,0,0,0,0,0,0,0,0,0,0,0,0,0,0,0,0
0,0,0,0,0,0,0,0,0,0,0,0,0,0,0,0,0,0,0,0,0,0,0,0,0,0,0,0,0,0,0,0
0,0,0,0,0,0,0,0,0,0,48,48,48,48,48,48,48,48,14,29,0,0,0,0,0,0,0,0,0,0,0,0
0,0,0,48,49,49,49,49,49,49,49,49,49,49,49,49,49,49,14,29,0,0,0,0,0,0,13,13,0,0,0,0
0,0,0,48,5,14,14,14,14,5,0,0,0,0,0,0,0,0,14,29,0,0,0,0,0,47,5,5,29,0,0,0
0,0,0,48,5,0,0,0,0,5,0,0,0,0,0,0,0,0,14,29,0,0,0,0,0,47,5,5,29,0,0,0
0,0,0,48,5,0,0,0,0,5,0,0,0,0,0,0,0,0,14,29,0,0,0,0,0,47,5,5,29,0,0,0
0,0,0,48,5,14,14,14,14,5,0,0,0,0,0,0,0,0,14,29,0,0,0,0,0,47,5,5,29,0,0,0
0,0,0,48,39,39,39,39,39,39,39,39,39,39,39,39,39,39,14,29,0,0,0,0,0,47,5,5,29,0,0,0
0,0,0,0,0,0,0,0,0,0,0,0,0,0,0,0,0,0,0,0,0,0,0,0,0,47,5,5,29,0,0,0
0,0,0,0,0,0,0,0,0,0,0,0,0,45,0,0,0,0,0,0,0,0,0,0,0,47,5,5,29,0,0,0
0,0,0,0,0,0,0,0,0,0,0,0,0,45,0,0,0,0,0,0,0,0,0,0,0,47,5,5,29,0,0,0
0,0,0,0,0,0,0,0,0,0,0,0,0,0,0,0,0,0,0,0,0,0,0,0,0,47,5,5,29,0,0,0
0,0,0,0,0,0,0,0,0,0,0,49,49,49,49,49,0,0,0,0,0,0,0,0,0,0,11,11,0,0,0,0
0,0,0,0,0,0,0,0,0,0,0,5,14,14,14,5,0,0,0,0,0,0,0,0,0,0,0,0,0,0,0,0
0,0,0,0,0,0,0,0,0,0,0,5,0,0,0,5,0,0,0,0,0,0,0,0,0,0,0,0,0,0,0,0
0,0,0,0,0,0,0,0,0,0,0,5,14,14,14,5,0,0,0,0,0,0,0,0,0,0,0,0,0,0,0,0
0,0,0,0,0,0,0,0,0,0,0,39,39,39,39,39,0,0,0,0,0,0,0,0,0,0,0,0,0,0,0,0
0,0,0,0,0,0,0,0,0,0,0,0,0,0,0,0,0,0,0,0,0,0,0,0,0,0,0,0,0,0,0,0
0,0,0,0,0,0,0,0,0,0,0,0,0,0,0,0,0,0,0,0,0,0,0,0,0,0,0,0,0,0,0,0
0,0,0,0,0,0,0,0,0,0,0,0,0,0,0,0,0,0,0,0,0,0,0,0,0,0,0,0,0,0,0,0
0,0,0,0,0,0,0,0,0,0,0,0,0,0,0,0,0,0,0,0,0,0,0,0,0,0,0,0,0,0,0,0
0,0,0,0,0,0,0,0,0,0,0,0,0,0,0,0,0,0,0,0,0,0,0,0,0,0,0,0,0,0,0,0
0,0,0,0,0,0,0,0,0,0,0,0,0,0,0,0,0,0,0,0,0,0,0,0,0,0,0,0,0,0,0,0
endlayer

layer
0,0,0,0,0,0,0,0,0,0,0,0,0,0,0,0,0,0,0,0,0,0,0,0,0,0,0,0,0,0,0,0
0,0,0,0,0,0,0,0,0,0,0,0,0,0,0,0,0,0,0,0,0,0,0,0,0,0,0,0,0,0,0,0
0,0,0,0,0,0,0,0,0,0,0,0,0,0,0,0,0,0,0,0,0,0,0,0,0,0,0,0,0,0,0,0
0,0,0,0,0,0,0,0,0,0,0,0,0,0,0,0,0,0,0,0,0,0,0,0,0,0,0,0,0,0,0,0
0,0,0,0,0,0,0,0,0,0,0,0,0,0,0,0,0,0,0,0,0,0,0,0,0,0,0,0,0,0,0,0
0,0,0,0,0,0,0,0,0,0,0,0,0,0,0,0,0,0,0,0,0,0,0,0,0,0,0,0,0,0,0,0
0,0,0,0,0,0,0,0,0,0,0,0,0,0,0,0,0,0,45,0,0,0,0,0,0,0,0,0,0,0,0,0
0,0,0,0,0,0,0,0,0,0,0,0,0,0,0,0,0,0,0,0,0,0,0,0,0,0,0,0,0,0,0,0
0,0,0,0,49,49,49,49,49,49,49,49,49,49,49,49,49,49,0,0,0,0,0,0,0,0,47,29,0,0,0,0
0,0,0,40,5,14,14,14,14,5,37,0,0,0,0,0,0,0,29,0,0,0,0,0,0,0,47,29,0,0,0,0
0,0,0,40,5,14,14,14,14,5,37,0,0,0,0,0,0,0,29,0,0,0,0,0,0,0,47,29,0,0,0,0
0,0,0,0,39,39,39,39,39,39,39,39,39,39,39,39,39,39,0,0,0,0,0,0,0,0,47,29,0,0,0,0
0,0,0,0,0,0,0,0,0,0,0,0,0,0,0,0,0,0,45,0,0,0,0,0,0,0,47,29,0,0,0,0
0,0,0,0,0,0,0,0,0,0,0,0,0,0,0,0,0,0,0,0,0,0,0,0,0,0,47,29,0,0,0,0
0,0,0,0,0,0,0,0,0,0,0,0,0,0,0,0,0,0,0,0,0,0,0,0,0,0,47,29,0,0,0,0
0,0,0,0,0,0,0,0,0,0,0,0,0,0,0,0,0,0,0,0,0,0,0,0,0,0,47,29,0,0,0,0
0,0,0,0,0,0,0,0,0,0,0,0,0,0,0,0,0,0,0,0,0,0,0,0,0,0,47,29,0,0,0,0
0,0,0,0,0,0,0,0,0,0,0,0,0,0,0,0,0,0,0,0,0,0,0,0,0,0,0,0,0,0,0,0
0,0,0,0,0,0,0,0,0,0,0,49,49,49,49,49,0,0,0,0,0,0,0,0,0,0,0,0,0,0,0,0
0,0,0,0,0,0,0,0,0,0,0,14,14,14,14,14,0,0,0,0,0,0,0,0,0,0,0,0,0,0,0,0
0,0,0,0,0,0,0,0,0,0,0,39,39,39,39,39,0,0,0,0,0,0,0,0,0,0,0,0,0,0,0,0
0,0,0,0,0,0,0,0,0,0,0,0,0,0,0,0,0,0,0,0,0,0,0,0,0,0,0,0,0,0,0,0
0,0,0,0,0,0,0,0,0,0,0,0,0,0,0,0,0,0,0,0,0,0,0,0,0,0,0,0,0,0,0,0
0,0,0,0,0,0,0,0,0,0,0,0,0,0,0,0,0,0,0,0,0,0,0,0,0,0,0,0,0,0,0,0
0,0,0,0,0,0,0,0,0,0,0,0,0,0,0,0,0,0,0,0,0,0,0,0,0,0,0,0,0,0,0,0
0,0,0,0,0,0,0,0,0,0,0,0,0,0,0,0,0,0,0,0,0,0,0,0,0,0,0,0,0,0,0,0
0,0,0,0,0,0,0,0,0,0,0,0,0,0,0,0,0,0,0,0,0,0,0,0,0,0,0,0,0,0,0,0
0,0,0,0,0,0,0,0,0,0,0,0,0,0,0,0,0,0,0,0,0,0,0,0,0,0,0,0,0,0,0,0
endlayer

layer
0,0,0,0,0,0,0,0,0,0,0,0,0,0,0,0,0,0,0,0,0,0,0,0,0,0,0,0,0,0,0,0
0,0,0,0,0,0,0,0,0,0,0,0,0,0,0,0,0,0,0,0,0,0,0,0,0,0,0,0,0,0,0,0
0,0,0,0,0,0,0,0,0,0,0,0,0,0,0,0,0,0,0,0,0,0,0,0,0,0,0,0,0,0,0,0
0,0,0,0,0,0,0,0,0,0,0,0,0,0,0,0,0,0,0,0,0,0,0,0,0,0,0,0,0,0,0,0
0,0,0,0,0,0,0,0,0,0,0,0,0,0,0,0,0,0,0,0,0,0,0,0,0,0,0,0,0,0,0,0
0,0,0,0,0,0,0,0,0,0,0,0,0,0,0,0,0,0,0,0,0,0,0,0,0,0,0,0,0,0,0,0
0,0,0,0,0,0,0,0,0,0,0,0,0,0,0,0,0,0,0,0,0,0,0,0,0,0,0,0,0,0,0,0
0,0,0,0,0,0,0,0,0,0,0,0,0,0,0,0,0,0,0,0,0,0,0,0,0,0,0,0,0,0,0,0
0,0,0,0,0,0,0,0,0,0,0,0,0,0,0,0,0,0,0,0,0,0,0,0,0,0,0,0,0,0,0,0
0,0,0,0,49,49,49,49,49,49,49,49,49,49,49,49,49,49,0,0,0,0,0,0,0,0,0,0,0,0,0,0
0,0,0,0,39,39,39,39,39,39,39,39,39,39,39,39,39,39,0,0,0,0,0,0,0,0,0,0,0,0,0,0
0,0,0,0,0,0,0,0,0,0,0,0,0,0,0,0,0,0,0,0,0,0,0,0,0,0,0,0,0,0,0,0
0,0,0,0,0,0,0,0,0,0,0,0,0,0,0,0,0,0,0,0,0,0,0,0,0,0,0,0,0,0,0,0
0,0,0,0,0,0,0,0,0,0,0,0,0,0,0,0,0,0,0,0,0,0,0,0,0,0,0,0,0,0,0,0
0,0,0,0,0,0,0,0,0,0,0,0,0,0,0,0,0,0,0,0,0,0,0,0,0,0,0,0,0,0,0,0
0,0,0,0,0,0,0,0,0,0,0,0,0,0,0,0,0,0,0,0,0,0,0,0,0,0,0,0,0,0,0,0
0,0,0,0,0,0,0,0,0,0,0,0,0,0,0,0,0,0,0,0,0,0,0,0,0,0,0,0,0,0,0,0
0,0,0,0,0,0,0,0,0,0,0,0,0,0,0,0,0,0,0,0,0,0,0,0,0,0,0,0,0,0,0,0
0,0,0,0,0,0,0,0,0,0,0,0,0,0,0,0,0,0,0,0,0,0,0,0,0,0,0,0,0,0,0,0
0,0,0,0,0,0,0,0,0,0,0,45,0,0,0,45,0,0,0,0,0,0,0,0,0,0,0,0,0,0,0,0
0,0,0,0,0,0,0,0,0,0,0,0,0,0,0,0,0,0,0,0,0,0,0,0,0,0,0,0,0,0,0,0
0,0,0,0,0,0,0,0,0,0,0,0,0,0,0,0,0,0,0,0,0,0,0,0,0,0,0,0,0,0,0,0
0,0,0,0,0,0,0,0,0,0,0,0,0,0,0,0,0,0,0,0,0,0,0,0,0,0,0,0,0,0,0,0
0,0,0,0,0,0,0,0,0,0,0,0,0,0,0,0,0,0,0,0,0,0,0,0,0,0,0,0,0,0,0,0
0,0,0,0,0,0,0,0,0,0,0,0,0,0,0,0,0,0,0,0,0,0,0,0,0,0,0,0,0,0,0,0
0,0,0,0,0,0,0,0,0,0,0,0,0,0,0,0,0,0,0,0,0,0,0,0,0,0,0,0,0,0,0,0
0,0,0,0,0,0,0,0,0,0,0,0,0,0,0,0,0,0,0,0,0,0,0,0,0,0,0,0,0,0,0,0
0,0,0,0,0,0,0,0,0,0,0,0,0,0,0,0,0,0,0,0,0,0,0,0,0,0,0,0,0,0,0,0
endlayer





