# Converted from schematic
# author:MohawkyMagoo

weight=10
embed_into_distance=4
#acceptable_target_blocks=1,2,3,12,13
dimensions=7,24,22
#allowable_overhang=0
max_cut_in=2
#cut_in_buffer=1
max_leveling=2
#leveling_buffer=1
#preserve_water=0
#preserve_lava=0
#preserve_plants=0


rule1=0,100,4
rule2=0,100,3
rule3=0,100,67-2
rule4=0,100,85
rule5=0,100,35-13
rule6=0,100,54-4
rule7=0,100,35-8
rule8=0,100,54-3
rule9=0,100,67-1
rule10=0,100,50-5
rule11=0,100,35-14
rule12=0,100,50-4
rule13=0,100,35-5
rule14=0,100,50-2
rule15=0,100,35-9
rule16=0,100,54-5
rule17=0,100,35-10
rule18=0,100,35-4
rule19=0,100,68-2
rule20=0,100,50-1
rule21=0,100,50-3
rule22=0,100,35-3
rule23=0,100,35
rule24=0,100,35-11


layer
0,0,0,0,0,0,0,0,0,0,0,0,0,0,0,1,1,1,1,1,1,1
1,1,1,1,1,1,1,1,1,1,1,1,1,1,1,1,1,1,1,1,1,1
1,1,1,1,1,1,1,1,1,1,1,1,1,1,1,1,1,1,1,1,1,1
1,1,1,1,1,1,1,1,1,1,1,1,1,1,1,1,1,1,1,1,1,1
1,1,1,1,1,1,1,1,1,1,1,1,1,1,1,1,1,1,1,1,1,1
1,1,1,1,1,1,1,1,1,1,1,1,1,1,1,1,1,1,1,1,1,1
1,1,1,1,1,1,1,1,1,1,1,1,1,1,1,1,1,1,1,1,1,1
1,1,1,1,1,1,1,1,1,1,1,1,1,1,1,1,1,1,1,1,1,1
1,1,1,1,1,1,2,2,2,2,1,2,2,2,2,1,1,1,1,1,1,1
1,1,1,1,1,1,2,2,2,1,1,1,1,1,1,1,1,1,1,1,1,1
1,1,1,1,1,1,2,2,1,1,1,1,1,1,1,1,1,1,1,1,1,1
1,1,1,1,1,1,2,2,2,1,1,1,1,1,1,1,1,1,1,1,1,1
1,1,1,1,1,1,2,2,2,2,1,1,1,1,1,1,1,1,1,1,1,1
1,1,1,1,1,1,1,1,1,1,1,1,1,1,1,1,1,1,1,1,1,1
1,1,1,1,1,1,1,1,1,1,1,1,1,1,1,1,1,1,1,1,1,1
1,1,1,1,1,1,1,1,1,1,1,1,1,1,1,1,2,2,1,1,1,1
1,1,1,1,1,1,1,1,1,1,1,1,1,1,1,1,1,1,1,1,1,1
1,1,1,1,1,1,1,1,1,1,1,1,1,1,1,1,1,1,1,1,1,1
1,1,1,1,1,1,1,1,1,1,1,1,1,1,1,1,1,1,1,1,1,1
1,1,1,1,1,1,1,1,1,1,1,1,1,1,1,1,1,1,1,1,1,1
1,1,1,1,1,1,1,1,1,1,1,1,1,1,1,1,1,1,1,1,1,1
1,1,1,1,1,1,1,1,2,2,1,1,1,1,1,2,2,2,1,1,1,1
1,1,1,1,1,1,1,2,1,1,1,1,1,1,1,1,2,2,1,1,1,1
1,1,1,1,1,1,1,1,1,1,1,1,1,1,1,1,1,1,1,1,1,1
endlayer

layer
0,0,0,0,0,0,0,0,0,0,0,0,0,0,0,0,4,4,4,4,4,0
1,1,1,1,1,1,1,1,1,1,1,1,1,1,1,0,0,0,0,0,0,0
1,1,1,1,1,1,1,1,1,1,1,1,1,1,1,0,0,0,0,0,0,0
1,1,1,1,1,1,1,1,1,1,1,1,1,1,1,0,4,0,0,0,4,0
1,1,1,1,1,1,1,1,1,1,1,1,1,1,1,0,5,5,6,5,5,0
1,1,1,1,1,1,1,1,1,1,1,1,1,1,1,0,4,5,5,5,4,0
1,1,1,1,1,1,1,1,1,1,1,1,1,1,1,9,0,0,0,0,0,0
1,1,1,1,1,1,1,1,1,1,1,1,1,1,1,9,0,0,0,0,0,0
1,1,1,1,1,1,1,1,1,1,1,1,1,1,1,9,0,0,0,0,0,0
1,1,1,1,1,1,1,1,1,1,1,1,1,1,1,1,4,7,4,0,0,0
1,1,1,1,1,1,1,1,1,1,1,1,1,1,1,0,0,7,7,0,0,0
1,1,1,1,1,1,1,1,1,1,1,1,1,1,1,0,0,8,7,0,0,0
1,1,1,1,1,1,1,1,1,1,1,1,1,1,1,0,0,7,7,0,0,0
1,1,1,1,1,1,1,1,1,1,1,1,1,1,1,0,4,7,4,3,3,3
1,1,1,1,1,1,1,1,1,1,1,1,1,1,1,1,1,1,1,1,1,1
1,1,1,1,1,1,1,1,1,1,1,1,1,1,1,1,1,1,1,1,1,1
1,1,1,1,1,1,1,1,1,1,1,1,1,1,1,1,1,1,1,1,1,1
1,1,1,1,1,1,1,1,1,1,1,1,1,1,1,1,1,1,1,1,1,1
1,1,1,1,1,1,1,1,1,1,1,1,1,1,1,1,1,1,1,1,1,1
1,1,1,1,1,1,1,1,1,1,1,1,1,1,1,1,1,1,1,1,1,1
1,1,1,1,1,1,1,1,1,1,1,1,1,1,1,1,1,1,1,1,1,1
1,1,1,1,1,1,1,1,1,1,1,1,1,1,1,1,1,1,1,1,1,1
1,1,1,1,1,1,1,1,1,1,1,1,1,1,1,1,1,1,1,1,1,1
1,1,1,1,1,1,1,1,1,1,1,1,1,1,1,1,1,1,1,1,1,1
endlayer

layer
0,0,0,0,0,0,0,0,0,0,0,0,0,0,0,0,0,0,0,0,10,0
0,0,4,4,4,4,4,4,4,4,4,4,4,4,4,0,0,0,0,0,0,0
0,0,0,0,0,0,0,0,0,0,0,0,0,0,0,0,0,0,0,0,0,0
0,0,4,0,0,4,0,4,0,0,4,0,4,0,4,0,4,0,0,0,4,0
0,0,11,6,11,11,0,7,6,7,7,0,13,0,13,0,0,0,0,0,0,0
0,0,4,11,11,4,0,4,7,7,4,0,4,13,4,0,4,0,0,0,4,0
0,0,0,0,0,0,0,0,0,0,0,0,0,0,0,0,0,0,0,0,0,0
0,0,0,0,0,0,0,0,0,0,0,0,0,0,0,0,0,0,0,0,0,0
0,0,0,0,0,0,0,0,0,0,0,0,0,0,0,12,0,0,0,0,0,0
0,4,18,4,0,0,0,0,1,0,0,0,0,0,14,1,4,0,4,0,0,0
0,0,18,18,0,0,0,0,4,0,0,0,0,0,4,0,0,0,0,0,0,0
0,0,8,18,0,0,0,0,15,15,15,6,15,15,15,0,0,0,0,0,0,0
0,0,18,18,0,0,0,0,4,15,15,15,15,15,4,0,0,0,0,0,0,0
0,4,18,4,0,0,0,0,0,0,0,0,0,0,0,0,4,0,4,0,0,0
0,0,0,0,0,0,0,0,0,0,0,0,0,0,0,0,0,0,0,0,0,0
0,0,0,1,0,0,0,0,0,0,0,0,0,0,0,0,0,0,0,0,0,0
0,0,0,0,0,0,0,0,0,0,0,0,0,0,0,0,0,0,0,0,0,0
0,0,0,0,0,0,0,0,0,0,0,0,0,0,0,0,0,0,0,0,0,0
0,0,0,0,0,0,0,0,0,0,0,0,0,0,0,0,0,0,0,0,0,0
0,0,0,0,0,4,17,17,17,4,0,0,4,11,11,11,4,0,0,0,0,0
0,0,0,0,0,17,17,16,17,17,0,0,11,11,16,11,11,0,0,0,0,0
0,0,0,0,0,4,0,0,0,4,0,0,4,0,0,0,4,0,0,0,0,0
0,0,0,0,0,0,0,0,0,0,0,0,0,0,0,0,0,0,0,0,0,0
0,0,0,0,0,0,4,4,4,4,4,4,4,4,4,4,4,4,1,0,0,0
endlayer

layer
0,0,0,0,0,0,0,0,0,0,0,0,0,0,0,0,0,0,0,0,0,0
0,0,10,0,0,0,10,0,0,0,0,10,0,0,10,0,0,0,0,0,0,0
0,0,0,0,0,0,0,0,0,0,0,0,0,0,0,0,0,0,0,0,0,0
0,0,4,0,0,4,0,4,0,0,4,0,4,0,4,0,4,0,0,0,4,0
0,0,0,0,0,0,0,0,0,0,0,0,0,0,0,0,0,0,0,0,0,0
0,0,4,0,0,4,0,4,0,0,4,0,4,0,4,0,4,0,0,0,4,0
0,0,0,0,0,0,0,0,0,0,0,0,0,0,0,0,0,0,0,0,0,0
0,0,0,0,0,0,0,0,0,0,0,0,0,0,0,0,0,0,0,0,0,0
0,0,0,0,0,0,0,0,12,0,0,0,0,0,0,0,0,0,0,0,0,0
0,4,0,4,0,0,0,14,1,20,0,0,0,0,0,10,4,0,4,0,0,0
0,0,0,0,0,0,0,0,4,0,0,0,0,0,4,0,0,0,0,0,0,0
0,0,0,0,0,0,0,0,0,0,0,0,0,0,0,0,0,0,0,0,0,0
0,0,0,0,0,0,0,0,4,0,0,0,0,0,4,0,0,0,0,0,0,0
0,4,0,4,0,0,0,0,0,0,0,0,0,0,0,0,4,0,4,0,0,0
0,0,0,12,0,0,0,0,0,0,0,0,0,0,0,0,0,0,0,0,0,0
0,0,14,1,20,0,0,0,0,0,0,0,0,0,0,0,0,0,0,0,0,0
0,0,0,21,0,0,0,0,0,0,0,0,0,0,0,0,0,0,0,0,0,0
0,0,0,0,0,0,0,0,0,0,0,0,0,0,0,0,0,0,0,0,0,0
0,0,0,0,0,0,0,0,0,0,0,0,0,0,0,0,0,0,0,0,0,0
0,0,0,0,0,4,0,0,0,4,0,0,4,0,0,0,4,0,0,0,0,0
0,0,0,0,0,0,0,0,0,0,0,0,0,0,0,0,0,0,0,0,0,0
0,0,0,0,0,4,0,0,0,4,0,0,4,0,0,0,4,0,0,0,0,0
0,0,0,0,0,0,0,0,0,0,0,0,0,0,0,0,0,0,19,0,0,0
0,0,0,0,0,0,10,0,0,0,10,0,0,0,10,0,0,10,1,0,0,0
endlayer

layer
0,0,0,0,0,0,0,0,0,0,0,0,0,0,0,0,0,0,0,0,0,0
0,0,0,0,0,0,0,0,0,0,0,0,0,0,0,0,0,0,0,0,0,0
0,0,0,0,0,0,0,0,0,0,0,0,0,0,0,0,0,0,0,0,0,0
0,0,4,0,0,4,0,4,0,0,4,0,4,0,4,0,5,15,5,15,5,0
0,0,0,0,0,0,0,0,0,0,0,0,0,0,0,0,15,5,15,5,15,0
0,0,4,0,0,4,0,4,0,0,4,0,4,0,4,0,5,15,5,15,5,0
0,0,0,0,0,0,0,0,0,0,0,0,0,0,0,0,0,0,0,0,0,0
0,0,0,0,0,0,0,0,0,0,0,0,0,0,0,0,0,0,0,0,0,0
0,0,0,0,0,0,0,0,0,0,0,0,0,0,0,0,0,0,0,0,0,0
0,4,0,4,0,0,0,0,10,0,0,0,0,0,0,0,7,7,7,0,0,0
0,0,0,0,0,0,0,0,4,0,0,0,0,0,4,0,11,11,11,0,0,0
0,0,0,0,0,0,0,0,0,0,0,0,0,0,0,0,7,7,7,0,0,0
0,0,0,0,0,0,0,0,4,0,0,0,0,0,4,0,11,11,11,0,0,0
0,4,0,4,0,0,0,0,0,0,0,0,0,0,0,0,7,7,7,0,0,0
0,0,0,0,0,0,0,0,0,0,0,0,0,0,0,0,0,0,0,0,0,0
0,0,0,10,0,0,0,0,0,0,0,0,0,0,0,0,0,0,0,0,0,0
0,0,0,0,0,0,0,0,0,0,0,0,0,0,0,0,0,0,0,0,0,0
0,0,0,0,0,0,0,0,0,0,0,0,0,0,0,0,0,0,0,0,0,0
0,0,0,0,0,0,0,0,0,0,0,0,0,0,0,0,0,0,0,0,0,0
0,0,0,0,0,4,0,0,0,4,0,0,4,0,0,0,4,0,0,0,0,0
0,0,0,0,0,0,0,0,0,0,0,0,0,0,0,0,0,0,0,0,0,0
0,0,0,0,0,4,0,0,0,4,0,0,4,0,0,0,4,0,0,0,0,0
0,0,0,0,0,0,0,0,0,0,0,0,0,0,0,0,0,0,0,0,0,0
0,0,0,0,0,0,0,0,0,0,0,0,0,0,0,0,0,0,0,0,0,0
endlayer

layer
0,0,0,0,0,0,0,0,0,0,0,0,0,0,0,0,0,0,0,0,0,0
0,0,0,0,0,0,0,0,0,0,0,0,0,0,0,0,0,0,0,0,0,0
0,0,0,0,0,0,0,0,0,0,0,0,0,0,0,0,0,0,0,0,0,0
0,0,15,5,5,15,0,24,23,23,24,0,23,23,23,0,0,0,0,0,0,0
0,0,15,5,5,15,0,23,24,24,23,0,23,13,23,0,0,0,10,0,0,0
0,0,15,5,5,15,0,24,23,23,24,0,23,23,23,0,0,0,0,0,0,0
0,0,0,0,0,0,0,0,0,0,0,0,0,0,0,0,0,0,0,0,0,0
0,0,0,0,0,0,0,0,0,0,0,0,0,0,0,0,0,0,0,0,0,0
0,0,0,0,0,0,0,0,0,0,0,0,0,0,0,0,0,0,0,0,0,0
0,18,18,18,0,0,0,0,0,0,0,0,0,0,0,0,0,0,0,0,0,0
0,22,22,22,0,0,0,0,15,23,15,23,15,23,15,0,0,0,0,0,0,0
0,18,18,18,0,0,0,0,15,23,15,23,15,23,15,0,0,10,0,0,0,0
0,22,22,22,0,0,0,0,15,23,15,23,15,23,15,0,0,0,0,0,0,0
0,18,18,18,0,0,0,0,0,0,0,0,0,0,0,0,0,0,0,0,0,0
0,0,0,0,0,0,0,0,0,0,0,0,0,0,0,0,0,0,0,0,0,0
0,0,0,0,0,0,0,0,0,0,0,0,0,0,0,0,0,0,0,0,0,0
0,0,0,0,0,0,0,0,0,0,0,0,0,0,0,0,0,0,0,0,0,0
0,0,0,0,0,0,0,0,0,0,0,0,0,0,0,0,0,0,0,0,0,0
0,0,0,0,0,0,0,0,0,0,0,0,0,0,0,0,0,0,0,0,0,0
0,0,0,0,0,17,17,17,17,17,0,0,11,22,11,22,11,0,0,0,0,0
0,0,0,0,0,7,7,7,7,7,0,0,22,11,22,11,22,0,0,0,0,0
0,0,0,0,0,17,17,17,17,17,0,0,11,22,11,22,11,0,0,0,0,0
0,0,0,0,0,0,0,0,0,0,0,0,0,0,0,0,0,0,0,0,0,0
0,0,0,0,0,0,0,0,0,0,0,0,0,0,0,0,0,0,0,0,0,0
endlayer

layer
0,0,0,0,0,0,0,0,0,0,0,0,0,0,0,0,0,0,0,0,0,0
0,0,0,0,0,0,0,0,0,0,0,0,0,0,0,0,0,0,0,0,0,0
0,0,0,0,0,0,0,0,0,0,0,0,0,0,0,0,0,0,0,0,0,0
0,0,0,0,0,0,0,0,0,0,0,0,0,0,0,0,0,0,0,0,0,0
0,0,0,10,10,0,0,0,10,10,0,0,0,10,0,0,0,0,0,0,0,0
0,0,0,0,0,0,0,0,0,0,0,0,0,0,0,0,0,0,0,0,0,0
0,0,0,0,0,0,0,0,0,0,0,0,0,0,0,0,0,0,0,0,0,0
0,0,0,0,0,0,0,0,0,0,0,0,0,0,0,0,0,0,0,0,0,0
0,0,0,0,0,0,0,0,0,0,0,0,0,0,0,0,0,0,0,0,0,0
0,0,0,0,0,0,0,0,0,0,0,0,0,0,0,0,0,0,0,0,0,0
0,0,0,0,0,0,0,0,0,0,0,0,0,0,0,0,0,0,0,0,0,0
0,0,10,0,0,0,0,0,0,0,0,10,0,0,0,0,0,0,0,0,0,0
0,0,0,0,0,0,0,0,0,0,0,0,0,0,0,0,0,0,0,0,0,0
0,0,0,0,0,0,0,0,0,0,0,0,0,0,0,0,0,0,0,0,0,0
0,0,0,0,0,0,0,0,0,0,0,0,0,0,0,0,0,0,0,0,0,0
0,0,0,0,0,0,0,0,0,0,0,0,0,0,0,0,0,0,0,0,0,0
0,0,0,0,0,0,0,0,0,0,0,0,0,0,0,0,0,0,0,0,0,0
0,0,0,0,0,0,0,0,0,0,0,0,0,0,0,0,0,0,0,0,0,0
0,0,0,0,0,0,0,0,0,0,0,0,0,0,0,0,0,0,0,0,0,0
0,0,0,0,0,0,0,0,0,0,0,0,0,0,0,0,0,0,0,0,0,0
0,0,0,0,0,0,0,10,0,0,0,0,0,0,10,0,0,0,0,0,0,0
0,0,0,0,0,0,0,0,0,0,0,0,0,0,0,0,0,0,0,0,0,0
0,0,0,0,0,0,0,0,0,0,0,0,0,0,0,0,0,0,0,0,0,0
0,0,0,0,0,0,0,0,0,0,0,0,0,0,0,0,0,0,0,0,0,0
endlayer

