# Converted from schematic
# author:MohawkyMagoo

weight=10
embed_into_distance=2
#acceptable_target_blocks=1,2,3,12,13
dimensions=16,37,23
#allowable_overhang=0
max_cut_in=2
#cut_in_buffer=1
max_leveling=2
#leveling_buffer=1
#preserve_water=0
#preserve_lava=0
#preserve_plants=0


rule1=0,100,4
rule2=0,100,3
rule3=0,100,1
rule4=0,100,9
rule5=0,100,2
rule6=0,100,98
rule7=0,100,109-1
rule8=0,100,109-2
rule9=0,100,64-0
rule10=0,100,109-0
rule11=0,100,64
rule12=0,100,17-2
rule13=0,100,85
rule14=0,100,54-4
rule15=0,100,64-8
rule16=0,100,5-3
rule17=0,100,102
rule18=0,100,53-2
rule19=0,100,53-3
rule20=0,100,53-1
rule21=0,100,58
rule22=0,100,53-0
rule23=0,100,61-2
rule24=0,100,5
rule25=0,100,9-9
rule26=0,100,98-3
rule27=0,100,101
rule28=0,100,50-1
rule29=0,100,50-3
rule30=0,100,96-2
rule31=0,100,72
rule32=0,100,17
rule33=0,100,50-2
rule34=0,100,50-4
rule35=0,100,109-5
rule36=0,100,109-4
rule37=0,100,109-7
rule38=0,100,109-6
rule39=0,100,9-1
rule40=0,100,18-2
rule41=0,100,64-2
rule42=0,100,126
rule43=0,100,64-1
rule44=0,100,50-5
rule45=0,100,126-8
rule46=0,100,126-0


layer
1,1,1,1,1,1,1,1,1,1,1,1,1,1,1,1,1,1,1,1,1,1,1
1,1,1,1,1,1,1,1,1,1,1,1,1,1,1,1,1,1,1,1,1,1,1
1,1,1,1,1,1,1,1,1,1,1,1,1,1,1,1,1,1,1,1,1,1,1
1,1,1,1,1,1,1,1,1,1,1,1,1,1,1,1,1,1,1,1,1,1,1
1,1,2,2,2,2,2,1,1,1,1,1,1,1,1,1,1,1,1,1,1,1,1
1,1,2,2,2,2,2,1,1,1,1,1,1,1,1,1,1,1,1,1,1,1,1
1,1,2,2,2,2,2,1,1,1,1,1,1,1,1,1,1,1,1,1,1,1,1
1,1,2,2,2,2,2,1,1,1,1,1,1,1,1,1,1,1,1,1,1,1,1
1,1,2,2,2,2,2,1,1,1,1,1,1,1,1,1,1,1,1,1,1,1,1
1,1,2,2,2,2,2,1,1,1,1,1,1,1,1,1,1,1,1,1,1,1,1
1,1,1,1,1,1,1,1,1,1,1,1,1,1,1,1,1,1,1,1,1,1,1
1,1,1,1,1,1,1,1,1,1,1,1,1,1,1,1,1,1,1,1,1,1,1
1,1,1,1,1,1,1,1,1,1,1,1,1,1,1,1,1,1,1,1,1,1,1
1,1,1,1,1,1,1,1,1,1,1,1,1,1,1,1,1,1,1,1,1,1,1
1,1,1,1,1,1,1,1,1,1,1,1,1,1,1,1,1,1,1,1,1,1,1
1,1,1,1,1,1,1,1,1,1,1,1,1,1,1,1,1,1,1,1,1,1,1
1,1,1,1,1,1,1,1,1,1,1,1,1,1,1,1,1,1,1,1,1,1,1
1,1,1,1,1,1,1,1,1,1,1,1,1,1,1,1,1,1,1,1,1,1,1
1,1,1,1,1,1,1,1,1,1,1,1,1,1,1,1,1,1,1,1,1,1,1
2,2,2,2,2,2,2,2,2,2,2,2,1,1,1,1,1,1,1,1,1,1,1
2,2,2,2,2,2,2,2,2,2,2,2,1,1,1,1,1,1,1,1,1,1,1
2,2,2,2,2,2,2,2,2,2,2,2,1,1,1,1,1,1,1,1,1,1,1
2,2,2,2,2,2,2,2,2,2,2,2,1,1,1,1,1,1,1,1,1,1,1
2,2,2,2,2,2,2,2,2,2,1,1,1,1,1,1,1,1,1,1,1,1,1
2,2,2,2,2,2,2,2,2,2,1,1,1,1,1,1,1,1,1,1,1,1,1
2,2,2,2,2,2,2,2,2,2,1,1,1,1,1,1,1,1,1,1,1,1,1
2,2,2,2,2,2,2,2,2,2,1,1,1,1,1,1,1,1,1,1,1,1,1
2,2,2,2,3,3,3,2,2,2,1,1,1,1,1,1,1,1,1,1,1,1,1
3,3,3,3,3,1,1,1,1,1,2,2,2,2,2,1,1,1,1,1,1,1,1
3,3,3,3,3,1,1,1,1,1,2,2,2,2,2,1,1,1,1,1,1,1,1
3,3,1,3,3,1,1,1,1,1,2,2,2,2,2,1,1,1,1,1,1,1,1
1,1,1,4,3,1,1,1,1,1,2,2,2,2,2,1,1,1,1,1,1,1,1
1,1,1,4,4,1,1,1,1,1,2,2,2,2,2,2,1,1,1,1,1,1,1
1,1,1,1,4,1,1,1,1,1,2,2,2,2,2,2,1,1,1,1,1,1,1
3,3,3,1,1,1,1,1,1,1,3,2,2,2,2,2,1,1,1,1,1,1,1
3,3,1,1,1,1,3,3,3,3,3,2,2,2,2,2,1,1,1,1,1,1,1
3,3,3,1,1,1,3,3,3,3,3,3,2,2,2,2,2,2,2,2,2,2,2
endlayer

layer
1,1,1,1,1,1,1,1,1,1,1,1,1,1,1,1,1,1,1,1,1,1,1
1,1,1,1,1,1,1,1,1,1,1,1,1,1,1,1,1,1,1,1,1,1,1
1,1,1,1,1,1,1,1,1,1,1,1,1,1,1,1,1,1,1,1,1,1,1
1,1,1,1,1,1,1,1,1,1,1,1,1,1,1,1,1,1,1,1,1,1,1
1,1,1,5,5,5,5,1,1,1,1,1,1,1,1,1,1,1,1,1,1,1,1
1,1,5,5,5,5,5,1,1,1,1,1,1,1,1,1,1,1,1,1,1,1,1
1,1,5,5,5,5,5,1,1,1,1,1,1,1,1,1,1,1,1,1,1,1,1
1,1,5,2,5,5,5,1,1,1,1,1,1,1,1,1,1,1,1,1,1,1,1
1,1,5,5,5,5,5,1,1,1,1,1,1,1,1,1,1,1,1,1,1,1,1
1,1,5,5,5,5,5,1,1,1,1,1,1,1,1,1,1,1,1,1,1,1,1
1,1,1,1,1,1,1,1,1,1,1,1,1,1,1,1,1,1,1,1,1,1,1
1,1,1,1,1,1,1,1,1,1,1,1,1,1,1,1,1,1,1,1,1,1,1
1,1,1,1,1,1,1,1,1,1,1,1,1,1,1,1,1,1,1,1,1,1,1
1,1,1,1,1,1,1,1,1,1,1,1,1,1,1,1,1,1,1,1,1,1,1
1,1,1,1,1,1,1,1,1,1,1,1,1,1,1,1,1,1,1,1,1,1,1
1,1,1,1,1,1,1,1,1,1,1,1,1,1,1,1,1,1,1,1,1,1,1
1,1,1,1,1,1,1,1,1,1,1,1,1,1,1,1,1,1,1,1,1,1,1
1,1,1,1,1,1,1,1,1,1,1,1,1,1,1,1,1,1,1,1,1,1,1
1,1,1,1,1,1,1,1,1,1,1,1,1,1,1,1,1,1,1,1,1,1,1
1,1,1,1,1,1,1,1,1,1,1,1,1,1,1,1,1,1,1,1,1,1,1
1,1,1,1,1,1,1,1,1,1,1,1,1,1,1,1,1,1,1,1,1,1,1
1,1,1,1,1,1,1,1,1,1,1,1,1,1,1,1,1,1,1,1,1,1,1
1,1,1,1,1,1,1,1,1,1,1,1,1,1,1,1,1,1,1,1,1,1,1
1,1,1,1,1,1,1,1,1,1,1,1,1,1,1,1,1,1,1,1,1,1,1
1,1,1,1,1,1,1,1,1,1,1,1,1,1,1,1,1,1,1,1,1,1,1
1,1,1,1,1,1,1,1,1,1,1,1,1,1,1,1,1,1,1,1,1,1,1
1,1,1,1,1,1,1,1,1,1,1,1,1,1,1,1,1,1,1,1,1,1,1
1,1,1,2,1,1,1,1,1,1,1,1,1,1,1,1,1,1,1,1,1,1,1
1,1,1,3,3,1,1,1,1,1,2,5,5,2,2,1,1,1,1,1,1,1,1
1,1,1,3,3,1,1,1,1,1,2,2,2,2,2,1,1,1,1,1,1,1,1
1,1,1,3,3,1,1,1,1,1,2,2,2,2,2,1,1,1,1,1,1,1,1
1,1,1,4,4,1,1,1,1,1,2,2,2,2,2,1,1,1,1,1,1,1,1
1,1,1,4,4,1,1,1,1,1,2,2,2,2,2,2,1,1,1,1,1,1,1
1,1,1,1,4,1,1,1,1,1,2,2,2,2,2,2,1,1,1,1,1,1,1
1,3,3,1,1,1,1,1,1,1,2,2,2,2,2,2,1,1,1,1,1,1,1
1,3,1,1,1,1,4,2,3,2,3,2,2,2,2,2,1,1,1,1,1,1,1
1,1,1,1,1,1,1,1,1,1,1,1,1,1,1,1,1,1,1,1,1,1,1
endlayer

layer
0,0,0,0,0,0,0,0,0,0,0,0,0,0,0,0,0,0,0,0,0,0,0
0,0,0,0,0,0,0,0,0,0,0,0,0,0,0,0,0,0,0,0,0,0,0
0,0,0,0,0,0,0,0,0,0,0,0,0,6,6,6,8,8,6,8,6,0,0
0,0,0,0,0,0,0,6,6,11,6,6,6,6,6,6,6,6,6,6,6,0,0
0,0,0,0,0,0,0,6,0,0,0,0,6,6,6,6,6,6,6,6,6,0,0
0,0,0,0,0,0,0,6,0,0,0,0,6,6,6,6,6,6,6,6,7,0,0
0,0,0,0,0,0,0,6,8,0,0,0,6,6,6,6,6,6,6,6,7,0,0
0,0,0,12,0,0,0,6,6,6,0,0,6,6,6,6,6,6,6,6,6,0,0
0,0,0,0,0,0,0,6,6,6,0,10,6,6,6,6,6,6,6,6,6,0,0
0,0,0,0,0,0,0,6,6,6,6,6,6,6,6,6,6,6,6,6,6,0,0
0,0,0,0,0,0,0,0,0,0,0,0,6,6,6,6,6,6,6,6,6,0,0
0,0,0,0,0,0,0,0,0,0,0,0,6,6,6,6,6,6,6,6,6,0,0
0,0,0,0,0,0,0,0,0,0,0,0,6,6,6,6,6,6,6,6,6,0,0
0,0,0,0,0,0,0,0,0,0,0,0,6,6,6,6,6,6,6,6,6,0,0
0,0,0,0,0,0,0,0,0,0,0,0,6,6,6,6,6,6,6,6,6,0,0
0,0,0,0,6,6,6,6,6,0,0,0,6,6,6,6,6,6,6,6,6,0,0
0,0,0,0,6,4,4,4,6,0,0,0,6,6,6,6,6,6,6,6,6,0,0
0,0,0,0,6,4,6,4,6,0,0,0,6,6,6,6,6,6,6,6,6,0,0
0,0,0,0,6,4,4,4,6,0,0,0,6,6,6,6,6,6,6,6,6,0,0
0,0,0,0,6,6,6,6,6,0,0,0,6,6,6,6,6,6,6,6,6,0,0
0,0,0,0,0,0,0,0,0,0,0,0,6,6,6,6,6,6,6,6,6,0,0
0,0,0,0,0,0,0,0,0,0,0,0,6,6,6,6,6,6,6,6,6,0,0
0,0,0,0,0,0,0,0,0,0,0,0,6,6,6,6,6,6,6,6,6,0,0
0,0,0,0,0,0,0,0,0,0,0,0,6,6,6,6,6,6,6,6,6,0,0
0,0,0,0,0,0,0,0,0,0,0,0,0,0,0,0,0,0,0,0,0,0,0
0,0,0,0,0,0,0,0,0,0,0,0,0,0,0,0,0,0,0,0,0,0,0
0,0,0,0,0,0,0,0,0,0,0,0,0,0,0,0,0,0,0,0,0,0,0
0,0,0,8,0,0,0,8,0,0,0,0,0,0,0,6,6,6,6,6,0,0,0
0,0,6,6,6,6,6,6,6,6,8,8,8,8,8,6,0,0,0,6,0,0,0
0,0,6,6,6,6,6,6,6,6,6,6,6,6,6,6,0,0,0,9,0,0,0
8,8,6,6,6,6,6,6,6,6,6,6,6,6,6,6,0,0,0,6,0,0,0
6,6,6,0,0,6,6,6,6,6,6,6,6,6,6,6,6,6,6,6,0,0,0
6,6,6,0,0,6,6,6,6,6,6,6,6,6,6,6,7,0,0,0,0,0,0
6,6,6,6,0,6,6,6,6,6,6,6,6,6,6,6,7,0,0,0,0,0,0
6,2,0,6,6,6,6,6,6,6,6,6,6,6,6,6,7,0,0,0,0,0,0
6,2,6,6,6,6,6,2,2,2,2,2,6,6,6,6,7,0,0,0,0,0,0
6,6,6,6,6,6,6,6,6,6,6,6,6,6,6,6,7,0,0,0,0,0,0
endlayer

layer
0,0,0,0,0,0,0,0,0,0,0,0,0,0,0,0,0,0,0,0,0,0,0
0,0,0,0,0,0,0,0,0,0,0,0,0,0,0,0,0,0,0,0,0,0,0
0,0,0,0,0,0,0,0,0,0,0,0,0,13,0,13,0,0,13,0,13,0,0
0,0,0,0,0,0,0,6,6,15,6,6,6,0,0,0,0,0,0,0,0,0,0
0,0,0,0,0,0,0,6,0,0,0,0,6,0,0,0,0,0,0,0,0,0,0
0,0,0,0,0,0,0,6,0,0,0,0,6,0,0,0,0,0,0,0,0,0,0
0,0,0,0,0,0,0,17,0,0,0,0,6,0,0,0,0,0,0,0,0,0,0
0,0,0,12,0,0,0,6,8,6,0,0,6,6,6,6,6,6,6,11,6,0,0
0,0,0,0,0,0,0,6,6,6,0,0,9,0,0,0,0,0,0,0,6,0,0
0,0,0,0,0,0,0,6,6,6,6,6,6,0,0,0,0,0,0,0,6,0,0
0,0,0,0,0,0,0,0,0,0,0,0,6,20,13,0,13,0,0,0,6,0,0
0,0,0,0,0,0,0,0,0,0,0,0,6,24,18,18,18,0,0,0,6,0,0
0,0,0,0,0,0,0,0,0,0,0,0,6,19,19,19,19,0,0,0,6,0,0
0,0,0,0,0,0,0,0,0,0,0,0,6,20,0,0,0,0,0,0,6,0,0
0,0,0,0,0,0,0,0,0,0,0,0,6,20,13,22,20,13,0,0,6,0,0
0,0,0,0,0,0,0,0,0,0,0,0,6,20,0,22,20,0,0,0,6,0,0
0,0,0,0,0,0,25,0,0,0,0,0,6,0,0,0,0,0,0,0,6,0,0
0,0,0,0,0,25,26,25,0,0,0,0,6,0,0,0,0,0,0,0,6,0,0
0,0,0,0,0,0,25,0,0,0,0,0,6,0,0,0,0,0,0,0,6,0,0
0,0,0,0,0,0,0,0,0,0,0,0,6,16,16,16,16,16,16,0,6,0,0
0,0,0,0,0,0,0,0,0,0,0,0,6,0,0,0,0,0,0,0,6,0,0
0,0,0,0,0,0,0,0,0,0,0,0,6,0,0,0,0,0,0,0,6,0,0
0,0,0,0,0,0,0,0,0,0,0,0,6,23,23,14,21,0,14,14,6,0,0
0,0,0,0,0,0,0,0,0,0,0,0,6,6,6,6,6,6,6,6,6,0,0
0,0,0,0,0,0,0,0,0,0,0,0,0,0,0,0,0,0,0,0,0,0,0
0,0,0,0,0,0,0,0,0,0,0,0,0,0,0,0,0,0,0,0,0,0,0
0,0,0,0,0,0,0,0,0,0,0,0,0,0,0,0,0,0,0,0,0,0,0
0,0,0,0,0,0,0,0,0,0,0,0,0,0,0,6,6,6,6,6,0,0,0
0,0,6,11,6,6,6,11,6,6,0,0,0,0,0,6,0,0,0,6,0,0,0
0,0,6,0,0,6,0,0,0,6,0,0,0,0,0,6,0,0,0,15,0,0,0
0,0,6,0,0,6,0,0,0,6,0,0,0,0,0,6,0,0,0,6,0,0,0
8,8,6,27,27,6,0,0,0,6,0,0,0,0,0,6,6,17,6,6,0,0,0
6,6,6,6,6,6,0,0,0,6,0,0,0,0,0,0,0,0,0,0,0,0,0
6,6,6,6,6,6,0,0,0,6,0,0,0,0,0,0,0,0,0,0,0,0,0
6,6,6,6,6,6,6,6,6,6,0,0,0,0,0,0,0,0,0,0,0,0,0
6,6,6,6,6,6,6,2,2,2,6,7,0,0,0,0,0,0,0,0,0,0,0
6,6,6,6,6,6,6,6,6,6,6,7,0,0,0,0,0,0,0,0,0,0,0
endlayer

layer
0,0,0,0,0,0,0,0,0,0,0,0,0,0,0,0,0,0,0,0,0,0,0
0,0,0,0,0,0,0,0,0,0,0,0,0,0,0,0,0,0,0,0,0,0,0
0,0,0,0,0,0,0,0,0,0,0,0,0,13,0,13,0,0,13,0,13,0,0
0,0,0,0,0,0,33,6,6,6,6,6,6,0,0,0,0,0,0,0,0,0,0
0,0,0,0,0,0,0,6,0,0,0,0,6,0,0,0,0,0,0,0,0,0,0
0,0,0,0,0,0,0,6,28,0,0,33,6,0,0,0,0,0,0,0,0,0,0
0,0,0,0,0,0,0,17,0,0,0,0,6,0,0,0,0,0,0,0,0,0,0
0,0,0,12,0,0,0,6,0,6,0,0,6,24,17,17,17,24,24,15,6,0,0
0,0,0,0,0,0,0,6,0,10,0,0,15,0,0,0,0,0,0,0,24,0,0
0,0,0,0,0,0,0,6,6,6,6,6,6,0,0,0,0,0,0,0,17,0,0
0,0,0,0,0,0,0,0,0,0,0,0,32,0,31,0,31,0,0,0,17,0,0
0,0,0,0,0,0,0,0,0,0,0,0,17,0,0,0,0,0,0,0,24,0,0
0,0,0,0,0,0,0,0,0,0,0,0,32,0,0,0,0,0,0,0,6,0,0
0,0,0,0,0,0,0,0,0,0,0,33,6,0,0,0,0,0,0,0,6,28,0
0,0,0,0,0,0,0,0,0,0,0,0,32,0,31,0,0,31,0,0,6,0,0
0,0,0,0,0,0,0,0,0,0,0,0,17,0,0,0,0,0,0,0,6,0,0
0,0,0,0,0,0,25,0,0,0,0,0,17,0,0,0,0,0,0,0,6,0,0
0,0,0,0,0,25,26,25,0,0,0,0,32,0,0,0,0,0,0,0,6,0,0
0,0,0,0,0,0,25,0,0,0,0,33,6,0,0,0,0,0,0,0,6,0,0
0,0,0,0,0,0,0,0,0,0,0,0,32,0,0,0,0,0,0,30,6,0,0
0,0,0,0,0,0,0,0,0,0,0,0,17,0,0,0,0,0,0,0,6,0,0
0,0,0,0,0,0,0,0,0,0,0,0,17,0,0,0,0,0,0,0,6,0,0
0,0,0,0,0,0,0,0,0,0,0,0,32,0,0,0,0,0,0,0,6,0,0
0,0,0,0,0,0,0,0,0,0,0,0,6,6,6,6,6,6,6,6,6,28,0
0,0,0,0,0,0,0,0,0,0,0,0,0,0,0,0,0,0,0,0,29,0,0
0,0,0,0,0,0,0,0,0,0,0,0,0,0,0,0,0,0,0,0,0,0,0
0,0,0,0,0,0,0,0,0,0,0,0,0,0,0,0,0,0,0,0,0,0,0
0,0,0,0,0,0,0,0,0,0,0,0,0,0,0,6,6,6,6,6,0,0,0
0,0,6,15,6,6,6,15,6,6,0,0,0,0,0,6,29,0,29,6,0,0,0
0,0,6,0,0,6,0,0,0,6,0,0,0,0,0,17,0,0,0,6,0,0,0
0,0,6,0,0,6,0,0,0,6,0,0,0,0,0,6,0,0,0,6,0,0,0
0,0,6,6,6,6,0,0,0,17,0,0,0,0,0,6,6,6,6,6,0,0,0
8,8,6,6,6,6,0,0,0,6,0,0,0,0,0,0,0,0,0,0,0,0,0
6,6,6,6,6,6,0,0,0,6,0,0,0,0,0,0,0,0,0,0,0,0,0
6,6,6,6,6,6,6,6,6,6,0,0,0,0,0,0,0,0,0,0,0,0,0
6,6,6,6,6,6,6,6,6,6,7,0,0,0,0,0,0,0,0,0,0,0,0
6,6,6,6,6,6,6,6,6,6,7,0,0,0,0,0,0,0,0,0,0,0,0
endlayer

layer
0,0,0,0,0,0,0,0,0,0,0,0,0,0,0,0,0,0,0,0,0,0,0
0,0,0,0,0,0,0,0,0,0,0,0,0,0,0,0,0,0,0,0,0,0,0
0,0,0,0,0,0,0,34,0,0,0,0,34,13,0,13,0,0,13,0,13,0,0
0,0,0,0,0,0,0,6,6,6,6,6,6,28,0,0,0,0,0,0,0,0,0
0,0,0,0,0,0,0,6,0,0,0,0,6,0,0,0,0,0,0,0,0,0,0
0,0,40,40,40,0,0,6,0,0,0,0,6,0,0,0,0,0,0,0,0,0,0
0,40,40,40,40,40,0,17,0,0,0,0,6,34,0,0,0,0,0,34,0,0,0
0,40,40,12,40,40,0,6,0,6,6,6,6,24,17,17,17,24,24,24,6,0,0
0,40,40,40,40,40,0,6,0,0,10,6,6,0,0,0,0,0,0,0,24,0,0
0,0,40,40,40,40,33,6,6,6,6,6,6,0,0,0,0,0,0,0,17,0,0
0,0,0,0,0,0,0,29,0,0,0,0,32,0,0,0,0,0,0,0,17,0,0
0,0,0,0,0,0,0,0,0,0,0,0,17,0,0,0,0,0,0,0,24,0,0
0,0,0,0,0,0,0,0,0,0,0,0,32,0,0,0,0,0,0,0,6,0,0
0,0,0,0,0,0,0,0,0,0,0,0,6,0,0,0,0,0,0,0,6,0,0
0,0,0,0,0,0,0,0,0,0,0,0,32,0,0,0,0,0,0,0,32,0,0
0,0,0,0,0,0,0,0,0,0,0,0,17,0,0,0,0,0,0,0,17,0,0
0,0,0,0,0,0,39,0,0,0,0,0,17,0,0,0,0,0,0,0,17,0,0
0,0,0,0,0,39,4,39,0,0,0,0,32,0,0,0,0,0,0,0,32,0,0
0,0,0,0,0,0,39,0,0,0,0,0,6,0,0,0,0,0,0,0,24,0,0
0,0,0,0,0,0,0,0,0,0,0,0,32,0,0,0,0,0,0,0,32,0,0
0,0,0,0,0,0,0,0,0,0,0,0,17,0,0,0,0,0,0,0,17,0,0
0,0,0,0,0,0,0,0,0,0,0,0,17,0,0,0,0,0,0,0,17,0,0
0,0,0,0,0,0,0,0,0,0,0,0,32,0,0,0,0,0,0,0,32,0,0
0,0,0,0,0,0,0,0,0,0,0,33,6,6,6,6,6,6,6,6,6,0,0
0,0,0,0,0,0,0,0,0,0,0,0,29,0,35,29,0,0,29,35,0,0,0
0,0,0,0,0,0,0,0,0,0,0,0,0,0,0,0,0,0,0,0,0,0,0
0,0,0,0,0,0,0,0,0,0,0,0,0,0,0,36,34,0,34,36,0,0,0
0,0,34,0,0,34,0,0,0,34,0,0,0,0,33,6,6,6,6,6,28,0,0
0,33,6,6,6,6,6,6,6,6,28,0,0,0,37,6,0,0,0,6,0,0,0
0,0,6,0,0,6,29,0,0,6,38,0,0,0,0,17,0,0,0,6,0,0,0
0,0,6,34,0,6,0,0,0,6,38,0,0,0,37,6,0,0,0,6,0,0,0
0,0,6,6,6,6,0,0,0,17,0,0,0,0,33,6,6,6,6,6,28,0,0
0,0,6,0,0,6,0,0,0,6,0,0,0,0,0,29,0,0,0,29,0,0,0
0,0,41,0,0,6,34,0,0,6,28,0,0,0,0,0,0,0,0,0,0,0,0
0,0,6,6,6,6,6,6,6,6,0,0,0,0,0,0,0,0,0,0,0,0,0
0,0,0,0,0,10,6,6,6,7,0,0,0,0,0,0,0,0,0,0,0,0,0
0,0,0,0,0,0,0,0,0,0,0,0,0,0,0,0,0,0,0,0,0,0,0
endlayer

layer
0,0,0,0,0,0,0,0,0,0,0,0,0,0,0,0,0,0,0,0,0,0,0
0,0,0,0,0,0,0,0,0,0,0,0,0,0,0,0,0,0,0,0,0,0,0
0,0,0,0,0,0,0,0,0,0,0,0,0,13,0,13,0,0,13,0,13,0,0
0,0,0,0,0,0,0,6,6,6,6,6,6,0,0,0,0,0,0,0,0,0,0
0,0,0,0,0,0,0,6,6,6,6,6,6,0,0,0,0,0,0,0,0,0,0
0,40,40,40,40,0,0,6,6,6,6,6,6,0,0,0,0,0,0,0,0,0,0
0,40,40,40,40,40,0,6,6,6,6,6,6,0,0,0,0,0,0,0,0,0,0
0,40,40,12,40,40,0,6,6,6,6,6,6,24,24,24,24,24,24,24,6,0,0
0,40,40,40,40,40,0,6,0,0,0,10,6,0,29,0,0,0,29,0,24,0,0
0,0,40,40,40,0,0,6,6,6,6,6,6,0,0,0,0,0,0,0,24,0,0
0,0,0,0,0,0,0,24,24,24,24,24,6,0,0,0,0,0,0,0,24,0,0
0,0,0,0,0,0,0,24,24,24,24,24,6,0,0,0,0,0,0,0,24,0,0
0,0,0,0,0,0,0,0,0,0,24,24,6,0,0,0,0,0,0,0,6,0,0
0,0,0,0,0,0,0,0,0,0,24,24,6,28,0,0,0,0,0,33,6,0,0
0,0,0,0,0,0,0,0,0,0,24,24,6,0,0,0,0,0,0,0,6,0,0
0,0,0,0,0,0,0,0,0,0,24,24,6,0,0,0,0,0,0,0,6,0,0
0,0,0,0,0,0,0,0,0,0,24,24,6,28,0,0,0,0,0,0,6,0,0
0,0,0,0,0,0,0,0,0,0,24,24,6,0,0,0,0,0,0,0,6,0,0
0,0,0,0,0,0,0,0,0,0,24,24,6,0,0,0,0,0,0,33,6,0,0
0,0,0,0,0,0,0,0,0,0,0,42,19,24,0,0,0,0,0,0,6,0,0
0,0,0,0,0,0,0,0,0,0,0,42,42,22,0,0,0,0,0,0,6,0,0
0,0,0,0,0,0,0,0,0,0,0,42,42,22,28,0,0,0,0,0,6,0,0
0,0,0,0,0,0,0,0,0,0,0,42,42,22,0,0,0,34,0,33,6,0,0
0,0,0,0,0,0,0,0,0,0,0,42,42,22,6,6,6,6,6,6,6,0,0
0,0,0,0,0,0,0,0,0,0,0,0,0,0,6,6,6,6,6,6,0,0,0
0,0,0,0,0,0,0,0,0,0,0,0,0,0,6,6,6,6,6,6,0,0,0
0,0,0,0,0,0,0,0,0,0,0,0,0,0,6,6,6,6,6,6,0,0,0
0,0,0,0,0,0,0,0,0,0,0,0,0,0,6,6,6,6,6,6,0,0,0
0,0,18,18,18,6,6,6,6,6,6,6,6,6,6,6,6,6,6,6,0,0,0
0,0,6,0,0,6,6,6,6,6,6,6,6,6,6,6,6,6,6,6,0,0,0
0,0,6,0,0,6,6,6,6,6,6,6,6,6,6,6,6,6,6,6,0,0,0
0,33,6,6,6,6,6,6,6,17,6,6,6,6,6,6,6,6,6,6,0,0,0
0,0,6,0,0,6,6,6,6,6,0,0,0,0,0,0,0,0,0,0,0,0,0
0,0,15,0,0,6,6,6,6,6,0,0,0,0,0,0,0,0,0,0,0,0,0
0,33,6,6,6,6,6,6,6,6,0,0,0,0,0,0,0,0,0,0,0,0,0
0,0,0,0,0,0,10,6,7,0,0,0,0,0,0,0,0,0,0,0,0,0,0
0,0,0,0,0,0,0,0,0,0,0,0,0,0,0,0,0,0,0,0,0,0,0
endlayer

layer
0,0,0,0,0,0,0,0,0,0,0,0,0,0,0,0,0,0,0,0,0,0,0
0,0,0,0,0,0,0,0,0,0,0,0,0,0,0,0,0,0,0,0,0,0,0
0,0,0,0,0,0,0,0,0,0,0,0,0,42,42,42,42,42,42,42,42,0,0
0,0,0,0,0,0,0,6,6,6,6,6,6,42,42,24,42,42,42,24,42,0,0
0,0,0,0,0,0,0,6,0,0,0,0,6,42,42,42,42,42,42,42,42,0,0
0,0,0,0,0,0,0,6,0,0,0,0,6,42,42,42,42,42,42,42,42,0,0
0,0,40,40,0,0,0,6,0,0,0,0,6,18,18,18,18,18,18,18,18,0,0
0,0,40,12,40,0,0,6,0,0,0,0,6,6,6,6,6,6,6,6,6,0,0
0,0,40,40,40,0,0,6,0,0,0,0,6,6,6,6,6,6,6,6,6,0,0
0,0,0,0,0,0,0,6,6,6,6,43,6,6,6,6,6,6,6,6,6,0,0
0,0,0,0,0,0,0,13,0,0,0,0,6,6,6,6,6,6,6,6,6,0,0
0,0,0,0,0,0,0,13,13,13,13,0,6,6,6,6,6,6,6,6,6,0,0
0,0,0,0,0,0,0,0,0,0,13,0,6,6,6,6,6,6,6,6,6,0,0
0,0,0,0,0,0,0,0,0,0,13,0,19,19,19,19,19,19,19,19,19,0,0
0,0,0,0,0,0,0,0,0,0,13,0,24,24,24,24,24,24,24,24,24,0,0
0,0,0,0,0,0,0,0,0,0,13,0,24,0,0,0,0,0,0,24,24,0,0
0,0,0,0,0,0,0,0,0,0,13,0,24,0,0,0,0,0,0,24,24,0,0
0,0,0,0,0,0,0,0,0,0,13,0,24,24,24,24,0,0,0,24,24,0,0
0,0,0,0,0,0,0,0,0,0,13,13,19,19,24,24,0,0,0,24,20,0,0
0,0,0,0,0,0,0,0,0,0,0,0,0,0,22,24,0,0,0,24,20,0,0
0,0,0,0,0,0,0,0,0,0,0,0,0,0,22,24,0,0,0,24,20,0,0
0,0,0,0,0,0,0,0,0,0,0,0,0,0,22,24,0,0,0,24,20,0,0
0,0,0,0,0,0,0,0,0,0,0,0,0,0,22,24,0,0,0,24,20,0,0
0,0,0,0,0,0,0,0,0,0,0,0,0,0,22,24,32,17,32,24,20,0,0
0,0,0,0,0,0,0,0,0,0,0,0,0,0,6,6,6,6,6,6,0,0,0
0,0,0,0,0,0,0,0,0,0,0,0,0,0,6,0,0,0,0,6,0,0,0
0,0,0,0,0,0,0,0,0,0,0,0,0,0,6,0,0,0,0,6,0,0,0
0,0,0,0,0,0,0,0,0,0,0,0,0,0,6,0,0,0,0,6,0,0,0
0,0,0,0,0,6,6,6,6,6,6,6,6,6,6,0,0,0,0,6,0,0,0
0,0,42,42,42,6,0,0,0,9,0,0,0,0,41,0,0,0,0,6,0,0,0
0,0,42,18,18,6,0,0,0,6,0,0,0,0,6,0,0,0,0,6,0,0,0
0,0,22,6,6,6,0,0,0,6,6,6,6,6,6,6,6,6,6,6,0,0,0
0,0,22,0,33,6,0,0,0,6,0,0,0,0,0,0,0,0,0,0,0,0,0
0,0,22,0,0,6,0,0,0,6,0,0,0,0,0,0,0,0,0,0,0,0,0
0,0,22,6,6,6,6,11,6,6,0,0,0,0,0,0,0,0,0,0,0,0,0
0,0,0,29,0,0,0,0,0,0,0,0,0,0,0,0,0,0,0,0,0,0,0
0,0,0,0,0,0,0,0,0,0,0,0,0,0,0,0,0,0,0,0,0,0,0
endlayer

layer
0,0,0,0,0,0,0,0,0,0,0,0,0,0,0,0,0,0,0,0,0,0,0
0,0,0,0,0,0,0,0,0,0,0,0,0,0,0,0,0,0,0,0,0,0,0
0,0,0,0,0,0,0,0,0,0,0,0,0,0,0,0,0,0,0,0,0,0,0
0,0,0,0,0,0,0,6,6,17,6,6,6,0,0,44,0,0,0,44,0,0,0
0,0,0,0,0,0,0,6,0,0,0,0,6,0,0,0,0,0,0,0,0,0,0
0,0,0,0,0,0,0,6,0,0,0,0,6,0,0,0,0,0,0,0,0,0,0
0,0,0,40,0,0,0,17,0,0,0,0,17,0,0,0,0,0,0,0,0,0,0
0,0,40,40,40,0,0,6,0,0,0,0,6,18,18,18,18,18,18,18,18,0,0
0,0,0,40,0,0,0,6,0,0,0,0,6,6,6,6,6,6,6,6,6,0,0
0,0,0,0,0,0,0,6,6,17,6,15,6,6,6,6,6,6,6,6,6,0,0
0,0,0,0,0,0,0,0,0,0,0,0,6,6,6,6,6,6,6,6,6,0,0
0,0,0,0,0,0,0,44,0,0,0,0,6,6,6,6,6,6,6,6,6,0,0
0,0,0,0,0,0,0,0,0,0,0,0,19,19,19,19,19,19,19,19,19,0,0
0,0,0,0,0,0,0,0,0,0,44,0,0,0,0,0,0,0,0,0,0,0,0
0,0,0,0,0,0,0,0,0,0,0,0,18,18,18,18,18,18,18,18,18,0,0
0,0,0,0,0,0,0,0,0,0,0,0,24,24,24,24,24,24,24,24,24,0,0
0,0,0,0,0,0,0,0,0,0,0,0,24,24,24,24,24,24,24,24,24,0,0
0,0,0,0,0,0,0,0,0,0,0,0,19,19,19,24,24,0,24,24,19,0,0
0,0,0,0,0,0,0,0,0,0,44,0,0,0,0,22,24,0,24,20,0,0,0
0,0,0,0,0,0,0,0,0,0,0,0,0,0,0,22,24,0,24,20,0,0,0
0,0,0,0,0,0,0,0,0,0,0,0,0,0,0,22,24,0,24,20,0,0,0
0,0,0,0,0,0,0,0,0,0,0,0,0,0,0,22,24,0,24,20,0,0,0
0,0,0,0,0,0,0,0,0,0,0,0,0,0,0,22,24,0,24,20,0,0,0
0,0,0,0,0,0,0,0,0,0,0,0,0,0,0,22,24,24,24,20,0,0,0
0,0,0,0,0,0,0,0,0,0,0,0,0,0,6,6,6,6,6,6,0,0,0
0,0,0,0,0,0,0,0,0,0,0,0,0,0,6,0,0,0,0,6,0,0,0
0,0,0,0,0,0,0,0,0,0,0,0,0,0,17,0,0,0,0,17,0,0,0
0,0,0,0,0,0,0,0,0,0,0,0,0,0,6,0,0,0,0,6,0,0,0
0,0,0,0,0,6,6,6,6,6,0,0,0,0,6,0,0,0,0,6,0,0,0
0,0,0,0,0,6,0,0,0,15,0,0,0,0,15,0,0,0,0,17,0,0,0
0,0,0,0,0,6,0,0,0,6,0,0,0,0,6,0,0,0,0,6,0,0,0
0,0,0,22,24,6,0,0,0,6,0,0,0,0,6,6,6,17,6,6,0,0,0
0,0,0,22,45,6,0,0,0,6,0,0,0,0,0,0,0,0,0,0,0,0,0
0,0,0,22,45,6,0,0,0,6,0,0,0,0,0,0,0,0,0,0,0,0,0
0,0,0,22,19,6,6,15,6,6,0,0,0,0,0,0,0,0,0,0,0,0,0
0,0,0,0,0,0,0,0,0,0,0,0,0,0,0,0,0,0,0,0,0,0,0
0,0,0,0,0,0,0,0,0,0,0,0,0,0,0,0,0,0,0,0,0,0,0
endlayer

layer
0,0,0,0,0,0,0,0,0,0,0,0,0,0,0,0,0,0,0,0,0,0,0
0,0,0,0,0,0,0,0,0,0,0,0,0,0,0,0,0,0,0,0,0,0,0
0,0,0,0,0,0,0,0,0,0,0,0,0,0,0,0,0,0,0,0,0,0,0
0,0,0,0,0,0,0,6,6,17,6,6,6,0,0,0,0,0,0,0,0,0,0
0,0,0,0,0,0,0,6,0,0,0,0,6,0,0,0,0,0,0,0,0,0,0
0,0,0,0,0,0,0,6,28,0,0,33,6,0,0,0,0,0,0,0,0,0,0
0,0,0,0,0,0,0,17,0,0,0,0,17,0,0,0,0,0,0,0,0,0,0
0,0,0,0,0,0,0,6,0,0,0,0,6,0,0,0,0,0,0,0,0,0,0
0,0,0,0,0,0,0,6,0,0,0,0,6,18,18,18,18,18,18,18,18,0,0
0,0,0,0,0,0,0,6,6,17,6,6,6,6,6,6,6,6,6,6,6,0,0
0,0,0,0,0,0,0,0,0,0,0,33,6,6,6,6,6,6,6,6,6,0,0
0,0,0,0,0,0,0,0,0,0,0,0,19,19,19,19,19,19,19,19,19,0,0
0,0,0,0,0,0,0,0,0,0,0,0,0,0,0,0,0,0,0,0,0,0,0
0,0,0,0,0,0,0,0,0,0,0,0,0,0,0,0,0,0,0,0,0,0,0
0,0,0,0,0,0,0,0,0,0,0,0,0,0,0,0,0,0,0,0,0,0,0
0,0,0,0,0,0,0,0,0,0,0,0,18,18,18,18,18,18,18,18,18,0,0
0,0,0,0,0,0,0,0,0,0,0,0,19,19,19,19,24,24,24,19,19,0,0
0,0,0,0,0,0,0,0,0,0,0,0,0,0,0,0,22,24,20,0,0,0,0
0,0,0,0,0,0,0,0,0,0,0,0,0,0,0,0,22,24,20,0,0,0,0
0,0,0,0,0,0,0,0,0,0,0,0,0,0,0,0,22,24,20,0,0,0,0
0,0,0,0,0,0,0,0,0,0,0,0,0,0,0,0,22,24,20,0,0,0,0
0,0,0,0,0,0,0,0,0,0,0,0,0,0,0,0,22,24,20,0,0,0,0
0,0,0,0,0,0,0,0,0,0,0,0,0,0,0,0,22,24,20,0,0,0,0
0,0,0,0,0,0,0,0,0,0,0,0,0,0,0,0,22,24,20,0,0,0,0
0,0,0,0,0,0,0,0,0,0,0,0,0,0,6,6,6,6,6,6,0,0,0
0,0,0,0,0,0,0,0,0,0,0,0,0,0,6,0,29,0,33,6,0,0,0
0,0,0,0,0,0,0,0,0,0,0,0,0,0,6,0,0,0,0,17,0,0,0
0,0,0,0,0,34,0,0,0,34,0,0,0,0,6,0,0,0,0,6,28,0,0
0,0,0,0,33,6,6,17,6,6,28,0,0,0,6,0,0,0,0,6,0,0,0
0,0,0,0,0,6,0,0,0,6,0,0,0,33,6,0,0,0,0,17,0,0,0
0,0,0,0,0,6,0,0,33,6,0,0,0,0,6,0,34,0,0,6,0,0,0
0,0,0,0,0,17,0,0,0,17,0,0,0,0,6,6,6,17,6,6,28,0,0
0,0,0,0,0,6,0,0,0,6,0,0,0,0,0,29,0,0,0,29,0,0,0
0,0,0,0,0,6,0,0,0,6,0,0,0,0,0,0,0,0,0,0,0,0,0
0,0,0,0,33,6,6,6,6,6,28,0,0,0,0,0,0,0,0,0,0,0,0
0,0,0,0,0,29,0,0,0,29,0,0,0,0,0,0,0,0,0,0,0,0,0
0,0,0,0,0,0,0,0,0,0,0,0,0,0,0,0,0,0,0,0,0,0,0
endlayer

layer
0,0,0,0,0,0,0,0,0,0,0,0,0,0,0,0,0,0,0,0,0,0,0
0,0,0,0,0,0,0,0,0,0,0,0,0,0,0,0,0,0,0,0,0,0,0
0,0,0,0,0,0,0,34,0,0,0,0,34,0,0,0,0,0,0,0,0,0,0
0,0,0,0,0,0,33,6,6,6,6,6,6,28,0,0,0,0,0,0,0,0,0
0,0,0,0,0,0,0,6,0,0,0,0,6,0,0,0,0,0,0,0,0,0,0
0,0,0,0,0,0,0,6,0,0,0,0,6,0,0,0,0,0,0,0,0,0,0
0,0,0,0,0,0,0,6,0,0,0,0,6,0,0,0,0,0,0,0,0,0,0
0,0,0,0,0,0,0,6,0,0,0,0,6,0,0,0,0,0,0,0,0,0,0
0,0,0,0,0,0,0,6,0,0,0,0,6,0,0,0,0,0,0,0,0,0,0
0,0,0,0,0,0,33,6,6,6,6,6,6,18,18,18,18,18,18,18,18,0,0
0,0,0,0,0,0,0,29,0,0,0,0,19,19,19,19,19,19,19,19,19,0,0
0,0,0,0,0,0,0,0,0,0,0,0,0,0,0,0,0,0,0,0,0,0,0
0,0,0,0,0,0,0,0,0,0,0,0,0,0,0,0,0,0,0,0,0,0,0
0,0,0,0,0,0,0,0,0,0,0,0,0,0,0,0,0,0,0,0,0,0,0
0,0,0,0,0,0,0,0,0,0,0,0,0,0,0,0,0,0,0,0,0,0,0
0,0,0,0,0,0,0,0,0,0,0,0,0,0,0,0,0,0,0,0,0,0,0
0,0,0,0,0,0,0,0,0,0,0,0,0,0,0,0,0,44,0,0,0,0,0
0,0,0,0,0,0,0,0,0,0,0,0,0,0,0,0,0,0,0,0,0,0,0
0,0,0,0,0,0,0,0,0,0,0,0,0,0,0,0,0,0,0,0,0,0,0
0,0,0,0,0,0,0,0,0,0,0,0,0,0,0,0,0,0,0,0,0,0,0
0,0,0,0,0,0,0,0,0,0,0,0,0,0,0,0,0,44,0,0,0,0,0
0,0,0,0,0,0,0,0,0,0,0,0,0,0,0,0,0,0,0,0,0,0,0
0,0,0,0,0,0,0,0,0,0,0,0,0,0,0,0,0,0,0,0,0,0,0
0,0,0,0,0,0,0,0,0,0,0,0,0,0,0,0,0,44,0,0,0,0,0
0,0,0,0,0,0,0,0,0,0,0,0,0,42,42,42,42,42,42,42,42,0,0
0,0,0,0,0,0,0,0,0,0,0,0,0,42,42,42,42,42,42,42,42,0,0
0,0,0,0,0,0,0,0,0,0,0,0,0,42,46,18,18,18,18,18,46,0,0
0,0,0,0,0,0,0,0,0,0,0,0,0,42,22,24,0,0,0,24,20,0,0
0,0,0,0,0,6,6,17,6,6,0,0,0,42,22,24,0,0,0,24,20,0,0
0,0,0,0,0,6,29,0,0,6,0,0,0,42,22,24,0,0,0,24,20,0,0
0,0,0,0,0,6,0,0,0,6,0,0,0,42,22,24,0,0,0,24,20,0,0
0,0,0,0,0,17,0,0,0,17,0,0,0,42,22,24,24,24,24,24,20,0,0
0,0,0,0,0,6,0,0,0,6,0,0,0,42,46,19,19,19,19,19,46,0,0
0,0,0,0,0,6,34,0,0,6,0,0,0,0,0,0,0,0,0,0,0,0,0
0,0,0,0,0,6,6,17,6,6,0,0,0,0,0,0,0,0,0,0,0,0,0
0,0,0,0,0,0,0,0,0,0,0,0,0,0,0,0,0,0,0,0,0,0,0
0,0,0,0,0,0,0,0,0,0,0,0,0,0,0,0,0,0,0,0,0,0,0
endlayer

layer
0,0,0,0,0,0,0,0,0,0,0,0,0,0,0,0,0,0,0,0,0,0,0
0,0,0,0,0,0,0,0,0,0,0,0,0,0,0,0,0,0,0,0,0,0,0
0,0,0,0,0,0,22,0,0,0,0,0,0,20,0,0,0,0,0,0,0,0,0
0,0,0,0,0,0,22,6,6,6,6,6,6,20,0,0,0,0,0,0,0,0,0
0,0,0,0,0,0,22,24,0,0,0,0,24,20,0,0,0,0,0,0,0,0,0
0,0,0,0,0,0,22,24,0,0,0,0,24,20,0,0,0,0,0,0,0,0,0
0,0,0,0,0,0,22,24,0,0,0,0,24,20,0,0,0,0,0,0,0,0,0
0,0,0,0,0,0,22,24,0,0,0,0,24,20,0,0,0,0,0,0,0,0,0
0,0,0,0,0,0,22,24,0,0,0,0,24,20,0,0,0,0,0,0,0,0,0
0,0,0,0,0,0,22,6,6,6,6,6,6,20,0,0,0,0,0,0,0,0,0
0,0,0,0,0,0,22,0,0,0,0,0,0,20,0,0,0,0,0,0,0,0,0
0,0,0,0,0,0,0,0,0,0,0,0,0,0,0,0,0,0,0,0,0,0,0
0,0,0,0,0,0,0,0,0,0,0,0,0,0,0,0,0,0,0,0,0,0,0
0,0,0,0,0,0,0,0,0,0,0,0,0,0,0,0,0,0,0,0,0,0,0
0,0,0,0,0,0,0,0,0,0,0,0,0,0,0,0,0,0,0,0,0,0,0
0,0,0,0,0,0,0,0,0,0,0,0,0,0,0,0,0,0,0,0,0,0,0
0,0,0,0,0,0,0,0,0,0,0,0,0,0,0,0,0,0,0,0,0,0,0
0,0,0,0,0,0,0,0,0,0,0,0,0,0,0,0,0,0,0,0,0,0,0
0,0,0,0,0,0,0,0,0,0,0,0,0,0,0,0,0,0,0,0,0,0,0
0,0,0,0,0,0,0,0,0,0,0,0,0,0,0,0,0,0,0,0,0,0,0
0,0,0,0,0,0,0,0,0,0,0,0,0,0,0,0,0,0,0,0,0,0,0
0,0,0,0,0,0,0,0,0,0,0,0,0,0,0,0,0,0,0,0,0,0,0
0,0,0,0,0,0,0,0,0,0,0,0,0,0,0,0,0,0,0,0,0,0,0
0,0,0,0,0,0,0,0,0,0,0,0,0,0,0,0,0,0,0,0,0,0,0
0,0,0,0,0,0,0,0,0,0,0,0,0,0,0,0,0,0,0,0,0,0,0
0,0,0,0,0,0,0,0,0,0,0,0,0,0,0,0,0,0,0,0,0,0,0
0,0,0,0,0,0,0,0,0,0,0,0,0,0,0,0,0,0,0,0,0,0,0
0,0,0,0,0,0,0,0,0,0,0,0,0,0,0,46,18,18,18,46,0,0,0
0,0,0,0,0,6,6,6,6,6,0,0,0,0,0,22,24,24,24,20,0,0,0
0,0,0,0,0,6,0,0,0,6,0,0,0,0,0,22,24,0,24,20,0,0,0
0,0,0,0,0,6,0,0,0,6,0,0,0,0,0,22,24,24,24,20,0,0,0
0,0,0,0,0,6,0,0,0,6,0,0,0,0,0,46,19,19,19,46,0,0,0
0,0,0,0,0,6,0,0,0,6,0,0,0,0,0,0,0,0,0,0,0,0,0
0,0,0,0,0,6,0,0,0,6,0,0,0,0,0,0,0,0,0,0,0,0,0
0,0,0,0,0,6,6,6,6,6,0,0,0,0,0,0,0,0,0,0,0,0,0
0,0,0,0,0,0,0,0,0,0,0,0,0,0,0,0,0,0,0,0,0,0,0
0,0,0,0,0,0,0,0,0,0,0,0,0,0,0,0,0,0,0,0,0,0,0
endlayer

layer
0,0,0,0,0,0,0,0,0,0,0,0,0,0,0,0,0,0,0,0,0,0,0
0,0,0,0,0,0,0,0,0,0,0,0,0,0,0,0,0,0,0,0,0,0,0
0,0,0,0,0,0,0,22,0,0,0,0,20,0,0,0,0,0,0,0,0,0,0
0,0,0,0,0,0,0,22,6,6,6,6,20,0,0,0,0,0,0,0,0,0,0
0,0,0,0,0,0,0,22,24,0,0,24,20,0,0,0,0,0,0,0,0,0,0
0,0,0,0,0,0,0,22,24,0,0,24,20,0,0,0,0,0,0,0,0,0,0
0,0,0,0,0,0,0,22,24,0,0,24,20,0,0,0,0,0,0,0,0,0,0
0,0,0,0,0,0,0,22,24,0,0,24,20,0,0,0,0,0,0,0,0,0,0
0,0,0,0,0,0,0,22,24,0,0,24,20,0,0,0,0,0,0,0,0,0,0
0,0,0,0,0,0,0,22,6,6,6,6,20,0,0,0,0,0,0,0,0,0,0
0,0,0,0,0,0,0,22,0,0,0,0,20,0,0,0,0,0,0,0,0,0,0
0,0,0,0,0,0,0,0,0,0,0,0,0,0,0,0,0,0,0,0,0,0,0
0,0,0,0,0,0,0,0,0,0,0,0,0,0,0,0,0,0,0,0,0,0,0
0,0,0,0,0,0,0,0,0,0,0,0,0,0,0,0,0,0,0,0,0,0,0
0,0,0,0,0,0,0,0,0,0,0,0,0,0,0,0,0,0,0,0,0,0,0
0,0,0,0,0,0,0,0,0,0,0,0,0,0,0,0,0,0,0,0,0,0,0
0,0,0,0,0,0,0,0,0,0,0,0,0,0,0,0,0,0,0,0,0,0,0
0,0,0,0,0,0,0,0,0,0,0,0,0,0,0,0,0,0,0,0,0,0,0
0,0,0,0,0,0,0,0,0,0,0,0,0,0,0,0,0,0,0,0,0,0,0
0,0,0,0,0,0,0,0,0,0,0,0,0,0,0,0,0,0,0,0,0,0,0
0,0,0,0,0,0,0,0,0,0,0,0,0,0,0,0,0,0,0,0,0,0,0
0,0,0,0,0,0,0,0,0,0,0,0,0,0,0,0,0,0,0,0,0,0,0
0,0,0,0,0,0,0,0,0,0,0,0,0,0,0,0,0,0,0,0,0,0,0
0,0,0,0,0,0,0,0,0,0,0,0,0,0,0,0,0,0,0,0,0,0,0
0,0,0,0,0,0,0,0,0,0,0,0,0,0,0,0,0,0,0,0,0,0,0
0,0,0,0,0,0,0,0,0,0,0,0,0,0,0,0,0,0,0,0,0,0,0
0,0,0,0,0,0,0,0,0,0,0,0,0,0,0,0,0,0,0,0,0,0,0
0,0,0,0,22,0,0,0,0,0,20,0,0,0,0,0,0,0,0,0,0,0,0
0,0,0,0,22,6,6,6,6,6,20,0,0,0,0,0,46,18,46,0,0,0,0
0,0,0,0,22,24,0,0,0,24,20,0,0,0,0,0,22,24,20,0,0,0,0
0,0,0,0,22,24,0,0,0,24,20,0,0,0,0,0,46,19,46,0,0,0,0
0,0,0,0,22,24,0,0,0,24,20,0,0,0,0,0,0,0,0,0,0,0,0
0,0,0,0,22,24,0,0,0,24,20,0,0,0,0,0,0,0,0,0,0,0,0
0,0,0,0,22,24,0,0,0,24,20,0,0,0,0,0,0,0,0,0,0,0,0
0,0,0,0,22,6,6,6,6,6,20,0,0,0,0,0,0,0,0,0,0,0,0
0,0,0,0,22,0,0,0,0,0,20,0,0,0,0,0,0,0,0,0,0,0,0
0,0,0,0,0,0,0,0,0,0,0,0,0,0,0,0,0,0,0,0,0,0,0
endlayer

layer
0,0,0,0,0,0,0,0,0,0,0,0,0,0,0,0,0,0,0,0,0,0,0
0,0,0,0,0,0,0,0,0,0,0,0,0,0,0,0,0,0,0,0,0,0,0
0,0,0,0,0,0,0,0,22,0,0,20,0,0,0,0,0,0,0,0,0,0,0
0,0,0,0,0,0,0,0,22,6,6,20,0,0,0,0,0,0,0,0,0,0,0
0,0,0,0,0,0,0,0,22,24,24,20,0,0,0,0,0,0,0,0,0,0,0
0,0,0,0,0,0,0,0,22,24,24,20,0,0,0,0,0,0,0,0,0,0,0
0,0,0,0,0,0,0,0,22,24,24,20,0,0,0,0,0,0,0,0,0,0,0
0,0,0,0,0,0,0,0,22,24,24,20,0,0,0,0,0,0,0,0,0,0,0
0,0,0,0,0,0,0,0,22,24,24,20,0,0,0,0,0,0,0,0,0,0,0
0,0,0,0,0,0,0,0,22,6,6,20,0,0,0,0,0,0,0,0,0,0,0
0,0,0,0,0,0,0,0,22,0,0,20,0,0,0,0,0,0,0,0,0,0,0
0,0,0,0,0,0,0,0,0,0,0,0,0,0,0,0,0,0,0,0,0,0,0
0,0,0,0,0,0,0,0,0,0,0,0,0,0,0,0,0,0,0,0,0,0,0
0,0,0,0,0,0,0,0,0,0,0,0,0,0,0,0,0,0,0,0,0,0,0
0,0,0,0,0,0,0,0,0,0,0,0,0,0,0,0,0,0,0,0,0,0,0
0,0,0,0,0,0,0,0,0,0,0,0,0,0,0,0,0,0,0,0,0,0,0
0,0,0,0,0,0,0,0,0,0,0,0,0,0,0,0,0,0,0,0,0,0,0
0,0,0,0,0,0,0,0,0,0,0,0,0,0,0,0,0,0,0,0,0,0,0
0,0,0,0,0,0,0,0,0,0,0,0,0,0,0,0,0,0,0,0,0,0,0
0,0,0,0,0,0,0,0,0,0,0,0,0,0,0,0,0,0,0,0,0,0,0
0,0,0,0,0,0,0,0,0,0,0,0,0,0,0,0,0,0,0,0,0,0,0
0,0,0,0,0,0,0,0,0,0,0,0,0,0,0,0,0,0,0,0,0,0,0
0,0,0,0,0,0,0,0,0,0,0,0,0,0,0,0,0,0,0,0,0,0,0
0,0,0,0,0,0,0,0,0,0,0,0,0,0,0,0,0,0,0,0,0,0,0
0,0,0,0,0,0,0,0,0,0,0,0,0,0,0,0,0,0,0,0,0,0,0
0,0,0,0,0,0,0,0,0,0,0,0,0,0,0,0,0,0,0,0,0,0,0
0,0,0,0,0,0,0,0,0,0,0,0,0,0,0,0,0,0,0,0,0,0,0
0,0,0,0,0,22,0,34,0,20,0,0,0,0,0,0,0,0,0,0,0,0,0
0,0,0,0,0,22,6,6,6,20,0,0,0,0,0,0,0,0,0,0,0,0,0
0,0,0,0,0,22,24,0,24,20,0,0,0,0,0,0,0,44,0,0,0,0,0
0,0,0,0,0,22,24,0,24,20,0,0,0,0,0,0,0,0,0,0,0,0,0
0,0,0,0,0,22,24,0,24,20,0,0,0,0,0,0,0,0,0,0,0,0,0
0,0,0,0,0,22,24,0,24,20,0,0,0,0,0,0,0,0,0,0,0,0,0
0,0,0,0,0,22,24,0,24,20,0,0,0,0,0,0,0,0,0,0,0,0,0
0,0,0,0,0,22,6,6,6,20,0,0,0,0,0,0,0,0,0,0,0,0,0
0,0,0,0,0,22,0,0,0,20,0,0,0,0,0,0,0,0,0,0,0,0,0
0,0,0,0,0,0,0,0,0,0,0,0,0,0,0,0,0,0,0,0,0,0,0
endlayer

layer
0,0,0,0,0,0,0,0,0,0,0,0,0,0,0,0,0,0,0,0,0,0,0
0,0,0,0,0,0,0,0,0,0,0,0,0,0,0,0,0,0,0,0,0,0,0
0,0,0,0,0,0,0,0,0,22,20,0,0,0,0,0,0,0,0,0,0,0,0
0,0,0,0,0,0,0,0,0,22,20,0,0,0,0,0,0,0,0,0,0,0,0
0,0,0,0,0,0,0,0,0,22,20,0,0,0,0,0,0,0,0,0,0,0,0
0,0,0,0,0,0,0,0,0,22,20,0,0,0,0,0,0,0,0,0,0,0,0
0,0,0,0,0,0,0,0,0,22,20,0,0,0,0,0,0,0,0,0,0,0,0
0,0,0,0,0,0,0,0,0,22,20,0,0,0,0,0,0,0,0,0,0,0,0
0,0,0,0,0,0,0,0,0,22,20,0,0,0,0,0,0,0,0,0,0,0,0
0,0,0,0,0,0,0,0,0,22,20,0,0,0,0,0,0,0,0,0,0,0,0
0,0,0,0,0,0,0,0,0,22,20,0,0,0,0,0,0,0,0,0,0,0,0
0,0,0,0,0,0,0,0,0,0,0,0,0,0,0,0,0,0,0,0,0,0,0
0,0,0,0,0,0,0,0,0,0,0,0,0,0,0,0,0,0,0,0,0,0,0
0,0,0,0,0,0,0,0,0,0,0,0,0,0,0,0,0,0,0,0,0,0,0
0,0,0,0,0,0,0,0,0,0,0,0,0,0,0,0,0,0,0,0,0,0,0
0,0,0,0,0,0,0,0,0,0,0,0,0,0,0,0,0,0,0,0,0,0,0
0,0,0,0,0,0,0,0,0,0,0,0,0,0,0,0,0,0,0,0,0,0,0
0,0,0,0,0,0,0,0,0,0,0,0,0,0,0,0,0,0,0,0,0,0,0
0,0,0,0,0,0,0,0,0,0,0,0,0,0,0,0,0,0,0,0,0,0,0
0,0,0,0,0,0,0,0,0,0,0,0,0,0,0,0,0,0,0,0,0,0,0
0,0,0,0,0,0,0,0,0,0,0,0,0,0,0,0,0,0,0,0,0,0,0
0,0,0,0,0,0,0,0,0,0,0,0,0,0,0,0,0,0,0,0,0,0,0
0,0,0,0,0,0,0,0,0,0,0,0,0,0,0,0,0,0,0,0,0,0,0
0,0,0,0,0,0,0,0,0,0,0,0,0,0,0,0,0,0,0,0,0,0,0
0,0,0,0,0,0,0,0,0,0,0,0,0,0,0,0,0,0,0,0,0,0,0
0,0,0,0,0,0,0,0,0,0,0,0,0,0,0,0,0,0,0,0,0,0,0
0,0,0,0,0,0,0,0,0,0,0,0,0,0,0,0,0,0,0,0,0,0,0
0,0,0,0,0,0,22,24,20,0,0,0,0,0,0,0,0,0,0,0,0,0,0
0,0,0,0,0,0,22,24,20,0,0,0,0,0,0,0,0,0,0,0,0,0,0
0,0,0,0,0,0,22,24,20,0,0,0,0,0,0,0,0,0,0,0,0,0,0
0,0,0,0,0,0,22,24,20,0,0,0,0,0,0,0,0,0,0,0,0,0,0
0,0,0,0,0,0,22,24,20,0,0,0,0,0,0,0,0,0,0,0,0,0,0
0,0,0,0,0,0,22,24,20,0,0,0,0,0,0,0,0,0,0,0,0,0,0
0,0,0,0,0,0,22,24,20,0,0,0,0,0,0,0,0,0,0,0,0,0,0
0,0,0,0,0,0,22,24,20,0,0,0,0,0,0,0,0,0,0,0,0,0,0
0,0,0,0,0,0,22,24,20,0,0,0,0,0,0,0,0,0,0,0,0,0,0
0,0,0,0,0,0,0,0,0,0,0,0,0,0,0,0,0,0,0,0,0,0,0
endlayer

layer
0,0,0,0,0,0,0,0,0,0,0,0,0,0,0,0,0,0,0,0,0,0,0
0,0,0,0,0,0,0,0,0,0,0,0,0,0,0,0,0,0,0,0,0,0,0
0,0,0,0,0,0,0,0,0,0,0,0,0,0,0,0,0,0,0,0,0,0,0
0,0,0,0,0,0,0,0,0,0,0,0,0,0,0,0,0,0,0,0,0,0,0
0,0,0,0,0,0,0,0,0,0,0,0,0,0,0,0,0,0,0,0,0,0,0
0,0,0,0,0,0,0,0,0,0,0,0,0,0,0,0,0,0,0,0,0,0,0
0,0,0,0,0,0,0,0,0,0,0,0,0,0,0,0,0,0,0,0,0,0,0
0,0,0,0,0,0,0,0,0,0,0,0,0,0,0,0,0,0,0,0,0,0,0
0,0,0,0,0,0,0,0,0,0,0,0,0,0,0,0,0,0,0,0,0,0,0
0,0,0,0,0,0,0,0,0,0,0,0,0,0,0,0,0,0,0,0,0,0,0
0,0,0,0,0,0,0,0,0,0,0,0,0,0,0,0,0,0,0,0,0,0,0
0,0,0,0,0,0,0,0,0,0,0,0,0,0,0,0,0,0,0,0,0,0,0
0,0,0,0,0,0,0,0,0,0,0,0,0,0,0,0,0,0,0,0,0,0,0
0,0,0,0,0,0,0,0,0,0,0,0,0,0,0,0,0,0,0,0,0,0,0
0,0,0,0,0,0,0,0,0,0,0,0,0,0,0,0,0,0,0,0,0,0,0
0,0,0,0,0,0,0,0,0,0,0,0,0,0,0,0,0,0,0,0,0,0,0
0,0,0,0,0,0,0,0,0,0,0,0,0,0,0,0,0,0,0,0,0,0,0
0,0,0,0,0,0,0,0,0,0,0,0,0,0,0,0,0,0,0,0,0,0,0
0,0,0,0,0,0,0,0,0,0,0,0,0,0,0,0,0,0,0,0,0,0,0
0,0,0,0,0,0,0,0,0,0,0,0,0,0,0,0,0,0,0,0,0,0,0
0,0,0,0,0,0,0,0,0,0,0,0,0,0,0,0,0,0,0,0,0,0,0
0,0,0,0,0,0,0,0,0,0,0,0,0,0,0,0,0,0,0,0,0,0,0
0,0,0,0,0,0,0,0,0,0,0,0,0,0,0,0,0,0,0,0,0,0,0
0,0,0,0,0,0,0,0,0,0,0,0,0,0,0,0,0,0,0,0,0,0,0
0,0,0,0,0,0,0,0,0,0,0,0,0,0,0,0,0,0,0,0,0,0,0
0,0,0,0,0,0,0,0,0,0,0,0,0,0,0,0,0,0,0,0,0,0,0
0,0,0,0,0,0,0,0,0,0,0,0,0,0,0,0,0,0,0,0,0,0,0
0,0,0,0,0,0,0,44,0,0,0,0,0,0,0,0,0,0,0,0,0,0,0
0,0,0,0,0,0,0,0,0,0,0,0,0,0,0,0,0,0,0,0,0,0,0
0,0,0,0,0,0,0,0,0,0,0,0,0,0,0,0,0,0,0,0,0,0,0
0,0,0,0,0,0,0,0,0,0,0,0,0,0,0,0,0,0,0,0,0,0,0
0,0,0,0,0,0,0,0,0,0,0,0,0,0,0,0,0,0,0,0,0,0,0
0,0,0,0,0,0,0,0,0,0,0,0,0,0,0,0,0,0,0,0,0,0,0
0,0,0,0,0,0,0,0,0,0,0,0,0,0,0,0,0,0,0,0,0,0,0
0,0,0,0,0,0,0,0,0,0,0,0,0,0,0,0,0,0,0,0,0,0,0
0,0,0,0,0,0,0,44,0,0,0,0,0,0,0,0,0,0,0,0,0,0,0
0,0,0,0,0,0,0,0,0,0,0,0,0,0,0,0,0,0,0,0,0,0,0
endlayer

