# Converted from schematic
# author:MohawkyMagoo

weight=10
embed_into_distance=3
#acceptable_target_blocks=1,2,3,12,13
dimensions=15,19,31
#allowable_overhang=0
max_cut_in=2
#cut_in_buffer=1
max_leveling=2
#leveling_buffer=1
#preserve_water=0
#preserve_lava=0
#preserve_plants=0


rule1=0,100,4
rule2=0,100,3
rule3=0,100,1
rule4=0,100,2
rule5=0,100,109-1
rule6=0,100,98
rule7=0,100,43
rule8=0,100,5
rule9=0,100,109-2
rule10=0,100,109-3
rule11=0,100,37
rule12=0,100,53-0
rule13=0,100,85
rule14=0,100,53-2
rule15=0,100,58
rule16=0,100,64-2
rule17=0,100,64-1
rule18=0,100,64-1
rule19=0,100,64-0
rule20=0,100,64-0
rule21=0,100,53-1
rule22=0,100,102
rule23=0,100,50-2
rule24=0,100,72
rule25=0,100,64-8
rule26=0,100,50-1
rule27=0,100,50-4
rule28=0,100,64-9
rule29=0,100,50-3
rule30=0,100,17
rule31=0,100,47
rule32=0,100,109-5
rule33=0,100,109-4
rule34=0,100,109-7
rule35=0,100,109-6
rule36=0,100,126-8
rule37=0,100,53-3
rule38=0,100,126
rule39=0,100,50-5


layer
1,1,1,1,1,1,1,1,1,1,1,1,1,1,1,1,1,1,1,1,1,1,1,1,1,1,1,1,1,1,1
1,1,1,1,1,1,1,1,1,1,1,1,1,1,1,1,1,1,1,1,1,1,1,1,1,1,1,1,1,1,1
1,1,3,3,2,1,1,1,1,1,1,1,1,2,2,2,2,2,2,2,2,2,2,2,2,2,2,2,2,2,1
1,1,3,2,2,1,1,1,1,1,1,1,1,2,2,2,2,2,2,2,2,2,2,2,2,2,2,2,2,2,2
1,1,2,2,2,1,1,1,1,1,1,1,1,2,2,2,2,2,2,2,2,2,2,2,2,2,2,2,2,2,2
1,1,2,2,2,1,1,1,1,1,1,1,1,2,2,2,2,2,2,2,2,2,2,2,2,2,2,2,2,2,2
1,1,2,2,2,1,1,1,1,1,1,1,1,2,2,2,2,2,2,2,2,2,2,2,2,2,2,2,2,2,2
1,1,2,2,2,2,2,2,2,2,2,2,2,2,2,2,2,2,2,2,2,2,2,2,2,2,2,2,2,2,2
1,1,2,2,2,2,2,2,2,2,2,2,2,2,2,2,2,2,2,2,2,2,2,2,2,2,2,2,2,2,2
1,1,2,2,2,2,2,2,2,2,2,2,2,2,2,2,2,2,2,2,2,2,2,2,2,2,2,2,2,2,2
1,1,1,1,1,1,1,2,2,2,2,2,2,2,2,2,2,2,2,2,2,2,2,2,2,2,2,2,2,2,2
1,1,1,1,1,1,1,2,2,2,2,2,2,2,2,2,2,2,2,2,2,2,2,2,2,2,2,2,2,2,2
1,1,1,1,1,1,1,2,2,2,2,2,2,2,2,2,2,2,2,2,2,2,2,2,2,2,2,2,2,2,2
1,1,1,1,1,1,1,2,2,2,2,2,2,2,2,2,2,2,2,2,2,2,2,2,2,2,2,2,2,2,2
1,1,1,1,1,1,1,2,2,2,2,2,2,2,2,2,2,2,2,2,2,2,2,2,2,2,2,2,2,2,2
1,1,1,1,1,1,1,2,2,2,2,2,2,2,2,2,2,2,2,2,2,2,1,1,1,2,2,2,2,2,2
1,1,1,1,1,1,1,2,2,2,2,2,2,2,2,2,2,2,2,2,2,1,1,1,1,1,2,2,2,2,2
1,1,1,1,1,1,1,1,1,1,1,1,1,1,1,1,1,1,1,1,1,1,1,1,1,1,1,1,1,1,1
1,1,1,1,1,1,1,1,1,1,1,1,1,1,1,1,1,1,1,1,1,1,1,1,1,1,1,1,1,1,1
endlayer

layer
1,1,1,1,1,1,1,1,1,1,1,1,1,1,1,1,1,1,1,1,1,1,1,1,1,1,1,1,1,1,1
1,1,1,1,1,1,1,1,1,1,1,1,1,1,1,1,1,1,1,1,1,1,1,1,1,1,1,1,1,1,1
1,1,2,2,2,1,1,1,1,1,1,1,1,2,2,2,2,2,2,2,2,2,2,2,2,2,2,2,2,2,1
1,1,2,2,2,1,1,1,1,1,1,1,1,2,2,2,2,2,2,2,2,2,2,2,2,2,2,2,2,2,1
1,1,2,2,2,1,1,1,1,1,1,1,1,2,2,2,2,2,2,2,2,2,2,2,2,2,2,2,2,2,1
1,1,2,2,2,1,1,1,1,1,1,1,1,2,2,2,2,2,2,2,2,2,2,2,2,2,2,2,2,2,1
1,1,2,2,2,1,1,1,1,1,1,1,1,2,2,2,2,2,2,2,2,2,2,2,2,2,2,2,2,2,1
1,1,2,2,2,2,2,1,1,1,1,1,2,2,2,2,2,2,2,2,2,2,2,2,2,2,2,2,2,2,1
1,1,2,2,2,2,2,1,1,1,1,1,2,2,2,2,2,2,2,2,2,2,2,2,2,2,2,2,1,1,1
1,1,2,2,2,2,2,1,1,1,1,1,2,2,2,2,2,2,2,2,2,2,2,2,2,2,2,2,1,1,1
1,1,1,1,1,1,1,1,1,1,1,1,2,2,2,2,2,2,2,2,2,2,2,2,2,2,2,2,1,1,1
1,1,1,1,1,1,1,1,1,1,1,1,2,2,2,2,2,2,2,2,2,2,2,2,2,2,2,2,1,1,1
1,1,1,1,1,1,1,1,1,1,1,1,2,2,2,2,2,2,2,2,2,2,2,2,2,2,2,2,1,1,1
1,1,1,1,1,1,1,1,1,1,1,1,2,2,2,2,2,2,2,2,2,2,2,2,2,2,2,2,1,1,1
1,1,1,1,1,1,1,1,1,1,1,1,2,2,2,2,2,2,2,2,2,2,2,2,2,2,2,2,1,1,1
1,1,1,1,1,1,1,1,1,1,1,1,2,2,2,2,2,2,2,2,2,2,1,1,1,2,2,2,1,1,1
1,1,1,1,1,1,1,1,1,1,1,1,2,2,2,2,2,2,2,2,2,1,1,1,1,1,2,2,1,1,1
1,1,1,1,1,1,1,1,1,1,1,1,1,1,1,1,1,1,1,1,1,1,1,1,1,1,1,1,1,1,1
1,1,1,1,1,1,1,1,1,1,1,1,1,1,1,1,1,1,1,1,1,1,1,1,1,1,1,1,1,1,1
endlayer

layer
1,1,1,1,1,1,1,1,1,1,1,1,1,1,1,1,1,1,1,1,1,1,1,1,1,1,1,1,1,1,1
1,1,1,1,1,1,1,1,1,1,1,1,1,1,1,1,1,1,1,1,1,1,1,1,1,1,1,1,1,1,1
1,1,2,2,2,1,1,1,1,1,1,1,1,4,4,4,4,4,4,4,4,4,4,4,4,4,4,4,1,1,1
1,1,2,1,1,1,1,1,1,1,1,1,1,4,4,4,4,4,4,4,4,4,4,4,4,4,4,4,1,1,1
1,1,2,1,1,1,1,1,1,1,1,1,1,4,4,4,4,4,4,4,4,4,4,4,4,4,4,4,1,1,1
1,1,2,1,1,1,1,1,1,1,1,1,1,4,4,4,4,4,4,4,4,4,4,4,4,4,4,4,1,1,1
1,1,2,1,1,1,1,1,1,1,1,1,1,4,1,1,1,1,1,1,1,1,1,2,2,2,2,2,1,1,1
1,1,2,1,1,1,1,1,1,1,1,1,2,4,1,1,1,1,1,1,1,1,1,2,2,2,2,2,1,1,1
1,1,1,1,1,1,1,1,1,1,1,1,2,4,1,1,1,1,1,1,1,1,1,2,2,2,2,2,1,1,1
1,1,2,1,1,1,1,1,1,1,1,1,2,4,1,1,1,1,1,1,1,1,1,2,2,2,2,2,1,1,1
1,1,1,1,1,1,1,1,1,1,1,1,2,4,1,1,1,1,1,1,1,1,1,2,2,2,2,2,1,1,1
1,1,1,1,1,1,1,1,1,1,1,1,1,1,1,1,1,1,1,1,1,1,1,2,2,2,2,2,1,1,1
1,1,1,1,1,1,1,1,1,1,1,1,1,1,1,1,1,1,1,1,1,1,1,2,2,2,2,2,1,1,1
1,1,1,1,1,1,1,1,1,1,1,1,1,1,1,1,1,1,1,1,1,1,1,2,2,2,2,2,1,1,1
1,1,1,1,1,1,1,1,1,1,1,1,1,1,1,1,1,1,1,1,1,1,1,2,2,2,2,2,1,1,1
1,1,1,1,1,1,1,1,1,1,1,1,1,1,1,1,1,1,1,1,1,1,1,4,4,4,4,4,1,1,1
1,1,1,1,1,1,1,1,1,1,1,1,2,1,1,1,1,1,1,1,1,1,1,1,1,1,1,1,1,1,1
1,1,1,1,1,1,1,1,1,1,1,1,1,1,1,1,1,1,1,1,1,1,1,1,1,1,1,1,1,1,1
1,1,1,1,1,1,1,1,1,1,1,1,1,1,1,1,1,1,1,1,1,1,1,1,1,1,1,1,1,1,1
endlayer

layer
0,0,0,0,0,0,0,0,0,0,0,0,0,0,0,0,0,0,0,0,0,0,0,0,0,0,0,0,0,0,0
0,0,0,0,0,0,0,0,0,0,0,0,0,0,0,0,0,0,0,0,0,0,0,0,0,0,0,0,0,0,0
0,0,6,6,6,6,6,6,6,6,6,6,6,0,0,0,0,0,0,0,11,0,0,0,0,0,0,0,0,0,0
0,0,6,0,0,6,0,0,6,6,5,0,6,0,0,0,0,0,0,0,0,0,0,0,0,0,0,0,0,0,0
0,0,6,0,0,0,0,0,0,0,0,0,6,0,0,0,0,0,0,0,0,0,0,0,0,0,0,0,0,0,0
0,0,6,0,0,0,0,0,0,0,0,0,6,0,0,0,0,0,0,0,0,0,0,0,0,0,0,0,0,0,0
0,0,6,0,0,6,6,6,6,17,6,6,6,0,0,6,6,6,6,6,6,9,9,6,6,6,6,6,6,0,0
0,0,6,6,6,6,0,0,0,0,0,0,6,0,0,16,0,0,0,0,6,6,6,6,8,7,7,7,6,0,0
0,0,20,0,0,19,0,0,0,0,0,0,6,0,0,6,0,0,0,0,6,6,6,6,8,7,7,7,6,0,0
0,0,6,6,6,6,0,0,0,0,0,0,6,0,0,6,0,0,0,12,6,10,10,6,8,7,7,7,6,0,0
0,0,6,0,0,6,6,6,18,6,6,6,6,0,0,6,0,0,13,12,6,0,0,6,8,8,8,8,6,0,0
0,0,6,0,0,0,6,0,0,0,0,0,0,0,0,6,0,0,0,12,6,0,0,6,8,8,8,8,6,0,0
0,0,6,0,0,0,6,0,0,0,0,0,0,0,0,6,0,0,13,12,6,0,0,6,8,8,8,8,6,5,0
0,0,6,0,0,0,19,0,0,0,0,0,0,0,0,6,15,0,14,8,6,0,0,6,8,8,8,8,6,0,0
0,0,6,0,0,0,6,0,0,0,0,0,0,0,0,6,6,6,6,6,6,0,0,6,6,6,6,6,6,0,0
0,0,6,0,0,0,6,0,0,0,0,0,0,0,0,0,0,0,0,0,0,0,0,0,0,0,0,0,0,0,0
0,0,6,6,6,6,6,0,0,0,0,0,6,0,0,0,0,0,0,0,0,0,0,0,0,0,0,0,0,0,0
0,0,0,0,0,0,0,0,0,0,0,0,0,0,0,0,0,0,0,0,0,0,0,0,0,0,0,0,0,0,0
0,0,0,0,0,0,0,0,0,0,0,0,0,0,0,0,0,0,0,0,0,0,0,0,0,0,0,0,0,0,0
endlayer

layer
0,0,0,0,0,0,0,0,0,0,0,0,0,0,0,0,0,0,0,0,0,0,0,0,0,0,0,0,0,0,0
0,0,0,0,0,0,0,0,0,0,0,0,0,0,0,0,0,0,0,0,0,0,0,0,0,0,0,0,0,0,0
0,0,6,6,6,6,6,6,6,6,6,6,6,0,0,0,0,0,0,0,0,0,0,0,0,0,0,0,0,0,0
0,0,6,0,0,6,0,0,6,5,0,0,6,0,0,0,0,0,0,0,0,0,0,0,0,0,0,0,0,0,0
0,0,22,0,0,0,0,0,0,0,0,0,22,0,0,0,0,0,0,0,0,0,0,0,0,0,0,0,0,0,0
0,0,6,0,0,0,0,0,0,0,0,0,6,0,0,0,0,0,0,0,0,0,0,0,0,0,0,0,0,0,0
0,0,6,0,0,6,6,6,6,25,6,6,6,0,0,6,8,22,22,8,6,0,0,6,6,6,6,6,6,0,0
0,0,6,6,6,6,0,0,0,0,0,0,6,0,0,25,0,0,0,0,8,0,0,6,0,0,0,0,6,0,0
0,0,25,0,0,25,0,0,0,0,0,0,22,0,0,8,0,0,0,0,8,0,0,16,0,0,7,7,6,0,0
0,0,6,6,6,6,0,0,0,0,0,0,6,0,0,8,0,0,0,23,8,0,0,6,0,0,0,0,6,0,0
0,0,6,0,0,6,6,6,25,6,22,6,6,0,0,22,0,0,24,0,8,0,0,6,0,0,0,0,6,0,0
0,0,6,0,0,0,6,0,0,0,0,0,0,0,0,22,0,0,0,0,22,0,0,6,0,0,0,0,6,0,0
0,0,6,0,0,0,6,0,0,0,0,0,0,0,0,22,0,0,24,0,22,0,0,6,21,13,0,0,16,0,0
0,0,22,0,0,0,25,0,0,0,0,0,0,0,0,8,0,0,0,23,8,0,0,6,8,14,0,0,6,0,0
0,0,6,0,0,0,6,0,0,0,0,0,0,0,0,6,8,22,22,8,6,0,0,6,6,6,6,6,6,0,0
0,0,6,0,0,0,6,0,0,0,0,0,0,0,0,0,0,0,0,0,0,0,0,0,0,0,0,0,0,0,0
0,0,6,6,22,6,6,0,0,0,0,0,6,0,0,0,0,0,0,0,0,0,0,0,0,0,0,0,0,0,0
0,0,0,0,0,0,0,0,0,0,0,0,0,0,0,0,0,0,0,0,0,0,0,0,0,0,0,0,0,0,0
0,0,0,0,0,0,0,0,0,0,0,0,0,0,0,0,0,0,0,0,0,0,0,0,0,0,0,0,0,0,0
endlayer

layer
0,0,0,0,0,0,0,0,0,0,0,0,0,0,0,0,0,0,0,0,0,0,0,0,0,0,0,0,0,0,0
0,0,0,0,0,0,0,0,0,0,0,0,0,0,0,0,0,0,0,0,0,0,0,0,0,0,0,0,0,0,0
0,0,6,6,6,6,6,6,6,22,6,6,6,0,0,0,0,0,0,0,0,0,0,0,0,0,0,0,0,0,0
0,0,6,29,0,6,6,6,5,0,29,0,6,0,0,0,0,0,0,0,0,0,0,0,0,0,0,0,0,0,0
0,0,22,0,0,0,0,0,0,0,0,0,22,0,0,0,0,0,0,0,0,0,0,0,0,0,0,0,0,0,0
0,0,6,0,0,0,0,0,0,0,27,0,6,0,0,0,0,0,0,0,0,0,0,27,0,0,0,0,27,0,0
0,0,6,0,27,6,6,6,6,6,6,6,6,0,0,6,8,22,22,8,6,0,23,6,30,22,22,30,6,26,0
0,0,6,6,6,6,0,0,0,29,0,0,6,0,0,8,26,0,0,31,8,0,0,8,0,0,0,0,8,0,0
0,0,6,26,23,6,26,0,0,0,0,0,22,0,0,8,0,0,0,31,8,0,0,28,0,0,0,0,8,0,0
0,0,6,6,6,6,0,0,27,0,0,0,6,0,0,8,0,0,0,31,8,0,0,8,0,0,0,0,22,0,0
0,0,6,0,0,6,6,6,6,6,22,6,6,26,0,22,0,0,0,31,8,0,0,8,0,0,0,0,8,0,0
0,0,6,0,0,0,6,0,29,0,0,0,29,0,0,22,0,0,0,31,8,0,0,22,0,0,0,0,8,0,0
0,0,6,26,0,23,6,0,0,0,0,0,0,0,0,22,0,0,0,31,8,0,0,22,0,24,0,0,28,0,0
0,0,22,0,0,0,6,26,0,0,0,0,0,0,0,8,0,0,0,31,8,0,0,8,0,0,0,0,8,0,0
0,0,6,0,0,0,6,0,0,0,0,0,0,0,0,6,8,22,22,8,6,0,23,6,30,22,22,30,6,26,0
0,0,6,0,0,0,6,0,0,0,0,0,27,0,0,0,0,0,0,0,0,0,0,29,0,0,0,0,29,0,0
0,0,6,6,22,6,6,0,0,0,0,23,6,26,0,0,0,0,0,0,0,0,0,0,0,0,0,0,0,0,0
0,0,0,0,0,0,0,0,0,0,0,0,29,0,0,0,0,0,0,0,0,0,0,0,0,0,0,0,0,0,0
0,0,0,0,0,0,0,0,0,0,0,0,0,0,0,0,0,0,0,0,0,0,0,0,0,0,0,0,0,0,0
endlayer

layer
0,0,0,0,0,0,0,0,0,0,0,0,0,0,0,0,0,0,0,0,0,0,0,0,0,0,0,0,0,0,0
0,0,0,0,0,0,0,0,0,0,0,0,0,0,0,0,0,0,0,0,0,0,0,0,0,0,0,0,0,0,0
0,0,6,6,6,6,6,6,6,22,6,6,6,0,0,0,0,0,0,0,0,0,0,0,0,0,0,0,0,0,0
0,0,6,0,0,6,6,5,0,0,0,0,6,0,0,0,0,0,0,0,0,0,0,0,0,0,0,0,0,0,0
0,0,6,0,0,0,0,0,0,0,0,0,22,0,0,0,0,0,0,0,0,0,0,0,0,0,0,0,0,0,0
0,0,6,0,0,0,0,0,0,0,0,0,6,0,0,27,0,0,0,0,27,0,0,0,0,0,0,0,0,0,0
0,0,6,0,0,6,6,6,6,6,6,6,6,0,23,6,8,8,8,8,6,26,12,6,6,6,6,6,6,21,0
0,0,6,6,6,6,0,0,0,0,0,0,6,0,0,8,8,0,0,8,8,0,12,8,0,0,29,0,8,21,0
0,0,6,0,0,6,0,0,0,0,0,23,6,0,0,8,8,0,0,8,8,0,12,8,26,0,0,0,8,21,0
0,0,6,6,6,6,0,0,0,0,0,0,6,0,0,8,8,0,0,8,8,0,12,8,0,0,0,0,8,21,0
0,0,6,0,0,6,6,6,6,6,6,6,6,0,0,8,8,0,0,8,8,0,12,8,0,0,0,0,8,21,0
0,0,6,0,0,0,6,32,0,0,0,0,32,0,0,8,8,0,0,8,8,0,12,8,0,0,0,0,8,21,0
0,0,6,0,0,0,6,0,0,0,0,0,0,0,0,8,8,0,0,8,8,0,12,8,26,0,0,23,8,21,0
0,0,22,0,0,0,6,0,0,0,0,0,0,0,0,8,8,27,0,8,8,0,12,8,0,0,0,0,8,21,0
0,0,6,0,0,0,6,0,0,0,0,0,0,0,23,6,8,8,8,8,6,26,12,6,6,6,6,6,6,21,0
0,0,6,0,0,0,6,0,0,0,0,0,33,0,0,29,0,0,0,0,29,0,0,0,0,0,0,0,0,0,0
0,0,6,6,22,6,6,35,0,0,0,34,6,0,0,0,0,0,0,0,0,0,0,0,0,0,0,0,0,0,0
0,0,0,0,0,0,0,0,0,0,0,0,0,0,0,0,0,0,0,0,0,0,0,0,0,0,0,0,0,0,0
0,0,0,0,0,0,0,0,0,0,0,0,0,0,0,0,0,0,0,0,0,0,0,0,0,0,0,0,0,0,0
endlayer

layer
0,0,0,0,0,0,0,0,0,0,0,0,0,0,0,0,0,0,0,0,0,0,0,0,0,0,0,0,0,0,0
0,0,0,0,0,27,0,0,0,0,0,0,27,0,0,0,0,0,0,0,0,0,0,0,0,0,0,0,0,0,0
0,0,6,6,6,6,6,6,6,6,6,6,6,26,0,0,0,0,0,0,0,0,0,0,0,0,0,0,0,0,0
0,0,6,6,6,6,5,0,0,0,6,6,6,0,0,0,0,0,0,0,0,0,0,0,0,0,0,0,0,0,0
0,0,6,6,6,6,6,6,6,6,6,6,6,0,0,0,0,0,0,0,0,0,0,0,0,0,0,0,0,0,0
0,0,6,6,6,6,6,6,6,6,6,6,6,0,0,0,0,0,0,0,0,0,0,0,0,0,0,0,0,0,0
0,0,6,6,6,6,6,6,6,6,6,6,6,26,12,6,6,6,6,6,6,21,0,12,8,8,8,8,21,0,0
0,0,6,6,6,6,6,6,6,6,6,6,6,0,12,6,6,6,6,6,6,21,0,12,8,0,0,8,21,0,0
0,0,6,6,6,6,6,6,6,6,6,6,6,0,12,6,6,6,6,6,6,21,0,12,8,0,0,8,21,0,0
0,0,6,6,6,6,6,6,6,6,6,6,6,0,12,6,6,6,6,6,6,21,0,12,8,0,0,8,21,0,0
0,23,6,6,6,6,6,6,6,6,6,6,6,0,12,6,6,6,6,6,6,21,0,12,8,0,0,8,21,0,0
0,0,6,6,6,6,6,6,6,6,6,6,6,0,12,6,6,6,6,6,6,21,0,12,8,0,0,8,21,0,0
0,0,6,6,6,6,6,6,6,6,6,6,6,0,12,6,6,6,6,6,6,21,0,12,8,0,0,8,21,0,0
0,0,6,6,6,6,6,6,6,6,6,6,6,0,12,6,6,6,6,6,6,21,0,12,8,0,0,8,21,0,0
0,0,6,6,6,6,6,6,6,6,6,6,6,0,12,6,6,6,6,6,6,21,0,12,8,8,8,8,21,0,0
0,0,6,6,6,6,6,6,6,6,6,6,6,0,0,0,0,0,0,0,0,0,0,0,0,0,0,0,0,0,0
0,23,6,6,6,6,6,6,6,6,6,6,6,0,0,0,0,0,0,0,0,0,0,0,0,0,0,0,0,0,0
0,0,29,0,0,0,29,0,0,0,0,0,0,0,0,0,0,0,0,0,0,0,0,0,0,0,0,0,0,0,0
0,0,0,0,0,0,0,0,0,0,0,0,0,0,0,0,0,0,0,0,0,0,0,0,0,0,0,0,0,0,0
endlayer

layer
0,0,0,0,0,0,0,0,0,0,0,0,0,0,0,0,0,0,0,0,0,0,0,0,0,0,0,0,0,0,0
0,0,27,0,0,0,0,0,0,0,0,0,0,0,0,0,0,0,0,0,0,0,0,0,0,0,0,0,0,0,0
0,23,6,6,6,6,6,6,6,6,6,6,6,0,0,0,0,0,0,0,0,0,0,0,0,0,0,0,0,0,0
0,0,6,0,0,0,0,0,0,0,0,0,6,0,0,0,0,0,0,0,0,0,0,0,0,0,0,0,0,0,0
0,0,6,0,0,0,0,0,0,0,0,0,6,0,0,0,0,0,0,0,0,0,0,0,0,0,0,0,0,0,0
0,0,6,0,0,0,0,0,0,0,0,0,6,0,0,0,0,0,0,0,0,0,0,0,0,0,0,0,0,0,0
0,0,6,6,6,6,6,6,6,17,6,6,6,0,0,12,6,6,6,6,21,0,0,0,12,8,8,21,0,0,0
0,0,6,0,0,0,0,0,0,0,0,0,6,0,0,12,6,6,6,6,21,0,0,0,12,8,8,21,0,0,0
0,0,6,0,0,0,0,0,0,0,0,0,6,0,0,12,6,6,6,6,21,0,0,0,12,8,8,21,0,0,0
0,0,6,0,0,0,0,0,0,0,0,0,6,0,0,12,6,6,6,6,21,0,0,0,12,8,8,21,0,0,0
0,0,6,0,0,0,0,0,0,0,0,0,6,0,0,12,6,6,6,6,21,0,0,0,12,8,8,21,0,0,0
0,0,6,6,6,6,6,6,6,17,6,6,6,0,0,12,6,6,6,6,21,0,0,0,12,8,8,21,0,0,0
0,0,6,0,0,0,6,0,0,0,0,0,6,0,0,12,6,6,6,6,21,0,0,0,12,8,8,21,0,0,0
0,0,6,0,0,0,20,0,0,0,0,0,6,0,0,12,6,6,6,6,21,0,0,0,12,8,8,21,0,0,0
0,0,6,0,0,0,6,0,0,0,0,0,6,0,0,12,6,6,6,6,21,0,0,0,12,8,8,21,0,0,0
0,0,6,0,0,0,6,0,0,0,0,0,6,0,0,0,0,0,0,0,0,0,0,0,0,0,0,0,0,0,0
0,0,6,6,6,6,6,6,6,6,6,6,6,0,0,0,0,0,0,0,0,0,0,0,0,0,0,0,0,0,0
0,0,0,0,0,0,0,0,0,0,0,0,0,0,0,0,0,0,0,0,0,0,0,0,0,0,0,0,0,0,0
0,0,0,0,0,0,0,0,0,0,0,0,0,0,0,0,0,0,0,0,0,0,0,0,0,0,0,0,0,0,0
endlayer

layer
0,0,0,0,0,0,0,0,0,0,0,0,0,0,0,0,0,0,0,0,0,0,0,0,0,0,0,0,0,0,0
0,0,0,0,0,0,0,0,0,0,0,0,0,0,0,0,0,0,0,0,0,0,0,0,0,0,0,0,0,0,0
0,0,6,6,6,6,6,6,6,6,6,6,6,0,0,0,0,0,0,0,0,0,0,0,0,0,0,0,0,0,0
0,0,6,0,0,0,0,0,0,0,0,0,6,0,0,0,0,0,0,0,0,0,0,0,0,0,0,0,0,0,0
0,0,22,0,0,0,0,0,0,0,0,0,6,0,0,0,0,0,0,0,0,0,0,0,0,0,0,0,0,0,0
0,0,6,0,0,0,0,0,0,0,0,0,6,0,0,0,0,0,0,0,0,0,0,0,0,0,0,0,0,0,0
0,0,6,6,6,6,6,6,6,25,6,6,6,0,0,0,12,6,6,21,0,0,0,0,0,12,21,0,0,0,0
0,0,6,0,0,0,0,0,0,0,0,0,6,0,0,0,12,6,6,21,0,0,0,0,0,12,21,0,0,0,0
0,0,22,0,0,0,0,0,0,0,0,0,22,0,0,0,12,6,6,21,0,0,0,0,0,12,21,0,0,0,0
0,0,6,0,0,0,0,0,0,0,0,0,6,0,0,0,12,6,6,21,0,0,0,0,0,12,21,0,0,0,0
0,0,6,0,0,0,0,0,0,0,0,0,22,0,0,0,12,6,6,21,0,0,0,0,0,12,21,0,0,0,0
0,0,6,6,6,6,6,6,6,25,6,6,6,0,0,0,12,6,6,21,0,0,0,0,0,12,21,0,0,0,0
0,0,6,0,0,0,6,0,0,0,0,0,22,0,0,0,12,6,6,21,0,0,0,0,0,12,21,0,0,0,0
0,0,22,0,0,0,25,0,0,0,0,0,6,0,0,0,12,6,6,21,0,0,0,0,0,12,21,0,0,0,0
0,0,6,0,0,0,6,0,0,0,0,0,22,0,0,0,12,6,6,21,0,0,0,0,0,12,21,0,0,0,0
0,0,6,0,0,0,6,0,0,0,0,0,6,0,0,0,0,0,0,0,0,0,0,0,0,0,0,0,0,0,0
0,0,6,6,22,6,6,6,22,6,22,6,6,0,0,0,0,0,0,0,0,0,0,0,0,0,0,0,0,0,0
0,0,0,0,0,0,0,0,0,0,0,0,0,0,0,0,0,0,0,0,0,0,0,0,0,0,0,0,0,0,0
0,0,0,0,0,0,0,0,0,0,0,0,0,0,0,0,0,0,0,0,0,0,0,0,0,0,0,0,0,0,0
endlayer

layer
0,0,0,0,0,0,0,0,0,0,0,0,0,0,0,0,0,0,0,0,0,0,0,0,0,0,0,0,0,0,0
0,8,8,8,8,8,8,8,8,8,8,8,8,8,0,0,0,0,0,0,0,0,0,0,0,0,0,0,0,0,0
0,0,6,6,6,6,8,8,8,8,8,8,6,0,0,0,0,0,0,0,0,0,0,0,0,0,0,0,0,0,0
0,0,6,0,0,0,0,0,29,0,0,0,6,0,0,0,0,0,0,0,0,0,0,0,0,0,0,0,0,0,0
0,0,22,0,0,0,0,0,0,0,0,0,6,0,0,0,0,0,0,0,0,0,0,0,0,0,0,0,0,0,0
0,0,6,0,0,0,0,0,0,27,0,0,6,0,0,0,0,0,0,0,0,0,0,0,0,0,0,0,0,0,0
0,0,6,6,6,6,6,6,6,6,6,6,6,0,0,0,0,12,21,0,0,0,0,0,0,0,0,0,0,0,0
0,0,6,0,0,0,0,0,0,29,0,0,6,0,0,0,0,12,21,0,0,0,0,0,0,0,0,0,0,0,0
0,0,22,0,0,0,0,0,0,0,0,0,22,0,0,0,0,12,21,0,0,0,0,0,0,0,0,0,0,0,0
0,0,6,0,0,0,0,0,0,0,0,23,6,0,0,0,0,12,21,0,0,0,0,0,0,0,0,0,0,0,0
0,0,6,0,0,0,0,0,0,0,0,0,22,0,0,0,0,12,21,0,0,0,0,0,0,0,0,0,0,0,0
0,0,6,6,6,6,6,6,6,6,6,6,6,0,0,0,0,12,21,0,0,0,0,0,0,0,0,0,0,0,0
0,0,6,26,0,23,6,0,0,0,0,0,22,0,0,0,0,12,21,0,0,0,0,0,0,0,0,0,0,0,0
0,0,22,0,0,0,6,26,0,0,0,0,6,0,0,0,0,12,21,0,0,0,0,0,0,0,0,0,0,0,0
0,0,6,0,0,0,6,0,0,0,0,0,22,0,0,0,0,12,21,0,0,0,0,0,0,0,0,0,0,0,0
0,0,6,0,0,0,6,0,0,0,0,27,6,0,0,0,0,0,0,0,0,0,0,0,0,0,0,0,0,0,0
0,0,6,6,22,6,6,6,22,6,22,6,6,0,0,0,0,0,0,0,0,0,0,0,0,0,0,0,0,0,0
0,0,0,0,0,0,0,0,0,0,0,0,0,0,0,0,0,0,0,0,0,0,0,0,0,0,0,0,0,0,0
0,0,0,0,0,0,0,0,0,0,0,0,0,0,0,0,0,0,0,0,0,0,0,0,0,0,0,0,0,0,0
endlayer

layer
0,0,0,0,0,0,0,0,0,0,0,0,0,0,0,0,0,0,0,0,0,0,0,0,0,0,0,0,0,0,0
0,0,0,0,0,0,0,0,0,0,0,0,0,0,0,0,0,0,0,0,0,0,0,0,0,0,0,0,0,0,0
0,14,14,14,14,14,14,14,14,14,14,14,14,14,0,0,0,0,0,0,0,0,0,0,0,0,0,0,0,0,0
0,0,6,6,6,6,8,8,8,8,8,8,6,0,0,0,0,0,0,0,0,0,0,0,0,0,0,0,0,0,0
0,23,6,0,0,6,26,0,0,0,0,23,6,0,0,0,0,0,0,0,0,0,0,0,0,0,0,0,0,0,0
0,0,6,0,0,6,8,8,8,8,8,8,6,0,0,0,0,0,0,0,0,0,0,0,0,0,0,0,0,0,0
0,0,6,6,6,6,6,6,6,6,6,6,6,0,0,0,0,0,0,0,0,0,0,0,0,0,0,0,0,0,0
0,23,6,0,0,6,0,0,0,0,0,0,6,0,0,0,0,0,0,0,0,0,0,0,0,0,0,0,0,0,0
0,0,6,0,0,6,0,0,0,0,0,0,6,0,0,0,0,0,0,0,0,0,0,0,0,0,0,0,0,0,0
0,0,6,0,0,6,0,0,0,0,0,0,6,0,0,0,0,0,0,0,0,0,0,0,0,0,0,0,0,0,0
0,12,6,6,6,6,0,0,0,0,0,0,6,0,0,0,0,0,0,0,0,0,0,0,0,0,0,0,0,0,0
0,12,8,0,0,0,8,6,6,6,6,6,6,0,0,0,0,0,0,0,0,0,0,0,0,0,0,0,0,0,0
0,12,8,0,0,0,8,0,0,0,0,0,6,0,0,0,0,0,0,0,0,0,0,0,0,0,0,0,0,0,0
0,12,8,0,0,0,8,0,0,0,0,0,6,0,0,0,0,0,0,0,0,0,0,0,0,0,0,0,0,0,0
0,12,8,0,0,0,8,0,0,0,0,0,6,0,0,0,0,0,0,0,0,0,0,0,0,0,0,0,0,0,0
0,12,8,0,0,0,8,0,0,0,0,0,6,0,0,0,0,0,0,0,0,0,0,0,0,0,0,0,0,0,0
0,12,6,6,6,6,6,6,6,6,6,6,6,0,0,0,0,0,0,0,0,0,0,0,0,0,0,0,0,0,0
0,12,0,0,0,0,0,0,0,0,0,0,0,0,0,0,0,0,0,0,0,0,0,0,0,0,0,0,0,0,0
0,0,0,0,0,0,0,0,0,0,0,0,0,0,0,0,0,0,0,0,0,0,0,0,0,0,0,0,0,0,0
endlayer

layer
0,0,0,0,0,0,0,0,0,0,0,0,0,0,0,0,0,0,0,0,0,0,0,0,0,0,0,0,0,0,0
0,0,0,0,0,0,0,0,0,0,0,0,0,0,0,0,0,0,0,0,0,0,0,0,0,0,0,0,0,0,0
0,0,0,0,0,0,0,0,0,0,0,0,0,0,0,0,0,0,0,0,0,0,0,0,0,0,0,0,0,0,0
0,14,14,14,14,14,14,14,14,14,14,14,14,14,0,0,0,0,0,0,0,0,0,0,0,0,0,0,0,0,0
0,8,8,8,8,8,8,8,8,8,8,8,8,36,0,0,0,0,0,0,0,0,0,0,0,0,0,0,0,0,0
0,37,37,37,37,37,37,37,37,37,37,37,37,37,0,0,0,0,0,0,0,0,0,0,0,0,0,0,0,0,0
0,14,14,14,14,14,14,14,14,14,14,14,14,14,0,0,0,0,0,0,0,0,0,0,0,0,0,0,0,0,0
0,0,6,0,0,8,0,0,0,0,0,0,8,0,0,0,0,0,0,0,0,0,0,0,0,0,0,0,0,0,0
0,0,6,0,0,8,0,0,0,0,0,0,8,0,0,0,0,0,0,0,0,0,0,0,0,0,0,0,0,0,0
0,8,8,8,8,8,0,0,0,0,0,0,8,0,0,0,0,0,0,0,0,0,0,0,0,0,0,0,0,0,0
0,0,12,6,6,6,37,37,37,37,37,37,37,37,0,0,0,0,0,0,0,0,0,0,0,0,0,0,0,0,0
0,0,12,8,0,8,21,39,0,0,0,0,39,38,0,0,0,0,0,0,0,0,0,0,0,0,0,0,0,0,0
0,0,12,8,0,8,14,14,14,14,14,14,14,14,0,0,0,0,0,0,0,0,0,0,0,0,0,0,0,0,0
0,0,12,8,0,8,21,0,0,0,0,0,6,0,0,0,0,0,0,0,0,0,0,0,0,0,0,0,0,0,0
0,0,12,8,0,8,21,0,0,0,0,0,6,0,0,0,0,0,0,0,0,0,0,0,0,0,0,0,0,0,0
0,0,12,8,0,8,21,0,0,0,0,0,6,0,0,0,0,0,0,0,0,0,0,0,0,0,0,0,0,0,0
0,0,12,6,6,6,37,37,37,37,37,37,37,37,0,0,0,0,0,0,0,0,0,0,0,0,0,0,0,0,0
0,0,38,36,36,36,38,38,38,38,38,38,38,38,0,0,0,0,0,0,0,0,0,0,0,0,0,0,0,0,0
0,0,0,0,0,0,0,0,0,0,0,0,0,0,0,0,0,0,0,0,0,0,0,0,0,0,0,0,0,0,0
endlayer

layer
0,0,0,0,0,0,0,0,0,0,0,0,0,0,0,0,0,0,0,0,0,0,0,0,0,0,0,0,0,0,0
0,0,0,0,0,0,0,0,0,0,0,0,0,0,0,0,0,0,0,0,0,0,0,0,0,0,0,0,0,0,0
0,0,0,0,0,0,0,0,0,0,0,0,0,0,0,0,0,0,0,0,0,0,0,0,0,0,0,0,0,0,0
0,0,0,0,0,0,0,0,0,0,0,0,0,0,0,0,0,0,0,0,0,0,0,0,0,0,0,0,0,0,0
0,0,39,0,0,39,0,0,0,0,0,0,39,0,0,0,0,0,0,0,0,0,0,0,0,0,0,0,0,0,0
0,0,0,0,0,0,0,0,0,0,0,0,0,0,0,0,0,0,0,0,0,0,0,0,0,0,0,0,0,0,0
0,0,0,0,0,0,0,0,0,0,0,0,0,0,0,0,0,0,0,0,0,0,0,0,0,0,0,0,0,0,0
0,14,14,14,14,14,14,14,14,14,14,14,14,14,0,0,0,0,0,0,0,0,0,0,0,0,0,0,0,0,0
0,8,8,8,8,8,36,36,36,36,36,36,8,36,0,0,0,0,0,0,0,0,0,0,0,0,0,0,0,0,0
0,37,37,37,37,37,37,37,37,37,37,37,37,37,0,0,0,0,0,0,0,0,0,0,0,0,0,0,0,0,0
0,0,0,12,8,21,0,0,0,0,0,0,0,0,0,0,0,0,0,0,0,0,0,0,0,0,0,0,0,0,0
0,0,0,12,8,21,0,0,0,0,0,0,0,0,0,0,0,0,0,0,0,0,0,0,0,0,0,0,0,0,0
0,0,0,12,8,21,0,0,0,0,0,0,0,0,0,0,0,0,0,0,0,0,0,0,0,0,0,0,0,0,0
0,0,0,12,8,21,14,14,14,14,14,14,14,14,0,0,0,0,0,0,0,0,0,0,0,0,0,0,0,0,0
0,0,0,12,8,21,36,36,36,36,36,36,8,36,0,0,0,0,0,0,0,0,0,0,0,0,0,0,0,0,0
0,0,0,12,8,21,37,37,37,37,37,37,37,37,0,0,0,0,0,0,0,0,0,0,0,0,0,0,0,0,0
0,0,0,12,8,21,0,0,0,0,0,0,0,0,0,0,0,0,0,0,0,0,0,0,0,0,0,0,0,0,0
0,0,0,0,0,0,0,0,0,0,0,0,0,0,0,0,0,0,0,0,0,0,0,0,0,0,0,0,0,0,0
0,0,0,0,0,0,0,0,0,0,0,0,0,0,0,0,0,0,0,0,0,0,0,0,0,0,0,0,0,0,0
endlayer

layer
0,0,0,0,0,0,0,0,0,0,0,0,0,0,0,0,0,0,0,0,0,0,0,0,0,0,0,0,0,0,0
0,0,0,0,0,0,0,0,0,0,0,0,0,0,0,0,0,0,0,0,0,0,0,0,0,0,0,0,0,0,0
0,0,0,0,0,0,0,0,0,0,0,0,0,0,0,0,0,0,0,0,0,0,0,0,0,0,0,0,0,0,0
0,0,0,0,0,0,0,0,0,0,0,0,0,0,0,0,0,0,0,0,0,0,0,0,0,0,0,0,0,0,0
0,0,0,0,0,0,0,0,0,0,0,0,0,0,0,0,0,0,0,0,0,0,0,0,0,0,0,0,0,0,0
0,0,0,0,0,0,0,0,0,0,0,0,0,0,0,0,0,0,0,0,0,0,0,0,0,0,0,0,0,0,0
0,0,0,0,0,0,0,0,0,0,0,0,0,0,0,0,0,0,0,0,0,0,0,0,0,0,0,0,0,0,0
0,0,0,0,0,0,0,0,0,0,0,0,0,0,0,0,0,0,0,0,0,0,0,0,0,0,0,0,0,0,0
0,0,0,0,0,39,0,0,0,0,0,0,39,0,0,0,0,0,0,0,0,0,0,0,0,0,0,0,0,0,0
0,0,0,0,0,0,0,0,0,0,0,0,0,0,0,0,0,0,0,0,0,0,0,0,0,0,0,0,0,0,0
0,0,0,0,39,0,0,0,0,0,0,0,0,0,0,0,0,0,0,0,0,0,0,0,0,0,0,0,0,0,0
0,0,0,0,0,0,0,0,0,0,0,0,0,0,0,0,0,0,0,0,0,0,0,0,0,0,0,0,0,0,0
0,0,0,0,0,0,0,0,0,0,0,0,0,0,0,0,0,0,0,0,0,0,0,0,0,0,0,0,0,0,0
0,0,0,0,0,0,0,0,0,0,0,0,0,0,0,0,0,0,0,0,0,0,0,0,0,0,0,0,0,0,0
0,0,0,0,0,0,0,0,0,0,0,0,39,0,0,0,0,0,0,0,0,0,0,0,0,0,0,0,0,0,0
0,0,0,0,0,0,0,0,0,0,0,0,0,0,0,0,0,0,0,0,0,0,0,0,0,0,0,0,0,0,0
0,0,0,0,39,0,0,0,0,0,0,0,0,0,0,0,0,0,0,0,0,0,0,0,0,0,0,0,0,0,0
0,0,0,0,0,0,0,0,0,0,0,0,0,0,0,0,0,0,0,0,0,0,0,0,0,0,0,0,0,0,0
0,0,0,0,0,0,0,0,0,0,0,0,0,0,0,0,0,0,0,0,0,0,0,0,0,0,0,0,0,0,0
endlayer

