# Converted from schematic
# author:MohawkyMagoo

weight=10
embed_into_distance=2
#acceptable_target_blocks=1,2,3,12,13
dimensions=19,14,21
#allowable_overhang=0
max_cut_in=2
#cut_in_buffer=1
max_leveling=2
#leveling_buffer=1
#preserve_water=0
#preserve_lava=0
#preserve_plants=0


rule1=0,100,4
rule2=0,100,3
rule3=0,100,1
rule4=0,100,2
rule5=0,100,98
rule6=0,100,64
rule7=0,100,109-2
rule8=0,100,109-3
rule9=0,100,50-2
rule10=0,100,109-0
rule11=0,100,64-8
rule12=0,100,64-1
rule13=0,100,50-4
rule14=0,100,50-3
rule15=0,100,64-9
rule16=0,100,50-1
rule17=0,100,5
rule18=0,100,85
rule19=0,100,64-0
rule20=0,100,109-1
rule21=0,100,50-5
rule22=0,100,102
rule23=0,100,53-2
rule24=0,100,53-3


layer
2,2,2,2,2,2,1,1,1,1,1,2,2,2,2,1,1,1,1,1,1
2,2,2,2,2,2,1,1,1,1,1,2,2,2,2,1,1,1,1,1,1
3,2,2,2,2,2,1,1,1,1,1,2,2,2,2,1,1,1,1,1,1
3,2,2,2,2,2,1,1,1,1,1,2,2,2,2,1,1,1,1,1,1
2,2,2,2,2,2,2,2,2,2,2,2,1,2,2,1,1,1,1,1,1
2,2,3,2,2,2,2,2,3,3,2,2,2,2,2,2,2,2,2,2,2
2,2,2,2,2,2,2,3,3,3,3,2,2,2,2,2,2,2,2,2,2
2,2,1,1,2,3,3,3,3,3,3,2,2,2,2,2,2,2,2,3,3
1,1,2,2,2,3,3,3,3,3,3,2,2,2,2,2,2,3,3,3,3
1,1,2,2,3,3,3,3,3,3,3,3,2,2,2,3,3,3,3,3,3
1,1,2,2,2,2,3,3,3,3,3,3,3,2,3,3,2,2,3,3,3
1,1,2,2,2,2,2,2,3,3,3,3,3,3,3,3,2,3,3,3,3
1,1,2,2,2,2,2,2,2,3,3,3,3,3,3,3,3,3,3,3,3
1,2,2,2,2,2,2,2,2,3,3,3,3,3,3,3,3,3,3,3,2
endlayer

layer
4,4,4,4,4,1,1,1,1,1,1,1,1,1,1,1,1,1,1,1,1
4,4,4,4,4,1,1,1,1,1,1,1,1,1,1,1,1,1,1,1,1
4,4,4,4,4,1,1,1,1,1,1,1,1,1,1,1,1,1,1,1,1
4,4,4,4,4,1,1,1,1,1,1,1,1,1,1,1,1,1,1,1,1
4,4,4,4,4,1,1,1,1,1,1,1,1,1,1,1,1,1,1,1,1
4,4,4,4,4,1,2,2,2,1,1,1,1,1,1,1,1,1,1,1,1
4,4,4,4,4,2,2,1,1,1,1,1,1,1,1,1,1,1,1,1,1
4,4,1,1,1,2,1,1,1,1,1,1,1,1,1,1,1,1,1,2,1
4,4,1,1,1,1,1,1,1,1,1,1,1,1,1,1,1,1,1,2,1
4,4,1,1,1,1,1,1,1,1,1,1,1,2,2,2,2,2,2,3,1
4,4,1,1,1,1,1,1,1,3,1,1,2,2,2,2,2,2,3,2,1
1,1,1,1,1,1,1,1,1,3,3,3,3,2,2,2,2,3,3,3,1
1,1,1,1,1,1,2,2,2,3,3,3,3,3,3,3,3,3,3,3,1
1,1,1,1,1,1,1,1,1,1,1,1,1,1,1,1,1,1,1,1,1
endlayer

layer
0,0,0,0,0,0,0,0,0,0,0,0,0,0,0,0,0,0,0,0,0
0,0,0,0,0,0,0,0,0,0,0,0,0,0,0,0,0,0,0,0,0
0,0,0,0,0,0,0,0,0,5,5,5,5,5,5,5,6,5,5,5,5
0,0,0,0,0,5,7,7,7,5,0,0,0,0,0,0,0,0,0,0,5
0,0,0,0,0,5,5,5,5,5,0,0,5,5,5,5,5,5,5,5,5
0,0,0,0,0,5,5,5,5,5,0,0,5,5,5,5,5,5,5,5,5
0,0,0,0,9,5,5,5,8,5,0,0,5,5,5,5,5,5,5,5,5
0,0,5,5,5,5,0,0,0,5,0,0,5,5,5,5,5,5,5,5,5
0,0,5,5,0,0,0,0,0,5,0,0,5,5,5,5,5,5,5,5,5
0,9,5,5,0,0,0,0,0,5,0,0,5,5,5,5,5,5,2,2,5
0,0,5,5,0,0,0,0,0,5,0,0,5,2,2,2,2,2,2,2,5
10,5,5,5,0,0,0,0,0,5,5,5,5,2,2,2,2,2,2,2,5
10,5,5,5,5,5,5,5,5,2,2,2,2,2,2,2,2,2,2,2,5
10,5,5,5,5,5,5,5,5,5,5,5,5,5,5,5,5,5,5,5,5
endlayer

layer
0,0,0,0,0,0,0,0,0,0,0,0,0,0,0,0,0,0,0,0,0
0,0,0,0,0,0,0,0,0,0,0,0,0,0,0,0,0,0,0,0,0
0,0,0,0,0,0,0,0,0,5,5,5,5,5,5,5,11,5,5,5,5
0,0,0,0,0,0,0,0,0,5,0,0,0,0,0,0,0,0,0,0,5
0,0,0,0,0,5,7,7,0,5,0,0,5,5,5,5,5,5,5,5,5
0,0,0,0,0,5,5,5,12,5,0,0,5,5,5,5,5,5,5,5,5
0,0,0,0,0,5,5,5,0,5,0,0,5,5,5,5,5,5,5,5,5
0,0,5,5,5,5,0,0,0,5,0,0,5,5,5,5,5,5,5,5,5
0,0,5,5,0,0,0,0,0,5,0,0,5,5,5,5,5,5,5,5,5
0,0,5,5,0,0,0,0,0,5,0,0,5,5,5,5,5,5,5,5,5
0,0,5,5,0,0,0,0,0,5,0,0,5,5,5,5,5,5,5,5,5
0,0,5,5,0,0,0,0,0,5,5,5,5,5,5,5,5,5,5,5,5
0,10,5,5,5,5,5,5,5,5,2,2,2,5,5,5,5,5,5,5,5
0,10,5,5,5,5,5,5,5,5,5,5,5,5,5,5,5,5,5,5,5
endlayer

layer
0,0,0,0,0,0,0,0,0,0,0,0,0,0,0,0,0,0,0,0,0
0,0,0,0,0,0,0,0,0,13,0,0,0,0,0,0,13,0,0,0,13
0,0,0,0,0,0,0,0,9,5,5,5,5,5,5,5,5,5,5,5,5
0,0,0,0,0,0,0,0,0,5,14,0,0,0,0,0,0,0,0,9,5
0,0,0,0,0,0,0,0,0,5,0,0,5,5,5,5,5,5,5,5,5
0,0,0,0,0,5,7,7,15,5,0,0,5,5,5,5,5,5,5,5,5
0,0,0,0,0,5,5,5,0,5,0,0,5,5,5,5,5,5,5,5,5
0,0,5,5,5,5,16,0,0,5,0,0,5,5,5,5,5,5,5,5,5
0,0,5,5,0,0,0,0,0,5,0,0,5,5,5,5,5,5,5,5,5
0,0,5,5,0,0,0,0,0,5,0,0,5,5,5,5,5,5,5,5,5
0,0,5,5,0,0,0,0,0,5,13,0,5,5,5,5,5,5,5,5,5
0,0,5,5,0,13,0,0,0,5,5,5,5,5,5,5,5,5,5,5,5
0,0,10,5,5,5,5,5,5,5,5,5,5,5,5,5,5,5,5,5,5
0,0,10,5,5,5,5,5,5,5,5,5,5,5,5,5,5,5,5,5,5
endlayer

layer
0,0,0,0,0,0,0,0,0,0,0,0,0,0,0,0,0,0,0,0,0
0,0,0,0,0,0,0,0,0,0,0,0,0,0,0,0,0,0,0,0,0
0,0,0,0,0,0,0,0,0,17,17,17,17,17,17,17,17,17,17,17,5
0,0,0,0,0,0,0,0,0,17,17,17,17,17,17,17,17,17,17,17,5
0,0,0,0,0,0,0,0,0,17,17,17,5,5,5,5,5,5,5,5,5
0,0,0,0,0,0,0,0,13,17,17,17,5,5,5,5,5,5,5,5,5
0,0,13,0,0,5,7,7,5,17,17,17,5,5,5,5,5,5,5,5,5
0,9,5,5,5,5,5,5,5,5,17,17,5,5,5,5,5,5,5,5,5
0,0,5,5,5,5,5,5,5,5,17,17,5,5,5,5,5,5,5,5,5
0,0,5,5,5,5,5,5,5,5,17,17,5,5,5,5,5,5,5,5,5
0,0,5,5,5,5,5,5,5,5,17,17,5,5,5,5,5,5,5,5,5
0,0,5,5,5,5,5,5,5,5,5,5,5,5,5,5,5,5,5,5,5
0,0,0,10,5,5,5,5,5,5,5,5,5,5,5,5,5,5,5,5,5
0,0,0,10,5,5,5,5,5,5,5,5,5,5,5,5,5,5,5,5,5
endlayer

layer
0,0,0,0,0,0,0,0,0,0,0,0,0,0,0,0,0,0,0,0,0
0,0,0,0,0,0,0,0,0,0,0,0,0,0,0,0,0,0,0,0,0
0,0,0,0,0,0,0,0,0,18,18,18,18,18,18,18,18,18,18,18,18
0,0,0,0,0,0,0,0,0,18,0,0,0,0,0,0,0,0,0,0,0
0,0,0,0,0,0,0,0,0,18,0,0,5,5,5,5,5,5,5,0,0
0,0,0,0,0,0,0,0,0,18,0,0,5,5,20,0,0,0,5,0,0
0,0,0,0,0,21,0,0,0,18,0,0,5,5,0,0,0,0,5,0,0
0,0,5,5,5,5,6,6,5,5,0,0,5,5,0,0,0,0,19,0,0
0,0,5,0,0,0,0,0,0,5,0,0,5,0,0,0,0,0,5,0,0
0,0,5,0,0,0,0,0,0,5,0,0,5,0,0,0,0,0,5,0,0
0,0,5,0,0,5,20,0,0,5,0,0,5,5,5,12,5,5,5,0,0
0,0,5,5,5,5,5,12,5,5,0,0,0,0,0,0,0,0,0,0,0
0,0,0,0,0,0,0,0,0,0,0,0,0,0,0,0,0,0,0,0,0
0,0,0,0,0,0,0,0,0,0,0,0,0,0,0,0,0,0,0,0,0
endlayer

layer
0,0,0,0,0,0,0,0,0,0,0,0,0,0,0,0,0,0,0,0,0
0,0,0,0,0,0,0,0,0,0,0,0,0,0,0,0,0,0,0,0,0
0,0,0,0,0,0,0,0,0,21,18,0,0,0,0,21,0,0,0,0,18
0,0,0,0,0,0,0,0,0,0,0,0,0,0,0,0,0,0,0,0,0
0,0,0,0,0,0,0,0,0,0,0,0,5,5,5,22,5,5,5,0,0
0,0,0,0,0,0,0,0,0,0,0,0,5,0,0,0,0,0,5,0,0
0,0,0,0,0,0,0,0,0,0,0,0,5,7,0,0,0,0,5,0,0
0,0,5,5,5,5,15,11,5,5,0,0,5,5,0,0,0,0,11,0,0
0,0,5,0,0,0,0,0,0,5,0,0,5,0,0,0,0,0,5,0,0
0,0,22,0,0,0,0,0,0,22,0,0,5,0,0,0,0,0,5,0,0
0,0,5,0,0,20,0,0,0,5,0,0,5,5,5,11,5,5,5,0,0
0,0,5,5,5,5,5,11,5,5,0,0,0,0,0,0,0,0,0,0,0
0,0,0,0,0,0,0,0,0,0,0,0,0,0,0,0,0,0,0,0,0
0,0,0,0,0,0,0,0,0,0,0,0,0,0,0,0,0,0,0,0,0
endlayer

layer
0,0,0,0,0,0,0,0,0,0,0,0,0,0,0,0,0,0,0,0,0
0,0,0,0,0,0,0,0,0,0,0,0,0,0,0,0,0,0,0,0,0
0,0,0,0,0,0,0,0,0,0,18,0,0,0,0,0,0,0,0,0,18
0,0,0,0,0,0,0,0,0,0,0,0,0,0,0,0,0,0,0,0,0
0,0,0,0,0,0,0,0,0,0,0,0,5,5,5,22,5,5,5,0,0
0,0,0,0,0,0,0,0,0,0,0,0,5,0,0,0,14,0,5,0,0
0,0,0,0,0,0,13,0,0,0,0,0,5,0,0,0,0,0,5,0,0
0,0,5,5,5,5,5,5,5,5,0,0,5,7,0,0,0,0,5,0,0
0,0,5,16,0,0,0,14,0,5,0,0,5,5,0,0,0,0,5,0,0
0,0,22,0,0,0,0,0,0,22,0,0,5,5,0,0,13,0,5,0,0
0,0,5,5,20,0,0,13,0,5,0,0,5,5,5,5,5,5,5,0,0
0,0,5,5,5,5,5,5,5,5,0,0,0,0,8,8,8,0,0,0,0
0,0,0,0,0,8,8,8,0,0,0,0,0,0,0,0,0,0,0,0,0
0,0,0,0,0,0,0,0,0,0,0,0,0,0,0,0,0,0,0,0,0
endlayer

layer
0,0,0,0,0,0,0,0,0,0,0,0,0,0,0,0,0,0,0,0,0
0,0,0,0,0,0,0,0,0,0,0,0,0,0,0,0,0,0,0,0,0
0,0,0,0,0,0,0,0,0,0,18,0,0,0,0,0,0,0,0,0,18
0,0,0,0,0,0,0,0,0,0,0,0,13,0,0,0,0,0,13,0,0
0,0,0,0,0,0,0,0,0,0,0,9,5,5,5,22,5,5,5,16,0
0,0,0,0,0,0,0,0,0,0,0,0,5,0,0,0,0,0,5,0,0
0,0,13,0,0,0,0,0,0,13,0,0,5,0,0,0,0,0,5,0,0
0,9,5,5,5,5,5,5,5,5,16,0,5,0,0,0,0,0,5,0,0
0,0,5,0,0,0,0,0,0,5,0,0,5,7,0,0,0,0,5,0,0
0,0,22,0,0,0,0,0,0,22,0,0,5,5,0,0,0,0,5,0,0
0,0,5,20,0,0,0,0,0,5,0,9,5,5,5,5,5,5,5,16,0
0,9,5,5,5,5,5,5,5,5,16,0,14,0,0,0,0,0,14,0,0
0,0,14,0,0,0,0,0,0,14,0,0,0,0,0,0,0,0,0,0,0
0,0,0,0,0,0,0,0,0,0,0,0,0,0,0,0,0,0,0,0,0
endlayer

layer
0,0,0,0,0,0,0,0,0,0,0,0,0,0,0,0,0,0,0,0,0
0,0,0,0,0,0,0,0,0,0,0,0,0,0,0,0,0,0,0,0,0
0,0,0,0,0,0,0,0,0,0,17,17,17,17,17,17,17,17,17,17,17
0,0,0,0,0,0,0,0,0,0,17,17,17,17,17,17,17,17,17,17,17
0,0,0,0,0,0,0,0,0,0,17,17,5,5,5,5,5,5,5,17,17
17,17,17,17,17,17,17,17,17,17,17,17,5,5,5,5,5,5,5,17,17
17,17,17,17,17,17,17,17,17,17,17,17,5,0,5,5,5,5,5,17,17
17,17,5,5,5,5,5,5,5,5,17,17,5,0,5,5,5,5,5,17,17
17,17,5,5,5,5,5,5,5,5,17,17,5,0,5,5,5,5,5,17,17
17,17,5,8,5,5,5,5,5,5,17,17,5,7,5,5,5,5,5,17,17
17,17,5,0,0,0,5,5,5,5,17,17,5,5,5,5,5,5,5,17,17
17,17,5,5,5,5,5,5,5,5,17,17,17,17,17,17,17,17,17,17,17
17,17,17,17,17,17,17,17,17,17,17,17,17,17,17,17,17,17,17,17,17
17,17,17,17,17,17,17,17,17,17,17,17,17,0,0,0,0,0,0,0,0
endlayer

layer
0,0,0,0,0,0,0,0,0,0,0,0,0,0,0,0,0,0,0,0,0
0,0,0,0,0,0,0,0,0,0,0,0,0,0,0,0,0,0,0,0,0
0,0,0,0,0,0,0,0,0,0,18,18,18,18,18,18,18,18,18,18,18
0,0,0,0,0,0,0,0,0,0,18,0,0,0,0,0,0,0,0,0,18
0,0,0,0,0,0,0,0,0,0,18,0,5,5,5,5,5,5,5,0,18
18,18,18,18,18,18,18,18,18,18,18,0,5,0,0,0,0,0,5,0,18
18,0,0,0,0,0,0,0,0,0,0,0,5,0,0,0,0,0,5,0,18
18,0,5,5,5,5,5,5,5,5,0,0,5,0,0,0,0,0,19,0,0
18,0,5,0,0,0,0,0,0,5,0,0,5,0,0,0,0,0,5,0,0
18,0,5,0,0,0,0,0,0,19,0,0,5,0,0,0,0,0,5,0,18
18,0,5,0,0,0,0,0,0,5,0,0,5,5,5,5,5,5,5,0,18
18,0,5,5,5,5,5,5,5,5,0,0,0,0,0,0,0,0,0,0,18
18,0,0,0,0,0,0,0,0,0,0,0,18,18,18,18,18,18,18,18,18
18,18,18,18,18,18,18,18,18,18,18,18,18,0,0,0,0,0,0,0,0
endlayer

layer
0,0,0,0,0,0,0,0,0,0,0,0,0,0,0,0,0,0,0,0,0
0,0,0,0,0,0,0,0,0,0,0,0,0,0,0,0,0,0,0,0,0
0,0,0,0,0,0,0,0,0,0,21,0,0,0,0,0,0,0,0,0,21
0,0,0,0,0,0,0,0,0,0,0,0,0,0,0,0,0,0,0,0,0
0,0,0,0,0,0,0,0,0,0,0,0,5,5,5,22,5,5,5,0,0
21,0,0,0,0,21,0,0,0,0,21,0,5,0,0,0,0,0,5,0,0
0,0,0,0,0,0,0,0,0,0,0,0,5,0,0,0,0,0,5,0,18
0,0,5,5,5,5,22,5,5,5,0,0,22,0,0,0,0,0,11,0,0
0,0,5,0,0,0,0,0,0,5,0,0,5,0,0,0,0,0,5,0,0
21,0,22,0,0,0,0,0,0,11,0,0,5,0,0,0,0,0,5,0,18
0,0,5,0,0,0,0,0,0,5,0,0,5,5,5,22,5,5,5,0,0
0,0,5,5,5,5,22,5,5,5,0,0,0,0,0,0,0,0,0,0,0
0,0,0,0,0,0,0,0,0,0,0,0,0,0,0,0,0,0,0,0,21
21,0,0,0,0,0,0,0,0,0,0,0,21,0,0,0,0,0,0,0,0
endlayer

layer
0,0,0,0,0,0,0,0,0,0,0,0,0,0,0,0,0,0,0,0,0
0,0,0,0,0,0,0,0,0,0,0,0,0,0,0,0,0,0,0,0,0
0,0,0,0,0,0,0,0,0,0,0,0,0,0,0,0,0,0,0,0,0
0,0,0,0,0,0,0,0,0,0,0,0,13,0,0,0,0,0,13,0,0
0,0,0,0,0,0,0,0,0,0,0,9,5,5,5,22,5,5,5,16,0
0,0,0,0,0,0,0,0,0,0,0,0,5,0,0,0,14,0,5,0,0
0,0,13,0,0,0,0,0,0,13,0,0,5,0,0,0,0,0,5,0,0
0,9,5,5,5,5,22,5,5,5,16,0,22,0,0,0,0,0,5,0,0
0,0,5,0,0,0,0,14,0,5,0,0,5,0,0,0,0,0,5,0,0
0,0,22,0,0,0,0,0,0,5,0,0,5,0,0,0,13,0,5,0,0
0,0,5,0,0,0,0,13,0,5,0,9,5,5,5,22,5,5,5,16,0
0,9,5,5,5,5,22,5,5,5,16,0,14,0,0,0,0,0,14,0,0
0,0,14,0,0,0,0,0,0,14,0,0,0,0,0,0,0,0,0,0,0
0,0,0,0,0,0,0,0,0,0,0,0,0,0,0,0,0,0,0,0,0
endlayer

layer
0,0,0,0,0,0,0,0,0,0,0,0,0,0,0,0,0,0,0,0,0
0,0,0,0,0,0,0,0,0,0,0,0,0,0,0,0,0,0,0,0,0
0,0,0,0,0,0,0,0,0,0,0,0,0,0,0,0,0,0,0,0,0
0,0,0,0,0,0,0,0,0,0,0,0,23,23,23,23,23,23,23,0,0
0,0,0,0,0,0,0,0,0,0,0,0,5,17,17,17,17,17,5,0,0
0,0,0,0,0,0,0,0,0,0,0,0,5,0,0,0,0,0,5,0,0
0,0,23,23,23,23,23,23,23,23,0,0,5,0,0,0,0,0,5,0,0
0,0,5,17,17,17,17,17,17,5,0,0,5,0,0,0,0,0,5,0,0
0,0,5,0,0,0,0,0,0,5,0,0,5,0,0,0,0,0,5,0,0
0,0,5,0,0,0,0,0,0,5,0,0,5,0,0,0,0,0,5,0,0
0,0,5,0,0,0,0,0,0,5,0,0,5,17,17,17,17,17,5,0,0
0,0,5,17,17,17,17,17,17,5,0,0,24,24,24,24,24,24,24,0,0
0,0,24,24,24,24,24,24,24,24,0,0,0,0,0,0,0,0,0,0,0
0,0,0,0,0,0,0,0,0,0,0,0,0,0,0,0,0,0,0,0,0
endlayer

layer
0,0,0,0,0,0,0,0,0,0,0,0,0,0,0,0,0,0,0,0,0
0,0,0,0,0,0,0,0,0,0,0,0,0,0,0,0,0,0,0,0,0
0,0,0,0,0,0,0,0,0,0,0,0,0,0,0,0,0,0,0,0,0
0,0,0,0,0,0,0,0,0,0,0,0,0,0,0,0,0,0,0,0,0
0,0,0,0,0,0,0,0,0,0,0,0,23,23,23,23,23,23,23,0,0
0,0,0,0,0,0,0,0,0,0,0,0,5,17,17,17,17,17,5,0,0
0,0,0,0,0,0,0,0,0,0,0,0,5,0,0,0,0,0,5,0,0
0,0,23,23,23,23,23,23,23,23,0,0,5,0,0,0,0,0,5,0,0
0,0,5,17,17,17,17,17,17,5,0,0,5,0,0,0,0,0,5,0,0
0,0,5,0,0,0,0,0,0,5,0,0,5,17,17,17,17,17,5,0,0
0,0,5,17,17,17,17,17,17,5,0,0,24,24,24,24,24,24,24,0,0
0,0,24,24,24,24,24,24,24,24,0,0,0,0,0,0,0,0,0,0,0
0,0,0,0,0,0,0,0,0,0,0,0,0,0,0,0,0,0,0,0,0
0,0,0,0,0,0,0,0,0,0,0,0,0,0,0,0,0,0,0,0,0
endlayer

layer
0,0,0,0,0,0,0,0,0,0,0,0,0,0,0,0,0,0,0,0,0
0,0,0,0,0,0,0,0,0,0,0,0,0,0,0,0,0,0,0,0,0
0,0,0,0,0,0,0,0,0,0,0,0,0,0,0,0,0,0,0,0,0
0,0,0,0,0,0,0,0,0,0,0,0,0,0,0,0,0,0,0,0,0
0,0,0,0,0,0,0,0,0,0,0,0,0,0,0,0,0,0,0,0,0
0,0,0,0,0,0,0,0,0,0,0,0,23,23,23,23,23,23,23,0,0
0,0,0,0,0,0,0,0,0,0,0,0,5,17,17,17,17,17,5,0,0
0,0,0,0,0,0,0,0,0,0,0,9,5,0,0,0,0,0,5,16,0
0,0,23,23,23,23,23,23,23,23,0,0,5,17,17,17,17,17,5,0,0
0,0,17,17,17,17,17,17,17,17,0,0,24,24,24,24,24,24,24,0,0
0,0,24,24,24,24,24,24,24,24,0,0,0,0,0,0,0,0,0,0,0
0,0,0,0,0,0,0,0,0,0,0,0,0,0,0,0,0,0,0,0,0
0,0,0,0,0,0,0,0,0,0,0,0,0,0,0,0,0,0,0,0,0
0,0,0,0,0,0,0,0,0,0,0,0,0,0,0,0,0,0,0,0,0
endlayer

layer
0,0,0,0,0,0,0,0,0,0,0,0,0,0,0,0,0,0,0,0,0
0,0,0,0,0,0,0,0,0,0,0,0,0,0,0,0,0,0,0,0,0
0,0,0,0,0,0,0,0,0,0,0,0,0,0,0,0,0,0,0,0,0
0,0,0,0,0,0,0,0,0,0,0,0,0,0,0,0,0,0,0,0,0
0,0,0,0,0,0,0,0,0,0,0,0,0,0,0,0,0,0,0,0,0
0,0,0,0,0,0,0,0,0,0,0,0,0,0,0,0,0,0,0,0,0
0,0,0,0,0,0,0,0,0,0,0,0,23,23,23,23,23,23,23,0,0
0,0,0,0,0,0,0,0,0,0,0,0,17,17,17,17,17,17,17,0,0
0,0,0,0,0,0,0,0,0,0,0,0,24,24,24,24,24,24,24,0,0
0,0,21,0,0,0,0,0,0,21,0,0,0,0,0,0,0,0,0,0,0
0,0,0,0,0,0,0,0,0,0,0,0,0,0,0,0,0,0,0,0,0
0,0,0,0,0,0,0,0,0,0,0,0,0,0,0,0,0,0,0,0,0
0,0,0,0,0,0,0,0,0,0,0,0,0,0,0,0,0,0,0,0,0
0,0,0,0,0,0,0,0,0,0,0,0,0,0,0,0,0,0,0,0,0
endlayer

layer
0,0,0,0,0,0,0,0,0,0,0,0,0,0,0,0,0,0,0,0,0
0,0,0,0,0,0,0,0,0,0,0,0,0,0,0,0,0,0,0,0,0
0,0,0,0,0,0,0,0,0,0,0,0,0,0,0,0,0,0,0,0,0
0,0,0,0,0,0,0,0,0,0,0,0,0,0,0,0,0,0,0,0,0
0,0,0,0,0,0,0,0,0,0,0,0,0,0,0,0,0,0,0,0,0
0,0,0,0,0,0,0,0,0,0,0,0,0,0,0,0,0,0,0,0,0
0,0,0,0,0,0,0,0,0,0,0,0,0,0,0,0,0,0,0,0,0
0,0,0,0,0,0,0,0,0,0,0,0,21,0,0,0,0,0,21,0,0
0,0,0,0,0,0,0,0,0,0,0,0,0,0,0,0,0,0,0,0,0
0,0,0,0,0,0,0,0,0,0,0,0,0,0,0,0,0,0,0,0,0
0,0,0,0,0,0,0,0,0,0,0,0,0,0,0,0,0,0,0,0,0
0,0,0,0,0,0,0,0,0,0,0,0,0,0,0,0,0,0,0,0,0
0,0,0,0,0,0,0,0,0,0,0,0,0,0,0,0,0,0,0,0,0
0,0,0,0,0,0,0,0,0,0,0,0,0,0,0,0,0,0,0,0,0
endlayer

