# Converted from schematic
# author:MohawkyMagoo

weight=10
embed_into_distance=3
#acceptable_target_blocks=1,2,3,12,13
dimensions=13,20,10
#allowable_overhang=0
max_cut_in=2
#cut_in_buffer=1
max_leveling=2
#leveling_buffer=1
#preserve_water=0
#preserve_lava=0
#preserve_plants=0


rule1=0,100,4
rule2=0,100,3
rule3=0,100,2
rule4=0,100,109-1
rule5=0,100,98
rule6=0,100,64-0
rule7=0,100,58
rule8=0,100,109-2
rule9=0,100,61-5
rule10=0,100,47
rule11=0,100,64-8
rule12=0,100,102
rule13=0,100,85
rule14=0,100,5
rule15=0,100,53-1
rule16=0,100,50-3
rule17=0,100,72
rule18=0,100,50-1
rule19=0,100,50-2
rule20=0,100,50-4
rule21=0,100,53-0


layer
1,1,1,1,1,1,1,1,1,1
1,1,1,1,1,1,1,1,1,1
1,1,1,1,1,1,1,1,1,1
1,1,2,2,2,2,2,2,2,2
1,1,2,2,2,2,2,2,2,2
1,1,2,2,2,2,2,2,2,2
1,1,2,2,2,2,2,2,2,2
1,1,2,2,2,2,2,2,2,2
1,1,2,2,2,2,2,2,2,2
1,1,2,2,2,2,2,2,2,2
1,1,2,2,2,2,2,2,2,2
1,1,2,2,2,2,2,2,2,2
1,1,2,2,2,2,2,2,2,2
1,1,2,2,2,2,2,2,2,2
1,1,2,2,2,2,2,2,2,2
1,1,2,2,2,2,2,2,2,2
1,1,2,2,2,2,2,2,2,2
1,1,2,2,2,2,2,2,2,2
1,1,1,1,1,1,1,1,1,1
1,1,1,1,1,1,1,1,1,1
endlayer

layer
1,1,1,1,1,1,1,1,1,1
1,1,1,1,1,1,1,1,1,1
1,1,1,1,1,1,1,1,1,1
1,1,1,1,1,1,1,1,2,2
1,1,1,1,1,1,1,1,2,2
1,1,1,1,1,1,1,1,2,2
1,1,1,1,1,1,1,1,2,2
1,1,1,1,1,1,1,1,2,2
1,1,2,2,2,2,2,2,2,2
1,1,2,2,2,2,2,2,2,2
1,1,2,2,2,2,2,2,2,2
1,1,2,2,2,2,2,2,2,2
1,1,2,2,2,2,2,2,2,2
1,1,2,2,2,2,2,2,2,2
1,1,2,2,2,2,2,2,2,2
1,1,2,2,2,2,2,2,2,2
1,1,2,2,2,2,2,2,2,2
1,1,2,2,2,2,2,2,2,2
1,1,1,1,1,1,1,1,1,1
1,1,1,1,1,1,1,1,1,1
endlayer

layer
1,1,1,1,1,1,1,1,1,1
1,1,1,1,1,1,1,1,1,1
1,1,1,1,1,1,1,1,1,1
1,1,1,1,1,1,1,1,1,1
1,1,1,1,1,1,1,1,1,1
1,1,1,1,1,1,1,1,1,1
1,1,1,1,1,1,1,1,1,1
1,1,1,1,1,1,1,1,1,1
1,1,2,2,2,2,2,2,1,1
1,1,2,2,2,2,2,2,1,1
1,1,2,2,2,2,3,2,1,1
1,1,2,2,2,2,2,2,1,1
1,1,2,2,2,2,2,2,1,1
1,1,2,2,2,2,2,2,1,1
1,1,2,3,2,2,2,2,1,1
1,1,2,2,2,2,2,2,2,2
1,1,2,2,2,2,2,2,2,2
1,1,2,2,2,2,2,2,2,2
1,1,1,1,1,1,1,1,1,1
1,1,1,1,1,1,1,1,1,1
endlayer

layer
1,1,1,1,1,1,1,1,1,1
1,1,1,1,1,1,1,1,1,1
1,1,1,1,1,1,1,1,1,1
1,1,1,1,1,1,1,1,1,1
1,1,1,1,1,1,1,1,1,1
1,1,1,1,1,1,1,1,1,1
1,1,1,1,1,1,1,1,1,1
1,1,1,1,1,1,1,1,1,1
1,1,2,2,2,2,2,2,1,1
1,1,2,2,2,2,2,2,1,1
1,1,2,2,2,2,0,2,1,1
1,1,2,2,2,2,2,2,1,1
1,1,2,2,2,2,2,2,1,1
1,1,2,2,2,2,2,2,1,1
1,1,2,0,2,2,2,2,1,1
1,1,2,2,2,2,2,2,1,1
1,1,2,2,2,2,2,2,3,1
1,1,2,2,2,2,2,2,1,1
1,1,1,1,1,1,1,1,1,1
1,1,1,1,1,1,1,1,1,1
endlayer

layer
0,0,0,0,0,0,0,0,0,0
0,0,0,0,0,0,0,0,0,0
0,0,5,5,5,5,5,5,0,0
0,0,5,9,0,0,7,5,0,0
0,0,5,9,0,0,0,6,0,0
0,0,5,0,0,0,0,5,0,0
0,0,5,10,8,8,8,5,0,0
0,0,5,5,5,5,5,5,0,0
0,0,5,5,5,5,5,5,0,0
0,0,5,5,5,5,5,5,0,0
0,0,5,5,5,5,5,5,0,0
0,0,5,5,5,5,5,5,0,0
0,0,5,5,5,5,5,5,0,0
0,0,5,5,5,5,5,5,0,0
0,0,5,5,5,5,5,5,0,0
0,0,5,5,5,5,5,5,0,0
0,0,5,5,5,5,5,5,4,0
0,0,5,5,5,5,5,5,0,0
0,0,0,0,0,0,0,0,0,0
0,0,0,0,0,0,0,0,0,0
endlayer

layer
0,0,0,0,0,0,0,0,0,0
0,0,0,0,0,0,0,0,0,0
0,0,5,5,12,5,5,5,0,0
0,0,5,0,0,0,0,5,0,0
0,0,12,0,0,0,0,11,0,0
0,0,5,0,0,0,0,5,0,0
0,0,5,10,0,0,0,5,0,0
0,0,5,10,0,0,0,5,0,0
0,0,5,10,0,0,0,5,0,0
0,0,5,5,0,0,0,5,0,0
0,0,5,14,0,0,0,5,0,0
0,0,5,15,13,0,0,5,0,0
0,0,5,15,0,0,0,5,0,0
0,0,5,15,13,0,0,5,0,0
0,0,5,15,0,0,0,5,0,0
0,0,5,0,0,0,0,5,0,0
0,0,5,0,0,0,0,6,0,0
0,0,5,5,5,5,5,5,0,0
0,0,0,0,0,0,0,0,0,0
0,0,0,0,0,0,0,0,0,0
endlayer

layer
0,0,0,0,0,0,0,0,0,0
0,0,0,0,0,0,0,0,0,0
0,0,5,5,12,5,5,5,0,0
0,0,5,16,0,0,16,5,0,0
0,0,12,0,0,0,0,5,0,0
0,0,5,0,0,0,0,5,0,0
0,0,5,10,0,0,0,5,0,0
0,0,5,10,0,0,0,5,0,0
0,0,5,10,0,0,0,5,0,0
0,0,5,14,0,0,0,5,0,0
0,0,14,0,0,0,0,14,0,0
0,0,12,0,17,0,0,12,0,0
0,0,12,0,0,0,0,12,0,0
0,0,14,18,17,0,0,12,0,0
0,0,12,0,0,0,0,14,0,0
0,0,12,0,0,0,0,14,0,0
0,0,14,0,0,0,0,11,0,0
0,0,5,14,12,12,14,5,0,0
0,0,0,0,0,0,0,0,0,0
0,0,0,0,0,0,0,0,0,0
endlayer

layer
0,0,0,0,0,0,0,0,0,0
0,0,0,0,0,0,0,0,0,0
0,19,5,5,12,5,5,5,18,0
0,0,5,0,0,0,0,5,0,0
0,0,12,0,0,0,0,5,0,0
0,0,5,0,0,0,0,5,0,0
0,0,5,10,0,0,0,5,0,0
0,19,5,10,0,0,0,5,18,0
0,0,5,10,0,0,19,5,0,0
0,0,5,14,0,0,0,5,0,0
0,0,14,10,0,0,0,14,0,0
0,0,14,10,0,0,0,12,0,0
0,0,14,10,0,0,0,12,0,0
0,0,14,10,0,0,0,12,0,0
0,0,14,10,0,0,19,14,0,0
0,0,14,10,0,0,0,14,0,0
0,0,14,10,0,0,0,14,0,0
0,0,5,14,12,12,14,5,0,0
0,0,0,0,0,0,0,0,0,0
0,0,0,0,0,0,0,0,0,0
endlayer

layer
0,0,0,0,0,0,0,0,0,0
0,0,0,0,0,0,0,0,0,0
0,21,5,5,5,5,5,5,15,0
0,21,14,0,0,0,0,14,15,0
0,21,14,0,0,0,0,14,15,0
0,21,14,0,0,0,0,14,15,0
0,21,14,10,0,0,0,14,15,0
0,21,5,10,0,0,0,5,15,0
0,21,5,10,0,0,0,5,15,0
0,19,5,14,0,0,0,5,18,0
0,0,14,14,0,0,0,14,0,0
0,0,14,14,0,0,0,14,0,0
0,0,14,14,0,0,0,14,0,0
0,0,14,14,0,0,0,14,0,0
0,0,14,14,0,0,0,14,0,0
0,0,14,14,0,0,0,14,0,0
0,0,14,14,0,20,0,14,0,0
0,19,5,14,14,14,14,5,18,0
0,0,16,0,0,0,0,16,0,0
0,0,0,0,0,0,0,0,0,0
endlayer

layer
0,0,0,0,0,0,0,0,0,0
0,0,0,0,0,0,0,0,0,0
0,0,21,5,5,5,5,15,0,0
0,0,21,14,0,0,14,15,0,0
0,0,21,14,0,0,14,15,0,0
0,0,21,14,0,0,14,15,0,0
0,0,21,14,0,0,14,15,0,0
0,0,21,5,5,5,5,15,0,0
0,0,21,5,5,5,5,15,0,0
0,21,5,5,5,5,5,5,15,0
0,21,5,5,5,5,5,5,15,0
0,21,5,5,5,5,5,5,15,0
0,21,5,5,5,5,5,5,15,0
0,21,5,5,5,5,5,5,15,0
0,21,5,5,5,5,5,5,15,0
0,21,5,5,5,5,5,5,15,0
0,21,5,5,5,5,5,5,15,0
0,21,5,5,5,5,5,5,15,0
0,0,0,0,0,0,0,0,0,0
0,0,0,0,0,0,0,0,0,0
endlayer

layer
0,0,0,0,0,0,0,0,0,0
0,0,0,0,0,0,0,0,0,0
0,0,0,21,5,5,15,0,0,0
0,0,0,21,14,14,15,0,0,0
0,0,0,21,14,14,15,0,0,0
0,0,0,21,14,14,15,0,0,0
0,0,0,21,14,14,15,0,0,0
0,0,0,21,5,5,15,0,0,0
0,0,0,21,0,0,15,0,0,0
0,0,21,5,5,5,5,15,0,0
0,0,21,5,5,5,5,15,0,0
0,0,21,5,5,5,5,15,0,0
0,0,21,5,5,5,5,15,0,0
0,0,21,5,5,5,5,15,0,0
0,0,21,5,5,5,5,15,0,0
0,0,21,5,5,5,5,15,0,0
0,0,21,5,5,5,5,15,0,0
0,0,21,5,5,5,5,15,0,0
0,0,0,0,0,0,0,0,0,0
0,0,0,0,0,0,0,0,0,0
endlayer

layer
0,0,0,0,0,0,0,0,0,0
0,0,0,0,0,0,0,0,0,0
0,0,0,0,21,15,0,0,0,0
0,0,0,0,21,15,0,0,0,0
0,0,0,0,21,15,0,0,0,0
0,0,0,0,21,15,0,0,0,0
0,0,0,0,21,15,0,0,0,0
0,0,0,0,21,15,0,0,0,0
0,0,0,0,21,15,0,0,0,0
0,0,0,21,5,5,15,0,0,0
0,0,0,21,5,5,15,0,0,0
0,0,0,21,5,5,15,0,0,0
0,0,0,21,5,5,15,0,0,0
0,0,0,21,5,5,15,0,0,0
0,0,0,21,5,5,15,0,0,0
0,0,0,21,5,5,15,0,0,0
0,0,0,21,5,5,15,0,0,0
0,0,0,21,5,5,15,0,0,0
0,0,0,0,0,0,0,0,0,0
0,0,0,0,0,0,0,0,0,0
endlayer

layer
0,0,0,0,0,0,0,0,0,0
0,0,0,0,0,0,0,0,0,0
0,0,0,0,0,0,0,0,0,0
0,0,0,0,0,0,0,0,0,0
0,0,0,0,0,0,0,0,0,0
0,0,0,0,0,0,0,0,0,0
0,0,0,0,0,0,0,0,0,0
0,0,0,0,0,0,0,0,0,0
0,0,0,0,0,0,0,0,0,0
0,0,0,0,21,15,0,0,0,0
0,0,0,0,21,15,0,0,0,0
0,0,0,0,21,15,0,0,0,0
0,0,0,0,21,15,0,0,0,0
0,0,0,0,21,15,0,0,0,0
0,0,0,0,21,15,0,0,0,0
0,0,0,0,21,15,0,0,0,0
0,0,0,0,21,15,0,0,0,0
0,0,0,0,21,15,0,0,0,0
0,0,0,0,0,0,0,0,0,0
0,0,0,0,0,0,0,0,0,0
endlayer

