# Converted from schematic
# author:MohawkyMagoo

weight=10
embed_into_distance=4
#acceptable_target_blocks=1,2,3,12,13
dimensions=14,11,15
#allowable_overhang=0
max_cut_in=2
#cut_in_buffer=1
max_leveling=2
#leveling_buffer=1
#preserve_water=0
#preserve_lava=0
#preserve_plants=0


rule1=0,100,3
rule2=0,100,1
rule3=0,100,4
rule4=0,100,2
rule5=0,100,109-1
rule6=0,100,98
rule7=0,100,109-0
rule8=0,100,64-3
rule9=0,100,64-1
rule10=0,100,64-0
rule11=0,100,58
rule12=0,100,53-3
rule13=0,100,85
rule14=0,100,5
rule15=0,100,64-8
rule16=0,100,102
rule17=0,100,50-1
rule18=0,100,50-4
rule19=0,100,64-9
rule20=0,100,50-3
rule21=0,100,72
rule22=0,100,50-2
rule23=0,100,47
rule24=0,100,53-1
rule25=0,100,53-0
rule26=0,100,50-5


layer
1,1,1,1,1,1,1,1,1,1,1,1,1,1,1
1,1,1,1,1,1,1,1,1,1,1,1,1,1,1
1,1,1,1,1,1,1,1,1,1,1,1,1,1,1
1,1,1,1,1,1,1,1,1,1,1,1,1,1,1
1,1,1,1,1,1,1,1,1,1,1,1,1,1,1
1,1,1,1,1,1,1,1,1,1,1,1,1,1,1
1,1,1,1,1,1,1,1,1,1,1,1,1,1,1
1,1,1,1,1,1,1,1,1,1,1,1,1,1,2
1,1,1,1,1,1,1,1,1,1,1,1,1,1,1
1,1,1,1,1,1,1,1,1,1,1,1,1,1,1
1,1,1,1,1,1,1,1,1,1,1,1,1,1,1
endlayer

layer
1,1,1,1,1,1,1,1,1,1,1,1,1,1,1
1,1,1,1,1,1,1,1,1,1,1,1,1,1,1
1,3,3,3,3,3,3,1,1,1,1,1,1,1,1
1,3,3,3,3,3,3,1,1,1,1,1,1,1,1
1,3,3,3,3,3,3,1,1,1,1,1,1,1,1
1,3,3,3,3,3,3,1,1,1,1,1,1,1,1
1,3,3,3,3,3,3,1,1,1,1,1,1,1,1
1,3,3,3,3,3,3,1,1,1,1,1,1,1,2
1,3,3,3,3,3,3,1,1,1,1,1,1,1,1
1,1,1,1,1,1,1,1,1,1,1,1,1,1,1
1,1,1,1,1,1,1,1,1,1,1,1,1,1,1
endlayer

layer
3,3,3,3,3,3,3,3,3,3,3,3,3,3,3
1,1,3,3,3,3,3,3,3,3,3,3,3,3,3
1,3,3,3,3,3,3,1,1,1,1,1,1,1,3
1,3,3,3,3,3,3,1,1,1,1,1,1,1,3
1,3,3,3,3,3,3,1,1,1,1,1,1,1,3
1,3,3,3,3,3,3,1,1,1,1,1,1,1,3
1,3,3,3,3,3,3,1,1,1,1,1,1,1,3
1,3,3,3,3,3,3,1,1,1,1,1,1,1,3
1,3,3,3,3,3,3,1,1,1,1,1,1,1,3
3,3,3,3,3,3,3,3,3,3,3,3,3,3,3
3,3,3,3,3,3,3,3,3,3,3,3,3,3,3
endlayer

layer
3,3,3,3,3,3,3,3,3,3,3,3,3,3,3
3,3,3,3,3,3,3,3,3,3,3,3,3,3,3
3,3,3,3,3,3,3,3,3,3,3,3,3,3,3
3,3,3,3,3,3,3,3,3,3,3,3,3,3,3
3,3,3,3,3,3,3,3,3,3,3,3,3,3,3
3,3,3,3,3,3,3,3,3,3,3,3,3,3,3
3,3,3,3,3,3,3,1,1,1,1,1,1,3,3
3,3,3,3,3,3,3,1,1,1,1,1,1,4,3
3,3,3,3,3,3,3,1,1,1,1,1,1,4,3
3,3,3,3,3,3,3,3,3,3,3,3,3,3,3
3,3,3,3,3,3,3,3,3,3,3,3,3,3,3
endlayer

layer
0,0,0,0,0,0,0,0,0,0,0,0,0,0,0
0,0,0,0,0,0,0,6,6,6,6,6,6,0,0
0,6,6,6,8,6,6,6,6,6,6,6,6,0,0
0,6,0,0,0,0,0,7,6,6,6,6,6,0,0
0,6,0,0,0,0,0,7,6,6,6,6,6,0,0
0,6,0,0,0,0,0,7,6,6,6,6,6,0,0
0,6,0,0,0,0,0,7,6,6,6,6,6,0,0
0,6,0,0,0,0,0,7,6,6,6,6,6,5,0
0,6,6,6,9,6,6,6,6,6,6,6,6,5,0
0,0,0,0,0,0,0,6,6,6,6,6,6,0,0
0,0,0,0,0,0,0,0,0,0,0,0,0,0,0
endlayer

layer
0,0,0,0,0,0,0,0,0,0,0,0,0,0,0
0,0,0,0,0,0,0,6,6,6,6,6,6,0,0
0,6,6,6,15,6,6,6,14,12,0,11,6,0,0
0,6,0,0,0,0,0,0,0,13,0,0,6,0,0
0,6,0,0,0,0,0,0,0,0,0,0,6,0,0
0,16,0,0,0,0,0,0,0,0,0,0,6,0,0
0,6,0,0,0,0,0,0,0,0,0,0,6,0,0
0,6,0,0,0,0,0,0,0,0,0,0,10,0,0
0,6,6,6,15,6,6,6,0,0,0,0,10,0,0
0,0,0,0,0,0,0,6,6,6,6,6,6,0,0
0,0,0,0,0,0,0,0,0,0,0,0,0,0,0
endlayer

layer
0,0,0,0,0,0,0,18,0,0,0,0,18,0,0
0,0,0,0,18,0,22,6,14,16,16,14,6,17,0
0,6,6,6,6,6,6,14,0,0,0,0,14,0,0
0,6,0,0,0,20,0,0,0,21,0,0,16,0,0
0,6,0,0,0,0,0,0,0,0,0,0,16,0,0
0,16,0,0,0,0,0,0,0,0,0,0,16,0,0
0,6,0,0,0,0,0,0,0,0,0,0,14,0,0
0,6,0,0,0,18,0,0,0,0,0,0,19,0,0
0,6,6,6,6,6,6,14,0,0,0,0,15,0,0
0,0,0,0,20,0,22,6,14,16,16,14,6,17,0
0,0,0,0,0,0,0,20,0,0,0,0,20,0,0
endlayer

layer
0,0,0,0,0,0,0,0,0,0,0,0,0,0,0
0,18,0,0,0,0,0,6,14,16,16,14,6,0,0
22,6,6,6,6,6,6,14,23,0,0,0,14,0,0
0,6,0,0,0,0,0,0,0,0,0,0,16,0,0
0,6,0,0,0,0,0,0,0,0,0,0,16,0,0
0,16,0,0,0,0,0,0,0,0,0,0,16,0,0
0,6,0,0,0,0,0,0,0,0,0,22,14,0,0
0,6,0,0,0,0,0,0,0,0,0,0,14,17,0
22,6,6,6,6,6,6,14,23,0,0,0,14,17,0
0,20,0,0,0,0,0,6,14,16,16,14,6,0,0
0,0,0,0,0,0,0,0,0,0,0,0,0,0,0
endlayer

layer
0,0,0,0,0,0,0,0,0,0,0,0,0,0,0
0,0,0,0,0,0,0,6,14,14,14,14,6,0,0
0,6,6,6,6,6,6,14,14,0,20,14,14,0,0
0,6,0,0,0,0,0,14,14,0,0,14,14,0,0
0,6,0,0,0,0,0,14,14,0,0,14,14,0,0
0,6,0,0,0,0,0,14,14,0,0,14,14,0,0
0,6,0,0,0,0,0,14,14,0,0,14,14,0,0
0,6,0,0,0,0,0,14,14,0,0,14,14,0,0
0,6,6,6,6,6,6,14,14,0,18,14,14,0,0
0,0,0,0,0,0,0,6,14,14,14,14,6,0,0
0,0,0,0,0,0,0,0,0,0,0,0,0,0,0
endlayer

layer
0,0,0,0,0,0,0,0,0,0,0,0,0,0,0
0,0,0,0,0,0,25,6,6,6,6,6,6,24,0
0,6,6,6,6,6,6,6,6,6,6,6,6,24,0
0,6,0,0,0,0,0,6,6,6,6,6,6,24,0
0,6,0,0,0,0,0,6,6,6,6,6,6,24,0
0,6,0,0,0,0,0,6,6,6,6,6,6,24,0
0,6,0,0,0,0,0,6,6,6,6,6,6,24,0
0,6,0,0,0,0,0,6,6,6,6,6,6,24,0
0,6,6,6,6,6,6,6,6,6,6,6,6,24,0
0,0,0,0,0,0,25,6,6,6,6,6,6,24,0
0,0,0,0,0,0,0,0,0,0,0,0,0,0,0
endlayer

layer
0,0,0,0,0,0,0,0,0,0,0,0,0,0,0
0,0,0,0,0,0,0,25,6,6,6,6,24,0,0
25,6,6,6,6,6,6,14,6,6,6,6,24,0,0
25,14,0,0,0,0,0,14,6,6,6,6,24,0,0
25,14,0,0,0,0,0,14,6,6,6,6,24,0,0
25,14,0,0,0,0,0,14,6,6,6,6,24,0,0
25,14,0,0,0,0,0,14,6,6,6,6,24,0,0
25,14,0,0,0,0,0,14,6,6,6,6,24,0,0
25,6,6,6,6,6,6,14,6,6,6,6,24,0,0
0,0,0,0,0,0,0,25,6,6,6,6,24,0,0
0,0,0,0,0,0,0,0,0,0,0,0,0,0,0
endlayer

layer
0,0,0,0,0,0,0,0,0,0,0,0,0,0,0
0,0,0,0,0,0,0,0,25,6,6,24,0,0,0
0,25,6,6,6,6,24,26,25,6,6,24,0,0,0
0,25,14,0,0,14,24,0,25,6,6,24,0,0,0
0,25,14,0,0,14,24,0,25,6,6,24,0,0,0
0,25,14,0,0,14,24,0,25,6,6,24,0,0,0
0,25,14,0,0,14,24,0,25,6,6,24,0,0,0
0,25,14,0,0,14,24,0,25,6,6,24,0,0,0
0,25,6,6,6,6,24,26,25,6,6,24,0,0,0
0,0,0,0,0,0,0,0,25,6,6,24,0,0,0
0,0,0,0,0,0,0,0,0,20,20,0,0,0,0
endlayer

layer
0,0,0,0,0,0,0,0,0,0,0,0,0,0,0
0,0,0,0,0,0,0,0,0,25,24,0,0,0,0
0,0,25,6,6,24,0,0,0,25,24,0,0,0,0
0,0,25,14,14,24,0,0,0,25,24,0,0,0,0
0,0,25,14,14,24,0,0,0,25,24,0,0,0,0
0,0,25,14,14,24,0,0,0,25,24,0,0,0,0
0,0,25,14,14,24,0,0,0,25,24,0,0,0,0
0,0,25,14,14,24,0,0,0,25,24,0,0,0,0
0,0,25,6,6,24,0,0,0,25,24,0,0,0,0
0,0,0,20,20,0,0,0,0,25,24,0,0,0,0
0,0,0,0,0,0,0,0,0,0,0,0,0,0,0
endlayer

layer
0,0,0,0,0,0,0,0,0,0,0,0,0,0,0
0,0,0,0,0,0,0,0,0,0,0,0,0,0,0
0,0,0,25,24,0,0,0,0,0,0,0,0,0,0
0,0,0,25,24,0,0,0,0,0,0,0,0,0,0
0,0,0,25,24,0,0,0,0,0,0,0,0,0,0
0,0,0,25,24,0,0,0,0,0,0,0,0,0,0
0,0,0,25,24,0,0,0,0,0,0,0,0,0,0
0,0,0,25,24,0,0,0,0,0,0,0,0,0,0
0,0,0,25,24,0,0,0,0,0,0,0,0,0,0
0,0,0,0,0,0,0,0,0,0,0,0,0,0,0
0,0,0,0,0,0,0,0,0,0,0,0,0,0,0
endlayer

