# Converted from schematic
# author:MohawkyMagoo

weight=10
embed_into_distance=5
#acceptable_target_blocks=1,2,3,12,13
dimensions=17,27,25
#allowable_overhang=0
max_cut_in=2
#cut_in_buffer=1
max_leveling=2
#leveling_buffer=1
#preserve_water=0
#preserve_lava=0
#preserve_plants=0


rule1=0,100,1
rule2=0,100,3
rule3=0,100,12
rule4=0,100,13
rule5=0,100,4
rule6=0,100,16
rule7=0,100,2
rule8=0,100,98
rule9=0,100,64-0
rule10=0,100,44-5
rule11=0,100,64
rule12=0,100,109-1
rule13=0,100,118-2
rule14=0,100,64-8
rule15=0,100,102
rule16=0,100,50-1
rule17=0,100,50-4
rule18=0,100,50-3
rule19=0,100,50-2
rule20=0,100,126
rule21=0,100,53-1
rule22=0,100,53-3
rule23=0,100,64-2
rule24=0,100,101
rule25=0,100,5
rule26=0,100,53-0
rule27=0,100,109-6
rule28=0,100,126-8
rule29=0,100,126-0
rule30=0,100,50-5
rule31=0,100,53-2


layer
5,5,5,1,1,1,1,1,1,1,1,2,2,2,2,1,1,1,1,1,1,4,4,4,1
5,5,5,1,1,1,1,1,1,1,1,2,2,2,1,1,1,1,1,1,4,4,4,4,1
5,5,5,1,1,1,1,1,1,1,1,2,2,2,1,1,1,1,1,1,1,4,4,1,1
5,5,5,1,1,1,1,1,1,1,1,2,2,2,2,1,1,1,1,1,1,1,1,1,1
5,5,5,1,1,1,1,1,1,1,1,2,2,2,2,1,1,1,1,1,1,1,1,1,1
5,5,5,1,1,1,1,1,1,1,1,2,2,2,2,1,1,1,1,1,1,1,1,1,1
5,5,5,1,1,1,1,1,1,2,2,2,2,2,2,1,1,1,1,1,1,1,1,1,1
5,5,5,1,1,1,1,1,1,2,2,2,2,2,2,2,2,2,2,0,2,2,2,2,2
5,5,5,1,1,1,1,1,1,1,1,2,2,2,2,2,2,2,0,0,0,2,2,2,2
5,5,5,1,1,1,1,1,1,1,2,2,2,2,2,2,0,1,1,1,0,2,2,2,2
5,5,5,1,1,1,1,1,1,2,2,2,2,2,2,2,1,1,1,1,0,2,2,2,2
5,5,5,1,1,1,1,1,2,2,2,2,2,2,2,2,1,1,1,1,2,2,2,2,2
5,5,5,1,1,2,2,2,2,2,2,2,2,2,2,2,2,1,1,2,2,2,2,2,2
5,5,5,2,2,2,2,2,2,2,2,2,2,2,2,2,2,2,2,2,2,2,2,2,2
5,5,5,2,2,2,2,2,2,2,2,2,2,2,2,2,2,2,2,2,2,2,2,2,2
5,5,5,2,2,2,2,2,2,2,2,2,2,2,2,2,2,2,2,2,2,2,2,2,2
5,5,5,2,2,2,2,2,2,2,2,2,2,2,2,2,2,2,2,2,2,2,2,2,2
5,5,5,2,2,2,2,2,2,2,2,2,2,2,2,2,2,2,2,2,2,2,2,2,2
5,5,5,2,2,2,2,2,2,2,2,2,2,2,2,2,2,2,2,2,2,2,2,2,2
5,5,5,2,2,2,2,2,2,2,2,2,2,2,2,2,2,2,2,2,2,2,2,2,3
5,5,5,2,2,3,3,3,2,2,2,2,2,2,2,2,2,2,2,2,2,2,2,2,3
5,5,5,3,3,3,3,3,3,2,2,2,2,2,2,2,2,2,2,2,2,2,2,3,3
5,5,5,3,2,2,3,3,3,2,2,2,2,2,2,2,2,2,2,2,2,2,2,2,3
5,5,5,2,2,2,3,3,3,2,2,2,2,2,2,2,2,2,2,2,2,2,2,2,2
5,5,5,2,2,2,2,3,3,3,2,2,2,2,2,2,2,2,2,2,2,2,2,2,2
5,5,5,2,2,2,2,2,3,2,2,2,2,2,2,2,2,2,2,2,2,2,2,2,2
5,5,5,2,2,2,2,2,3,2,2,2,2,2,2,2,2,2,2,2,2,2,2,2,2
endlayer

layer
5,5,5,1,1,1,1,1,1,1,1,1,2,2,1,1,2,2,2,1,1,1,1,1,1
5,5,5,1,1,1,1,1,1,1,1,1,1,1,2,2,2,2,2,2,2,1,1,1,1
5,5,5,1,1,1,1,1,1,1,1,1,2,2,2,2,2,2,2,2,2,1,1,1,1
5,5,5,1,1,1,1,1,1,1,1,1,2,2,1,1,2,2,2,1,1,1,1,1,1
5,5,5,1,1,1,1,1,1,1,1,1,2,2,2,1,1,1,1,1,1,1,1,1,1
5,5,5,1,1,1,1,1,2,2,2,2,2,2,2,1,1,2,2,2,1,1,1,2,2
5,5,5,1,1,1,2,2,2,2,2,2,2,2,2,1,2,2,2,2,2,2,2,2,2
5,5,5,1,1,1,2,2,2,2,2,2,2,2,2,2,2,2,2,2,2,2,2,2,2
5,5,5,1,1,1,1,2,2,2,2,2,2,2,2,2,2,2,2,2,2,2,2,2,2
5,5,5,1,1,1,1,1,2,2,2,2,2,2,2,2,2,1,1,1,2,2,2,2,2
5,5,5,1,1,1,1,1,2,2,2,2,2,2,2,2,1,1,1,1,2,2,2,2,2
5,5,5,1,1,1,2,2,2,2,2,2,2,2,2,2,1,1,1,1,2,2,2,2,2
5,5,5,2,2,2,2,2,2,2,2,2,2,2,2,2,2,1,1,2,2,2,2,2,2
5,5,5,2,2,2,2,2,2,2,2,2,2,2,2,2,2,2,2,2,2,2,2,2,2
5,5,5,2,2,2,2,2,2,2,2,2,2,2,2,2,2,2,2,2,2,2,2,2,2
5,5,5,2,2,2,2,2,2,2,2,2,2,2,2,2,2,2,2,2,2,2,2,2,2
5,5,5,2,2,2,2,2,2,2,2,2,2,2,2,2,2,2,2,2,2,2,2,2,2
5,5,5,2,2,2,2,2,2,2,2,2,2,2,2,2,2,2,2,2,2,2,2,2,2
5,5,5,2,2,2,2,2,2,2,2,2,2,2,2,2,2,2,2,2,2,2,2,2,2
5,5,5,2,2,2,2,2,2,2,2,2,2,2,2,2,2,2,2,2,2,2,2,2,2
5,5,5,2,2,2,2,2,2,2,2,2,2,2,2,2,2,2,2,2,2,2,2,2,2
5,5,5,2,2,2,2,2,2,2,2,2,2,2,2,2,2,2,2,2,2,2,2,2,2
5,5,5,2,2,2,2,2,2,2,2,2,2,2,2,2,2,2,2,2,2,2,2,2,2
5,5,5,2,2,2,2,2,2,2,2,2,2,2,2,2,2,2,2,2,2,2,2,2,2
5,5,5,2,2,2,2,2,2,2,2,2,2,2,2,2,2,2,2,2,2,2,2,2,2
5,5,5,2,2,2,2,2,2,2,2,2,2,2,2,2,2,2,2,2,2,2,2,2,2
5,5,5,2,2,2,2,2,2,2,2,2,2,2,2,2,2,2,2,2,2,2,2,2,2
endlayer

layer
5,5,5,1,1,1,1,1,1,1,1,1,1,1,2,2,2,2,2,2,2,1,1,1,1
5,5,5,1,1,1,1,1,1,1,1,1,2,2,2,2,2,2,2,2,2,2,1,1,1
5,5,5,1,1,1,1,1,1,1,1,1,2,2,2,2,2,2,2,2,2,2,1,1,2
5,5,5,1,1,1,1,1,1,1,1,1,1,2,2,2,2,2,2,2,2,2,2,2,2
5,5,5,1,1,1,1,1,1,1,1,1,1,2,2,2,2,2,2,2,2,2,2,2,2
5,5,5,1,1,1,1,2,2,2,2,2,2,2,2,2,2,2,2,2,2,2,2,2,2
5,5,5,1,1,1,2,2,2,2,2,2,2,2,2,2,2,2,2,2,2,2,2,2,2
5,5,5,1,1,1,2,2,2,2,2,2,2,2,2,2,2,2,2,2,2,2,2,2,2
5,5,5,1,1,1,1,6,2,2,2,2,2,2,2,2,2,2,2,2,2,2,2,2,2
5,5,5,1,1,1,1,2,2,2,2,2,2,2,2,2,2,1,1,1,2,2,2,2,2
5,5,5,1,1,1,2,2,2,2,2,2,2,2,2,2,1,1,1,1,2,2,2,2,2
5,5,5,2,2,2,2,2,2,2,2,2,2,2,2,2,1,1,1,1,2,2,2,2,2
5,5,5,2,2,2,2,2,2,2,2,2,2,2,2,2,2,1,1,2,2,2,2,2,2
5,5,5,2,2,2,2,2,2,2,2,2,2,2,2,2,2,2,2,2,2,2,2,2,2
5,5,5,2,2,2,2,2,2,2,2,2,2,2,2,2,2,2,2,2,2,2,2,2,2
5,5,5,2,2,2,2,2,2,2,2,2,2,2,2,2,2,2,2,2,2,2,2,2,2
5,5,5,2,2,2,2,2,2,2,2,2,2,2,2,2,2,2,2,2,2,2,2,2,2
5,5,5,5,5,5,5,5,5,5,5,5,5,5,5,5,5,5,5,5,5,5,2,2,2
5,5,5,5,5,5,5,5,5,5,5,5,5,5,5,5,5,5,5,5,5,5,2,2,2
5,5,5,5,5,5,5,5,5,5,5,5,5,5,5,5,5,5,5,5,5,5,2,2,2
5,5,5,5,5,5,5,5,5,5,5,5,5,5,5,5,5,5,5,5,5,5,2,2,2
5,5,5,5,5,5,5,5,5,5,5,5,5,5,5,5,5,5,5,5,5,5,2,2,2
5,5,5,2,2,2,2,2,2,2,2,2,2,2,2,2,2,2,2,2,2,2,2,2,2
5,5,5,2,2,2,2,2,2,2,2,2,2,2,2,2,2,2,2,2,2,2,2,2,2
5,5,5,2,2,2,2,2,2,2,2,2,2,2,2,2,2,2,2,2,2,2,2,2,2
5,5,5,2,2,2,2,2,2,2,2,2,2,2,2,2,2,2,2,2,2,2,2,2,2
5,5,5,2,2,2,2,2,2,2,2,2,2,2,2,2,2,2,2,2,2,2,2,2,2
endlayer

layer
5,5,5,1,1,1,1,1,2,2,2,2,2,2,2,2,2,2,2,2,2,2,2,2,2
5,5,5,1,1,1,1,2,2,2,2,2,2,2,2,2,2,2,2,2,2,2,2,2,2
5,5,5,1,1,1,2,2,2,2,2,2,2,2,2,2,2,2,2,2,2,2,2,2,2
5,5,5,1,1,1,1,2,2,2,2,2,2,2,2,2,2,2,2,2,2,2,2,2,2
5,5,5,1,1,1,6,6,2,2,2,2,2,2,2,2,2,2,2,2,2,2,2,2,2
5,5,5,1,1,1,1,1,2,2,2,2,2,2,2,2,2,2,2,2,2,2,2,2,2
5,5,5,1,1,1,1,2,2,2,2,2,2,2,2,2,2,2,2,2,2,2,2,2,2
5,5,5,1,1,1,2,2,2,2,2,2,2,2,2,2,2,2,2,2,2,2,2,2,2
5,5,5,1,1,1,2,2,2,2,2,2,2,2,2,2,2,2,2,2,2,2,2,2,2
5,5,5,1,2,2,2,2,2,2,2,2,2,2,2,2,2,1,1,1,2,2,2,2,2
5,5,5,1,2,2,2,2,2,2,2,2,2,2,2,2,1,1,1,1,2,2,2,2,2
5,5,5,2,2,2,2,2,2,2,2,2,2,2,2,2,1,1,1,1,2,2,2,2,2
5,5,5,2,2,2,2,2,2,2,2,2,2,2,2,2,2,1,1,2,2,2,2,2,2
5,5,5,2,2,2,2,2,2,2,2,2,2,2,2,2,2,2,2,2,2,2,2,2,2
5,5,5,2,2,2,2,2,2,2,2,2,2,2,2,2,2,2,2,2,2,2,2,2,2
5,5,5,2,2,2,2,2,2,2,2,2,2,2,2,2,2,2,2,2,2,2,2,2,2
5,5,5,2,2,2,2,2,2,2,2,2,2,2,2,2,2,2,2,2,2,2,2,2,2
5,5,5,5,5,5,5,5,5,5,5,5,5,5,5,5,5,5,5,5,5,5,5,5,5
5,5,5,5,5,5,5,5,5,5,5,5,5,5,5,5,5,5,5,5,5,5,5,5,5
5,5,5,5,5,5,5,5,5,5,5,5,5,5,5,5,5,5,5,5,5,5,5,5,5
5,5,5,5,5,5,5,5,5,5,5,5,5,5,5,5,5,5,5,5,5,5,5,5,5
5,5,5,5,5,5,5,5,5,5,5,5,5,5,5,5,5,5,5,5,5,5,5,5,5
5,5,5,2,2,2,2,2,2,2,2,2,2,2,2,2,2,2,2,2,2,2,2,2,2
5,5,5,2,2,2,2,2,2,2,2,2,2,2,2,2,2,2,2,2,2,2,2,2,2
5,5,5,2,2,2,2,2,2,2,2,2,5,5,5,5,5,5,5,5,5,5,5,5,5
5,5,5,2,2,2,2,2,2,2,2,2,5,5,5,5,5,5,5,5,5,5,5,5,5
5,5,5,2,2,2,2,2,2,2,2,2,5,5,5,5,5,5,5,5,5,5,5,5,5
endlayer

layer
5,5,5,5,5,5,5,5,5,5,5,5,5,5,5,5,5,5,5,5,5,5,5,5,5
5,5,5,5,5,5,5,5,5,5,5,5,5,5,5,5,5,5,5,5,5,5,5,5,5
5,5,5,5,5,5,5,5,5,5,5,5,5,5,5,5,5,5,5,5,5,5,5,5,5
5,5,5,2,2,2,2,2,2,2,2,2,2,2,2,2,2,2,2,5,2,2,5,5,5
5,5,5,7,7,7,7,7,7,7,7,7,7,7,7,7,7,5,5,5,5,2,5,5,5
5,5,5,7,7,7,7,7,7,7,7,7,7,7,7,7,7,5,5,5,5,2,5,5,5
5,5,5,7,7,7,7,7,7,7,7,7,2,7,7,7,7,5,5,5,5,2,5,5,5
5,5,5,7,7,7,7,7,7,7,7,7,7,7,7,7,7,5,5,5,5,2,5,5,5
5,5,5,7,7,7,7,7,7,7,7,7,7,7,7,7,7,5,5,5,5,2,5,5,5
5,5,5,7,7,7,7,7,7,7,7,7,2,7,7,7,7,1,1,1,7,2,5,5,5
5,5,5,7,7,7,7,7,7,7,7,7,7,7,7,7,1,1,1,1,7,2,5,5,5
5,5,5,7,7,7,7,7,7,7,7,7,7,7,7,7,1,1,1,1,7,2,5,5,5
5,5,5,7,7,7,7,7,7,7,7,7,2,7,7,7,7,1,1,7,7,2,5,5,5
5,5,5,7,7,7,7,7,7,7,7,7,7,7,7,7,7,7,7,7,7,2,5,5,5
5,5,5,7,7,7,7,7,7,7,7,7,7,7,7,7,7,7,7,7,7,2,5,5,5
5,5,5,7,7,7,7,7,7,7,7,7,7,7,7,7,7,7,7,7,7,2,5,5,5
5,5,5,7,7,7,7,7,7,7,7,7,2,7,7,7,7,7,7,7,7,2,5,5,5
5,5,5,5,5,5,5,5,5,5,5,5,5,5,5,5,5,5,5,5,5,5,5,5,5
5,5,5,5,5,5,5,5,5,5,5,5,5,5,5,5,5,5,5,5,5,5,5,5,5
5,5,5,5,5,5,5,5,5,5,5,5,5,5,5,5,5,5,5,5,5,5,5,5,5
5,5,5,5,5,5,5,5,5,5,5,5,5,5,5,5,5,5,5,5,5,5,5,5,5
5,5,5,5,5,5,5,5,5,5,5,5,5,5,5,5,5,5,5,5,5,5,5,5,5
5,5,5,7,7,7,7,7,7,7,7,7,7,7,7,7,7,7,7,7,7,7,5,5,5
5,5,5,7,7,7,7,7,7,7,7,7,7,7,7,7,7,7,7,7,7,7,5,5,5
5,5,5,5,5,2,5,5,5,2,5,5,5,5,5,5,5,5,5,5,5,5,5,5,5
5,5,5,5,5,5,5,5,5,5,5,5,5,5,5,5,5,5,5,5,5,5,5,5,5
5,5,5,5,5,5,5,5,5,5,5,5,5,5,5,5,5,5,5,5,5,5,5,5,5
endlayer

layer
0,0,0,0,0,0,0,0,0,0,0,0,0,0,0,0,0,0,0,0,0,0,0,0,0
0,0,0,0,0,0,0,0,0,0,0,0,0,0,0,0,0,0,0,0,0,0,0,0,0
0,0,0,0,0,0,0,0,0,0,0,0,0,0,0,0,0,0,0,0,0,0,0,0,0
0,0,8,8,8,8,8,8,8,8,8,8,8,8,8,8,8,8,8,11,8,8,0,0,0
0,0,8,10,10,10,10,10,10,10,10,10,10,10,10,10,10,8,0,0,0,8,0,0,0
0,0,8,10,10,10,10,10,10,10,10,10,10,10,10,10,10,8,0,0,0,8,0,0,0
0,0,8,10,10,10,10,10,10,10,10,10,8,10,10,10,10,9,0,0,0,8,0,0,0
0,0,8,10,10,10,10,10,10,10,10,10,10,10,10,10,10,8,0,0,0,8,0,0,0
0,0,8,10,10,10,10,10,10,10,10,10,10,10,10,10,10,8,8,8,8,8,0,0,0
0,0,8,10,10,10,10,10,10,10,10,10,8,10,10,10,10,10,10,10,10,8,0,0,0
0,0,8,10,10,10,10,10,10,10,10,10,10,10,10,10,10,10,10,10,10,8,0,0,0
0,0,8,10,10,10,10,10,10,10,10,10,10,10,10,10,10,10,10,10,10,8,0,0,0
0,0,8,10,10,10,10,10,10,10,10,10,8,10,10,10,10,10,10,10,10,8,0,0,0
0,0,8,10,10,10,10,10,10,10,10,10,10,10,10,10,10,10,10,10,10,8,0,0,0
0,0,8,10,10,10,10,10,10,10,10,10,10,10,10,10,10,10,10,10,10,8,0,0,0
0,0,8,10,10,10,10,10,10,10,10,10,10,10,10,10,10,10,10,10,10,8,0,0,0
0,0,8,10,10,10,10,10,10,10,10,10,8,10,10,10,10,10,10,10,10,8,0,0,0
0,0,8,8,0,0,8,0,0,8,0,0,8,0,0,8,0,0,8,0,8,8,0,0,0
0,0,8,0,0,0,0,13,0,0,0,0,0,0,0,0,0,0,0,0,0,8,0,0,0
0,0,8,0,0,0,0,0,0,0,0,0,0,0,0,0,0,0,0,0,0,9,0,0,0
0,0,8,0,0,0,8,8,12,0,0,0,0,0,0,0,0,0,0,0,0,8,0,0,0
0,0,8,8,8,8,8,8,8,8,8,8,8,8,8,8,8,8,8,8,8,8,0,0,0
0,0,10,10,10,10,10,10,10,10,10,10,10,10,10,10,10,10,10,10,10,10,0,0,0
0,0,10,10,10,10,10,10,10,10,10,10,10,10,10,10,10,10,10,10,10,10,0,0,0
0,0,0,0,0,8,0,0,0,8,0,0,0,8,0,0,0,8,0,0,0,8,0,0,0
0,0,0,0,0,0,0,0,0,0,0,0,0,0,0,0,0,0,0,0,0,0,0,0,0
0,0,0,0,0,0,0,0,0,0,0,0,0,0,0,0,0,0,0,0,0,0,0,0,0
endlayer

layer
0,0,0,0,0,0,0,0,0,0,0,0,0,0,0,0,0,0,0,0,0,0,0,0,0
0,0,0,0,0,0,0,0,0,0,0,0,0,0,0,0,0,0,0,0,0,0,0,0,0
0,0,0,0,0,0,0,0,0,0,0,0,0,0,0,0,0,0,0,0,0,0,0,0,0
0,0,8,8,8,8,8,8,8,8,8,8,8,8,8,8,8,8,8,14,8,8,0,0,0
0,0,8,0,0,0,0,0,0,0,0,0,0,0,0,0,0,8,0,0,0,8,0,0,0
0,0,8,0,0,0,0,0,0,0,0,0,0,0,0,0,0,8,0,0,0,8,0,0,0
0,0,8,0,0,0,0,0,0,0,0,0,8,0,0,0,0,14,0,0,0,8,0,0,0
0,0,8,0,0,0,0,0,0,0,0,0,0,0,0,0,0,8,0,0,0,8,0,0,0
0,0,8,0,0,0,0,0,0,0,0,0,0,0,0,0,0,8,8,8,8,8,0,0,0
0,0,8,0,0,0,0,0,0,0,0,0,8,0,0,0,0,0,0,0,0,8,0,0,0
0,0,8,0,0,0,0,0,0,0,0,0,0,0,0,0,0,0,0,0,0,8,0,0,0
0,0,8,0,0,0,0,0,0,0,0,0,0,0,0,0,0,0,0,0,0,8,0,0,0
0,0,8,0,0,0,0,0,0,0,0,0,8,0,0,0,0,0,0,0,0,8,0,0,0
0,0,8,0,0,0,0,0,0,0,0,0,0,0,0,0,0,0,0,0,0,8,0,0,0
0,0,8,0,0,0,0,0,0,0,0,0,0,0,0,0,0,0,0,0,0,8,0,0,0
0,0,8,0,0,0,0,0,0,0,0,0,0,0,0,0,0,0,0,0,0,8,0,0,0
0,0,8,16,0,0,0,0,0,0,0,0,8,0,0,0,0,0,0,0,0,8,0,0,0
0,0,8,8,0,0,8,0,0,8,0,0,8,0,0,8,0,0,8,0,8,8,0,0,0
0,0,8,0,0,0,0,0,0,0,0,0,0,0,0,0,0,0,0,0,0,8,0,0,0
0,0,15,0,0,0,0,0,0,0,0,0,0,0,0,0,0,0,0,0,0,14,0,0,0
0,0,8,0,0,0,8,12,0,0,0,0,0,0,0,0,0,0,0,0,0,8,0,0,0
0,0,8,8,8,8,8,15,8,8,8,15,8,8,8,15,8,8,8,15,8,8,0,0,0
0,0,0,0,0,0,0,0,0,0,0,0,0,0,0,0,0,0,0,0,0,0,0,0,0
0,0,0,0,0,0,0,0,0,0,0,0,0,0,0,0,0,0,0,0,0,0,0,0,0
0,0,0,0,0,8,0,0,0,8,0,0,0,8,0,0,0,8,0,0,0,8,0,0,0
0,0,0,0,0,0,0,0,0,0,0,0,0,0,0,0,0,0,0,0,0,0,0,0,0
0,0,0,0,0,0,0,0,0,0,0,0,0,0,0,0,0,0,0,0,0,0,0,0,0
endlayer

layer
0,0,0,0,0,0,0,0,0,0,0,0,0,0,0,0,0,0,0,0,0,0,0,0,0
0,0,0,0,0,0,0,0,0,0,0,0,0,0,0,0,0,0,0,0,0,0,0,0,0
0,0,0,0,0,0,0,0,0,0,0,0,0,0,0,0,0,0,0,17,0,0,0,0,0
0,0,8,8,15,8,15,8,15,8,15,8,15,8,15,8,15,8,8,8,8,8,0,0,0
0,0,8,16,0,0,0,0,0,0,0,0,0,0,0,0,0,8,0,18,0,8,0,0,0
0,0,15,0,0,0,0,0,0,0,0,0,17,0,0,0,0,8,0,0,0,15,0,0,0
0,0,8,0,0,0,0,0,0,0,0,0,8,0,0,0,19,8,0,0,19,8,0,0,0
0,0,15,0,0,0,0,0,0,0,0,0,18,0,0,0,0,8,0,0,0,15,0,0,0
0,0,8,0,0,0,0,0,0,0,0,0,17,0,0,0,0,8,8,8,8,8,0,0,0
0,0,15,0,0,0,0,0,0,0,0,0,8,0,0,0,0,0,0,0,0,15,0,0,0
0,0,8,0,0,0,0,0,0,0,0,0,18,0,0,0,0,0,0,0,0,8,0,0,0
0,0,15,0,0,0,0,0,0,0,0,0,17,0,0,0,0,0,0,0,0,15,0,0,0
0,0,8,0,0,0,0,0,0,0,0,0,8,0,0,0,0,0,0,0,0,8,0,0,0
0,0,15,0,0,0,0,0,0,0,0,0,18,0,0,0,0,0,0,0,0,15,0,0,0
0,0,8,0,0,0,0,0,0,0,0,0,0,0,0,0,0,0,0,0,0,8,0,0,0
0,0,15,0,0,0,0,0,0,0,0,0,17,0,0,0,0,0,0,0,0,15,0,0,0
0,0,8,0,0,0,0,0,0,0,0,0,8,0,0,0,0,0,0,0,0,8,0,0,0
0,0,8,8,16,0,8,16,0,8,0,19,8,16,0,8,0,19,8,0,8,8,0,0,0
0,0,8,18,0,0,0,0,0,0,0,0,0,0,0,0,0,0,0,0,0,8,0,0,0
0,0,15,0,0,0,0,0,0,0,0,0,0,0,0,0,0,0,0,0,19,8,16,0,0
0,0,8,8,8,8,12,0,0,0,0,0,0,0,0,0,0,0,0,0,0,8,0,0,0
0,0,8,8,8,8,8,15,8,8,8,15,8,8,8,15,8,8,8,15,8,8,0,0,0
0,0,0,0,0,0,0,0,0,0,0,0,0,0,0,0,0,0,0,0,0,0,0,0,0
0,0,0,0,0,17,0,0,0,17,0,0,0,17,0,0,0,17,0,0,0,17,0,0,0
0,0,0,0,0,8,0,0,0,8,0,0,0,8,0,0,0,8,0,0,0,8,16,0,0
0,0,0,0,0,18,0,0,0,18,0,0,0,18,0,0,0,18,0,0,0,18,0,0,0
0,0,0,0,0,0,0,0,0,0,0,0,0,0,0,0,0,0,0,0,0,0,0,0,0
endlayer

layer
0,0,0,0,0,0,0,0,0,0,0,0,0,0,0,0,0,0,0,0,0,0,0,0,0
0,0,0,0,0,0,0,0,0,0,0,0,0,0,0,0,0,0,0,0,0,0,0,0,0
0,0,17,0,0,17,0,17,0,17,0,17,0,17,0,17,0,17,0,0,0,17,0,0,0
0,0,8,8,15,8,15,8,15,8,15,8,15,8,15,8,15,8,8,8,8,8,16,0,0
0,0,8,0,0,0,0,0,0,0,0,0,0,0,0,0,19,8,0,0,0,8,0,0,0
0,0,15,0,0,0,0,0,0,0,0,0,0,0,0,0,0,8,0,0,0,15,0,0,0
0,0,8,0,0,0,0,0,0,0,0,0,8,0,0,0,0,8,0,0,0,8,16,0,0
0,0,15,0,0,0,0,0,0,0,0,0,0,0,0,0,0,8,0,0,0,15,0,0,0
0,0,8,0,0,0,0,0,0,0,0,0,0,0,0,0,19,8,8,8,8,8,16,0,0
0,0,15,0,0,0,0,0,0,0,0,0,8,0,0,0,0,18,0,0,0,15,0,0,0
0,0,8,0,0,0,0,0,0,0,0,0,0,0,0,0,0,0,0,0,0,8,16,0,0
0,0,15,0,0,0,0,0,0,0,0,0,0,0,0,0,0,0,0,0,0,15,0,0,0
0,0,8,0,0,0,0,0,0,0,0,0,8,0,0,0,0,0,0,0,0,8,16,0,0
0,0,15,0,0,0,0,0,0,0,0,0,0,0,0,0,0,0,0,0,0,15,0,0,0
0,0,8,0,0,0,0,0,0,0,0,0,0,0,0,0,0,0,0,0,0,8,16,0,0
0,0,15,0,0,0,0,0,0,0,0,0,0,0,0,0,0,0,0,0,0,15,0,0,0
0,0,8,0,0,0,0,0,0,0,0,0,8,0,0,0,0,0,0,0,0,8,16,0,0
0,0,8,8,8,8,8,8,8,8,8,8,8,8,8,8,8,8,8,8,8,8,0,0,0
0,0,8,0,0,0,0,0,0,0,0,0,0,0,0,0,0,0,18,0,0,8,0,0,0
0,0,15,0,0,0,0,0,0,0,0,0,0,0,0,0,0,0,0,0,0,8,0,0,0
0,0,8,8,8,12,0,0,0,0,0,0,0,0,17,0,0,0,0,0,0,8,0,0,0
0,0,8,8,8,8,8,15,8,8,8,15,8,8,8,15,8,8,8,15,8,8,16,0,0
0,0,18,0,0,0,0,0,0,0,0,0,0,0,0,0,0,0,0,0,0,18,0,0,0
0,0,0,0,0,0,0,0,0,0,0,0,0,0,0,0,0,0,0,0,0,0,0,0,0
0,0,0,0,0,8,0,0,0,8,0,0,0,8,0,0,0,8,0,0,0,8,0,0,0
0,0,0,0,0,0,0,0,0,0,0,0,0,0,0,0,0,0,0,0,0,0,0,0,0
0,0,0,0,0,0,0,0,0,0,0,0,0,0,0,0,0,0,0,0,0,0,0,0,0
endlayer

layer
0,0,0,0,0,0,0,0,0,0,0,0,0,0,0,0,0,0,0,0,0,0,0,0,0
0,0,0,0,0,0,0,0,0,0,0,0,0,0,0,0,0,0,0,0,0,0,0,0,0
0,0,0,0,0,0,0,0,0,0,0,0,0,0,0,0,0,0,0,0,0,0,0,0,0
0,0,8,8,15,8,15,8,15,8,15,8,15,8,15,8,15,8,8,8,8,8,0,0,0
0,0,8,0,0,0,0,18,0,18,0,0,0,0,0,0,0,8,0,0,0,8,0,0,0
0,0,15,0,0,0,0,0,0,0,0,0,0,0,0,0,0,8,0,0,0,15,0,0,0
0,0,8,16,0,0,0,0,0,0,0,0,8,0,0,0,0,8,0,0,0,8,0,0,0
0,0,15,0,0,0,0,0,0,0,0,0,0,0,0,0,0,8,0,0,0,15,0,0,0
0,0,8,0,0,0,0,0,0,0,0,0,0,0,0,0,0,8,8,8,8,8,0,0,0
0,0,15,0,0,0,0,0,0,0,0,0,8,0,0,0,0,0,0,0,0,15,0,0,0
0,0,8,16,0,0,0,0,0,0,0,0,0,0,0,0,0,0,0,0,0,8,0,0,0
0,0,15,0,0,0,0,0,0,0,0,0,0,0,0,0,0,0,0,0,0,15,0,0,0
0,0,8,0,0,0,0,0,0,0,0,0,8,0,0,0,0,0,0,0,0,8,0,0,0
0,0,15,0,0,0,0,0,0,0,0,0,0,0,0,0,0,0,0,0,0,15,0,0,0
0,0,8,16,0,0,0,0,0,0,0,0,0,0,0,0,0,0,0,0,0,8,0,0,0
0,0,15,0,0,0,0,0,0,0,0,0,0,0,0,0,0,0,0,0,0,15,0,0,0
0,0,8,0,0,0,0,0,0,0,0,0,8,0,0,0,0,0,0,0,0,8,0,0,0
0,0,8,8,8,8,8,8,8,8,8,8,8,8,8,8,8,8,8,8,8,8,20,0,0
0,0,8,8,8,8,8,8,8,8,8,8,8,8,8,8,8,8,8,8,8,8,21,0,0
0,0,8,8,8,8,8,8,8,8,8,8,8,8,8,8,8,8,8,8,8,8,21,0,0
0,0,8,8,12,0,0,0,8,8,8,8,8,8,8,8,8,8,8,8,8,8,21,0,0
0,0,8,8,8,8,8,8,8,8,8,8,8,8,8,8,8,8,8,8,8,8,21,0,0
0,0,0,0,0,8,8,8,8,8,8,8,8,8,8,8,8,8,8,8,8,8,21,0,0
0,0,0,0,0,8,8,8,8,8,8,8,8,8,8,8,8,8,8,8,8,8,21,0,0
0,0,0,0,0,8,8,8,8,8,8,8,8,8,8,8,8,8,8,8,8,8,21,0,0
0,0,0,0,0,22,22,22,22,22,22,22,22,22,22,22,22,22,22,22,22,22,20,0,0
0,0,0,0,0,0,0,0,0,0,0,0,0,0,0,0,0,0,0,0,0,0,0,0,0
endlayer

layer
0,0,0,0,0,0,0,0,0,0,0,0,0,0,0,0,0,0,0,0,0,0,0,0,0
0,0,0,0,0,0,0,0,0,0,0,0,0,0,0,0,0,0,0,0,0,0,0,0,0
0,0,0,0,0,0,0,0,0,0,0,0,0,0,0,0,0,0,0,0,0,0,0,0,0
0,0,8,8,8,8,8,8,8,8,8,8,8,8,8,8,8,8,8,8,8,8,0,0,0
0,0,8,0,0,0,0,0,0,0,0,0,18,0,0,0,0,8,0,0,0,8,0,0,0
0,0,8,0,0,0,0,0,0,0,0,0,17,0,0,0,0,8,0,0,0,8,0,0,0
0,0,8,0,0,0,0,0,0,0,0,19,8,16,0,0,0,8,0,0,19,8,0,0,0
0,0,8,0,0,0,0,0,0,0,0,0,18,0,0,0,0,8,0,0,0,8,0,0,0
0,0,8,0,0,0,0,0,0,0,0,0,17,0,0,0,0,8,8,8,8,8,0,0,0
0,0,8,0,0,0,0,0,0,0,0,19,8,16,0,0,0,0,0,0,0,8,0,0,0
0,0,8,0,0,0,0,0,0,0,0,0,18,0,0,0,0,0,0,0,19,8,0,0,0
0,0,8,0,0,0,0,0,0,0,0,0,17,0,0,0,0,0,0,0,0,8,0,0,0
0,0,8,0,0,0,0,0,0,0,0,19,8,16,0,0,0,0,0,0,0,8,0,0,0
0,0,8,0,0,0,0,0,0,0,0,0,18,0,0,0,0,0,0,0,19,8,0,0,0
0,0,8,0,0,0,0,0,0,0,0,0,0,0,0,0,0,0,0,0,0,8,0,0,0
0,0,8,0,0,0,0,0,0,0,0,0,17,0,0,0,0,0,0,0,0,8,0,0,0
0,0,8,17,0,0,17,0,0,0,0,0,8,0,17,0,0,17,0,0,17,8,0,0,0
0,0,8,8,8,8,8,8,24,24,24,24,8,8,8,8,8,8,8,8,8,8,0,0,0
0,0,8,0,0,0,0,0,0,0,0,0,8,0,0,0,0,0,0,0,0,8,0,0,0
0,0,8,0,0,0,0,0,0,0,0,0,23,0,0,0,0,0,0,0,0,8,0,0,0
0,0,8,0,0,0,0,0,0,0,0,0,8,0,0,0,0,0,0,0,0,8,0,0,0
0,0,8,8,8,8,0,0,0,0,0,0,8,0,0,0,0,0,0,0,0,8,0,0,0
0,0,0,0,0,8,0,0,0,0,0,0,8,0,0,0,0,0,0,0,0,8,0,0,0
0,0,0,0,0,8,0,0,0,0,0,0,8,0,0,0,0,0,0,0,0,8,0,0,0
0,0,0,0,0,8,8,8,8,8,8,8,8,8,8,8,8,8,8,8,8,8,0,0,0
0,0,0,0,0,0,0,0,0,0,0,0,0,0,0,0,0,0,0,0,0,0,0,0,0
0,0,0,0,0,0,0,0,0,0,0,0,0,0,0,0,0,0,0,0,0,0,0,0,0
endlayer

layer
0,0,0,0,0,0,0,0,0,0,0,0,0,0,0,0,0,0,0,0,0,0,0,0,0
0,0,0,0,0,0,0,0,0,0,0,0,0,0,0,0,0,0,0,0,0,0,0,0,0
0,0,0,0,0,0,0,0,0,0,0,0,0,0,0,0,0,0,0,17,17,0,0,0,0
0,0,26,8,15,8,21,26,8,8,8,8,8,8,8,8,8,21,26,8,8,21,0,0,0
0,0,26,0,0,0,21,26,0,0,0,0,8,18,0,18,0,21,26,18,0,21,0,0,0
0,0,26,0,0,0,21,26,0,0,0,0,8,0,0,0,0,21,26,0,0,21,0,0,0
0,0,26,0,0,0,21,26,0,0,0,0,8,0,0,0,0,21,26,0,0,21,0,0,0
0,0,26,0,0,0,21,26,0,0,0,0,8,0,0,0,0,21,26,0,0,21,0,0,0
0,0,26,0,0,0,21,26,0,0,0,0,8,0,0,0,0,21,26,25,25,21,0,0,0
0,0,26,0,0,0,21,26,0,0,0,0,8,0,0,0,0,21,26,0,0,21,0,0,0
0,0,26,0,0,0,21,26,0,0,0,0,8,0,0,0,0,21,26,0,0,21,0,0,0
0,0,26,0,0,0,21,26,0,0,0,0,8,0,0,0,0,21,26,0,0,21,0,0,0
0,0,26,0,0,0,21,26,0,0,0,0,8,0,0,0,0,21,26,0,0,21,0,0,0
0,0,26,0,0,0,21,26,0,0,0,0,8,0,0,0,0,21,26,0,0,21,0,0,0
0,0,26,0,0,0,21,26,0,0,0,0,8,0,0,0,0,21,26,0,0,21,0,0,0
0,0,26,0,0,0,21,26,0,0,0,0,8,0,0,0,0,21,26,0,0,21,0,0,0
0,0,26,0,0,0,25,26,0,0,0,0,8,0,0,0,0,21,26,0,0,21,0,0,0
0,0,8,8,8,8,8,8,0,0,0,0,8,8,8,8,8,8,8,8,8,8,0,0,0
0,0,8,0,0,0,0,0,0,0,0,0,8,0,0,0,0,0,0,0,0,8,0,0,0
0,0,15,0,0,0,0,0,0,0,0,0,14,0,0,0,0,0,0,0,0,15,0,0,0
0,0,8,0,0,0,0,0,0,0,0,0,8,0,0,0,0,0,0,0,0,8,0,0,0
0,0,8,8,8,8,0,0,0,0,0,0,8,0,0,0,0,0,0,0,0,8,0,0,0
0,0,0,0,0,8,0,0,0,0,0,0,8,0,0,0,0,0,0,0,0,15,0,0,0
0,0,0,0,0,8,0,0,0,0,0,0,8,0,0,0,0,0,0,0,0,8,0,0,0
0,0,0,0,0,8,8,15,8,15,8,15,8,15,8,15,8,15,8,15,8,8,0,0,0
0,0,0,0,0,0,0,0,0,0,0,0,0,0,0,0,0,0,0,0,0,0,0,0,0
0,0,0,0,0,0,0,0,0,0,0,0,0,0,0,0,0,0,0,0,0,0,0,0,0
endlayer

layer
0,0,0,0,0,0,0,0,0,0,0,0,0,0,0,0,0,0,0,0,0,0,0,0,0
0,0,0,0,0,0,0,0,0,0,0,0,0,0,0,0,0,0,0,0,0,0,0,0,0
0,0,0,0,0,0,0,0,0,0,0,0,0,0,0,0,0,0,0,0,0,0,0,0,0
0,0,0,26,8,21,0,0,26,8,15,8,8,8,15,8,21,0,0,26,21,0,0,0,0
0,0,0,26,25,21,0,0,26,0,0,0,8,0,0,0,21,0,0,26,21,0,0,0,0
0,0,0,26,28,21,0,0,26,0,0,0,8,0,0,0,21,0,0,26,21,0,0,0,0
0,0,0,26,28,21,0,0,26,0,0,0,8,0,0,0,21,0,0,26,21,0,0,0,0
0,0,0,26,28,21,0,0,26,0,0,0,8,0,0,0,21,0,0,26,21,0,0,0,0
0,0,0,26,28,21,0,0,26,0,0,0,8,0,0,0,21,25,25,26,21,0,0,0,0
0,0,0,26,28,21,0,0,26,0,0,0,8,0,0,0,21,0,0,26,21,0,0,0,0
0,0,0,26,28,21,0,0,26,0,0,0,8,0,0,0,21,0,0,26,21,0,0,0,0
0,0,0,26,28,21,0,0,26,0,0,0,8,0,0,0,21,0,0,26,21,0,0,0,0
0,0,0,26,25,21,0,0,26,0,0,0,8,0,0,0,21,0,0,26,21,0,0,0,0
0,0,0,26,28,21,0,0,26,0,0,0,8,0,0,0,21,0,0,26,21,0,0,0,0
0,0,0,26,28,21,0,0,26,0,0,0,8,0,0,0,21,0,0,26,21,0,0,0,0
0,0,0,26,28,21,0,0,26,0,0,0,8,0,0,0,21,0,0,26,21,0,0,0,0
0,0,0,26,25,21,0,17,26,0,0,0,8,0,0,0,21,0,17,26,21,17,0,0,0
0,0,8,8,8,8,8,8,27,0,0,0,8,8,8,8,8,8,8,8,8,8,0,0,0
0,0,8,18,0,0,0,0,0,0,0,0,8,0,0,18,0,0,0,0,18,8,0,0,0
0,0,15,0,0,0,0,0,0,0,0,19,8,16,0,0,0,0,0,0,0,15,0,0,0
0,0,8,0,0,17,0,0,0,0,0,0,8,0,0,0,0,0,0,0,0,8,0,0,0
0,0,8,8,8,8,0,0,0,0,0,0,8,0,0,0,0,0,0,0,0,8,0,0,0
0,0,0,0,0,8,0,0,0,0,0,0,8,16,0,0,0,0,0,0,0,15,0,0,0
0,0,0,0,0,8,16,0,0,0,0,0,8,0,0,0,17,0,0,0,17,8,0,0,0
0,0,0,0,0,8,8,15,8,15,8,15,8,15,8,15,8,15,8,15,8,8,0,0,0
0,0,0,0,0,0,0,0,0,0,0,0,0,0,0,0,0,0,0,0,0,0,0,0,0
0,0,0,0,0,0,0,0,0,0,0,0,0,0,0,0,0,0,0,0,0,0,0,0,0
endlayer

layer
0,0,0,0,0,0,0,0,0,0,0,0,0,0,0,0,0,0,0,0,0,0,0,0,0
0,0,0,0,0,0,0,0,0,0,0,0,0,0,0,0,0,0,0,0,0,0,0,0,0
0,0,0,0,0,0,0,0,0,0,0,0,0,0,0,0,0,0,0,0,0,0,0,0,0
0,0,0,0,30,0,0,0,0,26,8,8,8,8,8,21,0,0,0,0,0,0,0,0,0
0,0,0,0,0,0,0,0,0,26,0,0,25,0,0,21,0,0,0,0,0,0,0,0,0
0,0,0,0,0,0,0,0,0,26,0,0,25,0,0,21,0,0,0,0,0,0,0,0,0
0,0,0,0,0,0,0,0,0,26,0,0,25,0,0,21,0,0,0,0,0,0,0,0,0
0,0,0,0,0,0,0,0,0,26,0,0,25,0,0,21,0,0,0,0,0,0,0,0,0
0,0,0,0,0,0,0,0,0,26,0,0,25,0,0,21,0,30,30,0,0,0,0,0,0
0,0,0,0,0,0,0,0,0,26,0,0,25,0,0,21,0,0,0,0,0,0,0,0,0
0,0,0,0,0,0,0,0,0,26,0,0,25,0,0,21,0,0,0,0,0,0,0,0,0
0,0,0,0,0,0,0,0,0,26,0,0,25,0,0,21,0,0,0,0,0,0,0,0,0
0,0,0,0,30,0,0,0,0,26,0,0,25,0,0,21,0,0,0,0,0,0,0,0,0
0,0,0,0,0,0,0,0,0,26,0,0,25,0,0,21,0,0,0,0,0,0,0,0,0
0,0,0,0,0,0,0,0,0,26,0,0,25,0,0,21,0,0,0,0,0,0,0,0,0
0,0,0,0,0,0,0,0,0,26,0,0,25,0,0,21,0,0,0,0,0,0,0,0,0
0,0,0,0,30,0,0,0,0,26,0,31,25,31,31,21,0,0,0,0,0,0,0,0,0
0,0,25,25,25,25,25,25,25,25,0,25,25,25,25,25,25,25,25,25,25,25,21,0,0
0,0,25,0,0,0,0,0,0,0,0,0,8,0,0,0,0,0,0,0,0,25,21,0,0
0,0,25,0,0,0,0,0,0,0,0,0,8,0,0,0,0,0,0,0,0,25,21,0,0
0,0,25,0,0,0,0,0,0,0,0,0,8,0,0,0,0,0,0,0,0,25,21,0,0
0,0,25,25,25,25,25,25,25,25,25,25,25,25,25,25,25,25,25,25,25,25,21,0,0
0,0,22,22,22,22,22,22,22,22,22,22,22,22,22,22,22,22,22,22,22,22,29,0,0
0,0,0,0,20,20,20,20,20,20,20,20,20,20,20,20,20,20,20,20,20,20,20,0,0
0,0,0,0,20,25,20,20,20,20,25,20,20,20,25,20,20,20,25,20,20,20,20,0,0
0,0,0,0,20,20,20,20,20,20,20,20,20,20,20,20,20,20,20,20,20,20,20,0,0
0,0,0,0,0,0,0,0,0,0,0,0,0,0,0,0,0,0,0,0,0,0,0,0,0
endlayer

layer
0,0,0,0,0,0,0,0,0,0,0,0,0,0,0,0,0,0,0,0,0,0,0,0,0
0,0,0,0,0,0,0,0,0,0,0,0,0,0,0,0,0,0,0,0,0,0,0,0,0
0,0,0,0,0,0,0,0,0,0,0,17,0,17,0,0,0,0,0,0,0,0,0,0,0
0,0,0,0,0,0,0,0,0,0,26,8,8,8,21,0,0,0,0,0,0,0,0,0,0
0,0,0,0,0,0,0,0,0,0,26,0,25,0,21,0,0,0,0,0,0,0,0,0,0
0,0,0,0,0,0,0,0,0,0,26,0,25,0,21,0,0,0,0,0,0,0,0,0,0
0,0,0,0,0,0,0,0,0,0,26,0,25,0,21,0,0,0,0,0,0,0,0,0,0
0,0,0,0,0,0,0,0,0,0,26,0,25,0,21,0,0,0,0,0,0,0,0,0,0
0,0,0,0,0,0,0,0,0,0,26,0,25,0,21,0,0,0,0,0,0,0,0,0,0
0,0,0,0,0,0,0,0,0,0,26,0,25,0,21,0,0,0,0,0,0,0,0,0,0
0,0,0,0,0,0,0,0,0,0,26,0,25,0,21,0,0,0,0,0,0,0,0,0,0
0,0,0,0,0,0,0,0,0,0,26,0,25,0,21,0,0,0,0,0,0,0,0,0,0
0,0,0,0,0,0,0,0,0,0,26,0,25,0,21,0,0,0,0,0,0,0,0,0,0
0,0,0,0,0,0,0,0,0,0,26,0,25,0,21,0,0,0,0,0,0,0,0,0,0
0,0,0,0,0,0,0,0,0,0,26,0,25,0,21,0,0,0,0,0,0,0,0,0,0
0,0,0,0,0,0,0,0,0,0,26,0,25,0,21,0,0,0,0,0,0,0,0,0,0
0,0,0,0,0,0,0,0,0,0,26,0,25,0,21,0,0,0,0,0,0,0,0,0,0
0,0,29,31,31,31,31,31,31,31,25,31,25,31,25,31,31,31,31,31,31,29,0,0,0
0,0,26,25,25,25,25,25,25,25,25,25,25,25,25,25,25,25,25,25,25,21,0,0,0
0,0,26,25,0,0,0,0,0,0,0,0,8,0,0,0,0,0,0,0,25,21,0,0,0
0,0,26,25,25,25,25,25,25,25,25,25,25,25,25,25,25,25,25,25,25,21,0,0,0
0,0,29,22,22,22,22,22,22,22,22,22,22,22,22,22,22,22,22,22,22,29,0,0,0
0,0,0,0,0,0,0,0,0,0,0,0,0,0,0,0,0,0,0,0,0,0,0,0,0
0,0,0,0,0,0,0,0,0,0,0,0,0,0,0,0,0,0,0,0,0,0,0,0,0
0,0,0,0,0,30,0,0,0,0,30,0,0,0,30,0,0,0,30,0,0,0,0,0,0
0,0,0,0,0,0,0,0,0,0,0,0,0,0,0,0,0,0,0,0,0,0,0,0,0
0,0,0,0,0,0,0,0,0,0,0,0,0,0,0,0,0,0,0,0,0,0,0,0,0
endlayer

layer
0,0,0,0,0,0,0,0,0,0,0,0,0,0,0,0,0,0,0,0,0,0,0,0,0
0,0,0,0,0,0,0,0,0,0,0,0,0,0,0,0,0,0,0,0,0,0,0,0,0
0,0,0,0,0,0,0,0,0,0,0,0,0,0,0,0,0,0,0,0,0,0,0,0,0
0,0,0,0,0,0,0,0,0,0,0,26,25,21,0,0,0,0,0,0,0,0,0,0,0
0,0,0,0,0,0,0,0,0,0,0,26,25,21,0,0,0,0,0,0,0,0,0,0,0
0,0,0,0,0,0,0,0,0,0,0,26,25,21,0,0,0,0,0,0,0,0,0,0,0
0,0,0,0,0,0,0,0,0,0,0,26,25,21,0,0,0,0,0,0,0,0,0,0,0
0,0,0,0,0,0,0,0,0,0,0,26,25,21,0,0,0,0,0,0,0,0,0,0,0
0,0,0,0,0,0,0,0,0,0,0,26,25,21,0,0,0,0,0,0,0,0,0,0,0
0,0,0,0,0,0,0,0,0,0,0,26,25,21,0,0,0,0,0,0,0,0,0,0,0
0,0,0,0,0,0,0,0,0,0,0,26,25,21,0,0,0,0,0,0,0,0,0,0,0
0,0,0,0,0,0,0,0,0,0,0,26,25,21,0,0,0,0,0,0,0,0,0,0,0
0,0,0,0,0,0,0,0,0,0,0,26,25,21,0,0,0,0,0,0,0,0,0,0,0
0,0,0,0,0,0,0,0,0,0,0,26,25,21,0,0,0,0,0,0,0,0,0,0,0
0,0,0,0,0,0,0,0,0,0,0,26,25,21,0,0,0,0,0,0,0,0,0,0,0
0,0,0,0,0,0,0,0,0,0,0,26,25,21,0,0,0,0,0,0,0,0,0,0,0
0,0,0,0,0,0,0,0,0,0,0,26,25,21,0,0,0,0,0,0,0,0,0,0,0
0,0,0,0,0,0,0,0,0,0,30,26,25,21,30,0,0,0,0,0,0,0,0,0,0
0,0,0,29,31,31,31,31,31,31,31,31,25,31,31,31,31,31,31,31,29,0,0,0,0
0,0,0,26,25,25,25,25,25,25,25,25,25,25,25,25,25,25,25,25,21,0,0,0,0
0,0,0,29,22,22,22,22,22,22,22,22,22,22,22,22,22,22,22,22,29,0,0,0,0
0,0,0,0,0,0,0,0,0,0,0,0,0,0,0,0,0,0,0,0,0,0,0,0,0
0,0,0,0,0,0,0,0,0,0,0,0,0,0,0,0,0,0,0,0,0,0,0,0,0
0,0,0,0,0,0,0,0,0,0,0,0,0,0,0,0,0,0,0,0,0,0,0,0,0
0,0,0,0,0,0,0,0,0,0,0,0,0,0,0,0,0,0,0,0,0,0,0,0,0
0,0,0,0,0,0,0,0,0,0,0,0,0,0,0,0,0,0,0,0,0,0,0,0,0
0,0,0,0,0,0,0,0,0,0,0,0,0,0,0,0,0,0,0,0,0,0,0,0,0
endlayer

layer
0,0,0,0,0,0,0,0,0,0,0,0,0,0,0,0,0,0,0,0,0,0,0,0,0
0,0,0,0,0,0,0,0,0,0,0,0,0,0,0,0,0,0,0,0,0,0,0,0,0
0,0,0,0,0,0,0,0,0,0,0,0,0,0,0,0,0,0,0,0,0,0,0,0,0
0,0,0,0,0,0,0,0,0,0,0,0,30,0,0,0,0,0,0,0,0,0,0,0,0
0,0,0,0,0,0,0,0,0,0,0,0,0,0,0,0,0,0,0,0,0,0,0,0,0
0,0,0,0,0,0,0,0,0,0,0,0,0,0,0,0,0,0,0,0,0,0,0,0,0
0,0,0,0,0,0,0,0,0,0,0,0,0,0,0,0,0,0,0,0,0,0,0,0,0
0,0,0,0,0,0,0,0,0,0,0,0,0,0,0,0,0,0,0,0,0,0,0,0,0
0,0,0,0,0,0,0,0,0,0,0,0,0,0,0,0,0,0,0,0,0,0,0,0,0
0,0,0,0,0,0,0,0,0,0,0,0,30,0,0,0,0,0,0,0,0,0,0,0,0
0,0,0,0,0,0,0,0,0,0,0,0,0,0,0,0,0,0,0,0,0,0,0,0,0
0,0,0,0,0,0,0,0,0,0,0,0,0,0,0,0,0,0,0,0,0,0,0,0,0
0,0,0,0,0,0,0,0,0,0,0,0,0,0,0,0,0,0,0,0,0,0,0,0,0
0,0,0,0,0,0,0,0,0,0,0,0,0,0,0,0,0,0,0,0,0,0,0,0,0
0,0,0,0,0,0,0,0,0,0,0,0,30,0,0,0,0,0,0,0,0,0,0,0,0
0,0,0,0,0,0,0,0,0,0,0,0,0,0,0,0,0,0,0,0,0,0,0,0,0
0,0,0,0,0,0,0,0,0,0,0,0,0,0,0,0,0,0,0,0,0,0,0,0,0
0,0,0,0,0,0,0,0,0,0,0,0,0,0,0,0,0,0,0,0,0,0,0,0,0
0,0,0,0,0,0,0,0,0,0,0,0,30,0,0,0,0,0,0,0,0,0,0,0,0
0,0,0,0,29,29,29,29,29,29,29,29,29,29,29,29,29,29,29,29,0,0,0,0,0
0,0,0,0,0,0,0,0,0,0,0,0,0,0,0,0,0,0,0,0,0,0,0,0,0
0,0,0,0,0,0,0,0,0,0,0,0,0,0,0,0,0,0,0,0,0,0,0,0,0
0,0,0,0,0,0,0,0,0,0,0,0,0,0,0,0,0,0,0,0,0,0,0,0,0
0,0,0,0,0,0,0,0,0,0,0,0,0,0,0,0,0,0,0,0,0,0,0,0,0
0,0,0,0,0,0,0,0,0,0,0,0,0,0,0,0,0,0,0,0,0,0,0,0,0
0,0,0,0,0,0,0,0,0,0,0,0,0,0,0,0,0,0,0,0,0,0,0,0,0
0,0,0,0,0,0,0,0,0,0,0,0,0,0,0,0,0,0,0,0,0,0,0,0,0
endlayer

