# Converted from schematic
# author:MohawkyMagoo

weight=10
embed_into_distance=5
#acceptable_target_blocks=1,2,3,12,13
dimensions=20,13,33
#allowable_overhang=0
max_cut_in=2
#cut_in_buffer=1
max_leveling=2
#leveling_buffer=1
#preserve_water=0
#preserve_lava=0
#preserve_plants=0


rule1=0,100,3
rule2=0,100,98-1
rule3=0,100,98
rule4=0,100,1
rule5=0,100,98-2
rule6=0,100,4
rule7=0,100,2
rule8=0,100,109-1
rule9=0,100,64-1
rule10=0,100,17
rule11=0,100,64-1
rule12=0,100,64-0
rule13=0,100,64-2
rule14=0,100,102
rule15=0,100,64-8
rule16=0,100,18
rule17=0,100,50-3
rule18=0,100,50-4
rule19=0,100,50-1
rule20=0,100,50-2
rule21=0,100,53-7
rule22=0,100,85
rule23=0,100,109-3
rule24=0,100,53-0
rule25=0,100,101
rule26=0,100,47
rule27=0,100,64-2
rule28=0,100,5
rule29=0,100,53-3
rule30=0,100,53-2
rule31=0,100,50-5


layer
2,2,5,2,2,2,3,2,3,2,2,1,1,1,1,1,1,1,1,1,1,1,1,1,1,1,1,1,1,1,1,1,1
1,1,1,1,1,1,1,1,1,1,1,1,1,1,1,1,1,1,1,1,1,1,1,1,1,1,1,1,1,1,1,1,1
1,1,1,1,1,1,1,1,1,1,1,1,1,1,1,1,1,1,1,1,1,1,1,1,1,1,1,1,1,1,1,1,1
1,1,1,1,1,1,1,1,1,1,1,1,1,1,1,1,1,1,1,1,1,1,1,1,1,1,1,1,1,1,1,1,1
1,1,1,1,1,1,1,1,1,1,1,1,1,1,1,1,1,1,1,1,1,1,1,1,1,1,1,1,1,1,1,1,1
1,1,1,1,1,1,1,1,1,1,1,1,1,1,1,1,1,1,1,1,1,1,1,1,1,1,1,1,1,1,1,1,1
1,1,1,1,1,1,1,1,1,1,1,1,1,1,1,1,1,1,1,1,1,1,1,1,1,1,1,1,1,1,1,1,1
1,1,1,1,1,1,1,1,1,1,1,1,1,1,1,1,1,1,1,1,1,1,1,1,1,1,1,1,1,1,1,1,1
1,1,1,1,1,1,1,1,1,1,1,1,1,1,1,1,1,1,1,1,1,1,1,1,1,1,1,1,1,1,1,1,1
1,1,1,1,1,1,1,1,1,1,1,1,1,1,1,1,1,1,1,1,1,1,1,1,1,1,1,1,1,1,1,1,1
1,1,1,1,1,1,1,1,1,1,1,1,1,1,1,1,1,1,1,1,1,1,1,1,1,1,1,1,1,1,1,1,1
1,1,1,1,1,1,1,1,1,1,1,1,1,1,1,1,1,1,1,1,1,1,1,1,1,1,1,1,1,1,1,1,1
1,1,1,4,4,4,4,4,1,1,1,1,1,1,1,1,1,1,1,1,1,1,1,1,1,1,1,1,1,1,1,1,1
endlayer

layer
3,3,2,5,2,2,2,2,2,2,2,1,1,1,1,1,1,1,1,1,1,1,1,1,1,1,1,1,1,1,1,1,1
6,1,1,1,1,1,1,1,1,1,1,1,1,1,1,1,1,1,1,1,1,1,1,1,1,1,1,1,1,1,1,1,1
1,1,1,1,1,1,1,1,1,1,1,1,1,1,1,1,1,1,1,1,1,1,1,1,1,1,1,1,1,1,1,1,1
1,1,1,1,1,1,1,1,1,1,1,1,1,1,1,1,1,1,1,1,1,1,1,1,1,1,1,1,1,1,1,1,1
1,1,1,1,1,1,1,1,1,1,1,1,1,1,1,1,1,1,1,1,1,1,1,1,1,1,1,1,1,1,1,1,1
1,1,1,1,1,1,1,1,1,1,1,1,1,1,1,1,1,1,1,1,1,1,1,1,1,1,1,1,1,1,1,1,1
1,1,1,1,1,1,1,1,1,1,1,1,1,1,1,1,1,1,1,1,1,1,1,1,1,1,1,1,1,1,1,1,1
1,1,1,1,1,1,1,1,1,1,1,1,1,1,1,1,1,1,1,1,1,1,1,1,1,1,1,1,1,1,1,1,1
1,1,1,1,1,1,1,1,1,1,1,1,1,1,1,1,1,1,1,1,1,1,1,1,1,1,1,1,1,1,1,1,1
1,1,1,1,1,1,1,1,1,1,1,1,1,1,1,1,1,1,1,1,1,1,1,1,1,1,1,1,1,1,1,1,1
1,1,1,1,1,1,1,1,1,1,1,1,1,1,1,1,1,1,1,1,1,1,1,1,1,1,1,1,1,1,1,1,1
1,1,1,1,1,1,1,1,1,1,1,1,1,1,1,1,1,1,1,1,1,1,1,1,1,1,1,1,1,1,1,1,1
1,1,1,1,1,1,1,1,1,1,1,1,1,1,1,1,1,1,1,1,1,1,1,1,1,1,1,1,1,1,1,1,1
endlayer

layer
6,3,2,3,2,3,3,3,2,5,3,1,1,1,1,1,1,1,1,1,1,1,1,1,1,1,1,1,1,1,1,1,1
6,1,1,1,1,1,1,1,1,1,1,1,1,1,1,1,1,1,1,1,1,1,6,6,6,6,6,6,6,6,6,6,1
6,1,1,1,1,1,1,6,6,6,6,6,6,6,6,6,6,6,1,1,1,1,6,6,6,6,6,6,6,6,6,6,1
1,1,1,1,1,1,1,6,6,6,6,6,6,6,6,6,6,6,1,1,1,1,6,6,6,6,6,6,6,6,6,6,1
1,1,1,1,1,1,1,6,6,6,6,6,6,6,6,6,6,6,1,1,1,1,6,6,6,6,6,6,6,6,6,6,1
1,1,1,1,1,1,1,6,6,6,6,6,6,6,6,6,6,6,1,1,1,1,6,6,6,6,6,6,6,6,6,6,1
1,1,1,1,1,1,1,6,6,6,6,6,6,6,6,6,6,6,1,1,1,1,6,6,6,6,6,6,6,6,6,6,1
1,1,1,1,1,1,1,6,6,6,6,6,6,6,6,6,6,6,1,1,1,1,1,1,1,1,1,1,1,1,1,1,1
1,1,1,1,1,1,1,6,6,6,6,6,6,6,6,6,6,6,1,1,1,1,1,1,1,1,1,1,1,1,1,1,1
1,1,1,1,1,1,1,6,6,6,6,6,6,6,6,6,6,6,1,1,1,1,1,1,1,1,1,1,1,1,1,1,1
1,1,1,1,1,1,1,6,6,6,6,6,6,6,6,6,6,6,1,1,1,1,1,1,1,1,1,1,1,1,1,1,1
1,1,1,1,1,1,1,1,1,1,1,1,1,1,1,1,1,1,1,1,1,1,1,1,1,1,1,1,1,1,1,1,1
1,1,1,1,1,1,1,1,1,1,1,1,1,1,1,1,1,1,1,1,1,1,1,1,1,1,1,1,1,1,1,1,1
endlayer

layer
6,3,2,3,2,2,2,3,2,2,3,1,1,1,1,1,1,1,1,1,1,1,1,1,1,1,1,1,1,1,1,1,1
6,1,1,1,1,1,1,1,1,1,1,1,1,1,1,1,1,1,1,1,1,1,6,6,6,6,6,6,6,6,6,6,1
6,1,1,1,1,1,1,6,6,6,6,6,6,6,6,6,6,6,1,1,1,1,6,6,6,6,6,6,6,6,6,6,1
6,1,1,1,1,1,1,6,6,6,6,6,6,6,6,6,6,6,1,1,1,1,6,6,6,6,6,6,6,6,6,6,1
6,1,1,1,1,1,1,6,6,6,6,6,6,6,6,6,6,6,1,1,1,1,6,6,6,6,6,6,6,6,6,6,1
6,1,1,1,1,1,1,6,6,6,6,6,6,6,6,6,6,6,1,1,1,1,6,6,6,6,6,6,6,6,6,6,1
6,1,1,1,1,1,1,6,6,6,6,6,6,6,6,6,6,6,1,1,1,1,6,6,6,6,6,6,6,6,6,6,1
6,1,1,1,1,1,1,6,6,6,6,6,6,6,6,6,6,6,1,1,1,1,1,1,1,6,6,6,6,6,1,1,1
6,1,1,1,1,1,1,6,6,6,6,6,6,6,6,6,6,6,1,1,1,1,1,1,1,6,6,6,6,6,6,6,6
6,1,1,1,1,1,1,6,6,6,6,6,6,6,6,6,6,6,1,1,1,1,1,1,1,6,6,6,6,6,6,6,6
6,1,1,1,1,1,1,6,6,6,6,6,6,6,6,6,6,6,6,6,6,6,6,6,6,6,6,6,6,6,6,6,6
6,1,1,1,1,1,1,1,6,6,6,6,6,6,6,6,6,6,6,6,6,6,6,6,6,6,6,6,6,6,6,6,6
6,1,1,1,1,1,1,1,6,6,6,6,6,6,6,6,6,6,6,6,6,6,6,6,6,6,6,6,6,6,6,6,6
endlayer

layer
6,6,6,6,6,6,6,6,6,6,6,7,7,7,7,7,7,7,7,7,7,7,7,7,7,7,7,7,7,7,7,7,7
6,6,6,6,6,6,6,6,6,6,6,7,7,7,7,7,7,7,7,7,7,7,6,6,6,6,6,6,6,6,6,6,7
6,1,1,1,1,1,1,6,6,6,6,6,6,6,6,6,6,6,7,7,7,7,6,6,6,6,6,6,6,6,6,6,7
6,1,6,6,6,6,6,6,6,6,6,6,6,6,6,6,6,6,7,1,7,7,6,6,6,6,6,6,6,6,6,6,7
6,6,6,6,6,6,6,6,6,6,6,6,6,6,6,6,6,6,7,7,7,7,6,6,6,6,6,6,6,6,6,6,7
6,1,6,6,6,6,6,6,6,6,6,6,6,6,6,6,6,6,7,7,7,7,6,6,6,6,6,6,6,6,6,6,7
6,1,1,1,1,1,1,6,6,6,6,6,6,6,6,6,6,6,7,7,7,7,6,6,6,6,6,6,6,6,6,6,7
6,1,6,6,6,6,6,6,6,6,6,6,6,6,6,6,6,6,7,7,7,7,7,7,7,6,6,6,6,6,7,7,7
6,6,6,6,6,6,6,6,6,6,6,6,6,6,6,6,6,6,7,7,7,7,7,7,7,6,6,6,6,6,6,6,6
6,1,6,6,6,6,6,6,6,6,6,6,6,6,6,6,6,6,7,7,7,7,7,7,7,6,6,6,6,6,6,6,6
6,1,6,6,6,6,6,6,6,6,6,6,6,6,6,6,6,6,6,6,6,6,6,6,6,6,6,6,6,6,6,6,6
6,1,1,1,1,1,1,1,6,6,6,6,6,6,6,6,6,6,6,6,6,6,6,6,6,6,6,6,6,6,6,6,6
6,6,6,6,6,6,6,6,6,6,6,6,6,6,6,6,6,6,6,6,6,6,6,6,6,6,6,6,6,6,6,6,6
endlayer

layer
0,0,0,0,0,0,0,0,0,0,0,0,0,0,0,0,0,0,0,0,0,0,0,0,0,0,0,0,0,0,0,0,0
0,0,0,0,0,0,0,0,0,0,0,0,0,0,0,0,0,0,0,0,0,0,3,3,3,3,3,3,3,3,3,3,0
0,3,3,3,3,3,3,3,3,3,3,3,3,3,3,3,3,3,0,0,0,0,3,0,0,3,3,8,0,0,0,3,0
0,3,0,0,0,0,0,3,0,0,0,0,0,0,0,0,0,3,0,10,0,0,3,0,0,0,0,0,0,0,0,3,0
0,12,0,0,0,0,0,3,0,0,0,0,0,0,0,0,0,3,0,0,0,0,3,0,0,0,0,0,0,0,0,3,0
0,3,0,0,0,0,0,3,0,0,0,0,0,0,0,0,0,3,0,0,0,0,3,0,0,0,0,0,0,0,0,3,0
0,3,3,3,3,3,3,3,0,0,0,0,0,0,0,0,0,3,0,0,0,0,3,3,3,3,3,9,3,3,3,3,0
0,3,0,0,0,0,0,3,0,0,0,0,0,0,0,0,0,3,0,0,0,0,0,0,0,0,0,0,0,0,0,0,0
0,13,0,0,0,0,0,3,0,0,0,0,0,0,0,0,0,3,0,0,0,0,0,0,0,0,0,0,0,0,0,0,0
0,3,0,0,0,0,0,3,3,3,3,8,0,0,0,0,0,3,0,0,0,0,0,0,0,0,0,0,0,0,0,0,0
0,3,0,0,0,0,0,3,3,3,3,3,11,3,3,3,3,3,0,0,0,0,0,0,0,0,0,0,0,0,0,0,0
0,3,3,3,3,3,3,3,0,0,3,0,0,0,3,0,0,3,0,0,0,0,0,0,0,0,0,0,0,0,0,0,0
0,0,0,0,0,0,0,0,0,0,0,0,0,0,0,0,0,0,0,0,0,0,0,0,0,0,0,0,0,0,0,0,0
endlayer

layer
0,0,0,0,0,0,0,0,0,0,0,0,0,0,0,0,0,0,0,0,0,0,0,0,0,0,0,0,0,0,0,0,0
0,0,0,0,0,0,0,0,0,0,0,0,0,0,0,0,0,0,0,0,0,0,3,3,3,3,3,14,3,3,3,3,0
0,3,3,14,3,14,3,3,3,3,3,3,14,3,3,3,3,3,0,0,0,0,3,0,0,3,8,0,0,0,0,3,0
0,3,0,0,0,0,0,3,0,0,0,0,0,0,0,0,0,3,0,10,0,0,14,0,0,0,0,0,0,0,0,14,0
0,15,0,0,0,0,0,3,0,0,0,0,0,0,0,0,0,3,0,0,0,16,3,0,0,0,0,0,0,0,0,3,0
0,3,0,0,0,0,0,3,0,0,0,0,0,0,0,0,0,3,0,16,0,0,3,0,0,0,0,0,0,0,0,3,0
0,3,3,3,3,3,3,3,0,0,0,0,0,0,0,0,0,14,0,16,16,0,3,3,3,3,3,15,3,3,3,3,0
0,3,0,0,0,0,0,3,0,0,0,0,0,0,0,0,0,14,0,16,0,0,0,0,0,0,0,0,0,0,0,0,0
0,15,0,0,0,0,0,3,0,0,0,0,0,0,0,0,0,14,0,0,0,0,0,0,0,0,0,0,0,0,0,0,0
0,3,0,0,0,0,0,3,3,3,8,0,0,0,0,0,0,3,0,0,0,0,0,0,0,0,0,0,0,0,0,0,0
0,3,0,0,0,0,0,3,3,3,3,3,15,3,3,3,3,3,0,0,0,0,0,0,0,0,0,0,0,0,0,0,0
0,3,3,14,3,14,3,3,0,0,3,0,0,0,3,0,0,3,0,0,0,0,0,0,0,0,0,0,0,0,0,0,0
0,0,0,0,0,0,0,0,0,0,0,0,0,0,0,0,0,0,0,0,0,0,0,0,0,0,0,0,0,0,0,0,0
endlayer

layer
0,0,0,0,0,0,0,0,0,0,0,0,0,0,0,0,0,0,0,0,0,0,0,0,0,0,0,0,0,0,0,0,0
0,18,0,0,0,0,0,0,0,0,0,0,0,0,0,0,0,18,0,0,0,0,3,3,3,3,3,14,3,3,3,3,0
20,3,3,14,3,14,3,3,3,3,3,3,14,3,3,3,3,3,19,0,0,16,3,0,0,8,0,0,17,0,0,3,0
0,3,0,0,0,0,0,3,0,0,0,0,0,17,0,0,0,3,0,10,16,16,14,0,0,0,0,0,0,0,0,14,0
20,3,19,0,0,0,20,3,0,0,0,0,0,0,0,0,0,3,10,16,10,16,3,0,0,0,0,0,0,0,0,3,0
0,3,0,0,0,0,0,3,0,0,0,0,0,0,0,0,0,3,16,16,16,16,3,0,0,0,0,0,18,0,0,3,0
0,3,3,3,3,3,3,3,0,0,0,0,0,0,0,0,0,14,0,16,16,16,3,3,3,3,3,3,3,3,3,3,0
0,3,0,0,0,0,0,3,19,0,0,0,0,0,0,0,0,14,0,16,16,16,0,0,0,0,0,0,0,0,0,0,0
20,3,19,0,0,0,20,3,0,0,0,0,0,0,0,0,0,14,0,16,16,0,0,0,0,0,0,0,0,0,0,0,0
0,3,0,0,0,0,20,3,3,8,0,0,0,18,0,0,0,3,0,0,0,0,0,0,0,0,0,0,0,0,0,0,0
0,3,0,0,0,0,0,3,3,3,3,3,3,3,3,3,3,3,0,0,0,0,0,0,0,0,0,0,0,0,0,0,0
20,3,3,14,3,14,3,3,17,17,3,17,17,17,3,17,17,3,0,0,0,0,0,0,0,0,0,0,0,0,0,0,0
0,17,0,0,0,0,0,0,0,0,0,0,0,0,0,0,0,0,0,0,0,0,0,0,0,0,0,0,0,0,0,0,0
endlayer

layer
0,0,0,0,0,0,0,0,0,0,0,0,0,0,0,0,0,0,0,0,0,0,0,0,0,0,0,0,0,0,0,0,0
0,0,0,0,0,0,0,18,0,0,0,0,0,0,0,0,0,0,0,0,0,0,3,3,3,3,3,14,3,3,3,3,0
21,3,3,3,3,3,3,3,3,3,3,3,14,3,3,3,3,3,16,0,0,10,3,3,8,0,0,0,0,0,0,3,0
21,3,0,0,0,0,0,3,0,0,0,0,0,0,0,0,0,3,16,10,10,16,14,0,0,0,0,0,0,0,0,14,0
21,3,0,0,0,0,0,3,0,0,0,0,0,0,0,0,0,3,10,10,16,16,3,0,0,0,0,0,0,0,0,3,0
21,3,0,0,0,0,0,3,0,0,0,0,0,0,0,0,0,3,16,10,16,10,3,0,0,0,0,0,0,0,0,3,0
21,3,3,3,3,3,3,3,0,0,0,0,0,0,0,0,0,14,0,16,16,16,3,3,3,3,3,3,3,3,3,3,0
21,3,0,0,0,0,0,3,0,0,0,0,0,0,0,0,0,14,0,16,16,0,17,0,0,0,0,0,0,0,0,0,0
21,3,0,0,0,0,0,3,0,0,0,0,0,0,0,0,0,14,0,0,16,0,0,0,0,0,0,0,0,0,0,0,0
21,3,0,0,0,0,0,3,8,0,0,0,0,0,0,0,0,3,0,0,0,0,0,0,0,0,0,0,0,0,0,0,0
21,3,0,0,0,0,0,3,3,3,3,3,3,3,3,3,3,3,19,0,0,0,0,0,0,0,0,0,0,0,0,0,0
21,3,3,3,3,3,3,3,3,3,3,3,3,3,3,3,3,3,0,0,0,0,0,0,0,0,0,0,0,0,0,0,0
0,0,0,0,0,0,3,3,3,3,3,3,3,3,3,3,3,3,0,0,0,0,0,0,0,0,0,0,0,0,0,0,0
endlayer

layer
0,0,0,0,0,0,0,0,0,0,0,0,0,0,0,0,0,0,0,0,0,0,18,0,0,0,0,0,0,0,0,18,0
0,0,0,0,0,0,0,0,0,0,0,0,18,0,0,0,0,0,0,0,0,20,3,3,3,3,3,3,3,3,3,3,19
0,24,3,3,3,3,3,3,3,3,3,3,3,3,3,3,3,3,16,16,0,16,3,8,0,0,0,3,3,3,3,3,0
0,24,0,0,0,0,0,3,3,3,3,3,3,3,3,3,3,3,16,10,16,16,3,3,3,3,3,3,3,3,3,3,0
0,24,0,0,0,0,0,3,3,3,3,3,3,3,3,3,3,3,16,16,16,16,3,3,3,3,3,3,3,3,3,3,0
0,24,0,0,0,0,0,3,3,3,3,3,3,3,3,3,3,3,16,16,16,16,3,3,3,3,3,3,3,3,3,3,0
0,24,3,3,3,3,3,3,3,3,3,3,3,3,3,3,3,3,0,10,16,16,3,3,3,3,3,3,3,3,3,3,19
0,24,0,0,0,0,0,3,3,3,3,3,3,3,3,3,3,3,0,16,16,0,0,0,0,0,0,0,0,0,0,17,0
0,24,0,0,0,0,0,3,23,3,3,3,3,3,3,3,3,3,0,0,16,0,0,0,0,0,0,0,0,0,0,0,0
0,24,0,0,0,0,0,3,0,0,0,3,3,3,3,3,3,3,0,0,0,0,0,0,0,0,0,0,0,0,0,0,0
0,24,0,0,0,0,0,3,3,3,3,3,3,3,23,3,3,3,0,0,0,0,0,0,0,0,0,0,0,0,0,0,0
0,24,3,3,3,3,3,0,0,0,0,0,0,0,0,0,0,22,0,0,0,0,0,0,0,0,0,0,0,0,0,0,0
0,0,0,0,0,0,22,22,22,22,22,22,22,22,22,22,22,22,0,0,0,0,0,0,0,0,0,0,0,0,0,0,0
endlayer

layer
0,0,0,0,0,0,0,0,0,0,0,0,0,0,0,0,0,0,0,0,0,0,0,0,0,0,0,0,0,0,0,0,0
0,0,0,0,0,0,0,0,0,0,0,0,0,0,0,0,0,0,0,0,16,0,3,3,3,3,3,3,3,3,3,3,0
0,0,24,3,3,3,3,3,3,3,3,3,3,3,3,3,3,3,16,16,16,16,3,0,0,0,0,0,0,0,0,3,0
0,0,24,3,3,3,3,3,26,0,0,0,0,0,0,0,0,3,16,10,16,16,3,0,0,0,0,0,0,0,0,3,0
0,0,24,3,3,3,3,3,0,0,0,0,0,0,0,0,0,3,16,16,16,16,3,0,0,0,0,0,0,0,0,3,0
0,0,24,3,3,3,3,3,0,0,0,0,0,0,0,0,0,3,16,16,16,16,3,0,0,0,0,0,0,0,0,3,0
0,0,24,3,3,3,3,3,8,0,0,0,0,0,0,0,0,3,0,16,16,16,3,3,3,3,3,3,3,3,3,3,0
0,0,24,3,3,3,3,3,0,0,0,0,0,0,0,0,0,3,0,16,16,0,0,0,0,0,0,0,0,0,0,0,0
0,0,24,3,3,3,3,3,0,25,25,25,0,0,0,0,0,3,0,0,16,0,0,0,0,0,0,0,0,0,0,0,0
0,0,24,3,3,3,3,3,0,0,0,25,0,0,11,0,0,3,0,0,0,0,0,0,0,0,0,0,0,0,0,0,0
0,0,24,3,3,3,3,3,3,3,3,3,3,3,0,3,3,3,0,0,0,0,0,0,0,0,0,0,0,0,0,0,0
0,0,24,3,3,3,3,0,0,0,0,0,0,0,0,0,0,0,0,0,0,0,0,0,0,0,0,0,0,0,0,0,0
0,0,0,0,0,0,0,0,0,0,0,0,0,0,0,0,0,0,0,0,0,0,0,0,0,0,0,0,0,0,0,0,0
endlayer

layer
0,0,0,0,0,0,0,0,0,0,0,0,0,0,0,0,0,0,0,0,0,0,0,0,0,0,0,0,0,0,0,0,0
0,0,0,0,0,0,0,0,0,0,0,0,0,0,0,0,0,0,16,16,16,16,3,3,3,3,3,14,3,3,3,3,0
0,0,0,25,25,25,25,3,3,3,3,3,14,3,3,3,3,3,16,16,16,16,3,0,0,0,0,0,0,0,0,3,0
0,0,0,25,0,0,0,3,26,0,0,0,0,0,0,0,0,3,16,16,16,16,14,0,0,0,0,0,0,0,0,14,0
0,0,0,25,0,0,0,14,0,0,0,0,0,0,0,0,0,3,16,16,16,16,3,0,0,0,0,0,0,0,0,3,0
0,0,0,25,0,0,0,3,0,0,0,0,0,0,0,0,0,3,16,16,16,16,3,0,0,0,0,0,0,0,0,3,0
0,0,0,25,0,0,0,27,0,0,0,0,0,0,0,0,0,14,0,16,16,16,3,3,3,3,3,14,3,3,3,3,0
0,0,0,25,0,0,0,3,0,0,0,0,0,0,0,0,0,3,0,16,16,0,0,0,0,0,0,0,0,0,0,0,0
0,0,0,25,0,0,0,14,0,0,0,0,0,0,0,0,0,3,0,16,0,0,0,0,0,0,0,0,0,0,0,0,0
0,0,0,25,0,0,0,3,0,0,0,0,0,0,15,0,0,3,0,0,0,0,0,0,0,0,0,0,0,0,0,0,0
0,0,0,25,0,0,25,3,3,3,3,3,14,3,0,3,3,3,0,0,0,0,0,0,0,0,0,0,0,0,0,0,0
0,0,0,25,25,25,25,0,0,0,0,0,0,0,0,0,0,0,0,0,0,0,0,0,0,0,0,0,0,0,0,0,0
0,0,0,0,0,0,0,0,0,0,0,0,0,0,0,0,0,0,0,0,0,0,0,0,0,0,0,0,0,0,0,0,0
endlayer

layer
0,0,0,0,0,0,0,0,0,0,0,0,0,0,0,0,0,0,0,0,0,0,18,0,0,0,0,0,0,0,0,18,0
0,0,0,0,0,0,0,0,0,0,0,0,0,0,0,0,0,0,0,16,0,20,3,3,3,3,3,14,3,3,3,3,19
0,0,0,0,0,0,0,3,3,3,3,3,14,3,3,3,3,3,16,16,16,16,3,0,0,0,0,0,17,0,0,3,0
0,0,0,0,0,0,0,3,26,0,0,0,0,17,0,0,0,3,16,16,16,16,14,0,0,0,0,0,0,0,0,14,0
0,0,0,0,0,0,0,14,0,0,0,0,0,0,0,0,0,3,16,16,16,0,3,0,0,0,0,0,0,0,0,3,0
0,0,0,0,0,0,0,3,0,0,0,0,0,0,0,0,0,3,0,16,0,16,3,0,0,0,0,0,18,0,0,3,0
0,0,0,0,0,0,0,15,0,0,0,0,0,0,0,0,0,14,16,16,16,20,3,3,3,3,3,14,3,3,3,3,19
0,0,0,0,0,0,0,3,0,0,0,0,0,0,0,0,0,3,0,16,0,0,17,0,0,0,0,0,0,0,0,17,0
0,0,0,0,0,0,0,14,0,0,0,0,0,0,0,0,0,3,0,0,0,0,0,0,0,0,0,0,0,0,0,0,0
0,0,0,0,0,0,0,3,0,0,0,0,0,18,0,0,0,3,0,0,0,0,0,0,0,0,0,0,0,0,0,0,0
0,0,0,0,0,0,0,3,3,3,3,3,14,3,3,3,3,3,0,0,0,0,0,0,0,0,0,0,0,0,0,0,0
0,0,0,0,0,0,0,0,0,0,0,0,0,0,17,0,0,0,0,0,0,0,0,0,0,0,0,0,0,0,0,0,0
0,0,0,0,0,0,0,0,0,0,0,0,0,0,0,0,0,0,0,0,0,0,0,0,0,0,0,0,0,0,0,0,0
endlayer

layer
0,0,0,0,0,0,0,0,0,0,0,0,0,0,0,0,0,0,0,0,0,0,30,28,30,28,30,28,30,28,30,28,0
0,0,0,0,0,0,0,18,0,0,0,0,0,0,0,0,0,18,0,0,0,0,3,28,28,28,28,28,28,28,28,3,0
0,0,0,0,0,0,20,3,3,3,3,3,3,3,3,3,3,3,19,16,0,0,3,0,0,0,0,0,0,0,0,3,0
0,0,0,0,0,0,0,3,0,0,0,0,0,0,0,0,0,3,16,16,16,0,3,0,0,0,0,0,0,0,0,3,0
0,0,0,0,0,0,0,3,0,0,0,0,0,0,0,0,0,3,0,16,0,0,3,0,0,0,0,0,0,0,0,3,0
0,0,0,0,0,0,0,3,0,0,0,0,0,0,0,0,0,3,0,0,0,0,3,0,0,0,0,0,0,0,0,3,0
0,0,0,0,0,0,0,3,19,0,0,0,0,0,0,0,20,3,0,16,0,0,3,28,28,28,28,28,28,28,28,3,0
0,0,0,0,0,0,0,3,0,0,0,0,0,0,0,0,0,3,0,0,0,0,29,29,29,29,29,29,29,29,29,29,0
0,0,0,0,0,0,0,3,0,0,0,0,0,0,0,0,0,3,0,0,0,0,0,0,0,0,0,0,0,0,0,0,0
0,0,0,0,0,0,0,3,0,0,0,0,0,0,0,0,0,3,0,0,0,0,0,0,0,0,0,0,0,0,0,0,0
0,0,0,0,0,0,20,3,3,3,3,3,3,3,3,3,3,3,19,0,0,0,0,0,0,0,0,0,0,0,0,0,0
0,0,0,0,0,0,0,17,0,0,0,0,0,0,0,0,0,17,0,0,0,0,0,0,0,0,0,0,0,0,0,0,0
0,0,0,0,0,0,0,0,0,0,0,0,0,0,0,0,0,0,0,0,0,0,0,0,0,0,0,0,0,0,0,0,0
endlayer

layer
0,0,0,0,0,0,0,0,0,0,0,0,0,0,0,0,0,0,0,0,0,0,0,0,0,0,0,0,0,0,0,0,0
0,0,0,0,0,0,0,30,30,28,30,30,30,30,30,30,30,30,0,0,0,0,30,30,30,30,30,30,30,30,30,30,0
0,0,0,0,0,0,0,3,28,28,28,28,28,28,28,28,28,3,0,0,0,0,3,28,28,28,28,28,28,28,28,3,0
0,0,0,0,0,0,0,3,0,0,0,0,0,0,0,0,0,3,0,16,0,0,3,19,0,0,0,0,0,0,0,3,0
0,0,0,0,0,0,0,3,0,0,0,0,0,0,0,0,0,3,0,0,0,0,3,0,0,0,0,0,0,0,20,3,0
0,0,0,0,0,0,0,3,0,0,0,0,0,0,0,0,0,3,0,0,0,0,3,28,28,28,28,28,28,28,28,3,0
0,0,0,0,0,0,0,3,0,0,0,0,0,0,0,0,0,3,0,0,0,0,29,29,29,29,29,29,29,29,29,29,0
0,0,0,0,0,0,0,3,0,0,0,0,0,0,0,0,0,3,0,0,0,0,0,0,0,0,0,0,0,0,0,0,0
0,0,0,0,0,0,0,3,0,0,0,0,0,0,0,0,0,3,0,0,0,0,0,0,0,0,0,0,0,0,0,0,0
0,0,0,0,0,0,0,3,0,0,0,0,0,0,0,0,0,3,0,0,0,0,0,0,0,0,0,0,0,0,0,0,0
0,0,0,0,0,0,0,3,28,28,28,28,28,28,28,28,28,3,0,0,0,0,0,0,0,0,0,0,0,0,0,0,0
0,0,0,0,0,0,0,29,29,29,29,29,29,29,29,29,29,29,0,0,0,0,0,0,0,0,0,0,0,0,0,0,0
0,0,0,0,0,0,0,0,0,0,0,0,0,0,0,0,0,0,0,0,0,0,0,0,0,0,0,0,0,0,0,0,0
endlayer

layer
0,0,0,0,0,0,0,0,0,0,0,0,0,0,0,0,0,0,0,0,0,0,0,0,0,0,0,0,0,0,0,0,0
0,0,0,0,0,0,0,0,0,0,0,0,0,0,0,0,0,0,0,0,0,0,0,0,0,0,0,0,0,0,0,0,0
0,0,0,0,0,0,0,30,30,30,30,30,30,30,30,30,30,30,0,0,0,0,30,30,30,30,30,30,30,30,30,30,0
0,0,0,0,0,0,0,3,28,28,28,28,28,28,28,28,28,3,0,0,0,0,3,28,28,28,28,28,28,28,28,3,0
0,0,0,0,0,0,0,3,0,0,0,0,0,0,0,0,0,3,0,0,0,0,3,28,28,28,28,28,28,28,28,3,0
0,0,0,0,0,0,0,3,0,0,0,0,0,0,0,0,0,3,0,0,0,0,29,29,29,29,29,29,29,29,29,29,0
0,0,0,0,0,0,0,25,0,0,0,0,0,0,0,0,0,3,0,0,0,0,0,0,0,0,0,0,0,0,0,0,0
0,0,0,0,0,0,0,3,0,0,0,0,0,0,0,0,0,3,0,0,0,0,0,0,0,0,0,0,0,0,0,0,0
0,0,0,0,0,0,0,3,0,0,0,0,0,0,0,0,0,3,0,0,0,0,0,0,0,0,0,0,0,0,0,0,0
0,0,0,0,0,0,0,3,28,28,28,28,28,28,28,28,28,3,0,0,0,0,0,0,0,0,0,0,0,0,0,0,0
0,0,0,0,0,0,0,29,29,29,29,29,29,29,29,29,29,29,0,0,0,0,0,0,0,0,0,0,0,0,0,0,0
0,0,0,0,0,0,0,0,0,0,0,0,0,0,0,0,0,0,0,0,0,0,0,0,0,0,0,0,0,0,0,0,0
0,0,0,0,0,0,0,0,0,0,0,0,0,0,0,0,0,0,0,0,0,0,0,0,0,0,0,0,0,0,0,0,0
endlayer

layer
0,0,0,0,0,0,0,0,0,0,0,0,0,0,0,0,0,0,0,0,0,0,0,0,0,0,0,0,0,0,0,0,0
0,0,0,0,0,0,0,0,0,0,0,0,0,0,0,0,0,0,0,0,0,0,0,0,0,0,0,0,0,0,0,0,0
0,0,0,0,0,0,0,0,0,0,0,0,0,0,0,0,0,0,0,0,0,0,0,0,0,0,0,0,0,0,0,0,0
0,0,0,0,0,0,0,30,30,30,30,30,30,30,30,30,30,30,0,0,0,0,30,30,30,30,30,30,30,30,30,30,0
0,0,0,0,0,0,0,3,28,28,28,28,28,28,28,28,28,3,0,0,0,0,29,29,29,29,29,29,29,29,29,29,0
0,0,0,0,0,0,0,3,0,0,0,0,0,0,0,0,0,3,0,0,0,0,0,0,0,0,0,0,0,0,0,0,0
0,0,0,0,0,0,0,3,0,0,0,0,0,0,0,0,0,3,0,0,0,0,0,0,0,0,0,0,0,0,0,0,0
0,0,0,0,0,0,0,3,0,0,0,0,0,0,0,0,0,3,0,0,0,0,0,0,0,0,0,0,0,0,0,0,0
0,0,0,0,0,0,0,3,28,28,28,28,28,28,28,28,28,3,0,0,0,0,0,0,0,0,0,0,0,0,0,0,0
0,0,0,0,0,0,0,29,29,29,29,29,29,29,29,29,29,29,0,0,0,0,0,0,0,0,0,0,0,0,0,0,0
0,0,0,0,0,0,0,0,0,0,0,0,0,0,0,0,0,0,0,0,0,0,0,0,0,0,0,0,0,0,0,0,0
0,0,0,0,0,0,0,0,0,0,0,0,0,0,0,0,0,0,0,0,0,0,0,0,0,0,0,0,0,0,0,0,0
0,0,0,0,0,0,0,0,0,0,0,0,0,0,0,0,0,0,0,0,0,0,0,0,0,0,0,0,0,0,0,0,0
endlayer

layer
0,0,0,0,0,0,0,0,0,0,0,0,0,0,0,0,0,0,0,0,0,0,0,0,0,0,0,0,0,0,0,0,0
0,0,0,0,0,0,0,0,0,0,0,0,0,0,0,0,0,0,0,0,0,0,0,0,0,0,0,0,0,0,0,0,0
0,0,0,0,0,0,0,0,0,0,0,0,0,0,0,0,0,0,0,0,0,0,0,0,0,0,0,0,0,0,0,0,0
0,0,0,0,0,0,0,0,0,0,0,0,0,0,0,0,0,0,0,0,0,0,0,0,0,0,0,0,0,0,0,0,0
0,0,0,0,0,0,0,30,30,30,30,30,30,30,30,30,30,30,0,0,0,0,0,0,0,0,0,0,0,0,0,0,0
0,0,0,0,0,0,0,3,28,28,28,28,28,28,28,28,28,3,0,0,0,0,0,0,0,0,0,0,0,0,0,0,0
0,0,0,0,0,0,0,3,0,0,0,0,0,0,0,0,0,3,0,0,0,0,0,0,0,0,0,0,0,0,0,0,0
0,0,0,0,0,0,0,3,28,28,28,28,28,28,28,28,28,3,0,0,0,0,0,0,0,0,0,0,0,0,0,0,0
0,0,0,0,0,0,0,29,29,29,29,29,29,29,29,29,29,29,0,0,0,0,0,0,0,0,0,0,0,0,0,0,0
0,0,0,0,0,0,0,0,0,0,0,0,0,0,0,0,0,0,0,0,0,0,0,0,0,0,0,0,0,0,0,0,0
0,0,0,0,0,0,0,0,0,0,0,0,0,0,0,0,0,0,0,0,0,0,0,0,0,0,0,0,0,0,0,0,0
0,0,0,0,0,0,0,0,0,0,0,0,0,0,0,0,0,0,0,0,0,0,0,0,0,0,0,0,0,0,0,0,0
0,0,0,0,0,0,0,0,0,0,0,0,0,0,0,0,0,0,0,0,0,0,0,0,0,0,0,0,0,0,0,0,0
endlayer

layer
0,0,0,0,0,0,0,0,0,0,0,0,0,0,0,0,0,0,0,0,0,0,0,0,0,0,0,0,0,0,0,0,0
0,0,0,0,0,0,0,0,0,0,0,0,0,0,0,0,0,0,0,0,0,0,0,0,0,0,0,0,0,0,0,0,0
0,0,0,0,0,0,0,0,0,0,0,0,0,0,0,0,0,0,0,0,0,0,0,0,0,0,0,0,0,0,0,0,0
0,0,0,0,0,0,0,0,0,0,0,0,0,0,0,0,0,0,0,0,0,0,0,0,0,0,0,0,0,0,0,0,0
0,0,0,0,0,0,0,0,0,0,0,0,0,0,0,0,0,0,0,0,0,0,0,0,0,0,0,0,0,0,0,0,0
0,0,0,0,0,0,0,30,30,30,30,30,30,30,30,30,30,30,0,0,0,0,0,0,0,0,0,0,0,0,0,0,0
0,0,0,0,0,0,0,28,28,28,28,28,28,28,28,28,28,28,0,0,0,0,0,0,0,0,0,0,0,0,0,0,0
0,0,0,0,0,0,0,29,29,29,29,29,29,29,29,29,29,29,0,0,0,0,0,0,0,0,0,0,0,0,0,0,0
0,0,0,0,0,0,0,0,0,0,0,0,0,0,0,0,0,0,0,0,0,0,0,0,0,0,0,0,0,0,0,0,0
0,0,0,0,0,0,0,0,0,0,0,0,0,0,0,0,0,0,0,0,0,0,0,0,0,0,0,0,0,0,0,0,0
0,0,0,0,0,0,0,0,0,0,0,0,0,0,0,0,0,0,0,0,0,0,0,0,0,0,0,0,0,0,0,0,0
0,0,0,0,0,0,0,0,0,0,0,0,0,0,0,0,0,0,0,0,0,0,0,0,0,0,0,0,0,0,0,0,0
0,0,0,0,0,0,0,0,0,0,0,0,0,0,0,0,0,0,0,0,0,0,0,0,0,0,0,0,0,0,0,0,0
endlayer

layer
0,0,0,0,0,0,0,0,0,0,0,0,0,0,0,0,0,0,0,0,0,0,0,0,0,0,0,0,0,0,0,0,0
0,0,0,0,0,0,0,0,0,0,0,0,0,0,0,0,0,0,0,0,0,0,0,0,0,0,0,0,0,0,0,0,0
0,0,0,0,0,0,0,0,0,0,0,0,0,0,0,0,0,0,0,0,0,0,0,0,0,0,0,0,0,0,0,0,0
0,0,0,0,0,0,0,0,0,0,0,0,0,0,0,0,0,0,0,0,0,0,0,0,0,0,0,0,0,0,0,0,0
0,0,0,0,0,0,0,0,0,0,0,0,0,0,0,0,0,0,0,0,0,0,0,0,0,0,0,0,0,0,0,0,0
0,0,0,0,0,0,0,0,0,0,0,0,0,0,0,0,0,0,0,0,0,0,0,0,0,0,0,0,0,0,0,0,0
0,0,0,0,0,0,0,31,0,0,0,0,0,0,0,0,0,31,0,0,0,0,0,0,0,0,0,0,0,0,0,0,0
0,0,0,0,0,0,0,0,0,0,0,0,0,0,0,0,0,0,0,0,0,0,0,0,0,0,0,0,0,0,0,0,0
0,0,0,0,0,0,0,0,0,0,0,0,0,0,0,0,0,0,0,0,0,0,0,0,0,0,0,0,0,0,0,0,0
0,0,0,0,0,0,0,0,0,0,0,0,0,0,0,0,0,0,0,0,0,0,0,0,0,0,0,0,0,0,0,0,0
0,0,0,0,0,0,0,0,0,0,0,0,0,0,0,0,0,0,0,0,0,0,0,0,0,0,0,0,0,0,0,0,0
0,0,0,0,0,0,0,0,0,0,0,0,0,0,0,0,0,0,0,0,0,0,0,0,0,0,0,0,0,0,0,0,0
0,0,0,0,0,0,0,0,0,0,0,0,0,0,0,0,0,0,0,0,0,0,0,0,0,0,0,0,0,0,0,0,0
endlayer

