# Author: Mosslander
# From: Town Pack

weight=1
embed_into_distance=1
dimensions=6,13,11
max_cut_in=6
max_leveling=2


rule1=0,100,2
rule2=0,100,60
rule3=0,100,8
rule4=0,100,5
rule5=0,100,50-1
rule6=0,100,85
rule7=0,100,24
rule8=0,100,17
rule9=0,100,64-11
rule10=0,100,64-3
rule11=0,100,50-1
rule12=0,100,50-3
rule13=0,100,50-2
rule14=0,100,50-4
rule15=0,100,64-14
rule16=0,100,64-6
rule17=0,100,52-0-Pig
rule18=0,100,52-0-MushroomCow

layer:base
1,1,1,1,1,1,1,1,1,1,1
1,1,1,1,7,7,7,1,1,1,1
1,1,1,1,7,7,7,1,1,1,1
1,1,1,1,7,7,7,1,1,1,1
1,1,1,1,7,7,7,1,1,1,1
1,1,1,1,7,7,7,1,1,1,1
1,1,1,1,7,7,7,1,1,1,1
1,1,1,1,7,7,7,1,1,1,1
1,1,1,1,7,7,7,1,1,1,1
1,1,1,1,7,7,7,1,1,1,1
1,7,7,7,7,7,7,7,7,7,1
1,7,7,7,7,7,7,7,7,7,1
1,1,1,1,7,6,7,1,1,1,1
endlayer

layer
1,1,1,1,1,1,1,1,1,1,1
1,1,1,1,7,7,7,1,1,1,1
1,1,1,1,7,7,7,1,1,1,1
1,1,18,1,7,7,7,1,18,1,1
1,1,1,1,7,7,7,1,1,1,1
1,1,1,1,7,7,7,1,1,1,1
1,1,17,1,7,7,7,1,17,1,1
1,1,1,1,7,7,7,1,1,1,1
1,1,1,1,7,7,7,1,1,1,1
1,1,1,1,7,7,7,1,1,1,1
1,7,7,7,7,7,7,7,7,7,1
1,7,7,7,7,7,7,7,7,7,1
1,1,1,1,7,6,7,1,1,1,1
endlayer

layer
8,8,8,8,8,8,8,8,8,8,8
8,0,0,0,6,0,6,0,0,0,8
8,0,0,0,6,0,6,0,0,0,8
8,4,4,4,0,0,0,4,4,4,8
8,0,0,0,6,0,6,0,0,0,8
8,0,0,0,6,0,6,0,0,0,8
8,4,4,4,0,0,0,4,4,4,8
8,0,0,0,6,0,6,0,0,0,8
8,0,0,0,6,0,6,0,0,0,8
8,4,4,4,0,0,0,4,4,4,8
8,0,0,0,0,0,0,0,0,0,8
8,0,0,0,0,0,0,0,0,0,8
8,8,8,8,10,0,16,8,8,8,8
endlayer

layer
8,8,8,8,8,8,8,8,8,8,8
8,0,0,0,0,0,0,0,0,0,8
8,0,0,0,0,0,0,0,0,0,8
8,6,6,4,0,0,0,4,6,6,8
8,0,0,0,0,0,0,0,0,0,8
8,0,0,0,0,0,0,0,0,0,8
8,6,6,4,0,0,0,4,6,6,8
8,0,0,0,0,0,0,0,0,0,8
8,0,0,0,0,0,0,0,0,0,8
8,6,6,4,0,0,0,4,6,6,8
8,0,0,0,0,0,0,0,0,0,8
8,0,0,0,0,0,0,0,0,0,8
8,8,8,8,9,0,15,8,8,8,8
endlayer

layer
8,8,8,8,8,8,8,8,8,8,8
8,0,0,4,0,11,0,4,0,0,8
8,14,0,4,0,0,0,4,0,12,8
8,0,0,4,14,0,12,4,0,0,8
8,0,0,4,0,0,0,4,0,0,8
8,14,0,4,0,0,0,4,0,12,8
8,0,0,4,14,0,12,4,0,0,8
8,0,0,4,0,0,0,4,0,0,8
8,14,0,4,0,0,0,4,0,12,8
8,0,0,4,0,0,0,4,0,0,8
8,0,0,0,0,0,0,0,0,0,8
8,0,13,0,0,0,0,0,13,0,8
8,8,8,8,6,6,6,8,8,8,8
endlayer

layer
8,8,8,8,8,8,8,8,8,8,8
8,0,0,0,0,0,0,0,0,0,8
8,0,0,0,0,0,0,0,0,0,8
8,0,0,0,0,0,0,0,0,0,8
8,0,0,0,0,0,0,0,0,0,8
8,0,0,0,0,0,0,0,0,0,8
8,0,0,0,0,0,0,0,0,0,8
8,0,0,0,0,0,0,0,0,0,8
8,0,0,0,0,0,0,0,0,0,8
8,0,0,0,0,0,0,0,0,0,8
8,0,0,0,0,0,0,0,0,0,8
8,0,0,0,0,0,0,0,0,0,8
8,8,8,8,8,8,8,8,8,8,8
endlayer

layer
4,4,4,4,4,4,4,4,4,4,4
4,4,4,4,4,4,4,4,4,4,4
4,4,4,4,4,4,4,4,4,4,4
4,4,4,4,4,4,4,4,4,4,4
4,4,4,4,4,4,4,4,4,4,4
4,4,4,4,4,4,4,4,4,4,4
4,4,4,4,4,4,4,4,4,4,4
4,4,4,4,4,4,4,4,4,4,4
4,4,4,4,4,4,4,4,4,4,4
4,4,4,4,4,4,4,4,4,4,4
4,4,4,4,4,4,4,4,4,4,4
4,4,4,4,4,4,4,4,4,4,4
4,4,4,4,4,4,4,4,4,4,4
endlayer

