# Converted from schematic
# author:MohawkyMagoo

weight=10
embed_into_distance=1
#acceptable_target_blocks=1,2,3,12,13
dimensions=18,18,37
#allowable_overhang=0
max_cut_in=2
#cut_in_buffer=1
max_leveling=2
#leveling_buffer=1
#preserve_water=0
#preserve_lava=0
#preserve_plants=0


rule1=0,100,1
rule2=0,100,4
rule3=0,100,3
rule4=0,100,2
rule5=0,100,109-2
rule6=0,100,98
rule7=0,100,82
rule8=0,100,9
rule9=0,100,109-0
rule10=0,100,17-2
rule11=0,100,109-1
rule12=0,100,109-3
rule13=0,100,50-4
rule14=0,100,50-2
rule15=0,100,18-2
rule16=0,100,50-3
rule17=0,100,71
rule18=0,100,77-2
rule19=0,100,50-3
rule20=0,100,71-8
rule21=0,100,77-1
rule22=0,100,85
rule23=0,100,5
rule24=0,100,71-3
rule25=0,100,64-1
rule26=0,100,71-1
rule27=0,100,47
rule28=0,100,54-3
rule29=0,100,54-5
rule30=0,100,64
rule31=0,100,53-0
rule32=0,100,102
rule33=0,100,64-8
rule34=0,100,17
rule35=0,100,50-5
rule36=0,100,53-2
rule37=0,100,53-3
rule38=0,100,53-1
rule39=0,100,126
rule40=0,100,64-0


layer
2,2,2,2,2,2,2,2,2,2,2,2,2,2,2,2,2,2,2,2,2,2,2,2,2,2,2,2,2,2,1,1,1,1,1,1,1
2,4,4,4,4,4,4,4,4,2,2,3,3,3,3,3,3,3,3,3,3,3,3,3,3,3,3,3,3,1,1,1,1,1,1,1,2
2,3,4,4,4,3,4,4,4,2,2,3,1,1,1,3,3,3,3,1,1,1,3,3,3,3,3,3,1,1,1,1,1,1,1,1,1
2,4,4,4,4,4,4,4,4,2,2,3,1,1,1,1,1,1,1,1,1,1,1,3,3,3,3,1,1,1,1,1,1,1,1,1,1
2,4,4,4,4,4,4,4,4,2,2,3,1,1,1,1,1,1,1,1,1,1,1,1,1,1,1,1,1,1,1,1,1,1,1,1,3
2,2,2,2,2,2,2,2,2,2,2,1,1,1,1,1,1,1,1,1,1,1,1,1,1,1,1,1,1,1,1,1,1,1,1,1,2
2,2,2,2,2,3,3,2,3,3,1,1,1,1,1,1,1,1,1,1,1,1,1,1,1,1,1,1,1,1,1,2,2,1,1,1,1
2,3,3,4,2,2,2,3,3,3,1,1,1,1,1,1,1,1,1,1,1,1,1,1,1,1,1,1,1,1,1,2,2,1,1,1,1
2,3,3,3,3,3,3,3,3,1,1,1,1,1,1,1,1,1,1,1,1,1,1,1,1,1,1,1,1,1,1,2,1,1,1,1,1
2,3,3,1,1,1,1,1,1,1,1,1,1,1,1,1,1,1,1,1,1,1,1,1,1,1,1,1,1,1,1,1,1,1,1,1,1
2,3,3,1,1,1,1,1,1,1,1,1,1,1,1,1,1,1,1,1,1,1,1,1,1,1,1,1,1,1,1,1,1,1,1,1,1
2,3,3,1,1,1,1,1,1,1,1,1,1,1,1,1,1,1,1,1,1,1,1,1,1,1,1,1,1,1,1,1,1,1,1,1,1
2,3,1,1,1,1,1,3,1,1,1,1,1,1,1,1,1,1,1,1,1,1,1,1,1,1,1,1,1,1,1,1,1,1,1,1,1
2,1,1,1,3,3,3,1,1,1,1,1,1,1,1,1,1,1,1,1,1,1,1,1,1,1,1,1,1,1,1,1,1,1,1,1,1
2,1,1,1,3,3,3,1,1,1,1,1,1,1,1,1,1,1,1,1,1,1,1,1,1,1,1,1,1,1,1,1,1,1,1,1,1
2,1,1,3,3,3,3,2,2,1,1,1,1,1,1,1,1,1,3,1,1,1,1,1,1,1,1,1,1,1,1,1,1,1,1,1,1
2,1,1,3,3,3,2,2,2,1,1,1,1,1,3,3,3,3,3,3,3,1,1,1,1,1,1,1,1,1,1,1,1,1,1,1,1
2,2,2,2,2,2,2,2,2,1,1,1,1,1,3,3,3,3,3,3,3,3,3,1,1,1,1,1,1,1,1,1,1,1,1,1,1
endlayer

layer
0,0,0,0,0,0,0,0,0,0,0,0,0,0,0,0,0,0,0,0,0,0,0,0,0,0,9,6,6,6,6,6,6,6,6,5,5
0,0,0,0,0,0,0,0,0,0,0,6,6,6,6,6,6,6,6,6,6,6,6,6,6,6,6,6,6,7,7,3,6,6,6,3,6
0,10,0,0,0,10,0,0,0,0,0,9,3,3,3,3,3,3,3,3,3,3,3,3,3,3,3,7,7,7,7,7,3,6,6,3,6
0,0,0,0,0,0,0,0,0,0,0,6,3,3,3,3,3,3,3,3,3,3,3,3,3,3,8,8,8,8,8,8,6,6,6,3,6
0,0,0,0,0,0,0,0,0,0,0,6,3,3,3,3,3,3,3,3,3,3,3,3,3,3,8,8,8,8,8,8,6,3,3,3,6
0,0,0,0,0,0,0,0,0,0,0,6,3,3,3,3,3,3,3,3,3,3,3,3,3,3,8,8,8,8,8,8,6,3,3,3,6
0,0,0,0,0,6,6,6,6,6,6,3,3,3,3,3,3,3,3,3,3,3,3,3,3,3,8,8,8,8,8,8,6,6,3,1,6
6,6,6,11,0,6,6,6,3,3,3,3,3,3,3,3,3,3,3,3,3,3,3,3,3,3,8,8,8,8,8,8,6,3,1,1,6
6,6,6,6,6,3,3,3,3,3,3,3,1,3,3,3,3,3,3,3,3,3,3,3,3,3,8,8,8,8,8,8,6,3,1,1,6
6,3,3,3,3,3,3,3,3,3,3,1,1,1,3,3,3,3,3,3,3,3,3,3,3,3,3,3,3,3,3,6,3,1,1,3,6
6,3,3,3,3,3,3,3,3,3,1,1,1,1,1,1,3,3,3,3,3,3,3,3,3,3,3,3,3,3,3,6,1,1,1,3,6
6,3,3,3,3,3,3,3,3,1,1,1,1,1,1,1,1,1,1,3,3,3,3,3,3,3,3,3,3,1,1,1,1,1,1,1,6
6,3,3,3,3,3,3,3,1,1,1,1,1,1,1,1,1,1,1,1,1,1,1,1,1,1,1,1,1,1,1,1,3,1,1,1,6
6,3,3,3,3,3,3,1,3,3,1,1,1,1,1,1,1,1,1,1,1,1,1,1,1,1,1,1,1,1,1,1,3,1,1,1,6
6,3,3,3,3,3,3,3,1,1,3,1,1,1,1,1,1,1,1,1,1,1,1,1,1,1,1,1,1,1,1,1,1,1,1,1,6
6,3,3,3,3,3,3,3,3,1,1,1,1,1,1,1,1,1,1,1,1,1,1,1,1,1,1,1,1,1,1,1,1,1,1,1,6
6,3,3,3,3,3,3,3,1,1,3,1,1,1,1,3,1,3,3,3,3,1,1,1,1,1,1,1,1,1,1,1,1,1,1,1,6
6,6,6,6,6,6,6,6,6,6,6,6,6,6,6,6,6,6,6,6,6,6,6,6,6,6,6,6,6,6,6,6,6,6,6,6,6
endlayer

layer
0,0,0,0,0,0,0,0,0,0,0,0,0,0,0,0,0,0,0,0,0,0,0,0,0,0,0,9,6,6,6,6,6,6,6,0,0
0,0,0,0,0,0,0,0,0,0,0,0,6,6,6,6,6,6,6,6,6,6,6,6,6,6,6,6,6,6,6,6,6,6,6,5,5
0,10,0,0,0,10,0,0,0,0,0,0,9,6,6,6,6,6,6,6,6,6,3,3,3,6,6,6,6,6,6,6,6,6,6,6,6
0,0,0,0,0,0,0,0,0,0,0,6,6,3,3,3,3,3,3,3,3,3,3,3,3,6,8,8,8,8,8,8,6,6,6,6,6
0,0,0,0,0,0,0,0,0,0,0,6,3,3,3,3,3,3,3,3,3,3,3,3,3,6,8,8,8,8,8,8,6,6,6,6,6
0,0,0,0,0,0,0,0,0,0,0,6,3,3,3,3,3,3,3,3,3,3,3,3,3,6,8,8,8,8,8,8,6,6,6,3,6
0,0,0,0,0,6,6,6,6,6,6,6,3,3,3,3,3,3,3,3,3,3,3,3,3,6,8,8,8,8,8,8,6,6,3,3,6
6,6,11,0,0,6,6,6,6,6,6,6,3,3,3,3,3,3,3,3,3,3,3,3,3,6,8,8,8,8,8,8,6,6,3,3,6
6,6,6,6,6,6,6,6,6,6,6,3,3,3,3,3,3,3,3,3,3,3,3,3,3,6,8,8,8,8,8,8,6,6,3,3,6
6,3,3,6,6,6,6,6,6,6,3,3,3,3,3,3,3,3,3,3,3,3,3,3,3,6,6,6,6,6,6,6,6,3,3,3,6
6,6,6,6,6,6,6,6,3,3,3,3,3,3,3,3,3,3,3,3,3,3,3,3,3,6,6,6,6,6,6,6,6,3,3,3,6
6,6,6,6,6,6,6,3,3,3,3,3,3,3,3,3,3,3,3,3,3,3,3,3,3,3,3,3,3,3,3,3,3,3,3,3,6
6,6,6,6,6,3,3,3,3,3,3,3,3,3,3,3,3,3,3,3,3,3,3,3,3,3,3,3,3,3,3,3,3,3,3,1,6
6,6,6,6,3,3,3,3,3,3,3,3,3,3,3,3,3,3,3,3,3,3,3,3,3,3,3,3,3,3,3,3,3,1,1,3,6
6,6,6,3,3,3,3,3,3,3,3,3,3,3,3,3,3,3,3,3,3,3,3,3,3,3,3,3,3,3,3,3,1,1,3,3,6
6,6,3,3,3,3,3,3,3,3,3,3,3,1,1,1,1,1,1,1,1,1,1,1,3,3,1,1,1,1,1,1,3,1,1,1,6
6,3,3,3,3,3,3,3,3,3,3,3,1,1,1,1,1,1,1,1,1,1,1,1,1,1,1,3,3,3,3,3,3,3,3,3,6
6,6,6,6,6,6,6,6,6,6,6,6,6,6,6,6,6,6,6,6,6,6,6,6,6,6,6,6,6,6,6,6,6,6,6,6,6
endlayer

layer
0,0,0,0,0,0,0,0,0,0,0,0,0,0,13,0,0,0,0,13,0,0,0,13,0,0,0,0,9,6,6,6,6,6,6,0,0
0,0,0,0,15,15,15,0,0,0,0,0,0,6,6,6,6,6,6,6,6,6,6,6,6,6,6,6,6,6,6,6,6,6,6,0,0
0,10,0,0,15,10,15,0,0,0,0,0,0,9,6,6,6,6,6,6,6,6,6,6,6,6,0,0,0,0,12,0,0,6,6,5,5
0,0,0,0,15,15,15,0,0,0,14,6,6,6,6,6,6,6,6,6,6,6,6,3,6,0,0,0,0,0,0,0,0,6,6,6,6
0,0,0,0,0,0,0,0,0,0,0,6,6,6,6,6,6,6,6,6,6,6,6,3,6,0,0,0,0,0,0,0,0,6,6,6,6
0,0,0,0,0,13,0,0,0,0,0,6,6,6,6,6,6,6,6,6,6,6,6,3,6,6,0,0,0,0,0,0,0,6,6,6,6
16,0,0,0,14,6,6,6,6,6,6,6,6,6,6,6,6,6,6,6,6,6,3,3,6,0,0,0,0,0,0,0,0,0,6,6,6
6,11,0,0,0,6,6,6,6,6,6,6,6,6,6,6,6,6,6,6,6,6,6,3,6,6,0,0,0,0,0,0,0,6,3,3,6
6,6,6,6,6,6,6,6,6,6,6,3,3,3,6,6,6,6,6,6,6,6,3,3,6,0,0,0,0,0,0,0,0,0,6,3,6
6,3,3,6,6,6,6,6,6,6,3,3,3,3,6,6,6,6,6,6,6,6,3,3,6,0,0,0,0,0,0,0,0,6,3,3,6
6,6,6,6,6,6,6,6,6,6,6,3,3,6,6,6,6,6,6,6,6,6,3,3,6,6,0,6,0,0,6,0,6,6,3,3,6
6,6,6,6,6,6,6,6,6,6,6,3,3,3,3,3,6,6,6,6,6,6,3,3,3,6,6,6,6,6,6,6,6,3,3,3,6
6,6,6,6,6,6,6,6,6,6,6,3,3,3,3,3,3,3,3,3,3,3,3,3,3,6,6,6,6,6,6,6,6,3,3,3,6
6,6,6,6,6,6,6,6,6,6,6,3,3,3,3,3,3,3,3,3,3,3,3,3,3,6,6,6,6,6,6,6,6,3,3,3,6
6,6,6,6,6,6,6,6,6,6,6,3,3,3,3,3,3,3,3,3,3,3,3,3,3,6,6,6,6,6,6,6,6,3,3,3,6
6,6,6,6,6,6,6,3,3,3,3,3,3,3,3,3,3,3,3,3,3,3,3,3,3,6,6,6,6,6,6,6,6,3,3,3,6
6,6,6,6,6,6,6,3,3,3,3,3,3,3,3,3,3,3,3,3,3,3,3,3,3,3,3,3,3,3,3,3,3,3,3,3,6
6,6,6,6,6,6,6,6,6,6,6,6,6,6,6,6,6,6,6,6,6,6,6,6,6,6,6,6,6,6,6,6,6,6,6,6,6
endlayer

layer
15,15,15,15,15,15,15,0,0,0,0,0,0,0,0,0,0,0,0,0,0,0,0,0,0,0,0,0,0,0,0,0,0,0,0,0,0
15,15,15,15,15,15,15,15,0,0,0,0,0,0,6,6,6,6,6,6,6,6,6,6,6,6,6,6,6,6,17,6,6,6,0,0,0
15,10,15,15,15,10,15,15,0,0,0,0,0,0,9,6,6,6,6,6,6,6,6,6,6,6,0,0,0,0,0,0,0,6,0,0,0
15,15,15,15,15,15,15,15,0,0,0,6,6,6,6,6,6,6,6,6,6,6,6,6,6,0,0,0,0,0,0,0,0,6,0,0,0
15,15,15,15,15,15,15,15,0,0,0,6,6,6,6,6,6,6,6,6,6,6,6,6,6,0,0,0,0,0,0,0,0,6,5,5,5
0,0,0,0,0,0,0,0,0,0,0,6,6,6,6,6,6,6,6,6,6,6,6,6,6,6,16,0,0,0,0,0,14,6,0,6,6
0,0,0,0,0,6,6,6,6,6,6,6,6,6,6,6,6,6,6,6,6,6,6,6,6,0,0,0,0,0,0,0,0,0,6,6,6
11,0,0,0,0,6,6,6,6,6,6,6,6,6,6,6,6,6,6,6,6,6,6,6,6,6,0,0,0,0,0,0,0,6,6,6,6
6,6,6,6,6,6,6,6,6,6,6,6,6,6,6,6,6,6,6,6,6,6,6,6,6,0,0,0,0,0,0,0,0,0,6,6,6
6,6,6,6,6,6,6,6,6,6,3,3,3,6,6,6,6,6,6,6,6,6,6,6,6,0,0,0,0,0,13,0,0,6,6,6,6
6,6,6,6,6,6,6,6,6,6,6,3,3,6,6,6,6,6,6,6,6,6,6,6,6,6,0,6,0,0,6,0,6,6,6,6,6
6,6,6,6,6,6,6,6,6,6,6,3,3,6,6,6,6,6,6,6,6,6,6,6,6,6,6,6,6,6,6,6,6,3,3,6,6
6,6,6,6,6,6,6,6,6,6,6,3,3,6,6,6,6,6,6,6,6,6,3,3,3,6,6,6,6,6,6,6,6,3,3,6,6
6,6,6,6,6,6,6,6,6,6,6,3,3,6,6,6,6,6,6,6,6,6,3,3,3,6,6,6,6,6,6,6,6,3,3,6,6
6,6,6,6,6,6,6,6,6,6,6,3,3,6,6,6,6,6,6,6,6,6,3,3,3,6,6,6,6,6,6,6,6,3,3,6,6
6,6,6,6,6,6,6,6,3,3,3,3,3,6,6,6,6,6,6,6,6,6,3,3,3,6,6,6,6,6,6,6,6,3,3,6,6
6,6,6,6,6,6,6,6,6,6,6,6,6,6,6,6,6,6,6,6,6,6,6,6,6,6,6,6,6,6,6,6,6,6,6,6,6
6,6,6,6,6,6,6,6,6,6,6,6,6,6,6,6,6,6,6,6,6,6,6,6,6,6,6,6,6,6,6,6,6,6,6,6,6
endlayer

layer
15,15,15,15,0,0,0,0,0,0,0,0,0,0,0,0,0,0,0,0,0,0,0,0,0,0,0,0,0,13,0,18,0,0,0,0,0
15,15,15,15,0,15,15,0,0,0,0,0,0,0,22,22,22,22,22,22,22,22,22,22,22,6,6,6,6,6,20,6,6,6,0,0,0
15,10,15,15,15,10,15,0,0,0,0,0,0,0,0,0,0,0,0,0,0,0,0,0,0,6,0,0,0,21,0,19,0,6,0,0,0
15,15,15,15,0,15,15,0,0,0,0,22,22,22,0,0,0,0,0,0,0,0,0,0,0,6,0,0,0,0,0,0,0,6,0,0,0
15,15,15,0,0,0,0,0,0,0,0,22,0,0,0,6,6,6,6,6,6,6,0,0,0,6,0,0,0,0,0,0,0,6,0,0,0
0,0,0,0,0,0,0,0,0,0,0,22,0,0,0,6,23,23,23,23,23,6,0,0,0,6,0,0,0,0,0,0,0,6,5,5,5
0,0,0,0,0,6,6,6,6,6,6,6,6,0,0,6,23,23,23,23,23,6,0,0,0,6,0,0,0,0,0,0,0,6,6,6,6
0,0,0,0,0,6,6,6,6,6,6,6,6,0,0,6,23,23,23,23,23,6,0,0,0,6,0,0,0,0,0,0,0,6,6,6,6
6,6,6,6,6,6,6,6,6,6,6,6,6,0,0,6,23,23,23,23,23,6,0,0,0,6,0,0,0,0,0,0,0,6,6,6,6
6,6,6,6,6,6,6,6,6,6,6,6,6,0,0,6,23,23,23,23,23,6,6,6,5,6,0,0,0,0,0,0,0,6,6,6,6
6,6,6,6,6,6,6,6,6,6,6,6,6,0,0,6,23,23,23,23,23,23,23,6,6,6,6,6,6,6,6,6,6,6,6,6,6
6,6,6,6,6,6,6,6,6,6,6,6,6,5,5,6,23,23,23,23,23,23,23,6,6,6,6,6,6,6,6,6,6,6,6,6,6
6,6,6,6,6,6,6,6,6,6,6,6,6,6,6,6,23,23,23,23,23,23,23,6,6,6,6,6,6,6,6,6,6,6,6,6,6
6,6,6,6,6,6,6,6,6,6,6,6,6,6,6,6,23,23,23,23,23,23,23,6,6,6,6,6,6,6,6,6,6,6,6,6,6
12,12,12,6,6,6,6,6,6,6,6,6,6,6,6,6,6,6,6,6,6,6,6,6,6,6,6,6,6,6,6,6,6,6,6,6,6
0,0,0,0,0,0,9,6,6,6,6,6,6,6,6,6,6,6,6,6,6,6,6,6,6,6,6,6,6,6,6,6,6,6,6,6,6
0,0,0,0,0,0,9,6,6,6,6,6,6,6,6,6,6,6,6,6,6,6,6,6,6,6,6,6,6,6,6,6,6,6,6,6,6
0,0,0,0,0,0,9,6,6,6,6,6,6,6,6,6,6,6,6,6,6,6,6,6,6,6,6,6,6,6,6,6,6,6,6,6,6
endlayer

layer
0,0,0,0,0,0,0,0,0,0,0,0,0,0,0,0,0,0,0,0,0,0,0,0,0,0,0,0,0,0,0,0,0,0,0,0,0
15,15,0,0,0,15,0,0,0,0,0,0,0,0,0,0,0,0,0,0,0,0,0,0,0,22,22,22,22,22,22,22,22,22,0,0,0
15,10,15,0,15,15,15,0,0,0,0,0,0,0,0,0,0,0,0,0,0,0,0,0,0,22,0,0,0,0,0,0,0,22,0,0,0
0,15,0,0,0,15,0,0,0,0,0,0,0,0,0,0,0,0,0,0,0,0,0,0,0,22,0,0,0,0,0,0,0,22,0,0,0
0,0,0,0,0,0,0,0,0,0,0,0,0,0,0,6,6,6,6,6,6,6,0,0,0,22,0,0,0,0,0,0,0,22,0,0,0
0,0,0,0,0,0,0,0,0,0,0,0,0,0,0,6,27,27,27,27,27,6,0,0,0,22,0,0,0,0,0,0,0,22,0,0,0
0,0,0,0,0,22,22,22,22,22,22,22,22,0,0,6,0,0,0,0,0,6,0,0,0,22,0,0,0,0,0,0,0,22,0,0,0
0,0,0,0,0,22,0,0,0,0,0,0,22,0,0,6,0,0,0,0,28,6,0,0,0,22,0,0,0,0,0,0,0,22,0,0,0
22,22,22,22,22,22,0,0,0,0,0,0,22,0,0,6,0,0,0,0,28,6,0,0,0,22,0,0,0,0,0,0,0,22,0,0,0
22,0,0,0,0,0,0,0,0,0,0,0,0,0,0,6,0,27,27,27,27,6,6,6,0,6,0,0,0,0,0,0,0,6,0,0,0
22,0,0,6,6,6,6,30,6,6,6,0,0,0,0,6,0,0,0,0,0,0,27,6,0,26,0,0,0,0,0,0,0,24,0,0,0
22,0,0,6,0,31,23,0,29,29,6,0,0,0,0,6,0,0,0,0,0,0,27,6,0,6,6,6,6,6,6,6,6,6,0,0,0
22,0,0,6,0,0,0,0,0,0,6,0,0,0,0,6,0,0,0,0,0,0,27,6,0,6,0,0,6,11,0,0,6,0,0,0,0
22,0,0,6,0,0,0,0,0,0,6,0,0,0,0,6,27,27,27,27,0,0,27,6,0,6,0,0,0,0,0,0,6,0,0,0,0
0,0,0,6,6,6,6,25,6,6,6,0,0,0,0,6,6,6,6,6,6,25,6,6,0,6,0,0,0,0,0,0,6,0,0,0,0
0,0,0,0,0,0,0,0,0,0,0,0,0,0,0,0,0,0,0,0,0,0,0,0,0,6,6,6,6,25,6,6,6,0,0,0,0
0,0,0,0,0,0,0,0,0,0,0,0,0,0,0,0,0,0,0,0,0,0,0,0,0,0,0,0,0,0,0,0,0,0,0,0,0
0,0,0,0,0,0,0,0,0,0,0,0,0,0,0,0,0,0,0,0,0,0,0,0,0,0,0,0,0,0,0,0,0,0,0,0,0
endlayer

layer
0,0,0,0,0,0,0,0,0,0,0,0,0,0,0,0,0,0,0,0,0,0,0,0,0,0,0,0,0,0,0,0,0,0,0,0,0
0,15,0,0,0,0,0,0,0,0,0,0,0,0,0,0,0,0,0,0,0,0,0,0,0,0,0,0,0,0,0,0,0,0,0,0,0
15,15,15,0,0,0,0,0,0,0,0,0,0,0,0,0,0,0,0,0,0,0,0,0,0,0,0,0,0,0,0,0,0,0,0,0,0
0,15,0,0,0,0,0,0,0,0,0,0,0,0,0,13,0,0,0,0,0,13,0,0,0,0,0,0,0,0,0,0,0,0,0,0,0
0,0,0,0,0,0,0,0,0,0,0,0,0,0,14,6,6,6,6,6,6,6,16,0,0,0,0,0,0,0,0,0,0,0,0,0,0
0,0,0,0,0,0,0,0,0,0,0,0,0,0,0,34,27,27,27,27,27,34,0,0,0,0,0,0,0,0,0,0,0,0,0,0,0
0,0,0,0,0,35,0,0,35,0,0,0,35,0,0,32,0,0,0,0,0,32,0,0,0,0,0,0,0,0,0,0,0,0,0,0,0
0,0,0,0,0,0,0,0,0,0,0,0,0,0,0,32,0,0,0,0,0,32,0,0,0,0,0,0,0,0,0,0,0,0,0,0,0
35,22,0,0,0,0,0,0,0,0,0,0,22,0,0,34,0,0,0,0,0,34,0,13,0,0,0,0,0,0,0,0,0,0,0,0,0
0,0,0,0,0,0,0,0,0,0,0,0,0,0,0,23,0,0,0,0,0,23,23,6,16,6,0,0,0,0,0,0,0,6,0,0,0
0,0,0,6,6,6,6,33,6,6,6,0,0,0,0,34,0,0,0,0,0,0,27,34,0,20,0,0,0,0,0,0,0,20,0,0,0
0,0,0,6,0,0,31,0,0,0,6,0,0,0,0,32,0,0,0,0,0,0,0,32,0,6,6,6,6,32,6,6,6,6,0,0,0
0,0,0,6,0,0,0,0,0,0,32,0,0,0,0,32,0,0,0,0,0,0,0,32,0,6,0,0,11,0,0,0,6,0,0,0,0
35,0,0,6,0,0,0,0,0,0,6,0,0,0,0,34,27,27,35,27,0,0,27,34,0,32,0,0,0,0,0,0,32,0,0,0,0
0,0,0,6,6,6,6,33,6,6,6,0,0,0,0,6,23,34,32,34,23,33,23,6,0,6,0,0,0,0,0,0,6,0,0,0,0
0,0,0,0,0,0,0,0,0,0,0,0,0,0,0,19,0,0,0,0,0,0,0,19,0,6,6,6,6,33,6,6,6,0,0,0,0
0,0,0,0,0,0,0,0,0,0,0,0,0,0,0,0,0,0,0,0,0,0,0,0,0,0,0,0,0,0,0,0,0,0,0,0,0
0,0,0,0,0,0,0,0,0,0,0,0,0,0,0,0,0,0,0,0,0,0,0,0,0,0,0,0,0,0,0,0,0,0,0,0,0
endlayer

layer
0,0,0,0,0,0,0,0,0,0,0,0,0,0,0,0,0,0,0,0,0,0,0,0,0,0,0,0,0,0,0,0,0,0,0,0,0
0,0,0,0,0,0,0,0,0,0,0,0,0,0,0,0,0,0,0,0,0,0,0,0,0,0,0,0,0,0,0,0,0,0,0,0,0
0,0,0,0,0,0,0,0,0,0,0,0,0,0,0,0,0,0,0,0,0,0,0,0,0,0,0,0,0,0,0,0,0,0,0,0,0
0,0,0,0,0,0,0,0,0,0,0,0,0,0,0,0,0,0,0,0,0,0,0,0,0,0,0,0,0,0,0,0,0,0,0,0,0
0,0,0,0,0,0,0,0,0,0,0,0,0,0,0,6,6,6,6,6,6,6,38,0,0,0,0,0,0,0,0,0,0,0,0,0,0
0,0,0,0,0,0,0,0,0,0,0,0,0,0,0,6,27,27,27,27,27,6,38,0,0,0,0,0,0,0,0,0,0,0,0,0,0
0,0,0,0,0,0,0,0,0,0,0,0,0,0,0,6,0,0,0,0,0,6,38,0,0,0,0,0,0,0,0,0,0,0,0,0,0
0,0,0,0,0,0,0,0,0,0,0,0,0,0,0,6,0,0,0,0,0,6,38,0,0,0,0,0,0,0,0,0,0,0,0,0,0
0,22,0,0,0,0,0,0,0,0,0,0,22,0,0,6,0,0,0,0,0,6,23,36,0,0,0,0,0,0,0,0,0,0,0,0,0
0,0,0,13,0,0,0,13,0,0,13,0,0,0,0,6,16,0,0,0,14,23,23,6,0,35,0,0,0,0,0,0,0,35,0,0,0
0,0,14,6,6,6,6,6,6,6,6,16,0,0,0,6,0,0,0,0,0,19,27,6,0,13,0,0,0,0,0,0,13,0,0,0,0
0,0,0,6,0,0,0,39,31,23,6,0,0,0,0,6,0,0,0,0,0,0,27,6,14,6,6,6,6,32,6,6,6,16,0,0,0
0,0,0,6,0,0,0,0,0,0,32,0,0,0,0,6,0,0,0,0,0,0,27,6,0,6,6,11,0,0,19,0,6,0,0,0,0
0,0,0,6,0,0,0,0,13,0,6,0,0,0,0,6,27,27,27,27,0,13,27,6,0,32,0,0,0,0,0,0,32,0,0,0,0
0,0,14,6,6,6,6,6,6,6,6,16,0,0,0,6,23,23,23,23,23,23,23,6,16,6,16,0,0,0,13,0,6,0,0,0,0
0,0,0,19,0,0,12,12,12,0,19,0,0,0,0,37,37,37,37,37,37,37,37,37,14,6,6,6,6,6,6,6,6,16,0,0,0
0,0,0,0,0,0,0,0,0,0,0,0,0,0,0,0,0,0,0,0,0,0,0,0,0,19,0,0,0,0,0,0,19,0,0,0,0
0,0,0,0,0,0,0,0,0,0,0,0,0,0,0,0,0,0,0,0,0,0,0,0,0,0,0,0,0,0,0,0,0,0,0,0,0
endlayer

layer
0,0,0,0,0,0,0,0,0,0,0,0,0,0,0,0,0,0,0,0,0,0,0,0,0,0,0,0,0,0,0,0,0,0,0,0,0
0,0,0,0,0,0,0,0,0,0,0,0,0,0,0,0,0,0,0,0,0,0,0,0,0,0,0,0,0,0,0,0,0,0,0,0,0
0,0,0,0,0,0,0,0,0,0,0,0,0,0,0,0,0,0,0,0,0,0,0,0,0,0,0,0,0,0,0,0,0,0,0,0,0
0,0,0,0,0,0,0,0,0,0,0,0,0,0,0,0,0,0,0,0,0,0,0,0,0,0,0,0,0,0,0,0,0,0,0,0,0
0,0,0,0,0,0,0,0,0,0,0,0,0,0,0,31,23,34,32,34,23,38,0,0,0,0,0,0,0,0,0,0,0,0,0,0,0
0,0,0,0,0,0,0,0,0,0,0,0,0,0,0,31,23,27,0,27,23,38,0,0,0,0,0,0,0,0,0,0,0,0,0,0,0
0,0,0,0,0,0,0,0,0,0,0,0,0,0,0,31,23,0,0,0,23,38,0,0,0,0,0,0,0,0,0,0,0,0,0,0,0
0,0,0,0,0,0,0,0,0,0,0,0,0,0,0,31,23,0,0,0,23,38,0,0,0,0,0,0,0,0,0,0,0,0,0,0,0
0,22,0,0,0,0,0,0,0,0,0,0,22,0,0,31,23,0,0,0,23,38,0,0,0,0,0,0,0,0,0,0,0,0,0,0,0
0,0,0,0,0,0,0,0,0,0,0,0,0,0,0,31,23,0,0,0,23,23,23,23,0,0,0,0,0,0,0,0,0,0,0,0,0
0,0,0,6,6,6,6,6,6,6,6,0,0,0,0,23,23,0,0,0,23,23,23,23,0,0,0,0,0,0,0,0,0,0,0,0,0
0,0,0,6,0,0,0,0,0,31,6,0,0,0,0,23,23,0,0,0,0,0,27,23,0,6,6,6,6,32,6,6,6,0,0,0,0
0,0,0,6,0,0,0,0,0,0,32,0,0,0,0,23,23,16,0,0,0,0,27,23,0,6,11,0,0,0,0,0,6,0,0,0,0
0,0,0,6,0,0,0,0,0,0,6,0,0,0,0,23,23,23,23,23,23,23,23,23,0,32,0,0,0,0,0,0,32,0,0,0,0
0,0,0,6,6,6,6,6,6,6,6,0,0,0,0,37,37,37,37,37,37,37,37,37,0,6,0,0,0,0,0,0,6,0,0,0,0
0,0,0,0,0,0,0,0,0,0,0,0,0,0,0,0,0,0,0,0,0,0,0,0,0,6,6,6,6,6,6,6,6,0,0,0,0
0,0,0,0,0,0,0,0,0,0,0,0,0,0,0,0,0,0,0,0,0,0,0,0,0,0,0,0,0,0,0,0,0,0,0,0,0
0,0,0,0,0,0,0,0,0,0,0,0,0,0,0,0,0,0,0,0,0,0,0,0,0,0,0,0,0,0,0,0,0,0,0,0,0
endlayer

layer
0,0,0,0,0,0,0,0,0,0,0,0,0,0,0,0,0,0,0,0,0,0,0,0,0,0,0,0,0,0,0,0,0,0,0,0,0
0,0,0,0,0,0,0,0,0,0,0,0,0,0,0,0,0,0,0,0,0,0,0,0,0,0,0,0,0,0,0,0,0,0,0,0,0
0,0,0,0,0,0,0,0,0,0,0,0,0,0,0,0,0,0,0,0,0,0,0,0,0,0,0,0,0,0,0,0,0,0,0,0,0
0,0,0,0,0,0,0,0,0,0,0,0,0,0,0,0,0,0,0,0,0,0,0,0,0,0,0,0,0,0,0,0,0,0,0,0,0
0,0,0,0,0,0,0,0,0,0,0,0,0,0,0,0,31,23,23,23,38,0,0,0,0,0,0,0,0,0,0,0,0,0,0,0,0
0,0,0,0,0,0,0,0,0,0,0,0,0,0,0,0,31,23,27,23,38,0,0,0,0,0,0,0,0,0,0,0,0,0,0,0,0
0,0,0,0,0,0,0,0,0,0,0,0,0,0,0,0,31,23,0,23,38,0,0,0,0,0,0,0,0,0,0,0,0,0,0,0,0
0,0,0,0,0,0,0,0,0,0,0,0,0,0,0,0,31,23,0,23,38,0,0,0,0,0,0,0,0,0,0,0,0,0,0,0,0
0,23,23,23,23,23,23,23,23,23,23,23,23,0,0,0,31,23,0,23,38,0,0,0,0,0,0,0,0,0,0,0,0,0,0,0,0
0,23,23,23,23,23,23,23,23,23,23,23,23,0,0,0,31,23,0,23,38,0,23,23,23,23,23,23,23,23,23,23,0,0,0,0,0
0,23,23,6,6,6,6,6,6,6,6,23,23,23,23,23,23,23,23,23,23,23,23,23,23,23,23,23,23,23,23,23,0,0,0,0,0
0,23,23,6,23,23,0,0,0,0,6,23,23,23,23,23,23,23,23,23,23,23,23,23,23,6,6,6,6,6,6,6,6,0,0,0,0
0,23,23,23,23,23,23,23,23,36,6,23,23,23,23,23,23,23,23,23,23,23,23,23,23,6,0,0,0,6,6,6,6,0,0,0,0
0,23,23,6,23,23,23,23,23,23,6,23,23,23,23,23,23,23,23,23,23,23,23,23,23,6,6,6,6,6,6,6,6,0,0,0,0
0,23,23,6,6,6,6,6,6,6,6,23,23,0,0,0,0,0,0,0,0,0,0,0,0,6,6,6,6,6,6,6,6,0,0,0,0
0,23,23,23,23,23,23,23,23,23,23,23,23,0,0,0,0,0,0,0,0,0,0,0,0,6,6,6,6,6,6,6,6,0,0,0,0
0,23,23,23,23,23,23,23,23,23,23,23,23,0,0,0,0,0,0,0,0,0,0,0,0,0,0,0,0,0,0,0,0,0,0,0,0
0,0,0,0,0,0,0,0,0,0,0,0,0,0,0,0,0,0,0,0,0,0,0,0,0,0,0,0,0,0,0,0,0,0,0,0,0
endlayer

layer
0,0,0,0,0,0,0,0,0,0,0,0,0,0,0,0,0,0,0,0,0,0,0,0,0,0,0,0,0,0,0,0,0,0,0,0,0
0,0,0,0,0,0,0,0,0,0,0,0,0,0,0,0,0,0,0,0,0,0,0,0,0,0,0,0,0,0,0,0,0,0,0,0,0
0,0,0,0,0,0,0,0,0,0,0,0,0,0,0,0,0,0,0,0,0,0,0,0,0,0,0,0,0,0,0,0,0,0,0,0,0
0,0,0,0,0,0,0,0,0,0,0,0,0,0,0,0,0,0,0,0,0,0,0,0,0,0,0,0,0,0,0,0,0,0,0,0,0
0,0,0,0,0,0,0,0,0,0,0,0,0,0,0,0,0,31,23,38,0,0,0,0,0,0,0,0,0,0,0,0,0,0,0,0,0
0,0,0,0,0,0,0,0,0,0,0,0,0,0,0,0,0,31,23,38,0,0,0,0,0,0,0,0,0,0,0,0,0,0,0,0,0
0,0,0,0,0,0,0,0,0,0,0,0,0,0,0,0,0,31,23,38,0,0,0,0,0,0,0,0,0,0,0,0,0,0,0,0,0
0,0,0,0,0,0,0,0,0,0,0,0,0,0,0,0,0,31,23,38,0,0,0,0,0,0,0,0,0,0,0,0,0,0,0,0,0
0,22,22,22,22,22,22,22,22,22,22,22,22,0,0,0,0,31,23,38,0,0,0,0,0,0,0,0,0,0,0,0,0,0,0,0,0
0,22,0,0,0,0,0,0,0,0,0,0,22,0,0,0,0,31,23,38,0,0,22,22,22,22,22,22,22,22,22,22,0,0,0,0,0
0,22,0,6,6,6,6,6,6,6,6,0,22,22,22,22,22,22,37,22,22,22,22,0,0,0,0,0,0,0,0,22,13,0,0,0,0
0,22,0,6,0,0,0,0,0,0,6,0,0,0,0,0,0,0,0,0,0,0,0,0,14,6,6,6,6,30,6,6,6,16,0,0,0
0,22,0,40,0,0,0,0,0,0,6,0,0,0,0,0,0,0,0,0,0,0,0,0,0,6,0,0,0,0,0,0,6,0,0,0,0
0,22,0,6,0,0,0,0,0,0,6,0,22,22,22,22,22,22,22,22,22,22,22,22,22,6,0,0,0,0,0,0,6,0,0,0,0
0,22,0,6,6,6,6,6,6,6,6,0,22,0,0,0,0,0,0,0,0,0,0,0,0,6,0,0,0,0,0,0,6,0,0,0,0
0,22,0,0,0,0,0,0,0,0,0,0,22,0,0,0,0,0,0,0,0,0,0,0,14,6,6,6,6,6,6,6,6,16,0,0,0
0,22,22,22,22,22,22,22,22,22,22,22,22,0,0,0,0,0,0,0,0,0,0,0,0,19,0,0,0,0,0,0,19,0,0,0,0
0,0,0,0,0,0,0,0,0,0,0,0,0,0,0,0,0,0,0,0,0,0,0,0,0,0,0,0,0,0,0,0,0,0,0,0,0
endlayer

layer
0,0,0,0,0,0,0,0,0,0,0,0,0,0,0,0,0,0,0,0,0,0,0,0,0,0,0,0,0,0,0,0,0,0,0,0,0
0,0,0,0,0,0,0,0,0,0,0,0,0,0,0,0,0,0,0,0,0,0,0,0,0,0,0,0,0,0,0,0,0,0,0,0,0
0,0,0,0,0,0,0,0,0,0,0,0,0,0,0,0,0,0,0,0,0,0,0,0,0,0,0,0,0,0,0,0,0,0,0,0,0
0,0,0,0,0,0,0,0,0,0,0,0,0,0,0,0,0,0,0,0,0,0,0,0,0,0,0,0,0,0,0,0,0,0,0,0,0
0,0,0,0,0,0,0,0,0,0,0,0,0,0,0,0,0,0,35,0,0,0,0,0,0,0,0,0,0,0,0,0,0,0,0,0,0
0,0,0,0,0,0,0,0,0,0,0,0,0,0,0,0,0,0,0,0,0,0,0,0,0,0,0,0,0,0,0,0,0,0,0,0,0
0,0,0,0,0,0,0,0,0,0,0,0,0,0,0,0,0,0,0,0,0,0,0,0,0,0,0,0,0,0,0,0,0,0,0,0,0
0,0,0,0,0,0,0,0,0,0,0,0,0,0,0,0,0,0,0,0,0,0,0,0,0,0,0,0,0,0,0,0,0,0,0,0,0
0,35,0,0,0,0,0,0,0,0,0,0,35,0,0,0,0,0,0,0,0,0,0,0,0,0,0,0,0,0,0,0,0,0,0,0,0
0,0,0,0,0,0,0,0,0,0,0,0,0,0,0,0,0,0,0,0,0,0,0,0,35,0,0,0,0,0,0,35,0,0,0,0,0
0,0,0,6,6,6,6,32,6,6,6,0,0,0,0,0,0,0,0,0,0,0,0,0,0,0,0,0,0,0,0,0,0,0,0,0,0
0,0,0,6,0,0,0,0,0,0,6,0,0,0,0,0,0,0,0,0,0,0,0,0,0,6,23,23,23,33,23,23,6,0,0,0,0
0,0,0,33,0,0,0,0,0,0,32,0,0,0,0,0,0,0,0,0,0,0,0,0,0,6,0,0,0,0,0,0,6,0,0,0,0
0,0,0,6,0,0,0,0,0,0,6,0,0,0,0,0,0,0,0,0,0,0,0,0,0,6,0,0,0,0,0,0,6,0,0,0,0
0,0,0,6,6,6,6,32,6,6,6,0,0,0,0,0,0,0,0,0,0,0,0,0,0,6,0,0,0,0,0,0,6,0,0,0,0
0,0,0,0,0,0,0,0,0,0,0,0,0,0,0,0,0,0,0,0,0,0,0,0,0,6,23,23,23,23,23,23,6,0,0,0,0
0,35,0,0,0,0,0,0,0,0,0,0,35,0,0,0,0,0,0,0,0,0,0,0,0,37,37,37,37,37,37,37,37,0,0,0,0
0,0,0,0,0,0,0,0,0,0,0,0,0,0,0,0,0,0,0,0,0,0,0,0,0,0,0,0,0,0,0,0,0,0,0,0,0
endlayer

layer
0,0,0,0,0,0,0,0,0,0,0,0,0,0,0,0,0,0,0,0,0,0,0,0,0,0,0,0,0,0,0,0,0,0,0,0,0
0,0,0,0,0,0,0,0,0,0,0,0,0,0,0,0,0,0,0,0,0,0,0,0,0,0,0,0,0,0,0,0,0,0,0,0,0
0,0,0,0,0,0,0,0,0,0,0,0,0,0,0,0,0,0,0,0,0,0,0,0,0,0,0,0,0,0,0,0,0,0,0,0,0
0,0,0,0,0,0,0,0,0,0,0,0,0,0,0,0,0,0,0,0,0,0,0,0,0,0,0,0,0,0,0,0,0,0,0,0,0
0,0,0,0,0,0,0,0,0,0,0,0,0,0,0,0,0,0,0,0,0,0,0,0,0,0,0,0,0,0,0,0,0,0,0,0,0
0,0,0,0,0,0,0,0,0,0,0,0,0,0,0,0,0,0,0,0,0,0,0,0,0,0,0,0,0,0,0,0,0,0,0,0,0
0,0,0,0,0,0,0,0,0,0,0,0,0,0,0,0,0,0,0,0,0,0,0,0,0,0,0,0,0,0,0,0,0,0,0,0,0
0,0,0,0,0,0,0,0,0,0,0,0,0,0,0,0,0,0,0,0,0,0,0,0,0,0,0,0,0,0,0,0,0,0,0,0,0
0,0,0,0,0,0,0,0,0,0,0,0,0,0,0,0,0,0,0,0,0,0,0,0,0,0,0,0,0,0,0,0,0,0,0,0,0
0,0,0,13,0,0,0,0,0,0,13,0,0,0,0,0,0,0,0,0,0,0,0,0,0,0,0,0,0,0,0,0,0,0,0,0,0
0,0,14,6,6,6,6,32,6,6,6,16,0,0,0,0,0,0,0,0,0,0,0,0,0,0,0,0,0,0,0,0,0,0,0,0,0
0,0,0,6,0,0,0,0,19,0,6,0,0,0,0,0,0,0,0,0,0,0,0,0,0,36,36,36,36,36,36,36,36,0,0,0,0
0,0,0,6,16,0,0,0,0,0,32,0,0,0,0,0,0,0,0,0,0,0,0,0,0,6,23,23,23,23,23,23,6,0,0,0,0
0,0,0,6,0,0,0,0,13,0,6,0,0,0,0,0,0,0,0,0,0,0,0,0,14,6,16,0,0,0,0,14,6,16,0,0,0
0,0,14,6,6,6,6,32,6,6,6,16,0,0,0,0,0,0,0,0,0,0,0,0,0,6,23,23,23,23,23,23,6,0,0,0,0
0,0,0,19,0,0,0,0,0,0,19,0,0,0,0,0,0,0,0,0,0,0,0,0,0,37,37,37,37,37,37,37,37,0,0,0,0
0,0,0,0,0,0,0,0,0,0,0,0,0,0,0,0,0,0,0,0,0,0,0,0,0,0,0,0,0,0,0,0,0,0,0,0,0
0,0,0,0,0,0,0,0,0,0,0,0,0,0,0,0,0,0,0,0,0,0,0,0,0,0,0,0,0,0,0,0,0,0,0,0,0
endlayer

layer
0,0,0,0,0,0,0,0,0,0,0,0,0,0,0,0,0,0,0,0,0,0,0,0,0,0,0,0,0,0,0,0,0,0,0,0,0
0,0,0,0,0,0,0,0,0,0,0,0,0,0,0,0,0,0,0,0,0,0,0,0,0,0,0,0,0,0,0,0,0,0,0,0,0
0,0,0,0,0,0,0,0,0,0,0,0,0,0,0,0,0,0,0,0,0,0,0,0,0,0,0,0,0,0,0,0,0,0,0,0,0
0,0,0,0,0,0,0,0,0,0,0,0,0,0,0,0,0,0,0,0,0,0,0,0,0,0,0,0,0,0,0,0,0,0,0,0,0
0,0,0,0,0,0,0,0,0,0,0,0,0,0,0,0,0,0,0,0,0,0,0,0,0,0,0,0,0,0,0,0,0,0,0,0,0
0,0,0,0,0,0,0,0,0,0,0,0,0,0,0,0,0,0,0,0,0,0,0,0,0,0,0,0,0,0,0,0,0,0,0,0,0
0,0,0,0,0,0,0,0,0,0,0,0,0,0,0,0,0,0,0,0,0,0,0,0,0,0,0,0,0,0,0,0,0,0,0,0,0
0,0,0,0,0,0,0,0,0,0,0,0,0,0,0,0,0,0,0,0,0,0,0,0,0,0,0,0,0,0,0,0,0,0,0,0,0
0,0,0,0,0,0,0,0,0,0,0,0,0,0,0,0,0,0,0,0,0,0,0,0,0,0,0,0,0,0,0,0,0,0,0,0,0
0,0,0,36,36,36,36,36,36,36,36,0,0,0,0,0,0,0,0,0,0,0,0,0,0,0,0,0,0,0,0,0,0,0,0,0,0
0,0,0,6,23,23,23,23,23,23,6,0,0,0,0,0,0,0,0,0,0,0,0,0,0,0,0,0,0,0,0,0,0,0,0,0,0
0,0,0,6,0,0,0,0,0,0,6,0,0,0,0,0,0,0,0,0,0,0,0,0,0,0,0,0,0,0,0,0,0,0,0,0,0
0,0,0,6,0,0,0,0,0,0,6,0,0,0,0,0,0,0,0,0,0,0,0,0,0,36,36,36,36,36,36,36,36,0,0,0,0
0,0,0,6,0,0,0,0,0,0,6,0,0,0,0,0,0,0,0,0,0,0,0,0,0,23,23,23,23,23,23,23,23,0,0,0,0
0,0,0,6,23,23,23,23,23,23,6,0,0,0,0,0,0,0,0,0,0,0,0,0,0,37,37,37,37,37,37,37,37,0,0,0,0
0,0,0,37,37,37,37,37,37,37,37,0,0,0,0,0,0,0,0,0,0,0,0,0,0,0,0,0,0,0,0,0,0,0,0,0,0
0,0,0,0,0,0,0,0,0,0,0,0,0,0,0,0,0,0,0,0,0,0,0,0,0,0,0,0,0,0,0,0,0,0,0,0,0
0,0,0,0,0,0,0,0,0,0,0,0,0,0,0,0,0,0,0,0,0,0,0,0,0,0,0,0,0,0,0,0,0,0,0,0,0
endlayer

layer
0,0,0,0,0,0,0,0,0,0,0,0,0,0,0,0,0,0,0,0,0,0,0,0,0,0,0,0,0,0,0,0,0,0,0,0,0
0,0,0,0,0,0,0,0,0,0,0,0,0,0,0,0,0,0,0,0,0,0,0,0,0,0,0,0,0,0,0,0,0,0,0,0,0
0,0,0,0,0,0,0,0,0,0,0,0,0,0,0,0,0,0,0,0,0,0,0,0,0,0,0,0,0,0,0,0,0,0,0,0,0
0,0,0,0,0,0,0,0,0,0,0,0,0,0,0,0,0,0,0,0,0,0,0,0,0,0,0,0,0,0,0,0,0,0,0,0,0
0,0,0,0,0,0,0,0,0,0,0,0,0,0,0,0,0,0,0,0,0,0,0,0,0,0,0,0,0,0,0,0,0,0,0,0,0
0,0,0,0,0,0,0,0,0,0,0,0,0,0,0,0,0,0,0,0,0,0,0,0,0,0,0,0,0,0,0,0,0,0,0,0,0
0,0,0,0,0,0,0,0,0,0,0,0,0,0,0,0,0,0,0,0,0,0,0,0,0,0,0,0,0,0,0,0,0,0,0,0,0
0,0,0,0,0,0,0,0,0,0,0,0,0,0,0,0,0,0,0,0,0,0,0,0,0,0,0,0,0,0,0,0,0,0,0,0,0
0,0,0,0,0,0,0,0,0,0,0,0,0,0,0,0,0,0,0,0,0,0,0,0,0,0,0,0,0,0,0,0,0,0,0,0,0
0,0,0,0,0,0,0,0,0,0,0,0,0,0,0,0,0,0,0,0,0,0,0,0,0,0,0,0,0,0,0,0,0,0,0,0,0
0,0,0,36,36,36,36,36,36,36,36,0,0,0,0,0,0,0,0,0,0,0,0,0,0,0,0,0,0,0,0,0,0,0,0,0,0
0,0,0,6,23,23,23,23,23,23,6,0,0,0,0,0,0,0,0,0,0,0,0,0,0,0,0,0,0,0,0,0,0,0,0,0,0
0,0,14,6,0,0,0,0,0,0,6,16,0,0,0,0,0,0,0,0,0,0,0,0,0,0,0,0,0,0,0,0,0,0,0,0,0
0,0,0,6,23,23,23,23,23,23,6,0,0,0,0,0,0,0,0,0,0,0,0,0,0,35,0,0,0,0,0,0,35,0,0,0,0
0,0,0,37,37,37,37,37,37,37,37,0,0,0,0,0,0,0,0,0,0,0,0,0,0,0,0,0,0,0,0,0,0,0,0,0,0
0,0,0,0,0,0,0,0,0,0,0,0,0,0,0,0,0,0,0,0,0,0,0,0,0,0,0,0,0,0,0,0,0,0,0,0,0
0,0,0,0,0,0,0,0,0,0,0,0,0,0,0,0,0,0,0,0,0,0,0,0,0,0,0,0,0,0,0,0,0,0,0,0,0
0,0,0,0,0,0,0,0,0,0,0,0,0,0,0,0,0,0,0,0,0,0,0,0,0,0,0,0,0,0,0,0,0,0,0,0,0
endlayer

layer
0,0,0,0,0,0,0,0,0,0,0,0,0,0,0,0,0,0,0,0,0,0,0,0,0,0,0,0,0,0,0,0,0,0,0,0,0
0,0,0,0,0,0,0,0,0,0,0,0,0,0,0,0,0,0,0,0,0,0,0,0,0,0,0,0,0,0,0,0,0,0,0,0,0
0,0,0,0,0,0,0,0,0,0,0,0,0,0,0,0,0,0,0,0,0,0,0,0,0,0,0,0,0,0,0,0,0,0,0,0,0
0,0,0,0,0,0,0,0,0,0,0,0,0,0,0,0,0,0,0,0,0,0,0,0,0,0,0,0,0,0,0,0,0,0,0,0,0
0,0,0,0,0,0,0,0,0,0,0,0,0,0,0,0,0,0,0,0,0,0,0,0,0,0,0,0,0,0,0,0,0,0,0,0,0
0,0,0,0,0,0,0,0,0,0,0,0,0,0,0,0,0,0,0,0,0,0,0,0,0,0,0,0,0,0,0,0,0,0,0,0,0
0,0,0,0,0,0,0,0,0,0,0,0,0,0,0,0,0,0,0,0,0,0,0,0,0,0,0,0,0,0,0,0,0,0,0,0,0
0,0,0,0,0,0,0,0,0,0,0,0,0,0,0,0,0,0,0,0,0,0,0,0,0,0,0,0,0,0,0,0,0,0,0,0,0
0,0,0,0,0,0,0,0,0,0,0,0,0,0,0,0,0,0,0,0,0,0,0,0,0,0,0,0,0,0,0,0,0,0,0,0,0
0,0,0,0,0,0,0,0,0,0,0,0,0,0,0,0,0,0,0,0,0,0,0,0,0,0,0,0,0,0,0,0,0,0,0,0,0
0,0,0,0,0,0,0,0,0,0,0,0,0,0,0,0,0,0,0,0,0,0,0,0,0,0,0,0,0,0,0,0,0,0,0,0,0
0,0,0,36,36,36,36,36,36,36,36,0,0,0,0,0,0,0,0,0,0,0,0,0,0,0,0,0,0,0,0,0,0,0,0,0,0
0,0,0,23,23,23,23,23,23,23,23,0,0,0,0,0,0,0,0,0,0,0,0,0,0,0,0,0,0,0,0,0,0,0,0,0,0
0,0,0,37,37,37,37,37,37,37,37,0,0,0,0,0,0,0,0,0,0,0,0,0,0,0,0,0,0,0,0,0,0,0,0,0,0
0,0,0,0,0,0,0,0,0,0,0,0,0,0,0,0,0,0,0,0,0,0,0,0,0,0,0,0,0,0,0,0,0,0,0,0,0
0,0,0,0,0,0,0,0,0,0,0,0,0,0,0,0,0,0,0,0,0,0,0,0,0,0,0,0,0,0,0,0,0,0,0,0,0
0,0,0,0,0,0,0,0,0,0,0,0,0,0,0,0,0,0,0,0,0,0,0,0,0,0,0,0,0,0,0,0,0,0,0,0,0
0,0,0,0,0,0,0,0,0,0,0,0,0,0,0,0,0,0,0,0,0,0,0,0,0,0,0,0,0,0,0,0,0,0,0,0,0
endlayer

layer
0,0,0,0,0,0,0,0,0,0,0,0,0,0,0,0,0,0,0,0,0,0,0,0,0,0,0,0,0,0,0,0,0,0,0,0,0
0,0,0,0,0,0,0,0,0,0,0,0,0,0,0,0,0,0,0,0,0,0,0,0,0,0,0,0,0,0,0,0,0,0,0,0,0
0,0,0,0,0,0,0,0,0,0,0,0,0,0,0,0,0,0,0,0,0,0,0,0,0,0,0,0,0,0,0,0,0,0,0,0,0
0,0,0,0,0,0,0,0,0,0,0,0,0,0,0,0,0,0,0,0,0,0,0,0,0,0,0,0,0,0,0,0,0,0,0,0,0
0,0,0,0,0,0,0,0,0,0,0,0,0,0,0,0,0,0,0,0,0,0,0,0,0,0,0,0,0,0,0,0,0,0,0,0,0
0,0,0,0,0,0,0,0,0,0,0,0,0,0,0,0,0,0,0,0,0,0,0,0,0,0,0,0,0,0,0,0,0,0,0,0,0
0,0,0,0,0,0,0,0,0,0,0,0,0,0,0,0,0,0,0,0,0,0,0,0,0,0,0,0,0,0,0,0,0,0,0,0,0
0,0,0,0,0,0,0,0,0,0,0,0,0,0,0,0,0,0,0,0,0,0,0,0,0,0,0,0,0,0,0,0,0,0,0,0,0
0,0,0,0,0,0,0,0,0,0,0,0,0,0,0,0,0,0,0,0,0,0,0,0,0,0,0,0,0,0,0,0,0,0,0,0,0
0,0,0,0,0,0,0,0,0,0,0,0,0,0,0,0,0,0,0,0,0,0,0,0,0,0,0,0,0,0,0,0,0,0,0,0,0
0,0,0,0,0,0,0,0,0,0,0,0,0,0,0,0,0,0,0,0,0,0,0,0,0,0,0,0,0,0,0,0,0,0,0,0,0
0,0,0,0,0,0,0,0,0,0,0,0,0,0,0,0,0,0,0,0,0,0,0,0,0,0,0,0,0,0,0,0,0,0,0,0,0
0,0,0,35,0,0,0,0,0,0,35,0,0,0,0,0,0,0,0,0,0,0,0,0,0,0,0,0,0,0,0,0,0,0,0,0,0
0,0,0,0,0,0,0,0,0,0,0,0,0,0,0,0,0,0,0,0,0,0,0,0,0,0,0,0,0,0,0,0,0,0,0,0,0
0,0,0,0,0,0,0,0,0,0,0,0,0,0,0,0,0,0,0,0,0,0,0,0,0,0,0,0,0,0,0,0,0,0,0,0,0
0,0,0,0,0,0,0,0,0,0,0,0,0,0,0,0,0,0,0,0,0,0,0,0,0,0,0,0,0,0,0,0,0,0,0,0,0
0,0,0,0,0,0,0,0,0,0,0,0,0,0,0,0,0,0,0,0,0,0,0,0,0,0,0,0,0,0,0,0,0,0,0,0,0
0,0,0,0,0,0,0,0,0,0,0,0,0,0,0,0,0,0,0,0,0,0,0,0,0,0,0,0,0,0,0,0,0,0,0,0,0
endlayer

