# Converted from schematic
# author:MohawkyMagoo

weight=10
embed_into_distance=4
#acceptable_target_blocks=1,2,3,12,13
dimensions=9,36,29
#allowable_overhang=0
max_cut_in=2
#cut_in_buffer=1
max_leveling=2
#leveling_buffer=1
#preserve_water=0
#preserve_lava=0
#preserve_plants=0


rule1=0,100,4
rule2=0,100,3
rule3=0,100,1
rule4=0,100,2
rule5=0,100,85
rule6=0,100,98
rule7=0,100,35
rule8=0,100,54-2
rule9=0,100,35-4
rule10=0,100,109-2
rule11=0,100,64-1
rule12=0,100,54-5
rule13=0,100,35-3
rule14=0,100,54-4
rule15=0,100,109-1
rule16=0,100,54-3
rule17=0,100,96-8
rule18=0,100,9
rule19=0,100,109-3
rule20=0,100,5
rule21=0,100,109-0
rule22=0,100,64
rule23=0,100,47
rule24=0,100,35-14
rule25=0,100,35-2
rule26=0,100,43-3
rule27=0,100,53-1
rule28=0,100,97-1
rule29=0,100,5-3
rule30=0,100,64-8
rule31=0,100,20
rule32=0,100,102
rule33=0,100,91-3
rule34=0,100,64-0
rule35=0,100,64-2
rule36=0,100,61-3
rule37=0,100,61-2
rule38=0,100,58
rule39=0,100,50-1
rule40=0,100,50-4
rule41=0,100,50-3
rule42=0,100,50-2
rule43=0,100,53-2
rule44=0,100,35-11
rule45=0,100,53-3
rule46=0,100,53-0
rule47=0,100,53-6
rule48=0,100,53-5
rule49=0,100,53-4
rule50=0,100,50-5
rule51=0,100,5-1


layer
1,1,1,1,1,1,1,1,1,1,1,1,1,1,1,1,1,1,1,1,1,1,1,1,1,1,1,1,1
1,1,1,1,1,1,1,1,1,1,1,1,1,1,1,1,1,1,1,1,1,1,1,1,1,1,1,1,1
1,1,1,1,1,1,1,1,1,1,1,1,1,1,1,1,1,3,3,3,3,3,3,3,3,3,1,1,1
1,1,1,1,1,1,1,1,1,1,1,1,1,1,1,1,1,3,3,3,3,3,3,3,3,3,1,1,1
1,1,1,1,1,1,1,1,1,1,1,1,1,1,1,1,1,3,3,3,3,1,3,3,3,3,1,1,1
1,1,1,1,1,1,1,1,1,1,1,1,1,1,1,1,1,3,3,3,3,3,3,3,1,3,1,1,1
2,2,2,2,2,2,3,1,1,1,1,1,3,1,1,1,1,1,1,1,1,1,1,1,1,1,1,1,1
2,2,2,2,2,2,2,1,1,1,1,1,1,1,1,1,1,1,1,1,1,1,1,1,1,1,1,1,1
2,2,2,2,2,2,2,1,1,1,1,1,1,1,1,3,3,3,3,1,1,1,1,1,1,1,1,1,1
2,2,2,2,2,2,2,4,1,1,1,1,1,1,1,1,3,3,1,1,1,1,1,1,1,1,1,1,1
2,2,2,2,2,2,2,1,1,1,1,2,1,1,1,1,1,1,1,1,1,1,1,1,1,1,1,1,1
2,2,2,2,2,2,2,1,1,1,1,2,3,1,1,1,1,1,1,1,1,1,1,1,1,1,1,1,1
2,2,2,2,2,2,2,1,1,1,1,2,3,1,1,1,1,1,1,1,1,1,1,1,1,1,1,1,1
1,1,1,1,1,1,1,1,1,1,1,2,1,1,1,1,1,1,1,1,1,1,1,1,1,1,1,1,1
1,1,1,1,1,1,1,1,1,1,1,1,1,1,1,1,1,1,1,1,1,1,1,1,1,1,1,1,1
1,1,1,2,2,2,2,2,2,2,2,1,1,1,1,2,1,1,1,1,1,1,1,1,1,1,1,1,1
1,1,1,2,2,2,2,2,2,2,2,1,1,1,1,2,2,1,1,1,1,1,1,1,1,1,1,1,1
1,1,1,2,2,2,2,2,2,2,2,1,1,1,1,3,3,1,1,1,1,1,1,1,1,1,1,1,1
1,1,1,2,2,2,2,2,2,2,2,1,1,1,1,3,1,1,1,1,1,1,1,1,1,1,1,1,1
1,1,1,2,2,2,2,2,2,2,2,1,1,1,1,1,1,1,1,1,1,1,1,1,1,1,1,1,1
1,1,1,2,2,2,2,2,2,2,2,1,1,1,1,1,1,1,1,1,1,1,1,1,1,1,1,1,1
1,1,1,4,2,2,2,2,2,2,4,1,1,1,1,1,3,3,1,1,1,1,1,1,1,1,1,1,1
1,1,1,4,2,2,2,2,2,2,4,1,1,1,1,3,3,3,3,1,1,1,1,0,1,1,1,1,1
1,1,1,2,2,2,2,2,2,2,2,1,1,1,1,1,1,1,1,1,1,1,1,1,1,1,1,1,1
1,1,1,2,2,2,2,2,2,2,2,1,1,1,1,1,1,1,1,1,1,1,1,1,1,1,1,1,1
1,1,1,2,2,2,2,2,2,2,2,1,1,1,1,1,1,1,1,1,1,1,1,1,1,1,1,1,1
1,1,1,2,2,2,2,2,2,2,2,1,1,1,1,1,1,1,1,1,1,1,1,1,1,1,1,1,1
1,1,1,2,2,2,2,2,2,2,2,1,1,1,1,1,1,1,1,1,1,1,1,1,1,1,1,1,1
1,1,1,2,2,2,2,2,2,2,2,1,1,1,1,1,1,1,1,1,1,1,1,1,1,1,1,1,1
1,1,1,2,2,2,2,2,2,2,2,1,1,1,1,1,1,1,1,1,1,1,1,1,1,1,1,1,1
1,1,1,2,2,2,2,2,2,2,2,1,1,1,1,1,1,1,1,1,1,1,1,3,3,3,2,1,1
1,1,1,2,2,2,2,2,2,2,2,1,1,1,1,1,1,1,1,1,1,1,1,3,2,2,2,1,1
1,1,1,2,2,2,2,2,2,2,1,1,1,1,1,1,1,1,1,1,1,1,1,2,2,2,2,1,1
1,1,1,2,2,2,2,2,2,2,2,1,1,1,1,1,1,1,1,1,1,1,1,2,2,2,2,1,1
1,1,1,1,1,1,1,1,1,1,1,1,1,1,1,1,1,1,1,1,1,1,1,1,1,1,1,1,1
1,1,1,1,1,1,1,1,1,1,1,1,1,1,1,1,1,1,1,1,1,1,1,1,1,1,1,1,1
endlayer

layer
0,0,0,0,0,0,0,0,0,0,0,0,0,0,0,0,0,0,0,0,0,0,0,0,0,0,0,0,0
0,0,0,0,0,0,0,0,0,0,0,0,0,0,0,0,0,6,6,6,6,6,6,6,6,6,6,0,0
6,6,6,6,6,6,6,0,0,0,0,0,0,0,0,0,0,6,23,0,0,0,12,12,0,0,6,0,0
6,6,6,6,6,6,6,0,0,0,0,0,0,0,0,0,0,6,8,0,0,0,0,0,0,0,6,0,0
6,6,6,6,6,6,6,0,0,0,0,0,0,0,0,0,0,6,8,0,0,17,0,0,0,0,6,0,0
6,6,6,6,6,6,6,0,0,0,0,0,0,0,0,0,0,6,6,6,6,6,6,6,11,6,6,0,0
26,6,6,6,6,6,6,0,0,0,0,0,6,0,0,0,0,0,0,0,0,0,0,0,0,0,0,0,0
6,6,6,6,6,6,6,0,0,0,0,0,0,0,0,5,0,0,5,0,5,0,0,5,0,0,0,0,0
28,6,6,6,6,6,6,0,0,0,0,0,0,0,0,13,13,14,13,0,9,9,14,9,0,0,0,0,0
26,6,6,6,6,6,6,27,0,0,0,0,0,0,0,5,13,13,5,0,5,9,9,5,0,0,0,0,0
26,6,6,6,6,6,6,0,0,0,5,25,5,0,0,0,0,0,0,0,0,0,0,0,0,0,0,0,0
26,6,6,6,6,6,26,0,0,0,0,16,25,0,0,0,0,0,0,0,0,0,0,0,0,5,7,5,0
6,6,6,6,6,6,26,0,0,0,0,25,25,0,0,0,0,0,0,0,0,0,0,0,0,7,7,0,0
0,0,0,0,0,0,0,0,0,0,5,25,5,0,0,0,0,0,0,6,10,10,6,0,0,7,8,0,0
0,0,0,0,0,0,0,0,0,0,0,0,0,0,0,0,0,0,0,21,18,18,15,0,0,5,7,5,0
0,0,0,6,6,6,6,6,6,6,6,0,0,0,5,9,5,0,0,21,18,18,15,0,0,0,0,0,0
0,0,0,6,6,6,6,6,6,6,6,0,0,0,0,16,9,0,0,6,19,19,6,0,0,0,0,0,0
0,0,0,28,6,6,6,6,6,6,6,15,0,0,0,9,9,0,0,0,0,0,0,0,0,5,9,5,0
0,0,0,6,6,6,6,6,6,6,6,15,0,0,5,9,5,0,0,0,0,0,0,0,0,9,9,0,0
0,0,0,6,6,6,6,6,6,6,6,0,0,0,0,0,0,0,0,0,0,0,0,0,0,9,8,0,0
0,0,0,6,6,6,6,6,6,6,6,0,0,0,0,0,0,0,0,0,0,0,0,0,0,5,9,5,0
0,0,0,21,6,6,6,6,6,6,15,0,0,0,0,5,24,24,5,0,5,13,13,5,0,0,0,0,0
0,0,0,21,6,6,6,6,6,6,15,0,0,0,0,24,12,24,24,0,13,12,13,13,0,0,0,0,0
0,0,0,6,6,6,6,6,6,6,6,0,0,0,0,5,0,0,5,0,5,0,0,5,0,0,0,0,0
0,0,0,6,6,6,0,6,6,6,6,0,0,0,0,0,0,0,0,0,0,0,0,0,0,0,0,0,0
0,0,0,6,6,6,6,6,6,6,6,0,0,0,0,0,0,0,0,0,0,0,0,0,0,0,0,0,0
0,0,0,6,6,6,6,6,6,6,6,15,0,0,0,0,0,0,0,0,0,0,0,0,0,0,0,0,0
0,0,0,6,6,6,6,6,6,6,6,0,0,0,0,0,0,0,0,0,0,0,0,0,0,0,0,0,0
0,0,0,6,6,6,6,6,6,6,6,0,0,0,0,0,0,0,0,0,0,0,0,0,0,0,0,0,0
0,0,21,6,6,6,6,6,6,6,6,0,0,0,0,0,0,0,0,0,0,0,0,0,0,10,0,0,0
0,0,0,6,6,6,6,6,6,6,6,15,0,0,0,6,6,6,6,22,6,6,6,6,6,6,6,6,0
0,0,0,6,6,6,6,6,6,6,6,0,0,0,0,6,0,0,0,0,20,12,12,6,6,6,6,6,0
0,0,0,6,6,6,6,6,6,6,6,0,0,0,0,6,0,0,0,0,20,0,0,6,6,6,6,6,0
0,0,0,6,6,6,6,6,6,6,26,0,0,0,0,6,0,0,0,0,0,0,16,6,6,6,6,6,0
0,0,0,0,0,0,0,0,0,0,0,0,0,0,0,6,6,6,6,6,6,6,6,6,6,6,6,6,0
0,0,0,0,0,0,0,0,0,0,0,0,0,0,0,0,0,0,0,0,0,0,0,0,0,0,0,0,0
endlayer

layer
0,0,0,0,0,0,0,0,0,0,0,0,0,0,0,0,0,0,0,0,0,0,0,0,0,0,0,0,0
0,0,0,0,0,0,0,0,0,0,0,0,0,0,0,0,0,6,6,6,6,6,6,6,6,6,6,0,0
6,6,6,6,6,6,6,0,0,0,0,0,0,0,0,0,0,6,23,0,0,0,0,0,0,0,6,0,0
20,0,0,0,0,0,20,0,0,0,0,0,0,0,0,0,0,6,0,0,0,0,0,0,0,0,6,0,0
20,0,0,0,0,0,20,0,0,0,0,0,0,0,0,0,0,6,0,0,0,0,0,0,0,0,6,0,0
20,0,0,0,0,0,20,0,0,0,0,0,0,0,0,0,0,6,6,31,6,31,6,6,30,6,6,0,0
20,20,20,20,0,0,20,0,0,0,0,0,33,0,0,0,0,0,0,0,0,0,0,0,0,0,0,0,0
20,12,12,20,0,16,20,0,0,0,0,0,0,0,0,5,0,0,5,0,5,0,0,5,0,0,0,0,0
20,0,0,20,0,0,20,0,0,0,0,0,0,0,0,0,0,0,0,0,0,0,0,0,0,0,0,0,0
20,0,0,20,0,0,34,0,0,0,0,0,0,0,0,5,0,0,5,0,5,0,0,5,0,0,0,0,0
20,0,0,20,0,0,20,0,0,0,5,0,5,0,0,0,0,0,0,0,0,0,0,0,0,0,0,0,0
20,0,0,17,0,37,20,0,0,0,0,0,0,0,0,0,0,0,0,0,0,0,0,0,0,5,0,5,0
20,20,20,20,20,20,20,0,0,0,0,0,0,0,0,0,0,0,0,0,0,0,0,0,0,0,0,0,0
0,0,0,0,0,0,0,0,0,0,5,0,5,0,0,0,0,0,0,5,0,0,5,0,0,0,0,0,0
0,0,0,0,0,0,0,0,0,0,0,0,0,0,0,0,0,0,0,0,0,0,0,0,0,5,0,5,0
0,0,0,6,6,6,6,6,6,6,6,0,0,0,5,0,5,0,0,0,0,0,0,0,0,0,0,0,0
0,0,0,6,8,0,12,29,0,0,6,0,0,0,0,0,0,0,0,5,0,0,5,0,0,0,0,0,0
0,0,0,6,8,0,0,29,0,0,34,0,0,0,0,0,0,0,0,0,0,0,0,0,0,5,0,5,0
0,0,0,6,38,0,0,29,0,0,6,0,0,0,5,0,5,0,0,0,0,0,0,0,0,0,0,0,0
0,0,0,6,8,0,0,0,0,0,28,0,0,0,0,0,0,0,0,0,0,0,0,0,0,0,0,0,0
0,0,0,6,6,6,6,6,6,6,6,0,0,0,0,0,0,0,0,0,0,0,0,0,0,5,0,5,0
0,0,0,0,0,0,0,0,0,0,0,0,0,0,0,5,0,0,5,0,5,0,0,5,0,0,0,0,0
0,0,0,0,0,0,0,0,0,0,0,0,0,0,0,0,0,0,0,0,0,0,0,0,0,0,0,0,0
0,0,0,6,20,20,20,20,20,20,6,0,0,0,0,5,0,0,5,0,5,0,0,5,0,0,0,0,0
0,0,0,20,8,0,29,12,12,36,20,0,0,0,0,0,0,0,0,0,0,0,0,0,0,0,0,0,0
0,0,0,20,0,0,29,0,0,0,20,0,0,0,0,0,0,0,0,0,0,0,0,0,0,0,0,0,0
0,0,0,20,0,0,29,0,0,0,35,0,0,0,0,0,0,0,0,0,0,0,0,0,0,0,0,0,0
0,0,0,20,8,0,0,0,0,0,20,0,0,0,0,0,0,0,0,0,0,0,0,0,0,0,0,0,0
0,0,0,6,6,6,6,6,6,6,6,0,0,0,0,0,0,0,0,0,0,0,0,0,0,0,0,0,0
0,0,0,34,0,29,0,0,0,0,20,0,0,0,0,0,0,0,0,0,0,0,0,0,0,0,0,0,0
0,0,0,20,0,8,0,0,16,0,35,0,0,0,0,6,6,32,6,30,6,32,6,6,29,11,29,6,0
0,0,0,20,0,29,14,29,29,0,20,0,0,0,0,6,0,0,0,0,0,0,0,20,0,0,0,29,0
0,0,0,20,0,0,0,0,0,0,20,0,0,0,0,32,0,0,0,0,0,0,0,20,0,0,0,29,0
0,0,0,6,20,20,20,20,20,20,6,0,0,0,0,6,0,0,0,0,0,0,0,20,14,0,14,29,0
0,0,0,0,0,0,0,0,0,0,0,0,0,0,0,6,6,6,6,6,6,6,6,6,29,29,29,6,0
0,0,0,0,0,0,0,0,0,0,0,0,0,0,0,0,0,0,0,0,0,0,0,0,0,0,0,0,0
endlayer

layer
0,0,0,0,0,0,0,0,0,0,0,0,0,0,0,0,0,0,0,0,0,0,0,0,0,0,0,0,0
0,0,0,0,0,0,0,0,0,0,0,0,0,0,0,0,0,6,6,6,6,6,6,6,6,6,6,0,0
6,20,32,20,32,20,6,0,0,0,0,0,0,0,0,0,0,6,23,0,41,0,0,0,0,0,6,0,0
20,0,0,0,0,0,20,0,0,0,0,0,0,0,0,0,0,6,0,0,0,0,0,0,0,42,6,0,0
0,0,0,0,0,0,32,0,0,0,0,0,0,0,0,0,0,6,0,0,0,0,0,0,0,0,6,0,0
20,0,0,0,0,0,20,0,0,0,0,0,0,0,0,0,0,6,6,31,6,31,6,6,6,6,6,0,0
20,0,0,0,0,0,20,39,0,0,0,0,0,0,0,0,0,0,0,0,0,0,0,0,41,0,0,0,0
20,0,0,0,0,0,32,0,0,0,0,0,0,0,0,5,0,0,5,0,5,0,0,5,0,0,0,0,0
32,0,0,0,0,0,20,0,0,0,0,0,0,0,0,0,0,0,0,0,0,0,0,0,0,0,0,0,0
20,0,0,0,0,0,30,0,0,0,0,0,0,0,0,5,0,0,5,0,5,0,0,5,0,0,0,0,0
32,0,0,0,0,0,20,0,0,0,5,0,5,0,0,0,0,0,0,0,0,0,0,0,0,0,0,0,0
20,0,0,0,0,0,32,0,0,0,0,0,0,0,0,0,0,0,0,0,0,0,0,0,0,5,0,5,0
20,20,32,20,32,20,20,39,0,0,0,0,0,0,0,0,0,0,0,0,0,0,0,0,0,0,0,0,0
41,0,0,0,0,0,41,0,0,0,5,0,5,0,0,0,0,0,0,5,0,0,5,0,0,0,0,0,0
0,0,0,40,0,0,0,0,0,0,40,0,0,0,0,0,0,0,0,0,0,0,0,0,0,5,0,5,0
0,0,42,6,6,6,32,6,32,6,6,39,0,0,5,0,5,0,0,0,0,0,0,0,0,0,0,0,0
0,0,0,6,0,0,0,0,0,0,6,0,0,0,0,0,0,0,0,5,0,0,5,0,0,0,0,0,0
0,0,0,6,0,0,0,0,0,0,30,0,0,0,0,0,0,0,0,0,0,0,0,0,0,5,0,5,0
0,0,0,6,0,0,0,0,0,0,6,0,0,0,5,0,5,0,0,0,0,0,0,0,0,0,0,0,0
0,0,0,6,0,0,0,0,0,0,6,0,0,0,0,0,0,0,0,0,0,0,0,0,0,0,0,0,0
0,0,42,6,6,6,32,6,32,6,6,39,0,0,0,0,0,0,0,0,0,0,0,0,0,5,0,5,0
0,0,0,41,0,0,0,0,0,0,41,0,0,0,0,5,0,0,5,0,5,0,0,5,0,0,0,0,0
0,0,0,40,0,0,0,0,0,0,40,0,0,0,0,0,0,0,0,0,0,0,0,0,0,0,0,0,0
0,0,42,6,20,32,20,20,32,20,6,0,0,0,0,5,0,0,5,0,5,0,0,5,0,0,0,0,0
0,0,0,20,0,0,0,0,0,0,32,0,0,0,0,0,0,0,0,0,0,0,0,0,0,0,0,0,0
0,0,0,32,0,0,0,0,0,0,20,39,0,0,0,0,0,0,0,0,0,0,0,0,0,0,0,0,0
0,0,0,32,0,0,0,0,0,0,30,0,0,0,0,0,0,0,0,0,0,0,0,0,0,0,0,0,0
0,0,0,20,0,0,0,0,0,0,20,39,0,0,0,0,0,0,0,0,0,0,0,0,0,0,0,0,0
0,0,42,6,6,6,6,6,6,6,6,0,0,0,0,0,0,0,0,0,0,0,0,0,0,0,0,0,0
0,0,0,30,0,23,0,0,0,0,20,0,0,0,0,40,0,0,0,40,0,0,0,40,0,0,0,40,0
0,0,0,20,0,0,0,0,0,0,30,0,0,0,42,6,6,32,6,6,6,32,6,6,29,30,29,6,39
0,0,0,20,0,0,0,0,0,0,20,0,0,0,0,6,0,0,0,41,0,0,0,20,0,0,0,29,0
0,0,0,20,0,0,0,0,0,0,32,0,0,0,0,32,0,0,0,0,0,0,0,20,0,0,0,32,0
0,0,0,6,20,32,20,20,32,20,6,39,0,0,0,6,0,0,0,0,0,0,0,20,0,0,0,29,0
0,0,0,41,0,0,0,0,0,0,41,0,0,0,42,6,6,32,6,6,32,6,6,6,29,32,29,6,39
0,0,0,0,0,0,0,0,0,0,0,0,0,0,0,41,0,0,0,0,0,0,0,41,0,0,0,41,0
endlayer

layer
0,0,0,0,0,0,0,0,0,0,0,0,0,0,0,0,46,43,43,43,43,43,43,43,43,43,43,43,0
49,49,49,49,49,49,49,49,0,0,0,0,0,0,0,0,46,6,6,6,6,6,6,6,6,6,6,27,0
6,20,20,20,20,20,6,47,0,0,0,0,0,0,0,0,46,6,23,0,0,0,0,0,0,0,6,27,0
20,0,0,0,0,0,20,47,0,0,0,0,0,0,0,0,46,6,0,0,0,0,0,0,0,0,6,27,0
20,0,0,0,0,0,20,47,0,0,0,0,0,0,0,0,46,6,0,0,40,0,0,0,0,0,6,27,0
20,0,0,0,0,0,20,47,0,0,0,0,0,0,0,0,46,6,6,6,6,6,6,6,6,6,6,27,0
20,0,0,0,0,0,20,47,0,0,0,0,0,0,0,0,46,45,45,45,45,45,45,45,45,45,45,27,0
20,0,0,0,0,0,20,47,0,0,0,0,0,0,0,44,13,44,13,0,9,24,9,24,0,0,0,0,0
20,0,0,0,0,0,20,47,0,0,0,0,0,0,0,13,44,13,44,0,24,9,24,9,0,0,0,0,0
20,39,0,0,0,0,20,47,0,0,0,0,0,0,0,44,13,44,13,0,9,24,9,24,0,0,0,0,0
20,0,0,0,0,0,20,47,0,0,25,24,25,0,0,0,0,0,0,0,0,0,0,0,0,0,0,0,0
20,0,0,0,0,0,20,47,0,0,24,25,24,0,0,0,0,0,0,0,0,0,0,0,0,7,44,7,0
20,20,20,20,20,20,20,47,0,0,25,24,25,0,0,0,0,0,0,40,0,0,40,0,0,44,7,44,0
48,48,47,48,48,48,48,47,0,0,24,25,24,0,0,0,0,0,42,6,6,6,6,39,0,7,44,7,0
0,0,0,49,49,49,49,49,0,0,0,0,0,0,0,0,0,0,0,6,6,6,6,0,0,44,7,44,0
0,0,0,6,6,6,6,6,6,6,6,0,0,0,25,9,25,0,0,6,6,6,6,0,0,0,0,0,0
0,0,0,6,39,0,0,0,0,41,6,0,0,0,9,25,9,0,42,6,6,6,6,39,0,0,0,0,0
0,0,0,6,0,0,0,0,0,0,6,0,0,0,25,9,25,0,0,41,0,0,41,0,0,24,9,24,0
0,0,0,6,0,0,0,0,0,0,6,0,0,0,9,25,9,0,0,0,0,0,0,0,0,9,24,9,0
0,0,0,6,39,0,0,0,0,40,6,0,0,0,0,0,0,0,0,0,0,0,0,0,0,24,9,24,0
0,0,0,6,6,6,6,6,6,6,6,0,0,0,0,0,0,0,0,0,0,0,0,0,0,9,24,9,0
0,0,0,48,48,48,48,48,48,48,48,0,0,0,0,7,24,7,24,0,13,7,13,7,0,0,0,0,0
0,0,0,49,49,49,49,49,49,49,49,0,0,0,0,24,7,24,7,0,7,13,7,13,0,0,0,0,0
0,0,0,6,20,20,20,20,20,20,6,0,0,0,0,7,24,7,24,0,13,7,13,7,0,0,0,0,0
0,0,0,20,39,0,0,0,0,42,20,0,0,0,0,0,0,0,0,0,0,0,0,0,0,0,0,0,0
0,0,0,20,0,0,0,0,0,0,20,0,0,0,0,0,0,0,0,0,0,0,0,0,0,0,0,0,0
0,0,0,20,0,0,0,0,0,0,20,0,0,0,0,0,0,0,0,0,0,0,0,0,0,0,0,0,0
0,0,0,20,39,0,0,0,0,42,20,0,0,0,0,0,0,0,0,0,0,0,0,0,0,0,0,0,0
0,0,0,6,6,6,6,6,6,6,6,0,0,0,0,0,0,0,0,0,0,0,0,0,0,0,0,0,0
0,0,0,20,39,0,0,0,0,42,20,0,0,0,43,43,43,43,43,43,43,43,43,43,0,0,0,0,0
0,0,0,20,0,0,0,0,0,0,20,0,0,0,46,6,6,6,6,6,6,6,6,6,29,29,29,6,0
0,0,0,20,0,0,0,0,0,0,20,0,0,0,46,6,0,0,0,0,0,0,0,20,0,41,0,29,0
0,0,0,20,39,0,0,0,0,42,20,0,0,0,46,6,0,0,0,0,0,0,0,20,0,0,0,29,0
0,0,0,20,20,20,20,20,20,20,6,0,0,0,46,6,0,0,0,0,0,0,0,20,0,40,0,29,0
0,0,0,48,48,48,48,48,48,48,48,47,0,0,46,6,6,6,6,6,6,6,6,6,29,29,29,6,0
0,0,0,0,0,0,0,0,0,0,0,0,0,0,46,45,45,45,45,45,45,45,45,45,0,0,0,0,0
endlayer

layer
0,0,0,0,0,0,0,0,0,0,0,0,0,0,0,0,0,0,0,0,0,0,0,0,0,0,0,0,0
0,0,0,0,0,0,0,0,0,0,0,0,0,0,0,0,0,43,43,43,43,43,43,43,43,43,43,0,0
46,43,43,43,43,43,27,0,0,0,0,0,0,0,0,0,0,46,20,20,20,20,20,20,20,20,27,0,0
46,20,20,20,20,20,27,0,0,0,0,0,0,0,0,0,0,46,20,51,20,20,20,20,20,20,27,0,0
46,20,0,0,0,20,27,0,0,0,0,0,0,0,0,0,0,46,20,20,20,20,20,20,20,20,27,0,0
46,20,0,0,0,20,27,0,0,0,0,0,0,0,0,0,0,45,45,45,45,45,45,45,45,45,45,0,0
46,20,0,0,0,20,27,0,0,0,0,0,0,0,0,0,0,0,0,0,0,0,0,0,0,0,0,0,0
46,20,0,0,0,20,27,0,0,0,0,0,0,0,0,0,0,0,0,0,0,0,0,0,0,0,0,0,0
46,20,0,0,0,20,27,0,0,0,0,0,0,0,0,0,0,50,0,0,0,0,50,0,0,0,0,0,0
46,20,0,0,0,20,27,0,0,0,0,0,0,0,0,0,0,0,0,0,0,0,0,0,0,0,0,0,0
46,20,0,0,0,20,27,0,0,0,0,0,0,0,0,0,0,0,0,0,0,0,0,0,0,0,0,0,0
46,20,20,20,20,20,27,0,0,0,0,50,0,0,0,0,0,0,0,0,0,0,0,0,0,0,0,0,0
46,45,45,45,45,45,45,0,0,0,0,0,0,0,0,0,0,0,0,0,0,0,0,0,0,0,50,0,0
0,0,0,0,0,0,0,0,0,0,0,0,0,0,0,0,0,0,0,0,0,0,0,0,0,0,0,0,0
0,0,0,0,0,0,0,0,0,0,0,0,0,0,0,0,0,0,0,0,50,50,0,0,0,0,0,0,0
0,0,0,43,43,43,43,43,43,43,43,27,0,0,0,0,0,0,0,0,50,50,0,0,0,0,0,0,0
0,0,0,20,0,0,0,0,0,0,20,27,0,0,0,50,0,0,0,0,0,0,0,0,0,0,0,0,0
0,0,0,20,0,0,0,0,0,0,20,27,0,0,0,0,0,0,0,0,0,0,0,0,0,0,0,0,0
0,0,0,20,0,0,0,0,0,0,20,27,0,0,0,0,0,0,0,0,0,0,0,0,0,0,0,0,0
0,0,0,20,0,0,0,0,0,0,20,27,0,0,0,0,0,0,0,0,0,0,0,0,0,0,50,0,0
0,0,0,45,45,45,45,45,45,45,45,27,0,0,0,0,0,0,0,0,0,0,0,0,0,0,0,0,0
0,0,0,0,0,0,0,0,0,0,0,0,0,0,0,0,0,0,0,0,0,0,0,0,0,0,0,0,0
0,0,0,0,0,0,0,0,0,0,0,0,0,0,0,0,50,0,0,0,0,50,0,0,0,0,0,0,0
0,0,0,43,43,43,43,43,43,43,43,27,0,0,0,0,0,0,0,0,0,0,0,0,0,0,0,0,0
0,0,0,20,0,0,0,0,0,0,20,27,0,0,0,0,0,0,0,0,0,0,0,0,0,0,0,0,0
0,0,0,20,0,0,0,0,0,0,20,27,0,0,0,0,0,0,0,0,0,0,0,0,0,0,0,0,0
0,0,0,20,0,0,0,0,0,0,20,27,0,0,0,0,0,0,0,0,0,0,0,0,0,0,0,0,0
0,0,0,20,0,0,0,0,0,0,20,27,0,0,0,0,0,0,0,0,0,0,0,0,0,0,0,0,0
0,0,0,20,20,20,20,20,20,20,20,27,0,0,0,0,0,0,0,0,0,0,0,0,0,0,0,0,0
0,0,0,20,0,0,0,0,0,0,20,27,0,0,0,0,0,0,0,0,0,0,0,0,43,43,43,43,0
0,0,0,20,0,0,0,0,0,0,20,27,0,0,0,43,43,43,43,43,43,43,43,43,20,20,20,27,0
0,0,0,20,0,0,0,0,0,0,20,27,0,0,0,46,0,0,0,0,0,0,0,6,0,0,0,27,0
0,0,0,20,0,0,0,0,0,0,20,27,0,0,0,46,39,0,0,0,0,0,42,6,0,0,0,27,0
0,0,0,45,45,45,45,45,45,45,45,45,0,0,0,46,0,0,0,0,0,0,0,6,0,0,0,27,0
0,0,0,0,0,0,0,0,0,0,0,0,0,0,0,46,45,45,45,45,45,45,45,45,20,20,20,27,0
0,0,0,0,0,0,0,0,0,0,0,0,0,0,0,0,0,0,0,0,0,0,0,0,45,45,45,45,0
endlayer

layer
0,0,0,0,0,0,0,0,0,0,0,0,0,0,0,0,0,0,0,0,0,0,0,0,0,0,0,0,0
0,0,0,0,0,0,0,0,0,0,0,0,0,0,0,0,0,0,0,0,0,0,0,0,0,0,0,0,0
0,0,0,0,0,0,0,0,0,0,0,0,0,0,0,0,0,0,0,0,0,0,0,0,0,0,0,0,0
0,43,43,43,43,27,0,0,0,0,0,0,0,0,0,0,0,0,50,0,0,0,0,0,0,50,0,0,0
0,46,20,0,20,27,0,0,0,0,0,0,0,0,0,0,0,0,0,0,0,0,0,0,0,0,0,0,0
0,46,0,0,0,27,0,0,0,0,0,0,0,0,0,0,0,0,0,0,0,0,0,0,0,0,0,0,0
0,46,0,0,0,27,0,0,0,0,0,0,0,0,0,0,0,0,0,0,0,0,0,0,0,0,0,0,0
0,46,0,0,0,27,0,0,0,0,0,0,0,0,0,0,0,0,0,0,0,0,0,0,0,0,0,0,0
0,46,0,0,0,27,0,0,0,0,0,0,0,0,0,0,0,0,0,0,0,0,0,0,0,0,0,0,0
0,46,0,0,0,27,0,0,0,0,0,0,0,0,0,0,0,0,0,0,0,0,0,0,0,0,0,0,0
0,46,20,0,20,27,0,0,0,0,0,0,0,0,0,0,0,0,0,0,0,0,0,0,0,0,0,0,0
0,46,45,45,45,45,0,0,0,0,0,0,0,0,0,0,0,0,0,0,0,0,0,0,0,0,0,0,0
0,0,0,0,0,0,0,0,0,0,0,0,0,0,0,0,0,0,0,0,0,0,0,0,0,0,0,0,0
0,0,0,0,0,0,0,0,0,0,0,0,0,0,0,0,0,0,0,0,0,0,0,0,0,0,0,0,0
0,0,0,0,0,0,0,0,0,0,0,0,0,0,0,0,0,0,0,0,0,0,0,0,0,0,0,0,0
0,0,0,0,0,0,0,0,0,0,0,0,0,0,0,0,0,0,0,0,0,0,0,0,0,0,0,0,0
0,0,0,43,43,43,43,43,43,43,43,0,0,0,0,0,0,0,0,0,0,0,0,0,0,0,0,0,0
0,0,0,20,0,0,0,0,0,0,20,0,0,0,0,0,0,0,0,0,0,0,0,0,0,0,0,0,0
0,0,0,20,0,0,0,0,0,0,20,0,0,0,0,0,0,0,0,0,0,0,0,0,0,0,0,0,0
0,0,0,45,45,45,45,45,45,45,45,0,0,0,0,0,0,0,0,0,0,0,0,0,0,0,0,0,0
0,0,0,0,0,0,0,0,0,0,0,0,0,0,0,0,0,0,0,0,0,0,0,0,0,0,0,0,0
0,0,0,0,0,0,0,0,0,0,0,0,0,0,0,0,0,0,0,0,0,0,0,0,0,0,0,0,0
0,0,0,0,0,0,0,0,0,0,0,0,0,0,0,0,0,0,0,0,0,0,0,0,0,0,0,0,0
0,0,0,0,0,0,0,0,0,0,0,0,0,0,0,0,0,0,0,0,0,0,0,0,0,0,0,0,0
0,0,0,43,43,43,43,43,43,43,43,0,0,0,0,0,0,0,0,0,0,0,0,0,0,0,0,0,0
0,0,0,20,0,0,0,0,0,0,20,0,0,0,0,0,0,0,0,0,0,0,0,0,0,0,0,0,0
0,0,0,20,0,0,0,0,0,0,20,0,0,0,0,0,0,0,0,0,0,0,0,0,0,0,0,0,0
0,0,0,45,45,45,45,45,45,45,45,0,0,0,0,0,0,0,0,0,0,0,0,0,0,0,0,0,0
0,0,0,0,0,0,0,0,0,0,0,0,0,0,0,0,0,0,0,0,0,0,0,0,0,0,0,0,0
0,0,0,43,43,43,43,43,43,43,43,0,0,0,0,0,0,0,0,0,0,0,0,0,0,0,0,0,0
0,0,0,20,0,0,0,0,0,0,20,0,0,0,0,0,0,0,0,0,0,0,0,0,46,20,27,0,0
0,0,0,20,0,0,0,0,0,0,20,0,0,0,0,0,43,43,43,43,43,43,43,43,20,20,27,0,0
0,0,0,45,45,45,45,45,45,45,45,0,0,0,0,0,46,20,20,20,20,20,20,20,20,20,27,0,0
0,0,0,0,0,0,0,0,0,0,0,0,0,0,0,0,45,45,45,45,45,45,45,45,20,20,27,0,0
0,0,0,0,0,0,0,0,0,0,0,0,0,0,0,0,0,0,0,0,0,0,0,0,46,20,27,0,0
0,0,0,0,0,0,0,0,0,0,0,0,0,0,0,0,0,0,0,0,0,0,0,0,0,0,0,0,0
endlayer

layer
0,0,0,0,0,0,0,0,0,0,0,0,0,0,0,0,0,0,0,0,0,0,0,0,0,0,0,0,0
0,0,0,0,0,0,0,0,0,0,0,0,0,0,0,0,0,0,0,0,0,0,0,0,0,0,0,0,0
0,0,0,0,0,0,0,0,0,0,0,0,0,0,0,0,0,0,0,0,0,0,0,0,0,0,0,0,0
0,0,0,0,0,0,0,0,0,0,0,0,0,0,0,0,0,0,0,0,0,0,0,0,0,0,0,0,0
0,0,43,43,27,0,0,0,0,0,0,0,0,0,0,0,0,0,0,0,0,0,0,0,0,0,0,0,0
0,0,46,20,27,0,0,0,0,0,0,0,0,0,0,0,0,0,0,0,0,0,0,0,0,0,0,0,0
0,0,46,20,27,0,0,0,0,0,0,0,0,0,0,0,0,0,0,0,0,0,0,0,0,0,0,0,0
0,0,46,20,27,0,0,0,0,0,0,0,0,0,0,0,0,0,0,0,0,0,0,0,0,0,0,0,0
0,0,46,20,27,0,0,0,0,0,0,0,0,0,0,0,0,0,0,0,0,0,0,0,0,0,0,0,0
0,0,46,20,27,0,0,0,0,0,0,0,0,0,0,0,0,0,0,0,0,0,0,0,0,0,0,0,0
0,0,45,45,45,0,0,0,0,0,0,0,0,0,0,0,0,0,0,0,0,0,0,0,0,0,0,0,0
0,0,0,0,0,0,0,0,0,0,0,0,0,0,0,0,0,0,0,0,0,0,0,0,0,0,0,0,0
0,0,0,0,0,0,0,0,0,0,0,0,0,0,0,0,0,0,0,0,0,0,0,0,0,0,0,0,0
0,0,0,0,0,0,0,0,0,0,0,0,0,0,0,0,0,0,0,0,0,0,0,0,0,0,0,0,0
0,0,0,0,0,0,0,0,0,0,0,0,0,0,0,0,0,0,0,0,0,0,0,0,0,0,0,0,0
0,0,0,0,0,0,0,0,0,0,0,0,0,0,0,0,0,0,0,0,0,0,0,0,0,0,0,0,0
0,0,0,0,0,0,0,0,0,0,0,0,0,0,0,0,0,0,0,0,0,0,0,0,0,0,0,0,0
0,0,0,43,43,43,43,43,43,43,43,0,0,0,0,0,0,0,0,0,0,0,0,0,0,0,0,0,0
0,0,0,45,45,45,45,45,45,45,45,0,0,0,0,0,0,0,0,0,0,0,0,0,0,0,0,0,0
0,0,0,0,0,0,0,0,0,0,0,0,0,0,0,0,0,0,0,0,0,0,0,0,0,0,0,0,0
0,0,0,0,0,0,0,0,0,0,0,0,0,0,0,0,0,0,0,0,0,0,0,0,0,0,0,0,0
0,0,0,0,0,0,0,0,0,0,0,0,0,0,0,0,0,0,0,0,0,0,0,0,0,0,0,0,0
0,0,0,0,0,0,0,0,0,0,0,0,0,0,0,0,0,0,0,0,0,0,0,0,0,0,0,0,0
0,0,0,0,0,0,0,0,0,0,0,0,0,0,0,0,0,0,0,0,0,0,0,0,0,0,0,0,0
0,0,0,0,0,0,0,0,0,0,0,0,0,0,0,0,0,0,0,0,0,0,0,0,0,0,0,0,0
0,0,0,43,43,43,43,43,43,43,43,0,0,0,0,0,0,0,0,0,0,0,0,0,0,0,0,0,0
0,0,0,45,45,45,45,45,45,45,45,0,0,0,0,0,0,0,0,0,0,0,0,0,0,0,0,0,0
0,0,0,0,0,0,0,0,0,0,0,0,0,0,0,0,0,0,0,0,0,0,0,0,0,0,0,0,0
0,0,0,0,0,0,0,0,0,0,0,0,0,0,0,0,0,0,0,0,0,0,0,0,0,0,0,0,0
0,0,0,0,0,0,0,0,0,0,0,0,0,0,0,0,0,0,0,0,0,0,0,0,0,0,0,0,0
0,0,0,43,43,43,43,43,43,43,43,0,0,0,0,0,0,0,0,0,0,0,0,0,0,0,0,0,0
0,0,0,45,45,45,45,45,45,45,45,0,0,0,0,0,0,0,0,0,0,0,0,0,0,0,0,0,0
0,0,0,0,0,0,0,0,0,0,0,0,0,0,0,0,0,0,0,0,0,0,0,0,0,50,0,0,0
0,0,0,0,0,0,0,0,0,0,0,0,0,0,0,0,0,0,0,0,0,0,0,0,0,0,0,0,0
0,0,0,0,0,0,0,0,0,0,0,0,0,0,0,0,0,0,0,0,0,0,0,0,0,0,0,0,0
0,0,0,0,0,0,0,0,0,0,0,0,0,0,0,0,0,0,0,0,0,0,0,0,0,0,0,0,0
endlayer

layer
0,0,0,0,0,0,0,0,0,0,0,0,0,0,0,0,0,0,0,0,0,0,0,0,0,0,0,0,0
0,0,0,0,0,0,0,0,0,0,0,0,0,0,0,0,0,0,0,0,0,0,0,0,0,0,0,0,0
0,0,0,0,0,0,0,0,0,0,0,0,0,0,0,0,0,0,0,0,0,0,0,0,0,0,0,0,0
0,0,0,0,0,0,0,0,0,0,0,0,0,0,0,0,0,0,0,0,0,0,0,0,0,0,0,0,0
0,0,0,0,0,0,0,0,0,0,0,0,0,0,0,0,0,0,0,0,0,0,0,0,0,0,0,0,0
0,0,0,50,0,0,0,0,0,0,0,0,0,0,0,0,0,0,0,0,0,0,0,0,0,0,0,0,0
0,0,0,0,0,0,0,0,0,0,0,0,0,0,0,0,0,0,0,0,0,0,0,0,0,0,0,0,0
0,0,0,0,0,0,0,0,0,0,0,0,0,0,0,0,0,0,0,0,0,0,0,0,0,0,0,0,0
0,0,0,0,0,0,0,0,0,0,0,0,0,0,0,0,0,0,0,0,0,0,0,0,0,0,0,0,0
0,0,0,50,0,0,0,0,0,0,0,0,0,0,0,0,0,0,0,0,0,0,0,0,0,0,0,0,0
0,0,0,0,0,0,0,0,0,0,0,0,0,0,0,0,0,0,0,0,0,0,0,0,0,0,0,0,0
0,0,0,0,0,0,0,0,0,0,0,0,0,0,0,0,0,0,0,0,0,0,0,0,0,0,0,0,0
0,0,0,0,0,0,0,0,0,0,0,0,0,0,0,0,0,0,0,0,0,0,0,0,0,0,0,0,0
0,0,0,0,0,0,0,0,0,0,0,0,0,0,0,0,0,0,0,0,0,0,0,0,0,0,0,0,0
0,0,0,0,0,0,0,0,0,0,0,0,0,0,0,0,0,0,0,0,0,0,0,0,0,0,0,0,0
0,0,0,0,0,0,0,0,0,0,0,0,0,0,0,0,0,0,0,0,0,0,0,0,0,0,0,0,0
0,0,0,0,0,0,0,0,0,0,0,0,0,0,0,0,0,0,0,0,0,0,0,0,0,0,0,0,0
0,0,0,0,0,0,0,0,0,0,0,0,0,0,0,0,0,0,0,0,0,0,0,0,0,0,0,0,0
0,0,0,0,0,0,0,0,0,0,0,0,0,0,0,0,0,0,0,0,0,0,0,0,0,0,0,0,0
0,0,0,0,0,0,0,0,0,0,0,0,0,0,0,0,0,0,0,0,0,0,0,0,0,0,0,0,0
0,0,0,0,0,0,0,0,0,0,0,0,0,0,0,0,0,0,0,0,0,0,0,0,0,0,0,0,0
0,0,0,0,0,0,0,0,0,0,0,0,0,0,0,0,0,0,0,0,0,0,0,0,0,0,0,0,0
0,0,0,0,0,0,0,0,0,0,0,0,0,0,0,0,0,0,0,0,0,0,0,0,0,0,0,0,0
0,0,0,0,0,0,0,0,0,0,0,0,0,0,0,0,0,0,0,0,0,0,0,0,0,0,0,0,0
0,0,0,0,0,0,0,0,0,0,0,0,0,0,0,0,0,0,0,0,0,0,0,0,0,0,0,0,0
0,0,0,0,0,0,0,0,0,0,0,0,0,0,0,0,0,0,0,0,0,0,0,0,0,0,0,0,0
0,0,0,0,0,0,0,0,0,0,0,0,0,0,0,0,0,0,0,0,0,0,0,0,0,0,0,0,0
0,0,0,0,0,0,0,0,0,0,0,0,0,0,0,0,0,0,0,0,0,0,0,0,0,0,0,0,0
0,0,0,0,0,0,0,0,0,0,0,0,0,0,0,0,0,0,0,0,0,0,0,0,0,0,0,0,0
0,0,0,0,0,0,0,0,0,0,0,0,0,0,0,0,0,0,0,0,0,0,0,0,0,0,0,0,0
0,0,0,0,0,0,0,0,0,0,0,0,0,0,0,0,0,0,0,0,0,0,0,0,0,0,0,0,0
0,0,0,0,0,0,0,0,0,0,0,0,0,0,0,0,0,0,0,0,0,0,0,0,0,0,0,0,0
0,0,0,0,0,0,0,0,0,0,0,0,0,0,0,0,0,0,0,0,0,0,0,0,0,0,0,0,0
0,0,0,0,0,0,0,0,0,0,0,0,0,0,0,0,0,0,0,0,0,0,0,0,0,0,0,0,0
0,0,0,0,0,0,0,0,0,0,0,0,0,0,0,0,0,0,0,0,0,0,0,0,0,0,0,0,0
0,0,0,0,0,0,0,0,0,0,0,0,0,0,0,0,0,0,0,0,0,0,0,0,0,0,0,0,0
endlayer




