# Converted from schematic
# author:MohawkyMagoo

weight=10
embed_into_distance=3
#acceptable_target_blocks=1,2,3,12,13
dimensions=22,27,30
#allowable_overhang=0
max_cut_in=2
#cut_in_buffer=1
max_leveling=2
#leveling_buffer=1
#preserve_water=0
#preserve_lava=0
#preserve_plants=0


rule1=0,100,4
rule2=0,100,1
rule3=0,100,3
rule4=0,100,98
rule5=0,100,98-1
rule6=0,100,98-2
rule7=0,100,16
rule8=0,100,13
rule9=0,100,2
rule10=0,100,67-3
rule11=0,100,64
rule12=0,100,67-1
rule13=0,100,85
rule14=0,100,64-1
rule15=0,100,54-2
rule16=0,100,109-3
rule17=0,100,64-8
rule18=0,100,109-1
rule19=0,100,64-2
rule20=0,100,102
rule21=0,100,50-2
rule22=0,100,50-3
rule23=0,100,50-4
rule24=0,100,50-1
rule25=0,100,126
rule26=0,100,53-1
rule27=0,100,53-2
rule28=0,100,53-0
rule29=0,100,54-3
rule30=0,100,109-2
rule31=0,100,109-0
rule32=0,100,43
rule33=0,100,5
rule34=0,100,54-4
rule35=0,100,50-5
rule36=0,100,64-1
rule37=0,100,5-3
rule38=0,100,17
rule39=0,100,72
rule40=0,100,53-3
rule41=0,100,53-4
rule42=0,100,53-6
rule43=0,100,53-7
rule44=0,100,64-0
rule45=0,100,54-5


layer
1,1,1,1,1,1,1,1,1,1,1,1,1,1,1,1,1,1,1,1,1,1,1,1,1,1,1,1,1,1
1,1,1,1,1,1,1,1,1,1,1,1,1,1,1,1,1,1,1,1,1,1,1,1,1,1,1,1,1,1
1,1,1,1,1,1,1,1,1,1,1,1,1,1,1,1,1,1,1,1,1,1,1,1,1,1,1,1,1,1
1,1,1,1,1,1,1,1,1,1,1,1,1,1,1,1,1,1,1,1,1,1,1,1,1,1,1,1,1,1
1,1,1,1,1,2,2,2,2,2,2,2,2,2,2,2,2,2,2,2,2,2,2,2,2,2,2,1,1,1
1,1,1,1,1,2,2,2,2,2,2,2,2,2,2,2,2,2,2,2,2,2,2,2,2,2,2,1,1,1
1,1,1,1,1,2,2,2,2,2,2,2,2,2,2,2,2,2,2,2,2,2,2,2,2,2,2,1,1,1
1,1,1,1,1,2,2,2,2,2,2,2,2,2,2,2,2,2,2,2,3,3,3,3,3,3,3,1,1,1
1,1,1,1,1,2,2,2,2,2,2,2,2,2,2,3,3,3,3,3,3,3,3,3,3,3,3,1,1,1
1,1,1,1,1,8,2,2,7,7,2,2,2,2,3,3,3,3,3,3,3,3,3,3,3,3,3,1,1,1
1,1,1,1,1,8,2,2,7,7,7,2,2,3,3,3,3,3,3,3,3,3,3,3,3,3,3,1,1,1
1,1,1,1,1,2,2,7,7,7,2,2,2,3,3,3,3,3,3,3,3,3,3,3,3,3,3,1,1,1
1,1,1,1,1,8,2,7,7,7,2,2,3,3,3,3,3,3,3,3,3,3,3,3,3,3,3,1,1,1
1,1,1,1,1,8,2,2,7,2,2,3,3,3,3,3,3,3,3,3,3,3,3,3,3,3,3,1,1,1
1,1,1,1,1,2,2,2,2,2,2,3,3,3,3,3,3,1,1,1,1,1,1,1,1,1,1,1,1,1
1,1,1,1,1,2,2,2,2,2,3,3,3,3,3,3,3,1,1,1,1,1,1,1,1,1,1,1,1,1
1,1,1,1,1,2,2,2,2,2,3,3,3,3,3,3,3,1,1,1,1,1,1,1,1,1,1,1,1,1
1,1,1,1,1,2,2,2,2,2,3,3,3,3,3,3,3,1,1,1,1,1,1,1,1,1,1,1,1,1
1,1,1,1,1,2,2,2,2,2,3,3,3,3,3,3,3,1,1,1,1,1,1,1,1,1,1,1,1,1
1,1,1,1,1,2,2,2,2,3,3,3,3,3,3,3,3,1,1,1,1,1,1,1,1,1,1,1,1,1
1,1,1,1,1,2,2,2,2,3,3,3,3,3,3,3,3,1,1,1,1,1,1,1,1,1,1,1,1,1
1,1,1,1,1,2,2,2,2,3,3,3,3,3,3,3,3,1,1,1,1,1,1,1,1,1,1,1,1,1
1,1,1,1,1,2,2,2,2,3,3,3,3,3,3,3,3,1,1,1,1,1,1,1,1,1,1,1,1,1
1,1,1,1,1,2,2,2,2,3,3,3,3,3,3,3,3,3,3,3,3,3,3,3,3,3,3,1,1,1
1,1,1,1,1,2,2,2,2,3,3,3,3,3,3,3,3,3,3,3,3,4,5,5,6,5,4,1,1,1
1,1,1,1,1,2,2,2,2,3,3,3,3,3,3,3,3,5,6,4,4,4,4,4,4,4,4,1,1,1
1,1,1,1,1,1,1,1,1,1,1,1,1,1,1,1,1,1,1,1,1,1,1,1,1,1,1,1,1,1
endlayer

layer
1,1,1,1,1,1,1,1,1,1,1,1,1,1,1,1,1,1,1,1,1,1,1,1,1,1,1,1,1,1
1,1,1,1,1,1,1,1,1,1,1,1,1,1,1,1,1,1,1,1,1,1,1,1,1,1,1,1,1,1
1,1,1,1,1,1,1,1,1,1,1,1,1,1,1,1,1,1,1,1,1,1,1,1,1,1,1,1,1,1
1,1,1,1,1,1,1,1,1,1,1,1,1,1,1,1,1,1,1,1,1,1,1,1,1,1,1,1,1,1
1,1,1,1,1,2,2,2,2,2,2,2,2,2,2,2,2,2,2,2,2,2,2,2,2,2,2,1,1,1
1,1,1,1,1,2,2,2,2,2,2,2,2,2,2,2,2,2,2,2,2,2,2,2,2,2,2,1,1,1
1,1,1,1,1,2,2,2,2,2,2,2,2,2,2,2,2,2,2,2,2,2,2,2,2,2,3,1,1,1
1,1,1,1,1,2,2,2,2,2,2,2,2,2,2,2,2,2,2,2,2,3,3,3,3,3,3,1,1,1
1,1,1,1,1,2,2,2,2,2,2,2,2,2,2,2,2,2,3,3,3,3,3,3,3,3,3,1,1,1
1,1,1,1,1,2,2,2,2,2,2,2,2,2,2,1,1,1,3,3,3,3,3,3,3,3,3,1,1,1
1,1,1,1,1,2,2,2,2,7,2,2,2,2,2,1,1,1,1,1,1,1,1,1,1,1,1,1,1,1
1,1,1,1,1,2,2,2,2,7,2,2,2,2,2,1,1,1,1,1,1,1,1,1,1,1,1,1,1,1
1,1,1,1,1,2,2,2,2,2,2,2,2,2,2,1,1,1,1,1,1,1,1,1,1,1,1,1,1,1
1,1,1,1,1,2,2,2,2,2,2,2,1,1,1,1,1,1,1,1,1,1,1,1,1,1,1,1,1,1
1,1,1,1,1,2,2,2,2,2,2,2,3,3,3,3,1,1,1,1,1,1,1,1,1,1,1,1,1,1
1,1,1,1,1,2,2,2,2,3,3,1,1,1,1,3,3,1,1,1,1,1,1,1,1,1,1,1,1,1
1,1,1,1,1,2,2,2,2,3,3,1,1,1,1,3,3,1,1,1,1,1,1,1,1,1,1,1,1,1
1,1,1,1,1,2,2,2,2,3,3,1,1,1,1,3,3,1,1,1,1,1,1,1,1,1,1,1,1,1
1,1,1,1,1,2,2,2,2,2,3,1,1,1,1,3,3,1,1,1,1,1,1,1,1,1,1,1,1,1
1,1,1,1,1,2,2,2,2,3,3,1,1,1,1,3,3,1,1,1,1,1,1,1,1,1,1,1,1,1
1,1,1,1,1,2,2,2,2,3,3,1,1,1,1,3,3,1,1,1,1,1,1,1,1,1,1,1,1,1
1,1,1,1,1,2,2,2,2,3,3,1,1,1,1,3,3,1,1,1,1,1,1,1,1,1,1,1,1,1
1,1,1,1,1,2,2,2,2,3,3,1,1,1,1,3,3,1,1,1,1,1,1,1,1,1,1,1,1,1
1,1,1,1,1,2,2,2,2,3,3,1,1,1,1,3,3,3,3,3,3,3,3,3,3,3,3,1,1,1
1,1,1,1,1,2,2,2,2,3,3,3,3,3,3,3,3,3,3,3,3,5,5,5,5,5,6,1,1,1
1,1,1,1,1,2,3,2,3,3,3,3,3,3,3,3,3,5,5,5,4,4,4,6,4,4,4,1,1,1
1,1,1,1,1,1,1,1,1,1,1,1,1,1,1,1,1,1,1,1,1,1,1,1,1,1,1,1,1,1
endlayer

layer
1,1,1,1,1,1,1,1,1,1,1,1,1,1,1,1,1,1,1,1,1,1,1,1,1,1,1,1,1,1
1,1,1,1,1,1,1,1,1,1,1,1,1,1,1,1,1,1,1,1,1,1,1,1,1,1,1,1,1,1
1,1,1,1,1,1,1,1,1,1,1,1,1,1,1,1,1,1,1,1,1,1,1,1,1,1,1,1,1,1
1,1,1,0,0,4,0,0,10,0,0,0,0,4,0,10,0,0,0,0,0,4,4,1,1,1,1,1,1,1
1,1,1,0,0,4,0,0,0,0,0,0,0,4,0,0,0,0,0,0,0,4,1,1,1,1,1,1,1,1
1,1,1,0,0,4,0,0,0,0,0,0,0,4,0,0,0,0,0,0,0,4,1,1,1,1,1,1,1,1
1,1,1,0,0,4,4,4,4,4,0,0,0,4,0,0,0,0,0,0,0,4,1,1,1,1,1,1,1,1
1,1,1,12,0,0,0,0,0,4,0,0,0,4,0,0,0,0,0,0,0,4,1,1,1,1,1,1,1,1
1,1,1,0,0,0,0,0,0,4,4,4,11,4,4,4,0,0,4,4,4,1,1,1,1,1,1,1,1,1
1,1,1,0,0,0,0,0,0,4,0,0,0,0,0,4,4,4,4,1,3,1,1,1,1,1,1,1,1,1
1,1,1,0,0,0,0,0,0,4,0,0,0,0,0,4,1,1,1,1,1,1,1,1,1,1,1,1,1,1
1,1,1,4,4,4,4,4,4,4,0,0,0,0,0,4,1,1,1,1,1,1,1,1,1,1,1,1,1,1
1,1,1,0,0,0,0,0,0,4,0,0,0,0,0,4,1,1,1,1,1,1,1,1,1,1,1,1,1,1
1,1,1,0,0,0,0,0,0,4,4,4,4,4,4,1,1,1,1,1,1,1,1,1,1,1,1,1,1,1
1,1,1,12,0,0,0,0,0,4,4,4,1,1,1,1,1,1,1,1,1,1,1,1,1,1,1,1,1,1
1,1,1,0,0,0,0,0,0,4,3,1,1,1,1,9,9,1,1,1,1,1,1,1,1,1,1,1,1,1
1,1,1,0,0,0,0,0,0,4,1,1,1,1,1,9,9,1,1,1,1,1,1,1,1,1,1,1,1,1
1,1,1,0,0,0,0,0,0,4,1,1,1,1,1,9,9,1,1,1,1,1,1,1,1,1,1,1,1,1
1,1,1,4,4,4,4,4,4,4,1,1,1,1,1,9,9,1,1,1,1,1,1,1,1,1,1,1,1,1
1,1,1,0,0,0,0,0,0,4,1,1,1,1,1,9,9,1,1,1,1,1,1,1,1,1,1,1,1,1
1,1,1,0,0,0,0,0,0,4,1,1,1,1,1,9,9,1,1,1,1,1,1,1,1,1,1,1,1,1
1,1,1,0,0,0,0,0,0,4,1,1,1,1,1,9,9,1,1,1,1,1,1,1,1,1,1,1,1,1
1,1,1,12,0,0,0,0,0,4,1,1,1,1,1,9,9,1,1,1,1,1,1,1,1,1,1,1,1,1
1,1,1,0,0,0,0,0,0,4,1,1,1,1,1,9,9,9,9,9,9,9,9,9,9,9,9,1,1,1
1,1,1,0,0,0,0,0,0,4,3,1,1,1,1,1,1,1,1,1,1,1,1,1,1,1,1,1,1,1
1,1,1,1,1,1,1,1,1,1,1,1,1,1,1,1,1,1,1,1,1,1,1,1,1,1,1,1,1,1
1,1,1,1,1,1,1,1,1,1,1,1,1,1,1,1,1,1,1,1,1,1,1,1,1,1,1,1,1,1
endlayer

layer
13,0,0,0,0,0,0,13,0,0,0,0,0,0,13,0,0,0,0,0,0,13,0,0,0,0,0,0,13,0
0,0,0,0,0,0,0,0,0,0,0,0,0,0,0,0,0,0,0,0,0,0,0,0,0,0,0,0,0,0
0,0,4,4,4,4,4,4,11,4,4,4,4,4,4,11,4,4,4,4,4,4,4,4,4,4,4,0,0,0
0,0,4,0,0,4,0,0,0,0,0,0,0,4,0,0,0,0,0,0,0,4,4,4,4,4,4,0,0,0
0,0,4,0,0,4,0,0,0,0,0,0,0,4,0,0,0,0,0,0,0,4,0,0,0,0,4,0,0,0
0,0,4,0,0,4,0,0,0,0,0,0,0,4,0,0,0,0,0,0,0,4,0,0,0,0,4,0,13,0
0,0,4,0,0,4,4,4,4,4,0,0,0,4,0,0,0,0,0,0,0,4,15,0,0,0,4,0,0,0
0,0,19,0,0,0,0,0,0,4,0,0,0,4,0,0,0,0,0,0,0,4,15,0,0,0,4,0,0,0
13,0,4,0,0,0,0,0,0,4,4,4,17,4,4,4,0,0,4,4,4,4,0,0,0,0,4,0,0,0
0,0,4,0,0,0,0,0,0,4,0,0,0,0,0,4,4,4,4,4,4,4,0,0,0,0,4,0,0,0
0,0,4,0,0,0,0,0,0,4,0,0,0,0,0,4,4,4,0,4,4,4,4,4,4,14,4,0,13,0
0,0,4,4,4,4,4,4,4,4,0,0,0,0,0,4,4,4,0,16,16,0,0,0,0,0,0,0,0,0
0,0,4,0,0,0,0,0,0,4,0,0,0,0,0,4,4,4,0,0,0,0,0,0,0,0,0,0,0,0
0,0,4,0,0,0,0,0,0,4,4,4,4,4,4,4,4,4,0,0,0,0,0,0,0,0,0,0,0,0
0,0,19,0,0,0,0,0,0,4,4,18,0,0,0,0,0,4,4,4,4,11,4,4,4,4,4,0,0,0
13,0,4,0,0,0,0,0,0,4,4,4,4,4,4,0,0,4,0,0,0,0,0,0,0,0,4,0,0,0
0,0,4,0,0,0,0,0,0,4,4,4,4,4,4,0,0,4,0,0,0,0,0,0,0,0,4,0,0,0
0,0,4,0,0,0,0,0,0,4,4,4,4,4,4,0,0,4,0,0,0,0,0,0,0,0,4,0,0,0
0,0,4,4,4,4,4,4,4,4,4,4,4,4,4,0,0,4,0,0,0,0,0,0,0,0,4,0,0,0
0,0,4,0,0,0,0,0,0,4,4,4,4,4,4,0,0,4,0,0,0,0,0,0,0,0,4,0,0,0
0,0,4,0,0,0,0,0,0,4,4,4,4,4,4,0,0,4,0,0,0,0,0,0,0,0,4,0,0,0
0,0,4,0,0,0,0,0,0,4,4,4,4,4,4,0,0,4,0,0,0,0,0,0,0,0,4,0,0,0
0,0,19,0,0,0,0,0,0,4,4,4,4,4,4,0,0,4,4,4,4,4,4,4,4,4,4,0,0,0
0,0,4,0,0,0,0,0,0,4,4,4,4,4,4,0,0,0,0,0,0,0,0,0,0,0,0,0,0,0
0,0,4,0,0,0,0,0,0,4,4,18,0,0,0,0,0,0,0,0,0,0,0,0,0,0,0,0,0,0
13,0,4,4,4,4,4,4,4,4,4,18,0,0,0,0,0,0,0,0,0,0,0,0,0,0,0,0,0,0
0,0,0,0,0,0,0,0,0,0,0,0,0,0,0,0,0,0,0,0,0,0,0,0,0,0,0,0,0,0
endlayer

layer
13,0,0,0,0,0,0,13,0,0,0,0,0,0,13,0,0,0,0,0,0,13,0,0,0,0,0,0,13,0
0,0,0,0,0,0,0,0,0,0,0,0,0,0,0,0,0,0,0,0,0,0,0,0,0,0,0,0,0,0
0,0,4,4,4,4,20,4,17,4,20,4,4,4,4,17,4,20,4,4,4,4,4,4,4,4,4,0,0,0
0,0,4,0,22,4,0,0,0,22,0,0,21,4,0,0,22,0,0,0,0,4,4,4,4,4,4,0,0,0
0,0,4,0,0,4,0,0,0,0,0,0,0,4,0,0,0,0,0,0,21,4,0,0,0,0,4,0,0,0
0,0,20,0,0,4,24,0,0,0,0,0,0,4,0,0,0,0,0,0,0,4,0,0,0,0,20,0,13,0
0,0,4,24,0,4,4,4,4,4,0,0,0,4,0,0,0,0,0,0,0,4,0,0,0,0,4,0,0,0
0,0,17,0,0,0,0,0,0,4,0,0,23,4,0,0,0,0,0,0,0,4,0,0,0,0,4,0,0,0
13,0,4,0,0,0,0,0,0,4,4,4,4,4,4,4,0,0,4,4,4,4,0,0,0,0,20,0,0,0
0,0,20,0,0,0,0,0,0,4,0,0,0,0,0,4,4,4,0,4,4,4,0,0,0,0,4,0,0,0
0,0,4,24,0,0,0,0,21,4,0,0,0,0,0,4,4,4,0,16,16,4,4,4,4,17,4,0,13,0
0,0,4,4,4,4,4,4,4,4,0,0,0,0,0,4,4,4,0,0,0,0,0,0,0,0,0,0,0,0
0,0,20,0,0,0,0,0,0,4,0,0,0,0,0,4,4,4,0,0,0,0,0,0,0,0,0,0,0,0
0,0,4,24,0,0,0,0,0,4,4,4,4,4,4,4,4,4,0,0,0,0,0,0,0,0,0,0,0,0
0,0,17,0,0,0,0,0,0,4,18,0,0,0,0,0,0,4,4,4,4,17,4,4,4,4,4,0,0,0
13,0,4,0,0,0,0,0,0,4,4,4,4,4,4,0,0,4,0,0,0,0,0,0,0,0,4,0,0,0
0,0,20,0,0,0,0,0,0,4,4,4,4,4,4,0,0,4,0,0,0,0,0,0,0,0,4,0,0,0
0,0,4,0,0,0,0,0,0,4,4,4,4,4,4,0,0,4,0,0,0,0,0,0,0,0,4,0,0,0
0,0,4,4,4,4,4,4,4,4,4,4,4,4,4,0,0,20,0,0,0,0,0,0,0,0,20,0,0,0
0,0,4,0,0,0,0,0,0,4,4,4,4,4,4,0,0,4,0,0,0,0,0,0,0,0,4,0,0,0
0,0,20,0,0,0,0,0,0,4,4,4,4,4,4,0,0,4,0,0,0,0,0,0,0,0,4,0,0,0
0,0,4,24,0,0,0,0,0,4,4,4,4,4,4,0,0,4,0,0,0,0,0,0,0,0,4,0,0,0
0,0,17,0,0,0,0,0,0,4,4,4,4,4,4,0,0,4,4,4,4,20,4,4,4,4,4,0,0,0
0,0,4,0,0,0,0,0,0,4,4,4,4,4,4,0,0,0,0,0,0,0,0,0,0,0,0,0,0,0
0,0,4,0,0,0,0,0,0,18,0,0,0,0,0,0,0,0,0,0,0,0,0,0,0,0,0,0,0,0
13,0,4,4,4,4,4,4,4,18,0,0,0,0,0,0,0,0,0,0,0,0,0,0,0,0,0,0,0,0
0,0,0,0,0,0,0,0,0,0,0,0,0,0,0,0,0,0,0,0,0,0,0,0,0,0,0,0,0,0
endlayer

layer
13,0,0,0,0,0,0,13,0,0,0,0,0,0,13,0,0,0,0,0,0,13,0,0,0,0,0,0,13,0
0,0,23,0,0,0,0,0,0,0,0,0,0,0,0,0,0,0,0,0,0,0,0,0,0,0,0,0,0,0
0,21,4,4,4,4,4,4,4,4,4,4,4,4,4,4,4,4,4,4,4,4,4,4,4,4,4,0,0,0
0,0,4,4,4,4,4,4,4,4,4,4,4,4,4,4,4,4,4,4,4,4,4,4,4,4,4,0,0,0
0,0,4,4,4,4,4,4,4,4,4,4,4,4,4,4,4,4,4,4,4,4,0,0,0,0,4,0,0,0
0,0,4,4,4,4,4,4,4,4,4,0,0,4,0,0,0,0,0,4,4,4,0,0,0,0,20,0,13,0
0,0,4,4,4,4,4,4,4,4,4,0,0,4,0,0,0,0,0,4,4,4,0,0,0,0,4,0,0,0
0,21,4,4,4,4,4,4,4,4,4,0,0,4,0,0,0,0,0,4,4,4,0,0,0,0,4,0,0,0
13,0,4,4,4,4,4,4,4,4,4,4,4,4,4,4,0,0,4,4,4,4,0,0,0,0,20,0,0,0
0,0,4,4,4,4,4,4,4,4,22,0,0,0,22,4,4,4,0,16,16,4,0,0,0,0,4,0,0,0
0,0,4,4,4,4,4,4,4,4,0,0,0,0,0,4,4,4,0,0,0,4,4,20,4,4,4,0,13,0
0,0,4,4,4,4,4,4,4,4,0,0,0,0,0,4,4,4,0,0,0,0,0,0,0,0,0,0,0,0
0,0,4,4,4,4,4,4,4,4,23,0,0,0,23,4,4,4,24,0,0,0,0,0,0,0,0,0,0,0
0,0,4,4,4,4,4,4,4,4,4,4,4,4,4,4,4,4,0,0,0,23,0,0,0,23,0,0,0,0
0,21,4,4,4,4,4,4,4,18,0,0,0,0,0,0,0,4,4,4,4,4,4,4,4,4,4,0,0,0
13,0,4,4,4,4,4,4,4,4,4,4,4,4,4,0,0,4,0,0,22,0,0,0,0,0,4,0,0,0
0,0,4,4,4,4,4,4,4,4,4,4,4,4,4,0,0,4,0,0,0,0,0,0,0,0,4,0,0,0
0,0,4,4,4,4,4,4,4,4,4,4,4,4,4,0,0,4,0,0,0,0,0,0,0,0,4,0,0,0
0,0,4,4,4,4,4,4,4,4,4,4,4,4,4,0,0,20,0,0,0,0,0,0,0,0,20,0,0,0
0,0,4,4,4,4,4,4,4,4,4,4,4,4,4,0,0,4,0,0,0,0,0,0,0,0,4,0,0,0
0,0,4,4,4,4,4,4,4,4,4,4,4,4,4,0,0,4,0,0,0,0,0,0,0,0,4,0,0,0
0,0,4,4,4,4,4,4,4,4,4,4,4,4,4,0,0,4,0,0,23,0,0,0,0,0,4,0,0,0
0,21,4,4,4,4,4,4,4,4,4,4,4,4,4,0,0,4,4,4,4,20,4,4,4,4,4,0,0,0
0,0,4,4,4,4,4,4,4,4,4,4,4,4,4,0,0,0,0,0,0,0,0,0,0,0,0,0,0,0
0,0,4,4,4,4,4,4,18,0,0,0,0,0,0,0,0,0,0,0,0,0,0,0,0,0,0,0,0,0
13,21,4,4,4,4,4,4,18,0,0,0,0,0,0,0,0,0,0,0,0,0,0,0,0,0,0,0,0,0
0,0,0,0,0,0,0,0,0,0,0,0,0,0,0,0,0,0,0,0,0,0,0,0,0,0,0,0,0,0
endlayer

layer
25,25,25,25,25,25,25,25,25,25,25,25,25,25,25,25,25,25,25,25,25,25,25,25,25,25,25,25,25,0
25,27,27,27,27,27,27,27,27,27,27,27,27,27,27,27,27,27,27,27,27,27,27,27,27,27,27,26,25,0
25,28,4,4,4,4,4,4,4,4,4,4,4,4,4,4,4,4,4,4,4,4,4,4,4,4,4,26,25,0
25,28,4,4,4,4,4,4,4,4,4,4,4,4,4,4,4,4,4,4,4,4,4,4,4,4,4,26,25,0
25,28,4,4,4,4,4,4,4,4,4,4,4,4,4,4,4,4,4,4,4,4,0,0,0,0,4,26,25,0
25,28,4,4,4,4,4,4,4,4,4,4,4,4,4,4,4,4,4,4,4,4,0,0,0,0,4,26,25,0
25,28,4,4,4,4,4,4,4,4,4,4,4,4,4,4,4,4,4,4,4,4,0,0,0,0,4,26,25,0
25,28,4,4,4,4,4,4,4,4,4,4,4,4,4,4,4,4,4,4,4,4,0,0,0,0,4,26,25,0
25,28,4,4,4,4,4,4,4,4,4,4,4,4,4,4,4,4,4,16,16,4,0,0,0,0,4,26,25,0
25,28,4,4,4,4,3,4,4,3,4,4,4,4,4,4,4,4,0,0,0,4,0,0,0,0,4,26,25,0
25,28,4,4,4,4,3,4,4,3,4,4,4,4,4,4,4,4,0,0,0,4,4,4,4,4,4,26,25,0
25,28,4,4,4,4,4,4,4,3,4,4,4,4,4,4,4,4,0,0,0,0,0,0,0,0,0,0,0,0
25,28,4,4,4,4,4,4,4,3,4,4,4,4,4,4,4,4,0,0,0,0,0,0,0,0,0,0,0,0
25,28,4,4,4,4,4,4,4,4,4,4,4,4,4,4,4,4,0,0,0,0,0,0,0,0,0,0,0,0
25,28,4,4,4,4,4,4,18,0,0,0,0,0,0,0,22,4,4,4,4,4,4,4,4,4,4,0,0,0
25,28,4,4,4,4,4,4,4,4,4,4,4,4,4,0,0,4,0,0,0,0,0,0,0,0,4,0,0,0
25,28,4,4,4,4,4,4,4,4,4,4,4,4,4,0,0,4,0,0,0,0,0,0,0,21,4,0,0,0
25,28,4,4,4,4,4,4,4,4,4,4,4,4,4,0,0,4,0,0,0,0,0,0,0,0,4,0,0,0
25,28,4,4,4,4,4,4,4,4,4,4,4,4,4,0,0,20,0,0,0,0,0,0,0,0,20,0,0,0
25,28,4,4,4,4,4,4,4,4,4,4,4,4,4,0,0,4,0,0,0,0,0,0,0,0,4,0,0,0
25,28,4,4,4,4,4,4,4,4,4,4,4,4,4,0,0,4,0,0,0,0,0,0,0,0,4,0,0,0
25,28,4,4,4,4,4,4,4,4,4,4,4,4,4,0,0,4,0,0,0,0,0,0,0,0,4,0,0,0
25,28,4,4,4,4,4,4,4,4,4,4,4,4,4,0,21,4,4,4,4,20,4,4,4,4,4,24,0,0
25,28,4,4,4,4,4,4,4,4,4,4,4,4,4,24,0,22,0,0,0,0,0,0,0,0,22,0,0,0
25,28,4,4,4,4,18,0,0,0,0,0,0,0,22,0,0,0,0,0,0,0,0,0,0,0,0,0,0,0
25,28,4,4,4,4,18,0,0,0,0,0,0,0,0,0,0,0,0,0,0,0,0,0,0,0,0,0,0,0
0,0,0,0,0,0,0,0,0,0,0,0,0,0,0,0,0,0,0,0,0,0,0,0,0,0,0,0,0,0
endlayer

layer
0,0,0,0,0,0,0,0,0,0,0,0,0,0,0,0,0,0,0,0,0,0,0,0,0,0,0,0,0,0
0,4,4,4,4,4,4,4,4,4,4,4,4,4,4,4,4,4,4,4,4,4,4,4,4,4,4,4,0,0
0,4,4,4,4,4,4,4,4,4,4,4,4,4,4,4,4,4,4,4,4,4,4,4,4,4,4,4,0,0
0,4,4,4,4,4,4,4,4,4,4,4,4,4,4,4,4,4,4,4,4,4,4,4,4,4,4,4,0,0
0,4,4,4,4,4,4,4,4,4,4,4,4,4,4,4,4,4,4,4,4,4,4,4,4,4,4,4,0,0
0,4,4,4,4,4,4,4,4,4,4,4,4,4,4,4,4,4,4,4,4,4,4,4,4,4,4,4,0,0
0,4,4,4,4,4,4,4,4,4,4,4,4,4,4,4,4,4,4,4,4,4,4,4,4,4,4,4,0,0
0,4,4,4,4,4,4,4,4,4,4,4,4,4,4,4,4,4,4,16,16,4,4,4,4,4,4,4,0,0
0,4,4,4,4,4,4,4,4,4,4,4,4,4,4,4,4,4,4,0,0,4,4,4,4,4,4,4,0,0
0,4,4,4,4,4,3,3,3,3,3,3,4,4,4,4,4,4,0,0,0,4,4,4,4,4,4,4,0,0
0,4,4,4,4,4,3,3,3,3,3,3,4,4,4,4,4,4,0,0,0,4,4,4,4,4,4,4,0,0
0,4,4,4,4,4,3,3,3,3,3,3,4,4,4,4,4,4,0,0,0,0,0,0,0,0,0,0,0,0
0,4,4,4,4,4,3,3,3,3,3,3,4,4,4,4,4,4,0,0,0,0,0,0,0,0,0,0,0,0
0,4,4,4,4,4,4,4,4,4,4,4,4,4,4,4,4,4,0,0,0,0,0,0,0,0,0,0,0,0
0,4,4,4,4,4,4,18,0,0,0,0,0,0,0,0,0,4,4,4,4,4,4,4,4,4,4,0,0,0
0,4,4,4,4,4,4,4,4,4,4,4,4,4,4,0,0,4,4,4,4,4,4,4,4,4,4,0,0,0
0,4,4,4,4,4,4,4,4,4,4,4,4,4,4,0,0,4,4,4,4,4,4,4,4,4,4,0,0,0
0,4,4,4,4,4,4,4,4,4,4,4,4,4,4,0,0,4,4,4,4,4,4,4,4,4,4,0,0,0
0,4,4,4,4,4,4,4,4,4,4,4,4,4,4,0,0,4,4,4,4,4,4,4,4,4,4,0,0,0
0,4,4,4,4,4,4,4,4,4,4,4,4,4,4,0,0,4,4,4,4,4,4,4,4,4,4,0,0,0
0,4,16,16,16,16,4,4,4,4,4,4,4,4,4,0,0,4,4,4,4,4,4,4,4,4,4,0,0,0
0,4,0,0,0,0,4,4,4,4,4,4,4,4,4,0,0,4,4,4,4,4,4,4,4,4,4,0,0,0
0,4,0,0,0,0,4,4,4,4,4,4,4,4,4,0,0,4,4,4,4,4,4,4,4,4,4,0,0,0
0,4,0,0,0,0,4,4,4,4,4,4,4,4,4,0,0,0,0,0,0,0,0,0,0,0,0,0,0,0
0,4,0,0,0,0,0,0,0,0,0,0,0,0,0,0,0,0,0,0,0,0,0,0,0,0,0,0,0,0
0,4,4,13,13,0,0,0,0,0,0,0,0,0,0,0,0,0,0,0,0,0,0,0,0,0,0,0,0,0
0,0,0,0,0,0,0,0,0,0,0,0,0,0,0,0,0,0,0,0,0,0,0,0,0,0,0,0,0,0
endlayer

layer
0,0,0,0,0,0,0,0,0,0,0,0,0,0,0,0,0,0,0,0,0,0,0,0,0,0,0,0,0,0
0,13,13,13,13,13,13,13,13,13,13,13,13,13,13,13,13,13,13,13,13,13,13,13,13,13,13,13,0,0
0,13,0,0,0,0,0,0,0,0,0,0,0,0,0,0,0,0,0,0,0,0,0,0,0,0,0,13,0,0
0,13,0,0,0,0,0,0,0,0,0,0,0,0,0,0,0,0,0,0,0,0,0,0,0,0,0,13,0,0
0,13,0,0,0,4,4,4,4,4,4,0,4,4,4,4,4,4,0,0,0,0,0,0,0,0,0,13,0,0
0,13,0,0,0,4,33,32,32,32,4,0,4,0,0,0,0,4,0,0,0,0,0,0,0,0,0,13,0,0
0,13,0,0,31,4,33,32,32,32,4,0,4,0,0,0,0,4,0,0,0,0,0,0,0,0,0,13,0,0
0,13,0,0,0,4,33,32,32,32,4,0,4,0,0,0,0,4,0,0,0,13,0,0,0,0,0,13,0,0
0,13,0,0,0,4,33,33,33,33,4,0,4,0,0,0,0,4,4,0,0,13,0,0,0,0,0,13,0,0
0,13,0,0,0,4,33,33,33,33,4,30,4,4,11,4,4,4,0,0,0,13,0,0,0,0,0,13,0,0
0,13,0,0,0,4,33,33,33,33,4,4,4,0,0,0,0,4,0,0,0,13,13,13,13,13,13,13,0,0
0,13,0,0,0,4,33,33,33,33,4,4,4,0,0,0,0,4,0,0,0,0,0,0,0,0,0,0,0,0
0,13,0,0,0,4,4,4,4,4,4,16,4,0,0,0,0,4,0,0,0,0,0,0,0,0,0,0,0,0
0,13,13,0,0,0,0,0,0,0,0,0,4,4,4,4,4,4,0,0,0,0,0,0,0,0,0,0,0,0
0,13,0,0,0,0,0,0,0,0,0,0,0,0,0,0,0,4,4,4,4,4,4,4,4,4,4,0,0,0
0,13,0,0,0,0,4,4,4,4,4,4,4,4,4,0,0,4,0,0,0,0,0,0,0,0,4,0,0,0
0,13,0,0,0,0,4,0,0,0,0,0,0,0,4,0,0,4,0,0,0,0,0,0,0,0,4,0,0,0
0,13,0,0,0,0,4,0,0,0,0,0,0,0,4,0,0,4,0,0,0,0,0,0,0,0,4,0,0,0
0,13,0,0,0,0,4,0,0,0,0,0,0,0,4,0,0,4,0,0,0,0,0,0,0,0,4,0,0,0
0,13,13,0,0,0,19,0,0,0,0,0,0,29,4,0,0,4,0,0,0,0,0,0,0,0,4,0,0,0
0,13,0,0,0,0,4,0,0,0,0,0,0,29,4,0,0,4,0,0,0,0,0,0,0,0,4,0,0,0
0,13,0,0,0,0,4,0,0,0,0,0,0,4,4,0,0,4,0,0,0,0,0,0,0,0,4,0,0,0
0,13,0,0,0,0,4,34,0,0,31,4,4,4,4,0,0,4,4,4,4,4,4,4,4,4,4,0,0,0
0,13,0,0,0,0,4,4,4,4,4,4,4,4,4,0,0,0,0,0,0,0,0,0,0,0,0,0,0,0
0,13,0,0,0,0,0,0,0,0,0,0,0,0,0,0,0,0,0,0,0,0,0,0,0,0,0,0,0,0
0,13,13,13,0,0,0,0,0,0,0,0,0,0,0,0,0,0,0,0,0,0,0,0,0,0,0,0,0,0
0,0,0,0,0,0,0,0,0,0,0,0,0,0,0,0,0,0,0,0,0,0,0,0,0,0,0,0,0,0
endlayer

layer
0,0,0,0,0,0,0,0,0,0,0,0,0,0,0,0,0,0,0,0,0,0,0,0,0,0,0,0,0,0
0,35,0,0,0,0,0,0,0,0,0,0,0,0,0,0,0,0,0,0,0,0,0,0,0,0,0,35,0,0
0,0,0,0,0,0,0,0,0,0,0,0,0,0,0,0,0,0,0,0,0,0,0,0,0,0,0,0,0,0
0,0,0,0,0,0,0,0,0,0,0,0,0,0,0,0,0,0,0,0,0,0,0,0,0,0,0,0,0,0
0,0,0,0,0,4,4,4,4,4,4,0,4,4,20,20,4,4,0,0,0,0,0,0,0,0,0,0,0,0
0,0,0,0,0,4,0,0,37,0,4,0,4,0,0,0,0,4,0,0,0,0,0,0,0,0,0,0,0,0
0,0,0,0,0,36,0,0,37,0,4,0,4,0,0,0,0,20,0,0,0,0,0,0,0,0,0,0,0,0
0,0,0,0,0,4,0,0,37,37,4,0,4,0,0,0,0,4,0,0,0,35,0,0,0,0,0,0,0,0
0,0,0,0,0,4,0,0,0,0,4,0,4,0,0,0,0,4,4,0,0,0,0,0,0,0,0,0,0,0
0,0,0,0,0,4,0,0,0,0,4,0,4,4,17,4,4,4,0,0,0,0,0,0,0,0,0,0,0,0
0,0,0,0,0,4,26,13,0,0,36,0,4,0,0,0,0,4,0,0,0,35,0,0,0,0,0,35,0,0
0,0,0,0,0,4,33,27,0,0,4,0,4,0,0,0,0,20,0,0,0,0,0,0,0,0,0,0,0,0
0,0,0,0,0,4,4,4,4,4,4,0,4,0,0,0,0,4,0,0,0,0,0,0,0,0,0,0,0,0
0,35,13,0,0,0,0,0,0,0,0,0,4,4,20,4,4,4,0,0,0,0,0,0,0,0,0,0,0,0
0,0,0,0,0,0,0,0,0,0,0,0,0,0,0,0,0,4,4,4,4,20,4,4,4,4,4,0,0,0
0,0,0,0,0,0,4,4,4,4,20,4,4,4,4,0,0,4,0,0,0,0,0,0,0,0,4,0,0,0
0,0,0,0,0,0,4,0,0,0,0,0,0,0,4,0,0,4,0,0,0,0,0,0,0,0,4,0,0,0
0,0,0,0,0,0,4,0,0,0,0,0,0,0,4,0,0,4,0,0,0,0,0,0,0,0,4,0,0,0
0,0,0,0,0,0,4,0,0,0,0,0,0,0,4,0,0,20,0,0,0,0,0,0,0,0,20,0,0,0
0,0,13,0,0,0,17,0,0,0,0,0,0,0,20,0,0,4,0,0,0,0,0,0,0,0,4,0,0,0
0,35,0,0,0,0,4,0,0,0,0,0,0,0,4,0,0,4,0,0,0,0,0,0,0,0,4,0,0,0
0,0,0,0,0,0,4,0,0,0,0,0,0,4,4,0,0,4,0,0,0,0,0,0,0,0,4,0,0,0
0,0,0,0,0,0,4,0,0,0,0,31,4,4,4,0,0,4,4,4,4,20,4,4,4,4,4,0,0,0
0,0,0,0,0,21,4,4,4,4,20,4,4,4,4,0,0,0,0,0,0,0,0,0,0,0,0,0,0,0
0,0,0,0,0,0,22,0,0,0,0,0,0,0,0,0,0,0,0,0,0,0,0,0,0,0,0,0,0,0
0,35,13,0,0,0,0,0,0,0,0,0,0,0,0,0,0,0,0,0,0,0,0,0,0,0,0,0,0,0
0,0,0,0,0,0,0,0,0,0,0,0,0,0,0,0,0,0,0,0,0,0,0,0,0,0,0,0,0,0
endlayer

layer
0,0,0,0,0,0,0,0,0,0,0,0,0,0,0,0,0,0,0,0,0,0,0,0,0,0,0,0,0,0
0,0,0,0,0,0,0,0,0,0,0,0,0,0,0,0,0,0,0,0,0,0,0,0,0,0,0,0,0,0
0,0,0,0,0,0,0,0,0,0,0,0,0,0,0,0,0,0,0,0,0,0,0,0,0,0,0,0,0,0
0,0,0,0,0,23,0,0,0,0,23,0,0,0,0,0,0,0,0,0,0,0,0,0,0,0,0,0,0,0
0,0,0,0,21,4,38,20,20,38,4,24,4,4,20,20,4,4,0,0,0,0,0,0,0,0,0,0,0,0
0,0,0,0,0,33,0,0,0,0,33,0,4,0,0,0,0,4,0,0,0,0,0,0,0,0,0,0,0,0
0,0,0,0,0,17,0,0,0,0,33,0,4,0,0,0,0,20,0,0,0,0,0,0,0,0,0,0,0,0
0,0,0,0,0,33,0,0,0,0,20,0,4,0,0,0,0,4,0,0,0,0,0,0,0,0,0,0,0,0
0,0,0,0,0,33,0,0,0,0,33,24,4,0,0,0,0,4,4,0,0,0,0,0,0,0,0,0,0,0
0,0,0,0,0,20,0,0,0,0,33,0,4,4,4,4,4,4,0,0,0,0,0,0,0,0,0,0,0,0
0,0,0,0,0,20,0,39,0,0,17,0,4,22,0,0,0,4,0,0,0,0,0,0,0,0,0,0,0,0
0,0,0,0,0,33,0,0,0,0,33,0,4,0,0,0,0,20,0,0,0,0,0,0,0,0,0,0,0,0
0,0,0,0,21,4,38,20,20,38,4,0,4,23,0,0,0,4,0,0,0,0,0,0,0,0,0,0,0,0
0,0,13,0,0,22,0,0,0,0,0,0,4,4,20,4,4,4,0,0,0,0,0,0,0,0,23,0,0,0
0,0,0,0,0,0,0,0,0,0,0,0,0,0,0,0,0,4,4,4,4,20,4,4,4,4,4,24,0,0
0,0,0,0,0,0,4,4,4,4,20,4,4,4,4,0,0,4,0,0,22,0,0,0,0,0,4,0,0,0
0,0,0,0,0,0,4,0,0,0,0,0,0,0,4,0,0,4,0,0,0,0,0,0,0,0,4,0,0,0
0,0,0,0,0,0,4,0,0,0,0,0,0,0,4,0,0,4,0,0,0,0,0,0,0,0,4,0,0,0
0,0,0,0,0,0,4,0,0,0,0,0,0,0,4,0,0,20,0,0,0,0,0,0,0,0,20,0,0,0
0,0,13,0,0,0,4,0,0,0,0,0,0,0,20,0,0,4,0,0,0,0,0,0,0,0,4,0,0,0
0,0,0,0,0,0,4,24,0,0,0,0,0,21,4,0,0,4,0,0,0,0,0,0,0,0,4,0,0,0
0,0,0,0,0,0,4,0,0,0,0,0,0,4,4,0,0,4,0,0,23,0,0,0,0,0,4,0,0,0
0,0,0,0,0,0,4,0,0,0,0,0,31,4,4,0,0,4,4,4,4,20,4,4,4,4,4,0,0,0
0,0,0,0,0,0,4,4,4,4,20,4,4,4,4,0,0,0,0,0,0,0,0,0,0,0,0,0,0,0
0,0,0,0,0,0,0,0,0,0,0,0,0,0,0,0,0,0,0,0,0,0,0,0,0,0,0,0,0,0
0,0,13,0,0,0,0,0,0,0,0,0,0,0,0,0,0,0,0,0,0,0,0,0,0,0,0,0,0,0
0,0,0,0,0,0,0,0,0,0,0,0,0,0,0,0,0,0,0,0,0,0,0,0,0,0,0,0,0,0
endlayer

layer
0,0,0,0,0,0,0,0,0,0,0,0,0,0,0,0,0,0,0,0,0,0,0,0,0,0,0,0,0,0
0,0,0,0,0,0,0,0,0,0,0,0,0,0,0,0,0,0,0,0,0,0,0,0,0,0,0,0,0,0
0,0,0,0,0,0,0,0,0,0,0,0,0,0,0,0,0,0,0,0,0,0,0,0,0,0,0,0,0,0
0,0,0,0,0,0,0,0,0,0,0,0,0,0,0,0,0,23,0,0,0,0,0,0,0,0,0,0,0,0
0,0,0,0,28,4,4,4,4,4,4,0,4,4,4,4,4,4,24,0,0,0,0,0,0,0,0,0,0,0
0,0,0,0,28,33,0,0,0,21,33,0,4,0,0,0,0,4,0,0,0,0,0,0,0,0,0,0,0,0
0,0,0,0,28,33,24,0,0,0,33,0,4,0,0,0,0,4,0,0,0,0,0,0,0,0,0,0,0,0
0,0,0,0,28,33,0,0,0,0,33,0,4,0,0,0,0,4,0,0,0,0,0,0,0,0,0,0,0,0
0,0,0,0,28,33,0,0,0,0,33,0,4,0,0,0,0,4,4,0,0,0,0,0,0,0,0,0,0,0
0,0,0,0,28,33,0,0,0,0,33,0,4,4,4,4,4,4,24,0,0,0,0,0,0,0,0,0,0,0
0,0,0,0,28,33,0,0,0,21,33,0,4,0,0,0,0,4,0,0,0,0,0,0,0,0,0,0,0,0
0,0,0,0,28,33,0,0,0,23,33,0,4,0,0,0,0,20,0,0,0,0,0,0,0,0,0,0,0,0
0,0,0,0,28,4,4,4,4,4,4,0,4,0,0,0,0,4,0,0,0,0,0,0,0,0,0,0,0,0
0,0,13,0,0,0,0,0,0,0,0,21,4,4,20,4,4,4,27,27,27,27,27,27,27,27,27,0,0,0
0,0,0,0,0,0,23,0,0,0,0,0,22,0,23,0,0,4,33,33,33,33,33,33,33,33,4,0,0,0
0,0,0,0,0,21,4,4,4,4,20,4,4,4,4,24,0,4,0,0,0,0,0,0,0,0,4,0,0,0
0,0,0,0,0,0,4,0,0,0,0,0,0,0,4,0,0,4,0,0,0,0,0,0,0,0,4,0,0,0
0,0,0,0,0,0,4,0,0,0,0,0,0,0,4,0,0,4,0,0,0,0,0,0,0,0,4,0,0,0
0,0,0,0,0,0,4,0,0,0,0,0,0,0,4,0,0,4,0,0,0,0,0,0,0,0,4,0,0,0
0,0,13,0,0,0,4,0,0,0,0,0,0,0,20,0,0,4,0,0,0,0,0,0,0,0,4,0,0,0
0,0,0,0,0,0,4,0,0,0,0,0,0,0,4,0,0,4,0,0,0,0,0,0,0,0,4,0,0,0
0,0,0,0,0,0,4,0,0,0,0,0,0,4,4,0,0,4,0,0,0,0,0,0,0,0,4,0,0,0
0,0,0,0,0,0,4,0,0,0,0,0,0,31,4,0,0,4,33,33,33,33,33,33,33,33,4,0,0,0
0,0,0,0,0,0,4,4,4,4,20,4,4,4,4,0,0,40,40,40,40,40,40,40,40,40,40,0,0,0
0,0,0,0,0,0,0,0,0,0,0,0,0,0,0,0,0,0,0,0,0,0,0,0,0,0,0,0,0,0
0,0,13,0,0,0,0,0,0,0,0,0,0,0,0,0,0,0,0,0,0,0,0,0,0,0,0,0,0,0
0,0,0,0,0,0,0,0,0,0,0,0,0,0,0,0,0,0,0,0,0,0,0,0,0,0,0,0,0,0
endlayer

layer
0,0,0,0,0,0,0,0,0,0,0,0,0,0,0,0,0,0,0,0,0,0,0,0,0,0,0,0,0,0
0,0,0,0,0,0,0,0,0,0,0,0,0,0,0,0,0,0,0,0,0,0,0,0,0,0,0,0,0,0
0,0,0,0,0,0,0,0,0,0,0,0,0,0,0,0,0,0,0,0,0,0,0,0,0,0,0,0,0,0
0,0,0,0,0,0,0,0,0,0,0,43,41,41,41,41,41,41,41,0,0,0,0,0,0,0,0,0,0,0
0,0,0,0,0,28,33,33,33,33,33,43,4,4,4,4,4,4,42,0,0,0,0,0,0,0,0,0,0,0
0,0,0,0,0,28,33,0,0,33,33,43,4,0,0,0,0,4,42,0,0,0,0,0,0,0,0,0,0,0
0,0,0,0,0,28,33,0,0,33,33,43,4,0,0,0,0,4,42,0,0,0,0,0,0,0,0,0,0,0
0,0,0,0,0,28,33,0,0,33,33,43,4,0,0,0,0,4,42,0,0,0,0,0,0,0,0,0,0,0
0,0,0,0,0,28,33,0,0,33,33,43,4,0,0,0,0,4,4,0,0,0,0,0,0,0,0,0,0,0
0,0,0,0,0,28,33,0,0,33,33,43,4,4,4,4,4,4,0,0,0,0,0,0,0,0,0,0,0,0
0,0,0,0,0,28,33,0,0,33,33,43,4,0,0,0,0,4,0,0,0,0,0,0,0,0,0,0,0,0
0,0,0,0,0,28,33,0,0,33,33,43,4,0,0,0,0,4,0,0,0,0,0,0,0,0,0,0,0,0
0,0,0,0,0,28,33,33,33,33,33,43,4,0,0,0,0,4,0,0,0,0,0,0,0,0,0,0,0,0
0,0,33,33,33,33,33,33,33,33,33,33,4,4,4,4,4,4,0,0,0,0,0,0,0,0,0,0,0,0
0,0,33,33,33,33,33,33,33,33,33,33,33,33,33,33,33,27,27,27,27,27,27,27,27,27,27,0,0,0
0,0,33,33,33,33,4,4,4,4,4,4,4,4,4,33,33,4,33,33,33,33,33,33,33,33,4,0,0,0
0,0,33,33,33,33,4,4,4,4,4,4,4,4,4,33,33,4,0,0,0,0,0,0,0,0,4,0,0,0
0,0,33,33,33,33,4,4,4,4,4,4,4,4,4,33,33,4,0,0,0,0,0,0,0,0,4,0,0,0
0,0,33,33,33,33,4,4,4,4,4,4,4,4,4,33,33,4,0,0,0,0,0,0,0,0,4,0,0,0
0,0,33,33,33,33,4,4,4,4,4,4,4,4,4,33,33,4,0,0,0,0,0,0,0,0,4,0,0,0
0,0,33,33,33,33,4,4,4,4,4,4,4,4,4,33,33,4,0,0,0,0,0,0,0,0,4,0,0,0
0,0,33,33,33,33,4,4,4,4,4,4,4,16,4,33,33,4,33,33,33,33,33,33,33,33,4,0,0,0
0,0,33,33,33,33,4,4,4,4,4,0,0,0,4,33,33,40,40,40,40,40,40,40,40,40,40,0,0,0
0,0,33,33,33,33,4,4,4,4,4,4,4,4,4,33,33,0,0,0,0,0,0,0,0,0,0,0,0,0
0,0,33,33,33,33,33,33,33,33,33,33,33,33,33,33,33,0,0,0,0,0,0,0,0,0,0,0,0,0
0,0,33,33,33,33,33,33,33,33,33,33,33,33,33,33,33,0,0,0,0,0,0,0,0,0,0,0,0,0
0,0,0,0,0,0,0,0,0,0,0,0,0,0,0,0,0,0,0,0,0,0,0,0,0,0,0,0,0,0
endlayer

layer
0,0,0,0,0,0,0,0,0,0,0,0,0,0,0,0,0,0,0,0,0,0,0,0,0,0,0,0,0,0
0,0,0,0,0,0,0,0,0,0,0,0,0,0,0,0,0,0,0,0,0,0,0,0,0,0,0,0,0,0
0,0,0,0,0,0,0,0,0,0,0,0,0,0,0,0,0,0,0,0,0,0,0,0,0,0,0,0,0,0
0,0,0,0,0,0,0,0,0,0,0,0,0,0,0,0,0,0,0,0,0,0,0,0,0,0,0,0,0,0
0,0,0,0,0,0,28,33,33,26,0,0,25,25,25,33,25,25,0,0,0,0,0,0,0,0,0,0,0,0
0,0,0,0,0,0,28,33,33,26,0,0,25,25,25,25,25,25,0,0,0,0,0,0,0,0,0,0,0,0
0,0,0,0,0,0,28,33,33,26,0,0,25,25,25,25,25,25,0,0,0,0,0,0,0,0,0,0,0,0
0,0,0,0,0,0,28,33,33,26,0,0,25,25,25,25,25,25,0,0,0,0,0,0,0,0,0,0,0,0
0,0,0,0,0,0,28,33,33,26,0,0,27,27,27,27,27,27,0,0,0,0,0,0,0,0,0,0,0,0
0,0,0,0,0,0,28,33,33,26,0,21,4,33,33,33,33,4,0,0,0,0,0,0,0,0,0,0,0,0
0,0,0,0,0,0,28,33,33,26,0,0,4,0,0,0,0,4,0,0,0,0,0,0,0,0,0,0,0,0
0,0,0,0,0,0,28,33,33,26,0,0,4,0,0,0,0,4,0,0,0,0,0,0,0,0,0,0,0,0
0,0,0,0,0,0,28,33,33,26,0,0,4,0,0,0,0,4,0,0,0,0,0,0,0,0,0,0,0,0
0,0,13,13,13,13,13,13,13,13,13,0,4,33,33,33,33,4,0,0,0,0,0,0,0,0,0,0,0,0
0,0,13,0,0,0,0,0,0,0,0,0,0,0,0,0,0,0,0,0,0,0,0,0,0,0,0,0,0,0
0,0,13,0,0,0,4,4,4,4,4,4,4,4,4,0,0,27,27,27,27,27,27,27,27,27,27,0,0,0
0,0,13,0,0,0,4,0,0,0,0,45,45,0,4,0,0,4,33,33,33,33,33,33,33,33,4,0,0,0
0,0,13,0,0,0,4,0,0,0,0,0,0,0,44,0,0,4,0,0,0,0,0,0,0,0,4,0,0,0
0,0,13,0,0,0,4,0,0,0,0,0,0,0,4,0,0,4,0,0,0,0,0,0,0,0,4,0,0,0
0,0,13,0,0,0,4,0,0,0,0,0,0,0,4,0,0,4,0,0,0,0,0,0,0,0,4,0,0,0
0,0,13,0,0,0,4,0,0,0,0,0,0,0,4,0,0,4,33,33,33,33,33,33,33,33,4,0,0,0
0,0,13,0,0,0,19,0,0,0,0,0,0,0,4,0,13,40,40,40,40,40,40,40,40,40,40,0,0,0
0,0,13,0,0,0,4,0,0,0,34,0,0,0,4,0,13,0,0,0,0,0,0,0,0,0,0,0,0,0
0,0,13,0,0,0,4,4,4,4,4,4,4,4,4,0,13,0,0,0,0,0,0,0,0,0,0,0,0,0
0,0,13,0,0,0,0,0,0,0,0,0,0,0,0,0,13,0,0,0,0,0,0,0,0,0,0,0,0,0
0,0,13,13,13,13,13,13,13,13,13,13,13,13,13,13,13,0,0,0,0,0,0,0,0,0,0,0,0,0
0,0,0,0,0,0,0,0,0,0,0,0,0,0,0,0,0,0,0,0,0,0,0,0,0,0,0,0,0,0
endlayer

layer
0,0,0,0,0,0,0,0,0,0,0,0,0,0,0,0,0,0,0,0,0,0,0,0,0,0,0,0,0,0
0,0,0,0,0,0,0,0,0,0,0,0,0,0,0,0,0,0,0,0,0,0,0,0,0,0,0,0,0,0
0,0,0,0,0,0,0,0,0,0,0,0,0,0,0,0,0,0,0,0,0,0,0,0,0,0,0,0,0,0
0,0,0,0,0,0,0,0,0,0,0,0,0,0,0,0,0,0,0,0,0,0,0,0,0,0,0,0,0,0
0,0,0,0,0,0,0,28,26,0,0,0,0,0,0,35,0,0,0,0,0,0,0,0,0,0,0,0,0,0
0,0,0,0,0,0,0,28,26,0,0,0,0,0,0,0,0,0,0,0,0,0,0,0,0,0,0,0,0,0
0,0,0,0,0,0,0,28,26,0,0,0,0,0,0,0,0,0,0,0,0,0,0,0,0,0,0,0,0,0
0,0,0,0,0,0,0,28,26,0,0,0,0,0,0,0,0,0,0,0,0,0,0,0,0,0,0,0,0,0
0,0,0,0,0,0,0,28,26,0,0,0,0,0,0,0,0,0,0,0,0,0,0,0,0,0,0,0,0,0
0,0,0,0,0,0,0,28,26,0,0,0,27,27,27,27,27,27,0,0,0,0,0,0,0,0,0,0,0,0
0,0,0,0,0,0,0,28,26,0,0,0,4,33,33,33,33,4,0,0,0,0,0,0,0,0,0,0,0,0
0,0,0,0,0,0,0,28,26,0,0,0,4,0,0,0,0,4,0,0,0,0,0,0,0,0,0,0,0,0
0,0,0,0,0,0,0,28,26,0,0,0,4,33,33,33,33,4,0,0,0,0,0,0,0,0,0,0,0,0
0,0,35,0,0,0,0,0,0,0,35,0,40,40,40,40,40,40,0,0,0,0,0,0,0,0,0,0,0,0
0,0,0,0,0,0,0,0,0,0,0,0,0,0,0,0,0,0,0,0,0,0,0,0,0,0,0,0,0,0
0,0,0,0,0,0,4,4,4,4,20,4,4,4,4,0,0,0,0,0,0,0,0,0,0,0,0,0,0,0
0,0,0,0,0,0,4,0,0,0,0,0,0,0,4,0,0,27,27,27,27,27,27,27,27,27,27,0,0,0
0,0,0,0,0,0,4,0,0,0,0,0,0,0,17,0,0,4,33,33,33,33,33,33,33,33,4,0,0,0
0,0,0,0,0,0,4,0,0,0,0,0,0,0,4,0,0,4,0,0,0,0,0,0,0,0,4,0,0,0
0,0,0,0,0,0,20,0,0,0,0,0,0,0,20,0,0,4,33,33,33,33,33,33,33,33,4,0,0,0
0,0,35,0,0,0,4,0,0,0,0,0,0,0,4,0,0,40,40,40,40,40,40,40,40,40,40,0,0,0
0,0,0,0,0,0,17,0,0,0,0,0,0,0,4,0,0,0,0,0,0,0,0,0,0,0,0,0,0,0
0,0,0,0,0,0,4,0,0,0,0,0,0,0,4,0,0,0,0,0,0,0,0,0,0,0,0,0,0,0
0,0,0,0,0,0,4,4,4,4,20,4,4,4,4,0,0,0,0,0,0,0,0,0,0,0,0,0,0,0
0,0,0,0,0,0,0,0,0,0,0,0,0,0,0,0,0,0,0,0,0,0,0,0,0,0,0,0,0,0
0,0,35,0,0,0,0,0,0,0,0,0,0,0,0,0,35,0,0,0,0,0,0,0,0,0,0,0,0,0
0,0,0,0,0,0,0,0,0,0,0,0,0,0,0,0,0,0,0,0,0,0,0,0,0,0,0,0,0,0
endlayer

layer
0,0,0,0,0,0,0,0,0,0,0,0,0,0,0,0,0,0,0,0,0,0,0,0,0,0,0,0,0,0
0,0,0,0,0,0,0,0,0,0,0,0,0,0,0,0,0,0,0,0,0,0,0,0,0,0,0,0,0,0
0,0,0,0,0,0,0,0,0,0,0,0,0,0,0,0,0,0,0,0,0,0,0,0,0,0,0,0,0,0
0,0,0,0,0,0,0,0,0,0,0,0,0,0,0,0,0,0,0,0,0,0,0,0,0,0,0,0,0,0
0,0,0,0,0,0,0,0,0,0,0,0,0,0,0,0,0,0,0,0,0,0,0,0,0,0,0,0,0,0
0,0,0,0,0,0,0,0,0,0,0,0,0,0,0,0,0,0,0,0,0,0,0,0,0,0,0,0,0,0
0,0,0,0,0,0,0,0,0,0,0,0,0,0,0,0,0,0,0,0,0,0,0,0,0,0,0,0,0,0
0,0,0,0,0,0,0,0,0,0,0,0,0,0,0,0,0,0,0,0,0,0,0,0,0,0,0,0,0,0
0,0,0,0,0,0,0,0,0,0,0,0,0,0,0,0,0,0,0,0,0,0,0,0,0,0,0,0,0,0
0,0,0,0,0,0,0,0,0,0,0,0,0,0,0,0,0,0,0,0,0,0,0,0,0,0,0,0,0,0
0,0,0,0,0,0,0,0,0,0,0,0,27,27,27,27,27,27,0,0,0,0,0,0,0,0,0,0,0,0
0,0,0,0,0,0,0,0,0,0,0,0,33,33,33,33,33,33,0,0,0,0,0,0,0,0,0,0,0,0
0,0,0,0,0,0,0,0,0,0,0,0,40,40,40,40,40,40,0,0,0,0,0,0,0,0,0,0,0,0
0,0,0,0,0,0,0,0,0,0,0,0,0,0,0,0,0,0,0,0,0,0,0,0,0,0,0,0,0,0
0,0,0,0,0,0,23,0,0,0,0,0,0,0,23,0,0,0,0,0,0,0,0,0,0,0,0,0,0,0
0,0,0,0,0,21,4,4,4,4,20,4,4,4,4,24,0,0,0,0,0,0,0,0,0,0,0,0,0,0
0,0,0,0,0,0,4,0,0,0,0,0,0,0,4,0,0,0,0,0,0,0,0,0,0,0,0,0,0,0
0,0,0,0,0,0,4,0,0,0,0,0,0,0,4,0,0,27,27,27,27,27,27,27,27,27,27,0,0,0
0,0,0,0,0,0,4,0,0,0,0,0,0,0,4,0,0,33,33,33,33,33,33,33,33,33,33,0,0,0
0,0,0,0,0,0,20,0,0,0,0,0,0,0,20,0,0,40,40,40,40,40,40,40,40,40,40,0,0,0
0,0,0,0,0,0,4,24,0,0,0,0,0,21,4,0,0,0,0,0,0,0,0,0,0,0,0,0,0,0
0,0,0,0,0,0,4,0,0,0,0,0,0,0,4,0,0,0,0,0,0,0,0,0,0,0,0,0,0,0
0,0,0,0,0,0,4,0,0,0,0,0,0,0,4,0,0,0,0,0,0,0,0,0,0,0,0,0,0,0
0,0,0,0,0,21,4,4,4,4,20,4,4,4,4,24,0,0,0,0,0,0,0,0,0,0,0,0,0,0
0,0,0,0,0,0,22,0,0,0,0,0,0,0,22,0,0,0,0,0,0,0,0,0,0,0,0,0,0,0
0,0,0,0,0,0,0,0,0,0,0,0,0,0,0,0,0,0,0,0,0,0,0,0,0,0,0,0,0,0
0,0,0,0,0,0,0,0,0,0,0,0,0,0,0,0,0,0,0,0,0,0,0,0,0,0,0,0,0,0
endlayer

layer
0,0,0,0,0,0,0,0,0,0,0,0,0,0,0,0,0,0,0,0,0,0,0,0,0,0,0,0,0,0
0,0,0,0,0,0,0,0,0,0,0,0,0,0,0,0,0,0,0,0,0,0,0,0,0,0,0,0,0,0
0,0,0,0,0,0,0,0,0,0,0,0,0,0,0,0,0,0,0,0,0,0,0,0,0,0,0,0,0,0
0,0,0,0,0,0,0,0,0,0,0,0,0,0,0,0,0,0,0,0,0,0,0,0,0,0,0,0,0,0
0,0,0,0,0,0,0,0,0,0,0,0,0,0,0,0,0,0,0,0,0,0,0,0,0,0,0,0,0,0
0,0,0,0,0,0,0,0,0,0,0,0,0,0,0,0,0,0,0,0,0,0,0,0,0,0,0,0,0,0
0,0,0,0,0,0,0,0,0,0,0,0,0,0,0,0,0,0,0,0,0,0,0,0,0,0,0,0,0,0
0,0,0,0,0,0,0,0,0,0,0,0,0,0,0,0,0,0,0,0,0,0,0,0,0,0,0,0,0,0
0,0,0,0,0,0,0,0,0,0,0,0,0,0,0,0,0,0,0,0,0,0,0,0,0,0,0,0,0,0
0,0,0,0,0,0,0,0,0,0,0,0,0,0,0,0,0,0,0,0,0,0,0,0,0,0,0,0,0,0
0,0,0,0,0,0,0,0,0,0,0,0,0,0,0,0,0,0,0,0,0,0,0,0,0,0,0,0,0,0
0,0,0,0,0,0,0,0,0,0,0,0,35,0,0,0,0,35,0,0,0,0,0,0,0,0,0,0,0,0
0,0,0,0,0,0,0,0,0,0,0,0,0,0,0,0,0,0,0,0,0,0,0,0,0,0,0,0,0,0
0,0,0,0,0,0,0,0,0,0,0,0,0,0,0,0,0,0,0,0,0,0,0,0,0,0,0,0,0,0
0,0,0,0,0,0,0,0,0,0,0,0,0,0,0,0,0,0,0,0,0,0,0,0,0,0,0,0,0,0
0,0,0,0,0,28,4,4,4,4,4,4,4,4,4,26,0,0,0,0,0,0,0,0,0,0,0,0,0,0
0,0,0,0,0,28,33,0,0,0,0,0,0,0,33,26,0,0,0,0,0,0,0,0,0,0,0,0,0,0
0,0,0,0,0,28,33,0,0,0,0,0,0,0,33,26,0,0,0,0,0,0,0,0,0,0,0,0,0,0
0,0,0,0,0,28,33,0,0,0,0,0,0,0,33,26,0,35,0,0,0,0,0,0,0,0,35,0,0,0
0,0,0,0,0,28,33,0,0,0,0,0,0,0,33,26,0,0,0,0,0,0,0,0,0,0,0,0,0,0
0,0,0,0,0,28,33,0,0,0,0,0,0,0,33,26,0,0,0,0,0,0,0,0,0,0,0,0,0,0
0,0,0,0,0,28,33,0,0,0,0,0,0,0,33,26,0,0,0,0,0,0,0,0,0,0,0,0,0,0
0,0,0,0,0,28,33,0,0,0,0,0,0,0,33,26,0,0,0,0,0,0,0,0,0,0,0,0,0,0
0,0,0,0,0,28,4,4,4,4,4,4,4,4,4,26,0,0,0,0,0,0,0,0,0,0,0,0,0,0
0,0,0,0,0,0,0,0,0,0,0,0,0,0,0,0,0,0,0,0,0,0,0,0,0,0,0,0,0,0
0,0,0,0,0,0,0,0,0,0,0,0,0,0,0,0,0,0,0,0,0,0,0,0,0,0,0,0,0,0
0,0,0,0,0,0,0,0,0,0,0,0,0,0,0,0,0,0,0,0,0,0,0,0,0,0,0,0,0,0
endlayer

layer
0,0,0,0,0,0,0,0,0,0,0,0,0,0,0,0,0,0,0,0,0,0,0,0,0,0,0,0,0,0
0,0,0,0,0,0,0,0,0,0,0,0,0,0,0,0,0,0,0,0,0,0,0,0,0,0,0,0,0,0
0,0,0,0,0,0,0,0,0,0,0,0,0,0,0,0,0,0,0,0,0,0,0,0,0,0,0,0,0,0
0,0,0,0,0,0,0,0,0,0,0,0,0,0,0,0,0,0,0,0,0,0,0,0,0,0,0,0,0,0
0,0,0,0,0,0,0,0,0,0,0,0,0,0,0,0,0,0,0,0,0,0,0,0,0,0,0,0,0,0
0,0,0,0,0,0,0,0,0,0,0,0,0,0,0,0,0,0,0,0,0,0,0,0,0,0,0,0,0,0
0,0,0,0,0,0,0,0,0,0,0,0,0,0,0,0,0,0,0,0,0,0,0,0,0,0,0,0,0,0
0,0,0,0,0,0,0,0,0,0,0,0,0,0,0,0,0,0,0,0,0,0,0,0,0,0,0,0,0,0
0,0,0,0,0,0,0,0,0,0,0,0,0,0,0,0,0,0,0,0,0,0,0,0,0,0,0,0,0,0
0,0,0,0,0,0,0,0,0,0,0,0,0,0,0,0,0,0,0,0,0,0,0,0,0,0,0,0,0,0
0,0,0,0,0,0,0,0,0,0,0,0,0,0,0,0,0,0,0,0,0,0,0,0,0,0,0,0,0,0
0,0,0,0,0,0,0,0,0,0,0,0,0,0,0,0,0,0,0,0,0,0,0,0,0,0,0,0,0,0
0,0,0,0,0,0,0,0,0,0,0,0,0,0,0,0,0,0,0,0,0,0,0,0,0,0,0,0,0,0
0,0,0,0,0,0,0,0,0,0,0,0,0,0,0,0,0,0,0,0,0,0,0,0,0,0,0,0,0,0
0,0,0,0,0,0,0,0,0,0,0,0,0,0,0,0,0,0,0,0,0,0,0,0,0,0,0,0,0,0
0,0,0,0,0,0,28,4,4,4,4,4,4,4,26,0,0,0,0,0,0,0,0,0,0,0,0,0,0,0
0,0,0,0,0,0,28,33,0,0,0,0,0,33,26,0,0,0,0,0,0,0,0,0,0,0,0,0,0,0
0,0,0,0,0,0,28,33,0,0,0,0,0,33,26,0,0,0,0,0,0,0,0,0,0,0,0,0,0,0
0,0,0,0,0,0,28,33,0,0,0,0,0,33,26,0,0,0,0,0,0,0,0,0,0,0,0,0,0,0
0,0,0,0,0,0,28,33,0,0,0,0,0,33,26,0,0,0,0,0,0,0,0,0,0,0,0,0,0,0
0,0,0,0,0,0,28,33,0,0,0,0,0,33,26,0,0,0,0,0,0,0,0,0,0,0,0,0,0,0
0,0,0,0,0,0,28,33,0,0,0,0,0,33,26,0,0,0,0,0,0,0,0,0,0,0,0,0,0,0
0,0,0,0,0,0,28,33,0,0,0,0,0,33,26,0,0,0,0,0,0,0,0,0,0,0,0,0,0,0
0,0,0,0,0,0,28,4,4,4,4,4,4,4,26,0,0,0,0,0,0,0,0,0,0,0,0,0,0,0
0,0,0,0,0,0,0,0,0,0,0,0,0,0,0,0,0,0,0,0,0,0,0,0,0,0,0,0,0,0
0,0,0,0,0,0,0,0,0,0,0,0,0,0,0,0,0,0,0,0,0,0,0,0,0,0,0,0,0,0
0,0,0,0,0,0,0,0,0,0,0,0,0,0,0,0,0,0,0,0,0,0,0,0,0,0,0,0,0,0
endlayer

layer
0,0,0,0,0,0,0,0,0,0,0,0,0,0,0,0,0,0,0,0,0,0,0,0,0,0,0,0,0,0
0,0,0,0,0,0,0,0,0,0,0,0,0,0,0,0,0,0,0,0,0,0,0,0,0,0,0,0,0,0
0,0,0,0,0,0,0,0,0,0,0,0,0,0,0,0,0,0,0,0,0,0,0,0,0,0,0,0,0,0
0,0,0,0,0,0,0,0,0,0,0,0,0,0,0,0,0,0,0,0,0,0,0,0,0,0,0,0,0,0
0,0,0,0,0,0,0,0,0,0,0,0,0,0,0,0,0,0,0,0,0,0,0,0,0,0,0,0,0,0
0,0,0,0,0,0,0,0,0,0,0,0,0,0,0,0,0,0,0,0,0,0,0,0,0,0,0,0,0,0
0,0,0,0,0,0,0,0,0,0,0,0,0,0,0,0,0,0,0,0,0,0,0,0,0,0,0,0,0,0
0,0,0,0,0,0,0,0,0,0,0,0,0,0,0,0,0,0,0,0,0,0,0,0,0,0,0,0,0,0
0,0,0,0,0,0,0,0,0,0,0,0,0,0,0,0,0,0,0,0,0,0,0,0,0,0,0,0,0,0
0,0,0,0,0,0,0,0,0,0,0,0,0,0,0,0,0,0,0,0,0,0,0,0,0,0,0,0,0,0
0,0,0,0,0,0,0,0,0,0,0,0,0,0,0,0,0,0,0,0,0,0,0,0,0,0,0,0,0,0
0,0,0,0,0,0,0,0,0,0,0,0,0,0,0,0,0,0,0,0,0,0,0,0,0,0,0,0,0,0
0,0,0,0,0,0,0,0,0,0,0,0,0,0,0,0,0,0,0,0,0,0,0,0,0,0,0,0,0,0
0,0,0,0,0,0,0,0,0,0,0,0,0,0,0,0,0,0,0,0,0,0,0,0,0,0,0,0,0,0
0,0,0,0,0,0,0,0,0,0,0,0,0,0,0,0,0,0,0,0,0,0,0,0,0,0,0,0,0,0
0,0,0,0,0,0,0,28,4,4,4,4,4,26,0,0,0,0,0,0,0,0,0,0,0,0,0,0,0,0
0,0,0,0,0,0,0,28,33,0,0,0,33,26,0,0,0,0,0,0,0,0,0,0,0,0,0,0,0,0
0,0,0,0,0,0,0,28,33,0,0,0,33,26,0,0,0,0,0,0,0,0,0,0,0,0,0,0,0,0
0,0,0,0,0,0,0,28,33,0,0,0,33,26,0,0,0,0,0,0,0,0,0,0,0,0,0,0,0,0
0,0,0,0,0,0,0,28,33,0,0,0,33,26,0,0,0,0,0,0,0,0,0,0,0,0,0,0,0,0
0,0,0,0,0,0,0,28,33,0,0,0,33,26,0,0,0,0,0,0,0,0,0,0,0,0,0,0,0,0
0,0,0,0,0,0,0,28,33,0,0,0,33,26,0,0,0,0,0,0,0,0,0,0,0,0,0,0,0,0
0,0,0,0,0,0,0,28,33,0,0,0,33,26,0,0,0,0,0,0,0,0,0,0,0,0,0,0,0,0
0,0,0,0,0,0,0,28,4,4,4,4,4,26,0,0,0,0,0,0,0,0,0,0,0,0,0,0,0,0
0,0,0,0,0,0,0,0,0,0,0,0,0,0,0,0,0,0,0,0,0,0,0,0,0,0,0,0,0,0
0,0,0,0,0,0,0,0,0,0,0,0,0,0,0,0,0,0,0,0,0,0,0,0,0,0,0,0,0,0
0,0,0,0,0,0,0,0,0,0,0,0,0,0,0,0,0,0,0,0,0,0,0,0,0,0,0,0,0,0
endlayer

layer
0,0,0,0,0,0,0,0,0,0,0,0,0,0,0,0,0,0,0,0,0,0,0,0,0,0,0,0,0,0
0,0,0,0,0,0,0,0,0,0,0,0,0,0,0,0,0,0,0,0,0,0,0,0,0,0,0,0,0,0
0,0,0,0,0,0,0,0,0,0,0,0,0,0,0,0,0,0,0,0,0,0,0,0,0,0,0,0,0,0
0,0,0,0,0,0,0,0,0,0,0,0,0,0,0,0,0,0,0,0,0,0,0,0,0,0,0,0,0,0
0,0,0,0,0,0,0,0,0,0,0,0,0,0,0,0,0,0,0,0,0,0,0,0,0,0,0,0,0,0
0,0,0,0,0,0,0,0,0,0,0,0,0,0,0,0,0,0,0,0,0,0,0,0,0,0,0,0,0,0
0,0,0,0,0,0,0,0,0,0,0,0,0,0,0,0,0,0,0,0,0,0,0,0,0,0,0,0,0,0
0,0,0,0,0,0,0,0,0,0,0,0,0,0,0,0,0,0,0,0,0,0,0,0,0,0,0,0,0,0
0,0,0,0,0,0,0,0,0,0,0,0,0,0,0,0,0,0,0,0,0,0,0,0,0,0,0,0,0,0
0,0,0,0,0,0,0,0,0,0,0,0,0,0,0,0,0,0,0,0,0,0,0,0,0,0,0,0,0,0
0,0,0,0,0,0,0,0,0,0,0,0,0,0,0,0,0,0,0,0,0,0,0,0,0,0,0,0,0,0
0,0,0,0,0,0,0,0,0,0,0,0,0,0,0,0,0,0,0,0,0,0,0,0,0,0,0,0,0,0
0,0,0,0,0,0,0,0,0,0,0,0,0,0,0,0,0,0,0,0,0,0,0,0,0,0,0,0,0,0
0,0,0,0,0,0,0,0,0,0,0,0,0,0,0,0,0,0,0,0,0,0,0,0,0,0,0,0,0,0
0,0,0,0,0,0,0,0,0,0,0,0,0,0,0,0,0,0,0,0,0,0,0,0,0,0,0,0,0,0
0,0,0,0,0,0,0,0,28,4,4,4,26,0,0,0,0,0,0,0,0,0,0,0,0,0,0,0,0,0
0,0,0,0,0,0,0,0,28,33,0,33,26,0,0,0,0,0,0,0,0,0,0,0,0,0,0,0,0,0
0,0,0,0,0,0,0,0,28,33,0,33,26,0,0,0,0,0,0,0,0,0,0,0,0,0,0,0,0,0
0,0,0,0,0,0,0,0,28,33,0,33,26,0,0,0,0,0,0,0,0,0,0,0,0,0,0,0,0,0
0,0,0,0,0,0,0,0,28,33,0,33,26,0,0,0,0,0,0,0,0,0,0,0,0,0,0,0,0,0
0,0,0,0,0,0,0,0,28,33,0,33,26,0,0,0,0,0,0,0,0,0,0,0,0,0,0,0,0,0
0,0,0,0,0,0,0,0,28,33,0,33,26,0,0,0,0,0,0,0,0,0,0,0,0,0,0,0,0,0
0,0,0,0,0,0,0,0,28,33,0,33,26,0,0,0,0,0,0,0,0,0,0,0,0,0,0,0,0,0
0,0,0,0,0,0,0,0,28,4,4,4,26,0,0,0,0,0,0,0,0,0,0,0,0,0,0,0,0,0
0,0,0,0,0,0,0,0,0,0,0,0,0,0,0,0,0,0,0,0,0,0,0,0,0,0,0,0,0,0
0,0,0,0,0,0,0,0,0,0,0,0,0,0,0,0,0,0,0,0,0,0,0,0,0,0,0,0,0,0
0,0,0,0,0,0,0,0,0,0,0,0,0,0,0,0,0,0,0,0,0,0,0,0,0,0,0,0,0,0
endlayer

layer
0,0,0,0,0,0,0,0,0,0,0,0,0,0,0,0,0,0,0,0,0,0,0,0,0,0,0,0,0,0
0,0,0,0,0,0,0,0,0,0,0,0,0,0,0,0,0,0,0,0,0,0,0,0,0,0,0,0,0,0
0,0,0,0,0,0,0,0,0,0,0,0,0,0,0,0,0,0,0,0,0,0,0,0,0,0,0,0,0,0
0,0,0,0,0,0,0,0,0,0,0,0,0,0,0,0,0,0,0,0,0,0,0,0,0,0,0,0,0,0
0,0,0,0,0,0,0,0,0,0,0,0,0,0,0,0,0,0,0,0,0,0,0,0,0,0,0,0,0,0
0,0,0,0,0,0,0,0,0,0,0,0,0,0,0,0,0,0,0,0,0,0,0,0,0,0,0,0,0,0
0,0,0,0,0,0,0,0,0,0,0,0,0,0,0,0,0,0,0,0,0,0,0,0,0,0,0,0,0,0
0,0,0,0,0,0,0,0,0,0,0,0,0,0,0,0,0,0,0,0,0,0,0,0,0,0,0,0,0,0
0,0,0,0,0,0,0,0,0,0,0,0,0,0,0,0,0,0,0,0,0,0,0,0,0,0,0,0,0,0
0,0,0,0,0,0,0,0,0,0,0,0,0,0,0,0,0,0,0,0,0,0,0,0,0,0,0,0,0,0
0,0,0,0,0,0,0,0,0,0,0,0,0,0,0,0,0,0,0,0,0,0,0,0,0,0,0,0,0,0
0,0,0,0,0,0,0,0,0,0,0,0,0,0,0,0,0,0,0,0,0,0,0,0,0,0,0,0,0,0
0,0,0,0,0,0,0,0,0,0,0,0,0,0,0,0,0,0,0,0,0,0,0,0,0,0,0,0,0,0
0,0,0,0,0,0,0,0,0,0,0,0,0,0,0,0,0,0,0,0,0,0,0,0,0,0,0,0,0,0
0,0,0,0,0,0,0,0,0,0,0,0,0,0,0,0,0,0,0,0,0,0,0,0,0,0,0,0,0,0
0,0,0,0,0,0,0,0,0,28,33,26,0,0,0,0,0,0,0,0,0,0,0,0,0,0,0,0,0,0
0,0,0,0,0,0,0,0,0,28,33,26,0,0,0,0,0,0,0,0,0,0,0,0,0,0,0,0,0,0
0,0,0,0,0,0,0,0,0,28,33,26,0,0,0,0,0,0,0,0,0,0,0,0,0,0,0,0,0,0
0,0,0,0,0,0,0,0,0,28,33,26,0,0,0,0,0,0,0,0,0,0,0,0,0,0,0,0,0,0
0,0,0,0,0,0,0,0,0,28,33,26,0,0,0,0,0,0,0,0,0,0,0,0,0,0,0,0,0,0
0,0,0,0,0,0,0,0,0,28,33,26,0,0,0,0,0,0,0,0,0,0,0,0,0,0,0,0,0,0
0,0,0,0,0,0,0,0,0,28,33,26,0,0,0,0,0,0,0,0,0,0,0,0,0,0,0,0,0,0
0,0,0,0,0,0,0,0,0,28,33,26,0,0,0,0,0,0,0,0,0,0,0,0,0,0,0,0,0,0
0,0,0,0,0,0,0,0,0,28,33,26,0,0,0,0,0,0,0,0,0,0,0,0,0,0,0,0,0,0
0,0,0,0,0,0,0,0,0,0,0,0,0,0,0,0,0,0,0,0,0,0,0,0,0,0,0,0,0,0
0,0,0,0,0,0,0,0,0,0,0,0,0,0,0,0,0,0,0,0,0,0,0,0,0,0,0,0,0,0
0,0,0,0,0,0,0,0,0,0,0,0,0,0,0,0,0,0,0,0,0,0,0,0,0,0,0,0,0,0
endlayer

layer
0,0,0,0,0,0,0,0,0,0,0,0,0,0,0,0,0,0,0,0,0,0,0,0,0,0,0,0,0,0
0,0,0,0,0,0,0,0,0,0,0,0,0,0,0,0,0,0,0,0,0,0,0,0,0,0,0,0,0,0
0,0,0,0,0,0,0,0,0,0,0,0,0,0,0,0,0,0,0,0,0,0,0,0,0,0,0,0,0,0
0,0,0,0,0,0,0,0,0,0,0,0,0,0,0,0,0,0,0,0,0,0,0,0,0,0,0,0,0,0
0,0,0,0,0,0,0,0,0,0,0,0,0,0,0,0,0,0,0,0,0,0,0,0,0,0,0,0,0,0
0,0,0,0,0,0,0,0,0,0,0,0,0,0,0,0,0,0,0,0,0,0,0,0,0,0,0,0,0,0
0,0,0,0,0,0,0,0,0,0,0,0,0,0,0,0,0,0,0,0,0,0,0,0,0,0,0,0,0,0
0,0,0,0,0,0,0,0,0,0,0,0,0,0,0,0,0,0,0,0,0,0,0,0,0,0,0,0,0,0
0,0,0,0,0,0,0,0,0,0,0,0,0,0,0,0,0,0,0,0,0,0,0,0,0,0,0,0,0,0
0,0,0,0,0,0,0,0,0,0,0,0,0,0,0,0,0,0,0,0,0,0,0,0,0,0,0,0,0,0
0,0,0,0,0,0,0,0,0,0,0,0,0,0,0,0,0,0,0,0,0,0,0,0,0,0,0,0,0,0
0,0,0,0,0,0,0,0,0,0,0,0,0,0,0,0,0,0,0,0,0,0,0,0,0,0,0,0,0,0
0,0,0,0,0,0,0,0,0,0,0,0,0,0,0,0,0,0,0,0,0,0,0,0,0,0,0,0,0,0
0,0,0,0,0,0,0,0,0,0,0,0,0,0,0,0,0,0,0,0,0,0,0,0,0,0,0,0,0,0
0,0,0,0,0,0,0,0,0,0,0,0,0,0,0,0,0,0,0,0,0,0,0,0,0,0,0,0,0,0
0,0,0,0,0,0,0,0,0,0,35,0,0,0,0,0,0,0,0,0,0,0,0,0,0,0,0,0,0,0
0,0,0,0,0,0,0,0,0,0,0,0,0,0,0,0,0,0,0,0,0,0,0,0,0,0,0,0,0,0
0,0,0,0,0,0,0,0,0,0,0,0,0,0,0,0,0,0,0,0,0,0,0,0,0,0,0,0,0,0
0,0,0,0,0,0,0,0,0,0,0,0,0,0,0,0,0,0,0,0,0,0,0,0,0,0,0,0,0,0
0,0,0,0,0,0,0,0,0,0,0,0,0,0,0,0,0,0,0,0,0,0,0,0,0,0,0,0,0,0
0,0,0,0,0,0,0,0,0,0,0,0,0,0,0,0,0,0,0,0,0,0,0,0,0,0,0,0,0,0
0,0,0,0,0,0,0,0,0,0,0,0,0,0,0,0,0,0,0,0,0,0,0,0,0,0,0,0,0,0
0,0,0,0,0,0,0,0,0,0,0,0,0,0,0,0,0,0,0,0,0,0,0,0,0,0,0,0,0,0
0,0,0,0,0,0,0,0,0,0,35,0,0,0,0,0,0,0,0,0,0,0,0,0,0,0,0,0,0,0
0,0,0,0,0,0,0,0,0,0,0,0,0,0,0,0,0,0,0,0,0,0,0,0,0,0,0,0,0,0
0,0,0,0,0,0,0,0,0,0,0,0,0,0,0,0,0,0,0,0,0,0,0,0,0,0,0,0,0,0
0,0,0,0,0,0,0,0,0,0,0,0,0,0,0,0,0,0,0,0,0,0,0,0,0,0,0,0,0,0
endlayer

