# Converted from schematic
# author:MohawkyMagoo

weight=10
embed_into_distance=4
#acceptable_target_blocks=1,2,3,12,13
dimensions=39,13,11
#allowable_overhang=0
max_cut_in=2
#cut_in_buffer=1
max_leveling=2
#leveling_buffer=1
#preserve_water=0
#preserve_lava=0
#preserve_plants=0


rule1=0,100,4
rule2=0,100,3
rule3=0,100,98
rule4=0,100,43-5
rule5=0,100,109-1
rule6=0,100,109-2
rule7=0,100,61-5
rule8=0,100,109
rule9=0,100,53-1
rule10=0,100,85
rule11=0,100,53-2
rule12=0,100,54-0-MEDIUM
rule13=0,100,71-2
rule14=0,100,72
rule15=0,100,50-4
rule16=0,100,50-2
rule17=0,100,50-1
rule18=0,100,50-3
rule19=0,100,50-5
rule20=0,100,69-3
rule21=0,100,71-8
rule22=0,100,5
rule23=0,100,71
rule24=0,100,101
rule25=0,100,69-2
rule26=0,100,44-5
rule27=0,100,65-4


layer
0,0,0,0,0,0,0,0,0,0,0
0,0,1,0,0,1,0,0,1,0,0
0,1,2,3,3,2,3,3,2,1,0
0,0,4,2,2,2,2,2,3,0,0
0,0,4,2,2,2,2,2,3,0,0
0,1,2,2,2,2,2,2,2,1,0
0,0,3,2,2,2,2,2,3,0,0
0,0,3,2,2,2,2,2,3,0,0
0,1,2,2,2,2,2,2,2,1,0
0,0,1,2,2,2,2,2,1,0,0
0,0,0,3,2,2,2,3,3,0,0
0,0,0,0,3,2,3,0,0,0,0
0,0,0,0,3,3,3,0,0,0,0
endlayer

layer
0,0,0,0,0,0,0,0,0,0,0
0,0,1,0,0,1,0,0,1,0,0
0,1,2,4,4,2,4,4,2,1,0
0,0,4,2,2,2,2,2,3,0,0
0,0,4,2,2,2,2,2,3,0,0
0,1,2,2,2,2,2,2,2,1,0
0,0,3,2,2,2,2,2,4,0,0
0,0,3,2,2,2,2,2,4,0,0
0,1,2,2,2,2,2,2,2,1,0
0,0,1,2,2,2,2,2,1,0,0
0,0,0,3,2,2,2,3,3,0,0
0,0,0,0,3,2,3,0,0,0,0
0,0,0,0,3,3,3,0,0,0,0
endlayer

layer
0,0,0,0,0,0,0,0,0,0,0
0,0,1,0,0,1,0,0,1,0,0
0,1,2,4,4,2,4,4,2,1,0
0,0,4,2,2,2,2,2,4,0,0
0,0,4,2,2,2,2,2,4,0,0
0,1,2,2,2,2,2,2,2,1,0
0,0,3,2,2,2,2,2,4,0,0
0,0,3,2,2,2,2,2,4,0,0
0,1,2,2,2,2,2,2,2,1,0
0,0,1,2,2,2,2,2,1,0,0
0,0,0,3,2,2,2,3,3,0,0
0,0,0,0,3,3,3,0,0,0,0
0,0,0,0,5,5,5,0,0,0,0
endlayer

layer
0,0,0,0,0,0,0,0,0,0,0
0,0,1,0,0,1,0,0,1,0,0
0,1,1,4,4,1,4,4,1,1,0
0,0,4,1,1,1,1,1,4,0,0
0,0,4,1,1,1,1,1,4,0,0
0,1,1,1,1,1,1,1,1,1,0
0,0,4,1,1,1,1,1,4,0,0
0,0,4,1,1,1,1,1,4,0,0
0,1,2,4,4,4,4,4,2,1,0
0,0,1,3,3,3,3,3,1,0,0
0,0,0,3,3,3,3,3,0,0,0
0,0,0,0,5,5,5,0,0,0,0
0,0,0,0,0,0,0,0,0,0,0
endlayer

layer
0,0,0,0,0,0,0,0,0,0,0
0,0,1,0,0,1,0,0,1,0,0
0,1,1,4,4,1,4,4,1,1,0
0,0,4,9,9,7,6,0,4,0,0
0,0,4,11,10,0,0,0,4,0,0
0,1,1,11,0,0,0,0,0,1,0
0,0,4,12,0,0,0,0,4,0,0
0,0,4,0,0,8,0,0,4,0,0
0,1,1,4,4,4,4,4,2,1,0
0,0,1,3,3,3,3,3,1,0,0
0,0,0,3,5,5,5,3,0,0,0
0,0,0,0,0,0,0,0,0,0,0
0,0,0,0,0,0,0,0,0,0,0
endlayer

layer
0,0,0,0,0,0,0,0,0,0,0
0,0,1,0,0,1,0,0,1,0,0
0,1,1,4,4,1,4,3,1,1,0
0,0,4,0,0,6,0,0,4,0,0
0,0,4,0,14,0,0,0,4,0,0
0,1,1,0,0,0,0,0,0,1,0
0,0,4,0,0,0,0,0,4,0,0
0,0,4,0,0,0,0,0,4,0,0
0,1,1,4,4,13,4,4,1,1,0
0,0,1,0,0,0,0,0,1,0,0
0,0,0,3,0,0,0,3,0,0,0
0,0,0,0,0,0,0,0,0,0,0
0,0,0,0,0,0,0,0,0,0,0
endlayer

layer
0,0,0,0,0,0,0,0,0,0,0
0,0,16,0,0,16,0,0,16,0,0
0,18,3,4,4,1,4,4,3,15,0
0,0,4,17,6,0,0,0,4,0,0
0,0,4,0,0,0,0,0,4,0,0
0,18,3,0,0,0,0,18,3,15,0
0,0,4,0,0,0,0,0,4,0,0
0,0,4,0,16,0,0,0,4,0,0
0,18,3,4,4,21,20,4,3,15,0
0,0,0,0,0,0,0,0,17,0,0
0,0,0,19,0,0,0,19,0,0,0
0,0,0,0,0,0,0,0,0,0,0
0,0,0,0,0,0,0,0,0,0,0
endlayer

layer
0,0,0,0,0,0,0,0,0,0,0
0,0,0,0,0,0,0,0,0,0,0
0,0,3,3,3,3,3,3,3,0,0
0,0,3,6,0,0,0,22,3,0,0
0,0,3,8,22,22,22,22,3,0,0
0,0,3,22,22,22,22,22,3,0,0
0,0,3,22,22,22,22,22,3,0,0
0,0,3,22,22,22,22,22,3,0,0
0,0,3,3,3,3,3,3,3,0,0
0,0,0,0,0,17,0,0,0,0,0
0,0,0,0,0,0,0,0,0,0,0
0,0,0,0,0,0,0,0,0,0,0
0,0,0,0,0,0,0,0,0,0,0
endlayer

layer
0,0,0,0,0,0,0,0,0,0,0
0,0,0,0,0,0,0,0,0,0,0
0,0,3,1,1,3,1,1,3,0,0
0,0,1,0,0,0,6,0,1,0,0
0,0,1,0,0,0,0,0,1,0,0
0,0,3,24,24,24,3,23,3,0,0
0,0,1,0,0,0,0,0,1,0,0
0,0,1,0,0,0,0,0,1,0,0
0,0,3,1,1,3,1,1,3,0,0
0,0,0,0,0,0,0,0,0,0,0
0,0,0,0,0,0,0,0,0,0,0
0,0,0,0,0,0,0,0,0,0,0
0,0,0,0,0,0,0,0,0,0,0
endlayer

layer
0,0,0,0,0,0,0,0,0,0,0
0,0,0,0,0,0,0,0,0,0,0
0,0,3,24,24,3,24,24,3,0,0
0,0,24,0,0,6,0,0,24,0,0
0,0,24,0,0,0,0,0,24,0,0
0,0,3,24,24,24,3,21,3,0,0
0,0,24,0,0,0,0,0,24,0,0
0,0,24,0,0,0,0,0,24,0,0
0,0,3,24,24,3,24,24,3,0,0
0,0,0,0,0,0,0,0,0,0,0
0,0,0,0,0,0,0,0,0,0,0
0,0,0,0,0,0,0,0,0,0,0
0,0,0,0,0,0,0,0,0,0,0
endlayer

layer
0,0,0,0,0,0,0,0,0,0,0
0,0,0,0,0,0,0,0,0,0,0
0,0,4,1,1,4,1,1,4,0,0
0,0,1,0,6,0,0,0,1,0,0
0,0,1,15,0,0,0,25,1,0,0
0,0,4,24,24,24,3,3,4,0,0
0,0,1,0,0,0,0,0,1,0,0
0,0,1,0,0,0,0,0,1,0,0
0,0,4,1,1,4,1,1,4,0,0
0,0,0,0,0,0,0,0,0,0,0
0,0,0,0,0,0,0,0,0,0,0
0,0,0,0,0,0,0,0,0,0,0
0,0,0,0,0,0,0,0,0,0,0
endlayer

layer
0,0,0,0,0,0,0,0,0,0,0
0,0,0,0,0,0,0,0,0,0,0
0,0,4,1,1,4,1,1,4,0,0
0,0,1,6,0,0,0,17,1,0,0
0,0,1,0,0,0,0,0,1,0,0
0,0,4,24,24,24,3,3,4,0,0
0,0,1,0,0,0,0,0,1,0,0
0,0,1,16,0,0,0,16,1,0,0
0,0,4,1,1,4,1,1,4,0,0
0,0,0,0,0,0,0,0,0,0,0
0,0,0,0,0,0,0,0,0,0,0
0,0,0,0,0,0,0,0,0,0,0
0,0,0,0,0,0,0,0,0,0,0
endlayer

layer
0,0,0,0,0,0,0,0,0,0,0
0,0,0,0,0,0,0,0,0,0,0
0,0,4,1,1,4,1,1,4,0,0
0,0,1,0,0,0,22,22,1,0,0
0,0,1,8,22,22,22,22,1,0,0
0,0,4,22,22,22,3,22,4,0,0
0,0,1,22,22,22,22,22,1,0,0
0,0,1,22,22,22,22,22,1,0,0
0,0,4,1,1,4,1,1,4,0,0
0,0,0,0,0,0,0,0,0,0,0
0,0,0,0,0,0,0,0,0,0,0
0,0,0,0,0,0,0,0,0,0,0
0,0,0,0,0,0,0,0,0,0,0
endlayer

layer
0,0,0,0,0,0,0,0,0,0,0
0,0,0,0,0,0,0,0,0,0,0
0,0,4,1,1,4,1,1,4,0,0
0,0,1,0,0,0,6,0,1,0,0
0,0,1,0,0,0,0,0,1,0,0
0,0,4,24,24,24,3,23,4,0,0
0,0,1,0,0,0,0,0,1,0,0
0,0,1,0,0,0,0,0,1,0,0
0,0,4,1,1,4,1,1,4,0,0
0,0,0,0,0,0,0,0,0,0,0
0,0,0,0,0,0,0,0,0,0,0
0,0,0,0,0,0,0,0,0,0,0
0,0,0,0,0,0,0,0,0,0,0
endlayer

layer
0,0,0,0,0,0,0,0,0,0,0
0,0,0,0,0,0,0,0,0,0,0
0,0,3,24,24,3,24,24,3,0,0
0,0,24,0,0,6,0,0,24,0,0
0,0,24,0,0,0,0,0,24,0,0
0,0,3,24,24,24,3,21,3,0,0
0,0,24,0,0,0,0,0,24,0,0
0,0,24,0,0,0,0,0,24,0,0
0,0,3,24,24,3,24,24,3,0,0
0,0,0,0,0,0,0,0,0,0,0
0,0,0,0,0,0,0,0,0,0,0
0,0,0,0,0,0,0,0,0,0,0
0,0,0,0,0,0,0,0,0,0,0
endlayer

layer
0,0,0,0,0,0,0,0,0,0,0
0,0,0,0,0,0,0,0,0,0,0
0,0,4,1,1,4,1,1,4,0,0
0,0,1,0,6,0,0,0,1,0,0
0,0,1,15,0,0,0,25,1,0,0
0,0,4,24,24,24,3,3,4,0,0
0,0,1,0,0,0,0,0,1,0,0
0,0,1,16,0,0,0,16,1,0,0
0,0,4,1,1,4,1,1,4,0,0
0,0,0,0,0,0,0,0,0,0,0
0,0,0,0,0,0,0,0,0,0,0
0,0,0,0,0,0,0,0,0,0,0
0,0,0,0,0,0,0,0,0,0,0
endlayer

layer
0,0,0,0,0,0,0,0,0,0,0
0,0,0,0,0,0,0,0,0,0,0
0,0,4,1,1,4,1,1,4,0,0
0,0,1,6,0,0,0,0,1,0,0
0,0,1,0,0,0,0,0,1,0,0
0,0,4,24,24,24,24,3,4,0,0
0,0,1,0,0,0,0,0,1,0,0
0,0,1,0,0,0,0,0,1,0,0
0,0,4,1,1,4,1,1,4,0,0
0,0,0,0,0,0,0,0,0,0,0
0,0,0,0,0,0,0,0,0,0,0
0,0,0,0,0,0,0,0,0,0,0
0,0,0,0,0,0,0,0,0,0,0
endlayer

layer
0,0,0,0,0,0,0,0,0,0,0
0,0,0,0,0,0,0,0,0,0,0
0,0,4,1,1,4,1,1,4,0,0
0,0,1,0,0,0,22,22,1,0,0
0,0,1,8,22,22,22,22,1,0,0
0,0,4,22,22,22,22,22,4,0,0
0,0,1,22,22,22,22,22,1,0,0
0,0,1,22,22,22,22,22,1,0,0
0,0,4,1,1,4,1,1,4,0,0
0,0,0,0,0,0,0,0,0,0,0
0,0,0,0,0,0,0,0,0,0,0
0,0,0,0,0,0,0,0,0,0,0
0,0,0,0,0,0,0,0,0,0,0
endlayer

layer
0,0,0,0,0,0,0,0,0,0,0
0,0,0,0,0,0,0,0,0,0,0
0,0,4,1,1,4,1,1,4,0,0
0,0,1,0,0,0,6,0,1,0,0
0,0,1,0,0,0,0,0,1,0,0
0,0,4,24,24,24,3,23,4,0,0
0,0,1,0,0,0,0,0,1,0,0
0,0,1,0,0,0,0,0,1,0,0
0,0,4,1,1,4,1,1,4,0,0
0,0,0,0,0,0,0,0,0,0,0
0,0,0,0,0,0,0,0,0,0,0
0,0,0,0,0,0,0,0,0,0,0
0,0,0,0,0,0,0,0,0,0,0
endlayer

layer
0,0,0,0,0,0,0,0,0,0,0
0,0,0,0,0,0,0,0,0,0,0
0,0,3,24,24,3,24,24,3,0,0
0,0,24,0,0,6,0,0,24,0,0
0,0,24,0,0,0,0,0,24,0,0
0,0,3,24,24,24,3,21,3,0,0
0,0,24,0,0,0,0,0,24,0,0
0,0,24,0,0,0,0,0,24,0,0
0,0,3,24,24,3,24,24,3,0,0
0,0,0,0,0,0,0,0,0,0,0
0,0,0,0,0,0,0,0,0,0,0
0,0,0,0,0,0,0,0,0,0,0
0,0,0,0,0,0,0,0,0,0,0
endlayer

layer
0,0,0,0,0,0,0,0,0,0,0
0,0,0,0,0,0,0,0,0,0,0
0,0,4,1,1,4,1,1,4,0,0
0,0,1,0,6,0,0,0,1,0,0
0,0,1,15,0,0,0,25,1,0,0
0,0,4,24,24,24,3,3,4,0,0
0,0,1,15,0,0,0,0,1,0,0
0,0,1,0,0,0,0,16,1,0,0
0,0,4,1,1,4,1,1,4,0,0
0,0,0,0,0,0,0,0,0,0,0
0,0,0,0,0,0,0,0,0,0,0
0,0,0,0,0,0,0,0,0,0,0
0,0,0,0,0,0,0,0,0,0,0
endlayer

layer
0,0,0,0,0,0,0,0,0,0,0
0,0,0,0,0,0,0,0,0,0,0
0,0,4,1,1,4,1,1,4,0,0
0,0,1,6,0,0,0,0,1,0,0
0,0,1,0,0,0,16,0,1,0,0
0,0,4,24,24,24,3,3,4,0,0
0,0,1,0,0,0,0,0,1,0,0
0,0,1,0,0,0,0,0,1,0,0
0,0,4,1,1,4,1,1,4,0,0
0,0,0,0,0,0,0,0,0,0,0
0,0,0,0,0,0,0,0,0,0,0
0,0,0,0,0,0,0,0,0,0,0
0,0,0,0,0,0,0,0,0,0,0
endlayer

layer
0,0,0,0,0,0,0,0,0,0,0
0,0,0,0,0,0,0,0,0,0,0
0,0,4,1,1,4,1,1,4,0,0
0,0,1,0,0,0,22,22,1,0,0
0,0,1,8,22,22,22,22,1,0,0
0,0,4,22,22,22,22,22,4,0,0
0,0,1,22,22,22,22,22,1,0,0
0,0,1,22,22,22,22,22,1,0,0
0,0,4,1,1,4,1,1,4,0,0
0,0,0,0,0,0,0,0,0,0,0
0,0,0,0,0,0,0,0,0,0,0
0,0,0,0,0,0,0,0,0,0,0
0,0,0,0,0,0,0,0,0,0,0
endlayer

layer
0,0,0,0,0,0,0,0,0,0,0
0,0,0,0,0,0,0,0,0,0,0
0,0,4,1,1,4,1,1,4,0,0
0,0,1,0,0,0,6,0,1,0,0
0,0,1,0,0,0,0,0,1,0,0
0,0,4,24,24,24,3,23,4,0,0
0,0,1,0,0,0,0,0,1,0,0
0,0,1,0,0,0,0,0,1,0,0
0,0,4,1,1,4,1,1,4,0,0
0,0,0,0,0,0,0,0,0,0,0
0,0,0,0,0,0,0,0,0,0,0
0,0,0,0,0,0,0,0,0,0,0
0,0,0,0,0,0,0,0,0,0,0
endlayer

layer
0,0,0,0,0,0,0,0,0,0,0
0,0,0,0,0,0,0,0,0,0,0
0,0,3,24,24,3,24,24,3,0,0
0,0,24,0,0,6,0,0,24,0,0
0,0,24,0,0,0,0,0,24,0,0
0,0,3,24,24,24,3,21,3,0,0
0,0,24,0,0,0,0,0,24,0,0
0,0,24,0,0,0,0,0,24,0,0
0,0,3,24,24,3,24,24,3,0,0
0,0,0,0,0,0,0,0,0,0,0
0,0,0,0,0,0,0,0,0,0,0
0,0,0,0,0,0,0,0,0,0,0
0,0,0,0,0,0,0,0,0,0,0
endlayer

layer
0,0,0,0,0,0,0,0,0,0,0
0,0,0,0,0,0,0,0,0,0,0
0,0,4,1,1,4,1,1,4,0,0
0,0,1,0,6,0,0,0,1,0,0
0,0,1,15,0,0,0,25,1,0,0
0,0,4,24,24,24,3,3,4,0,0
0,0,1,0,0,0,0,0,1,0,0
0,0,1,0,0,0,0,0,1,0,0
0,0,4,1,1,4,1,1,4,0,0
0,0,0,0,0,0,0,0,0,0,0
0,0,0,0,0,0,0,0,0,0,0
0,0,0,0,0,0,0,0,0,0,0
0,0,0,0,0,0,0,0,0,0,0
endlayer

layer
0,0,0,0,0,0,0,0,0,0,0
0,0,0,0,0,0,0,0,0,0,0
0,0,4,1,1,4,1,1,4,0,0
0,0,1,6,0,0,0,0,1,0,0
0,0,1,0,0,0,0,0,1,0,0
0,0,4,24,24,24,3,3,4,0,0
0,0,1,0,0,0,0,0,1,0,0
0,0,1,0,0,0,0,0,1,0,0
0,0,4,1,1,4,1,1,4,0,0
0,0,0,0,0,0,0,0,0,0,0
0,0,0,0,0,0,0,0,0,0,0
0,0,0,0,0,0,0,0,0,0,0
0,0,0,0,0,0,0,0,0,0,0
endlayer

layer
0,0,0,0,0,0,0,0,0,0,0
0,0,0,0,0,0,0,0,0,0,0
0,0,4,1,1,4,1,1,4,0,0
0,0,1,0,0,0,22,22,1,0,0
0,0,1,8,22,22,22,22,1,0,0
0,0,4,22,22,22,22,22,4,0,0
0,0,1,22,22,22,22,22,1,0,0
0,0,1,22,22,22,22,22,1,0,0
0,0,4,1,1,4,1,1,4,0,0
0,0,0,0,0,0,0,0,0,0,0
0,0,0,0,0,0,0,0,0,0,0
0,0,0,0,0,0,0,0,0,0,0
0,0,0,0,0,0,0,0,0,0,0
endlayer

layer
0,0,0,0,0,0,0,0,0,0,0
0,0,0,0,0,0,0,0,0,0,0
0,0,4,1,1,4,1,1,4,0,0
0,0,1,0,0,0,6,0,1,0,0
0,0,1,0,0,0,0,0,1,0,0
0,0,4,24,24,24,3,23,4,0,0
0,0,1,0,0,0,0,0,1,0,0
0,0,1,0,0,0,0,0,1,0,0
0,0,4,1,1,4,1,1,4,0,0
0,0,0,0,0,0,0,0,0,0,0
0,0,0,0,0,0,0,0,0,0,0
0,0,0,0,0,0,0,0,0,0,0
0,0,0,0,0,0,0,0,0,0,0
endlayer

layer
0,0,0,0,0,0,0,0,0,0,0
0,0,0,0,0,0,0,0,0,0,0
0,0,3,24,24,3,24,24,3,0,0
0,0,24,0,0,6,0,0,24,0,0
0,0,24,0,0,0,0,0,24,0,0
0,0,3,24,24,24,3,21,3,0,0
0,0,24,0,0,0,0,0,24,0,0
0,0,24,0,0,0,0,0,24,0,0
0,0,3,24,24,3,24,24,3,0,0
0,0,0,0,0,0,0,0,0,0,0
0,0,0,0,0,0,0,0,0,0,0
0,0,0,0,0,0,0,0,0,0,0
0,0,0,0,0,0,0,0,0,0,0
endlayer

layer
0,0,0,0,0,0,0,0,0,0,0
0,4,0,4,0,4,0,4,0,4,0
0,0,4,1,1,4,1,1,4,0,0
0,4,1,0,6,0,0,0,1,4,0
0,0,1,15,0,0,0,25,1,0,0
0,4,4,24,24,24,3,3,4,4,0
0,0,1,15,0,0,0,17,1,0,0
0,4,1,0,0,0,0,0,1,4,0
0,0,4,1,1,4,1,1,4,0,0
0,4,0,4,0,4,0,4,0,4,0
0,0,0,0,0,0,0,0,0,0,0
0,0,0,0,0,0,0,0,0,0,0
0,0,0,0,0,0,0,0,0,0,0
endlayer

layer
0,4,0,4,0,4,0,4,0,4,0
4,4,0,4,0,4,0,4,0,4,4
0,0,4,1,1,4,1,1,4,0,0
4,4,1,6,0,0,0,0,1,4,4
0,0,1,0,0,0,0,0,1,0,0
4,4,4,24,24,24,3,3,4,4,4
0,0,1,0,0,0,0,0,1,0,0
4,4,1,0,0,0,0,0,1,4,4
0,0,4,1,1,4,1,1,4,0,0
4,4,0,4,0,4,0,4,0,4,4
0,4,0,4,0,4,0,4,0,4,0
0,0,0,0,0,0,0,0,0,0,0
0,0,0,0,0,0,0,0,0,0,0
endlayer

layer
4,4,4,4,4,4,4,4,4,4,4
4,4,4,4,4,4,4,4,4,4,4
4,4,22,22,22,4,22,22,22,4,4
4,4,6,0,0,0,22,22,22,4,4
4,4,22,22,22,22,22,22,22,4,4
4,4,22,22,22,22,22,22,22,4,4
4,4,22,22,22,22,22,22,22,4,4
4,4,22,22,22,22,22,22,22,4,4
4,4,22,22,22,22,22,22,22,4,4
4,4,4,4,4,4,4,4,4,4,4
4,4,4,4,4,4,4,4,4,4,4
0,0,0,0,0,0,0,0,0,0,0
0,0,0,0,0,0,0,0,0,0,0
endlayer

layer
1,1,1,1,1,1,1,1,1,1,1
1,26,26,0,0,26,0,0,26,26,1
1,26,4,0,0,4,0,0,4,26,1
1,0,0,0,0,0,0,0,0,0,1
1,0,0,0,0,0,0,0,0,0,1
1,26,4,0,0,0,0,0,4,26,1
1,0,0,0,0,0,0,0,0,0,1
1,0,0,0,0,27,0,0,0,0,1
1,0,4,0,0,4,0,0,4,26,1
1,26,26,0,0,26,0,0,26,26,1
1,1,1,1,1,1,1,1,1,1,1
0,0,0,0,0,0,0,0,0,0,0
0,0,0,0,0,0,0,0,0,0,0
endlayer

layer
3,0,3,0,3,0,3,0,3,0,3
0,0,0,0,0,0,0,0,0,0,0
3,0,3,0,0,3,0,0,3,0,3
0,0,0,0,0,17,0,0,0,0,0
3,0,0,0,0,0,0,0,0,0,3
0,0,3,15,0,0,0,18,3,0,0
3,0,0,0,0,0,0,0,0,0,3
0,0,0,0,0,27,0,0,0,0,0
3,0,3,0,0,3,0,0,3,0,3
0,0,0,0,0,0,0,0,0,0,0
3,0,3,0,3,0,3,0,3,0,3
0,0,0,0,0,0,0,0,0,0,0
0,0,0,0,0,0,0,0,0,0,0
endlayer

layer
19,0,0,0,0,0,0,0,0,0,19
0,0,0,0,0,0,0,0,0,0,0
0,0,4,1,1,4,1,1,4,0,0
0,0,1,0,0,0,0,0,1,0,0
0,0,1,0,0,0,0,0,1,0,0
0,0,4,0,0,0,0,0,4,0,0
0,0,1,0,0,0,0,0,1,0,0
0,0,1,0,16,27,16,0,1,0,0
0,0,4,1,1,4,1,1,4,0,0
0,0,0,0,0,0,0,0,0,0,0
19,0,0,0,0,0,0,0,0,0,19
0,0,0,0,0,0,0,0,0,0,0
0,0,0,0,0,0,0,0,0,0,0
endlayer

layer
0,0,0,0,0,0,0,0,0,0,0
0,0,0,0,0,0,0,0,0,0,0
0,0,3,3,3,3,3,3,4,0,0
0,0,3,22,22,22,22,22,4,0,0
0,0,3,22,22,22,22,22,4,0,0
0,0,3,22,22,22,22,22,4,0,0
0,0,3,22,22,22,22,22,4,0,0
0,0,3,22,22,27,22,22,4,0,0
0,0,4,4,4,4,4,4,4,0,0
0,0,0,0,0,0,0,0,0,0,0
0,0,0,0,0,0,0,0,0,0,0
0,0,0,0,0,0,0,0,0,0,0
0,0,0,0,0,0,0,0,0,0,0
endlayer

layer
0,0,0,0,0,0,0,0,0,0,0
0,0,0,0,0,0,0,0,0,0,0
0,0,3,0,0,3,0,0,3,0,0
0,0,0,0,0,0,0,0,0,0,0
0,0,0,0,0,0,0,0,0,0,0
0,0,3,0,0,0,0,0,3,0,0
0,0,0,0,0,0,0,0,0,0,0
0,0,0,0,0,27,0,0,0,0,0
0,0,3,0,0,3,0,0,3,0,0
0,0,0,0,0,0,0,0,0,0,0
0,0,0,0,0,0,0,0,0,0,0
0,0,0,0,0,0,0,0,0,0,0
0,0,0,0,0,0,0,0,0,0,0
endlayer

layer
0,0,0,0,0,0,0,0,0,0,0
0,0,0,0,0,0,0,0,0,0,0
0,0,19,0,0,0,0,0,19,0,0
0,0,0,0,0,0,0,0,0,0,0
0,0,0,0,0,0,0,0,0,0,0
0,0,0,0,0,0,0,0,0,0,0
0,0,0,0,0,0,0,0,0,0,0
0,0,0,0,0,0,0,0,0,0,0
0,0,19,0,0,0,0,0,19,0,0
0,0,0,0,0,0,0,0,0,0,0
0,0,0,0,0,0,0,0,0,0,0
0,0,0,0,0,0,0,0,0,0,0
0,0,0,0,0,0,0,0,0,0,0
endlayer





