# Converted from schematic
# author:MohawkyMagoo

weight=10
embed_into_distance=11
#acceptable_target_blocks=1,2,3,12,13,9
dimensions=62,17,17
#allowable_overhang=0
max_cut_in=2
#cut_in_buffer=1
max_leveling=2
#leveling_buffer=1
#preserve_water=0
#preserve_lava=0
#preserve_plants=0


rule1=0,100,4
rule2=0,100,71-2
rule3=0,100,71-3
rule4=0,100,71
rule5=0,100,53-1
rule6=0,100,71-1
rule7=0,100,69-1
rule8=0,100,101
rule9=0,100,71-8
rule10=0,100,69-3
rule11=0,100,71-9
rule12=0,100,5
rule13=0,100,69-2
rule14=0,100,69-4
rule15=0,100,53-3
rule16=0,100,50-3
rule17=0,100,50-2
rule18=0,100,50-4
rule19=0,100,53
rule20=0,100,50-1
rule21=0,100,53-2
rule22=0,100,85
rule23=0,100,67-1
rule24=0,100,67-3
rule25=0,100,67-0
rule26=0,100,67-1
rule27=0,100,102
rule28=0,100,20
rule29=0,100,89
rule30=0,100,70
rule31=0,100,50-5


layer
1,1,1,1,1,1,1,1,1,1,1,1,1,1,1,1,1
1,1,1,1,1,1,1,1,1,1,1,1,1,1,1,1,1
1,1,1,1,1,1,1,1,1,1,1,1,1,1,1,1,1
1,1,1,1,1,1,1,1,1,1,1,1,1,1,1,1,1
1,1,1,1,1,1,1,1,1,1,1,1,1,1,1,1,1
1,1,1,1,1,1,1,1,1,1,1,1,1,1,1,1,1
1,1,1,1,1,1,1,1,1,1,1,1,1,1,1,1,1
1,1,1,1,1,1,1,1,1,1,1,1,1,1,1,1,1
1,1,1,1,1,1,1,1,1,1,1,1,1,1,1,1,1
1,1,1,1,1,1,1,1,1,1,1,1,1,1,1,1,1
1,1,1,1,1,1,1,1,1,1,1,1,1,1,1,1,1
1,1,1,1,1,1,1,1,1,1,1,1,1,1,1,1,1
1,1,1,1,1,1,1,1,1,1,1,1,1,1,1,1,1
1,1,1,1,1,1,1,1,1,1,1,1,1,1,1,1,1
1,1,1,1,1,1,1,1,1,1,1,1,1,1,1,1,1
1,1,1,1,1,1,1,1,1,1,1,1,1,1,1,1,1
1,1,1,1,1,1,1,1,1,1,1,1,1,1,1,1,1
endlayer

layer
1,1,1,1,1,1,1,1,1,1,1,1,1,1,1,1,1
1,0,0,1,0,0,0,0,0,0,0,0,0,1,0,0,1
1,0,0,6,0,0,0,0,0,0,0,0,0,1,0,0,1
1,0,0,1,0,0,0,0,0,0,0,0,0,1,0,0,1
1,1,1,1,0,0,1,1,1,1,1,0,0,1,2,1,1
1,0,0,0,0,1,1,1,1,1,1,1,0,0,0,0,1
1,0,0,0,1,1,1,0,0,1,0,0,1,0,0,0,1
1,0,0,0,1,1,0,0,0,3,0,0,1,0,0,0,1
1,0,0,0,1,5,0,1,4,1,1,1,1,0,0,0,1
1,0,0,0,3,0,0,1,0,0,0,0,1,0,0,0,1
1,0,0,0,1,0,0,1,0,0,0,0,1,0,0,0,1
1,0,0,0,0,1,0,1,0,0,0,1,0,0,0,0,1
1,1,4,1,0,0,1,1,1,1,1,0,0,0,0,0,1
1,0,0,1,0,0,0,0,0,0,0,0,1,1,1,1,1
1,0,0,1,0,0,0,0,0,0,0,0,3,0,0,0,1
1,0,0,1,0,0,0,0,0,0,0,0,1,0,0,0,1
1,1,1,1,1,1,1,1,1,1,1,1,1,1,1,1,1
endlayer

layer
1,1,1,1,1,1,1,1,1,1,1,1,1,1,1,1,1
1,0,0,1,14,0,0,0,0,0,0,0,0,8,0,0,1
1,0,0,9,0,0,0,0,0,0,0,0,0,8,0,0,1
1,0,0,1,0,0,0,0,0,0,0,0,0,8,0,0,1
1,8,8,8,0,0,1,1,1,1,1,0,0,1,9,1,1
1,0,0,0,0,1,12,12,1,1,1,1,0,0,0,7,1
1,0,0,0,1,12,12,0,10,1,0,0,1,0,0,0,1
1,0,0,0,1,5,0,13,0,11,0,0,1,0,0,0,1
1,0,0,0,1,0,0,1,9,1,8,8,1,0,0,0,1
1,0,0,0,9,0,0,8,0,0,0,0,1,0,0,0,1
1,0,0,0,1,14,0,8,0,0,0,0,1,0,0,0,1
1,13,0,0,0,1,0,8,0,0,0,1,0,0,0,0,1
1,1,9,1,0,0,1,1,1,1,1,0,0,0,0,0,1
1,0,0,8,0,0,0,0,0,0,0,0,1,8,8,8,1
1,0,0,8,0,0,0,0,0,0,0,0,9,0,0,0,1
1,0,0,8,0,0,0,0,0,0,0,10,1,0,0,0,1
1,1,1,1,1,1,1,1,1,1,1,1,1,1,1,1,1
endlayer

layer
1,1,1,1,1,1,1,1,1,1,1,1,1,1,1,1,1
1,0,0,1,0,0,0,0,0,0,0,0,0,8,0,0,1
1,0,0,1,0,0,0,0,0,0,0,0,0,8,0,0,1
1,0,0,1,0,0,0,0,0,0,0,0,0,8,0,0,1
1,8,8,8,0,0,1,1,1,1,1,0,0,1,1,1,1
1,0,0,0,0,1,0,15,1,1,1,1,0,0,0,0,1
1,0,0,0,1,0,0,0,0,1,0,0,1,0,0,0,1
1,0,0,0,1,0,0,0,0,1,0,0,1,0,0,0,1
1,0,0,0,1,0,0,1,1,1,8,8,1,0,0,0,1
1,0,0,0,1,0,0,8,0,0,0,0,1,0,0,0,1
1,0,0,0,1,0,0,8,0,0,0,0,1,0,0,0,1
1,0,0,0,0,1,0,8,0,0,0,1,0,0,0,0,1
1,1,1,1,0,0,1,1,1,1,1,0,0,0,0,0,1
1,0,0,8,0,0,0,0,0,0,0,0,1,8,8,8,1
1,0,0,8,0,0,0,0,0,0,0,0,1,0,0,0,1
1,0,0,8,0,0,0,0,0,0,0,0,1,0,0,0,1
1,1,1,1,1,1,1,1,1,1,1,1,1,1,1,1,1
endlayer

layer
1,1,1,1,1,1,1,1,1,1,1,1,1,1,1,1,1
1,0,0,1,0,0,0,0,0,0,0,0,0,8,0,0,1
1,0,0,1,0,0,0,0,0,0,0,0,0,8,0,0,1
1,0,0,1,18,0,0,0,0,0,0,0,0,8,0,0,1
1,8,8,8,0,0,1,1,1,1,1,0,16,1,1,1,1
1,0,0,0,0,1,0,0,15,1,1,1,0,0,0,0,1
1,0,0,0,1,0,0,0,0,1,1,1,1,0,0,0,1
1,0,0,0,1,0,0,0,0,1,1,1,1,0,0,0,1
1,0,0,0,1,0,0,1,1,1,1,1,1,0,0,0,1
1,0,0,0,1,0,0,1,1,1,1,1,1,0,0,0,1
1,0,0,0,1,1,1,1,1,1,1,1,1,0,0,0,1
1,0,0,0,0,1,1,1,1,1,1,1,0,0,0,0,1
1,1,1,1,18,0,1,1,1,1,1,0,17,0,0,0,1
1,0,0,8,0,0,0,0,0,0,0,0,1,8,8,8,1
1,0,0,8,0,0,0,0,0,0,0,0,1,0,0,0,1
1,0,0,8,0,0,0,0,0,0,0,0,1,0,0,0,1
1,1,1,1,1,1,1,1,1,1,1,1,1,1,1,1,1
endlayer

layer
1,1,1,1,1,1,1,1,1,1,1,1,1,1,1,1,1
1,1,1,1,1,1,0,0,0,0,0,1,1,1,1,1,1
1,1,1,1,1,1,0,0,0,0,0,1,1,1,1,1,1
1,1,1,1,1,1,0,0,0,0,0,1,1,1,1,1,1
1,1,1,1,1,1,1,1,1,1,1,1,1,1,1,1,1
1,1,1,1,1,1,0,0,0,15,12,1,1,1,1,1,1
1,0,0,0,1,0,0,0,0,1,12,12,1,0,0,0,1
1,0,0,0,1,0,0,0,0,1,12,12,1,0,0,0,1
1,0,0,0,1,1,1,1,1,1,1,1,1,0,0,0,1
1,0,0,0,1,1,1,1,1,1,1,1,1,0,0,0,1
1,0,0,0,1,1,1,1,1,1,1,1,1,0,0,0,1
1,1,1,1,1,1,1,1,1,1,1,1,1,1,1,1,1
1,1,1,1,1,1,1,1,1,1,1,1,1,1,1,1,1
1,1,1,1,1,1,0,0,0,0,0,1,1,1,1,1,1
1,1,1,1,1,1,0,0,0,0,0,1,1,1,1,1,1
1,1,1,1,1,1,0,0,0,0,0,1,1,1,1,1,1
1,1,1,1,1,1,1,1,1,1,1,1,1,1,1,1,1
endlayer

layer
1,1,1,1,1,1,1,1,1,1,1,1,1,1,1,1,1
1,0,0,0,0,0,0,0,0,0,0,0,0,0,0,0,1
1,0,0,0,0,0,0,0,0,0,0,0,0,0,0,0,1
1,0,0,0,0,0,0,0,0,0,0,0,0,0,0,0,1
1,0,0,0,0,0,1,1,1,1,1,0,0,0,0,0,1
1,0,0,0,0,1,0,0,0,0,0,1,0,0,0,0,1
1,0,0,0,1,0,0,0,0,0,0,0,1,0,0,0,1
1,0,0,0,1,0,0,0,0,0,0,19,1,0,0,0,1
1,0,0,0,1,0,0,0,0,0,0,12,1,0,0,0,1
1,0,0,0,1,0,0,0,0,0,0,0,1,0,0,0,1
1,0,0,0,1,0,0,0,0,0,0,0,1,0,0,0,1
1,0,0,0,0,1,0,0,0,0,0,1,0,0,0,0,1
1,0,0,0,0,0,1,1,1,1,1,0,0,0,0,0,1
1,0,0,0,0,0,0,0,0,0,0,0,0,0,0,0,1
1,0,0,0,0,0,0,0,0,0,0,0,0,0,0,0,1
1,0,0,0,0,0,0,0,0,0,0,0,0,0,0,0,1
1,1,1,1,1,1,1,1,1,1,1,1,1,1,1,1,1
endlayer

layer
1,1,1,1,1,1,1,1,1,1,1,1,1,1,1,1,1
1,0,0,0,0,0,0,0,0,0,0,0,0,0,0,0,1
1,0,0,0,0,0,0,0,0,0,0,0,0,0,0,0,1
1,0,0,0,0,0,0,0,0,0,0,0,0,0,0,0,1
1,0,0,0,0,0,1,1,1,1,1,0,0,0,0,0,1
1,0,0,0,0,1,0,0,0,0,0,1,0,0,0,0,1
1,0,0,0,1,0,0,0,0,0,0,0,1,0,0,0,1
1,0,0,0,1,0,0,0,0,0,0,0,1,0,0,0,1
1,0,0,0,1,0,0,0,0,0,0,19,1,0,0,0,1
1,0,0,0,1,0,0,0,0,0,0,0,1,0,0,0,1
1,0,0,0,1,0,0,0,0,0,0,0,1,0,0,0,1
1,0,0,0,0,1,0,0,0,0,0,1,0,0,0,0,1
1,0,0,0,0,0,1,1,1,1,1,0,0,0,0,0,1
1,0,0,0,0,0,0,0,0,0,0,0,0,0,0,0,1
1,0,0,0,0,0,0,0,0,0,0,0,0,0,0,0,1
1,0,0,0,0,0,0,0,0,0,0,0,0,0,0,0,1
1,1,1,1,1,1,1,1,1,1,1,1,1,1,1,1,1
endlayer

layer
1,1,1,1,1,1,1,1,1,1,1,1,1,1,1,1,1
1,0,0,0,0,0,0,0,0,0,0,0,0,0,0,0,1
1,0,0,0,0,0,0,0,0,0,0,0,0,0,0,0,1
1,0,0,0,0,0,0,0,0,0,0,0,0,0,0,0,1
1,0,0,0,0,0,1,1,1,1,1,0,0,0,0,0,1
1,0,0,0,0,1,20,0,0,0,0,1,0,0,0,0,1
1,0,0,0,1,0,0,0,0,0,0,0,1,0,0,0,1
1,0,0,0,1,0,0,0,0,0,0,0,1,0,0,0,1
1,0,0,0,1,0,0,0,0,0,0,0,1,0,0,0,1
1,0,0,0,1,0,0,0,0,0,0,19,1,0,0,0,1
1,0,0,0,1,17,0,0,0,12,12,12,1,0,0,0,1
1,0,0,0,0,1,0,0,0,12,12,1,0,0,0,0,1
1,0,0,0,0,0,1,1,1,1,1,0,0,0,0,0,1
1,0,0,0,0,0,0,0,0,0,0,0,0,0,0,0,1
1,0,0,0,0,0,0,0,0,0,0,0,0,0,0,0,1
1,0,0,0,0,0,0,0,0,0,0,0,0,0,0,0,1
1,1,1,1,1,1,1,1,1,1,1,1,1,1,1,1,1
endlayer

layer
1,1,1,1,1,1,1,1,1,1,1,1,1,1,1,1,1
1,0,0,0,0,0,0,0,0,0,0,0,0,0,0,0,1
1,0,0,0,0,0,0,0,0,0,0,0,0,0,0,0,1
1,0,0,0,0,0,0,0,0,0,0,0,0,0,0,0,1
1,0,0,0,0,0,1,1,1,1,1,0,0,0,0,0,1
1,0,0,0,0,1,0,0,0,0,0,1,0,0,0,0,1
1,0,0,0,1,0,0,0,0,0,0,20,1,0,0,0,1
1,0,0,0,1,0,0,0,0,0,0,0,1,0,0,0,1
1,0,0,0,1,0,0,0,0,0,0,0,1,0,0,0,1
1,0,0,0,1,0,0,0,0,0,0,0,1,0,0,0,1
1,0,0,0,1,0,0,0,0,0,0,0,1,0,0,0,1
1,0,0,0,0,1,0,0,0,21,0,1,0,0,0,0,1
1,0,0,0,0,0,1,1,1,1,1,0,0,0,0,0,1
1,0,0,0,0,0,0,0,0,0,0,0,0,0,0,0,1
1,0,0,0,0,0,0,0,0,0,0,0,0,0,0,0,1
1,0,0,0,0,0,0,0,0,0,0,0,0,0,0,0,1
1,1,1,1,1,1,1,1,1,1,1,1,1,1,1,1,1
endlayer

layer
1,1,1,1,1,1,1,1,1,1,1,1,1,1,1,1,1
1,0,0,0,0,0,0,0,0,0,0,0,0,0,0,0,1
1,0,0,0,0,0,0,0,0,0,0,0,0,0,0,0,1
1,0,0,0,0,0,0,0,0,0,0,0,0,0,0,0,1
1,0,0,0,0,0,1,1,1,1,1,0,0,0,0,0,1
1,0,0,0,0,1,0,0,0,0,0,1,0,0,0,0,1
1,0,0,0,1,0,0,0,0,0,0,0,1,0,0,0,1
1,0,0,0,1,0,0,0,0,0,0,0,1,0,0,0,1
1,0,0,0,1,0,0,0,0,0,0,0,1,0,0,0,1
1,0,0,0,1,0,0,0,0,0,0,0,1,0,0,0,1
1,0,0,0,1,0,0,0,0,0,0,0,1,0,0,0,1
1,0,0,0,0,1,0,0,21,0,0,1,0,0,0,0,1
1,0,0,0,0,0,1,1,1,1,1,0,0,0,0,0,1
1,0,0,0,0,0,0,0,0,0,0,0,0,0,0,0,1
1,0,0,0,0,0,0,0,0,0,0,0,0,0,0,0,1
1,0,0,0,0,0,0,0,0,0,0,0,0,0,0,0,1
1,1,1,1,1,1,1,1,1,1,1,1,1,1,1,1,1
endlayer

layer
1,1,1,1,1,1,1,1,1,1,1,1,1,1,1,1,1
1,1,1,1,1,1,1,1,1,1,1,1,1,1,1,1,1
1,1,1,1,1,1,1,1,1,1,1,1,1,1,1,1,1
1,1,1,1,1,1,1,1,1,1,1,1,1,1,1,1,1
1,1,1,1,1,1,1,1,1,1,1,1,1,1,1,1,1
1,1,1,1,1,1,12,12,12,12,12,1,1,1,1,1,1
1,1,1,1,1,12,12,12,12,12,12,12,1,1,1,1,1
1,1,1,1,1,12,12,12,12,12,12,12,1,1,1,1,1
1,1,1,1,1,12,12,12,12,12,12,12,1,1,1,1,1
1,1,1,1,1,12,12,12,12,12,12,12,1,1,1,1,1
1,1,1,1,1,12,12,12,12,12,12,12,1,1,1,1,1
1,1,1,1,1,1,12,21,0,0,0,1,1,1,1,1,1
1,1,1,1,1,1,1,1,1,1,1,1,1,1,1,1,1
1,1,1,1,1,1,1,1,1,1,1,1,1,1,1,1,1
1,1,1,1,1,1,1,1,1,1,1,1,1,1,1,1,1
1,1,1,1,1,1,1,1,1,1,1,1,1,1,1,1,1
1,1,1,1,1,1,1,1,1,1,1,1,1,1,1,1,1
endlayer

layer
1,1,1,1,1,1,1,1,1,1,1,1,1,1,1,1,1
1,0,0,0,0,0,0,0,0,0,0,0,0,0,0,0,1
1,0,0,0,0,0,0,0,0,0,0,0,0,0,0,0,1
1,0,0,0,0,0,0,0,0,0,0,0,0,0,0,0,1
1,0,0,0,0,0,1,1,1,1,1,0,0,0,0,0,1
1,0,0,0,0,1,0,12,12,21,0,1,0,0,0,0,1
1,0,0,0,1,0,0,0,0,0,0,0,1,0,0,0,1
0,0,0,0,1,0,0,0,0,0,0,0,1,0,0,0,0
0,0,0,0,6,0,0,0,0,0,0,0,3,0,0,0,0
0,0,0,0,1,0,0,0,0,0,0,0,1,0,0,0,0
1,0,0,0,1,0,0,22,22,22,22,0,1,0,0,0,1
1,0,0,0,0,1,0,0,0,0,0,1,0,0,0,0,1
1,0,0,0,0,0,1,1,1,1,1,0,0,0,0,0,1
1,0,0,0,0,0,0,0,0,0,0,0,0,0,0,0,1
1,0,0,0,0,0,0,0,0,0,0,0,0,0,0,0,1
1,0,0,0,0,0,0,0,0,0,0,0,0,0,0,0,1
1,1,1,1,1,1,1,1,1,1,1,1,1,1,1,1,1
endlayer

layer
1,0,1,0,1,0,1,0,1,0,1,0,1,0,1,0,1
0,0,0,0,0,0,0,0,0,0,0,0,0,0,0,0,0
1,0,0,0,0,0,0,0,0,0,0,0,0,0,0,0,1
0,0,0,0,0,0,0,0,0,0,0,0,0,0,0,0,0
1,0,0,0,0,0,1,1,1,1,1,0,0,0,0,0,1
0,0,0,0,0,1,0,12,21,0,0,1,0,0,0,0,0
1,0,0,0,1,0,0,0,0,0,0,0,1,0,0,0,1
0,0,0,0,7,0,0,0,0,0,0,0,7,0,0,0,0
0,0,0,0,9,0,0,0,0,0,0,0,9,0,0,0,0
0,0,0,0,1,0,0,0,0,0,0,0,1,0,0,0,0
1,0,0,0,1,0,0,0,0,0,0,0,1,0,0,0,1
0,0,0,0,0,1,0,0,0,0,0,1,0,0,0,0,0
1,0,0,0,0,0,1,1,1,1,1,0,0,0,0,0,1
0,0,0,0,0,0,0,0,0,0,0,0,0,0,0,0,0
1,0,0,0,0,0,0,0,0,0,0,0,0,0,0,0,1
0,0,0,0,0,0,0,0,0,0,0,0,0,0,0,0,0
1,0,1,0,1,0,1,0,1,0,1,0,1,0,1,0,1
endlayer

layer
1,0,1,0,1,0,1,0,1,0,1,0,1,0,1,0,1
0,0,0,0,0,0,0,0,0,0,0,0,0,0,0,0,0
1,0,0,0,0,0,0,0,0,0,0,0,0,0,0,0,1
0,0,0,0,0,0,0,0,0,0,0,0,0,0,0,0,0
1,0,0,0,0,0,1,1,1,1,1,0,0,0,0,0,1
0,0,0,0,0,1,12,21,20,0,0,1,0,0,0,0,0
1,0,0,0,1,0,0,0,0,0,0,0,1,0,0,0,1
0,0,0,0,1,0,0,0,0,0,0,0,1,0,0,0,0
0,0,0,0,1,18,0,0,0,0,0,16,1,0,0,0,0
0,0,0,0,1,0,0,0,0,0,0,0,1,0,0,0,0
1,0,0,0,1,0,0,0,0,0,0,0,1,0,0,0,1
0,0,0,0,0,1,0,0,17,0,0,1,0,0,0,0,0
1,0,0,0,0,0,1,1,1,1,1,0,0,0,0,0,1
0,0,0,0,0,0,0,0,0,0,0,0,0,0,0,0,0
1,0,0,0,0,0,0,0,0,0,0,0,0,0,0,0,1
0,0,0,0,0,0,0,0,0,0,0,0,0,0,0,0,0
1,0,1,0,1,0,1,0,1,0,1,0,1,0,1,0,1
endlayer

layer
0,0,0,0,0,0,1,0,1,0,1,0,0,0,0,0,0
0,0,0,0,0,0,1,0,1,0,1,0,0,0,0,0,0
0,0,0,0,0,0,0,0,0,0,0,0,0,0,0,0,0
0,0,0,0,0,0,0,0,0,0,0,0,0,0,0,0,0
0,0,0,0,0,0,1,1,1,1,1,0,0,0,0,0,0
0,0,0,0,0,1,21,0,0,0,12,1,0,0,0,0,0
1,1,0,0,1,12,12,12,12,12,12,12,1,0,0,1,1
0,0,0,0,1,12,12,12,12,12,12,12,1,0,0,0,0
0,0,0,0,1,12,12,12,12,12,12,12,1,0,0,0,0
0,0,0,0,1,12,12,12,12,12,12,12,1,0,0,0,0
1,1,0,0,1,12,12,12,12,12,12,12,1,0,0,1,1
0,0,0,0,0,1,12,12,12,12,12,1,0,0,0,0,0
0,0,0,0,0,0,1,1,1,1,1,0,0,0,0,0,0
0,0,0,0,0,0,0,0,0,0,0,0,0,0,0,0,0
0,0,0,0,0,0,0,0,0,0,0,0,0,0,0,0,0
0,0,0,0,0,0,1,0,1,0,1,0,0,0,0,0,0
0,0,0,0,0,0,1,0,1,0,1,0,0,0,0,0,0
endlayer

layer
0,0,0,0,0,0,24,0,24,0,24,0,0,0,0,0,0
0,0,0,0,0,0,1,0,1,0,1,0,0,0,0,0,0
0,0,0,0,0,0,1,0,1,0,1,0,0,0,0,0,0
0,0,0,0,0,0,0,0,0,0,0,0,0,0,0,0,0
0,0,0,0,0,0,1,1,1,1,1,0,0,0,0,0,0
0,0,0,0,0,1,0,0,0,0,22,1,0,0,0,0,0
26,1,1,0,1,0,0,22,22,22,22,0,1,0,1,1,23
0,0,0,0,1,0,0,0,0,0,0,0,1,0,0,0,0
0,0,0,0,1,0,0,0,0,0,0,0,1,0,0,0,0
0,0,0,0,1,0,0,0,0,0,0,0,1,0,0,0,0
26,1,1,0,1,0,0,0,0,0,0,0,1,0,1,1,23
0,0,0,0,0,1,0,15,0,0,0,1,0,0,0,0,0
0,0,0,0,0,0,1,1,1,1,1,0,0,0,0,0,0
0,0,0,0,0,0,0,0,0,0,0,0,0,0,0,0,0
0,0,0,0,0,0,1,0,1,0,1,0,0,0,0,0,0
0,0,0,0,0,0,1,0,1,0,1,0,0,0,0,0,0
0,0,0,0,0,0,25,0,25,0,25,0,0,0,0,0,0
endlayer

layer
0,0,0,0,0,0,0,0,0,0,0,0,0,0,0,0,0
0,0,0,0,0,0,24,0,24,0,24,0,0,0,0,0,0
0,0,0,0,0,0,1,0,1,0,1,0,0,0,0,0,0
0,0,0,0,0,0,1,0,1,0,1,0,0,0,0,0,0
0,0,0,0,0,0,1,1,1,1,1,0,0,0,0,0,0
0,0,0,0,0,1,0,0,0,0,0,1,0,0,0,0,0
0,26,1,1,1,0,0,0,0,0,0,0,1,1,1,23,0
0,0,0,0,1,0,0,0,0,0,0,0,1,0,0,0,0
0,0,0,0,1,0,0,0,0,0,0,0,1,0,0,0,0
0,0,0,0,1,0,0,0,0,0,0,0,1,0,0,0,0
0,26,1,1,1,0,0,0,0,0,0,0,1,1,1,23,0
0,0,0,0,0,1,0,0,15,0,0,1,0,0,0,0,0
0,0,0,0,0,0,1,1,1,1,1,0,0,0,0,0,0
0,0,0,0,0,0,1,0,1,0,1,0,0,0,0,0,0
0,0,0,0,0,0,1,0,1,0,1,0,0,0,0,0,0
0,0,0,0,0,0,25,0,25,0,25,0,0,0,0,0,0
0,0,0,0,0,0,0,0,0,0,0,0,0,0,0,0,0
endlayer

layer
0,0,0,0,0,0,0,0,0,0,0,0,0,0,0,0,0
0,0,0,0,0,0,0,0,0,0,0,0,0,0,0,0,0
0,0,0,0,0,0,24,0,24,0,24,0,0,0,0,0,0
0,0,0,0,0,0,1,0,1,0,1,0,0,0,0,0,0
0,0,0,0,0,0,1,1,1,1,1,0,0,0,0,0,0
0,0,0,0,0,1,20,0,0,0,20,1,0,0,0,0,0
0,0,26,1,1,20,0,0,0,0,0,20,1,1,23,0,0
0,0,0,0,1,0,0,0,0,0,0,0,1,0,0,0,0
0,0,0,0,1,0,0,0,0,0,0,0,1,0,0,0,0
0,0,0,0,1,0,0,0,0,0,0,0,1,0,0,0,0
0,0,26,1,1,17,0,0,0,0,0,17,1,1,23,0,0
0,0,0,0,0,1,17,0,0,15,17,1,0,0,0,0,0
0,0,0,0,0,0,1,1,1,1,1,0,0,0,0,0,0
0,0,0,0,0,0,1,0,1,0,1,0,0,0,0,0,0
0,0,0,0,0,0,25,0,25,0,25,0,0,0,0,0,0
0,0,0,0,0,0,0,0,0,0,0,0,0,0,0,0,0
0,0,0,0,0,0,0,0,0,0,0,0,0,0,0,0,0
endlayer

layer
0,0,0,0,0,0,0,0,0,0,0,0,0,0,0,0,0
0,0,0,0,0,0,0,0,0,0,0,0,0,0,0,0,0
0,0,0,0,0,0,0,0,0,0,0,0,0,0,0,0,0
0,0,0,0,0,0,24,0,24,0,24,0,0,0,0,0,0
0,0,0,0,0,0,1,1,1,1,1,0,0,0,0,0,0
0,0,0,0,0,1,0,0,0,0,0,1,0,0,0,0,0
0,0,0,26,1,0,0,0,0,0,0,0,1,23,0,0,0
0,0,0,0,1,0,0,0,0,0,0,0,1,0,0,0,0
0,0,0,0,1,0,0,0,0,0,0,0,1,0,0,0,0
0,0,0,0,1,0,0,0,0,0,0,0,1,0,0,0,0
0,0,0,26,1,0,0,0,0,0,0,0,1,23,0,0,0
0,0,0,0,0,1,0,0,0,0,15,1,0,0,0,0,0
0,0,0,0,0,0,1,1,1,1,1,0,0,0,0,0,0
0,0,0,0,0,0,25,0,25,0,25,0,0,0,0,0,0
0,0,0,0,0,0,0,0,0,0,0,0,0,0,0,0,0
0,0,0,0,0,0,0,0,0,0,0,0,0,0,0,0,0
0,0,0,0,0,0,0,0,0,0,0,0,0,0,0,0,0
endlayer

layer
0,0,0,0,0,0,0,0,0,0,0,0,0,0,0,0,0
0,0,0,0,0,0,0,0,0,0,0,0,0,0,0,0,0
0,0,0,0,0,0,0,0,0,0,0,0,0,0,0,0,0
0,0,0,0,0,0,12,12,12,12,12,0,0,0,0,0,0
0,0,0,0,0,12,12,12,12,12,12,12,0,0,0,0,0
0,0,0,0,12,12,0,0,0,0,0,12,12,0,0,0,0
0,0,0,12,12,0,0,0,0,0,0,0,12,12,0,0,0
0,0,0,12,12,0,0,0,0,0,0,0,12,12,0,0,0
0,0,0,12,12,0,0,0,0,0,0,0,12,12,0,0,0
0,0,0,12,12,0,0,0,0,0,0,0,12,12,0,0,0
0,0,0,12,12,0,0,0,0,0,0,0,12,12,0,0,0
0,0,0,0,12,12,0,0,0,0,0,15,12,0,0,0,0
0,0,0,0,0,12,12,12,12,12,12,12,0,0,0,0,0
0,0,0,0,0,0,12,12,12,12,12,0,0,0,0,0,0
0,0,0,0,0,0,0,0,0,0,0,0,0,0,0,0,0
0,0,0,0,0,0,0,0,0,0,0,0,0,0,0,0,0
0,0,0,0,0,0,0,0,0,0,0,0,0,0,0,0,0
endlayer

layer
0,0,0,0,0,0,0,0,0,0,0,0,0,0,0,0,0
0,0,0,0,0,0,0,0,12,0,0,0,0,0,0,0,0
0,0,0,0,0,0,12,12,12,12,12,0,0,0,0,0,0
0,0,0,0,12,12,12,12,12,12,12,12,12,0,0,0,0
0,0,0,12,12,12,12,12,12,12,12,12,12,12,0,0,0
0,0,0,12,12,12,12,12,12,12,12,12,12,12,0,0,0
0,0,12,12,12,12,12,12,12,12,12,12,12,12,12,0,0
0,0,12,12,12,12,12,12,12,12,12,12,12,12,12,0,0
0,12,12,12,12,12,12,12,12,12,12,12,12,12,12,12,0
0,0,12,12,12,12,12,12,12,12,12,12,12,12,12,0,0
0,0,12,12,12,12,12,12,12,12,12,12,12,12,12,0,0
0,0,0,12,12,12,12,12,0,0,0,0,15,12,0,0,0
0,0,0,12,12,12,12,12,12,12,12,12,12,12,0,0,0
0,0,0,0,12,12,12,12,12,12,12,12,12,0,0,0,0
0,0,0,0,0,0,12,12,12,12,12,0,0,0,0,0,0
0,0,0,0,0,0,0,0,12,0,0,0,0,0,0,0,0
0,0,0,0,0,0,0,0,0,0,0,0,0,0,0,0,0
endlayer

layer
0,0,0,0,0,0,0,0,0,0,0,0,0,0,0,0,0
0,0,0,0,0,0,1,1,1,1,1,0,0,0,0,0,0
0,0,0,0,1,1,0,0,0,0,0,1,1,0,0,0,0
0,0,0,1,0,0,0,0,0,0,0,0,0,1,0,0,0
0,0,1,0,0,0,12,0,0,0,0,0,0,0,1,0,0
0,0,1,0,0,0,0,0,0,0,0,0,0,12,1,0,0
0,1,0,0,0,0,0,0,0,0,0,0,0,12,0,1,0
0,1,0,0,0,0,0,0,0,0,0,0,0,12,0,1,0
0,1,0,0,0,0,0,0,0,0,0,0,0,12,0,1,0
0,1,0,0,0,12,0,0,0,0,0,0,0,5,0,1,0
0,1,0,0,0,0,0,12,12,12,12,12,0,0,0,1,0
0,0,1,0,0,0,0,12,0,0,0,0,0,0,1,0,0
0,0,1,0,0,0,0,22,22,22,22,22,0,0,1,0,0
0,0,0,1,0,0,0,0,0,0,0,0,0,1,0,0,0
0,0,0,0,1,1,0,0,0,0,0,1,1,0,0,0,0
0,0,0,0,0,0,1,1,1,1,1,0,0,0,0,0,0
0,0,0,0,0,0,0,0,0,0,0,0,0,0,0,0,0
endlayer

layer
0,0,0,0,0,0,0,0,0,0,0,0,0,0,0,0,0
0,0,0,0,0,0,1,12,27,12,1,0,0,0,0,0,0
0,0,0,0,1,1,0,0,0,0,0,1,1,0,0,0,0
0,0,0,1,0,0,0,0,0,0,0,0,0,1,0,0,0
0,0,1,0,0,0,12,0,0,0,0,0,0,0,1,0,0
0,0,1,0,0,0,0,0,0,0,0,0,0,12,1,0,0
0,1,0,0,0,0,0,0,0,0,0,0,0,12,0,1,0
0,12,0,0,0,0,0,0,0,0,0,0,0,12,0,12,0
0,27,0,0,0,0,0,0,0,0,0,0,0,5,0,27,0
0,12,0,0,0,12,0,0,0,0,0,0,0,0,0,12,0
0,1,0,0,0,0,0,12,12,12,12,12,0,0,0,1,0
0,0,1,0,0,0,0,12,0,0,0,0,0,0,1,0,0
0,0,1,0,0,0,0,0,0,0,0,0,0,0,1,0,0
0,0,0,1,0,0,0,0,0,0,0,0,0,1,0,0,0
0,0,0,0,1,1,0,0,0,0,0,1,1,0,0,0,0
0,0,0,0,0,0,1,12,27,12,1,0,0,0,0,0,0
0,0,0,0,0,0,0,0,0,0,0,0,0,0,0,0,0
endlayer

layer
0,0,0,0,0,0,0,0,0,0,0,0,0,0,0,0,0
0,0,0,0,0,0,1,12,27,12,1,0,0,0,0,0,0
0,0,0,0,1,1,0,20,0,20,0,1,1,0,0,0,0
0,0,0,28,0,0,0,0,0,0,0,0,0,28,0,0,0
0,0,1,0,0,0,12,0,0,0,0,0,0,0,1,0,0
0,0,1,0,0,0,0,0,0,0,0,0,0,12,1,0,0
0,1,0,0,0,0,0,0,0,0,0,0,0,12,0,1,0
0,12,18,0,0,0,0,0,0,0,0,0,0,5,16,12,0
0,27,0,0,0,0,0,0,0,0,0,0,0,0,0,27,0
0,12,18,0,0,12,0,0,0,0,0,0,0,0,16,12,0
0,1,0,0,0,0,0,12,12,12,12,12,0,0,0,1,0
0,0,1,0,0,0,16,12,20,0,0,0,0,0,1,0,0
0,0,1,0,0,0,0,0,0,0,0,0,0,0,1,0,0
0,0,0,28,0,0,0,0,0,0,0,0,0,28,0,0,0
0,0,0,0,1,1,0,17,0,17,0,1,1,0,0,0,0
0,0,0,0,0,0,1,12,27,12,1,0,0,0,0,0,0
0,0,0,0,0,0,0,0,0,0,0,0,0,0,0,0,0
endlayer

layer
0,0,0,0,0,0,0,0,0,0,0,0,0,0,0,0,0
0,0,0,0,0,0,1,12,27,12,1,0,0,0,0,0,0
0,0,0,0,1,1,0,0,0,0,0,1,1,0,0,0,0
0,0,0,28,0,0,0,0,0,0,0,0,0,28,0,0,0
0,0,1,0,0,0,12,0,0,0,0,0,0,0,1,0,0
0,0,1,0,0,0,0,0,0,0,0,0,0,12,1,0,0
0,1,0,0,0,0,0,0,0,0,0,0,0,5,0,1,0
0,12,0,0,0,0,0,0,0,0,0,0,0,0,0,12,0
0,27,0,0,0,0,0,0,0,0,0,0,0,0,0,27,0
0,12,0,0,0,12,0,0,17,0,0,17,0,0,0,12,0
0,1,0,0,0,0,0,12,12,12,12,12,0,0,0,1,0
0,0,1,0,0,0,0,12,0,0,0,0,0,0,1,0,0
0,0,1,0,0,0,0,0,0,0,0,0,0,0,1,0,0
0,0,0,28,0,0,0,0,0,0,0,0,0,28,0,0,0
0,0,0,0,1,1,0,0,0,0,0,1,1,0,0,0,0
0,0,0,0,0,0,1,12,27,12,1,0,0,0,0,0,0
0,0,0,0,0,0,0,0,0,0,0,0,0,0,0,0,0
endlayer

layer
0,0,0,0,0,0,0,0,19,0,0,0,0,0,0,0,0
0,0,0,0,0,0,1,1,1,1,1,0,0,0,0,0,0
0,0,0,0,1,1,12,12,12,12,12,1,1,0,0,0,0
0,0,0,1,12,12,12,12,12,12,12,12,12,1,0,0,0
0,0,1,12,12,12,12,12,12,12,12,12,12,12,1,0,0
0,0,1,12,12,12,12,12,12,12,12,12,12,5,1,0,0
0,1,12,12,12,12,0,0,0,0,0,0,0,0,0,1,0
0,1,12,12,12,12,0,0,0,0,0,0,0,0,0,1,0
15,1,12,12,12,12,0,0,0,0,0,0,0,0,0,1,21
0,1,12,12,12,12,0,0,0,0,0,0,0,0,0,1,0
0,1,12,12,12,12,12,12,12,12,12,12,12,12,12,1,0
0,0,1,12,12,12,12,12,12,12,12,12,12,12,1,0,0
0,0,1,12,12,12,12,12,12,12,12,12,12,12,1,0,0
0,0,0,1,12,12,12,12,12,12,12,12,12,1,0,0,0
0,0,0,0,1,1,12,12,12,12,12,1,1,0,0,0,0
0,0,0,0,0,0,1,1,1,1,1,0,0,0,0,0,0
0,0,0,0,0,0,0,0,5,0,0,0,0,0,0,0,0
endlayer

layer
0,0,0,0,0,0,12,12,12,12,12,0,0,0,0,0,0
0,0,0,0,12,12,12,12,12,12,12,12,12,0,0,0,0
0,0,12,12,12,12,0,0,0,0,0,12,12,12,12,0,0
0,0,12,12,0,0,0,0,0,0,0,0,0,12,12,0,0
0,12,12,0,0,0,0,0,0,0,0,0,0,0,12,12,0
0,12,12,0,0,19,22,22,22,22,22,22,22,0,12,12,0
12,12,0,0,0,12,0,0,0,0,0,0,0,0,0,12,12
12,12,0,0,0,12,0,0,0,0,0,0,0,0,0,12,12
12,12,0,0,0,12,18,0,0,0,0,0,0,0,0,12,12
12,12,0,0,0,12,0,0,0,0,0,0,0,0,0,12,12
12,12,0,0,0,22,22,22,22,22,22,22,22,22,22,12,12
0,12,12,0,0,0,0,0,0,0,0,0,0,0,12,12,0
0,12,12,0,0,0,0,0,0,0,0,0,0,0,12,12,0
0,0,12,12,0,0,0,0,0,0,0,0,0,12,12,0,0
0,0,12,12,12,12,0,0,0,0,0,12,12,12,12,0,0
0,0,0,0,12,12,12,12,12,12,12,12,12,0,0,0,0
0,0,0,0,0,0,12,12,12,12,12,0,0,0,0,0,0
endlayer

layer
0,0,0,0,0,0,0,0,0,0,0,0,0,0,0,0,0
0,0,0,0,0,0,12,12,12,12,12,0,0,0,0,0,0
0,0,0,0,12,12,0,0,0,0,0,12,12,0,0,0,0
0,0,0,12,0,0,0,0,0,0,0,0,0,12,0,0,0
0,0,12,0,0,0,0,0,0,0,0,0,0,0,12,0,0
0,0,12,0,0,0,0,0,0,0,0,0,0,0,12,0,0
0,12,0,0,0,19,0,0,0,0,0,0,0,0,0,12,0
0,12,0,0,0,12,0,0,0,0,0,0,0,0,0,12,0
0,12,0,0,0,12,0,0,0,0,0,0,0,0,0,12,0
0,12,0,0,0,12,0,0,0,0,0,0,0,0,0,12,0
0,12,0,0,0,0,0,0,0,0,0,0,0,0,0,12,0
0,0,12,0,0,0,0,0,0,0,0,0,0,0,12,0,0
0,0,12,17,0,0,0,0,0,0,0,0,0,17,12,0,0
0,0,0,12,17,0,0,0,0,0,0,17,0,12,0,0,0
0,0,0,0,12,12,0,0,17,0,0,12,12,0,0,0,0
0,0,0,0,0,0,12,12,12,12,12,0,0,0,0,0,0
0,0,0,0,0,0,0,0,0,0,0,0,0,0,0,0,0
endlayer

layer
0,0,0,0,0,0,0,0,0,0,0,0,0,0,0,0,0
0,0,0,0,0,0,0,0,0,0,0,0,0,0,0,0,0
0,0,0,0,0,0,12,12,12,12,12,0,0,0,0,0,0
0,0,0,0,12,12,20,0,0,0,20,12,12,0,0,0,0
0,0,0,12,0,0,0,0,0,0,0,0,0,12,0,0,0
0,0,0,12,0,0,0,0,0,0,0,0,0,12,0,0,0
0,0,12,20,0,0,0,0,0,0,0,0,0,20,12,0,0
0,0,12,0,0,19,0,0,0,0,0,0,0,0,12,0,0
0,0,12,0,0,12,0,0,0,0,0,0,0,0,12,0,0
0,0,12,0,16,12,0,0,0,0,0,0,0,0,12,0,0
0,0,12,0,0,0,0,0,0,0,0,0,0,0,12,0,0
0,0,0,12,0,0,0,0,0,0,0,0,0,12,0,0,0
0,0,0,12,0,0,0,0,0,0,0,0,0,12,0,0,0
0,0,0,0,12,12,0,0,0,0,0,12,12,0,0,0,0
0,0,0,0,0,0,12,12,12,12,12,0,0,0,0,0,0
0,0,0,0,0,0,0,0,0,0,0,0,0,0,0,0,0
0,0,0,0,0,0,0,0,0,0,0,0,0,0,0,0,0
endlayer

layer
0,0,0,0,0,0,0,0,0,0,0,0,0,0,0,0,0
0,0,0,0,0,0,0,0,0,0,0,0,0,0,0,0,0
0,0,0,0,0,0,0,0,0,0,0,0,0,0,0,0,0
0,0,0,0,0,0,12,12,12,12,12,0,0,0,0,0,0
0,0,0,0,12,12,1,1,1,1,1,12,12,0,0,0,0
0,0,0,0,12,0,0,0,0,0,0,1,12,0,0,0,0
0,0,0,12,1,0,0,0,0,0,0,0,1,12,0,0,0
0,0,0,12,1,0,0,0,0,0,0,0,1,12,0,0,0
0,0,0,12,1,19,0,0,0,0,0,0,1,12,0,0,0
0,0,0,12,1,12,0,0,0,0,0,0,1,12,0,0,0
0,0,0,12,1,0,0,0,0,0,0,0,1,12,0,0,0
0,0,0,0,12,1,0,0,0,0,0,1,12,0,0,0,0
0,0,0,0,12,12,1,1,1,1,1,12,12,0,0,0,0
0,0,0,0,0,0,12,12,12,12,12,0,0,0,0,0,0
0,0,0,0,0,0,0,0,0,0,0,0,0,0,0,0,0
0,0,0,0,0,0,0,0,0,0,0,0,0,0,0,0,0
0,0,0,0,0,0,0,0,0,0,0,0,0,0,0,0,0
endlayer

layer
0,0,0,0,0,0,0,0,0,0,0,0,0,0,0,0,0
0,0,0,0,0,0,0,0,0,0,0,0,0,0,0,0,0
0,0,0,0,0,0,0,0,0,0,0,0,0,0,0,0,0
0,0,0,0,0,0,0,0,12,0,0,0,0,0,0,0,0
0,0,0,0,0,0,1,1,1,1,1,0,0,0,0,0,0
0,0,0,0,0,1,0,0,0,0,0,1,0,0,0,0,0
0,0,0,0,1,0,0,0,0,0,0,0,1,0,0,0,0
0,0,0,0,1,0,0,0,0,0,0,0,1,0,0,0,0
0,0,0,12,1,0,0,0,0,0,0,0,1,12,0,0,0
0,0,0,0,1,19,0,0,0,0,0,0,1,0,0,0,0
0,0,0,0,1,0,0,0,0,0,0,0,1,0,0,0,0
0,0,0,0,0,1,0,0,0,0,0,1,0,0,0,0,0
0,0,0,0,0,0,1,1,1,1,1,0,0,0,0,0,0
0,0,0,0,0,0,0,0,12,0,0,0,0,0,0,0,0
0,0,0,0,0,0,0,0,0,0,0,0,0,0,0,0,0
0,0,0,0,0,0,0,0,0,0,0,0,0,0,0,0,0
0,0,0,0,0,0,0,0,0,0,0,0,0,0,0,0,0
endlayer

layer
0,0,0,0,0,0,0,0,0,0,0,0,0,0,0,0,0
0,0,0,0,0,0,0,0,0,0,0,0,0,0,0,0,0
0,0,0,0,0,0,0,0,0,0,0,0,0,0,0,0,0
0,0,0,0,0,0,0,0,0,0,0,0,0,0,0,0,0
0,0,0,0,0,0,1,1,1,1,1,0,0,0,0,0,0
0,0,0,0,0,1,12,12,12,12,12,1,0,0,0,0,0
0,0,0,0,1,12,12,12,12,12,12,12,1,0,0,0,0
0,0,0,0,1,0,12,12,12,12,12,12,1,0,0,0,0
0,0,0,0,1,0,12,12,12,12,12,12,1,0,0,0,0
0,0,0,0,1,0,12,12,12,12,12,12,1,0,0,0,0
0,0,0,0,1,19,12,12,12,12,12,12,1,0,0,0,0
0,0,0,0,0,1,12,12,12,12,12,1,0,0,0,0,0
0,0,0,0,0,0,1,1,1,1,1,0,0,0,0,0,0
0,0,0,0,0,0,0,0,0,0,0,0,0,0,0,0,0
0,0,0,0,0,0,0,0,0,0,0,0,0,0,0,0,0
0,0,0,0,0,0,0,0,0,0,0,0,0,0,0,0,0
0,0,0,0,0,0,0,0,0,0,0,0,0,0,0,0,0
endlayer

layer
0,0,0,0,0,0,0,0,0,0,0,0,0,0,0,0,0
0,0,0,0,0,0,0,0,0,0,0,0,0,0,0,0,0
0,0,0,0,0,0,0,0,0,0,0,0,0,0,0,0,0
0,0,0,0,0,0,0,0,0,0,0,0,0,0,0,0,0
0,0,0,0,0,0,1,1,1,1,1,0,0,0,0,0,0
0,0,0,0,0,1,0,0,0,15,12,1,0,0,0,0,0
0,0,0,0,1,12,0,0,0,0,12,12,1,0,0,0,0
0,0,0,0,1,0,0,0,0,0,0,12,1,0,0,0,0
0,0,0,0,1,0,0,0,0,0,0,12,1,0,0,0,0
0,0,0,0,1,0,0,0,0,0,0,0,1,0,0,0,0
0,0,0,0,1,0,0,0,0,0,0,0,1,0,0,0,0
0,0,0,0,0,1,0,0,0,0,0,1,0,0,0,0,0
0,0,0,0,0,0,1,1,1,1,1,0,0,0,0,0,0
0,0,0,0,0,0,0,0,0,0,0,0,0,0,0,0,0
0,0,0,0,0,0,0,0,0,0,0,0,0,0,0,0,0
0,0,0,0,0,0,0,0,0,0,0,0,0,0,0,0,0
0,0,0,0,0,0,0,0,0,0,0,0,0,0,0,0,0
endlayer

layer
0,0,0,0,0,0,0,0,0,0,0,0,0,0,0,0,0
0,0,0,0,0,0,0,0,0,0,0,0,0,0,0,0,0
0,0,0,0,0,0,0,0,0,0,0,0,0,0,0,0,0
0,0,0,0,0,0,0,0,0,0,0,0,0,0,0,0,0
0,0,0,0,0,0,1,1,1,1,1,0,0,0,0,0,0
0,0,0,0,0,1,0,0,20,0,0,1,0,0,0,0,0
0,0,0,0,1,0,0,0,0,0,0,0,1,0,0,0,0
0,0,0,0,1,0,0,0,0,0,0,19,1,0,0,0,0
0,0,0,0,1,18,0,0,0,0,0,12,1,0,0,0,0
0,0,0,0,1,0,0,0,0,0,0,0,1,0,0,0,0
0,0,0,0,1,0,0,0,0,0,0,0,1,0,0,0,0
0,0,0,0,0,1,0,0,17,0,0,1,0,0,0,0,0
0,0,0,0,0,0,1,1,1,1,1,0,0,0,0,0,0
0,0,0,0,0,0,0,0,0,0,0,0,0,0,0,0,0
0,0,0,0,0,0,0,0,0,0,0,0,0,0,0,0,0
0,0,0,0,0,0,0,0,0,0,0,0,0,0,0,0,0
0,0,0,0,0,0,0,0,0,0,0,0,0,0,0,0,0
endlayer

layer
0,0,0,0,0,0,0,0,0,0,0,0,0,0,0,0,0
0,0,0,0,0,0,0,0,0,0,0,0,0,0,0,0,0
0,0,0,0,0,0,0,0,0,0,0,0,0,0,0,0,0
0,0,0,0,0,0,0,0,0,0,0,0,0,0,0,0,0
0,0,0,0,0,0,1,1,1,1,1,0,0,0,0,0,0
0,0,0,0,0,1,0,0,0,0,0,1,0,0,0,0,0
0,0,0,0,1,0,0,0,0,0,0,0,1,0,0,0,0
0,0,0,0,1,0,0,0,0,0,0,0,1,0,0,0,0
0,0,0,0,1,0,0,0,0,0,0,19,1,0,0,0,0
0,0,0,0,1,0,0,0,0,0,0,12,1,0,0,0,0
0,0,0,0,1,0,0,0,0,0,0,12,1,0,0,0,0
0,0,0,0,0,1,0,0,0,0,0,1,0,0,0,0,0
0,0,0,0,0,0,1,1,1,1,1,0,0,0,0,0,0
0,0,0,0,0,0,0,0,0,0,0,0,0,0,0,0,0
0,0,0,0,0,0,0,0,0,0,0,0,0,0,0,0,0
0,0,0,0,0,0,0,0,0,0,0,0,0,0,0,0,0
0,0,0,0,0,0,0,0,0,0,0,0,0,0,0,0,0
endlayer

layer
0,0,0,0,0,0,0,0,0,0,0,0,0,0,0,0,0
0,0,0,0,0,0,0,0,0,0,0,0,0,0,0,0,0
0,0,0,0,0,0,0,0,0,0,0,0,0,0,0,0,0
0,0,0,0,0,0,0,0,0,0,0,0,0,0,0,0,0
0,0,0,0,0,0,1,1,1,1,1,0,0,0,0,0,0
0,0,0,0,0,1,0,0,0,0,0,1,0,0,0,0,0
0,0,0,0,1,0,0,0,0,0,0,0,1,0,0,0,0
0,0,0,0,1,0,0,0,0,0,0,0,1,0,0,0,0
0,0,0,0,1,0,0,0,0,0,0,0,1,0,0,0,0
0,0,0,0,1,0,0,0,0,0,0,19,1,0,0,0,0
0,0,0,0,1,0,0,0,0,12,12,12,1,0,0,0,0
0,0,0,0,0,1,0,0,0,12,12,1,0,0,0,0,0
0,0,0,0,0,0,1,1,1,1,1,0,0,0,0,0,0
0,0,0,0,0,0,0,0,0,0,0,0,0,0,0,0,0
0,0,0,0,0,0,0,0,0,0,0,0,0,0,0,0,0
0,0,0,0,0,0,0,0,0,0,0,0,0,0,0,0,0
0,0,0,0,0,0,0,0,0,0,0,0,0,0,0,0,0
endlayer

layer
0,0,0,0,0,0,0,0,0,0,0,0,0,0,0,0,0
0,0,0,0,0,0,0,0,0,0,0,0,0,0,0,0,0
0,0,0,0,0,0,0,0,0,0,0,0,0,0,0,0,0
0,0,0,0,0,0,0,0,0,0,0,0,0,0,0,0,0
0,0,0,0,0,0,1,1,1,1,1,0,0,0,0,0,0
0,0,0,0,0,1,0,0,0,0,0,1,0,0,0,0,0
0,0,0,0,1,0,0,0,0,0,0,0,1,0,0,0,0
0,0,0,0,1,0,0,0,0,0,0,0,1,0,0,0,0
0,0,0,0,1,0,0,0,0,0,0,0,1,0,0,0,0
0,0,0,0,1,12,12,12,0,0,0,0,1,0,0,0,0
0,0,0,0,1,12,12,12,12,12,0,0,1,0,0,0,0
0,0,0,0,0,1,12,12,12,21,0,1,0,0,0,0,0
0,0,0,0,0,0,1,1,1,1,1,0,0,0,0,0,0
0,0,0,0,0,0,0,0,0,0,0,0,0,0,0,0,0
0,0,0,0,0,0,0,0,0,0,0,0,0,0,0,0,0
0,0,0,0,0,0,0,0,0,0,0,0,0,0,0,0,0
0,0,0,0,0,0,0,0,0,0,0,0,0,0,0,0,0
endlayer

layer
0,0,0,0,0,0,0,0,0,0,0,0,0,0,0,0,0
0,0,0,0,0,0,0,0,0,0,0,0,0,0,0,0,0
0,0,0,0,0,0,0,0,0,0,0,0,0,0,0,0,0
0,0,0,0,0,0,0,0,0,0,0,0,0,0,0,0,0
0,0,0,0,0,0,1,1,1,1,1,0,0,0,0,0,0
0,0,0,0,0,1,0,0,0,0,0,1,0,0,0,0,0
0,0,0,0,1,0,0,0,0,0,0,0,1,0,0,0,0
0,0,0,0,1,0,0,0,0,0,0,0,1,0,0,0,0
0,0,0,0,1,12,0,0,0,0,0,0,1,0,0,0,0
0,0,0,0,1,5,22,22,0,0,0,0,1,0,0,0,0
0,0,0,0,1,0,0,22,22,22,0,0,1,0,0,0,0
0,0,0,0,0,1,0,0,0,0,0,1,0,0,0,0,0
0,0,0,0,0,0,1,1,1,1,1,0,0,0,0,0,0
0,0,0,0,0,0,0,0,0,0,0,0,0,0,0,0,0
0,0,0,0,0,0,0,0,0,0,0,0,0,0,0,0,0
0,0,0,0,0,0,0,0,0,0,0,0,0,0,0,0,0
0,0,0,0,0,0,0,0,0,0,0,0,0,0,0,0,0
endlayer

layer
0,0,0,0,0,0,0,0,0,0,0,0,0,0,0,0,0
0,0,0,0,0,0,0,0,0,0,0,0,0,0,0,0,0
0,0,0,0,0,0,0,0,0,0,0,0,0,0,0,0,0
0,0,0,0,0,0,0,0,0,0,0,0,0,0,0,0,0
0,0,0,0,0,0,1,1,1,1,1,0,0,0,0,0,0
0,0,0,0,0,1,0,0,0,0,0,1,0,0,0,0,0
0,0,0,0,1,0,0,0,0,0,0,0,1,0,0,0,0
0,0,0,0,1,12,0,0,0,0,0,0,1,0,0,0,0
0,0,0,0,1,5,0,0,0,0,0,0,1,0,0,0,0
0,0,0,0,1,0,0,0,0,0,0,0,1,0,0,0,0
0,0,0,0,1,0,0,0,0,0,0,0,1,0,0,0,0
0,0,0,0,0,1,0,0,0,0,0,1,0,0,0,0,0
0,0,0,0,0,0,1,1,1,1,1,0,0,0,0,0,0
0,0,0,0,0,0,0,0,0,0,0,0,0,0,0,0,0
0,0,0,0,0,0,0,0,0,0,0,0,0,0,0,0,0
0,0,0,0,0,0,0,0,0,0,0,0,0,0,0,0,0
0,0,0,0,0,0,0,0,0,0,0,0,0,0,0,0,0
endlayer

layer
0,0,0,0,0,0,0,0,0,0,0,0,0,0,0,0,0
0,0,0,0,0,0,0,0,0,0,0,0,0,0,0,0,0
0,0,0,0,0,0,0,0,0,0,0,0,0,0,0,0,0
0,0,0,0,0,0,12,12,12,12,12,0,0,0,0,0,0
0,0,0,0,0,12,12,12,12,12,12,12,0,0,0,0,0
0,0,0,0,12,12,0,0,0,0,0,12,12,0,0,0,0
0,0,0,12,12,12,0,0,0,0,0,0,12,12,0,0,0
0,0,0,12,12,5,0,0,0,0,0,0,12,12,0,0,0
0,0,0,12,12,0,0,0,0,0,0,0,12,12,0,0,0
0,0,0,12,12,0,0,0,0,0,0,0,12,12,0,0,0
0,0,0,12,12,0,0,0,0,0,0,0,12,12,0,0,0
0,0,0,0,12,12,0,0,0,0,0,12,12,0,0,0,0
0,0,0,0,0,12,12,12,12,12,12,12,0,0,0,0,0
0,0,0,0,0,0,12,12,12,12,12,0,0,0,0,0,0
0,0,0,0,0,0,0,0,0,0,0,0,0,0,0,0,0
0,0,0,0,0,0,0,0,0,0,0,0,0,0,0,0,0
0,0,0,0,0,0,0,0,0,0,0,0,0,0,0,0,0
endlayer

layer
0,0,0,0,0,0,0,0,0,0,0,0,0,0,0,0,0
0,0,0,0,0,0,0,0,12,0,0,0,0,0,0,0,0
0,0,0,0,0,0,12,12,12,12,12,0,0,0,0,0,0
0,0,0,0,12,12,12,12,12,12,12,12,12,0,0,0,0
0,0,0,12,12,12,12,12,12,12,12,12,12,12,0,0,0
0,0,0,12,12,12,12,12,12,12,12,12,12,12,0,0,0
0,0,12,12,12,0,15,12,12,12,12,12,12,12,12,0,0
0,0,12,12,12,0,12,12,12,12,12,12,12,12,12,0,0
0,12,12,12,12,0,12,12,12,12,12,12,12,12,12,12,0
0,0,12,12,12,0,12,12,12,12,12,12,12,12,12,0,0
0,0,12,12,12,12,12,12,12,12,12,12,12,12,12,0,0
0,0,0,12,12,12,12,12,12,12,12,12,12,12,0,0,0
0,0,0,12,12,12,12,12,12,12,12,12,12,12,0,0,0
0,0,0,0,12,12,12,12,12,12,12,12,12,0,0,0,0
0,0,0,0,0,0,12,12,12,12,12,0,0,0,0,0,0
0,0,0,0,0,0,0,0,12,0,0,0,0,0,0,0,0
0,0,0,0,0,0,0,0,0,0,0,0,0,0,0,0,0
endlayer

layer
0,0,0,0,0,0,0,0,0,0,0,0,0,0,0,0,0
0,0,0,0,0,0,1,1,1,1,1,0,0,0,0,0,0
0,0,0,0,1,1,0,0,0,0,0,1,1,0,0,0,0
0,0,0,1,0,0,0,0,0,0,0,0,0,1,0,0,0
0,0,1,0,0,0,0,0,0,0,0,0,0,0,1,0,0
0,0,1,0,0,0,0,0,0,0,0,0,0,0,1,0,0
0,1,0,0,0,0,0,0,0,0,0,0,0,0,0,1,0
0,1,0,0,0,0,0,0,0,0,0,0,0,0,0,1,0
0,1,0,0,0,0,0,0,0,0,0,0,0,0,0,1,0
0,1,0,0,0,0,0,0,0,0,0,0,0,0,0,1,0
0,1,0,0,0,0,0,0,0,0,0,0,0,0,0,1,0
0,0,1,0,0,0,0,0,0,0,0,0,0,0,1,0,0
0,0,1,0,0,0,0,0,0,0,0,0,0,0,1,0,0
0,0,0,1,0,0,0,0,0,0,0,0,0,1,0,0,0
0,0,0,0,1,1,0,0,0,0,0,1,1,0,0,0,0
0,0,0,0,0,0,1,1,1,1,1,0,0,0,0,0,0
0,0,0,0,0,0,0,0,0,0,0,0,0,0,0,0,0
endlayer

layer
0,0,0,0,0,0,0,0,0,0,0,0,0,0,0,0,0
0,0,0,0,0,0,1,12,27,12,1,0,0,0,0,0,0
0,0,0,0,1,1,0,0,0,0,0,1,1,0,0,0,0
0,0,0,1,0,0,0,0,0,0,0,0,0,1,0,0,0
0,0,1,0,0,0,0,0,0,0,0,0,0,0,1,0,0
0,0,1,0,0,0,0,0,0,0,0,0,0,0,1,0,0
0,1,0,0,0,0,0,0,0,0,0,0,0,0,0,1,0
0,12,0,0,0,0,0,0,0,0,0,0,0,0,0,12,0
0,27,0,0,0,0,0,0,0,0,0,0,0,0,0,27,0
0,12,0,0,0,0,0,0,0,0,0,0,0,0,0,12,0
0,1,0,0,0,0,0,0,0,0,0,0,0,0,0,1,0
0,0,1,0,0,0,0,0,0,0,0,0,0,0,1,0,0
0,0,1,0,0,0,0,0,0,0,0,0,0,0,1,0,0
0,0,0,1,0,0,0,0,0,0,0,0,0,1,0,0,0
0,0,0,0,1,1,0,0,0,0,0,1,1,0,0,0,0
0,0,0,0,0,0,1,12,27,12,1,0,0,0,0,0,0
0,0,0,0,0,0,0,0,0,0,0,0,0,0,0,0,0
endlayer

layer
0,0,0,0,0,0,0,0,0,0,0,0,0,0,0,0,0
0,0,0,0,0,0,1,12,27,12,1,0,0,0,0,0,0
0,0,0,0,1,1,0,20,0,20,0,1,1,0,0,0,0
0,0,0,28,0,0,0,0,0,0,0,0,0,28,0,0,0
0,0,1,0,0,0,0,0,0,0,0,0,0,0,1,0,0
0,0,1,0,0,0,0,0,0,0,0,0,0,0,1,0,0
0,1,0,0,0,0,0,0,0,0,0,0,0,0,0,1,0
0,12,18,0,0,0,0,0,0,0,0,0,0,0,16,12,0
0,27,0,0,0,0,0,0,0,0,0,0,0,0,0,27,0
0,12,18,0,0,0,0,0,0,0,0,0,0,0,16,12,0
0,1,0,0,0,0,0,0,0,0,0,0,0,0,0,1,0
0,0,1,0,0,0,0,0,0,0,0,0,0,0,1,0,0
0,0,1,0,0,0,0,0,0,0,0,0,0,0,1,0,0
0,0,0,28,0,0,0,0,0,0,0,0,0,28,0,0,0
0,0,0,0,1,1,0,17,0,17,0,1,1,0,0,0,0
0,0,0,0,0,0,1,12,27,12,1,0,0,0,0,0,0
0,0,0,0,0,0,0,0,0,0,0,0,0,0,0,0,0
endlayer

layer
0,0,0,0,0,0,0,0,0,0,0,0,0,0,0,0,0
0,0,0,0,0,0,1,12,27,12,1,0,0,0,0,0,0
0,0,0,0,1,1,0,0,0,0,0,1,1,0,0,0,0
0,0,0,28,0,0,0,0,0,0,0,0,0,28,0,0,0
0,0,1,0,0,0,0,0,0,0,0,0,0,0,1,0,0
0,0,1,0,0,0,0,0,0,0,0,0,0,0,1,0,0
0,1,0,0,0,0,0,0,0,0,0,0,0,0,0,1,0
0,12,0,0,0,0,0,0,0,0,0,0,0,0,0,12,0
0,27,0,0,0,0,0,0,0,0,0,0,0,0,0,27,0
0,12,0,0,0,0,0,0,0,0,0,0,0,0,0,12,0
0,1,0,0,0,0,0,0,0,0,0,0,0,0,0,1,0
0,0,1,0,0,0,0,0,0,0,0,0,0,0,1,0,0
0,0,1,0,0,0,0,0,0,0,0,0,0,0,1,0,0
0,0,0,28,0,0,0,0,0,0,0,0,0,28,0,0,0
0,0,0,0,1,1,0,0,0,0,0,1,1,0,0,0,0
0,0,0,0,0,0,1,12,27,12,1,0,0,0,0,0,0
0,0,0,0,0,0,0,0,0,0,0,0,0,0,0,0,0
endlayer

layer
0,0,0,0,0,0,0,0,19,0,0,0,0,0,0,0,0
0,0,0,0,0,0,1,1,1,1,1,0,0,0,0,0,0
0,0,0,0,1,1,0,0,0,0,0,1,1,0,0,0,0
0,0,0,1,0,0,0,0,0,0,0,0,0,1,0,0,0
0,0,1,0,0,0,0,0,0,0,0,0,0,0,1,0,0
0,0,1,0,0,0,0,0,0,0,0,0,0,0,1,0,0
0,1,0,0,0,0,0,0,0,0,0,0,0,0,0,1,0
0,1,0,0,0,0,0,0,0,0,0,0,0,0,0,1,0
15,1,0,0,0,0,0,0,0,0,0,0,0,0,0,1,21
0,1,0,0,0,0,0,0,0,0,0,0,0,0,0,1,0
0,1,0,0,0,0,0,0,0,0,0,0,0,0,0,1,0
0,0,1,0,0,0,0,0,0,0,0,0,0,0,1,0,0
0,0,1,0,0,0,0,0,0,0,0,0,0,0,1,0,0
0,0,0,1,0,0,0,0,0,0,0,0,0,1,0,0,0
0,0,0,0,1,1,0,0,0,0,0,1,1,0,0,0,0
0,0,0,0,0,0,1,1,1,1,1,0,0,0,0,0,0
0,0,0,0,0,0,0,0,5,0,0,0,0,0,0,0,0
endlayer

layer
0,0,0,0,0,0,12,12,12,12,12,0,0,0,0,0,0
0,0,0,0,12,12,12,12,12,12,12,12,12,0,0,0,0
0,0,12,12,12,12,0,0,0,0,0,12,12,12,12,0,0
0,0,12,12,0,0,0,0,0,0,0,0,0,12,12,0,0
0,12,12,0,0,0,0,0,0,0,0,0,0,0,12,12,0
0,12,12,0,0,0,0,0,0,0,0,0,0,0,12,12,0
12,12,0,0,0,0,0,0,29,0,0,0,0,0,0,12,12
12,12,0,0,0,0,0,0,0,0,0,0,0,0,0,12,12
12,12,0,0,0,0,29,0,0,0,29,0,0,0,0,12,12
12,12,0,0,0,0,0,0,0,0,0,0,0,0,0,12,12
12,12,0,0,0,0,0,0,29,0,0,0,0,0,0,12,12
0,12,12,0,0,0,0,0,0,0,0,0,0,0,12,12,0
0,12,12,0,0,0,0,0,0,0,0,0,0,0,12,12,0
0,0,12,12,0,0,0,0,0,0,0,0,0,12,12,0,0
0,0,12,12,12,12,0,0,0,0,0,12,12,12,12,0,0
0,0,0,0,12,12,12,12,12,12,12,12,12,0,0,0,0
0,0,0,0,0,0,12,12,12,12,12,0,0,0,0,0,0
endlayer

layer
0,0,0,0,0,0,0,0,0,0,0,0,0,0,0,0,0
0,0,0,0,0,0,12,12,12,12,12,0,0,0,0,0,0
0,0,0,0,12,12,0,0,0,0,0,12,12,0,0,0,0
0,0,0,12,0,0,0,0,0,0,0,0,0,12,0,0,0
0,0,12,0,0,0,0,0,0,0,0,0,0,0,12,0,0
0,0,12,0,0,0,0,0,0,0,0,0,0,0,12,0,0
0,12,0,0,0,0,0,0,22,0,0,0,0,0,0,12,0
0,12,0,0,0,0,0,0,22,0,0,0,0,0,0,12,0
0,12,0,0,0,0,22,22,22,22,22,0,0,0,0,12,0
0,12,0,0,0,0,0,0,22,0,0,0,0,0,0,12,0
0,12,0,0,0,0,0,0,22,0,0,0,0,0,0,12,0
0,0,12,0,0,0,0,0,0,0,0,0,0,0,12,0,0
0,0,12,0,0,0,0,0,0,0,0,0,0,0,12,0,0
0,0,0,12,0,0,0,0,0,0,0,0,0,12,0,0,0
0,0,0,0,12,12,0,0,0,0,0,12,12,0,0,0,0
0,0,0,0,0,0,12,12,12,12,12,0,0,0,0,0,0
0,0,0,0,0,0,0,0,0,0,0,0,0,0,0,0,0
endlayer

layer
0,0,0,0,0,0,0,0,0,0,0,0,0,0,0,0,0
0,0,0,0,0,0,0,0,0,0,0,0,0,0,0,0,0
0,0,0,0,0,0,12,12,12,12,12,0,0,0,0,0,0
0,0,0,0,12,12,0,0,0,0,0,12,12,0,0,0,0
0,0,0,12,0,0,0,0,0,0,0,0,0,12,0,0,0
0,0,0,12,0,0,0,0,0,0,0,0,0,12,0,0,0
0,0,12,0,0,0,0,0,30,0,0,0,0,0,12,0,0
0,0,12,0,0,0,0,0,0,0,0,0,0,0,12,0,0
0,0,12,0,0,0,30,0,22,0,30,0,0,0,12,0,0
0,0,12,0,0,0,0,0,0,0,0,0,0,0,12,0,0
0,0,12,0,0,0,0,0,30,0,0,0,0,0,12,0,0
0,0,0,12,0,0,0,0,0,0,0,0,0,12,0,0,0
0,0,0,12,0,0,0,0,0,0,0,0,0,12,0,0,0
0,0,0,0,12,12,0,0,0,0,0,12,12,0,0,0,0
0,0,0,0,0,0,12,12,12,12,12,0,0,0,0,0,0
0,0,0,0,0,0,0,0,0,0,0,0,0,0,0,0,0
0,0,0,0,0,0,0,0,0,0,0,0,0,0,0,0,0
endlayer

layer
0,0,0,0,0,0,0,0,0,0,0,0,0,0,0,0,0
0,0,0,0,0,0,0,0,0,0,0,0,0,0,0,0,0
0,0,0,0,0,0,0,0,0,0,0,0,0,0,0,0,0
0,0,0,0,0,0,12,12,12,12,12,0,0,0,0,0,0
0,0,0,0,12,12,0,0,0,0,0,12,12,0,0,0,0
0,0,0,0,12,0,0,0,0,0,0,0,12,0,0,0,0
0,0,0,12,0,0,0,0,0,0,0,0,0,12,0,0,0
0,0,0,12,0,0,0,0,0,0,0,0,0,12,0,0,0
0,0,0,12,0,0,0,0,22,0,0,0,0,12,0,0,0
0,0,0,12,0,0,0,0,0,0,0,0,0,12,0,0,0
0,0,0,12,0,0,0,0,0,0,0,0,0,12,0,0,0
0,0,0,0,12,0,0,0,0,0,0,0,12,0,0,0,0
0,0,0,0,12,12,0,0,0,0,0,12,12,0,0,0,0
0,0,0,0,0,0,12,12,12,12,12,0,0,0,0,0,0
0,0,0,0,0,0,0,0,0,0,0,0,0,0,0,0,0
0,0,0,0,0,0,0,0,0,0,0,0,0,0,0,0,0
0,0,0,0,0,0,0,0,0,0,0,0,0,0,0,0,0
endlayer

layer
0,0,0,0,0,0,0,0,0,0,0,0,0,0,0,0,0
0,0,0,0,0,0,0,0,0,0,0,0,0,0,0,0,0
0,0,0,0,0,0,0,0,0,0,0,0,0,0,0,0,0
0,0,0,0,0,0,0,0,12,0,0,0,0,0,0,0,0
0,0,0,0,0,0,12,12,12,12,12,0,0,0,0,0,0
0,0,0,0,0,12,0,0,0,0,0,12,0,0,0,0,0
0,0,0,0,12,0,0,0,0,0,0,0,12,0,0,0,0
0,0,0,0,12,0,0,0,0,0,0,0,12,0,0,0,0
0,0,0,12,12,0,0,0,22,0,0,0,12,12,0,0,0
0,0,0,0,12,0,0,0,0,0,0,0,12,0,0,0,0
0,0,0,0,12,0,0,0,0,0,0,0,12,0,0,0,0
0,0,0,0,0,12,0,0,0,0,0,12,0,0,0,0,0
0,0,0,0,0,0,12,12,12,12,12,0,0,0,0,0,0
0,0,0,0,0,0,0,0,12,0,0,0,0,0,0,0,0
0,0,0,0,0,0,0,0,0,0,0,0,0,0,0,0,0
0,0,0,0,0,0,0,0,0,0,0,0,0,0,0,0,0
0,0,0,0,0,0,0,0,0,0,0,0,0,0,0,0,0
endlayer

layer
0,0,0,0,0,0,0,0,0,0,0,0,0,0,0,0,0
0,0,0,0,0,0,0,0,0,0,0,0,0,0,0,0,0
0,0,0,0,0,0,0,0,0,0,0,0,0,0,0,0,0
0,0,0,0,0,0,0,0,0,0,0,0,0,0,0,0,0
0,0,0,0,0,0,0,0,12,0,0,0,0,0,0,0,0
0,0,0,0,0,0,12,12,12,12,12,0,0,0,0,0,0
0,0,0,0,0,12,0,0,0,0,0,12,0,0,0,0,0
0,0,0,0,0,12,0,0,0,0,0,12,0,0,0,0,0
0,0,0,0,12,12,0,0,22,0,0,12,12,0,0,0,0
0,0,0,0,0,12,0,0,0,0,0,12,0,0,0,0,0
0,0,0,0,0,12,0,0,0,0,0,12,0,0,0,0,0
0,0,0,0,0,0,12,12,12,12,12,0,0,0,0,0,0
0,0,0,0,0,0,0,0,12,0,0,0,0,0,0,0,0
0,0,0,0,0,0,0,0,0,0,0,0,0,0,0,0,0
0,0,0,0,0,0,0,0,0,0,0,0,0,0,0,0,0
0,0,0,0,0,0,0,0,0,0,0,0,0,0,0,0,0
0,0,0,0,0,0,0,0,0,0,0,0,0,0,0,0,0
endlayer

layer
0,0,0,0,0,0,0,0,0,0,0,0,0,0,0,0,0
0,0,0,0,0,0,0,0,0,0,0,0,0,0,0,0,0
0,0,0,0,0,0,0,0,0,0,0,0,0,0,0,0,0
0,0,0,0,0,0,0,0,0,0,0,0,0,0,0,0,0
0,0,0,0,0,0,0,0,0,0,0,0,0,0,0,0,0
0,0,0,0,0,0,12,12,12,12,12,0,0,0,0,0,0
0,0,0,0,0,12,0,0,0,0,0,12,0,0,0,0,0
0,0,0,0,0,12,0,0,0,0,0,12,0,0,0,0,0
0,0,0,0,0,12,0,0,22,0,0,12,0,0,0,0,0
0,0,0,0,0,12,0,0,0,0,0,12,0,0,0,0,0
0,0,0,0,0,12,0,0,0,0,0,12,0,0,0,0,0
0,0,0,0,0,0,12,12,12,12,12,0,0,0,0,0,0
0,0,0,0,0,0,0,0,0,0,0,0,0,0,0,0,0
0,0,0,0,0,0,0,0,0,0,0,0,0,0,0,0,0
0,0,0,0,0,0,0,0,0,0,0,0,0,0,0,0,0
0,0,0,0,0,0,0,0,0,0,0,0,0,0,0,0,0
0,0,0,0,0,0,0,0,0,0,0,0,0,0,0,0,0
endlayer

layer
0,0,0,0,0,0,0,0,0,0,0,0,0,0,0,0,0
0,0,0,0,0,0,0,0,0,0,0,0,0,0,0,0,0
0,0,0,0,0,0,0,0,0,0,0,0,0,0,0,0,0
0,0,0,0,0,0,0,0,0,0,0,0,0,0,0,0,0
0,0,0,0,0,0,0,0,0,0,0,0,0,0,0,0,0
0,0,0,0,0,0,0,0,12,0,0,0,0,0,0,0,0
0,0,0,0,0,0,12,12,12,12,12,0,0,0,0,0,0
0,0,0,0,0,0,12,0,0,0,12,0,0,0,0,0,0
0,0,0,0,0,12,12,0,22,0,12,12,0,0,0,0,0
0,0,0,0,0,0,12,0,0,0,12,0,0,0,0,0,0
0,0,0,0,0,0,12,12,12,12,12,0,0,0,0,0,0
0,0,0,0,0,0,0,0,12,0,0,0,0,0,0,0,0
0,0,0,0,0,0,0,0,0,0,0,0,0,0,0,0,0
0,0,0,0,0,0,0,0,0,0,0,0,0,0,0,0,0
0,0,0,0,0,0,0,0,0,0,0,0,0,0,0,0,0
0,0,0,0,0,0,0,0,0,0,0,0,0,0,0,0,0
0,0,0,0,0,0,0,0,0,0,0,0,0,0,0,0,0
endlayer

layer
0,0,0,0,0,0,0,0,0,0,0,0,0,0,0,0,0
0,0,0,0,0,0,0,0,0,0,0,0,0,0,0,0,0
0,0,0,0,0,0,0,0,0,0,0,0,0,0,0,0,0
0,0,0,0,0,0,0,0,0,0,0,0,0,0,0,0,0
0,0,0,0,0,0,0,0,0,0,0,0,0,0,0,0,0
0,0,0,0,0,0,0,0,0,0,0,0,0,0,0,0,0
0,0,0,0,0,0,0,12,12,12,0,0,0,0,0,0,0
0,0,0,0,0,0,12,0,0,0,12,0,0,0,0,0,0
0,0,0,0,0,0,12,0,22,0,12,0,0,0,0,0,0
0,0,0,0,0,0,12,0,0,0,12,0,0,0,0,0,0
0,0,0,0,0,0,0,12,12,12,0,0,0,0,0,0,0
0,0,0,0,0,0,0,0,0,0,0,0,0,0,0,0,0
0,0,0,0,0,0,0,0,0,0,0,0,0,0,0,0,0
0,0,0,0,0,0,0,0,0,0,0,0,0,0,0,0,0
0,0,0,0,0,0,0,0,0,0,0,0,0,0,0,0,0
0,0,0,0,0,0,0,0,0,0,0,0,0,0,0,0,0
0,0,0,0,0,0,0,0,0,0,0,0,0,0,0,0,0
endlayer

layer
0,0,0,0,0,0,0,0,0,0,0,0,0,0,0,0,0
0,0,0,0,0,0,0,0,0,0,0,0,0,0,0,0,0
0,0,0,0,0,0,0,0,0,0,0,0,0,0,0,0,0
0,0,0,0,0,0,0,0,0,0,0,0,0,0,0,0,0
0,0,0,0,0,0,0,0,0,0,0,0,0,0,0,0,0
0,0,0,0,0,0,0,0,0,0,0,0,0,0,0,0,0
0,0,0,0,0,0,0,0,0,0,0,0,0,0,0,0,0
0,0,0,0,0,0,0,12,12,12,0,0,0,0,0,0,0
0,0,0,0,0,0,0,12,12,12,0,0,0,0,0,0,0
0,0,0,0,0,0,0,12,12,12,0,0,0,0,0,0,0
0,0,0,0,0,0,0,0,0,0,0,0,0,0,0,0,0
0,0,0,0,0,0,0,0,0,0,0,0,0,0,0,0,0
0,0,0,0,0,0,0,0,0,0,0,0,0,0,0,0,0
0,0,0,0,0,0,0,0,0,0,0,0,0,0,0,0,0
0,0,0,0,0,0,0,0,0,0,0,0,0,0,0,0,0
0,0,0,0,0,0,0,0,0,0,0,0,0,0,0,0,0
0,0,0,0,0,0,0,0,0,0,0,0,0,0,0,0,0
endlayer

layer
0,0,0,0,0,0,0,0,0,0,0,0,0,0,0,0,0
0,0,0,0,0,0,0,0,0,0,0,0,0,0,0,0,0
0,0,0,0,0,0,0,0,0,0,0,0,0,0,0,0,0
0,0,0,0,0,0,0,0,0,0,0,0,0,0,0,0,0
0,0,0,0,0,0,0,0,0,0,0,0,0,0,0,0,0
0,0,0,0,0,0,0,0,0,0,0,0,0,0,0,0,0
0,0,0,0,0,0,0,0,0,0,0,0,0,0,0,0,0
0,0,0,0,0,0,0,0,0,0,0,0,0,0,0,0,0
0,0,0,0,0,0,0,0,12,0,0,0,0,0,0,0,0
0,0,0,0,0,0,0,0,0,0,0,0,0,0,0,0,0
0,0,0,0,0,0,0,0,0,0,0,0,0,0,0,0,0
0,0,0,0,0,0,0,0,0,0,0,0,0,0,0,0,0
0,0,0,0,0,0,0,0,0,0,0,0,0,0,0,0,0
0,0,0,0,0,0,0,0,0,0,0,0,0,0,0,0,0
0,0,0,0,0,0,0,0,0,0,0,0,0,0,0,0,0
0,0,0,0,0,0,0,0,0,0,0,0,0,0,0,0,0
0,0,0,0,0,0,0,0,0,0,0,0,0,0,0,0,0
endlayer

layer
0,0,0,0,0,0,0,0,0,0,0,0,0,0,0,0,0
0,0,0,0,0,0,0,0,0,0,0,0,0,0,0,0,0
0,0,0,0,0,0,0,0,0,0,0,0,0,0,0,0,0
0,0,0,0,0,0,0,0,0,0,0,0,0,0,0,0,0
0,0,0,0,0,0,0,0,0,0,0,0,0,0,0,0,0
0,0,0,0,0,0,0,0,0,0,0,0,0,0,0,0,0
0,0,0,0,0,0,0,0,0,0,0,0,0,0,0,0,0
0,0,0,0,0,0,0,0,0,0,0,0,0,0,0,0,0
0,0,0,0,0,0,0,0,12,0,0,0,0,0,0,0,0
0,0,0,0,0,0,0,0,0,0,0,0,0,0,0,0,0
0,0,0,0,0,0,0,0,0,0,0,0,0,0,0,0,0
0,0,0,0,0,0,0,0,0,0,0,0,0,0,0,0,0
0,0,0,0,0,0,0,0,0,0,0,0,0,0,0,0,0
0,0,0,0,0,0,0,0,0,0,0,0,0,0,0,0,0
0,0,0,0,0,0,0,0,0,0,0,0,0,0,0,0,0
0,0,0,0,0,0,0,0,0,0,0,0,0,0,0,0,0
0,0,0,0,0,0,0,0,0,0,0,0,0,0,0,0,0
endlayer

layer
0,0,0,0,0,0,0,0,0,0,0,0,0,0,0,0,0
0,0,0,0,0,0,0,0,0,0,0,0,0,0,0,0,0
0,0,0,0,0,0,0,0,0,0,0,0,0,0,0,0,0
0,0,0,0,0,0,0,0,0,0,0,0,0,0,0,0,0
0,0,0,0,0,0,0,0,0,0,0,0,0,0,0,0,0
0,0,0,0,0,0,0,0,0,0,0,0,0,0,0,0,0
0,0,0,0,0,0,0,0,0,0,0,0,0,0,0,0,0
0,0,0,0,0,0,0,0,0,0,0,0,0,0,0,0,0
0,0,0,0,0,0,0,0,22,0,0,0,0,0,0,0,0
0,0,0,0,0,0,0,0,0,0,0,0,0,0,0,0,0
0,0,0,0,0,0,0,0,0,0,0,0,0,0,0,0,0
0,0,0,0,0,0,0,0,0,0,0,0,0,0,0,0,0
0,0,0,0,0,0,0,0,0,0,0,0,0,0,0,0,0
0,0,0,0,0,0,0,0,0,0,0,0,0,0,0,0,0
0,0,0,0,0,0,0,0,0,0,0,0,0,0,0,0,0
0,0,0,0,0,0,0,0,0,0,0,0,0,0,0,0,0
0,0,0,0,0,0,0,0,0,0,0,0,0,0,0,0,0
endlayer

layer
0,0,0,0,0,0,0,0,0,0,0,0,0,0,0,0,0
0,0,0,0,0,0,0,0,0,0,0,0,0,0,0,0,0
0,0,0,0,0,0,0,0,0,0,0,0,0,0,0,0,0
0,0,0,0,0,0,0,0,0,0,0,0,0,0,0,0,0
0,0,0,0,0,0,0,0,0,0,0,0,0,0,0,0,0
0,0,0,0,0,0,0,0,0,0,0,0,0,0,0,0,0
0,0,0,0,0,0,0,0,0,0,0,0,0,0,0,0,0
0,0,0,0,0,0,0,0,0,0,0,0,0,0,0,0,0
0,0,0,0,0,0,0,0,22,0,0,0,0,0,0,0,0
0,0,0,0,0,0,0,0,0,0,0,0,0,0,0,0,0
0,0,0,0,0,0,0,0,0,0,0,0,0,0,0,0,0
0,0,0,0,0,0,0,0,0,0,0,0,0,0,0,0,0
0,0,0,0,0,0,0,0,0,0,0,0,0,0,0,0,0
0,0,0,0,0,0,0,0,0,0,0,0,0,0,0,0,0
0,0,0,0,0,0,0,0,0,0,0,0,0,0,0,0,0
0,0,0,0,0,0,0,0,0,0,0,0,0,0,0,0,0
0,0,0,0,0,0,0,0,0,0,0,0,0,0,0,0,0
endlayer

layer
0,0,0,0,0,0,0,0,0,0,0,0,0,0,0,0,0
0,0,0,0,0,0,0,0,0,0,0,0,0,0,0,0,0
0,0,0,0,0,0,0,0,0,0,0,0,0,0,0,0,0
0,0,0,0,0,0,0,0,0,0,0,0,0,0,0,0,0
0,0,0,0,0,0,0,0,0,0,0,0,0,0,0,0,0
0,0,0,0,0,0,0,0,0,0,0,0,0,0,0,0,0
0,0,0,0,0,0,0,0,0,0,0,0,0,0,0,0,0
0,0,0,0,0,0,0,0,0,0,0,0,0,0,0,0,0
0,0,0,0,0,0,0,0,31,0,0,0,0,0,0,0,0
0,0,0,0,0,0,0,0,0,0,0,0,0,0,0,0,0
0,0,0,0,0,0,0,0,0,0,0,0,0,0,0,0,0
0,0,0,0,0,0,0,0,0,0,0,0,0,0,0,0,0
0,0,0,0,0,0,0,0,0,0,0,0,0,0,0,0,0
0,0,0,0,0,0,0,0,0,0,0,0,0,0,0,0,0
0,0,0,0,0,0,0,0,0,0,0,0,0,0,0,0,0
0,0,0,0,0,0,0,0,0,0,0,0,0,0,0,0,0
0,0,0,0,0,0,0,0,0,0,0,0,0,0,0,0,0
endlayer



