# Converted from schematic
# author:MohawkyMagoo

weight=10
embed_into_distance=0
#acceptable_target_blocks=1,2,3,12,13,9
dimensions=36,13,12
#allowable_overhang=0
max_cut_in=2
#cut_in_buffer=1
max_leveling=2
#leveling_buffer=1
#preserve_water=0
#preserve_lava=0
#preserve_plants=0


rule1=0,100,17
rule2=0,100,4
rule3=0,100,98
rule4=0,100,109-3
rule5=0,100,71-3
rule6=0,100,71-8
rule7=0,100,69-2
rule8=0,100,109
rule9=0,100,67-1
rule10=0,100,5
rule11=0,100,67-3
rule12=0,100,67
rule13=0,100,67-0
rule14=0,100,85
rule15=0,100,65-4
rule16=0,100,53-6
rule17=0,100,53-4
rule18=0,100,53-5
rule19=0,100,53-7
rule20=0,100,67-6
rule21=0,100,67-4
rule22=0,100,67-5
rule23=0,100,67-7
rule24=0,100,65-3
rule25=0,100,102
rule26=0,100,44-2
rule27=0,100,53
rule28=0,100,53-1
rule29=0,100,53-3
rule30=0,100,53-2


layer
0,0,0,0,0,0,0,0,0,0,0,0
0,0,0,0,0,0,0,0,0,0,0,0
0,0,0,0,0,1,2,1,0,0,0,0
0,0,0,0,2,3,3,3,2,0,0,0
0,0,3,2,3,3,3,3,3,2,0,0
0,0,3,3,3,3,3,3,3,3,1,0
0,0,3,3,3,3,3,3,3,3,2,0
0,0,3,3,3,3,3,3,3,3,1,0
0,0,3,2,3,3,3,3,3,2,0,0
0,0,0,0,2,3,3,3,2,0,0,0
0,0,0,0,0,1,2,1,0,0,0,0
0,0,0,0,0,0,0,0,0,0,0,0
0,0,0,0,0,0,0,0,0,0,0,0
endlayer

layer
0,0,0,0,0,0,0,0,0,0,0,0
0,0,0,0,0,0,0,0,0,0,0,0
0,0,0,0,0,1,2,1,0,0,0,0
0,0,0,0,2,3,3,3,2,0,0,0
0,0,3,2,4,3,3,0,0,2,0,0
0,0,3,0,0,0,0,0,0,0,1,0
0,0,5,0,0,0,0,0,0,0,2,0
0,0,3,0,0,0,0,0,0,0,1,0
0,0,3,2,0,0,0,0,0,2,0,0
0,0,0,0,2,0,0,0,2,0,0,0
0,0,0,0,0,1,2,1,0,0,0,0
0,0,0,0,0,0,0,0,0,0,0,0
0,0,0,0,0,0,0,0,0,0,0,0
endlayer

layer
0,0,0,0,0,0,0,0,0,0,0,0
0,0,0,0,0,0,0,0,0,0,0,0
0,0,0,0,0,1,2,1,0,0,0,0
0,0,0,0,2,3,3,3,2,0,0,0
0,0,3,2,0,4,3,0,0,2,0,0
0,0,3,0,0,0,0,0,0,0,1,0
0,0,6,0,0,0,0,0,0,0,2,0
0,0,7,0,0,0,0,0,0,0,1,0
0,0,3,2,0,0,0,0,0,2,0,0
0,0,0,0,2,0,0,0,2,0,0,0
0,0,0,0,0,1,2,1,0,0,0,0
0,0,0,0,0,0,0,0,0,0,0,0
0,0,0,0,0,0,0,0,0,0,0,0
endlayer

layer
0,0,0,0,0,0,0,0,0,0,0,0
0,0,0,0,0,0,0,0,0,0,0,0
0,0,0,0,0,1,2,1,0,0,0,0
0,0,0,0,2,0,3,3,2,0,0,0
0,0,3,2,0,0,4,3,0,2,0,0
0,0,3,0,0,0,0,0,0,0,1,0
0,0,3,0,0,0,0,0,0,0,2,0
0,0,3,0,0,0,0,0,0,0,1,0
0,0,3,2,0,0,0,0,0,2,0,0
0,0,0,0,2,0,0,0,2,0,0,0
0,0,0,0,0,1,2,1,0,0,0,0
0,0,0,0,0,0,0,0,0,0,0,0
0,0,0,0,0,0,0,0,0,0,0,0
endlayer

layer
0,0,0,0,0,0,0,0,0,0,0,0
0,0,0,0,0,0,0,0,0,0,0,0
0,0,0,0,0,1,2,1,0,0,0,0
0,0,0,0,2,0,0,3,2,0,0,0
0,0,0,2,0,0,0,4,3,2,0,0
0,0,1,0,0,0,0,0,3,0,1,0
0,0,3,0,0,0,0,0,0,0,2,0
0,0,1,0,0,0,0,0,0,0,1,0
0,0,0,2,0,0,0,0,0,2,0,0
0,0,0,0,2,0,0,0,2,0,0,0
0,0,0,0,0,1,2,1,0,0,0,0
0,0,0,0,0,0,0,0,0,0,0,0
0,0,0,0,0,0,0,0,0,0,0,0
endlayer

layer
0,0,0,0,0,0,0,0,0,0,0,0
0,0,0,0,0,0,0,0,0,0,0,0
0,0,0,0,0,1,2,1,0,0,0,0
0,0,0,0,2,0,0,0,2,0,0,0
0,0,0,2,0,0,0,0,0,2,0,0
0,0,1,0,0,0,0,0,8,3,1,0
0,0,3,0,0,0,0,0,3,3,2,0
0,0,1,0,0,0,0,0,0,3,1,0
0,0,0,2,0,0,0,0,0,2,0,0
0,0,0,0,2,0,0,0,2,0,0,0
0,0,0,0,0,1,2,1,0,0,0,0
0,0,0,0,0,0,0,0,0,0,0,0
0,0,0,0,0,0,0,0,0,0,0,0
endlayer

layer
0,0,0,0,0,0,0,0,0,0,0,0
0,0,0,0,0,0,0,0,0,0,0,0
0,0,0,0,0,1,2,1,0,0,0,0
0,0,0,0,2,0,0,0,2,0,0,0
0,0,0,2,0,0,0,0,0,2,0,0
0,0,1,0,0,0,0,0,0,3,1,0
0,0,3,0,0,0,0,0,8,3,2,0
0,0,1,0,0,0,0,0,0,3,1,0
0,0,0,2,0,0,0,0,0,2,0,0
0,0,0,0,2,0,0,0,2,0,0,0
0,0,0,0,0,1,2,1,0,0,0,0
0,0,0,0,0,0,0,0,0,0,0,0
0,0,0,0,0,0,0,0,0,0,0,0
endlayer

layer
0,0,0,0,0,0,0,0,0,0,0,0
0,0,0,0,0,0,0,0,0,0,0,0
0,0,0,0,0,1,12,1,0,0,0,0
0,0,0,0,3,10,10,10,3,0,0,0
0,0,0,3,2,10,10,10,0,3,0,0
0,0,1,10,10,10,10,10,0,10,1,0
0,0,3,10,10,10,10,10,0,10,9,0
0,0,1,10,10,10,10,10,8,10,1,0
0,0,0,11,2,10,10,10,2,11,0,0
0,0,0,0,13,10,10,10,9,0,0,0
0,0,0,0,0,1,11,1,0,0,0,0
0,0,0,0,0,0,0,0,0,0,0,0
0,0,0,0,0,0,0,0,0,0,0,0
endlayer

layer
0,0,0,0,0,0,0,0,0,0,0,0
0,0,0,0,0,0,0,0,0,0,0,0
0,0,0,0,0,14,0,14,0,0,0,0
0,0,0,0,3,2,1,2,3,0,0,0
0,0,0,0,2,0,0,0,2,0,0,0
0,0,14,2,0,0,0,0,0,2,14,0
0,0,0,1,0,0,0,0,0,1,0,0
0,0,14,2,0,0,0,0,0,2,14,0
0,0,0,0,2,0,15,0,2,0,0,0
0,0,0,0,0,2,1,2,0,0,0,0
0,0,0,0,0,14,0,14,0,0,0,0
0,0,0,0,0,0,0,0,0,0,0,0
0,0,0,0,0,0,0,0,0,0,0,0
endlayer

layer
0,0,0,0,0,0,0,0,0,0,0,0
0,0,0,0,0,0,0,0,0,0,0,0
0,0,0,0,0,0,0,0,0,0,0,0
0,0,0,0,0,2,1,2,0,0,0,0
0,0,0,0,2,0,0,0,2,0,0,0
0,0,0,3,0,0,0,0,0,2,0,0
0,0,0,1,0,0,0,0,0,1,0,0
0,0,0,2,0,0,0,0,0,2,0,0
0,0,0,0,2,0,15,0,2,0,0,0
0,0,0,0,0,2,1,2,0,0,0,0
0,0,0,0,0,0,0,0,0,0,0,0
0,0,0,0,0,0,0,0,0,0,0,0
0,0,0,0,0,0,0,0,0,0,0,0
endlayer

layer
0,0,0,0,0,0,0,0,0,0,0,0
0,0,0,0,0,0,0,0,0,0,0,0
0,0,0,0,0,0,0,0,0,0,0,0
0,0,0,0,0,2,1,2,0,0,0,0
0,0,0,0,2,0,0,0,2,0,0,0
0,0,0,2,0,0,0,0,0,2,0,0
0,0,0,1,0,0,0,0,0,1,0,0
0,0,0,2,0,0,0,0,0,2,0,0
0,0,0,0,2,0,15,0,2,0,0,0
0,0,0,0,0,2,1,2,0,0,0,0
0,0,0,0,0,0,0,0,0,0,0,0
0,0,0,0,0,0,0,0,0,0,0,0
0,0,0,0,0,0,0,0,0,0,0,0
endlayer

layer
0,0,0,0,0,0,0,0,0,0,0,0
0,0,0,0,0,0,0,0,0,0,0,0
0,0,0,0,0,0,17,0,0,0,0,0
0,0,0,0,0,2,1,2,0,0,0,0
0,0,0,0,2,0,0,0,2,0,0,0
0,0,0,2,0,0,0,0,0,2,0,0
0,0,19,1,0,0,0,0,0,1,16,0
0,0,0,2,0,0,0,0,0,2,0,0
0,0,0,0,2,0,15,0,2,0,0,0
0,0,0,0,0,2,1,2,0,0,0,0
0,0,0,0,0,0,18,0,0,0,0,0
0,0,0,0,0,0,0,0,0,0,0,0
0,0,0,0,0,0,0,0,0,0,0,0
endlayer

layer
0,0,0,0,0,0,0,0,0,0,0,0
0,0,0,0,0,0,0,0,0,0,0,0
0,0,0,0,0,19,1,16,0,0,0,0
0,0,0,0,21,2,1,2,21,0,0,0
0,0,0,23,2,0,0,0,2,20,0,0
0,0,17,2,0,0,0,0,0,2,17,0
0,0,1,1,0,0,0,0,0,1,1,0
0,0,18,2,0,0,0,0,0,2,18,0
0,0,0,23,2,0,15,0,2,20,0,0
0,0,0,0,22,2,1,2,22,0,0,0
0,0,0,0,0,19,1,16,0,0,0,0
0,0,0,0,0,0,0,0,0,0,0,0
0,0,0,0,0,0,0,0,0,0,0,0
endlayer

layer
0,0,0,0,0,0,0,0,0,0,0,0
0,0,0,0,0,0,17,0,0,0,0,0
0,0,0,0,14,1,2,1,14,0,0,0
0,0,0,14,2,10,10,10,2,14,0,0
0,0,14,2,10,10,10,10,10,2,14,0
0,0,1,10,10,10,10,10,10,10,1,0
0,19,2,10,10,10,10,10,10,10,2,16
0,0,1,10,10,10,10,10,10,10,1,0
0,0,14,2,10,10,15,10,10,2,14,0
0,0,0,14,2,10,10,10,2,14,0,0
0,0,0,0,14,1,2,1,14,0,0,0
0,0,0,0,0,0,18,0,0,0,0,0
0,0,0,0,0,0,0,0,0,0,0,0
endlayer

layer
0,0,0,0,0,0,0,0,0,0,0,0
0,0,0,0,0,0,1,0,0,0,0,0
0,0,0,0,1,1,1,1,1,0,0,0
0,0,0,1,0,0,0,0,0,1,0,0
0,0,1,0,0,0,0,0,0,0,1,0
0,0,1,0,0,0,0,0,0,0,1,0
0,1,1,0,0,0,0,0,0,24,1,1
0,0,1,0,0,0,0,0,0,0,1,0
0,0,1,0,0,0,0,0,0,0,1,0
0,0,0,1,0,0,0,0,0,1,0,0
0,0,0,0,1,1,1,1,1,0,0,0
0,0,0,0,0,0,1,0,0,0,0,0
0,0,0,0,0,0,0,0,0,0,0,0
endlayer

layer
0,0,0,0,0,0,0,0,0,0,0,0
0,0,0,0,0,0,1,0,0,0,0,0
0,0,0,0,10,25,10,25,10,0,0,0
0,0,0,1,0,0,0,0,0,1,0,0
0,0,10,0,0,0,0,0,0,0,10,0
0,0,25,0,0,0,0,0,0,0,25,0
0,1,10,0,0,0,0,0,0,24,10,1
0,0,25,0,0,0,0,0,0,0,25,0
0,0,10,0,0,0,0,0,0,0,10,0
0,0,0,1,0,0,0,0,0,1,0,0
0,0,0,0,10,25,10,25,10,0,0,0
0,0,0,0,0,0,1,0,0,0,0,0
0,0,0,0,0,0,0,0,0,0,0,0
endlayer

layer
0,0,0,0,0,0,0,0,0,0,0,0
0,0,0,0,0,0,1,0,0,0,0,0
0,0,0,0,10,25,10,25,10,0,0,0
0,0,0,1,0,0,0,0,0,1,0,0
0,0,10,0,0,0,0,0,0,0,10,0
0,0,25,0,0,0,0,0,0,0,25,0
0,1,10,0,0,0,0,0,0,24,10,1
0,0,25,0,0,0,0,0,0,0,25,0
0,0,10,0,0,0,0,0,0,0,10,0
0,0,0,1,0,0,0,0,0,1,0,0
0,0,0,0,10,25,10,25,10,0,0,0
0,0,0,0,0,0,1,0,0,0,0,0
0,0,0,0,0,0,0,0,0,0,0,0
endlayer

layer
0,0,0,0,0,0,0,0,0,0,0,0
0,0,0,0,0,0,1,0,0,0,0,0
0,0,0,0,10,25,10,25,10,0,0,0
0,0,0,1,0,0,0,0,0,1,0,0
0,0,10,0,0,0,0,0,0,0,10,0
0,0,25,0,0,0,0,0,0,0,25,0
0,1,10,0,0,0,0,0,0,24,10,1
0,0,25,0,0,0,0,0,0,0,25,0
0,0,10,0,0,0,0,0,0,0,10,0
0,0,0,1,0,0,0,0,0,1,0,0
0,0,0,0,10,25,10,25,10,0,0,0
0,0,0,0,0,0,1,0,0,0,0,0
0,0,0,0,0,0,0,0,0,0,0,0
endlayer

layer
0,0,0,0,0,0,0,0,0,0,0,0
0,0,0,0,0,0,1,0,0,0,0,0
0,0,0,0,1,1,1,1,1,0,0,0
0,0,0,1,10,10,10,10,10,1,0,0
0,0,1,10,10,10,10,10,10,10,1,0
0,0,1,10,10,10,10,10,10,10,1,0
0,1,1,10,10,10,10,10,10,24,1,1
0,0,1,10,10,10,10,10,10,10,1,0
0,0,1,10,10,10,10,10,10,10,1,0
0,0,0,1,10,10,10,10,10,1,0,0
0,0,0,0,1,1,1,1,1,0,0,0
0,0,0,0,0,0,1,0,0,0,0,0
0,0,0,0,0,0,0,0,0,0,0,0
endlayer

layer
0,0,0,0,26,27,27,27,26,0,0,0
0,0,0,26,10,10,0,10,10,26,0,0
0,0,26,10,0,0,0,0,0,10,26,0
0,26,10,0,0,0,0,0,0,0,10,26
26,10,0,0,0,0,0,0,0,0,0,10
29,10,0,0,0,0,0,0,0,0,0,10
29,0,0,0,0,0,0,0,0,0,0,0
29,10,0,0,0,0,0,0,0,0,0,10
26,10,0,0,0,0,0,0,0,0,0,10
0,26,10,0,0,0,0,0,0,0,10,26
0,0,26,10,0,0,0,0,0,10,26,0
0,0,0,26,10,10,0,10,10,26,0,0
0,0,0,0,26,28,28,28,26,0,0,0
endlayer

layer
0,0,0,0,0,0,0,0,0,0,0,0
0,0,0,0,0,27,27,27,0,0,0,0
0,0,0,0,27,10,0,10,27,0,0,0
0,0,0,10,0,0,0,0,0,10,0,0
0,0,29,0,0,0,0,0,0,0,30,0
0,29,10,0,0,0,0,0,0,0,10,30
0,29,0,0,0,0,0,0,0,0,0,30
0,29,10,0,0,0,0,0,0,0,10,30
0,0,29,0,0,0,0,0,0,0,30,0
0,0,0,10,0,0,0,0,0,10,0,0
0,0,0,0,28,10,0,10,28,0,0,0
0,0,0,0,0,28,28,28,0,0,0,0
0,0,0,0,0,0,0,0,0,0,0,0
endlayer

layer
0,0,0,0,0,0,0,0,0,0,0,0
0,0,0,0,0,0,0,0,0,0,0,0
0,0,0,0,0,29,10,30,0,0,0,0
0,0,0,0,27,10,10,10,27,0,0,0
0,0,0,29,10,10,10,10,10,30,0,0
0,0,27,10,10,10,10,10,10,10,27,0
0,0,10,10,10,10,10,10,10,10,10,0
0,0,28,10,10,10,10,10,10,10,28,0
0,0,0,29,10,10,10,10,10,30,0,0
0,0,0,0,28,10,10,10,28,0,0,0
0,0,0,0,0,29,10,30,0,0,0,0
0,0,0,0,0,0,0,0,0,0,0,0
0,0,0,0,0,0,0,0,0,0,0,0
endlayer

layer
0,0,0,0,0,0,0,0,0,0,0,0
0,0,0,0,0,0,0,0,0,0,0,0
0,0,0,0,0,0,0,0,0,0,0,0
0,0,0,0,14,14,1,14,14,0,0,0
0,0,0,14,14,0,0,0,14,14,0,0
0,0,0,14,0,0,0,0,0,14,0,0
0,0,0,1,0,0,0,0,0,1,0,0
0,0,0,14,0,0,0,0,0,14,0,0
0,0,0,14,14,0,0,0,14,14,0,0
0,0,0,0,14,14,1,14,14,0,0,0
0,0,0,0,0,0,0,0,0,0,0,0
0,0,0,0,0,0,0,0,0,0,0,0
0,0,0,0,0,0,0,0,0,0,0,0
endlayer

layer
0,0,0,0,0,0,0,0,0,0,0,0
0,0,0,0,0,0,0,0,0,0,0,0
0,0,0,0,0,0,0,0,0,0,0,0
0,0,0,0,0,0,1,0,0,0,0,0
0,0,0,0,0,0,0,0,0,0,0,0
0,0,0,0,0,0,0,0,0,0,0,0
0,0,0,1,0,0,0,0,0,1,0,0
0,0,0,0,0,0,0,0,0,0,0,0
0,0,0,0,0,0,0,0,0,0,0,0
0,0,0,0,0,0,1,0,0,0,0,0
0,0,0,0,0,0,0,0,0,0,0,0
0,0,0,0,0,0,0,0,0,0,0,0
0,0,0,0,0,0,0,0,0,0,0,0
endlayer

layer
0,0,0,0,0,0,0,0,0,0,0,0
0,0,0,0,0,0,0,0,0,0,0,0
0,0,0,0,0,27,27,27,0,0,0,0
0,0,0,0,10,1,1,1,10,0,0,0
0,0,0,10,1,0,0,0,1,10,0,0
0,0,29,1,0,0,0,0,0,1,30,0
0,0,29,1,0,0,0,0,0,1,30,0
0,0,29,1,0,0,0,0,0,1,30,0
0,0,0,10,1,0,0,0,1,10,0,0
0,0,0,0,10,1,1,1,10,0,0,0
0,0,0,0,0,28,28,28,0,0,0,0
0,0,0,0,0,0,0,0,0,0,0,0
0,0,0,0,0,0,0,0,0,0,0,0
endlayer

layer
0,0,0,0,0,0,0,0,0,0,0,0
0,0,0,0,0,0,0,0,0,0,0,0
0,0,0,0,0,0,0,0,0,0,0,0
0,0,0,0,0,27,27,27,0,0,0,0
0,0,0,0,10,0,0,0,10,0,0,0
0,0,0,29,0,0,0,0,0,30,0,0
0,0,0,29,0,0,0,0,0,30,0,0
0,0,0,29,0,0,0,0,0,30,0,0
0,0,0,0,10,0,0,0,10,0,0,0
0,0,0,0,0,28,28,28,0,0,0,0
0,0,0,0,0,0,0,0,0,0,0,0
0,0,0,0,0,0,0,0,0,0,0,0
0,0,0,0,0,0,0,0,0,0,0,0
endlayer

layer
0,0,0,0,0,0,0,0,0,0,0,0
0,0,0,0,0,0,0,0,0,0,0,0
0,0,0,0,0,0,0,0,0,0,0,0
0,0,0,0,0,0,0,0,0,0,0,0
0,0,0,0,0,10,10,10,0,0,0,0
0,0,0,0,10,0,0,0,10,0,0,0
0,0,0,0,10,0,0,0,10,0,0,0
0,0,0,0,10,0,0,0,10,0,0,0
0,0,0,0,0,10,10,10,0,0,0,0
0,0,0,0,0,0,0,0,0,0,0,0
0,0,0,0,0,0,0,0,0,0,0,0
0,0,0,0,0,0,0,0,0,0,0,0
0,0,0,0,0,0,0,0,0,0,0,0
endlayer

layer
0,0,0,0,0,0,0,0,0,0,0,0
0,0,0,0,0,0,0,0,0,0,0,0
0,0,0,0,0,0,0,0,0,0,0,0
0,0,0,0,0,0,0,0,0,0,0,0
0,0,0,0,0,0,27,0,0,0,0,0
0,0,0,0,0,10,0,10,0,0,0,0
0,0,0,0,29,0,0,0,30,0,0,0
0,0,0,0,0,10,0,10,0,0,0,0
0,0,0,0,0,0,28,0,0,0,0,0
0,0,0,0,0,0,0,0,0,0,0,0
0,0,0,0,0,0,0,0,0,0,0,0
0,0,0,0,0,0,0,0,0,0,0,0
0,0,0,0,0,0,0,0,0,0,0,0
endlayer

layer
0,0,0,0,0,0,0,0,0,0,0,0
0,0,0,0,0,0,0,0,0,0,0,0
0,0,0,0,0,0,0,0,0,0,0,0
0,0,0,0,0,0,0,0,0,0,0,0
0,0,0,0,0,0,0,0,0,0,0,0
0,0,0,0,0,10,10,10,0,0,0,0
0,0,0,0,0,10,0,10,0,0,0,0
0,0,0,0,0,10,10,10,0,0,0,0
0,0,0,0,0,0,0,0,0,0,0,0
0,0,0,0,0,0,0,0,0,0,0,0
0,0,0,0,0,0,0,0,0,0,0,0
0,0,0,0,0,0,0,0,0,0,0,0
0,0,0,0,0,0,0,0,0,0,0,0
endlayer

layer
0,0,0,0,0,0,0,0,0,0,0,0
0,0,0,0,0,0,0,0,0,0,0,0
0,0,0,0,0,0,0,0,0,0,0,0
0,0,0,0,0,0,0,0,0,0,0,0
0,0,0,0,0,0,0,0,0,0,0,0
0,0,0,0,0,0,27,0,0,0,0,0
0,0,0,0,0,29,0,30,0,0,0,0
0,0,0,0,0,0,28,0,0,0,0,0
0,0,0,0,0,0,0,0,0,0,0,0
0,0,0,0,0,0,0,0,0,0,0,0
0,0,0,0,0,0,0,0,0,0,0,0
0,0,0,0,0,0,0,0,0,0,0,0
0,0,0,0,0,0,0,0,0,0,0,0
endlayer

layer
0,0,0,0,0,0,0,0,0,0,0,0
0,0,0,0,0,0,0,0,0,0,0,0
0,0,0,0,0,0,0,0,0,0,0,0
0,0,0,0,0,0,0,0,0,0,0,0
0,0,0,0,0,0,0,0,0,0,0,0
0,0,0,0,0,0,0,0,0,0,0,0
0,0,0,0,0,0,10,0,0,0,0,0
0,0,0,0,0,0,0,0,0,0,0,0
0,0,0,0,0,0,0,0,0,0,0,0
0,0,0,0,0,0,0,0,0,0,0,0
0,0,0,0,0,0,0,0,0,0,0,0
0,0,0,0,0,0,0,0,0,0,0,0
0,0,0,0,0,0,0,0,0,0,0,0
endlayer

layer
0,0,0,0,0,0,0,0,0,0,0,0
0,0,0,0,0,0,0,0,0,0,0,0
0,0,0,0,0,0,0,0,0,0,0,0
0,0,0,0,0,0,0,0,0,0,0,0
0,0,0,0,0,0,0,0,0,0,0,0
0,0,0,0,0,0,0,0,0,0,0,0
0,0,0,0,0,0,10,0,0,0,0,0
0,0,0,0,0,0,0,0,0,0,0,0
0,0,0,0,0,0,0,0,0,0,0,0
0,0,0,0,0,0,0,0,0,0,0,0
0,0,0,0,0,0,0,0,0,0,0,0
0,0,0,0,0,0,0,0,0,0,0,0
0,0,0,0,0,0,0,0,0,0,0,0
endlayer

layer
0,0,0,0,0,0,0,0,0,0,0,0
0,0,0,0,0,0,0,0,0,0,0,0
0,0,0,0,0,0,0,0,0,0,0,0
0,0,0,0,0,0,0,0,0,0,0,0
0,0,0,0,0,0,0,0,0,0,0,0
0,0,0,0,0,0,0,0,0,0,0,0
0,0,0,0,0,0,14,0,0,0,0,0
0,0,0,0,0,0,0,0,0,0,0,0
0,0,0,0,0,0,0,0,0,0,0,0
0,0,0,0,0,0,0,0,0,0,0,0
0,0,0,0,0,0,0,0,0,0,0,0
0,0,0,0,0,0,0,0,0,0,0,0
0,0,0,0,0,0,0,0,0,0,0,0
endlayer

layer
0,0,0,0,0,0,0,0,0,0,0,0
0,0,0,0,0,0,0,0,0,0,0,0
0,0,0,0,0,0,0,0,0,0,0,0
0,0,0,0,0,0,0,0,0,0,0,0
0,0,0,0,0,0,0,0,0,0,0,0
0,0,0,0,0,0,0,0,0,0,0,0
0,0,0,0,0,0,14,0,0,0,0,0
0,0,0,0,0,0,0,0,0,0,0,0
0,0,0,0,0,0,0,0,0,0,0,0
0,0,0,0,0,0,0,0,0,0,0,0
0,0,0,0,0,0,0,0,0,0,0,0
0,0,0,0,0,0,0,0,0,0,0,0
0,0,0,0,0,0,0,0,0,0,0,0
endlayer

layer
0,0,0,0,0,0,0,0,0,0,0,0
0,0,0,0,0,0,0,0,0,0,0,0
0,0,0,0,0,0,0,0,0,0,0,0
0,0,0,0,0,0,0,0,0,0,0,0
0,0,0,0,0,0,0,0,0,0,0,0
0,0,0,0,0,0,14,0,0,0,0,0
0,0,0,0,0,0,14,0,0,0,0,0
0,0,0,0,0,0,14,0,0,0,0,0
0,0,0,0,0,0,0,0,0,0,0,0
0,0,0,0,0,0,0,0,0,0,0,0
0,0,0,0,0,0,0,0,0,0,0,0
0,0,0,0,0,0,0,0,0,0,0,0
0,0,0,0,0,0,0,0,0,0,0,0
endlayer

layer
0,0,0,0,0,0,0,0,0,0,0,0
0,0,0,0,0,0,0,0,0,0,0,0
0,0,0,0,0,0,0,0,0,0,0,0
0,0,0,0,0,0,0,0,0,0,0,0
0,0,0,0,0,0,0,0,0,0,0,0
0,0,0,0,0,0,0,0,0,0,0,0
0,0,0,0,0,0,14,0,0,0,0,0
0,0,0,0,0,0,0,0,0,0,0,0
0,0,0,0,0,0,0,0,0,0,0,0
0,0,0,0,0,0,0,0,0,0,0,0
0,0,0,0,0,0,0,0,0,0,0,0
0,0,0,0,0,0,0,0,0,0,0,0
0,0,0,0,0,0,0,0,0,0,0,0
endlayer






















