weight=2
embed_into_distance=1
dimensions=4,12,6
max_leveling=8

building_templates=NONE
walk_height=5
min_length=100
max_length=1000
building_interval=75
make_buildings=1
make_end_towers=1

#default towers
tower_rule=1
default_tower_weight=3
spawner_rule=0,40,52-0-Villager
circular_probability=0.25
square_min_height=14
square_max_height=14
square_min_width=7
square_max_width=7
square_roof_styles=Crenel,Steep
circular_tower_min_height=14
circular_tower_max_height=16
circular_tower_min_width=10
circular_tower_max_width=10
circular_tower_roof_styles=Crenel,Dome


rule1=0,100,4 #tower rule, bulk rule
rule2=0,100,WALL_STAIR-3 #steps

#roofway
rule3=0,100,53-0
rule4=0,100,53-1
rule5=0,100,5
rule6=0,100,85
rule7=0,100,50-5 #torch

layer
0,0,3,4,0,0
0,3,5,5,4,0
3,0,0,0,0,4
0,0,0,0,0,0
0,0,0,0,0,0
0,0,0,0,0,0
1,0,0,0,0,1
1,1,1,1,1,1
1,1,1,1,1,1
1,1,1,1,1,1
1,1,1,1,1,1
1,1,1,1,1,1
endlayer

layer
0,0,3,4,0,0
0,3,5,5,4,0
3,0,0,0,0,4
6,0,0,0,0,6
6,0,0,0,0,6
6,0,0,0,0,6
1,0,0,0,0,1
1,1,1,1,1,1
1,1,1,1,1,1
1,1,1,1,1,1
1,1,1,1,1,1
1,1,1,1,1,1
endlayer

layer
0,0,3,4,0,0
0,3,5,5,4,0
3,0,0,0,0,4
0,0,0,0,0,0
0,0,0,0,0,0
0,0,0,0,0,0
1,0,0,0,0,1
1,1,1,1,1,1
1,1,1,1,1,1
1,1,1,1,1,1
1,1,1,1,1,1
1,1,1,1,1,1
endlayer


layer
0,0,3,4,0,0
0,3,5,5,4,0
3,0,0,0,0,4
0,0,0,0,0,0
0,0,0,0,0,0
7,0,0,0,0,7
1,0,0,0,0,1
1,1,1,1,1,1
1,1,1,1,1,1
1,1,1,1,1,1
1,1,1,1,1,1
1,1,1,1,1,1
endlayer


layer:shifted
0,0,3,4,0,0
0,3,5,5,4,0
3,5,0,0,5,4
6,0,0,0,0,6
6,0,0,0,0,6
6,0,0,0,0,6
1,2,2,2,2,1
1,1,1,1,1,1
1,1,1,1,1,1
1,1,1,1,1,1
1,1,1,1,1,1
1,1,1,1,1,1
endlayer

layer:shifted_up
0,0,3,4,0,0
0,3,5,5,4,0
3,5,0,0,5,4
0,0,0,0,0,0
0,0,0,0,0,0
0,0,0,0,0,0
1,2,2,2,2,1
1,1,1,1,1,1
1,1,1,1,1,1
1,1,1,1,1,1
1,1,1,1,1,1
1,1,1,1,1,1
endlayer

layer:shifted_down
0,0,3,4,0,0
0,3,5,5,4,0
3,5,0,0,5,4
0,0,0,0,0,0
0,0,0,0,0,0
0,0,0,0,0,0
1,2,2,2,2,1
1,1,1,1,1,1
1,1,1,1,1,1
1,1,1,1,1,1
1,1,1,1,1,1
1,1,1,1,1,1
endlayer

layer:shifted_right
0,0,3,4,0,0
0,3,5,5,4,0
3,5,0,0,5,4
0,0,0,0,0,0
0,0,0,0,0,0
0,0,0,0,0,0
1,2,2,2,2,1
1,1,1,1,1,1
1,1,1,1,1,1
1,1,1,1,1,1
1,1,1,1,1,1
1,1,1,1,1,1
endlayer

layer:shifted_left
0,0,3,4,0,0
0,3,5,5,4,0
3,5,0,0,5,4
0,0,0,0,0,0
0,0,0,0,0,0
0,0,0,0,0,0
1,2,2,2,2,1
1,1,1,1,1,1
1,1,1,1,1,1
1,1,1,1,1,1
1,1,1,1,1,1
1,1,1,1,1,1
endlayer



layer:base
1,1,1,1,1,1
endlayer