weight=3
embed_into_distance=2
dimensions=4,17,9
max_leveling=8
water_height=4


biomes=Forest,Swampland,Mushroom Island,Taiga,Sky,Jungle
street_templates=RuinedMossyStreet1.tml,RuinedMossyStreet2.tml
building_templates=Mausoleum.tml,BattleBasementUnderground.tml
street_density=14
level_interior=0
walk_height=7
min_length=125
max_length=225
building_interval=15
make_buildings=1

#default towers
tower_rule=2
default_tower_weight=5
spawner_rule=0,35,52-0-Blaze
circular_probability=1.0
tower_offset=-2
circular_tower_min_height=12
circular_tower_max_height=30
circular_tower_min_width=5
circular_tower_max_width=5
circular_tower_roof_styles=Cone

#bulk and tower mossy cobblestone rules
rule1=0,95,4,48,48
rule2=0,87,4,48,48
rule3=0,85,4,48,48,48,48

#stairs for slopes
rule4=0,70,67-1
rule5=0,70,67-0
rule6=0,90,67-3
rule7=0,90,67-2

rule8=1,100,PRESERVE

layer
0,0,0,0,0,0,0,0,0
0,0,0,0,0,0,0,0,0
0,0,0,0,0,0,0,0,0
0,0,0,0,2,0,0,0,0
0,0,0,0,2,0,0,0,0
0,0,0,5,2,4,0,0,0
0,0,0,3,2,3,0,0,0
8,8,8,2,2,2,8,8,8
8,8,8,2,2,2,8,8,8
8,8,8,2,2,2,8,8,8
8,8,8,2,2,2,8,8,8
8,8,8,2,2,2,8,8,8
8,8,5,2,2,2,4,8,8
8,5,3,2,2,2,3,4,8
5,3,1,1,1,1,1,3,4
3,1,1,1,1,1,1,1,3
1,1,1,1,1,1,1,1,1
endlayer

layer
0,0,0,0,0,0,0,0,0
0,0,0,0,6,0,0,0,0
0,0,0,0,1,0,0,0,0
0,0,0,0,2,0,0,0,0
0,0,0,0,2,0,0,0,0
0,0,0,5,2,4,0,0,0
0,0,0,3,2,3,0,0,0
8,8,8,2,2,2,8,8,8
8,8,8,2,2,2,8,8,8
8,8,8,2,2,2,8,8,8
8,8,8,2,2,2,8,8,8
8,8,8,2,2,2,8,8,8
8,8,5,2,2,2,4,8,8
8,5,3,2,2,2,3,4,8
5,3,1,1,1,1,1,3,4
3,1,1,1,1,1,1,1,3
1,1,1,1,1,1,1,1,1
endlayer

layer
0,0,0,0,1,0,0,0,0
0,0,0,0,1,0,0,0,0
0,0,0,0,0,0,0,0,0
0,0,0,0,0,0,0,0,0
0,0,0,0,2,0,0,0,0
0,0,0,5,2,4,0,0,0
0,0,0,3,2,3,0,0,0
8,8,8,2,2,2,8,8,8
8,8,8,2,2,2,8,8,8
8,8,8,2,2,2,8,8,8
8,8,8,2,2,2,8,8,8
8,8,8,2,2,2,8,8,8
8,8,5,2,2,2,4,8,8
8,5,3,2,2,2,3,4,8
5,3,1,1,1,1,1,3,4
3,1,1,1,1,1,1,1,3
1,1,1,1,1,1,1,1,1
endlayer

layer
0,0,0,0,0,0,0,0,0
0,0,0,0,7,0,0,0,0
0,0,0,0,1,0,0,0,0
0,0,0,0,2,0,0,0,0
0,0,0,0,2,0,0,0,0
0,0,0,5,2,4,0,0,0
0,0,0,3,2,3,0,0,0
8,8,8,2,2,2,8,8,8
8,8,8,2,2,2,8,8,8
8,8,8,2,2,2,8,8,8
8,8,8,2,2,2,8,8,8
8,8,8,2,2,2,8,8,8
8,8,5,2,2,2,4,8,8
8,5,3,2,2,2,3,4,8
5,3,1,1,1,1,1,3,4
3,1,1,1,1,1,1,1,3
1,1,1,1,1,1,1,1,1
endlayer

layer:base
1,1,1,1,1,1,1,1,1
endlayer