weight=0
acceptable_target_blocks=0
dimensions=4,12,8

street_templates=SandstoneStreetHumansPlus1.tml,SandstoneStreetHumansPlus2.tml
street_density=16
level_interior=1
building_templates=NONE
walk_height=10
min_length=75
max_length=200
building_interval=20
make_buildings=1

#default towers
tower_rule=1
default_tower_weight=1
spawner_rule=0,100,52-0-humansplus.assassin
circular_probability=1.0
square_min_height=14
square_max_height=20
square_min_width=8
square_max_width=10
square_roof_styles=Crenel,Dome
circular_tower_min_height=16
circular_tower_max_height=20
circular_tower_min_width=7
circular_tower_max_width=7
circular_tower_roof_styles=Dome
circular_tower_roof_rule=5,100,22,22,41,35-14,35-7,35-15,35-13


rule1=0,100,24 #bulk wall and tower rule
rule2=0,100,WALL_STAIR-1 #stairs
rule3=0,100,44-1

layer
0,0,0,0,0,0,0,0
0,0,0,0,0,0,0,0
1,1,1,1,1,1,1,1
1,1,1,1,1,1,1,1
1,1,1,1,1,1,1,1
1,1,1,1,1,1,1,1
1,1,1,1,1,1,1,1
1,1,1,1,1,1,1,1
1,1,1,1,1,1,1,1
1,1,1,1,1,1,1,1
1,1,1,1,1,1,1,1
1,1,1,1,1,1,1,1
endlayer

layer
3,0,0,0,0,0,0,3
1,0,0,0,0,0,0,1
1,1,1,1,1,1,1,1
1,1,1,1,1,1,1,1
1,1,1,1,1,1,1,1
1,1,1,1,1,1,1,1
1,1,1,1,1,1,1,1
1,1,1,1,1,1,1,1
1,1,1,1,1,1,1,1
1,1,1,1,1,1,1,1
1,1,1,1,1,1,1,1
1,1,1,1,1,1,1,1
endlayer

layer
1,0,0,0,0,0,0,1
0,0,0,0,0,0,0,0
1,1,1,1,1,1,1,1
1,1,1,1,1,1,1,1
1,1,1,1,1,1,1,1
1,1,1,1,1,1,1,1
1,1,1,1,1,1,1,1
1,1,1,1,1,1,1,1
1,1,1,1,1,1,1,1
1,1,1,1,1,1,1,1
1,1,1,1,1,1,1,1
1,1,1,1,1,1,1,1
endlayer


layer
3,0,0,0,0,0,0,3
1,0,0,0,0,0,0,1
1,1,1,1,1,1,1,1
1,1,1,1,1,1,1,1
1,1,1,1,1,1,1,1
1,1,1,1,1,1,1,1
1,1,1,1,1,1,1,1
1,1,1,1,1,1,1,1
1,1,1,1,1,1,1,1
1,1,1,1,1,1,1,1
1,1,1,1,1,1,1,1
1,1,1,1,1,1,1,1
endlayer


layer:shifted
0,0,0,0,0,0,0,0
1,2,2,2,2,2,2,1
1,1,1,1,1,1,1,1
1,1,1,1,1,1,1,1
1,1,1,1,1,1,1,1
1,1,1,1,1,1,1,1
1,1,1,1,1,1,1,1
1,1,1,1,1,1,1,1
1,1,1,1,1,1,1,1
1,1,1,1,1,1,1,1
1,1,1,1,1,1,1,1
1,1,1,1,1,1,1,1
endlayer

layer:base
1,1,1,1,1,1,1,1
endlayer