# Author: d00dv4d3r
# From: Default Template

weight=4
embed_into_distance=1
dimensions=4,7,5
max_leveling=2

rule1=0,100,0,43,44
rule2=0,100,4,48
rule3=1,50,45

layer
2,2,2,2,2
2,1,1,1,2
2,1,1,1,2
2,1,1,1,2
2,1,1,1,2
2,1,1,1,2
2,2,2,2,2
endlayer

layer
3,3,3,3,3
3,0,0,0,3
3,0,0,0,3
3,0,0,0,3
3,0,0,0,3
3,0,0,0,3
3,3,3,3,3
endlayer

layer
3,3,3,3,3
3,0,0,0,3
3,0,0,0,3
3,0,0,0,3
3,0,0,0,3
3,0,0,0,3
3,3,3,3,3
endlayer

layer
3,3,3,3,3
3,0,0,0,3
3,0,0,0,3
3,0,0,0,3
3,0,0,0,3
3,0,0,0,3
3,3,3,3,3
endlayer