# Author: Malgor
# From: Minecraft Forums
biomes=FrozenOcean,FrozenRiver,Taiga,IceMountains,IcePlains
weight=5
embed_into_distance=1
acceptable_target_blocks=2,3,12,79
dimensions=5,6,6
allowable_overhang=2
max_cut_in=2
cut_in_buffer=1
max_leveling=2
leveling_buffer=1
preserve_water=0
preserve_lava=0
preserve_plants=0

rule1=1,80,80
rule2=2,60,80
rule3=0,100,79

layer
3,3,3,3,3,3
3,3,3,3,3,3
3,3,3,3,3,3
3,3,3,3,3,3
3,3,3,3,3,3
3,3,3,3,3,3
endlayer

layer
1,1,0,1,1,1
1,0,0,0,0,1
1,0,1,1,0,1
0,0,1,1,0,1
1,0,0,0,0,1
1,1,1,1,1,1
endlayer

layer
1,1,0,0,1,1
1,0,0,0,0,0
1,0,0,0,0,1
0,0,0,0,0,1
1,0,0,0,0,0
1,1,1,1,1,1
endlayer

layer
0,1,1,1,1,0
1,1,0,0,1,1
1,0,0,0,0,1
1,0,0,0,0,1
1,1,0,0,1,1
0,1,1,1,1,0
endlayer

layer
0,0,2,2,0,0
0,2,2,2,2,0
2,2,2,2,2,2
2,2,2,2,2,2
0,2,2,2,2,0
0,0,2,2,0,0
endlayer