# Author: Malgor
# From: Minecraft Forums

weight=5
embed_into_distance=1
dimensions=3,7,7
max_leveling=4


rule1=0,100,2,2,3
rule2=1,95,8,8,8,8,3
rule3=0,80,60
rule4=1,70,59-1,59-2,59-3
rule5=1,40,85

layer
1,1,1,1,1,1,1
1,3,3,2,3,3,1
1,3,3,2,3,3,1
1,2,2,2,2,2,1
1,3,3,2,3,3,1
1,3,3,2,3,3,1
1,1,1,1,1,1,1
endlayer

layer
5,5,5,5,5,5,5
5,4,4,0,4,4,5
5,4,4,0,4,4,5
5,0,0,0,0,0,5
5,4,4,0,4,4,5
5,4,4,0,4,4,5
5,5,5,5,5,5,5
endlayer

layer
0,0,0,0,0,0,0
0,0,0,0,0,0,0
0,0,0,0,0,0,0
0,0,0,0,0,0,0
0,0,0,0,0,0,0
0,0,0,0,0,0,0
0,0,0,0,0,0,0
endlayer